Workbook

Sheet 报价汇总-装修工程
B1: D座塔楼办公室3903-04-05-06装饰工程汇总 装修工程 | J1: =2450/83 -> 29.518072 | L1: =40*83 -> 3320
A2: 序号 | B2: 名称 | C2: 金额（元） | D2: 面积（㎡） | E2: 单方价格（元/㎡） | F2: 备注 | M2: =100/83 -> 1.2048193
A3: 一 | B3: 装饰工程 | C3: =不含空调消防清单!G3 -> 653982.63
A4: （一） | B4: 拆除工程 | C4: =不含空调消防清单!G4 -> 22177.008
A5: （二） | B5: 隔墙工程 | C5: =不含空调消防清单!G8 -> 172720.41
A6: （三） | B6: 办公室一 | C6: =不含空调消防清单!G14 -> 75493.417
A7: （四） | B7: 办公室二 | C7: =不含空调消防清单!G32 -> 55916.234
A8: （五） | B8: 办公室三 | C8: =不含空调消防清单!G50 -> 48771.897
A9: （六） | B9: 办公室四 | C9: =不含空调消防清单!G68 -> 39052.824
A10: （七） | B10: 办公室五 | C10: =不含空调消防清单!G86 -> 41796.512
A11: （八） | B11: 办公室六 | C11: =不含空调消防清单!G104 -> 102911.5
A12: （九） | B12: 办公室七 | C12: =不含空调消防清单!G123 -> 45389.108
A13: （十） | B13: 办公室八 | C13: =不含空调消防清单!G141 -> 49753.722
A14: 二 | B14: 安装工程 | C14: =不含空调消防清单!G159 -> 205172.92
A15: （一） | B15: 办公室一安装工程 | C15: =不含空调消防清单!G160 -> 32647
A16: （二） | B16: 办公室二安装工程 | C16: =不含空调消防清单!G175 -> 24303.417
A17: （三） | B17: 办公室三安装工程 | C17: =不含空调消防清单!G190 -> 22195.167
A18: （四） | B18: 办公室四安装工程 | C18: =不含空调消防清单!G205 -> 18135.167
A19: （五） | B19: 办公室五安装工程 | C19: =不含空调消防清单!G220 -> 21797.667
A20: （六） | B20: 办公室六安装工程 | C20: =不含空调消防清单!G235 -> 45150.667
A21: （七） | B21: 办公室七安装工程 | C21: =不含空调消防清单!G250 -> 20399.417
A22: （八） | B22: 办公室八安装工程 | C22: =不含空调消防清单!G265 -> 20544.417
A23: 三 | B23: 其他工程 | C23: =不含空调消防清单!G280 -> 187720.02
A24: 四 | B24: 小计：一+二+三 | C24: =C3+C14+C23 -> 1046875.6 | D24: 864.74 | E24: =C24/D24 -> 1210.6247 | G24: 含消防空调成本总价 | H24: 255733.89 | I24: =C24+'报价汇总-空调消防'!C13 -> 1490105.9
A25: 五 | B25: 管理费 | C25: =不含空调消防清单!G290 -> 52343.778 | G25: 含消防空调单方造价 | H25: =H24/D24 -> 295.735 | I25: =I24/D24 -> 1723.1837
A26: 六 | B26: 税金 | C26: =不含空调消防清单!G291 -> 32976.58
A27: 七 | B27: 合计=四+五+六 | C27: =C24+C25+C26 -> 1132195.9 | D27: 864.74 | E27: =C27/D27 -> 1309.2906
A28: 八 | B28: 施工图、效果图设计费 | C28: 0
A29: 九 | B29: 总计:七+八 | C29: =C28+C27 -> 1132195.9 | D29: 864.74 | E29: =C29/D29 -> 1309.2906 | G29: =C29+'报价汇总-空调消防'!C16 -> 1611549.5 | H29: =H24*1.43 -> 365699.46
B31: 空调消防工程 | C31: ='报价汇总-空调消防'!C16 -> 479353.57
B32: 总计 | C32: =C29+C31 -> 1611549.5
B34: 装饰成本 | C34: =1011875.56878667+30000 -> 1041875.6 | E34: =C24 -> 1046875.6 | F34: =E34-C34 -> 5000
B35: 空调成本 | C35: ='报价汇总-空调消防'!G3 -> 252000 | E35: ='报价汇总-空调消防'!C3 -> 319500 | F35: =E35-C35 -> 67500
B36: 消防成本 | C36: ='报价汇总-空调消防'!G12 -> 88645.8 | E36: ='报价汇总-空调消防'!C12 -> 123730.3 | F36: =E36-C36 -> 35084.5
C37: =SUM(C34:C36) -> 1382521.4 | E37: =SUM(E34:E36) -> 1490105.9 | F37: =E37-C37 -> 107584.5
B38: 管理费 | C38: 0 | E38: =E37*0.05 -> 74505.293
B39: 直接费 | C39: =SUM(C37:C38) -> 1382521.4 | E39: =SUM(E37:E38) -> 1564611.2
B40: 税金 | C40: =C39*0.03 -> 41475.641 | E40: =E39*0.03 -> 46938.335
B41: 含税合计 | C41: =C39+C40 -> 1423997 | E41: =E39+E40 -> 1611549.5 | F41: =(E41-C41)/C41 -> 0.13170848

Sheet 不含空调消防清单
A1: D座塔楼办公室3903-04-05-06装饰工程- （不含空调消防） | I1: =G292 -> 1132195.9 | Q1: 1 | S1: =$Q$1 -> 1 | T1: =$Q$1 -> 1 | U1: =$Q$1 -> 1 | V1: ='报价汇总-装修工程'!G29 -> 1611549.5 | W1: =18.84+18.31+39.39+16.39+7.1+10.25+8.68+2.78 -> 121.74
A2: 序号 | B2: 项目名称 | C2: 项目特征 | D2: 单位 | E2: 工程量 | F2: 综合单价（不含税） | G2: 合价 | H2: 备注 | I2: 综合单价（不含税） | J2: 主材费 | K2: 主材损耗率 | L2: 人工费 | M2: 辅材费 | N2: 机械费 | O2: 合计 | P2: 成本价 | Q2: 主材费 | R2: 主材损耗率 | S2: 人工费 | T2: 辅材费 | U2: 机械费
A3: 一 | B3: 装饰工程 | G3: =SUBTOTAL(9,G4:G158) -> 653982.63
A4: （一） | B4: 拆除工程 | G4: =SUBTOTAL(9,G5:G7) -> 22177.008
A5: 1 | B5: 拆除原有砖墙 （150mm厚） | C5: 1、人工拆除 2、机械设备 3、防护措施 4、垃圾清理装袋 | D5: ㎡ | E5: =3.81*(4.3+2.4+10.08+9.93)-1.5*2.2+1.5*2.2*3 -> 108.3651 | F5: =I5 -> 141.9 | G5: =F5*E5 -> 15377.008 | I5: =J5+J5*K5+L5+M5+N5 -> 141.9 | J5: =Q5*$Q$1 -> 40 | K5: =R5 -> 0.01 | L5: =S5*$S$1 -> 70 | M5: =T5*$T$1 -> 30 | N5: =U5*$U$1 -> 1.5 | O5: =E5*I5 -> 15377.008 | P5: =Q5*(1+R5)+S5+T5+U5 -> 141.9 | Q5: =10*4 -> 40 | R5: 0.01 | S5: 70 | T5: 30 | U5: 1.5
A6: 2 | B6: 原墙面开门洞后加固 （1500*2200） | C6: 1、横梁槽钢加固 2、门洞侧边水泥砂浆修补 3、12mm阻燃版封边 | D6: 樘 | E6: 3 | F6: =I6 -> 1500 | G6: =F6*E6 -> 4500 | I6: =J6+J6*K6+L6+M6+N6 -> 1500 | J6: =Q6*$Q$1 -> 1000 | K6: =R6 -> 0 | L6: =S6*$S$1 -> 500 | M6: =T6*$T$1 -> 0 | N6: =U6*$U$1 -> 0 | O6: =E6*I6 -> 4500 | P6: =Q6*(1+R6)+S6+T6+U6 -> 1500 | Q6: 1000 | S6: 500
A7: 3 | B7: 原墙面开门洞后加固 （4300*2200） | C7: 1、横梁槽钢加固 2、门洞侧边水泥砂浆修补 3、12mm阻燃版封边 | D7: 樘 | E7: 1 | F7: =I7 -> 2300 | G7: =F7*E7 -> 2300 | I7: =J7+J7*K7+L7+M7+N7 -> 2300 | J7: =Q7*$Q$1 -> 1500 | K7: =R7 -> 0 | L7: =S7*$S$1 -> 800 | M7: =T7*$T$1 -> 0 | N7: =U7*$U$1 -> 0 | O7: =E7*I7 -> 2300 | P7: =Q7*(1+R7)+S7+T7+U7 -> 2300 | Q7: 1500 | S7: 800
A8: （二） | B8: 隔墙工程 | G8: =SUBTOTAL(9,G9:G13) -> 172720.41
A9: 1 | B9: 轻钢龙骨隔墙 | C9: 双层双面轻钢龙骨隔墙 1、墙厚120mm; 2、75mm轻钢龙骨； 3、50mm厚，48kg/m3的吸音棉； 4、9.5mm厚石膏板 | D9: ㎡ | E9: =3.81*(3.71+3.38*3+0.83+1.63+3+12.8+3.19*3+12.26+2.8+3.19*2+10.08+3.8+3.08+11.16+3.52+3.21+0.1+0.25+0.4+0.43+0.23+4.22+4.15+4.19+0.44+0.3+2.81+0.55+0.52+4.3+2.75+9.93+0.55+1.56+2.8+3*2+11.88+0.44+1.56+2.8+2.74*2+0.55+0.33+0.8+0.8)+1.31*(1.8+1.7+1.2+1.6+1.6+2.18+1.67+1.2+1.2) -> 662.7694 | F9: =I9 -> 135.95 | G9: =F9*E9 -> 90103.5 | I9: =J9+J9*K9+L9+M9+N9 -> 135.95 | J9: =Q9*$Q$1 -> 30 | K9: =R9 -> 0.01 | L9: =S9*$S$1 -> 70 | M9: =T9*$T$1 -> 34.15 | N9: =U9*$U$1 -> 1.5 | O9: =E9*I9 -> 90103.5 | P9: =Q9*(1+R9)+S9+T9+U9 -> 135.95 | Q9: =7.5*4 -> 30 | R9: 0.01 | S9: 70 | T9: =22.5+11.65 -> 34.15 | U9: 1.5
A10: 2 | B10: 新建轻质砖墙 （150mm厚） | C10: 1、成品砂浆、15#轻质砖 2、完成面150mm厚 | D10: ㎡ | E10: =1.5*2.2*3+3.81*(6.76+2.28)-1.5*2.2 -> 41.0424 | F10: =I10 -> 98.4 | G10: =F10*E10 -> 4038.5722 | I10: =J10+J10*K10+L10+M10+N10 -> 98.4 | J10: =Q10*$Q$1 -> 42.9 | K10: =R10 -> 0 | L10: =S10*$S$1 -> 45 | M10: =T10*$T$1 -> 10 | N10: =U10*$U$1 -> 0.5 | O10: =E10*I10 -> 4038.5722 | P10: =Q10*(1+R10)+S10+T10+U10 -> 98.4 | Q10: =286*0.15 -> 42.9 | R10: 0 | S10: 45 | T10: 10 | U10: 0.5
A11: 3 | B11: 内墙水泥砂浆抹灰 | C11: 1、基层墙体：砌体墙、混凝土墙 2、厚度：20mm 3、做法：墙面基层清理，不同界面交接处、阴角转角处、管线开槽处，挂镀锌电焊网，公区人流通道等局部砌体墙满挂镀锌电焊网，面层压入1道耐碱网格布，水泥砂浆找平、压实抹光； | D11: ㎡ | E11: =E10*2 -> 82.0848 | F11: =I11 -> 38.5 | G11: =F11*E11 -> 3160.2648 | I11: =J11+J11*K11+L11+M11+N11 -> 38.5 | J11: =Q11*$Q$1 -> 0 | K11: =R11 -> 0.01 | L11: =S11*$S$1 -> 30 | M11: =T11*$T$1 -> 8.5 | N11: =U11*$U$1 -> 0 | O11: =E11*I11 -> 3160.2648 | P11: =Q11*(1+R11)+S11+T11+U11 -> 38.5 | R11: 0.01 | S11: 30 | T11: 8.5
A12: 4 | B12: GL-01 中空钢化玻璃隔断（含免漆板隔断） | C12: 1、GL-01 5+5mm钢化玻璃; 2、铝框包边 3、五金配件等制作安装 | D12: ㎡ | E12: =2.8*(1.88+10.25+10.65+1.25+9.13+8.85+6.55+1.86+7.12+2.85+1+9.18+1+7.23+0.91)-0.9*2.4*25 -> 169.188 | F12: =I12 -> 328.5 | G12: =F12*E12 -> 55578.258 | I12: =J12+J12*K12+L12+M12+N12 -> 328.5 | J12: =Q12*$Q$1 -> 300 | K12: =R12 -> 0.01 | L12: =S12*$S$1 -> 15 | M12: =T12*$T$1 -> 10.5 | N12: =U12*$U$1 -> 0 | O12: =E12*I12 -> 55578.258 | P12: =Q12*(1+R12)+S12+T12+U12 -> 328.5 | Q12: 300 | R12: 0.01 | S12: 15 | T12: 10.5
A13: 5 | B13: 玻璃隔断上方封板 | C13: 双层双面钢结构龙骨隔墙 1、墙厚100mm; 2、钢结构龙骨； 3、50mm厚，48kg/m3的吸音棉； 4、12mm厚阻燃夹板+9.5mm厚石膏板 | D13: ㎡ | E13: =1.31*(1.88+10.25+10.65+1.25+9.13+8.85+6.55+1.86+7.12+2.85+1+9.18+1+7.23+0.91) -> 104.4201 | F13: =I13 -> 190 | G13: =F13*E13 -> 19839.819 | I13: =J13+J13*K13+L13+M13+N13 -> 190 | J13: =Q13*$Q$1 -> 85 | K13: =R13 -> 0.01 | L13: =S13*$S$1 -> 70 | M13: =T13*$T$1 -> 34.15 | N13: =U13*$U$1 -> 0 | O13: =E13*I13 -> 19839.819 | P13: =Q13*(1+R13)+S13+T13+U13 -> 190 | Q13: =35*2+7.5*2 -> 85 | R13: 0.01 | S13: 70 | T13: =22.5+11.65 -> 34.15
A14: （三） | B14: 办公室一 | G14: =SUBTOTAL(9,G15:G31) -> 75493.417
A15: 1 | B15: 地面架空层 | C15: 1、100mm高 2、500*500mm架空地板 | D15: ㎡ | E15: =19.02+9.71+9.38+25.69+16.52+53.48-2.25 -> 131.55 | F15: =I15 -> 126.25 | G15: =F15*E15 -> 16608.188 | I15: =J15+J15*K15+L15+M15+N15 -> 126.25 | J15: =Q15*$Q$1 -> 125 | K15: =R15 -> 0.01 | L15: =S15*$S$1 -> 0 | M15: =T15*$T$1 -> 0 | N15: =U15*$U$1 -> 0 | O15: =E15*I15 -> 16608.188 | P15: =Q15*(1+R15)+S15+T15+U15 -> 126.25 | Q15: 125 | R15: 0.01 | U15: 0
A16: 2 | B16: 地面地毯 | C16: 1、规格尺寸：500*500 2、地毯专用胶，厚度包干，后期不因厚度调整价格； | D16: ㎡ | E16: =E15 -> 131.55 | F16: =I16 -> 71.5 | G16: =F16*E16 -> 9405.825 | I16: =J16+J16*K16+L16+M16+N16 -> 71.5 | J16: =Q16*$Q$1 -> 60 | K16: =R16 -> 0.025 | L16: =S16*$S$1 -> 5 | M16: =T16*$T$1 -> 5 | N16: =U16*$U$1 -> 0 | O16: =E16*I16 -> 9405.825 | P16: =Q16*(1+R16)+S16+T16+U16 -> 71.5 | Q16: 60 | R16: 0.025 | S16: 5 | T16: 5 | U16: 0
A17: 3 | B17: 原天棚喷乳胶漆PT-02 (含墙体上部) | C17: 1、面层：PT-02深色涂料两遍 2、包含各种管道 | D17: ㎡ | E17: =53.48+33.9*1.31 -> 97.889 | F17: =I17 -> 20.08 | G17: =F17*E17 -> 1965.6111 | I17: =J17+J17*K17+L17+M17+N17 -> 20.08 | J17: =Q17*$Q$1 -> 8 | K17: =R17 -> 0.01 | L17: =S17*$S$1 -> 10 | M17: =T17*$T$1 -> 0.5 | N17: =U17*$U$1 -> 1.5 | O17: =E17*I17 -> 1965.6111 | P17: =Q17*(1+R17)+S17+T17+U17 -> 20.08 | Q17: 8 | R17: 0.01 | S17: 10 | T17: 0.5 | U17: 1.5
A18: 4 | B18: 石膏板天花吊顶 | C18: 1、吊顶形式：平级+跌级吊顶 2、基层：轻钢龙骨+双层9.5mm厚石膏板 | D18: ㎡ | E18: =19.02+9.71+9.38+25.69+16.52-2.25 -> 78.07 | F18: =I18 -> 144.18 | G18: =F18*E18 -> 11256.133 | I18: =J18+J18*K18+L18+M18+N18 -> 144.18 | J18: =Q18*$Q$1 -> 18 | K18: =R18 -> 0.01 | L18: =S18*$S$1 -> 100 | M18: =T18*$T$1 -> 26 | N18: =U18*$U$1 -> 0 | O18: =E18*I18 -> 11256.133 | P18: =Q18*(1+R18)+S18+T18+U18 -> 144.18 | Q18: 18 | R18: 0.01 | S18: 100 | T18: 26
A19: 5 | B19: 天花板缝贴纸带刮平整 | C19: 1、螺丝钉刷防锈漆 2、缝贴纸带刮平整 | D19: ㎡ | E19: =$E$18 -> 78.07 | F19: =I19 -> 8.5 | G19: =F19*E19 -> 663.595 | I19: =J19+J19*K19+L19+M19+N19 -> 8.5 | J19: =Q19*$Q$1 -> 3.5 | K19: =R19 -> 0 | L19: =S19*$S$1 -> 5 | M19: =T19*$T$1 -> 0 | N19: =U19*$U$1 -> 0 | O19: =E19*I19 -> 663.595 | P19: =Q19*(1+R19)+S19+T19+U19 -> 8.5 | Q19: 3.5 | R19: 0 | S19: 5 | T19: 0 | U19: 0
A20: 6 | B20: 天花挂耐水腻子 | C20: 1、耐水腻子2道，含打磨、修补 | D20: ㎡ | E20: =$E$18 -> 78.07 | F20: =I20 -> 23.5 | G20: =F20*E20 -> 1834.645 | I20: =J20+J20*K20+L20+M20+N20 -> 23.5 | J20: =Q20*$Q$1 -> 3.5 | K20: =R20 -> 0 | L20: =S20*$S$1 -> 20 | M20: =T20*$T$1 -> 0 | N20: =U20*$U$1 -> 0 | O20: =E20*I20 -> 1834.645 | P20: =Q20*(1+R20)+S20+T20+U20 -> 23.5 | Q20: 3.5 | R20: 0 | S20: 20 | T20: 0 | U20: 0
A21: 7 | B21: 天棚乳胶漆 | C21: 1、面层：PT-01无机白色涂料一底二面 | D21: ㎡ | E21: =$E$18 -> 78.07 | F21: =I21 -> 13 | G21: =F21*E21 -> 1014.91 | I21: =J21+J21*K21+L21+M21+N21 -> 13 | J21: =Q21*$Q$1 -> 3 | K21: =R21 -> 0 | L21: =S21*$S$1 -> 10 | M21: =T21*$T$1 -> 0 | N21: =U21*$U$1 -> 0 | O21: =E21*I21 -> 1014.91 | P21: =Q21*(1+R21)+S21+T21+U21 -> 13 | Q21: 3 | R21: 0 | S21: 10 | T21: 0 | U21: 0
A22: 8 | B22: 窗帘盒 | C22: 1、基层：钢结构龙骨+阻燃板基层 2、面层：9.5mm厚石膏板 | D22: m | E22: =3.48+2.63+2.53+7+3.28+4.9 -> 23.82 | F22: =I22 -> 195.17 | G22: =F22*E22 -> 4648.9494 | I22: =J22+J22*K22+L22+M22+N22 -> 195.17 | J22: =Q22*$Q$1 -> 131.67 | K22: =R22 -> 0 | L22: =S22*$S$1 -> 55 | M22: =T22*$T$1 -> 8.5 | N22: =U22*$U$1 -> 0 | O22: =E22*I22 -> 4648.9494 | P22: =Q22*(1+R22)+S22+T22+U22 -> 195.17 | Q22: =4.2*5.7*5.5 -> 131.67 | S22: 55 | T22: 8.5
A23: 9 | B23: 窗帘 | C23: 1、成品窗帘 | D23: ㎡ | E23: =(3.48+2.63+2.53+7+3.28+4.9)*2.8 -> 66.696 | F23: =I23 -> 75 | G23: =F23*E23 -> 5002.2 | I23: =J23+J23*K23+L23+M23+N23 -> 75 | J23: =Q23*$Q$1 -> 68 | K23: =R23 -> 0 | L23: =S23*$S$1 -> 5 | M23: =T23*$T$1 -> 1.5 | N23: =U23*$U$1 -> 0.5 | O23: =E23*I23 -> 5002.2 | P23: =Q23*(1+R23)+S23+T23+U23 -> 75 | Q23: 68 | S23: 5 | T23: 1.5 | U23: 0.5
A24: 10 | B24: 墙面缝贴纸带刮平整 | C24: 1、螺丝钉刷防锈漆 2、缝贴纸带刮平整 | D24: ㎡ | E24: =2.8*(5.3+0.625*2+3.59+3.41*4+3.69*2+0.83*2+6+1.63+2.95+3.71+3+5.51+0.1+3+9.58)-1.5*2.2 -> 187.94 | F24: =I24 -> 8.5 | G24: =F24*E24 -> 1597.49 | I24: =J24+J24*K24+L24+M24+N24 -> 8.5 | J24: =Q24*$Q$1 -> 3.5 | K24: =R24 -> 0 | L24: =S24*$S$1 -> 5 | M24: =T24*$T$1 -> 0 | N24: =U24*$U$1 -> 0 | O24: =E24*I24 -> 1597.49 | P24: =Q24*(1+R24)+S24+T24+U24 -> 8.5 | Q24: =Q19 -> 3.5 | R24: =R19 -> 0 | S24: =S19 -> 5 | T24: =T19 -> 0 | U24: 0
A25: 11 | B25: 墙面挂耐水腻子 | C25: 耐水腻子2道，含打磨、修补 | D25: ㎡ | E25: =E24 -> 187.94 | F25: =I25 -> 23.5 | G25: =F25*E25 -> 4416.59 | I25: =J25+J25*K25+L25+M25+N25 -> 23.5 | J25: =Q25*$Q$1 -> 3.5 | K25: =R25 -> 0 | L25: =S25*$S$1 -> 20 | M25: =T25*$T$1 -> 0 | N25: =U25*$U$1 -> 0 | O25: =E25*I25 -> 4416.59 | P25: =Q25*(1+R25)+S25+T25+U25 -> 23.5 | Q25: =Q20 -> 3.5 | R25: =R20 -> 0 | S25: =S20 -> 20 | T25: =T20 -> 0 | U25: 0
A26: 12 | B26: 墙面乳胶漆PT-01 | C26: 1、面层：PT-01无机白色涂料一底二面 | D26: ㎡ | E26: =E24-10.39 -> 177.55 | F26: =I26 -> 13 | G26: =F26*E26 -> 2308.15 | I26: =J26+J26*K26+L26+M26+N26 -> 13 | J26: =Q26*$Q$1 -> 3 | K26: =R26 -> 0 | L26: =S26*$S$1 -> 10 | M26: =T26*$T$1 -> 0 | N26: =U26*$U$1 -> 0 | O26: =E26*I26 -> 2308.15 | P26: =Q26*(1+R26)+S26+T26+U26 -> 13 | Q26: =Q21 -> 3 | R26: =R21 -> 0 | S26: =S21 -> 10 | T26: =T21 -> 0 | U26: 0
A27: 13 | B27: 墙面艺术涂料 | C27: 1、面层：艺术涂料一底二面 | D27: ㎡ | E27: =2.8*3.71 -> 10.388 | F27: =I27 -> 120.85 | G27: =F27*E27 -> 1255.3898 | I27: =J27+J27*K27+L27+M27+N27 -> 120.85 | J27: =Q27*$Q$1 -> 85 | K27: =R27 -> 0.01 | L27: =S27*$S$1 -> 35 | M27: =T27*$T$1 -> 0 | N27: =U27*$U$1 -> 0 | O27: =E27*I27 -> 1255.3898 | P27: =Q27*(1+R27)+S27+T27+U27 -> 120.85 | Q27: 85 | R27: 0.01 | S27: 35 | T27: 0 | U27: 0
A28: 14 | B28: MT-01 1.2mm厚不锈钢踢脚线 | C28: 1、规格尺寸：50mm高 2、面层：MT-01 1.2mm厚不锈钢 3、基层：轻钢龙骨+12mm厚阻燃夹板 | D28: m | E28: =5.3+0.625*2+3.59+3.41*4+3.69*2+0.83*2+6+1.63+2.95+3.71+3+5.51+0.1+3+9.58-1.5 -> 66.8 | F28: =I28 -> 42.062 | G28: =F28*E28 -> 2809.7416 | I28: =J28+J28*K28+L28+M28+N28 -> 42.062 | J28: =Q28*$Q$1 -> 23.1 | K28: =R28 -> 0.02 | L28: =S28*$S$1 -> 15 | M28: =T28*$T$1 -> 3.5 | N28: =U28*$U$1 -> 0 | O28: =E28*I28 -> 2809.7416 | P28: =Q28*(1+R28)+S28+T28+U28 -> 42.062 | Q28: =0.06*360+1.5 -> 23.1 | R28: 0.02 | S28: 15 | T28: 3.5
A29: 15 | B29: 门禁系统安装 | C29: 1、门洞尺寸：1500*2200mm 2、包含设备、管线、调试等 | D29: 项 | E29: 1 | F29: =I29 -> 2050 | G29: =F29*E29 -> 2050 | I29: =J29+J29*K29+L29+M29+N29 -> 2050 | J29: =Q29*$Q$1 -> 1200 | K29: =R29 -> 0 | L29: =S29*$S$1 -> 800 | M29: =T29*$T$1 -> 50 | N29: =U29*$U$1 -> 0 | O29: =E29*I29 -> 2050 | P29: =Q29*(1+R29)+S29+T29+U29 -> 2050 | Q29: 1200 | S29: 800 | T29: 50
A30: 16 | B30: 隔断免漆板单开门 | C30: 1、免漆板单开门 2、门洞尺寸：800mm*2400mm 4、含门锁.五金等制作安装 | D30: 樘 | E30: 4 | F30: =I30 -> 1800 | G30: =F30*E30 -> 7200 | I30: =J30+J30*K30+L30+M30+N30 -> 1800 | J30: =Q30*$Q$1 -> 1620 | K30: =R30 -> 0 | L30: =S30*$S$1 -> 180 | M30: =T30*$T$1 -> 0 | N30: =U30*$U$1 -> 0 | O30: =E30*I30 -> 7200 | P30: =Q30*(1+R30)+S30+T30+U30 -> 1800 | Q30: =750*0.9*2.4 -> 1620 | S30: 180
A31: 17 | B31: 玻璃双开门 （无框） | C31: 1、10mm厚钢化玻璃门 2、门洞尺寸：1500mm*2200mm 4、含门锁.不锈钢扶手五金等制作安装 | D31: 樘 | E31: 1 | F31: =I31 -> 1456 | G31: =F31*E31 -> 1456 | I31: =J31+J31*K31+L31+M31+N31 -> 1456 | J31: =Q31*$Q$1 -> 396 | K31: =R31 -> 0 | L31: =S31*$S$1 -> 360 | M31: =T31*$T$1 -> 700 | N31: =U31*$U$1 -> 0 | O31: =E31*I31 -> 1456 | P31: =Q31*(1+R31)+S31+T31+U31 -> 1456 | Q31: =120*1.5*2.2 -> 396 | S31: =180*2 -> 360 | T31: =350*2 -> 700
A32: （四） | B32: 办公室二 | G32: =SUBTOTAL(9,G33:G49) -> 55916.234
A33: 1 | B33: 地面架空层 | C33: 1、100mm高 2、500*500mm架空地板 | D33: ㎡ | E33: =14.88+5.92+7.67+11.08+16+47.63-2.56 -> 100.62 | F33: =I33 -> 126.25 | G33: =F33*E33 -> 12703.275 | I33: =J33+J33*K33+L33+M33+N33 -> 126.25 | J33: =Q33*$Q$1 -> 125 | K33: =R33 -> 0.01 | L33: =S33*$S$1 -> 0 | M33: =T33*$T$1 -> 0 | N33: =U33*$U$1 -> 0 | O33: =E33*I33 -> 12703.275 | P33: =Q33*(1+R33)+S33+T33+U33 -> 126.25 | Q33: =$Q$15 -> 125 | R33: =$R$15 -> 0.01 | S33: =$S$15 -> 0 | T33: =$T$15 -> 0 | U33: =$U$15 -> 0
A34: 2 | B34: 地面地毯 | C34: 1、规格尺寸：500*500 2、地毯专用胶，厚度包干，后期不因厚度调整价格； | D34: ㎡ | E34: =E33 -> 100.62 | F34: =I34 -> 71.5 | G34: =F34*E34 -> 7194.33 | I34: =J34+J34*K34+L34+M34+N34 -> 71.5 | J34: =Q34*$Q$1 -> 60 | K34: =R34 -> 0.025 | L34: =S34*$S$1 -> 5 | M34: =T34*$T$1 -> 5 | N34: =U34*$U$1 -> 0 | O34: =E34*I34 -> 7194.33 | P34: =Q34*(1+R34)+S34+T34+U34 -> 71.5 | Q34: =$Q$16 -> 60 | R34: =$R$16 -> 0.025 | S34: =$S$16 -> 5 | T34: =$T$16 -> 5 | U34: =$U$16 -> 0
A35: 3 | B35: 原天棚喷乳胶漆PT-02 (含墙体上部) | C35: 1、面层：PT-02深色涂料两遍 2、包含各种管道 | D35: ㎡ | E35: =47.63-2.56+1.31*(33.02+6.4) -> 96.7102 | F35: =I35 -> 20.08 | G35: =F35*E35 -> 1941.9408 | I35: =J35+J35*K35+L35+M35+N35 -> 20.08 | J35: =Q35*$Q$1 -> 8 | K35: =R35 -> 0.01 | L35: =S35*$S$1 -> 10 | M35: =T35*$T$1 -> 0.5 | N35: =U35*$U$1 -> 1.5 | O35: =E35*I35 -> 1941.9408 | P35: =Q35*(1+R35)+S35+T35+U35 -> 20.08 | Q35: =$Q$17 -> 8 | R35: =$R$17 -> 0.01 | S35: =$S$17 -> 10 | T35: =$T$17 -> 0.5 | U35: =$U$17 -> 1.5
A36: 4 | B36: 石膏板天花吊顶 | C36: 1、吊顶形式：平级+跌级吊顶 2、基层：轻钢龙骨+双层9.5mm厚石膏板 | D36: ㎡ | E36: =14.88+5.92+7.67+11.08+16 -> 55.55 | F36: =I36 -> 144.18 | G36: =F36*E36 -> 8009.199 | I36: =J36+J36*K36+L36+M36+N36 -> 144.18 | J36: =Q36*$Q$1 -> 18 | K36: =R36 -> 0.01 | L36: =S36*$S$1 -> 100 | M36: =T36*$T$1 -> 26 | N36: =U36*$U$1 -> 0 | O36: =E36*I36 -> 8009.199 | P36: =Q36*(1+R36)+S36+T36+U36 -> 144.18 | Q36: =$Q$18 -> 18 | R36: =$R$18 -> 0.01 | S36: =$S$18 -> 100 | T36: =$T$18 -> 26 | U36: =$U$18 -> 0
A37: 5 | B37: 天花板缝贴纸带刮平整 | C37: 1、螺丝钉刷防锈漆 2、缝贴纸带刮平整 | D37: ㎡ | E37: =$E$36 -> 55.55 | F37: =I37 -> 8.5 | G37: =F37*E37 -> 472.175 | I37: =J37+J37*K37+L37+M37+N37 -> 8.5 | J37: =Q37*$Q$1 -> 3.5 | K37: =R37 -> 0 | L37: =S37*$S$1 -> 5 | M37: =T37*$T$1 -> 0 | N37: =U37*$U$1 -> 0 | O37: =E37*I37 -> 472.175 | P37: =Q37*(1+R37)+S37+T37+U37 -> 8.5 | Q37: =$Q$19 -> 3.5 | R37: =$R$19 -> 0 | S37: =$S$19 -> 5 | T37: =$T$19 -> 0 | U37: =$U$19 -> 0
A38: 6 | B38: 天花挂耐水腻子 | C38: 1、耐水腻子2道，含打磨、修补 | D38: ㎡ | E38: =$E$36 -> 55.55 | F38: =I38 -> 23.5 | G38: =F38*E38 -> 1305.425 | I38: =J38+J38*K38+L38+M38+N38 -> 23.5 | J38: =Q38*$Q$1 -> 3.5 | K38: =R38 -> 0 | L38: =S38*$S$1 -> 20 | M38: =T38*$T$1 -> 0 | N38: =U38*$U$1 -> 0 | O38: =E38*I38 -> 1305.425 | P38: =Q38*(1+R38)+S38+T38+U38 -> 23.5 | Q38: =$Q$20 -> 3.5 | R38: =$R$20 -> 0 | S38: =$S$20 -> 20 | T38: =$T$20 -> 0 | U38: =$U$20 -> 0
A39: 7 | B39: 天棚乳胶漆 | C39: 1、面层：PT-01无机白色涂料一底二面 | D39: ㎡ | E39: =$E$36 -> 55.55 | F39: =I39 -> 13 | G39: =F39*E39 -> 722.15 | I39: =J39+J39*K39+L39+M39+N39 -> 13 | J39: =Q39*$Q$1 -> 3 | K39: =R39 -> 0 | L39: =S39*$S$1 -> 10 | M39: =T39*$T$1 -> 0 | N39: =U39*$U$1 -> 0 | O39: =E39*I39 -> 722.15 | P39: =Q39*(1+R39)+S39+T39+U39 -> 13 | Q39: =$Q$21 -> 3 | R39: =$R$21 -> 0 | S39: =$S$21 -> 10 | T39: =$T$21 -> 0 | U39: =$U$21 -> 0
A40: 8 | B40: 窗帘盒 | C40: 1、基层：钢结构龙骨+阻燃板基层 2、面层：9.5mm厚石膏板 | D40: m | E40: 7.08 | F40: =I40 -> 195.17 | G40: =F40*E40 -> 1381.8036 | I40: =J40+J40*K40+L40+M40+N40 -> 195.17 | J40: =Q40*$Q$1 -> 131.67 | K40: =R40 -> 0 | L40: =S40*$S$1 -> 55 | M40: =T40*$T$1 -> 8.5 | N40: =U40*$U$1 -> 0 | O40: =E40*I40 -> 1381.8036 | P40: =Q40*(1+R40)+S40+T40+U40 -> 195.17 | Q40: =$Q$22 -> 131.67 | R40: =$R$22 -> 0 | S40: =$S$22 -> 55 | T40: =$T$22 -> 8.5 | U40: =$U$22 -> 0
...

Sheet 报价汇总-空调消防
B1: D座塔楼办公室3903-04-05-06装饰工程汇总 空调消防
A2: 序号 | B2: 名称 | C2: 金额（元） | D2: 面积（㎡） | E2: 单方价格（元/㎡） | F2: 备注 | G2: 成本
A3: 一 | B3: =空调消防清单!B3 -> 空调工程 | C3: =空调消防清单!G3 -> 319500 | G3: =6000*42 -> 252000 | H3: =(C3-G3)/G3 -> 0.26785714
A4: （一） | B4: 办公室一空调工程 | C4: =空调消防清单!G4 -> 45500
A5: （二） | B5: 办公室二空调工程 | C5: =空调消防清单!G7 -> 38000
A6: （三） | B6: 办公室三空调工程 | C6: =空调消防清单!G10 -> 38000
A7: （四） | B7: 办公室四空调工程 | C7: =空调消防清单!G13 -> 30500
A8: （五） | B8: 办公室五空调工程 | C8: =空调消防清单!G16 -> 30500
A9: （六） | B9: 办公室六空调工程 | C9: =空调消防清单!G19 -> 61000
A10: （七） | B10: 办公室七空调工程 | C10: =空调消防清单!G22 -> 38000
A11: （八） | B11: 办公室八空调工程 | C11: =空调消防清单!G25 -> 38000
A12: 二 | B12: =空调消防清单!B28 -> 消防改造 | C12: =空调消防清单!G28 -> 123730.3 | G12: =1404.86*30+250*170+4000 -> 88645.8 | H12: =(C12-G12)/G12 -> 0.39578299
A13: 三 | B13: 合计：一+二 | C13: =C3+C12 -> 443230.3 | G13: =SUM(G3:G12) -> 340645.8
A14: 四 | B14: 管理费 | C14: =空调消防清单!G46 -> 22161.515
A15: 五 | B15: 税金 | C15: =空调消防清单!G47 -> 13961.754
A16: 六 | B16: 合计=三+四+五 | C16: =C13+C14+C15 -> 479353.57 | D16: ='报价汇总-装修工程'!D29 -> 864.74 | E16: =C16/D16 -> 554.3326

Sheet 空调消防清单
A1: D座塔楼办公室3903-04-05-06装饰工程清单 空调消防 | I1: =G48 -> 479353.57 | Q1: 1.35 | S1: =$Q$1 -> 1.35 | T1: =$Q$1 -> 1.35 | U1: =$Q$1 -> 1.35 | V1: =(18+7+7)*170 -> 5440 | W1: =232.32*30 -> 6969.6 | X1: =V1+W1 -> 12409.6
A2: 序号 | B2: 项目名称 | C2: 项目特征 | D2: 单位 | E2: 工程量 | F2: 综合单价（不含税） | G2: 合价 | H2: 备注 | I2: 综合单价（不含税） | J2: 主材费 | K2: 主材损耗率 | L2: 人工费 | M2: 辅材费 | N2: 机械费 | O2: 合计 | P2: 成本价 | Q2: 主材费 | R2: 主材损耗率 | S2: 人工费 | T2: 辅材费 | U2: 机械费
A3: 一 | B3: 空调工程 | G3: =SUBTOTAL(9,G5:G27) -> 319500
A4: （一） | B4: 办公室一 | G4: =SUBTOTAL(9,G5:G6) -> 45500
A5: 1 | B5: 空调风机盘管1P | C5: 1、包含铝合金风口、空调管道、帆布、钢结构支架等 | D5: 台 | E5: 5 | F5: =I5 -> 7500 | G5: =F5*E5 -> 37500 | H5: 品牌：麦克维尔 | I5: 7500 | J5: =Q5*$Q$1 -> 7830 | K5: =R5 -> 0 | L5: =S5*$S$1 -> 472.5 | M5: =T5*$T$1 -> 0 | N5: =U5*$U$1 -> 0 | O5: =E5*I5 -> 37500 | P5: =Q5*(1+R5)+S5+T5+U5 -> 6150 | Q5: 5800 | S5: 350
A6: 2 | B6: 空调风机盘管2P | C6: 1、包含铝合金风口、空调管道、帆布、钢结构支架等 | D6: 台 | E6: 1 | F6: =I6 -> 8000 | G6: =F6*E6 -> 8000 | H6: 品牌：麦克维尔 | I6: 8000 | J6: =Q6*$Q$1 -> 8505 | K6: =R6 -> 0 | L6: =S6*$S$1 -> 472.5 | M6: =T6*$T$1 -> 0 | N6: =U6*$U$1 -> 0 | O6: =E6*I6 -> 8000 | P6: =Q6*(1+R6)+S6+T6+U6 -> 6650 | Q6: 6300 | S6: 350
A7: （二） | B7: 办公室二 | G7: =SUBTOTAL(9,G8:G9) -> 38000
A8: 1 | B8: 空调风机盘管1P | C8: 1、包含铝合金风口、空调管道、帆布、钢结构支架等 | D8: 台 | E8: 4 | F8: =I8 -> 7500 | G8: =F8*E8 -> 30000 | H8: 品牌：麦克维尔 | I8: =$I$5 -> 7500 | J8: =Q8*$Q$1 -> 7830 | K8: =R8 -> 0 | L8: =S8*$S$1 -> 472.5 | M8: =T8*$T$1 -> 0 | N8: =U8*$U$1 -> 0 | O8: =E8*I8 -> 30000 | P8: =Q8*(1+R8)+S8+T8+U8 -> 6150 | Q8: =$Q$5 -> 5800 | R8: =$R$5 -> 0 | S8: =$S$5 -> 350 | T8: =$T$5 -> 0 | U8: =$U$5 -> 0
A9: 2 | B9: 空调风机盘管2P | C9: 1、包含铝合金风口、空调管道、帆布、钢结构支架等 | D9: 台 | E9: 1 | F9: =I9 -> 8000 | G9: =F9*E9 -> 8000 | H9: 品牌：麦克维尔 | I9: =$I$6 -> 8000 | J9: =Q9*$Q$1 -> 8505 | K9: =R9 -> 0 | L9: =S9*$S$1 -> 472.5 | M9: =T9*$T$1 -> 0 | N9: =U9*$U$1 -> 0 | O9: =E9*I9 -> 8000 | P9: =Q9*(1+R9)+S9+T9+U9 -> 6650 | Q9: =$Q$6 -> 6300 | R9: =$R$6 -> 0 | S9: =$S$6 -> 350 | T9: =$T$6 -> 0 | U9: =$U$6 -> 0
A10: （三） | B10: 办公室三 | G10: =SUBTOTAL(9,G11:G12) -> 38000
A11: 1 | B11: 空调风机盘管1P | C11: 1、包含铝合金风口、空调管道、帆布、钢结构支架等 | D11: 台 | E11: 4 | F11: =I11 -> 7500 | G11: =F11*E11 -> 30000 | H11: 品牌：麦克维尔 | I11: =$I$5 -> 7500 | J11: =Q11*$Q$1 -> 7830 | K11: =R11 -> 0 | L11: =S11*$S$1 -> 472.5 | M11: =T11*$T$1 -> 0 | N11: =U11*$U$1 -> 0 | O11: =E11*I11 -> 30000 | P11: =Q11*(1+R11)+S11+T11+U11 -> 6150 | Q11: =$Q$5 -> 5800 | R11: =$R$5 -> 0 | S11: =$S$5 -> 350 | T11: =$T$5 -> 0 | U11: =$U$5 -> 0
A12: 2 | B12: 空调风机盘管2P | C12: 1、包含铝合金风口、空调管道、帆布、钢结构支架等 | D12: 台 | E12: 1 | F12: =I12 -> 8000 | G12: =F12*E12 -> 8000 | H12: 品牌：麦克维尔 | I12: =$I$6 -> 8000 | J12: =Q12*$Q$1 -> 8505 | K12: =R12 -> 0 | L12: =S12*$S$1 -> 472.5 | M12: =T12*$T$1 -> 0 | N12: =U12*$U$1 -> 0 | O12: =E12*I12 -> 8000 | P12: =Q12*(1+R12)+S12+T12+U12 -> 6650 | Q12: =$Q$6 -> 6300 | R12: =$R$6 -> 0 | S12: =$S$6 -> 350 | T12: =$T$6 -> 0 | U12: =$U$6 -> 0
A13: （四） | B13: 办公室四 | G13: =SUBTOTAL(9,G14:G15) -> 30500
A14: 1 | B14: 空调风机盘管1P | C14: 1、包含铝合金风口、空调管道、帆布、钢结构支架等 | D14: 台 | E14: 3 | F14: =I14 -> 7500 | G14: =F14*E14 -> 22500 | H14: 品牌：麦克维尔 | I14: =$I$5 -> 7500 | J14: =Q14*$Q$1 -> 7830 | K14: =R14 -> 0 | L14: =S14*$S$1 -> 472.5 | M14: =T14*$T$1 -> 0 | N14: =U14*$U$1 -> 0 | O14: =E14*I14 -> 22500 | P14: =Q14*(1+R14)+S14+T14+U14 -> 6150 | Q14: =$Q$5 -> 5800 | R14: =$R$5 -> 0 | S14: =$S$5 -> 350 | T14: =$T$5 -> 0 | U14: =$U$5 -> 0
A15: 2 | B15: 空调风机盘管2P | C15: 1、包含铝合金风口、空调管道、帆布、钢结构支架等 | D15: 台 | E15: 1 | F15: =I15 -> 8000 | G15: =F15*E15 -> 8000 | H15: 品牌：麦克维尔 | I15: =$I$6 -> 8000 | J15: =Q15*$Q$1 -> 8505 | K15: =R15 -> 0 | L15: =S15*$S$1 -> 472.5 | M15: =T15*$T$1 -> 0 | N15: =U15*$U$1 -> 0 | O15: =E15*I15 -> 8000 | P15: =Q15*(1+R15)+S15+T15+U15 -> 6650 | Q15: =$Q$6 -> 6300 | R15: =$R$6 -> 0 | S15: =$S$6 -> 350 | T15: =$T$6 -> 0 | U15: =$U$6 -> 0
A16: （五） | B16: 办公室五 | G16: =SUBTOTAL(9,G17:G18) -> 30500
A17: 1 | B17: 空调风机盘管1P | C17: 1、包含铝合金风口、空调管道、帆布、钢结构支架等 | D17: 台 | E17: 3 | F17: =I17 -> 7500 | G17: =F17*E17 -> 22500 | H17: 品牌：麦克维尔 | I17: =$I$5 -> 7500 | J17: =Q17*$Q$1 -> 7830 | K17: =R17 -> 0 | L17: =S17*$S$1 -> 472.5 | M17: =T17*$T$1 -> 0 | N17: =U17*$U$1 -> 0 | O17: =E17*I17 -> 22500 | P17: =Q17*(1+R17)+S17+T17+U17 -> 6150 | Q17: =$Q$5 -> 5800 | R17: =$R$5 -> 0 | S17: =$S$5 -> 350 | T17: =$T$5 -> 0 | U17: =$U$5 -> 0
A18: 2 | B18: 空调风机盘管2P | C18: 1、包含铝合金风口、空调管道、帆布、钢结构支架等 | D18: 台 | E18: 1 | F18: =I18 -> 8000 | G18: =F18*E18 -> 8000 | H18: 品牌：麦克维尔 | I18: =$I$6 -> 8000 | J18: =Q18*$Q$1 -> 8505 | K18: =R18 -> 0 | L18: =S18*$S$1 -> 472.5 | M18: =T18*$T$1 -> 0 | N18: =U18*$U$1 -> 0 | O18: =E18*I18 -> 8000 | P18: =Q18*(1+R18)+S18+T18+U18 -> 6650 | Q18: =$Q$6 -> 6300 | R18: =$R$6 -> 0 | S18: =$S$6 -> 350 | T18: =$T$6 -> 0 | U18: =$U$6 -> 0
A19: （六） | B19: 办公室六 | G19: =SUBTOTAL(9,G20:G21) -> 61000
A20: 1 | B20: 空调风机盘管1P | C20: 1、包含铝合金风口、空调管道、帆布、钢结构支架等 | D20: 台 | E20: 6 | F20: =I20 -> 7500 | G20: =F20*E20 -> 45000 | H20: 品牌：麦克维尔 | I20: =$I$5 -> 7500 | J20: =Q20*$Q$1 -> 7830 | K20: =R20 -> 0 | L20: =S20*$S$1 -> 472.5 | M20: =T20*$T$1 -> 0 | N20: =U20*$U$1 -> 0 | O20: =E20*I20 -> 45000 | P20: =Q20*(1+R20)+S20+T20+U20 -> 6150 | Q20: =$Q$5 -> 5800 | R20: =$R$5 -> 0 | S20: =$S$5 -> 350 | T20: =$T$5 -> 0 | U20: =$U$5 -> 0
A21: 2 | B21: 空调风机盘管2P | C21: 1、包含铝合金风口、空调管道、帆布、钢结构支架等 | D21: 台 | E21: 2 | F21: =I21 -> 8000 | G21: =F21*E21 -> 16000 | H21: 品牌：麦克维尔 | I21: =$I$6 -> 8000 | J21: =Q21*$Q$1 -> 8505 | K21: =R21 -> 0 | L21: =S21*$S$1 -> 472.5 | M21: =T21*$T$1 -> 0 | N21: =U21*$U$1 -> 0 | O21: =E21*I21 -> 16000 | P21: =Q21*(1+R21)+S21+T21+U21 -> 6650 | Q21: =$Q$6 -> 6300 | R21: =$R$6 -> 0 | S21: =$S$6 -> 350 | T21: =$T$6 -> 0 | U21: =$U$6 -> 0
A22: （七） | B22: 办公室七 | G22: =SUBTOTAL(9,G23:G24) -> 38000
A23: 1 | B23: 空调风机盘管1P | C23: 1、包含铝合金风口、空调管道、帆布、钢结构支架等 | D23: 台 | E23: 4 | F23: =I23 -> 7500 | G23: =F23*E23 -> 30000 | H23: 品牌：麦克维尔 | I23: =$I$5 -> 7500 | J23: =Q23*$Q$1 -> 7830 | K23: =R23 -> 0 | L23: =S23*$S$1 -> 472.5 | M23: =T23*$T$1 -> 0 | N23: =U23*$U$1 -> 0 | O23: =E23*I23 -> 30000 | P23: =Q23*(1+R23)+S23+T23+U23 -> 6150 | Q23: =$Q$5 -> 5800 | R23: =$R$5 -> 0 | S23: =$S$5 -> 350 | T23: =$T$5 -> 0 | U23: =$U$5 -> 0
A24: 2 | B24: 空调风机盘管2P | C24: 1、包含铝合金风口、空调管道、帆布、钢结构支架等 | D24: 台 | E24: 1 | F24: =I24 -> 8000 | G24: =F24*E24 -> 8000 | H24: 品牌：麦克维尔 | I24: =$I$6 -> 8000 | J24: =Q24*$Q$1 -> 8505 | K24: =R24 -> 0 | L24: =S24*$S$1 -> 472.5 | M24: =T24*$T$1 -> 0 | N24: =U24*$U$1 -> 0 | O24: =E24*I24 -> 8000 | P24: =Q24*(1+R24)+S24+T24+U24 -> 6650 | Q24: =$Q$6 -> 6300 | R24: =$R$6 -> 0 | S24: =$S$6 -> 350 | T24: =$T$6 -> 0 | U24: =$U$6 -> 0
A25: （八） | B25: 办公室八 | G25: =SUBTOTAL(9,G26:G27) -> 38000
A26: 1 | B26: 空调风机盘管1P | C26: 1、包含铝合金风口、空调管道、帆布、钢结构支架等 | D26: 台 | E26: 4 | F26: =I26 -> 7500 | G26: =F26*E26 -> 30000 | H26: 品牌：麦克维尔 | I26: =$I$5 -> 7500 | J26: =Q26*$Q$1 -> 7830 | K26: =R26 -> 0 | L26: =S26*$S$1 -> 472.5 | M26: =T26*$T$1 -> 0 | N26: =U26*$U$1 -> 0 | O26: =E26*I26 -> 30000 | P26: =Q26*(1+R26)+S26+T26+U26 -> 6150 | Q26: =$Q$5 -> 5800 | R26: =$R$5 -> 0 | S26: =$S$5 -> 350 | T26: =$T$5 -> 0 | U26: =$U$5 -> 0
A27: 2 | B27: 空调风机盘管2P | C27: 1、包含铝合金风口、空调管道、帆布、钢结构支架等 | D27: 台 | E27: 1 | F27: =I27 -> 8000 | G27: =F27*E27 -> 8000 | H27: 品牌：麦克维尔 | I27: =$I$6 -> 8000 | J27: =Q27*$Q$1 -> 8505 | K27: =R27 -> 0 | L27: =S27*$S$1 -> 472.5 | M27: =T27*$T$1 -> 0 | N27: =U27*$U$1 -> 0 | O27: =E27*I27 -> 8000 | P27: =Q27*(1+R27)+S27+T27+U27 -> 6650 | Q27: =$Q$6 -> 6300 | R27: =$R$6 -> 0 | S27: =$S$6 -> 350 | T27: =$T$6 -> 0 | U27: =$U$6 -> 0
A28: 二 | B28: 消防改造 | G28: =SUBTOTAL(9,G30:G44) -> 123730.3
A29: （一） | B29: 火灾自动报警系统
A30: 1 | B30: 探测器拆除、安装 | C30: 1、含配合装修 2、含布管布线及其他辅材 | D30: 套 | E30: =18 -> 18 | F30: =I30 -> 191.4 | G30: =F30*E30 -> 3445.2 | H30: 按实结算 | I30: 191.4 | J30: =Q30*$Q$1 -> 258.39 | K30: =R30 -> 0 | L30: =S30*$S$1 -> 0 | M30: =T30*$T$1 -> 0 | N30: =U30*$U$1 -> 0 | O30: =E30*I30 -> 3445.2 | P30: =Q30*(1+R30)+S30+T30+U30 -> 191.4 | Q30: 191.4
A31: 2 | B31: 探测器新增、安装 | C31: 1、含设备增加及配合装修 2、含布管布线及其他辅材 | D31: 套 | E31: =7+7+6+5+5+10+6+6 -> 52 | F31: =I31 -> 261 | G31: =F31*E31 -> 13572 | H31: 按实结算 | I31: 261 | J31: =Q31*$Q$1 -> 352.35 | K31: =R31 -> 0 | L31: =S31*$S$1 -> 0 | M31: =T31*$T$1 -> 0 | N31: =U31*$U$1 -> 0 | O31: =E31*I31 -> 13572 | P31: =Q31*(1+R31)+S31+T31+U31 -> 261 | Q31: 261
A32: 3 | B32: 消防广播拆除、安装 | C32: 1、含配合装修 2、含布管布线及其他辅材 | D32: 套 | E32: 4 | F32: =I32 -> 191.4 | G32: =F32*E32 -> 765.6 | H32: 按实结算 | I32: 191.4 | J32: =Q32*$Q$1 -> 258.39 | K32: =R32 -> 0 | L32: =S32*$S$1 -> 0 | M32: =T32*$T$1 -> 0 | N32: =U32*$U$1 -> 0 | O32: =E32*I32 -> 765.6 | P32: =Q32*(1+R32)+S32+T32+U32 -> 191.4 | Q32: 191.4
A33: 4 | B33: 消防广播新增、安装 | C33: 1、含设备增加及配合装修 2、含布管布线及其他辅材 | D33: 套 | E33: 8 | F33: =I33 -> 261 | G33: =F33*E33 -> 2088 | H33: 按实结算 | I33: 261 | J33: =Q33*$Q$1 -> 352.35 | K33: =R33 -> 0 | L33: =S33*$S$1 -> 0 | M33: =T33*$T$1 -> 0 | N33: =U33*$U$1 -> 0 | O33: =E33*I33 -> 2088 | P33: =Q33*(1+R33)+S33+T33+U33 -> 261 | Q33: 261
A34: 5 | B34: 应急照明拆除、安装 | C34: 1、含配合装修 2、含布管布线及其他辅材 | D34: 套 | E34: 8 | F34: =I34 -> 191.4 | G34: =F34*E34 -> 1531.2 | H34: 按实结算 | I34: 191.4 | J34: =Q34*$Q$1 -> 258.39 | K34: =R34 -> 0 | L34: =S34*$S$1 -> 0 | M34: =T34*$T$1 -> 0 | N34: =U34*$U$1 -> 0 | O34: =E34*I34 -> 1531.2 | P34: =Q34*(1+R34)+S34+T34+U34 -> 191.4 | Q34: 191.4
A35: 6 | B35: 应急照明新增、安装 | C35: 1、含设备增加及配合装修 2、含布管布线及其他辅材 | D35: 套 | E35: 26 | F35: =I35 -> 261 | G35: =F35*E35 -> 6786 | H35: 按实结算 | I35: 261 | J35: =Q35*$Q$1 -> 352.35 | K35: =R35 -> 0 | L35: =S35*$S$1 -> 0 | M35: =T35*$T$1 -> 0 | N35: =U35*$U$1 -> 0 | O35: =E35*I35 -> 6786 | P35: =Q35*(1+R35)+S35+T35+U35 -> 261 | Q35: 261
A36: 7 | B36: 编程入网、系统接驳 | C36: 1、由大厦原消防施工单位负责，物业统一收费 | D36: ㎡ | E36: =244.34+336.33+258.32+565.87 -> 1404.86 | F36: =I36 -> 30 | G36: =F36*E36 -> 42145.8 | H36: 1、不足4000元的按最低4000元计算。超过4000元的按建筑面积30元/㎡计算。 | I36: 30 | J36: =Q36*$Q$1 -> 0 | K36: =R36 -> 0 | L36: =S36*$S$1 -> 27 | M36: =T36*$T$1 -> 0 | N36: =U36*$U$1 -> 0 | O36: =E36*I36 -> 42145.8 | P36: =Q36*(1+R36)+S36+T36+U36 -> 20 | S36: 20
A37: （二） | B37: 自动喷淋灭火系统
A38: 1 | B38: 喷头拆除、安装 | C38: 1、含配合装修 2、含消防管道、管件及其他辅材 | D38: 个 | E38: =7+5+4+3+3+11+4+4 -> 41 | F38: =I38 -> 174 | G38: =F38*E38 -> 7134 | H38: 按实结算 | I38: 174 | J38: =Q38*$Q$1 -> 234.9 | K38: =R38 -> 0 | L38: =S38*$S$1 -> 0 | M38: =T38*$T$1 -> 0 | N38: =U38*$U$1 -> 0 | O38: =E38*I38 -> 7134 | P38: =Q38*(1+R38)+S38+T38+U38 -> 174 | Q38: 174
A39: 2 | B39: 喷头新增、安装 | C39: 1、含设备增加及配合装修 2、含消防管道、管件及其他辅材 | D39: 个 | E39: =15+11+9+8+8+24+9+9 -> 93 | F39: =I39 -> 217.5 | G39: =F39*E39 -> 20227.5 | H39: 按实结算 | I39: 217.5 | J39: =Q39*$Q$1 -> 293.625 | K39: =R39 -> 0 | L39: =S39*$S$1 -> 0 | M39: =T39*$T$1 -> 0 | N39: =U39*$U$1 -> 0 | O39: =E39*I39 -> 20227.5 | P39: =Q39*(1+R39)+S39+T39+U39 -> 217.5 | Q39: 217.5
A40: 3 | B40: 喷淋管网排水费 | C40: 1、含管网排水费 及人工 | D40: 项 | E40: 1 | F40: =I40 -> 800 | G40: =F40*E40 -> 800 | I40: 800 | J40: =Q40*$Q$1 -> 0 | K40: =R40 -> 0 | L40: =S40*$S$1 -> 0 | M40: =T40*$T$1 -> 0 | N40: =U40*$U$1 -> 0 | O40: =E40*I40 -> 800 | P40: =Q40*(1+R40)+S40+T40+U40 -> 0
...

Sheet 材料设备参考品牌
A1: 材料设备参考品牌
A2: 序号 | B2: 专业 | C2: 材料名称 | D2: 品牌 | E2: 备注
A3: 1 | B3: 装饰 | C3: 地砖 | D3: 东鹏、马可罗兰
A4: 2 | B4: 装饰 | C4: 墙砖 | D4: 东鹏、马可罗兰
A5: 3 | B5: 装饰 | C5: 方块地毯 | D5: 国产
A6: 4 | B6: 装饰 | C6: 500*500mm架空地板 | D6: 深圳沈飞
A7: 5 | B7: 装饰 | C7: 石膏板 | D7: 泰山、深耐福
A8: 6 | B8: 装饰 | C8: 乳胶漆 | D8: 立邦
A9: 7 | B9: 装饰 | C9: 腻子 | D9: 立邦
A10: 8 | B10: 安装 | C10: 照明，强电用线 | D10: 南洋、成天泰
A11: 9 | B11: 安装 | C11: 筒灯 | D11: 佛山照明
A12: 10 | B12: 安装 | C12: LED灯带 | D12: 佛山照明
A13: 11 | B13: 安装 | C13: 照明开关 | D13: 公牛
A14: 12 | B14: 安装 | C14: 插座 | D14: 公牛
... A17: 15 | B17: 空调 | C17: 空调风机盘管 | D17: 麦克维尔
