Workbook

Sheet 1207报价汇总
B1: 岁宝壹品苑D栋1207办公室装修汇总
A2: 序号 | B2: 名称 | C2: 金额（元） | D2: 面积（㎡） | E2: 单方价格（元/㎡） | F2: 备注
A3: 一 | B3: 装饰工程 | C3: ='[1]1207清单'!G3 -> 51372.001 | G3: 装饰成本 | H3: 58828.343
A4: 二 | B4: 安装工程 | C4: ='[1]1207清单'!G32 -> 18591.239 | G4: 空调成本 | H4: =6000*3 -> 18000
A5: 三 | B5: 其他工程 | C5: ='[1]1207清单'!G41 -> 9903 | G5: 消防成本 | H5: =12*170+4000+3000 -> 9040
A6: 四 | B6: 装饰工程小计：一+二+三 | C6: =SUM(C3:C5) -> 79866.24 | D6: 66.62 | E6: =C6/D6 -> 1198.8328
A7: 五 | B7: 空调消防工程 | C7: ='[1]1207空调消防清单'!G36 -> 32688.58 | G7: 成本合计 | H7: =SUM(H3:H5) -> 85868.343
A8: 六 | B8: 小计：四+五 | C8: =C6+C7 -> 112554.82 | D8: 66.62 | E8: =C8/D8 -> 1689.505 | H8: =C8+C9 -> 118182.56
A9: 七 | B9: 管理费 | C9: ='[1]1207清单'!G50+'[1]1207空调消防清单'!G37 -> 5627.741 | H9: =(H8-H7)/H7 -> 0.37632284
A10: 八 | B10: 税金 | C10: ='[1]1207清单'!G51+'[1]1207空调消防清单'!G38 -> 0
A11: 九 | B11: 含税合计=六+七+八 | C11: =C8+C9+C10 -> 118182.56 | D11: 66.62 | E11: =C11/D11 -> 1773.9802

Sheet 1207清单
A1: 岁宝壹品苑D座塔楼1207办公室装修清单 | R1: =R52 -> 61769.76 | T1: 1 | V1: =$T$1 -> 1 | W1: =$T$1 -> 1 | X1: =$T$1 -> 1 | Y1: =Y52 -> 61769.76
A2: 序号 | B2: 项目名称 | C2: 项目特征 | D2: 单位 | E2: 工程量 | F2: 综合单价（不含税） | G2: 合价 | H2: 备注 | I2: 综合单价（不含税） | J2: 主材费 | K2: 主材损耗率 | L2: 人工费 | M2: 辅材费 | N2: 机械费 | O2: 管理费 | P2: 利润 | Q2: 税金 | R2: 合计 | S2: 成本价 | T2: 主材费 | U2: 主材损耗率 | V2: 人工费 | W2: 辅材费 | X2: 机械费 | Y2: 成本合计
A3: 一 | B3: 装饰工程 | G3: =SUBTOTAL(9,G5:G31) -> 35924.476
A4: (一) | B4: 地面工程 | J4: =T4*$T$1 -> 0 | K4: =U4 -> 0 | L4: =V4*$V$1 -> 0 | M4: =W4*$W$1 -> 0 | N4: =X4*$X$1 -> 0
A5: 1 | B5: 地面架空层 | C5: 1、100mm高 2、500*500mm架空地板 | D5: ㎡ | E5: 65.66 | F5: =I5 -> 126.25 | G5: =F5*E5 -> 8289.575 | I5: =J5+J5*K5+L5+M5+N5+O5+P5+Q5 -> 126.25 | J5: =T5*$T$1 -> 125 | K5: =U5 -> 0.01 | L5: =V5*$V$1 -> 0 | M5: =W5*$W$1 -> 0 | N5: =X5*$X$1 -> 0 | O5: =(J5+J5*K5+L5+M5+N5)*$O$1 -> 0 | P5: =(J5+J5*K5+L5+M5+N5+O5)*$P$1 -> 0 | Q5: =(J5+J5*K5+L5+M5+N5+O5+P5)*$Q$1 -> 0 | R5: =E5*I5 -> 8289.575 | S5: =T5+T5*U5+V5+W5+X5 -> 126.25 | T5: 125 | U5: 0.01 | V5: 0 | W5: 0 | X5: 0 | Y5: =S5*E5 -> 8289.575
A6: 2 | B6: 地面地毯 | C6: 1、规格尺寸：500*500 2、地毯专用胶，厚度包干，后期不因厚度调整价格； | D6: ㎡ | E6: =42.68+0.1*2+0.3+9.27+12.69 -> 65.14 | F6: =I6 -> 71.5 | G6: =F6*E6 -> 4657.51 | I6: =J6+J6*K6+L6+M6+N6+O6+P6+Q6 -> 71.5 | J6: =T6*$T$1 -> 60 | K6: =U6 -> 0.025 | L6: =V6*$V$1 -> 5 | M6: =W6*$W$1 -> 5 | N6: =X6*$X$1 -> 0 | O6: =(J6+J6*K6+L6+M6+N6)*$O$1 -> 0 | P6: =(J6+J6*K6+L6+M6+N6+O6)*$P$1 -> 0 | Q6: =(J6+J6*K6+L6+M6+N6+O6+P6)*$Q$1 -> 0 | R6: =E6*I6 -> 4657.51 | S6: =T6+T6*U6+V6+W6+X6 -> 71.5 | T6: 60 | U6: 0.025 | V6: 5 | W6: 5 | X6: 0 | Y6: =S6*E6 -> 4657.51
A7: (二) | B7: 天花工程
A8: 1 | B8: 原天棚喷深色乳胶漆 (含墙体上部) | C8: 1、面层：深色涂料两遍 2、包含各种管道 | D8: ㎡ | E8: =65.66+(41.58-8.67+6.1+6.34*2+3.27*2)*1.31 -> 141.9413 | F8: =I8 -> 20.16 | G8: =F8*E8 -> 2861.5366 | I8: =J8+J8*K8+L8+M8+N8+O8+P8+Q8 -> 20.16 | J8: =T8*$T$1 -> 8 | K8: =U8 -> 0.02 | L8: =V8*$V$1 -> 10 | M8: =W8*$W$1 -> 0.5 | N8: =X8*$X$1 -> 1.5 | O8: =(J8+J8*K8+L8+M8+N8)*$O$1 -> 0 | P8: =(J8+J8*K8+L8+M8+N8+O8)*$P$1 -> 0 | Q8: =(J8+J8*K8+L8+M8+N8+O8+P8)*$Q$1 -> 0 | R8: =E8*I8 -> 2861.5366 | S8: =T8+T8*U8+V8+W8+X8 -> 20.16 | T8: 8 | U8: 0.02 | V8: 10 | W8: 0.5 | X8: 1.5 | Y8: =S8*E8 -> 2861.5366
A9: (三) | B9: 墙面工程 | J9: =T9*$T$1 -> 0 | K9: =U9 -> 0 | L9: =V9*$V$1 -> 0 | M9: =W9*$W$1 -> 0 | N9: =X9*$X$1 -> 0
A10: 1 | B10: 轻钢龙骨隔墙 | C10: 双层双面轻钢龙骨隔墙 1、墙厚120mm; 2、75mm轻钢龙骨； 3、50mm厚，48kg/m3的吸音棉； 4、12mm阻燃夹板+9.5mm厚石膏板 | D10: ㎡ | E10: =3.27*3.81 -> 12.4587 | I10: =J10+J10*K10+L10+M10+N10+O10+P10+Q10 -> 0 | J10: =T10*$T$1 -> 0 | K10: =U10 -> 0 | L10: =V10*$V$1 -> 0 | M10: =W10*$W$1 -> 0 | N10: =X10*$X$1 -> 0 | O10: =(J10+J10*K10+L10+M10+N10)*$O$1 -> 0 | P10: =(J10+J10*K10+L10+M10+N10+O10)*$P$1 -> 0 | Q10: =(J10+J10*K10+L10+M10+N10+O10+P10)*$Q$1 -> 0 | R10: =E10*I10 -> 0 | S10: =T10+T10*U10+V10+W10+X10 -> 0 | Y10: =S10*E10 -> 0
A11: 1.1 | B11: 轻钢龙骨 | C11: 1、天地龙骨 2、竖龙骨 3、穿心龙骨 4、其他辅材 | D11: ㎡ | E11: =E10 -> 12.4587 | F11: =I11 -> 53.5 | G11: =F11*E11 -> 666.54045 | I11: =J11+J11*K11+L11+M11+N11+O11+P11+Q11 -> 53.5 | J11: =T11*$T$1 -> 26 | K11: =U11 -> 0 | L11: =V11*$V$1 -> 26 | M11: =W11*$W$1 -> 0 | N11: =X11*$X$1 -> 1.5 | O11: =(J11+J11*K11+L11+M11+N11)*$O$1 -> 0 | P11: =(J11+J11*K11+L11+M11+N11+O11)*$P$1 -> 0 | Q11: =(J11+J11*K11+L11+M11+N11+O11+P11)*$Q$1 -> 0 | R11: =E11*I11 -> 666.54045 | S11: =T11+T11*U11+V11+W11+X11 -> 53.5 | T11: 26 | V11: 26 | X11: 1.5 | Y11: =S11*E11 -> 666.54045
A12: 1.2 | B12: 50mm厚吸音棉 | C12: 1、50mm厚，48kg/m3的吸音棉 | D12: ㎡ | E12: =E10 -> 12.4587 | F12: =I12 -> 21.65 | G12: =F12*E12 -> 269.73086 | I12: =J12+J12*K12+L12+M12+N12+O12+P12+Q12 -> 21.65 | J12: =T12*$T$1 -> 11.65 | K12: =U12 -> 0 | L12: =V12*$V$1 -> 10 | M12: =W12*$W$1 -> 0 | N12: =X12*$X$1 -> 0 | O12: =(J12+J12*K12+L12+M12+N12)*$O$1 -> 0 | P12: =(J12+J12*K12+L12+M12+N12+O12)*$P$1 -> 0 | Q12: =(J12+J12*K12+L12+M12+N12+O12+P12)*$Q$1 -> 0 | R12: =E12*I12 -> 269.73086 | S12: =T12+T12*U12+V12+W12+X12 -> 21.65 | T12: 11.65 | V12: 10 | Y12: =S12*E12 -> 269.73086
A13: 1.3 | B13: 12mm阻燃夹板 | C13: 1、单层12mm阻燃夹板打底 | D13: ㎡ | E13: =E10*2 -> 24.9174 | F13: =I13 -> 48.8 | G13: =F13*E13 -> 1215.9691 | I13: =J13+J13*K13+L13+M13+N13+O13+P13+Q13 -> 48.8 | J13: =T13*$T$1 -> 28 | K13: =U13 -> 0 | L13: =V13*$V$1 -> 20 | M13: =W13*$W$1 -> 0.8 | N13: =X13*$X$1 -> 0 | O13: =(J13+J13*K13+L13+M13+N13)*$O$1 -> 0 | P13: =(J13+J13*K13+L13+M13+N13+O13)*$P$1 -> 0 | Q13: =(J13+J13*K13+L13+M13+N13+O13+P13)*$Q$1 -> 0 | R13: =E13*I13 -> 1215.9691 | S13: =T13+T13*U13+V13+W13+X13 -> 48.8 | T13: 28 | V13: 20 | W13: 0.8 | Y13: =S13*E13 -> 1215.9691
A14: 1.4 | B14: 9.5mm厚石膏板 | C14: 1、双面单层9.5mm厚石膏板 | D14: ㎡ | E14: =E10*2 -> 24.9174 | F14: =I14 -> 28.3 | G14: =F14*E14 -> 705.16242 | I14: =J14+J14*K14+L14+M14+N14+O14+P14+Q14 -> 28.3 | J14: =T14*$T$1 -> 7.5 | K14: =U14 -> 0 | L14: =V14*$V$1 -> 20 | M14: =W14*$W$1 -> 0.8 | N14: =X14*$X$1 -> 0 | O14: =(J14+J14*K14+L14+M14+N14)*$O$1 -> 0 | P14: =(J14+J14*K14+L14+M14+N14+O14)*$P$1 -> 0 | Q14: =(J14+J14*K14+L14+M14+N14+O14+P14)*$Q$1 -> 0 | R14: =E14*I14 -> 705.16242 | S14: =T14+T14*U14+V14+W14+X14 -> 28.3 | T14: 7.5 | V14: 20 | W14: 0.8 | Y14: =S14*E14 -> 705.16242
A15: 2 | B15: 钢化玻璃隔断上方封板 | C15: 双层双面钢结构龙骨隔墙 1、墙厚120mm; 2、钢结构龙骨； 3、50mm厚，48kg/m3的吸音棉； 4、12mm厚阻燃夹板+9.5mm厚石膏板 | D15: ㎡ | E15: =6.35*1.31 -> 8.3185 | I15: =J15+J15*K15+L15+M15+N15+O15+P15+Q15 -> 0 | J15: =T15*$T$1 -> 0 | K15: =U15 -> 0 | L15: =V15*$V$1 -> 0 | M15: =W15*$W$1 -> 0 | N15: =X15*$X$1 -> 0 | O15: =(J15+J15*K15+L15+M15+N15)*$O$1 -> 0 | P15: =(J15+J15*K15+L15+M15+N15+O15)*$P$1 -> 0 | Q15: =(J15+J15*K15+L15+M15+N15+O15+P15)*$Q$1 -> 0 | R15: =E15*I15 -> 0 | S15: =T15+T15*U15+V15+W15+X15 -> 0 | Y15: =S15*E15 -> 0
A16: 2.1 | B16: 钢结构龙骨 | C16: 1、钢结构龙骨 2、刷防锈漆 3、其他辅材 | D16: ㎡ | E16: =E15 -> 8.3185 | F16: =I16 -> 53.5 | G16: =F16*E16 -> 445.03975 | I16: =J16+J16*K16+L16+M16+N16+O16+P16+Q16 -> 53.5 | J16: =T16*$T$1 -> 26 | K16: =U16 -> 0 | L16: =V16*$V$1 -> 26 | M16: =W16*$W$1 -> 0 | N16: =X16*$X$1 -> 1.5 | O16: =(J16+J16*K16+L16+M16+N16)*$O$1 -> 0 | P16: =(J16+J16*K16+L16+M16+N16+O16)*$P$1 -> 0 | Q16: =(J16+J16*K16+L16+M16+N16+O16+P16)*$Q$1 -> 0 | R16: =E16*I16 -> 445.03975 | S16: =T16+T16*U16+V16+W16+X16 -> 53.5 | T16: 26 | U16: =U11 -> 0 | V16: =V11 -> 26 | W16: =W11 -> 0 | X16: =X11 -> 1.5 | Y16: =S16*E16 -> 445.03975
A17: 2.2 | B17: 50mm厚吸音棉 | C17: 1、50mm厚，48kg/m3的吸音棉 | D17: ㎡ | E17: =E15 -> 8.3185 | F17: =I17 -> 21.65 | G17: =F17*E17 -> 180.09553 | I17: =J17+J17*K17+L17+M17+N17+O17+P17+Q17 -> 21.65 | J17: =T17*$T$1 -> 11.65 | K17: =U17 -> 0 | L17: =V17*$V$1 -> 10 | M17: =W17*$W$1 -> 0 | N17: =X17*$X$1 -> 0 | O17: =(J17+J17*K17+L17+M17+N17)*$O$1 -> 0 | P17: =(J17+J17*K17+L17+M17+N17+O17)*$P$1 -> 0 | Q17: =(J17+J17*K17+L17+M17+N17+O17+P17)*$Q$1 -> 0 | R17: =E17*I17 -> 180.09553 | S17: =T17+T17*U17+V17+W17+X17 -> 21.65 | T17: 11.65 | U17: =U12 -> 0 | V17: =V12 -> 10 | W17: =W12 -> 0 | X17: =X12 -> 0 | Y17: =S17*E17 -> 180.09553
A18: 2.3 | B18: 12mm阻燃夹板 | C18: 1、单层12mm阻燃夹板打底 | D18: ㎡ | E18: =E15*2 -> 16.637 | F18: =I18 -> 48.8 | G18: =F18*E18 -> 811.8856 | I18: =J18+J18*K18+L18+M18+N18+O18+P18+Q18 -> 48.8 | J18: =T18*$T$1 -> 28 | K18: =U18 -> 0 | L18: =V18*$V$1 -> 20 | M18: =W18*$W$1 -> 0.8 | N18: =X18*$X$1 -> 0 | O18: =(J18+J18*K18+L18+M18+N18)*$O$1 -> 0 | P18: =(J18+J18*K18+L18+M18+N18+O18)*$P$1 -> 0 | Q18: =(J18+J18*K18+L18+M18+N18+O18+P18)*$Q$1 -> 0 | R18: =E18*I18 -> 811.8856 | S18: =T18+T18*U18+V18+W18+X18 -> 48.8 | T18: 28 | U18: =U13 -> 0 | V18: =V13 -> 20 | W18: =W13 -> 0.8 | X18: =X13 -> 0 | Y18: =S18*E18 -> 811.8856
A19: 2.4 | B19: 9.5mm厚石膏板 | C19: 1、双面单层9.5mm厚石膏板 | D19: ㎡ | E19: =E15*2 -> 16.637 | F19: =I19 -> 28.3 | G19: =F19*E19 -> 470.8271 | I19: =J19+J19*K19+L19+M19+N19+O19+P19+Q19 -> 28.3 | J19: =T19*$T$1 -> 7.5 | K19: =U19 -> 0 | L19: =V19*$V$1 -> 20 | M19: =W19*$W$1 -> 0.8 | N19: =X19*$X$1 -> 0 | O19: =(J19+J19*K19+L19+M19+N19)*$O$1 -> 0 | P19: =(J19+J19*K19+L19+M19+N19+O19)*$P$1 -> 0 | Q19: =(J19+J19*K19+L19+M19+N19+O19+P19)*$Q$1 -> 0 | R19: =E19*I19 -> 470.8271 | S19: =T19+T19*U19+V19+W19+X19 -> 28.3 | T19: 7.5 | U19: =U14 -> 0 | V19: =V14 -> 20 | W19: =W14 -> 0.8 | X19: =X14 -> 0 | Y19: =S19*E19 -> 470.8271
A20: 3 | B20: GL-01 10mm厚钢化玻璃隔断 | C20: 1、GL-01 10mm厚钢化玻璃; 2、玻璃胶收口 | D20: ㎡ | E20: =6.34*2.8 -> 17.752 | F20: =I20 -> 201.6 | G20: =F20*E20 -> 3578.8032 | I20: =J20+J20*K20+L20+M20+N20+O20+P20+Q20 -> 201.6 | J20: =T20*$T$1 -> 110 | K20: =U20 -> 0.01 | L20: =V20*$V$1 -> 80 | M20: =W20*$W$1 -> 10.5 | N20: =X20*$X$1 -> 0 | O20: =(J20+J20*K20+L20+M20+N20)*$O$1 -> 0 | P20: =(J20+J20*K20+L20+M20+N20+O20)*$P$1 -> 0 | Q20: =(J20+J20*K20+L20+M20+N20+O20+P20)*$Q$1 -> 0 | R20: =E20*I20 -> 3578.8032 | S20: =T20+T20*U20+V20+W20+X20 -> 201.6 | T20: 110 | U20: 0.01 | V20: 80 | W20: 10.5 | Y20: =S20*E20 -> 3578.8032
A21: 4 | B21: 铝合金包边 | C21: 1、铝合金包边 2、12mm厚阻燃夹板 | D21: ㎡ | E21: =0.15*(2.8*2+6.34) -> 1.791 | F21: =I21 -> 308.35 | G21: =F21*E21 -> 552.25485 | I21: =J21+J21*K21+L21+M21+N21+O21+P21+Q21 -> 308.35 | J21: =T21*$T$1 -> 185 | K21: =U21 -> 0.01 | L21: =V21*$V$1 -> 90 | M21: =W21*$W$1 -> 31.5 | N21: =X21*$X$1 -> 0 | O21: =(J21+J21*K21+L21+M21+N21)*$O$1 -> 0 | P21: =(J21+J21*K21+L21+M21+N21+O21)*$P$1 -> 0 | Q21: =(J21+J21*K21+L21+M21+N21+O21+P21)*$Q$1 -> 0 | R21: =E21*I21 -> 552.25485 | S21: =T21+T21*U21+V21+W21+X21 -> 308.35 | T21: 185 | U21: 0.01 | V21: 90 | W21: 31.5 | Y21: =S21*E21 -> 552.25485
A22: 5 | B22: 墙体抹灰 | C22: 1、12mm-15mm水泥砂浆压光找平； | D22: ㎡ | E22: =3.81*(11.85+0.8*2+0.61+2.68+3.71+4.03+0.51)-1.5*2.2 -> 91.9119 | F22: =I22 -> 37.24 | G22: =F22*E22 -> 3422.7992 | I22: =J22+J22*K22+L22+M22+N22+O22+P22+Q22 -> 37.24 | J22: =T22*$T$1 -> 12 | K22: =U22 -> 0.02 | L22: =V22*$V$1 -> 25 | M22: =W22*$W$1 -> 0 | N22: =X22*$X$1 -> 0 | O22: =(J22+J22*K22+L22+M22+N22)*$O$1 -> 0 | P22: =(J22+J22*K22+L22+M22+N22+O22)*$P$1 -> 0 | Q22: =(J22+J22*K22+L22+M22+N22+O22+P22)*$Q$1 -> 0 | R22: =E22*I22 -> 3422.7992 | S22: =T22+T22*U22+V22+W22+X22 -> 37.24 | T22: 12 | U22: 0.02 | V22: 25 | Y22: =S22*E22 -> 3422.7992
A23: 6 | B23: 墙面缝贴纸带刮平整 | C23: 1.贴纸带刮平整 | D23: ㎡ | E23: =3.27*3.81*2+6.34*1.31*2 -> 41.5282 | F23: =I23 -> 8.5 | G23: =F23*E23 -> 352.9897 | I23: =J23+J23*K23+L23+M23+N23+O23+P23+Q23 -> 8.5 | J23: =T23*$T$1 -> 3.5 | K23: =U23 -> 0 | L23: =V23*$V$1 -> 5 | M23: =W23*$W$1 -> 0 | N23: =X23*$X$1 -> 0 | O23: =(J23+J23*K23+L23+M23+N23)*$O$1 -> 0 | P23: =(J23+J23*K23+L23+M23+N23+O23)*$P$1 -> 0 | Q23: =(J23+J23*K23+L23+M23+N23+O23+P23)*$Q$1 -> 0 | R23: =E23*I23 -> 352.9897 | S23: =T23+T23*U23+V23+W23+X23 -> 8.5 | T23: 3.5 | U23: 0 | V23: 5 | W23: 0 | X23: 0 | Y23: =S23*E23 -> 352.9897
A24: 7 | B24: 墙面挂耐水腻子 | C24: 1、耐水腻子2道，含打磨、修补 | D24: ㎡ | E24: =3.81*(11.85+0.8*2+0.61+2.68+3.71+4.03+0.51)-1.5*2.2+3.27*3.81*2+1.31*6.34*2 -> 133.4401 | F24: =I24 -> 23.5 | G24: =F24*E24 -> 3135.8423 | I24: =J24+J24*K24+L24+M24+N24+O24+P24+Q24 -> 23.5 | J24: =T24*$T$1 -> 3.5 | K24: =U24 -> 0 | L24: =V24*$V$1 -> 20 | M24: =W24*$W$1 -> 0 | N24: =X24*$X$1 -> 0 | O24: =(J24+J24*K24+L24+M24+N24)*$O$1 -> 0 | P24: =(J24+J24*K24+L24+M24+N24+O24)*$P$1 -> 0 | Q24: =(J24+J24*K24+L24+M24+N24+O24+P24)*$Q$1 -> 0 | R24: =E24*I24 -> 3135.8423 | S24: =T24+T24*U24+V24+W24+X24 -> 23.5 | T24: 3.5 | U24: 0 | V24: 20 | W24: 0 | X24: 0 | Y24: =S24*E24 -> 3135.8423
A25: 8 | B25: 墙面乳胶漆PT-01 | C25: 1、面层：PT-01无机白色涂料一底二面 | D25: ㎡ | E25: =2.8*(11.85+0.8*2+0.61+2.68+3.71+4.03+0.51)-1.5*2.2+3.27*2.8*2 -> 84.984 | F25: =I25 -> 13 | G25: =F25*E25 -> 1104.792 | I25: =J25+J25*K25+L25+M25+N25+O25+P25+Q25 -> 13 | J25: =T25*$T$1 -> 3 | K25: =U25 -> 0 | L25: =V25*$V$1 -> 10 | M25: =W25*$W$1 -> 0 | N25: =X25*$X$1 -> 0 | O25: =(J25+J25*K25+L25+M25+N25)*$O$1 -> 0 | P25: =(J25+J25*K25+L25+M25+N25+O25)*$P$1 -> 0 | Q25: =(J25+J25*K25+L25+M25+N25+O25+P25)*$Q$1 -> 0 | R25: =E25*I25 -> 1104.792 | S25: =T25+T25*U25+V25+W25+X25 -> 13 | T25: 3 | U25: 0 | V25: 10 | W25: 0 | X25: 0 | Y25: =S25*E25 -> 1104.792
A26: 9 | B26: 铝合金踢脚线 | C26: 1、规格尺寸：50mm高 2、面层：铝合金不锈钢 3、基层：轻钢龙骨+12mm厚阻燃夹板 | D26: m | E26: =11.85+0.8*2+0.61+2.68+3.71+4.03+0.51-1.5+3.27*2 -> 30.03 | F26: =I26 -> 30.74 | G26: =F26*E26 -> 923.1222 | I26: =J26+J26*K26+L26+M26+N26+O26+P26+Q26 -> 30.74 | J26: =T26*$T$1 -> 12 | K26: =U26 -> 0.02 | L26: =V26*$V$1 -> 15 | M26: =W26*$W$1 -> 3.5 | N26: =X26*$X$1 -> 0 | O26: =(J26+J26*K26+L26+M26+N26)*$O$1 -> 0 | P26: =(J26+J26*K26+L26+M26+N26+O26)*$P$1 -> 0 | Q26: =(J26+J26*K26+L26+M26+N26+O26+P26)*$Q$1 -> 0 | R26: =E26*I26 -> 923.1222 | S26: =T26+T26*U26+V26+W26+X26 -> 30.74 | T26: 12 | U26: 0.02 | V26: 15 | W26: 3.5 | X26: 0 | Y26: =S26*E26 -> 923.1222
A27: 10 | B27: 窗户自动开关器 | C27: 1、窗户自动开关器 | D27: 套 | E27: 0 | F27: =I27 -> 800 | G27: =F27*E27 -> 0 | I27: =J27+J27*K27+L27+M27+N27+O27+P27+Q27 -> 800 | J27: =T27*$T$1 -> 800 | K27: =U27 -> 0 | L27: =V27*$V$1 -> 0 | M27: =W27*$W$1 -> 0 | N27: =X27*$X$1 -> 0 | O27: =(J27+J27*K27+L27+M27+N27)*$O$1 -> 0 | P27: =(J27+J27*K27+L27+M27+N27+O27)*$P$1 -> 0 | Q27: =(J27+J27*K27+L27+M27+N27+O27+P27)*$Q$1 -> 0 | R27: =E27*I27 -> 0 | S27: =T27+T27*U27+V27+W27+X27 -> 800 | T27: 800
A28: 11.1 | B28: 玻璃单开门 （无框） | C28: 1、10mm厚钢化玻璃门 2、门洞尺寸：900mm*2800mm 4、含门锁.不锈钢扶手五金等制作安装 | D28: 樘 | E28: 2 | F28: =I28 -> 550 | G28: =F28*E28 -> 1100 | I28: =J28+J28*K28+L28+M28+N28+O28+P28+Q28 -> 550 | J28: =T28*$T$1 -> 315 | K28: =U28 -> 0 | L28: =V28*$V$1 -> 200 | M28: =W28*$W$1 -> 35 | N28: =X28*$X$1 -> 0 | O28: =(J28+J28*K28+L28+M28+N28)*$O$1 -> 0 | P28: =(J28+J28*K28+L28+M28+N28+O28)*$P$1 -> 0 | Q28: =(J28+J28*K28+L28+M28+N28+O28+P28)*$Q$1 -> 0 | R28: =E28*I28 -> 1100 | S28: =T28+T28*U28+V28+W28+X28 -> 550 | T28: =125*0.9*2.8 -> 315 | V28: 200 | W28: =35 -> 35 | Y28: =S28*E28 -> 1100
A29: 11.2 | B29: 扶手 | D29: 副 | E29: 2 | F29: =I29 -> 150 | G29: =F29*E29 -> 300 | I29: =J29+J29*K29+L29+M29+N29+O29+P29+Q29 -> 150 | J29: =T29*$T$1 -> 150 | K29: =U29 -> 0 | L29: =V29*$V$1 -> 0 | M29: =W29*$W$1 -> 0 | N29: =X29*$X$1 -> 0 | O29: =(J29+J29*K29+L29+M29+N29)*$O$1 -> 0 | P29: =(J29+J29*K29+L29+M29+N29+O29)*$P$1 -> 0 | Q29: =(J29+J29*K29+L29+M29+N29+O29+P29)*$Q$1 -> 0 | R29: =E29*I29 -> 300 | S29: =T29+T29*U29+V29+W29+X29 -> 150 | T29: 150 | Y29: =S29*E29 -> 300
A30: 11.3 | B30: 门夹 | D30: 副 | E30: 4 | F30: =I30 -> 45 | G30: =F30*E30 -> 180 | I30: =J30+J30*K30+L30+M30+N30+O30+P30+Q30 -> 45 | J30: =T30*$T$1 -> 45 | K30: =U30 -> 0 | L30: =V30*$V$1 -> 0 | M30: =W30*$W$1 -> 0 | N30: =X30*$X$1 -> 0 | O30: =(J30+J30*K30+L30+M30+N30)*$O$1 -> 0 | P30: =(J30+J30*K30+L30+M30+N30+O30)*$P$1 -> 0 | Q30: =(J30+J30*K30+L30+M30+N30+O30+P30)*$Q$1 -> 0 | R30: =E30*I30 -> 180 | S30: =T30+T30*U30+V30+W30+X30 -> 45 | T30: 45 | Y30: =S30*E30 -> 180
A31: 11.4 | B31: 地弹簧 | D31: 副 | E31: 2 | F31: =I31 -> 350 | G31: =F31*E31 -> 700 | I31: =J31+J31*K31+L31+M31+N31+O31+P31+Q31 -> 350 | J31: =T31*$T$1 -> 350 | K31: =U31 -> 0 | L31: =V31*$V$1 -> 0 | M31: =W31*$W$1 -> 0 | N31: =X31*$X$1 -> 0 | O31: =(J31+J31*K31+L31+M31+N31)*$O$1 -> 0 | P31: =(J31+J31*K31+L31+M31+N31+O31)*$P$1 -> 0 | Q31: =(J31+J31*K31+L31+M31+N31+O31+P31)*$Q$1 -> 0 | R31: =E31*I31 -> 700 | S31: =T31+T31*U31+V31+W31+X31 -> 350 | T31: 350 | Y31: =S31*E31 -> 700
A32: 二 | B32: 机电工程 | G32: =SUBTOTAL(9,G33:G40) -> 13000.867 | J32: =T32*$T$1 -> 0 | K32: =U32 -> 0 | L32: =V32*$V$1 -> 0 | M32: =W32*$W$1 -> 0 | N32: =X32*$X$1 -> 0
A33: 1 | B33: 强电部分(不含照明灯具及开关插座) | C33: 1、成天泰2.5、4平方国标电源线； 2、照明线用wdz-byj-2.5m²,每路线负荷220V/2500W; 3、插座线用wdz-byj-4m²,每路线负荷 220V/4000W 4、含人工及镀锌金属线管 | D33: ㎡ | E33: 66.62 | F33: =I33 -> 100 | G33: =F33*E33 -> 6662 | I33: =J33+J33*K33+L33+M33+N33+O33+P33+Q33 -> 100 | J33: =T33*$T$1 -> 30 | K33: =U33 -> 0 | L33: =V33*$V$1 -> 70 | M33: =W33*$W$1 -> 0 | N33: =X33*$X$1 -> 0 | O33: =(J33+J33*K33+L33+M33+N33)*$O$1 -> 0 | P33: =(J33+J33*K33+L33+M33+N33+O33)*$P$1 -> 0 | Q33: =(J33+J33*K33+L33+M33+N33+O33+P33)*$Q$1 -> 0 | R33: =E33*I33 -> 6662 | S33: =T33+T33*U33+V33+W33+X33 -> 100 | T33: 30 | V33: 70 | Y33: =S33*E33 -> 6662
A34: 2 | B34: 装饰明装筒灯 | C34: 1、名称:明装筒灯 2、规格: 3、安装形式:吊装 4、其他:满足设计及施工要求 | D34: 个 | E34: 14 | F34: =I34 -> 75 | G34: =F34*E34 -> 1050 | I34: =J34+J34*K34+L34+M34+N34+O34+P34+Q34 -> 75 | J34: =T34*$T$1 -> 55 | K34: =U34 -> 0 | L34: =V34*$V$1 -> 20 | M34: =W34*$W$1 -> 0 | N34: =X34*$X$1 -> 0 | O34: =(J34+J34*K34+L34+M34+N34)*$O$1 -> 0 | P34: =(J34+J34*K34+L34+M34+N34+O34)*$P$1 -> 0 | Q34: =(J34+J34*K34+L34+M34+N34+O34+P34)*$Q$1 -> 0 | R34: =E34*I34 -> 1050 | S34: =T34+T34*U34+V34+W34+X34 -> 75 | T34: 55 | V34: 20 | Y34: =S34*E34 -> 1050
A35: 3 | B35: 磁吸灯 | C35: 1、名称:磁吸灯 2、规格: 3、安装形式:嵌入式 4、其他:满足设计及施工要求 | D35: m | E35: =1.6*2 -> 3.2 | F35: =I35 -> 103.33333 | G35: =F35*E35 -> 330.66667 | I35: =J35+J35*K35+L35+M35+N35+O35+P35+Q35 -> 103.33333 | J35: =T35*$T$1 -> 83.333333 | K35: =U35 -> 0 | L35: =V35*$V$1 -> 20 | M35: =W35*$W$1 -> 0 | N35: =X35*$X$1 -> 0 | O35: =(J35+J35*K35+L35+M35+N35)*$O$1 -> 0 | P35: =(J35+J35*K35+L35+M35+N35+O35)*$P$1 -> 0 | Q35: =(J35+J35*K35+L35+M35+N35+O35+P35)*$Q$1 -> 0 | R35: =E35*I35 -> 330.66667 | S35: =T35+T35*U35+V35+W35+X35 -> 103.33333 | T35: =50/0.6 -> 83.333333 | V35: 20 | Y35: =S35*E35 -> 330.66667
A36: 4 | B36: 照明开关 | C36: (1)名称:各种开关 (2)安装方式:距地1.3米安装 (3)其他:满足设计及施工要求 | D36: 个 | E36: 3 | F36: =I36 -> 27 | G36: =F36*E36 -> 81 | I36: =J36+J36*K36+L36+M36+N36+O36+P36+Q36 -> 27 | J36: =T36*$T$1 -> 17 | K36: =U36 -> 0 | L36: =V36*$V$1 -> 10 | M36: =W36*$W$1 -> 0 | N36: =X36*$X$1 -> 0 | O36: =(J36+J36*K36+L36+M36+N36)*$O$1 -> 0 | P36: =(J36+J36*K36+L36+M36+N36+O36)*$P$1 -> 0 | Q36: =(J36+J36*K36+L36+M36+N36+O36+P36)*$Q$1 -> 0 | R36: =E36*I36 -> 81 | S36: =T36+T36*U36+V36+W36+X36 -> 27 | T36: 17 | V36: 10 | Y36: =S36*E36 -> 81
A37: 5 | B37: 插座 | C37: (1)名称:单相二.三孔普通插座 (2)规格:250V 10A 安全型 (3)安装方式:详见图纸 (4)其他:满足设计及施工要求 | D37: 个 | E37: 22 | F37: =I37 -> 25 | G37: =F37*E37 -> 550 | I37: =J37+J37*K37+L37+M37+N37+O37+P37+Q37 -> 25 | J37: =T37*$T$1 -> 15 | K37: =U37 -> 0 | L37: =V37*$V$1 -> 10 | M37: =W37*$W$1 -> 0 | N37: =X37*$X$1 -> 0 | O37: =(J37+J37*K37+L37+M37+N37)*$O$1 -> 0 | P37: =(J37+J37*K37+L37+M37+N37+O37)*$P$1 -> 0 | Q37: =(J37+J37*K37+L37+M37+N37+O37+P37)*$Q$1 -> 0 | R37: =E37*I37 -> 550 | S37: =T37+T37*U37+V37+W37+X37 -> 25 | T37: 15 | V37: 10 | Y37: =S37*E37 -> 550
A38: 6 | B38: 弱电部分（包含信号线、网线） | C38: 1、紧定式镀锌电线管 2、信号线、网线 3、数据插座、路由器 | D38: ㎡ | E38: 66.62 | F38: =I38 -> 60 | G38: =F38*E38 -> 3997.2 | I38: =J38+J38*K38+L38+M38+N38+O38+P38+Q38 -> 60 | J38: =T38*$T$1 -> 20 | K38: =U38 -> 0 | L38: =V38*$V$1 -> 40 | M38: =W38*$W$1 -> 0 | N38: =X38*$X$1 -> 0 | O38: =(J38+J38*K38+L38+M38+N38)*$O$1 -> 0 | P38: =(J38+J38*K38+L38+M38+N38+O38)*$P$1 -> 0 | Q38: =(J38+J38*K38+L38+M38+N38+O38+P38)*$Q$1 -> 0 | R38: =E38*I38 -> 3997.2 | S38: =T38+T38*U38+V38+W38+X38 -> 60 | T38: 20 | V38: 40 | Y38: =S38*E38 -> 3997.2
A39: 7 | B39: 网络插座 | C39: (1)名称:网络插座 (2)安装方式: (3)其他:满足设计及施工要求 | D39: 个 | E39: 11 | F39: =I39 -> 30 | G39: =F39*E39 -> 330 | I39: =J39+J39*K39+L39+M39+N39+O39+P39+Q39 -> 30 | J39: =T39*$T$1 -> 20 | K39: =U39 -> 0 | L39: =V39*$V$1 -> 10 | M39: =W39*$W$1 -> 0 | N39: =X39*$X$1 -> 0 | O39: =(J39+J39*K39+L39+M39+N39)*$O$1 -> 0 | P39: =(J39+J39*K39+L39+M39+N39+O39)*$P$1 -> 0 | Q39: =(J39+J39*K39+L39+M39+N39+O39+P39)*$Q$1 -> 0 | R39: =E39*I39 -> 330 | S39: =T39+T39*U39+V39+W39+X39 -> 30 | T39: 20 | V39: 10 | Y39: =S39*E39 -> 330
A40: 8 | B40: 门禁系统安装 | C40: 1、门洞尺寸：1500*2200mm 2、门洞开口及修补加固 3、玻璃门保护性拆除及拆除后重新安装 | D40: 项 | E40: 0 | F40: =I40 -> 2050 | G40: =F40*E40 -> 0 | I40: =J40+J40*K40+L40+M40+N40+O40+P40+Q40 -> 2050 | J40: =T40*$T$1 -> 1200 | K40: =U40 -> 0 | L40: =V40*$V$1 -> 800 | M40: =W40*$W$1 -> 50 | N40: =X40*$X$1 -> 0 | O40: =(J40+J40*K40+L40+M40+N40)*$O$1 -> 0 | P40: =(J40+J40*K40+L40+M40+N40+O40)*$P$1 -> 0 | Q40: =(J40+J40*K40+L40+M40+N40+O40+P40)*$Q$1 -> 0 | R40: =E40*I40 -> 0 | S40: =T40+T40*U40+V40+W40+X40 -> 2050 | T40: 1200 | V40: 800 | W40: 50 | Y40: =S40*E40 -> 0
...

Sheet 1207空调消防清单
A1: 岁宝壹品苑D栋1207办公室装修清单 空调消防 | I1: =G39 -> 28905.009 | P1: ='1207清单'!$T$1 -> 1 | R1: ='1207清单'!$V$1 -> 1 | S1: ='1207清单'!$W$1 -> 1 | T1: ='1207清单'!$X$1 -> 1
A2: 序号 | B2: 项目名称 | C2: 项目特征 | D2: 单位 | E2: 工程量 | F2: 综合单价（不含税） | G2: 合价 | H2: 备注 | I2: 成本价 | J2: 主材费 | K2: 主材损耗率 | L2: 人工费 | M2: 辅材费 | N2: 机械费 | O2: 合计 | P2: 主材费 | Q2: 主材损耗率 | R2: 人工费 | S2: 辅材费 | T2: 机械费
A3: 一 | B3: 空调工程 | G3: =SUBTOTAL(9,G4:G4) -> 12000
A4: 1 | B4: 空调风机盘管1P | C4: 1、包含铝合金风口、空调管道、帆布、钢结构支架等 | D4: 台 | E4: 2 | F4: =I4 -> 6000 | G4: =F4*E4 -> 12000 | I4: =J4+J4*K4+L4+M4+N4 -> 6000 | J4: =P4*$P$1 -> 6000 | K4: =Q4 -> 0 | L4: =R4*$R$1 -> 0 | M4: =S4*$S$1 -> 0 | N4: =T4*$T$1 -> 0 | O4: =E4*I4 -> 12000 | P4: 6000
A5: 1 | B5: 空调风机盘管2P | C5: 1、包含铝合金风口、空调管道、帆布、钢结构支架等 | D5: 台 | E5: 1 | F5: =I5 -> 6300 | G5: =F5*E5 -> 6300 | I5: =J5+J5*K5+L5+M5+N5 -> 6300 | J5: =P5*$P$1 -> 6300 | K5: =Q5 -> 0 | L5: =R5*$R$1 -> 0 | M5: =S5*$S$1 -> 0 | N5: =T5*$T$1 -> 0 | O5: =E5*I5 -> 6300 | P5: 6300
A6: 二 | B6: 消防改造 | G6: =SUBTOTAL(9,G8:G35) -> 15528.58 | I6: =12*170+4000+3000 -> 9040
A7: （一） | B7: 火灾自动报警系统
A8: 1 | B8: 探测器拆除、安装 | C8: 1、含配合装修 | D8: 套 | E8: 2 | F8: =I8 -> 191.4 | G8: =F8*E8 -> 382.8 | I8: 191.4 | J8: =P8*$P$1 -> 0 | K8: =Q8 -> 0 | L8: =R8*$R$1 -> 0 | M8: =S8*$S$1 -> 0 | N8: =T8*$T$1 -> 0 | O8: =E8*I8 -> 382.8
A9: 2 | B9: 探测器新增、安装 | C9: 1、含设备增加及配合装修 | D9: 套 | E9: 1 | F9: =I9 -> 261 | G9: =F9*E9 -> 261 | I9: 261 | J9: =P9*$P$1 -> 0 | K9: =Q9 -> 0 | L9: =R9*$R$1 -> 0 | M9: =S9*$S$1 -> 0 | N9: =T9*$T$1 -> 0 | O9: =E9*I9 -> 261
A10: 3 | B10: 消防广播拆除、安装 | C10: 1、含设备增加及配合装修 | D10: 套 | E10: 1 | F10: =I10 -> 191.4 | G10: =F10*E10 -> 191.4 | I10: 191.4 | J10: =P10*$P$1 -> 0 | K10: =Q10 -> 0 | L10: =R10*$R$1 -> 0 | M10: =S10*$S$1 -> 0 | N10: =T10*$T$1 -> 0 | O10: =E10*I10 -> 191.4
A11: 4 | B11: 增加镀锌线管φ20(含配件) | C11: 1、国标 | D11: 米 | E11: 5 | F11: =I11 -> 24.36 | G11: =F11*E11 -> 121.8 | I11: 24.36 | J11: =P11*$P$1 -> 0 | K11: =Q11 -> 0 | L11: =R11*$R$1 -> 0 | M11: =S11*$S$1 -> 0 | N11: =T11*$T$1 -> 0 | O11: =E11*I11 -> 121.8
A12: 5 | B12: 增加金属软管￠ 16（含配件） | C12: 1、国标 | D12: 米 | E12: 3 | F12: =I12 -> 10.44 | G12: =F12*E12 -> 31.32 | I12: 10.44 | J12: =P12*$P$1 -> 0 | K12: =Q12 -> 0 | L12: =R12*$R$1 -> 0 | M12: =S12*$S$1 -> 0 | N12: =T12*$T$1 -> 0 | O12: =E12*I12 -> 31.32
A13: 6 | B13: 增加ZR-RVS-2x1.5mm² 电线 | C13: 1、国标 | D13: 米 | E13: 30 | F13: =I13 -> 6.96 | G13: =F13*E13 -> 208.8 | I13: 6.96 | J13: =P13*$P$1 -> 0 | K13: =Q13 -> 0 | L13: =R13*$R$1 -> 0 | M13: =S13*$S$1 -> 0 | N13: =T13*$T$1 -> 0 | O13: =E13*I13 -> 208.8
A14: 7 | B14: 报警系统调试 | C14: 1、仅限我司施工 的项目 | D14: 项 | E14: 1 | F14: =I14 -> 1000 | G14: =F14*E14 -> 1000 | I14: 1000 | J14: =P14*$P$1 -> 0 | K14: =Q14 -> 0 | L14: =R14*$R$1 -> 0 | M14: =S14*$S$1 -> 0 | N14: =T14*$T$1 -> 0 | O14: =E14*I14 -> 1000
A15: 8 | B15: 编程入网、系统接驳 | C15: 1、由大厦原消防施工单位负责，物业统一收费 | D15: 项 | E15: 1 | F15: 4000 | G15: =F15*E15 -> 4000 | H15: 不足4000元的按最低4000元计算。超过4000元的按建筑面积30元/㎡计算。 | I15: 35.5 | J15: =P15*$P$1 -> 0 | K15: =Q15 -> 0 | L15: =R15*$R$1 -> 30 | M15: =S15*$S$1 -> 0 | N15: =T15*$T$1 -> 0 | O15: =E15*I15 -> 35.5 | R15: 30
A16: （二） | B16: 自动喷淋灭火系统
A17: 1 | B17: 喷头拆除、安装 | C17: 1、含配合装修 | D17: 个 | E17: 8 | F17: =I17 -> 174 | G17: =F17*E17 -> 1392 | I17: 174 | J17: =P17*$P$1 -> 0 | K17: =Q17 -> 0 | L17: =R17*$R$1 -> 0 | M17: =S17*$S$1 -> 0 | N17: =T17*$T$1 -> 0 | O17: =E17*I17 -> 1392
A18: 2 | B18: 喷头新增、安装 | C18: 1、含设备增加 | D18: 个 | E18: 1 | F18: =I18 -> 217.5 | G18: =F18*E18 -> 217.5 | I18: 217.5 | J18: =P18*$P$1 -> 0 | K18: =Q18 -> 0 | L18: =R18*$R$1 -> 0 | M18: =S18*$S$1 -> 0 | N18: =T18*$T$1 -> 0 | O18: =E18*I18 -> 217.5
A19: 3 | B19: 管网支吊架 | C19: 1、含配合装修 | D19: KG | E19: 12 | F19: =I19 -> 21.75 | G19: =F19*E19 -> 261 | I19: 21.75 | J19: =P19*$P$1 -> 0 | K19: =Q19 -> 0 | L19: =R19*$R$1 -> 0 | M19: =S19*$S$1 -> 0 | N19: =T19*$T$1 -> 0 | O19: =E19*I19 -> 261
A20: 4 | B20: 大红油漆（含人工及天那水） | C20: 1、含油漆、天那水、人工 | D20: 桶 | E20: 0.5 | F20: =I20 -> 435 | G20: =F20*E20 -> 217.5 | I20: 435 | J20: =P20*$P$1 -> 0 | K20: =Q20 -> 0 | L20: =R20*$R$1 -> 0 | M20: =S20*$S$1 -> 0 | N20: =T20*$T$1 -> 0 | O20: =E20*I20 -> 217.5
A21: 5 | B21: 新增镀锌水管DN25 | C21: 1、含材料以及人工安装费用 | D21: 米 | E21: 5 | F21: =I21 -> 50.46 | G21: =F21*E21 -> 252.3 | I21: 50.46 | J21: =P21*$P$1 -> 0 | K21: =Q21 -> 0 | L21: =R21*$R$1 -> 0 | M21: =S21*$S$1 -> 0 | N21: =T21*$T$1 -> 0 | O21: =E21*I21 -> 252.3
A22: 6 | B22: 新增镀锌水管DN32 | C22: 1、含材料以及人工安装费用 | D22: 米 | E22: 3 | F22: =I22 -> 56.55 | G22: =F22*E22 -> 169.65 | I22: 56.55 | J22: =P22*$P$1 -> 0 | K22: =Q22 -> 0 | L22: =R22*$R$1 -> 0 | M22: =S22*$S$1 -> 0 | N22: =T22*$T$1 -> 0 | O22: =E22*I22 -> 169.65
A23: 7 | B23: 新增镀锌水管DN40 | C23: 1、含材料以及人工安装费用 | D23: 米 | E23: 1 | F23: =I23 -> 65.25 | G23: =F23*E23 -> 65.25 | I23: 65.25 | J23: =P23*$P$1 -> 0 | K23: =Q23 -> 0 | L23: =R23*$R$1 -> 0 | M23: =S23*$S$1 -> 0 | N23: =T23*$T$1 -> 0 | O23: =E23*I23 -> 65.25
A24: 8 | B24: 新增镀锌水管DN50 | C24: 1、含材料以及人工安装费用 | D24: 米 | E24: 1 | F24: =I24 -> 80.91 | G24: =F24*E24 -> 80.91 | I24: 80.91 | J24: =P24*$P$1 -> 0 | K24: =Q24 -> 0 | L24: =R24*$R$1 -> 0 | M24: =S24*$S$1 -> 0 | N24: =T24*$T$1 -> 0 | O24: =E24*I24 -> 80.91
A25: 9 | B25: 喷淋管网排水费 | C25: 1、含管网排水费 及人工 | D25: 项 | E25: 1 | F25: =I25 -> 800 | G25: =F25*E25 -> 800 | I25: 800 | J25: =P25*$P$1 -> 0 | K25: =Q25 -> 0 | L25: =R25*$R$1 -> 0 | M25: =S25*$S$1 -> 0 | N25: =T25*$T$1 -> 0 | O25: =E25*I25 -> 800
A26: 10 | B26: 喷淋管网试压 | C26: 1、管网冲洗、试 压、调试 | D26: 项 | E26: 1 | F26: =I26 -> 870 | G26: =F26*E26 -> 870 | I26: 870 | J26: =P26*$P$1 -> 0 | K26: =Q26 -> 0 | L26: =R26*$R$1 -> 0 | M26: =S26*$S$1 -> 0 | N26: =T26*$T$1 -> 0 | O26: =E26*I26 -> 870
A27: （三） | B27: 机械排烟系统
A28: 1 | B28: 镀锌风管拆除、移位 | C28: 含配合装修 | D28: ㎡ | E28: 2.5 | F28: =I28 -> 156.6 | G28: =F28*E28 -> 391.5 | I28: 156.6 | J28: =P28*$P$1 -> 0 | K28: =Q28 -> 0 | L28: =R28*$R$1 -> 0 | M28: =S28*$S$1 -> 0 | N28: =T28*$T$1 -> 0 | O28: =E28*I28 -> 391.5
A29: 2 | B29: 镀锌风管新增、安装 | C29: 含材料增加及 配合装修 | D29: ㎡ | E29: 1.5 | F29: =I29 -> 147.9 | G29: =F29*E29 -> 221.85 | I29: 147.9 | J29: =P29*$P$1 -> 0 | K29: =Q29 -> 0 | L29: =R29*$R$1 -> 0 | M29: =S29*$S$1 -> 0 | N29: =T29*$T$1 -> 0 | O29: =E29*I29 -> 221.85
A30: 3 | B30: 风管防火包裹 | C30: 含材料增加及 配合装修 | D30: ㎡ | E30: =E28+E29 -> 4 | F30: =I30 -> 87 | G30: =F30*E30 -> 348 | I30: 87 | J30: =P30*$P$1 -> 0 | K30: =Q30 -> 0 | L30: =R30*$R$1 -> 0 | M30: =S30*$S$1 -> 0 | N30: =T30*$T$1 -> 0 | O30: =E30*I30 -> 348
A31: 5 | B31: 常开百叶风 口 | C31: 含设备增加及 配合装修 | D31: 个 | E31: 3 | F31: =I31 -> 348 | G31: =F31*E31 -> 1044 | I31: 348 | J31: =P31*$P$1 -> 0 | K31: =Q31 -> 0 | L31: =R31*$R$1 -> 0 | M31: =S31*$S$1 -> 0 | N31: =T31*$T$1 -> 0 | O31: =E31*I31 -> 1044
A32: 6 | B32: 排烟系统调试 | D32: 项 | E32: 0 | F32: =I32 -> 1500 | G32: =F32*E32 -> 0 | I32: 1500 | J32: =P32*$P$1 -> 0 | K32: =Q32 -> 0 | L32: =R32*$R$1 -> 0 | M32: =S32*$S$1 -> 0 | N32: =T32*$T$1 -> 0 | O32: =E32*I32 -> 0
A33: （四） | B33: 其他
A34: 1 | B34: 消防报验 | C34: 含相关部门收取的报验费用。 | D34: 项 | E34: 1 | F34: =I34 -> 3000 | G34: =F34*E34 -> 3000 | I34: 3000 | J34: =P34*$P$1 -> 0 | K34: =Q34 -> 0 | L34: =R34*$R$1 -> 0 | M34: =S34*$S$1 -> 0 | N34: =T34*$T$1 -> 0 | O34: =E34*I34 -> 3000
A35: 2 | B35: 综合专业设计出图 | D35: 套 | E35: 0 | F35: =I35 -> 870 | G35: =F35*E35 -> 0 | I35: 870
A36: 三 | B36: 小计 | D36: 项 | E36: 1 | G36: =G3+G6 -> 27528.58 | I36: =SUBTOTAL(9,G3:G35) -> 33828.58
A37: 四 | B37: 管理费 | C37: ='1207清单'!C50 -> 0.05 | D37: 项 | E37: 1 | G37: =G36*C37 -> 1376.429
A38: 五 | B38: 税金 | C38: ='1207清单'!C51 -> 0 | D38: 项 | E38: 1 | G38: =(G37+G36)*C38 -> 0
A39: 六 | B39: 合计 | D39: 项 | E39: 1 | G39: =G38+G37+G36 -> 28905.009

Sheet 材料设备参考品牌
A1: 材料设备参考品牌
A2: 序号 | B2: 专业 | C2: 材料名称 | D2: 品牌 | E2: 备注
A3: 1 | B3: 装饰 | C3: 地砖 | D3: 东鹏、马可罗兰
A4: 2 | B4: 装饰 | C4: 墙砖 | D4: 东鹏、马可罗兰
A5: 3 | B5: 装饰 | C5: 方块地毯 | D5: 国产
A6: 4 | B6: 装饰 | C6: 500*500mm架空地板 | D6: 深圳沈飞
A7: 5 | B7: 装饰 | C7: 石膏板 | D7: 泰山、深耐福
A8: 6 | B8: 装饰 | C8: 乳胶漆 | D8: 立邦
A9: 7 | B9: 装饰 | C9: 腻子 | D9: 立邦
A10: 8 | B10: 安装 | C10: 照明，强电用线 | D10: 南洋、成天泰
A11: 9 | B11: 安装 | C11: 筒灯 | D11: 佛山照明
A12: 10 | B12: 安装 | C12: LED灯带 | D12: 佛山照明
A13: 11 | B13: 安装 | C13: 照明开关 | D13: 公牛
A14: 12 | B14: 安装 | C14: 插座 | D14: 公牛
... A17: 15 | B17: 空调 | C17: 空调风机盘管 | D17: 麦克维尔
