Workbook

Sheet 报价汇总-装修工程
B1: 岁宝壹品苑D栋1906-09-11办公室装修汇总 装修工程 | J1: =2450/83 -> 29.518072 | L1: =40*83 -> 3320
A2: 序号 | B2: 名称 | C2: 金额（元） | D2: 面积（㎡） | E2: 单方价格（元/㎡） | F2: 备注 | M2: =100/83 -> 1.2048193
A3: 一 | B3: 装饰工程 | C3: =不含空调消防清单!G3 -> 144304.86
A4: （一） | B4: 隔墙工程 | C4: =不含空调消防清单!G4 -> 29939.526
A5: （二） | B5: 地面工程 | C5: =不含空调消防清单!G8 -> 31012.215
A6: （三） | B6: 天花工程 | C6: =不含空调消防清单!G13 -> 22584.014
A7: （四） | B7: 墙面工程 | C7: =不含空调消防清单!G22 -> 13745.171
A8: （五） | B8: 固定家具及门窗工程 | C8: =不含空调消防清单!G29 -> 47023.93
A9: 二 | B9: 安装工程 | C9: =不含空调消防清单!G37 -> 38929.107
A10: （一） | B10: 强电工程 | C10: =不含空调消防清单!G38 -> 31309.107
A11: （二） | B11: 弱电工程 | C11: =不含空调消防清单!G51 -> 7620
A12: 三 | B12: 其他工程 | C12: =不含空调消防清单!G54 -> 47121.2
A13: 四 | B13: 小计：一+二+三 | C13: =C3+C9+C12 -> 230355.16 | D13: 204 | E13: =C13/D13 -> 1129.192 | G13: 含消防空调成本总价 | H13: 255733.89 | I13: =C13+'报价汇总-空调消防'!C5 -> 300136.39
A14: 五 | B14: 管理费 | C14: =不含空调消防清单!G63 -> 11517.758 | G14: 含消防空调单方造价 | H14: =H13/D13 -> 1253.5975 | I14: =I13/D13 -> 1471.2568
A15: 六 | B15: 税金 | C15: =不含空调消防清单!G64 -> 21768.563
A16: 七 | B16: 合计=四+五+六 | C16: =C13+C14+C15 -> 263641.48 | D16: 204 | E16: =C16/D16 -> 1292.3602
A17: 八 | B17: 施工图、效果图设计费 | C17: 0
A18: 九 | B18: 总计:七+八 | C18: =C17+C16 -> 263641.48 | D18: 204 | E18: =C18/D18 -> 1292.3602 | G18: =C18+'报价汇总-空调消防'!C8 -> 343506.1 | H18: =H13*1.43 -> 365699.46
C20: =C18+'报价汇总-空调消防'!C8 -> 343506.1

Sheet 不含空调消防清单
A1: 岁宝壹品苑D栋1906-09-11办公室装修清单 （不含空调消防） | I1: =G65 -> 263641.48 | P1: 1 | R1: =$P$1 -> 1 | S1: =$P$1 -> 1 | T1: =$P$1 -> 1 | U1: ='报价汇总-装修工程'!G18 -> 343506.1 | V1: =18.84+18.31+39.39+16.39+7.1+10.25+8.68+2.78 -> 121.74
A2: 序号 | B2: 项目名称 | C2: 项目特征 | D2: 单位 | E2: 工程量 | F2: 综合单价（不含税） | G2: 合价 | H2: 备注 | I2: 成本价 | J2: 主材费 | K2: 主材损耗率 | L2: 人工费 | M2: 辅材费 | N2: 机械费 | O2: 合计 | P2: 主材费 | Q2: 主材损耗率 | R2: 人工费 | S2: 辅材费 | T2: 机械费
A3: 一 | B3: 装饰工程 | G3: =SUBTOTAL(9,G4:G36) -> 144304.86
A4: （一） | B4: 隔墙工程 | G4: =SUBTOTAL(9,G5:G7) -> 29939.526
A5: 1 | B5: 轻钢龙骨隔墙 | C5: 双层双面轻钢龙骨隔墙 1、墙厚100mm; 2、75mm轻钢龙骨； 3、50mm厚，48kg/m3的吸音棉； 4、9.5mm厚石膏板 | D5: ㎡ | E5: =3.81*(0.8+3.69+3.12+2.69+3+3.06+1.7)-0.6*2.4 -> 67.3686 | F5: =I5 -> 141.9 | G5: =F5*E5 -> 9559.6043 | I5: =J5+J5*K5+L5+M5+N5 -> 141.9 | J5: =P5*$P$1 -> 40 | K5: =Q5 -> 0.01 | L5: =R5*$R$1 -> 70 | M5: =S5*$S$1 -> 30 | N5: =T5*$T$1 -> 1.5 | O5: =E5*I5 -> 9559.6043 | P5: =10*4 -> 40 | Q5: 0.01 | R5: 70 | S5: 30 | T5: 1.5
A6: 2 | B6: GL-01 中空钢化玻璃隔断（含免漆板隔断） | C6: 1、GL-01 5+5mm钢化玻璃; 2、铝框包边 3、五金配件等制作安装 | D6: ㎡ | E6: =2.8*(7.09+5.65+5.29) -> 50.484 | F6: =I6 -> 323.5 | G6: =F6*E6 -> 16331.574 | I6: =J6+J6*K6+L6+M6+N6 -> 323.5 | J6: =P6*$P$1 -> 300 | K6: =Q6 -> 0.01 | L6: =R6*$R$1 -> 10 | M6: =S6*$S$1 -> 10.5 | N6: =T6*$T$1 -> 0 | O6: =E6*I6 -> 16331.574 | P6: 300 | Q6: 0.01 | R6: 10 | S6: 10.5
A7: 3 | B7: 玻璃隔断上方封板 | C7: 双层双面钢结构龙骨隔墙 1、墙厚100mm; 2、钢结构龙骨； 3、50mm厚，48kg/m3的吸音棉； 4、12mm厚阻燃夹板+9.5mm厚石膏板 | D7: ㎡ | E7: =1.31*(7.09+5.65+5.29) -> 23.6193 | F7: =I7 -> 171.4 | G7: =F7*E7 -> 4048.348 | I7: =J7+J7*K7+L7+M7+N7 -> 171.4 | J7: =P7*$P$1 -> 90 | K7: =Q7 -> 0.01 | L7: =R7*$R$1 -> 70 | M7: =S7*$S$1 -> 10.5 | N7: =T7*$T$1 -> 0 | O7: =E7*I7 -> 4048.348 | P7: =35*2+10*2 -> 90 | Q7: 0.01 | R7: 70 | S7: 10.5
A8: （二） | B8: 地面工程 | G8: =SUBTOTAL(9,G9:G12) -> 31012.215
A9: 1 | B9: 100mm厚陶粒拌混泥土垫层 | C9: 1、100mm厚陶粒拌混泥土垫层 | D9: ㎡ | E9: 135.04 | F9: =I9 -> 76.93 | G9: =F9*E9 -> 10388.627 | I9: =J9+J9*K9+L9+M9+N9 -> 76.93 | J9: =P9*$P$1 -> 43 | K9: =Q9 -> 0.01 | L9: =R9*$R$1 -> 30 | M9: =S9*$S$1 -> 3.5 | N9: =T9*$T$1 -> 0 | O9: =E9*I9 -> 10388.627 | P9: 43 | Q9: 0.01 | R9: 30 | S9: 3.5 | T9: 0
A10: 2 | B10: 20mm厚柜底水泥砂浆找平 | C10: 1、20mm厚干硬性M20水泥砂浆找平 | D10: ㎡ | E10: =4.62+2.67 -> 7.29 | F10: =I10 -> 34.42 | G10: =F10*E10 -> 250.9218 | I10: =J10+J10*K10+L10+M10+N10 -> 34.42 | J10: =P10*$P$1 -> 12 | K10: =Q10 -> 0.01 | L10: =R10*$R$1 -> 22 | M10: =S10*$S$1 -> 0.3 | N10: =T10*$T$1 -> 0 | O10: =E10*I10 -> 250.9218 | P10: 12 | Q10: 0.01 | R10: 22 | S10: 0.3 | T10: 0
A11: 3 | B11: 地面块料 | C11: 1、CT-01灰色地砖 2、瓷砖规格：600*1200 3、瓷砖专用胶泥结合层，厚度包干，后期不因厚度调整价格； 4、白水泥擦缝 | D11: ㎡ | E11: =18.84+18.31+39.39+16.39+7.1+10.25+8.68+2.78+0.09*6 -> 122.28 | F11: =I11 -> 162.7 | G11: =F11*E11 -> 19894.956 | I11: =J11+J11*K11+L11+M11+N11 -> 162.7 | J11: =P11*$P$1 -> 85 | K11: =Q11 -> 0.02 | L11: =R11*$R$1 -> 60 | M11: =S11*$S$1 -> 16 | N11: =T11*$T$1 -> 0 | O11: =E11*I11 -> 19894.956 | P11: 85 | Q11: 0.02 | R11: 60 | S11: 16
A12: 4 | B12: 石材门槛 | C12: 1、ST-01石材 2、石材规格：200mm宽 3、石材专用胶泥结合层，厚度包干，后期不因厚度调整价格； 4、白水泥擦缝 | D12: m | E12: =1.6+1.5 -> 3.1 | F12: =I12 -> 154.1 | G12: =F12*E12 -> 477.71 | I12: =J12+J12*K12+L12+M12+N12 -> 154.1 | J12: =P12*$P$1 -> 90 | K12: =Q12 -> 0.01 | L12: =R12*$R$1 -> 60 | M12: =S12*$S$1 -> 3.2 | N12: =T12*$T$1 -> 0 | O12: =E12*I12 -> 477.71 | P12: =450*0.2 -> 90 | Q12: 0.01 | R12: 60 | S12: =16*0.2 -> 3.2
A13: （三） | B13: 天花工程 | G13: =SUBTOTAL(9,G14:G21) -> 22584.014
A14: 1 | B14: 原天棚喷乳胶漆PT-02 (含墙体上部) | C14: 1、面层：PT-02深色涂料两遍 2、包含各种管道 | D14: ㎡ | E14: =18.84+39.39+1.31*(17.59+25.24) -> 114.3373 | F14: =I14 -> 20.16 | G14: =F14*E14 -> 2305.04 | I14: =J14+J14*K14+L14+M14+N14 -> 20.16 | J14: =P14*$P$1 -> 8 | K14: =Q14 -> 0.02 | L14: =R14*$R$1 -> 10 | M14: =S14*$S$1 -> 0.5 | N14: =T14*$T$1 -> 1.5 | O14: =E14*I14 -> 2305.04 | P14: 8 | Q14: 0.02 | R14: 10 | S14: 0.5 | T14: 1.5
A15: 2 | B15: 石膏板天花吊顶 | C15: 1、吊顶形式：平级+跌级吊顶 2、基层：轻钢龙骨+双层9.5mm厚石膏板 | D15: ㎡ | E15: =18.31+16.39+7.1+10.25+8.68+2.78 -> 63.51 | F15: =I15 -> 144.18 | G15: =F15*E15 -> 9156.8718 | I15: =J15+J15*K15+L15+M15+N15 -> 144.18 | J15: =P15*$P$1 -> 18 | K15: =Q15 -> 0.01 | L15: =R15*$R$1 -> 100 | M15: =S15*$S$1 -> 26 | N15: =T15*$T$1 -> 0 | O15: =E15*I15 -> 9156.8718 | P15: 18 | Q15: 0.01 | R15: 100 | S15: 26
A16: 3 | B16: 天花板缝贴纸带刮平整 | D16: ㎡ | E16: =63.51+8.06*0.3+0.5*17.75 -> 74.803 | F16: =I16 -> 8.5 | G16: =F16*E16 -> 635.8255 | I16: =J16+J16*K16+L16+M16+N16 -> 8.5 | J16: =P16*$P$1 -> 3.5 | K16: =Q16 -> 0 | L16: =R16*$R$1 -> 5 | M16: =S16*$S$1 -> 0 | N16: =T16*$T$1 -> 0 | O16: =E16*I16 -> 635.8255 | P16: 3.5 | Q16: 0 | R16: 5 | S16: 0 | T16: 0
A17: 4 | B17: 天花挂耐水腻子 | C17: 1、耐水腻子2道，含打磨、修补 | D17: ㎡ | E17: =63.51+8.06*0.3+0.5*17.75 -> 74.803 | F17: =I17 -> 23.5 | G17: =F17*E17 -> 1757.8705 | I17: =J17+J17*K17+L17+M17+N17 -> 23.5 | J17: =P17*$P$1 -> 3.5 | K17: =Q17 -> 0 | L17: =R17*$R$1 -> 20 | M17: =S17*$S$1 -> 0 | N17: =T17*$T$1 -> 0 | O17: =E17*I17 -> 1757.8705 | P17: 3.5 | Q17: 0 | R17: 20 | S17: 0 | T17: 0
A18: 5 | B18: 天棚乳胶漆 | C18: 1、面层：PT-01无机白色涂料一底二面 | D18: ㎡ | E18: =63.51+8.06*0.3+0.5*17.75 -> 74.803 | F18: =I18 -> 13 | G18: =F18*E18 -> 972.439 | I18: =J18+J18*K18+L18+M18+N18 -> 13 | J18: =P18*$P$1 -> 3 | K18: =Q18 -> 0 | L18: =R18*$R$1 -> 10 | M18: =S18*$S$1 -> 0 | N18: =T18*$T$1 -> 0 | O18: =E18*I18 -> 972.439 | P18: 3 | Q18: 0 | R18: 10 | S18: 0 | T18: 0
A19: 6 | B19: 天花灯槽 | C19: 1、规格：150*70*50mm天花灯槽 2、基层：轻钢龙骨 3、面层：12mm厚阻燃夹板+9.5mm厚石膏板 | D19: m | E19: 8.06 | F19: =I19 -> 70 | G19: =F19*E19 -> 564.2 | I19: =J19+J19*K19+L19+M19+N19 -> 70 | J19: =P19*$P$1 -> 13.5 | K19: =Q19 -> 0 | L19: =R19*$R$1 -> 55 | M19: =S19*$S$1 -> 1.5 | N19: =T19*$T$1 -> 0 | O19: =E19*I19 -> 564.2 | P19: =0.3*(35+10) -> 13.5 | R19: 55 | S19: 1.5
A20: 7 | B20: 窗帘盒 | C20: 1、基层：钢结构龙骨+阻燃板基层 2、面层：9.5mm厚石膏板 | D20: m | E20: =5.77+3.08+8.9 -> 17.75 | F20: =I20 -> 195.17 | G20: =F20*E20 -> 3464.2675 | I20: =J20+J20*K20+L20+M20+N20 -> 195.17 | J20: =P20*$P$1 -> 131.67 | K20: =Q20 -> 0 | L20: =R20*$R$1 -> 55 | M20: =S20*$S$1 -> 8.5 | N20: =T20*$T$1 -> 0 | O20: =E20*I20 -> 3464.2675 | P20: =4.2*5.7*5.5 -> 131.67 | R20: 55 | S20: 8.5
A21: 8 | B21: 窗帘 | D21: ㎡ | E21: =(5.77+3.08+8.9)*2.8 -> 49.7 | F21: =I21 -> 75 | G21: =F21*E21 -> 3727.5 | I21: =J21+J21*K21+L21+M21+N21 -> 75 | J21: =P21*$P$1 -> 68 | K21: =Q21 -> 0 | L21: =R21*$R$1 -> 5 | M21: =S21*$S$1 -> 1.5 | N21: =T21*$T$1 -> 0.5 | O21: =E21*I21 -> 3727.5 | P21: 68 | R21: 5 | S21: 1.5 | T21: 0.5
A22: （四） | B22: 墙面工程 | G22: =SUBTOTAL(9,G23:G28) -> 13745.171
A23: 1 | B23: 墙面缝贴纸带刮平整 | D23: ㎡ | E23: =E24 -> 193.711 | F23: =I23 -> 8.5 | G23: =F23*E23 -> 1646.5435 | I23: =J23+J23*K23+L23+M23+N23 -> 8.5 | J23: =P23*$P$1 -> 3.5 | K23: =Q23 -> 0 | L23: =R23*$R$1 -> 5 | M23: =S23*$S$1 -> 0 | N23: =T23*$T$1 -> 0 | O23: =E23*I23 -> 1646.5435 | P23: =P16 -> 3.5 | Q23: =Q16 -> 0 | R23: =R16 -> 5 | S23: =S16 -> 0 | T23: 0
A24: 2 | B24: 墙面挂耐水腻子 | C24: 耐水腻子2道，含打磨、修补 | D24: ㎡ | E24: =2.8*(0.8+3.69*2+5.1+3.69+1.6+3.12+3.12+2.69+3.06+1.37+1.7*2+1.31+1.37+0.3+3.06*2+1.56+0.2+0.4+0.5*2+0.2+2.4+2.88)+0.3*(7.09+5.65+2.83+3.32+5+25.24)-1.6*2.4+2.8*(0.6*2+4.45+0.8+5.77) -> 193.711 | F24: =I24 -> 23.5 | G24: =F24*E24 -> 4552.2085 | I24: =J24+J24*K24+L24+M24+N24 -> 23.5 | J24: =P24*$P$1 -> 3.5 | K24: =Q24 -> 0 | L24: =R24*$R$1 -> 20 | M24: =S24*$S$1 -> 0 | N24: =T24*$T$1 -> 0 | O24: =E24*I24 -> 4552.2085 | P24: =P17 -> 3.5 | Q24: =Q17 -> 0 | R24: =R17 -> 20 | S24: =S17 -> 0 | T24: 0
A25: 3 | B25: 墙面乳胶漆PT-01 | C25: 1、面层：PT-01无机白色涂料一底二面 | D25: ㎡ | E25: =2.8*(0.8+3.69*2+5.1+3.69+1.6+3.12+3.12+2.69+3.06+1.37+1.7*2+1.31+1.37+0.3+3.06*2+1.56+0.2+0.4+0.5*2+0.2+2.4+2.88)+0.3*(7.09+5.65+2.83+3.32+5+25.24)-1.6*2.4 -> 159.495 | F25: =I25 -> 13 | G25: =F25*E25 -> 2073.435 | I25: =J25+J25*K25+L25+M25+N25 -> 13 | J25: =P25*$P$1 -> 3 | K25: =Q25 -> 0 | L25: =R25*$R$1 -> 10 | M25: =S25*$S$1 -> 0 | N25: =T25*$T$1 -> 0 | O25: =E25*I25 -> 2073.435 | P25: =P18 -> 3 | Q25: =Q18 -> 0 | R25: =R18 -> 10 | S25: =S18 -> 0 | T25: 0
A26: 4 | B26: logo招牌 （背景墙） | C26: 1、面层：成品定制 | D26: 套 | E26: 1 | F26: =I26 -> 2500 | G26: =F26*E26 -> 2500 | I26: =J26+J26*K26+L26+M26+N26 -> 2500 | J26: =P26*$P$1 -> 2500 | K26: =Q26 -> 0 | L26: =R26*$R$1 -> 0 | M26: =S26*$S$1 -> 0 | N26: =T26*$T$1 -> 0 | O26: =E26*I26 -> 2500 | P26: 2500
A27: 5 | B27: MT-01 1.2mm厚不锈钢踢脚线 | C27: 1、规格尺寸：50mm高 2、面层：MT-01 1.2mm厚不锈钢 3、基层：轻钢龙骨+12mm厚阻燃夹板 | D27: m | E27: =0.8+3.69*2+5.1+3.69+1.6+3.12+3.12+2.69+3.06+1.37+1.7*2+1.31+1.37+0.3+3.06*2+1.56+0.2+0.4+0.5*2+0.2+2.4+2.88+5.77+4.45 -> 63.29 | F27: =I27 -> 41.831 | G27: =F27*E27 -> 2647.484 | I27: =J27+J27*K27+L27+M27+N27 -> 41.831 | J27: =P27*$P$1 -> 23.1 | K27: =Q27 -> 0.01 | L27: =R27*$R$1 -> 15 | M27: =S27*$S$1 -> 3.5 | N27: =T27*$T$1 -> 0 | O27: =E27*I27 -> 2647.484 | P27: =0.06*360+1.5 -> 23.1 | Q27: 0.01 | R27: 15 | S27: 3.5
A28: 6 | B28: 墙面灯槽 | C28: 1、规格：100*50mm灯槽 2、基层：轻钢龙骨 3、面层：12mm厚阻燃夹板+9.5mm厚石膏板 | D28: m | E28: =2.5*2 -> 5 | F28: =I28 -> 65.1 | G28: =F28*E28 -> 325.5 | I28: =J28+J28*K28+L28+M28+N28 -> 65.1 | J28: =P28*$P$1 -> 10 | K28: =Q28 -> 0.01 | L28: =R28*$R$1 -> 55 | M28: =S28*$S$1 -> 0 | N28: =T28*$T$1 -> 0 | O28: =E28*I28 -> 325.5 | P28: =(35+15)*0.2 -> 10 | Q28: 0.01 | R28: 55
A29: （五） | B29: 固定家具及门窗工程 | G29: =SUBTOTAL(9,G30:G36) -> 47023.93
A30: 1 | B30: 门禁系统安装 | C30: 1、门洞尺寸：1600*2500mm 2、门洞开口及修补加固 3、玻璃门保护性拆除及拆除后重新安装 | D30: 项 | E30: 1 | F30: =I30 -> 2050 | G30: =F30*E30 -> 2050 | I30: =J30+J30*K30+L30+M30+N30 -> 2050 | J30: =P30*$P$1 -> 1200 | K30: =Q30 -> 0 | L30: =R30*$R$1 -> 800 | M30: =S30*$S$1 -> 50 | N30: =T30*$T$1 -> 0 | O30: =E30*I30 -> 2050 | P30: 1200 | R30: 800 | S30: 50
A31: 2 | B31: 卷帘 | C31: 遮光卷帘 | D31: ㎡ | E31: =1.5*2.4 -> 3.6 | F31: =I31 -> 75 | G31: =F31*E31 -> 270 | I31: =J31+J31*K31+L31+M31+N31 -> 75 | J31: =P31*$P$1 -> 75 | K31: =Q31 -> 0 | L31: =R31*$R$1 -> 0 | M31: =S31*$S$1 -> 0 | N31: =T31*$T$1 -> 0 | O31: =E31*I31 -> 270 | P31: 75
A32: 3 | B32: 隔断免漆板单开门 | C32: 1、免漆板单开门 2、门洞尺寸：800mm*2400mm 4、含门锁.五金等制作安装 | D32: 樘 | E32: 6 | F32: =I32 -> 1812 | G32: =F32*E32 -> 10872 | I32: =J32+J32*K32+L32+M32+N32 -> 1812 | J32: =P32*$P$1 -> 1632 | K32: =Q32 -> 0 | L32: =R32*$R$1 -> 180 | M32: =S32*$S$1 -> 0 | N32: =T32*$T$1 -> 0 | O32: =E32*I32 -> 10872 | P32: =850*0.8*2.4 -> 1632 | R32: 180
A33: 4 | B33: 柜子 （董事长办公室） | C33: 1、规格尺寸：4450*600*2500mm 2、木饰面板柜体； 3、人造石台面，厚度20mm 4、按立面投影面积计算,综合考虑柜体尺寸及内部做法； 5、含包边、饰面、柜体五金、抽屉及其他所需材料安装施工,含低柜水龙头及相关水龙头连接件； 6、满足设计图纸、招标要求及国家有关现行施工及验收规范要求 | D33: m2 | E33: =4.45*2.5 -> 11.125 | F33: =I33 -> 1250 | G33: =F33*E33 -> 13906.25 | I33: =J33+J33*K33+L33+M33+N33 -> 1250 | J33: =P33*$P$1 -> 1250 | K33: =Q33 -> 0 | L33: =R33*$R$1 -> 0 | M33: =S33*$S$1 -> 0 | N33: =T33*$T$1 -> 0 | O33: =E33*I33 -> 13906.25 | P33: 1250
A34: 5 | B34: 柜顶封板 （董事长办公室） | C34: 1、12mm厚阻燃夹板+9.5mm厚石膏板 2、轻钢龙骨 | D34: m2 | E34: =4.45*1.31 -> 5.8295 | F34: =I34 -> 141.5 | G34: =F34*E34 -> 824.87425 | I34: =J34+J34*K34+L34+M34+N34 -> 141.5 | J34: =P34*$P$1 -> 45.5 | K34: =Q34 -> 0 | L34: =R34*$R$1 -> 70 | M34: =S34*$S$1 -> 26 | N34: =T34*$T$1 -> 0 | O34: =E34*I34 -> 824.87425 | P34: =35+10.5 -> 45.5 | R34: =35+20+15 -> 70 | S34: 26
A35: 6 | B35: 柜子 （开放办公区） （不含鱼缸） | C35: 1、规格尺寸：5770*800*2500mm 2、木饰面板柜体； 3、人造石台面，厚度20mm 4、按立面投影面积计算,综合考虑柜体尺寸及内部做法； 5、含包边、饰面、柜体五金、抽屉及其他所需材料安装施工,含低柜水龙头及相关水龙头连接件； 6、满足设计图纸、招标要求及国家有关现行施工及验收规范要求 | D35: m2 | E35: =5.77*2.5 -> 14.425 | F35: =I35 -> 1250 | G35: =F35*E35 -> 18031.25 | I35: =J35+J35*K35+L35+M35+N35 -> 1250 | J35: =P35*$P$1 -> 1250 | K35: =Q35 -> 0 | L35: =R35*$R$1 -> 0 | M35: =S35*$S$1 -> 0 | N35: =T35*$T$1 -> 0 | O35: =E35*I35 -> 18031.25 | P35: 1250
A36: 7 | B36: 柜顶封板 （开放办公区） | C36: 1、12mm厚阻燃夹板+9.5mm厚石膏板 2、轻钢龙骨 | D36: m2 | E36: =5.77*1.31 -> 7.5587 | F36: =I36 -> 141.5 | G36: =F36*E36 -> 1069.556 | I36: =J36+J36*K36+L36+M36+N36 -> 141.5 | J36: =P36*$P$1 -> 45.5 | K36: =Q36 -> 0 | L36: =R36*$R$1 -> 70 | M36: =S36*$S$1 -> 26 | N36: =T36*$T$1 -> 0 | O36: =E36*I36 -> 1069.556 | P36: =35+10.5 -> 45.5 | R36: =35+20+15 -> 70 | S36: 26
A37: 二 | B37: 安装工程 | G37: =SUBTOTAL(9,G38:G53) -> 38929.107
A38: （一） | B38: 强电工程 | G38: =SUBTOTAL(9,G39:G50) -> 31309.107
A39: 1 | B39: 强电部分(不含照明灯具及开关插座) | C39: 1、成天泰2.5、4平方国标电源线； 2、照明线用wdz-byj-2.5m²,每路线负荷220V/2500W; 3、插座线用wdz-byj-4m²,每路线负荷 220V/4000W 4、含人工及镀锌金属线管 | D39: ㎡ | E39: 204 | F39: =I39 -> 90 | G39: =F39*E39 -> 18360 | I39: =J39+J39*K39+L39+M39+N39 -> 90 | J39: =P39*$P$1 -> 30 | K39: =Q39 -> 0 | L39: =R39*$R$1 -> 60 | M39: =S39*$S$1 -> 0 | N39: =T39*$T$1 -> 0 | O39: =E39*I39 -> 18360 | P39: 30 | R39: 60
A40: 2 | B40: 强电配电箱移位 | D40: 个 | E40: 1 | F40: =I40 -> 800 | G40: =F40*E40 -> 800 | I40: =J40+J40*K40+L40+M40+N40 -> 800 | J40: =P40*$P$1 -> 0 | K40: =Q40 -> 0 | L40: =R40*$R$1 -> 800 | M40: =S40*$S$1 -> 0 | N40: =T40*$T$1 -> 0 | O40: =E40*I40 -> 800 | R40: 800
...

Sheet 报价汇总-空调消防
B1: 岁宝壹品苑D栋1906-09-11办公室装修汇总 空调消防
A2: 序号 | B2: 名称 | C2: 金额（元） | D2: 面积（㎡） | E2: 单方价格（元/㎡） | F2: 备注 | G2: 成本
A3: 一 | B3: =空调消防清单!B3 -> 空调工程 | C3: =空调消防清单!G3 -> 43550 | G3: =6000*7 -> 42000
A4: 二 | B4: =空调消防清单!B6 -> 消防改造 | C4: =空调消防清单!G6 -> 26231.231 | G4: =12400+4000 -> 16400
A5: 三 | B5: 合计：一+二 | C5: =C3+C4 -> 69781.231 | G5: =SUM(G3:G4) -> 58400
A6: 四 | B6: 管理费 | C6: =空调消防清单!G33 -> 3489.0615
A7: 五 | B7: 税金 | C7: =空调消防清单!G34 -> 6594.3263
A8: 六 | B8: 合计=三+四+五 | C8: =C5+C6+C7 -> 79864.619 | D8: 204 | E8: =C8/D8 -> 391.49323

Sheet 空调消防清单
A1: 岁宝壹品苑D栋1906-09-11办公室装修清单 空调消防 | I1: =G35 -> 79864.619 | P1: =不含空调消防清单!P1 -> 1 | Q1: =G6 -> 26231.231 | R1: =不含空调消防清单!R1 -> 1 | S1: =不含空调消防清单!S1 -> 1 | T1: =不含空调消防清单!T1 -> 1 | U1: =(18+7+7)*170 -> 5440 | V1: =232.32*30 -> 6969.6 | W1: =U1+V1 -> 12409.6
A2: 序号 | B2: 项目名称 | C2: 项目特征 | D2: 单位 | E2: 工程量 | F2: 综合单价（不含税） | G2: 合价 | H2: 备注 | I2: 成本价 | J2: 主材费 | K2: 主材损耗率 | L2: 人工费 | M2: 辅材费 | N2: 机械费 | O2: 合计 | P2: 主材费 | Q2: 主材损耗率 | R2: 人工费 | S2: 辅材费 | T2: 机械费
A3: 一 | B3: 空调工程 | G3: =SUBTOTAL(9,G4:G5) -> 43550
A4: 1 | B4: 空调风机盘管1P | C4: 1、包含铝合金风口、空调管道、帆布、钢结构支架等 | D4: 台 | E4: 6 | F4: =I4 -> 6150 | G4: =F4*E4 -> 36900 | H4: 品牌：麦克维尔 | I4: =J4+J4*K4+L4+M4+N4 -> 6150 | J4: =P4*$P$1 -> 5800 | K4: =Q4 -> 0 | L4: =R4*$R$1 -> 350 | M4: =S4*$S$1 -> 0 | N4: =T4*$T$1 -> 0 | O4: =E4*I4 -> 36900 | P4: 5800 | R4: 350
A5: 2 | B5: 空调风机盘管2P | C5: 1、包含铝合金风口、空调管道、帆布、钢结构支架等 | D5: 台 | E5: 1 | F5: =I5 -> 6650 | G5: =F5*E5 -> 6650 | H5: 品牌：麦克维尔 | I5: =J5+J5*K5+L5+M5+N5 -> 6650 | J5: =P5*$P$1 -> 6300 | K5: =Q5 -> 0 | L5: =R5*$R$1 -> 350 | M5: =S5*$S$1 -> 0 | N5: =T5*$T$1 -> 0 | O5: =E5*I5 -> 6650 | P5: 6300 | R5: 350
A6: 二 | B6: 消防改造 | G6: =SUBTOTAL(9,G8:G31) -> 26231.231
A7: （一） | B7: 火灾自动报警系统
A8: 1 | B8: 探测器拆除、安装 | C8: 1、含配合装修 | D8: 套 | E8: 2 | F8: =I8 -> 191.4 | G8: =F8*E8 -> 382.8 | I8: 191.4 | J8: =P8*$P$1 -> 0 | K8: =Q8 -> 0 | L8: =R8*$R$1 -> 0 | M8: =S8*$S$1 -> 0 | N8: =T8*$T$1 -> 0 | O8: =E8*I8 -> 382.8
A9: 2 | B9: 探测器新增、安装 | C9: 1、含设备增加及配合装修 | D9: 套 | E9: 6 | F9: =I9 -> 261 | G9: =F9*E9 -> 1566 | I9: 261 | J9: =P9*$P$1 -> 0 | K9: =Q9 -> 0 | L9: =R9*$R$1 -> 0 | M9: =S9*$S$1 -> 0 | N9: =T9*$T$1 -> 0 | O9: =E9*I9 -> 1566
A10: 3 | B10: 消防广播拆除、安装 | C10: 1、含设备增加及配合装修 | D10: 套 | E10: 1 | F10: =I10 -> 191.4 | G10: =F10*E10 -> 191.4 | I10: 191.4 | J10: =P10*$P$1 -> 0 | K10: =Q10 -> 0 | L10: =R10*$R$1 -> 0 | M10: =S10*$S$1 -> 0 | N10: =T10*$T$1 -> 0 | O10: =E10*I10 -> 191.4
A11: 4 | B11: 增加镀锌线管φ20(含配件) | C11: 1、国标 | D11: 米 | E11: =4.95+4.75+3.6+4.1+1.65+8+4+(5.8+5.5+6.2+3.7+9+4.5) -> 65.75 | F11: =I11 -> 24.36 | G11: =F11*E11 -> 1601.67 | I11: 24.36 | J11: =P11*$P$1 -> 0 | K11: =Q11 -> 0 | L11: =R11*$R$1 -> 0 | M11: =S11*$S$1 -> 0 | N11: =T11*$T$1 -> 0 | O11: =E11*I11 -> 1601.67
A12: 5 | B12: 增加金属软管￠ 16（含配件） | C12: 1、国标 | D12: 米 | E12: =7*1 -> 7 | F12: =I12 -> 10.44 | G12: =F12*E12 -> 73.08 | I12: 10.44 | J12: =P12*$P$1 -> 0 | K12: =Q12 -> 0 | L12: =R12*$R$1 -> 0 | M12: =S12*$S$1 -> 0 | N12: =T12*$T$1 -> 0 | O12: =E12*I12 -> 73.08
A13: 6 | B13: 增加ZR-RVS-2x1.5mm² 电线 | C13: 1、国标 | D13: 米 | E13: 32 | F13: =I13 -> 6.96 | G13: =F13*E13 -> 222.72 | I13: 6.96 | J13: =P13*$P$1 -> 0 | K13: =Q13 -> 0 | L13: =R13*$R$1 -> 0 | M13: =S13*$S$1 -> 0 | N13: =T13*$T$1 -> 0 | O13: =E13*I13 -> 222.72
A14: 7 | B14: 报警系统调试 | C14: 1、含设备增加及配合装修 | D14: 项 | E14: 1 | F14: =I14 -> 1000 | G14: =F14*E14 -> 1000 | I14: 1000 | J14: =P14*$P$1 -> 0 | K14: =Q14 -> 0 | L14: =R14*$R$1 -> 0 | M14: =S14*$S$1 -> 0 | N14: =T14*$T$1 -> 0 | O14: =E14*I14 -> 1000
A15: 8 | B15: 灯具电池 | C15: 1、含设备增加及配合装修 | D15: 套 | E15: 7 | F15: =I15 -> 40 | G15: =F15*E15 -> 280 | I15: 40 | J15: =P15*$P$1 -> 0 | K15: =Q15 -> 0 | L15: =R15*$R$1 -> 0 | M15: =S15*$S$1 -> 0 | N15: =T15*$T$1 -> 0 | O15: =E15*I15 -> 280
A16: 9 | B16: 疏散出口指示灯 | C16: 1、含设备增加及配合装修 | D16: 套 | E16: 1 | F16: =I16 -> 115 | G16: =F16*E16 -> 115 | I16: 115 | J16: =P16*$P$1 -> 0 | K16: =Q16 -> 0 | L16: =R16*$R$1 -> 0 | M16: =S16*$S$1 -> 0 | N16: =T16*$T$1 -> 0 | O16: =E16*I16 -> 115
A17: 10 | B17: 编程入网、系统接驳 | C17: 1、由大厦原消防施工单位负责，物业统一收费 | D17: ㎡ | E17: =119.03+113.79 -> 232.82 | F17: =I17 -> 30 | G17: =F17*E17 -> 6984.6 | H17: 不足4000元的按最低4000元计算。超过4000元的按建筑面积30元/㎡计算。 | I17: 30 | J17: =P17*$P$1 -> 0 | K17: =Q17 -> 0 | L17: =R17*$R$1 -> 20 | M17: =S17*$S$1 -> 0 | N17: =T17*$T$1 -> 0 | O17: =E17*I17 -> 6984.6 | R17: 20
A18: （二） | B18: 自动喷淋灭火系统
A19: 1 | B19: 喷头拆除、安装 | C19: 1、含配合装修 | D19: 个 | E19: 12 | F19: =I19 -> 174 | G19: =F19*E19 -> 2088 | I19: 174 | J19: =P19*$P$1 -> 0 | K19: =Q19 -> 0 | L19: =R19*$R$1 -> 0 | M19: =S19*$S$1 -> 0 | N19: =T19*$T$1 -> 0 | O19: =E19*I19 -> 2088
A20: 2 | B20: 喷头新增、安装 | C20: 1、含设备增加 | D20: 个 | E20: 5 | F20: =I20 -> 217.5 | G20: =F20*E20 -> 1087.5 | I20: 217.5 | J20: =P20*$P$1 -> 0 | K20: =Q20 -> 0 | L20: =R20*$R$1 -> 0 | M20: =S20*$S$1 -> 0 | N20: =T20*$T$1 -> 0 | O20: =E20*I20 -> 1087.5
A21: 3 | B21: 管网支吊架 | C21: 1、含配合装修 | D21: KG | E21: 40 | F21: =I21 -> 21.75 | G21: =F21*E21 -> 870 | I21: 21.75 | J21: =P21*$P$1 -> 0 | K21: =Q21 -> 0 | L21: =R21*$R$1 -> 0 | M21: =S21*$S$1 -> 0 | N21: =T21*$T$1 -> 0 | O21: =E21*I21 -> 870
A22: 4 | B22: 大红油漆（含人工及天那水） | C22: 1、含油漆、天那水、人工 | D22: 桶 | E22: 1 | F22: =I22 -> 435 | G22: =F22*E22 -> 435 | I22: 435 | J22: =P22*$P$1 -> 0 | K22: =Q22 -> 0 | L22: =R22*$R$1 -> 0 | M22: =S22*$S$1 -> 0 | N22: =T22*$T$1 -> 0 | O22: =E22*I22 -> 435
A23: 5 | B23: 新增镀锌水管DN25 | C23: 1、含材料以及人工安装费用 | D23: 米 | E23: =1.3*15+2.1*3+3.25*4+3.2+0.85 -> 42.85 | F23: =I23 -> 50.46 | G23: =F23*E23 -> 2162.211 | I23: 50.46 | J23: =P23*$P$1 -> 0 | K23: =Q23 -> 0 | L23: =R23*$R$1 -> 0 | M23: =S23*$S$1 -> 0 | N23: =T23*$T$1 -> 0 | O23: =E23*I23 -> 2162.211
A24: 6 | B24: 新增镀锌水管DN32 | C24: 1、含材料以及人工安装费用 | D24: 米 | E24: =4.3+2+3+1*2+2.5 -> 13.8 | F24: =I24 -> 56.55 | G24: =F24*E24 -> 780.39 | I24: 56.55 | J24: =P24*$P$1 -> 0 | K24: =Q24 -> 0 | L24: =R24*$R$1 -> 0 | M24: =S24*$S$1 -> 0 | N24: =T24*$T$1 -> 0 | O24: =E24*I24 -> 780.39
A25: 7 | B25: 新增镀锌水管DN40 | C25: 1、含材料以及人工安装费用 | D25: 米 | E25: 2.5 | F25: =I25 -> 65.25 | G25: =F25*E25 -> 163.125 | I25: 65.25 | J25: =P25*$P$1 -> 0 | K25: =Q25 -> 0 | L25: =R25*$R$1 -> 0 | M25: =S25*$S$1 -> 0 | N25: =T25*$T$1 -> 0 | O25: =E25*I25 -> 163.125
A26: 8 | B26: 新增镀锌水管DN50 | C26: 1、含材料以及人工安装费用 | D26: 米 | E26: =1.5+2.5+3+1.5 -> 8.5 | F26: =I26 -> 80.91 | G26: =F26*E26 -> 687.735 | I26: 80.91 | J26: =P26*$P$1 -> 0 | K26: =Q26 -> 0 | L26: =R26*$R$1 -> 0 | M26: =S26*$S$1 -> 0 | N26: =T26*$T$1 -> 0 | O26: =E26*I26 -> 687.735
A27: 9 | B27: 喷淋管网排水费 | C27: 1、含管网排水费 及人工 | D27: 项 | E27: 1 | F27: =I27 -> 800 | G27: =F27*E27 -> 800 | I27: 800 | J27: =P27*$P$1 -> 0 | K27: =Q27 -> 0 | L27: =R27*$R$1 -> 0 | M27: =S27*$S$1 -> 0 | N27: =T27*$T$1 -> 0 | O27: =E27*I27 -> 800
A28: 10 | B28: 喷淋管网试压 | C28: 1、管网冲洗、试 压、调试 | D28: 项 | E28: 1 | F28: =I28 -> 870 | G28: =F28*E28 -> 870 | I28: 870 | J28: =P28*$P$1 -> 0 | K28: =Q28 -> 0 | L28: =R28*$R$1 -> 0 | M28: =S28*$S$1 -> 0 | N28: =T28*$T$1 -> 0 | O28: =E28*I28 -> 870
A29: （四） | B29: 其他
A30: 1 | B30: 消防报验 | C30: 含相关部门收取的报验费用。 | D30: 项 | E30: 1 | F30: =I30 -> 3000 | G30: =F30*E30 -> 3000 | I30: 3000 | J30: =P30*$P$1 -> 0 | K30: =Q30 -> 0 | L30: =R30*$R$1 -> 0 | M30: =S30*$S$1 -> 0 | N30: =T30*$T$1 -> 0 | O30: =E30*I30 -> 3000
A31: 2 | B31: 综合专业设计出图 | D31: 套 | E31: 1 | F31: =I31 -> 870 | G31: =F31*E31 -> 870 | I31: 870
A32: 三 | B32: 小计 | D32: 项 | E32: 1 | G32: =G3+G6 -> 69781.231 | I32: =SUBTOTAL(9,G3:G31) -> 69781.231
A33: 四 | B33: 管理费 | C33: =不含空调消防清单!C63 -> 0.05 | D33: 项 | E33: 1 | G33: =G32*C33 -> 3489.0615
A34: 五 | B34: 税金 | C34: =不含空调消防清单!C64 -> 0.09 | D34: 项 | E34: 1 | G34: =(G32+G33)*C34 -> 6594.3263
A35: 六 | B35: 合计 | D35: 项 | E35: 1 | G35: =G34+G33+G32 -> 79864.619
