Workbook

Sheet 报价汇总-装修工程
B1: 岁宝壹品苑D栋3901办公室装修汇总 装修工程
A2: 序号 | B2: 名称 | C2: 金额（元） | D2: 面积（㎡） | E2: 单方价格（元/㎡） | F2: 备注
A3: 一 | B3: 装饰工程 | C3: =不含空调消防清单!G3 -> 169645.07 | G3: 成本
A4: （一） | B4: 隔墙工程 | C4: =不含空调消防清单!G4 -> 53466.411 | G4: 装饰 | H4: =不含空调消防清单!G92 -> 239782.42
A5: （二） | B5: 地面工程 | C5: =不含空调消防清单!G22 -> 34168.421 | G5: 空调 | H5: 48600
A6: （三） | B6: 天花工程 | C6: =不含空调消防清单!G28 -> 37942.385 | G6: 消防 | H6: 12500
A7: （四） | B7: 墙面工程 | C7: =不含空调消防清单!G41 -> 21072.015 | G7: 合计 | H7: =SUM(H4:H6) -> 300882.42
A8: （五） | B8: 固定家具及门窗工程 | C8: =不含空调消防清单!G48 -> 22995.837 | H8: =C13+C14+'报价汇总-空调消防'!C5+'报价汇总-空调消防'!C6 -> 344019.41
A9: 二 | B9: 安装工程 | C9: =不含空调消防清单!G66 -> 45325.202 | H9: =(H8-H7)/H7 -> 0.14336827
A10: （一） | B10: 强电工程 | C10: =不含空调消防清单!G67 -> 37343.602
A11: （二） | B11: 弱电工程 | C11: =不含空调消防清单!G81 -> 7981.6
A12: 三 | B12: 其他工程 | C12: =不含空调消防清单!G84 -> 24812.15
A13: 四 | B13: 小计：一+二+三 | C13: =C3+C9+C12 -> 239782.42
A14: 五 | B14: 管理费 | C14: =不含空调消防清单!G93 -> 8392.3847
A15: 六 | B15: 税金 | C15: 0
A16: 七 | B16: 装饰合计=四+五+六 （不含消防空调） | C16: =C13+C14+C15 -> 248174.8 | D16: =193.06+0.7 -> 193.76 | E16: =C16/D16 -> 1280.8361 | F16: 建筑面积319.15㎡
A17: 八 | B17: 消防空调 | C17: ='报价汇总-空调消防'!C8 -> 95844.607 | D17: =$D$16 -> 193.76 | E17: =C17/D17 -> 494.65631
A18: 九 | B18: 总计: （装饰+消防空调） | C18: =C16+C17 -> 344019.41 | D18: =$D$16 -> 193.76 | E18: =C18/D18 -> 1775.4924 | F18: =F16 -> 建筑面积319.15㎡

Sheet 不含空调消防清单
A1: 岁宝壹品苑D栋3901办公室装修清单 （不含空调消防） | I1: =G95 -> 248174.8 | Q1: 1 | S1: 1 | T1: =$Q$1 -> 1 | U1: =$Q$1 -> 1 | V1: ='报价汇总-装修工程'!G17 -> 0
A2: 序号 | B2: 项目名称 | C2: 项目特征 | D2: 单位 | E2: 工程量 | F2: 综合单价（不含税） | G2: 合价 | H2: 备注 | I2: 综合单价（不含税） | J2: 主材费 | K2: 主材损耗率 | L2: 人工费 | M2: 辅材费 | N2: 机械费 | O2: 合计 | P2: 成本价 | Q2: 主材费 | R2: 主材损耗率 | S2: 人工费 | T2: 辅材费 | U2: 机械费 | V2: 成本合计
A3: 一 | B3: 装饰工程 | G3: =SUBTOTAL(9,G4:G65) -> 169645.07
A4: （一） | B4: 隔墙工程 | G4: =SUBTOTAL(9,G5:G21) -> 53466.411
A5: 1 | B5: 拆除原有砖墙 （150mm厚） | C5: 1、人工拆除 2、机械设备 3、防护措施 4、垃圾清理装袋 | D5: ㎡ | E5: =(1.7+1)*2.8 -> 7.56 | F5: =I5 -> 100 | G5: =F5*E5 -> 756 | I5: =J5+J5*K5+L5+M5+N5 -> 100 | J5: =Q5*$Q$1 -> 0 | K5: =R5 -> 0 | L5: =S5*$S$1 -> 70 | M5: =T5*$T$1 -> 30 | N5: =U5*$U$1 -> 0 | O5: =E5*I5 -> 756 | P5: =Q5+Q5*R5+S5+T5+U5 -> 100 | S5: 70 | T5: 30 | V5: =E5*P5 -> 756
A6: 2 | B6: 门洞顶部横梁槽钢加固 | C6: 1、原墙面开门洞后横梁槽钢加固 | D6: m | E6: =1.7+1+0.2*4 -> 3.5 | F6: =I6 -> 500 | G6: =F6*E6 -> 1750 | I6: =J6+J6*K6+L6+M6+N6 -> 500 | J6: =Q6*$Q$1 -> 300 | K6: =R6 -> 0 | L6: =S6*$S$1 -> 200 | M6: =T6*$T$1 -> 0 | N6: =U6*$U$1 -> 0 | O6: =E6*I6 -> 1750 | P6: =Q6+Q6*R6+S6+T6+U6 -> 500 | Q6: 300 | S6: 200 | V6: =E6*P6 -> 1750
A7: 3 | B7: 门洞侧边水泥砂浆修补 | C7: 1、门洞侧边水泥砂浆修补 | D7: m | E7: =(2.8*4+3.5) -> 14.7 | F7: =I7 -> 41.12 | G7: =F7*E7 -> 604.464 | I7: =J7+J7*K7+L7+M7+N7 -> 41.12 | J7: =Q7*$Q$1 -> 6 | K7: =R7 -> 0.02 | L7: =S7*$S$1 -> 35 | M7: =T7*$T$1 -> 0 | N7: =U7*$U$1 -> 0 | O7: =E7*I7 -> 604.464 | P7: =Q7+Q7*R7+S7+T7+U7 -> 41.12 | Q7: =12*0.5 -> 6 | R7: 0.02 | S7: 35 | V7: =E7*P7 -> 604.464
A8: 4 | B8: 门洞侧边12mm阻燃夹板封边 | C8: 1、原墙面开门洞后12mm阻燃夹板封边 | D8: m | E8: =(2.8*4+3.5) -> 14.7 | F8: =I8 -> 25.6 | G8: =F8*E8 -> 376.32 | I8: =J8+J8*K8+L8+M8+N8 -> 25.6 | J8: =Q8*$Q$1 -> 5.6 | K8: =R8 -> 0 | L8: =S8*$S$1 -> 20 | M8: =T8*$T$1 -> 0 | N8: =U8*$U$1 -> 0 | O8: =E8*I8 -> 376.32 | P8: =Q8+Q8*R8+S8+T8+U8 -> 25.6 | Q8: =28*0.2 -> 5.6 | S8: 20 | V8: =E8*P8 -> 376.32
A9: 5 | B9: 新建轻质砖墙-旧门洞封堵 （150mm厚） | C9: 1、成品砂浆、15#轻质砖 2、完成面150mm厚 | D9: ㎡ | E9: =1.5*2.2*2 -> 6.6 | F9: =I9 -> 98.4 | G9: =F9*E9 -> 649.44 | I9: =J9+J9*K9+L9+M9+N9 -> 98.4 | J9: =Q9*$Q$1 -> 42.9 | K9: =R9 -> 0 | L9: =S9*$S$1 -> 45 | M9: =T9*$T$1 -> 10 | N9: =U9*$U$1 -> 0.5 | O9: =E9*I9 -> 649.44 | P9: =Q9+Q9*R9+S9+T9+U9 -> 98.4 | Q9: =286*0.15 -> 42.9 | R9: 0 | S9: 45 | T9: 10 | U9: 0.5 | V9: =E9*P9 -> 649.44
A10: 6 | B10: 内墙水泥砂浆抹灰 | C10: 1、基层墙体：砌体墙、混凝土墙 2、厚度：20mm 3、做法：墙面基层清理，不同界面交接处、阴角转角处、管线开槽处，挂镀锌电焊网，公区人流通道等局部砌体墙满挂镀锌电焊网，面层压入1道耐碱网格布，水泥砂浆找平、压实抹光； | D10: ㎡ | E10: =3.93*(30.85+5.6)-(1+1.7)*2.8+6.6 -> 142.2885 | F10: =I10 -> 39 | G10: =F10*E10 -> 5549.2515 | I10: =J10+J10*K10+L10+M10+N10 -> 39 | J10: =Q10*$Q$1 -> 0 | K10: =R10 -> 0.01 | L10: =S10*$S$1 -> 30 | M10: =T10*$T$1 -> 8.5 | N10: =U10*$U$1 -> 0.5 | O10: =E10*I10 -> 5549.2515 | P10: =Q10+Q10*R10+S10+T10+U10 -> 39 | R10: 0.01 | S10: 30 | T10: 8.5 | U10: 0.5 | V10: =E10*P10 -> 5549.2515
A11: 7 | B11: 轻钢龙骨隔墙 | C11: 双层双面轻钢龙骨隔墙 1、墙厚120mm; 2、75mm轻钢龙骨； 3、50mm厚，48kg/m3的吸音棉； 4、12mm阻燃夹板+9.5mm厚石膏板 | D11: ㎡ | E11: =E12 -> 141.1207 | I11: =J11+J11*K11+L11+M11+N11 -> 0 | J11: =Q11*$Q$1 -> 0 | K11: =R11 -> 0 | L11: =S11*$S$1 -> 0 | M11: =T11*$T$1 -> 0 | N11: =U11*$U$1 -> 0 | O11: =E11*I11 -> 0 | P11: =Q11+Q11*R11+S11+T11+U11 -> 0 | V11: =E11*P11 -> 0
A12: 7.1 | B12: 轻钢龙骨 | C12: 1、天地龙骨 2、竖龙骨 3、穿心龙骨 4、其他辅材 | D12: ㎡ | E12: =3.93*(1.17+2.56+11.05+7.5+5.07+5.07+5.17)-0.85*2.8*2-0.66*2.8 -> 141.1207 | F12: =I12 -> 53.5 | G12: =F12*E12 -> 7549.9574 | I12: =J12+J12*K12+L12+M12+N12 -> 53.5 | J12: =Q12*$Q$1 -> 26 | K12: =R12 -> 0 | L12: =S12*$S$1 -> 26 | M12: =T12*$T$1 -> 0 | N12: =U12*$U$1 -> 1.5 | O12: =E12*I12 -> 7549.9574 | P12: =Q12+Q12*R12+S12+T12+U12 -> 53.5 | Q12: 26 | S12: 26 | U12: 1.5 | V12: =E12*P12 -> 7549.9574
A13: 7.2 | B13: 50mm厚吸音棉 | C13: 1、50mm厚，48kg/m3的吸音棉 | D13: ㎡ | E13: =E12 -> 141.1207 | F13: =I13 -> 21.65 | G13: =F13*E13 -> 3055.2632 | I13: =J13+J13*K13+L13+M13+N13 -> 21.65 | J13: =Q13*$Q$1 -> 11.65 | K13: =R13 -> 0 | L13: =S13*$S$1 -> 10 | M13: =T13*$T$1 -> 0 | N13: =U13*$U$1 -> 0 | O13: =E13*I13 -> 3055.2632 | P13: =Q13+Q13*R13+S13+T13+U13 -> 21.65 | Q13: 11.65 | S13: 10 | V13: =E13*P13 -> 3055.2632
A14: 7.3 | B14: 12mm阻燃夹板 | C14: 1、双面单层12mm阻燃夹板打底 | D14: ㎡ | E14: =E12*2 -> 282.2414 | F14: =I14 -> 50.8 | G14: =F14*E14 -> 14337.863 | I14: =J14+J14*K14+L14+M14+N14 -> 50.8 | J14: =Q14*$Q$1 -> 28 | K14: =R14 -> 0 | L14: =S14*$S$1 -> 22 | M14: =T14*$T$1 -> 0.8 | N14: =U14*$U$1 -> 0 | O14: =E14*I14 -> 14337.863 | P14: =Q14+Q14*R14+S14+T14+U14 -> 50.8 | Q14: 28 | S14: 22 | T14: 0.8 | V14: =E14*P14 -> 14337.863
A15: 7.4 | B15: 9.5mm厚石膏板 | C15: 1、双面单层9.5mm厚石膏板 | D15: ㎡ | E15: =E12*2 -> 282.2414 | F15: =I15 -> 26.3 | G15: =F15*E15 -> 7422.9488 | I15: =J15+J15*K15+L15+M15+N15 -> 26.3 | J15: =Q15*$Q$1 -> 7.5 | K15: =R15 -> 0 | L15: =S15*$S$1 -> 18 | M15: =T15*$T$1 -> 0.8 | N15: =U15*$U$1 -> 0 | O15: =E15*I15 -> 7422.9488 | P15: =Q15+Q15*R15+S15+T15+U15 -> 26.3 | Q15: =7.5 -> 7.5 | S15: 18 | T15: 0.8 | V15: =E15*P15 -> 7422.9488
A16: 8 | B16: GL-01 中空钢化玻璃隔断（含免漆板隔断） | C16: 1、GL-01 5+5mm钢化玻璃; 2、铝框包边 3、五金配件等制作安装 | D16: ㎡ | E16: =2.8*(8.97+3)-0.85*2.8*4 -> 23.996 | F16: =I16 -> 325 | G16: =F16*E16 -> 7798.7 | I16: =J16+J16*K16+L16+M16+N16 -> 325 | J16: =Q16*$Q$1 -> 300 | K16: =R16 -> 0.01 | L16: =S16*$S$1 -> 10 | M16: =T16*$T$1 -> 10.5 | N16: =U16*$U$1 -> 1.5 | O16: =E16*I16 -> 7798.7 | P16: =Q16+Q16*R16+S16+T16+U16 -> 325 | Q16: 300 | R16: 0.01 | S16: 10 | T16: 10.5 | U16: 1.5 | V16: =E16*P16 -> 7798.7
A17: 9 | B17: 钢化玻璃隔断上方封板 | C17: 双层双面钢结构龙骨隔墙 1、墙厚120mm; 2、钢结构龙骨； 3、50mm厚，48kg/m3的吸音棉； 4、12mm厚阻燃夹板+9.5mm厚石膏板 | D17: ㎡ | E17: =E18 -> 13.5261
A18: 9.1 | B18: 钢结构龙骨 | C18: 1、钢结构龙骨 2、刷防锈漆 3、其他辅材 | D18: ㎡ | E18: =1.13*(8.97+3) -> 13.5261 | F18: =I18 -> 91.5 | G18: =F18*E18 -> 1237.6381 | I18: =J18+J18*K18+L18+M18+N18 -> 91.5 | J18: =Q18*$Q$1 -> 55 | K18: =R18 -> 0 | L18: =S18*$S$1 -> 35 | M18: =T18*$T$1 -> 0 | N18: =U18*$U$1 -> 1.5 | O18: =E18*I18 -> 1237.6381 | P18: =Q18+Q18*R18+S18+T18+U18 -> 91.5 | Q18: 55 | S18: 35 | U18: 1.5 | V18: =E18*P18 -> 1237.6381
A19: 9.2 | B19: 50mm厚吸音棉 | C19: 1、50mm厚，48kg/m3的吸音棉 | D19: ㎡ | E19: =E18 -> 13.5261 | F19: =I19 -> 21.65 | G19: =F19*E19 -> 292.84006 | I19: =J19+J19*K19+L19+M19+N19 -> 21.65 | J19: =Q19*$Q$1 -> 11.65 | K19: =R19 -> 0 | L19: =S19*$S$1 -> 10 | M19: =T19*$T$1 -> 0 | N19: =U19*$U$1 -> 0 | O19: =E19*I19 -> 292.84006 | P19: =Q19+Q19*R19+S19+T19+U19 -> 21.65 | Q19: 11.65 | S19: 10 | V19: =E19*P19 -> 292.84006
A20: 9.3 | B20: 12mm阻燃夹板 | C20: 1、单层12mm阻燃夹板打底 | D20: ㎡ | E20: =E18*2 -> 27.0522 | F20: =I20 -> 50.8 | G20: =F20*E20 -> 1374.2518 | I20: =J20+J20*K20+L20+M20+N20 -> 50.8 | J20: =Q20*$Q$1 -> 28 | K20: =R20 -> 0 | L20: =S20*$S$1 -> 22 | M20: =T20*$T$1 -> 0.8 | N20: =U20*$U$1 -> 0 | O20: =E20*I20 -> 1374.2518 | P20: =Q20+Q20*R20+S20+T20+U20 -> 50.8 | Q20: 28 | S20: 22 | T20: 0.8 | V20: =E20*P20 -> 1374.2518
A21: 9.4 | B21: 9.5mm厚石膏板 | C21: 1、双面单层9.5mm厚石膏板 | D21: ㎡ | E21: =E18*2 -> 27.0522 | F21: =I21 -> 26.3 | G21: =F21*E21 -> 711.47286 | I21: =J21+J21*K21+L21+M21+N21 -> 26.3 | J21: =Q21*$Q$1 -> 7.5 | K21: =R21 -> 0 | L21: =S21*$S$1 -> 18 | M21: =T21*$T$1 -> 0.8 | N21: =U21*$U$1 -> 0 | O21: =E21*I21 -> 711.47286 | P21: =Q21+Q21*R21+S21+T21+U21 -> 26.3 | Q21: =7.5 -> 7.5 | S21: =$S$15 -> 18 | T21: 0.8 | V21: =E21*P21 -> 711.47286
A22: （二） | B22: 地面工程 | G22: =SUBTOTAL(9,G23:G27) -> 34168.421
A23: 1 | B23: 100mm厚陶粒拌混泥土垫层 | C23: 1、100mm厚陶粒拌混泥土垫层 | D23: ㎡ | E23: 35.33 | F23: =I23 -> 76.93 | G23: =F23*E23 -> 2717.9369 | I23: =J23+J23*K23+L23+M23+N23 -> 76.93 | J23: =Q23*$Q$1 -> 43 | K23: =R23 -> 0.01 | L23: =S23*$S$1 -> 30 | M23: =T23*$T$1 -> 3.5 | N23: =U23*$U$1 -> 0 | O23: =E23*I23 -> 2717.9369 | P23: =Q23+Q23*R23+S23+T23+U23 -> 76.93 | Q23: 43 | R23: 0.01 | S23: 30 | T23: 3.5 | U23: 0 | V23: =E23*P23 -> 2717.9369
A24: 2 | B24: 地面块料 | C24: 1、CT-01灰色地砖 2、瓷砖规格：750*1500 3、瓷砖专用胶泥结合层，厚度包干，后期不因厚度调整价格； 4、白水泥擦缝 | D24: ㎡ | E24: 35.33 | F24: =I24 -> 142.3 | G24: =F24*E24 -> 5027.459 | I24: =J24+J24*K24+L24+M24+N24 -> 142.3 | J24: =Q24*$Q$1 -> 65 | K24: =R24 -> 0.02 | L24: =S24*$S$1 -> 60 | M24: =T24*$T$1 -> 16 | N24: =U24*$U$1 -> 0 | O24: =E24*I24 -> 5027.459 | P24: =Q24+Q24*R24+S24+T24+U24 -> 142.3 | Q24: 65 | R24: 0.02 | S24: 60 | T24: 16 | V24: =E24*P24 -> 5027.459
A25: 3 | B25: 美缝 | C25: 1、专业美缝剂美缝 | D25: ㎡ | E25: 35.33 | F25: 0 | G25: =F25*E25 -> 0 | I25: =J25+J25*K25+L25+M25+N25 -> 20 | J25: =Q25*$Q$1 -> 0 | K25: =R25 -> 0.02 | L25: =S25*$S$1 -> 16 | M25: =T25*$T$1 -> 4 | N25: =U25*$U$1 -> 0 | O25: =E25*I25 -> 706.6 | P25: =Q25+Q25*R25+S25+T25+U25 -> 20 | R25: 0.02 | S25: 16 | T25: 4 | V25: =E25*P25 -> 706.6
A26: 4 | B26: 地面架空层 | C26: 1、100mm高 2、500*500mm架空地板 | D26: ㎡ | E26: =54.41+18.93+4.79+13.74+12.77+11.76+20.26+6.09 -> 142.75 | F26: =I26 -> 128.75 | G26: =F26*E26 -> 18379.062 | I26: =J26+J26*K26+L26+M26+N26 -> 128.75 | J26: =Q26*$Q$1 -> 125 | K26: =R26 -> 0.03 | L26: =S26*$S$1 -> 0 | M26: =T26*$T$1 -> 0 | N26: =U26*$U$1 -> 0 | O26: =E26*I26 -> 18379.062 | P26: =Q26+Q26*R26+S26+T26+U26 -> 128.75 | Q26: 125 | R26: 0.03 | S26: 0 | T26: 0 | V26: =E26*P26 -> 18379.062
A27: 5 | B27: 地面地毯 | C27: 1、规格尺寸：500*500 2、地毯专用胶，厚度包干，后期不因厚度调整价格； | D27: ㎡ | E27: =E26 -> 142.75 | F27: =I27 -> 56.35 | G27: =F27*E27 -> 8043.9625 | I27: =J27+J27*K27+L27+M27+N27 -> 56.35 | J27: =Q27*$Q$1 -> 45 | K27: =R27 -> 0.03 | L27: =S27*$S$1 -> 5 | M27: =T27*$T$1 -> 5 | N27: =U27*$U$1 -> 0 | O27: =E27*I27 -> 8043.9625 | P27: =Q27+Q27*R27+S27+T27+U27 -> 56.35 | Q27: 45 | R27: 0.03 | S27: 5 | T27: 5 | V27: =E27*P27 -> 8043.9625
A28: （三） | B28: 天花工程 | G28: =SUBTOTAL(9,G29:G40) -> 37942.385
A29: 1 | B29: 原天棚喷乳胶漆PT-02 (含墙体上部) | C29: 1、面层：PT-02深色涂料两遍 2、包含各种管道 | D29: ㎡ | E29: =45.22+1.13*(26.95-13.47) -> 60.4524 | F29: =I29 -> 20.16 | G29: =F29*E29 -> 1218.7204 | I29: =J29+J29*K29+L29+M29+N29 -> 20.16 | J29: =Q29*$Q$1 -> 8 | K29: =R29 -> 0.02 | L29: =S29*$S$1 -> 10 | M29: =T29*$T$1 -> 0.5 | N29: =U29*$U$1 -> 1.5 | O29: =E29*I29 -> 1218.7204 | P29: =Q29+Q29*R29+S29+T29+U29 -> 20.16 | Q29: 8 | R29: 0.02 | S29: 10 | T29: 0.5 | U29: 1.5 | V29: =E29*P29 -> 1218.7204
A30: 2 | B30: 办公室高晶硅钙板吊顶 | C30: 1、吊顶形式：平级 2、基层：轻钢龙骨+高晶硅钙板 3.含各种灯具、检修口、风口开口 | D30: ㎡ | E30: =20.26 -> 20.26 | F30: =I30 -> 128.3 | G30: =F30*E30 -> 2599.358 | I30: =J30+J30*K30+L30+M30+N30 -> 128.3 | J30: =Q30*$Q$1 -> 65 | K30: =R30 -> 0.02 | L30: =S30*$S$1 -> 60 | M30: =T30*$T$1 -> 0.5 | N30: =U30*$U$1 -> 1.5 | O30: =E30*I30 -> 2599.358 | P30: =Q30+Q30*R30+S30+T30+U30 -> 128.3 | Q30: 65 | R30: 0.02 | S30: 60 | T30: 0.5 | U30: 1.5 | V30: =E30*P30 -> 2599.358
A31: 3 | B31: 石膏板天花吊顶 | C31: 1、吊顶形式：平级+跌级吊顶 2、基层：轻钢龙骨+双层9.5mm厚石膏板 3.含各种灯具、检修口、风口开口 | D31: ㎡
A32: 3.1 | B32: 轻钢龙骨 | C32: 1、轻钢龙骨吊顶 2、其他辅材 | D32: ㎡ | E32: =54.41-45.22+35.33+18.93+4.79+13.74+12.77+11.76+6.09 -> 112.6 | F32: =I32 -> 71.5 | G32: =F32*E32 -> 8050.9 | I32: =J32+J32*K32+L32+M32+N32 -> 71.5 | J32: =Q32*$Q$1 -> 0 | K32: =R32 -> 0 | L32: =S32*$S$1 -> 35 | M32: =T32*$T$1 -> 35 | N32: =U32*$U$1 -> 1.5 | O32: =E32*I32 -> 8050.9 | P32: =Q32+Q32*R32+S32+T32+U32 -> 71.5 | S32: 35 | T32: 35 | U32: 1.5 | V32: =E32*P32 -> 8050.9
A33: 3.2 | B33: 12mm阻燃夹板 | C33: 1、12mm阻燃夹板 | D33: ㎡ | E33: =E32 -> 112.6 | F33: =I33 -> 48.8 | G33: =F33*E33 -> 5494.88 | I33: =J33+J33*K33+L33+M33+N33 -> 48.8 | J33: =Q33*$Q$1 -> 28 | K33: =R33 -> 0 | L33: =S33*$S$1 -> 20 | M33: =T33*$T$1 -> 0.8 | N33: =U33*$U$1 -> 0 | O33: =E33*I33 -> 5494.88 | P33: =Q33+Q33*R33+S33+T33+U33 -> 48.8 | Q33: 28 | S33: 20 | T33: 0.8 | V33: =E33*P33 -> 5494.88
A34: 3.3 | B34: 9.5mm厚石膏板 | C34: 1、双面单层9.5mm厚石膏板 | D34: ㎡ | E34: =E32 -> 112.6 | F34: =I34 -> 26.3 | G34: =F34*E34 -> 2961.38 | I34: =J34+J34*K34+L34+M34+N34 -> 26.3 | J34: =Q34*$Q$1 -> 7.5 | K34: =R34 -> 0 | L34: =S34*$S$1 -> 18 | M34: =T34*$T$1 -> 0.8 | N34: =U34*$U$1 -> 0 | O34: =E34*I34 -> 2961.38 | P34: =Q34+Q34*R34+S34+T34+U34 -> 26.3 | Q34: =7.5 -> 7.5 | S34: =$S$15 -> 18 | T34: 0.8 | V34: =E34*P34 -> 2961.38
A35: 4 | B35: 天花板缝贴纸带刮平整 | D35: ㎡ | E35: =54.41-45.22+35.33+18.93+4.79+13.74+12.77+11.76+20.26+6.09+1.13*13.47 -> 148.0811 | F35: =I35 -> 8.5 | G35: =F35*E35 -> 1258.6894 | I35: =J35+J35*K35+L35+M35+N35 -> 8.5 | J35: =Q35*$Q$1 -> 3.5 | K35: =R35 -> 0 | L35: =S35*$S$1 -> 5 | M35: =T35*$T$1 -> 0 | N35: =U35*$U$1 -> 0 | O35: =E35*I35 -> 1258.6894 | P35: =Q35+Q35*R35+S35+T35+U35 -> 8.5 | Q35: 3.5 | R35: 0 | S35: 5 | T35: 0 | U35: 0 | V35: =E35*P35 -> 1258.6894
A36: 5 | B36: 天花挂耐水腻子 | C36: 1、耐水腻子2道，含打磨、修补 | D36: ㎡ | E36: =E35 -> 148.0811 | F36: =I36 -> 21.5 | G36: =F36*E36 -> 3183.7436 | I36: =J36+J36*K36+L36+M36+N36 -> 21.5 | J36: =Q36*$Q$1 -> 3.5 | K36: =R36 -> 0 | L36: =S36*$S$1 -> 18 | M36: =T36*$T$1 -> 0 | N36: =U36*$U$1 -> 0 | O36: =E36*I36 -> 3183.7436 | P36: =Q36+Q36*R36+S36+T36+U36 -> 21.5 | Q36: 3.5 | R36: 0 | S36: 18 | T36: 0 | U36: 0 | V36: =E36*P36 -> 3183.7436
A37: 6 | B37: 天棚乳胶漆 | C37: 1、面层：PT-01无机白色涂料一底二面 | D37: ㎡ | E37: =E35 -> 148.0811 | F37: =I37 -> 13 | G37: =F37*E37 -> 1925.0543 | I37: =J37+J37*K37+L37+M37+N37 -> 13 | J37: =Q37*$Q$1 -> 3 | K37: =R37 -> 0 | L37: =S37*$S$1 -> 10 | M37: =T37*$T$1 -> 0 | N37: =U37*$U$1 -> 0 | O37: =E37*I37 -> 1925.0543 | P37: =Q37+Q37*R37+S37+T37+U37 -> 13 | Q37: 3 | R37: 0 | S37: 10 | T37: 0 | U37: 0 | V37: =E37*P37 -> 1925.0543
A38: 7 | B38: 天花灯槽 | C38: 1、规格：100*100*100mm天花灯槽 2、基层：轻钢龙骨 3、面层：12mm厚阻燃夹板+9.5mm厚石膏板 | D38: m | E38: =3.08+8.66+9.7 -> 21.44 | F38: =I38 -> 70 | G38: =F38*E38 -> 1500.8 | I38: =J38+J38*K38+L38+M38+N38 -> 70 | J38: =Q38*$Q$1 -> 13.5 | K38: =R38 -> 0 | L38: =S38*$S$1 -> 55 | M38: =T38*$T$1 -> 1.5 | N38: =U38*$U$1 -> 0 | O38: =E38*I38 -> 1500.8 | P38: =Q38+Q38*R38+S38+T38+U38 -> 70 | Q38: =0.3*(35+10) -> 13.5 | S38: 55 | T38: 1.5 | V38: =E38*P38 -> 1500.8
A39: 8 | B39: 窗帘盒 | C39: 1、基层：钢结构龙骨+阻燃板基层 2、面层：9.5mm厚石膏板 | D39: m | E39: =10.68+3.4+2.4+2.85+3.48+2.68+5.28 -> 30.77 | F39: =I39 -> 171.23 | G39: =F39*E39 -> 5268.7471 | I39: =J39+J39*K39+L39+M39+N39 -> 171.23 | J39: =Q39*$Q$1 -> 107.73 | K39: =R39 -> 0 | L39: =S39*$S$1 -> 55 | M39: =T39*$T$1 -> 8.5 | N39: =U39*$U$1 -> 0 | O39: =E39*I39 -> 5268.7471 | P39: =Q39+Q39*R39+S39+T39+U39 -> 171.23 | Q39: =4.2*5.7*4.5 -> 107.73 | S39: 55 | T39: 8.5 | V39: =E39*P39 -> 5268.7471
A40: 9 | B40: 窗帘 | C40: 1、成品窗帘 | D40: ㎡ | E40: =(10.68+3.4+2.4+2.85+3.48+2.68+5.28)*2.8 -> 86.156 | F40: =I40 -> 52 | G40: =F40*E40 -> 4480.112 | I40: =J40+J40*K40+L40+M40+N40 -> 52 | J40: =Q40*$Q$1 -> 45 | K40: =R40 -> 0 | L40: =S40*$S$1 -> 5 | M40: =T40*$T$1 -> 1.5 | N40: =U40*$U$1 -> 0.5 | O40: =E40*I40 -> 4480.112 | P40: =Q40+Q40*R40+S40+T40+U40 -> 52 | Q40: 45 | S40: 5 | T40: 1.5 | U40: 0.5 | V40: =E40*P40 -> 4480.112
...

Sheet 报价汇总-空调消防
B1: 岁宝壹品苑D栋3901办公室装修汇总 空调消防
A2: 序号 | B2: 名称 | C2: 金额（元） | D2: 面积（㎡） | E2: 单方价格（元/㎡） | F2: 备注
A3: 一 | B3: =空调消防清单!B3 -> 空调工程 | C3: =空调消防清单!G3 -> 66000
A4: 二 | B4: =空调消防清单!B6 -> 消防改造 | C4: =空调消防清单!G6 -> 26603.485
A5: 三 | B5: 合计：一+二 | C5: =C3+C4 -> 92603.485
A6: 四 | B6: 管理费 | C6: =空调消防清单!G38 -> 3241.122
A7: 五 | B7: 税金 | C7: =空调消防清单!G39 -> 0
A8: 六 | B8: 合计=三+四+五 | C8: =C5+C6+C7 -> 95844.607 | D8: 156.78 | E8: =C8/D8 -> 611.33185

Sheet 空调消防清单
A1: 岁宝壹品苑D栋3901办公室装修清单 空调消防 | I1: =G40 -> 95844.607 | O1: =G6 -> 26603.485 | Q1: =不含空调消防清单!Q1 -> 1 | S1: =不含空调消防清单!S1 -> 1 | T1: =不含空调消防清单!T1 -> 1 | U1: =不含空调消防清单!U1 -> 1
A2: 序号 | B2: 项目名称 | C2: 项目特征 | D2: 单位 | E2: 工程量 | F2: 综合单价（不含税） | G2: 合价 | H2: 备注 | I2: 综合单价（不含税） | J2: 主材费 | K2: 主材损耗率 | L2: 人工费 | M2: 辅材费 | N2: 机械费 | O2: 合计 | P2: 成本价 | Q2: 主材费 | R2: 主材损耗率 | S2: 人工费 | T2: 辅材费 | U2: 机械费 | V2: 成本合计
A3: 一 | B3: 空调工程 | G3: =SUBTOTAL(9,G4:G5) -> 66000
A4: 1 | B4: 空调风机盘管1P | C4: 1、包含铝合金风口、空调管道、帆布、钢结构支架等 | D4: 台 | E4: 7 | F4: 7200 | G4: =F4*E4 -> 50400 | I4: =J4+J4*K4+L4+M4+N4 -> 6000 | J4: =Q4*$Q$1 -> 6000 | K4: =R4 -> 0 | L4: =S4*$S$1 -> 0 | M4: =T4*$T$1 -> 0 | N4: =U4*$U$1 -> 0 | O4: =E4*I4 -> 42000 | P4: =Q4+Q4*R4+S4+T4+U4 -> 6000 | Q4: 6000 | V4: =E4*P4 -> 42000
A5: 1 | B5: 空调风机盘管2P | C5: 1、包含铝合金风口、空调管道、帆布、钢结构支架等 | D5: 台 | E5: 2 | F5: 7800 | G5: =F5*E5 -> 15600 | I5: =J5+J5*K5+L5+M5+N5 -> 6300 | J5: =Q5*$Q$1 -> 6300 | K5: =R5 -> 0 | L5: =S5*$S$1 -> 0 | M5: =T5*$T$1 -> 0 | N5: =U5*$U$1 -> 0 | O5: =E5*I5 -> 12600 | P5: =Q5+Q5*R5+S5+T5+U5 -> 6300 | Q5: 6300 | V5: =E5*P5 -> 12600
A6: 二 | B6: 消防改造 | G6: =SUBTOTAL(9,G8:G36) -> 26603.485
A7: （一） | B7: 火灾自动报警系统
A8: 1 | B8: 探测器拆除、安装 | C8: 1.名称：感烟 2.型号.规格： | D8: 套 | E8: 3 | F8: =I8 -> 191.4 | G8: =F8*E8 -> 574.2 | I8: 191.4 | J8: =Q8*$Q$1 -> 0 | K8: =R8 -> 0 | L8: =S8*$S$1 -> 0 | M8: =T8*$T$1 -> 0 | N8: =U8*$U$1 -> 0 | O8: =E8*I8 -> 574.2 | P8: =Q8+Q8*R8+S8+T8+U8 -> 0 | V8: =E8*P8 -> 0
A9: 2 | B9: 探测器新增、安装 | C9: 1.规格型号:感烟 2.其它：符合规范和设计要求 | D9: 套 | E9: 3 | F9: =I9 -> 261 | G9: =F9*E9 -> 783 | I9: 261 | J9: =Q9*$Q$1 -> 0 | K9: =R9 -> 0 | L9: =S9*$S$1 -> 0 | M9: =T9*$T$1 -> 0 | N9: =U9*$U$1 -> 0 | O9: =E9*I9 -> 783 | P9: =Q9+Q9*R9+S9+T9+U9 -> 0 | V9: =E9*P9 -> 0
A10: 3 | B10: 消防广播拆除、安装 | C10: 1.名称：消防广播 2.型号.规格： | D10: 套 | E10: 1 | F10: =I10 -> 191.4 | G10: =F10*E10 -> 191.4 | I10: 191.4 | J10: =Q10*$Q$1 -> 0 | K10: =R10 -> 0 | L10: =S10*$S$1 -> 0 | M10: =T10*$T$1 -> 0 | N10: =U10*$U$1 -> 0 | O10: =E10*I10 -> 191.4 | P10: =Q10+Q10*R10+S10+T10+U10 -> 0 | V10: =E10*P10 -> 0
A11: 4 | B11: 电气配管 | C11: 1.型号规格：JDG20 2.敷设形式：综合考虑 3.含接线盒 4.根据现场情况改造到位 | D11: 米 | E11: 20 | F11: =I11 -> 24.36 | G11: =F11*E11 -> 487.2 | I11: 24.36 | J11: =Q11*$Q$1 -> 0 | K11: =R11 -> 0 | L11: =S11*$S$1 -> 0 | M11: =T11*$T$1 -> 0 | N11: =U11*$U$1 -> 0 | O11: =E11*I11 -> 487.2 | P11: =Q11+Q11*R11+S11+T11+U11 -> 0 | V11: =E11*P11 -> 0
A12: 5 | B12: 金属软管 | C12: 1.型号规格：φ20 2.敷设形式：综合考虑 | D12: 米 | E12: 3 | F12: =I12 -> 10.44 | G12: =F12*E12 -> 31.32 | I12: 10.44 | J12: =Q12*$Q$1 -> 0 | K12: =R12 -> 0 | L12: =S12*$S$1 -> 0 | M12: =T12*$T$1 -> 0 | N12: =U12*$U$1 -> 0 | O12: =E12*I12 -> 31.32 | P12: =Q12+Q12*R12+S12+T12+U12 -> 0 | V12: =E12*P12 -> 0
A13: 6 | B13: 电气配线 | C13: 1.名称:阻燃屏蔽双绞线 2.型号规格：ZR-RVS-2*1.5mm 3.敷设方式：穿管及线槽敷设 | D13: 米 | E13: 40 | F13: =I13 -> 6.96 | G13: =F13*E13 -> 278.4 | I13: 6.96 | J13: =Q13*$Q$1 -> 0 | K13: =R13 -> 0 | L13: =S13*$S$1 -> 0 | M13: =T13*$T$1 -> 0 | N13: =U13*$U$1 -> 0 | O13: =E13*I13 -> 278.4 | P13: =Q13+Q13*R13+S13+T13+U13 -> 0 | V13: =E13*P13 -> 0
A14: 7 | B14: 报警系统调试 | C14: 1、仅限我司施工 的项目 | D14: 项 | E14: 1 | F14: =I14 -> 800 | G14: =F14*E14 -> 800 | I14: 800 | J14: =Q14*$Q$1 -> 0 | K14: =R14 -> 0 | L14: =S14*$S$1 -> 0 | M14: =T14*$T$1 -> 0 | N14: =U14*$U$1 -> 0 | O14: =E14*I14 -> 800 | P14: =Q14+Q14*R14+S14+T14+U14 -> 0 | V14: =E14*P14 -> 0
A15: 8 | B15: 编程入网、系统接驳 | C15: 1、由大厦原消防施工单位负责，物业统一收费 | D15: ㎡ | E15: =不含空调消防清单!E85 -> 319.15 | F15: =I15 -> 30 | G15: =F15*E15 -> 9574.5 | H15: 不足4000元的按最低4000元计算。超过4000元的按建筑面积30元/㎡计算。 | I15: 30 | J15: =Q15*$Q$1 -> 0 | K15: =R15 -> 0 | L15: =S15*$S$1 -> 20 | M15: =T15*$T$1 -> 0 | N15: =U15*$U$1 -> 0 | O15: =E15*I15 -> 9574.5 | P15: =Q15+Q15*R15+S15+T15+U15 -> 20 | S15: 20 | V15: =E15*P15 -> 6383
A16: （二） | B16: 自动喷淋灭火系统 | G16: =F16*E16 -> 0
A17: 1 | B17: 保护性拆除明装喷头 | C17: 1.名称：上喷头保护性拆除 2.型号.规格： | D17: 个 | E17: 10 | F17: =I17 -> 174 | G17: =F17*E17 -> 1740 | I17: 174 | J17: =Q17*$Q$1 -> 0 | K17: =R17 -> 0 | L17: =S17*$S$1 -> 0 | M17: =T17*$T$1 -> 0 | N17: =U17*$U$1 -> 0 | O17: =E17*I17 -> 1740 | P17: =Q17+Q17*R17+S17+T17+U17 -> 0 | V17: =E17*P17 -> 0
A18: 2 | B18: 明装喷头 | C18: 1.名称：明装喷头 2.型号.规格： 3.其它：符合规范和设计要求 | D18: 个 | E18: 12 | F18: =I18 -> 217.5 | G18: =F18*E18 -> 2610 | I18: 217.5 | J18: =Q18*$Q$1 -> 0 | K18: =R18 -> 0 | L18: =S18*$S$1 -> 0 | M18: =T18*$T$1 -> 0 | N18: =U18*$U$1 -> 0 | O18: =E18*I18 -> 2610 | P18: =Q18+Q18*R18+S18+T18+U18 -> 0 | V18: =E18*P18 -> 0
A19: 3 | B19: 管网支吊架 | C19: 1、含钢制作、安装 | D19: KG | E19: 12 | F19: =I19 -> 21.75 | G19: =F19*E19 -> 261 | I19: 21.75 | J19: =Q19*$Q$1 -> 0 | K19: =R19 -> 0 | L19: =S19*$S$1 -> 0 | M19: =T19*$T$1 -> 0 | N19: =U19*$U$1 -> 0 | O19: =E19*I19 -> 261 | P19: =Q19+Q19*R19+S19+T19+U19 -> 0 | V19: =E19*P19 -> 0
A20: 4 | B20: 大红油漆（含人工及天那水） | C20: 1、含油漆、天那水、人工 | D20: 桶 | E20: 1 | F20: =I20 -> 435 | G20: =F20*E20 -> 435 | I20: 435 | J20: =Q20*$Q$1 -> 0 | K20: =R20 -> 0 | L20: =S20*$S$1 -> 0 | M20: =T20*$T$1 -> 0 | N20: =U20*$U$1 -> 0 | O20: =E20*I20 -> 435 | P20: =Q20+Q20*R20+S20+T20+U20 -> 0 | V20: =E20*P20 -> 0
A21: 5 | B21: 消防喷淋管 DN25 | C21: 1.安装部位：室内 2.介质:喷淋给水 3.材质、规格:内外壁热镀锌钢管DN25 4.连接方式:螺纹连接 含管件 5.其他要求:满足施工图纸技术规范要求 | D21: 米 | E21: 16.5 | F21: =I21 -> 50.46 | G21: =F21*E21 -> 832.59 | I21: 50.46 | J21: =Q21*$Q$1 -> 0 | K21: =R21 -> 0 | L21: =S21*$S$1 -> 0 | M21: =T21*$T$1 -> 0 | N21: =U21*$U$1 -> 0 | O21: =E21*I21 -> 832.59 | P21: =Q21+Q21*R21+S21+T21+U21 -> 0 | V21: =E21*P21 -> 0
A22: 6 | B22: 消防喷淋管 DN32 | C22: 1.安装部位：室内 2.介质:喷淋给水 3.材质、规格:内外壁热镀锌钢管DN32 4.连接方式:螺纹连接 含管件 5.其他要求:满足施工图纸技术规范要求 | D22: 米 | E22: 8.5 | F22: =I22 -> 56.55 | G22: =F22*E22 -> 480.675 | I22: 56.55 | J22: =Q22*$Q$1 -> 0 | K22: =R22 -> 0 | L22: =S22*$S$1 -> 0 | M22: =T22*$T$1 -> 0 | N22: =U22*$U$1 -> 0 | O22: =E22*I22 -> 480.675 | P22: =Q22+Q22*R22+S22+T22+U22 -> 0 | V22: =E22*P22 -> 0
A23: 7 | B23: 消防喷淋管 DN40 | C23: 1.安装部位：室内 2.介质:喷淋给水 3.材质、规格:内外壁热镀锌钢管DN40 4.连接方式:螺纹连接 含管件 5.其他要求:满足施工图纸技术规范要求 | D23: 米 | E23: 3.5 | F23: =I23 -> 65.25 | G23: =F23*E23 -> 228.375 | I23: 65.25 | J23: =Q23*$Q$1 -> 0 | K23: =R23 -> 0 | L23: =S23*$S$1 -> 0 | M23: =T23*$T$1 -> 0 | N23: =U23*$U$1 -> 0 | O23: =E23*I23 -> 228.375 | P23: =Q23+Q23*R23+S23+T23+U23 -> 0 | V23: =E23*P23 -> 0
A24: 8 | B24: 消防喷淋管 DN50 | C24: 1.安装部位：室内 2.介质:喷淋给水 3.材质、规格:内外壁热镀锌钢管DN50 4.连接方式:螺纹连接 含管件 5.其他要求:满足施工图纸技术规范要求 | D24: 米 | E24: 2.5 | F24: =I24 -> 80.91 | G24: =F24*E24 -> 202.275 | I24: 80.91 | J24: =Q24*$Q$1 -> 0 | K24: =R24 -> 0 | L24: =S24*$S$1 -> 0 | M24: =T24*$T$1 -> 0 | N24: =U24*$U$1 -> 0 | O24: =E24*I24 -> 202.275 | P24: =Q24+Q24*R24+S24+T24+U24 -> 0 | V24: =E24*P24 -> 0
A25: 9 | B25: 喷淋管网排水费 | C25: 1、含管网排水费及人工 | D25: 项 | E25: 1 | F25: =I25 -> 800 | G25: =F25*E25 -> 800 | I25: 800 | J25: =Q25*$Q$1 -> 0 | K25: =R25 -> 0 | L25: =S25*$S$1 -> 0 | M25: =T25*$T$1 -> 0 | N25: =U25*$U$1 -> 0 | O25: =E25*I25 -> 800 | P25: =Q25+Q25*R25+S25+T25+U25 -> 0 | V25: =E25*P25 -> 0
A26: 10 | B26: 喷淋管网试压 | C26: 1、管网冲洗、试压、调试 | D26: 项 | E26: 1 | F26: =I26 -> 870 | G26: =F26*E26 -> 870 | I26: 870 | J26: =Q26*$Q$1 -> 0 | K26: =R26 -> 0 | L26: =S26*$S$1 -> 0 | M26: =T26*$T$1 -> 0 | N26: =U26*$U$1 -> 0 | O26: =E26*I26 -> 870 | P26: =Q26+Q26*R26+S26+T26+U26 -> 0 | V26: =E26*P26 -> 0
A27: （三） | B27: 机械排烟系统
A28: 1 | B28: 镀锌风管拆除、移位 | D28: ㎡ | E28: 4.5 | F28: =I28 -> 156.6 | G28: =F28*E28 -> 704.7 | I28: 156.6 | J28: =Q28*$Q$1 -> 0 | K28: =R28 -> 0 | L28: =S28*$S$1 -> 0 | M28: =T28*$T$1 -> 0 | N28: =U28*$U$1 -> 0 | O28: =E28*I28 -> 704.7 | P28: =Q28+Q28*R28+S28+T28+U28 -> 0 | V28: =E28*P28 -> 0
A29: 2 | B29: 镀锌风管新增、安装 | C29: 1.风管的制作与安装 2.法兰、支架的制作、防锈与安装固定 | D29: ㎡ | E29: 1.5 | F29: =I29 -> 147.9 | G29: =F29*E29 -> 221.85 | I29: 147.9 | J29: =Q29*$Q$1 -> 0 | K29: =R29 -> 0 | L29: =S29*$S$1 -> 0 | M29: =T29*$T$1 -> 0 | N29: =U29*$U$1 -> 0 | O29: =E29*I29 -> 221.85 | P29: =Q29+Q29*R29+S29+T29+U29 -> 0 | V29: =E29*P29 -> 0
A30: 3 | B30: 风管防火包裹 | D30: ㎡ | E30: 3 | F30: =I30 -> 87 | G30: =F30*E30 -> 261 | I30: 87 | J30: =Q30*$Q$1 -> 0 | K30: =R30 -> 0 | L30: =S30*$S$1 -> 0 | M30: =T30*$T$1 -> 0 | N30: =U30*$U$1 -> 0 | O30: =E30*I30 -> 261 | P30: =Q30+Q30*R30+S30+T30+U30 -> 0 | V30: =E30*P30 -> 0
A31: 4 | B31: 280℃防火阀拆除、安装 | C31: 1.型号：防火阀280℃ 2.包含设备及辅材安装费 3.包含电源线接驳 | D31: 套 | E31: 1 | F31: =I31 -> 870 | G31: =F31*E31 -> 870 | I31: 870 | J31: =Q31*$Q$1 -> 0 | K31: =R31 -> 0 | L31: =S31*$S$1 -> 0 | M31: =T31*$T$1 -> 0 | N31: =U31*$U$1 -> 0 | O31: =E31*I31 -> 870 | P31: =Q31+Q31*R31+S31+T31+U31 -> 0 | V31: =E31*P31 -> 0
A32: 5 | B32: 常开百叶风口 | C32: 1、规格：成品铝框架百叶风口供货及安装 2、包含但不限于编制说明、图纸、技术要求中的相关内容及完成该项目的一切所需 | D32: 个 | E32: 2 | F32: =I32 -> 348 | G32: =F32*E32 -> 696 | I32: 348 | J32: =Q32*$Q$1 -> 0 | K32: =R32 -> 0 | L32: =S32*$S$1 -> 0 | M32: =T32*$T$1 -> 0 | N32: =U32*$U$1 -> 0 | O32: =E32*I32 -> 696 | P32: =Q32+Q32*R32+S32+T32+U32 -> 0 | V32: =E32*P32 -> 0
A33: 6 | B33: 排烟系统调试 | D33: 项 | E33: 1 | F33: =I33 -> 800 | G33: =F33*E33 -> 800 | I33: 800 | J33: =Q33*$Q$1 -> 0 | K33: =R33 -> 0 | L33: =S33*$S$1 -> 0 | M33: =T33*$T$1 -> 0 | N33: =U33*$U$1 -> 0 | O33: 1000 | P33: =Q33+Q33*R33+S33+T33+U33 -> 0 | V33: =E33*P33 -> 0
A34: （四） | B34: 其他
A35: 1 | B35: 消防报验 | C35: 含相关部门收取的报验费用。 | D35: 项 | E35: 1 | F35: =I35 -> 1000 | G35: =F35*E35 -> 1000 | I35: 1000 | J35: =Q35*$Q$1 -> 0 | K35: =R35 -> 0 | L35: =S35*$S$1 -> 0 | M35: =T35*$T$1 -> 0 | N35: =U35*$U$1 -> 0 | O35: 1500 | P35: =Q35+Q35*R35+S35+T35+U35 -> 0 | V35: =E35*P35 -> 0
A36: 2 | B36: 综合专业设计出图 | D36: 套 | E36: 1 | F36: =I36 -> 870 | G36: =F36*E36 -> 870 | I36: 870 | P36: =Q36+Q36*R36+S36+T36+U36 -> 0 | V36: =E36*P36 -> 0
A37: 三 | B37: 小计 | D37: 项 | E37: 1 | G37: =G3+G6 -> 92603.485 | I37: =SUBTOTAL(9,G3:G36) -> 92603.485
A38: 四 | B38: 管理费 | C38: =不含空调消防清单!C93 -> 0.035 | D38: 项 | E38: 1 | G38: =G37*C38 -> 3241.122
A39: 五 | B39: 税金 | C39: =不含空调消防清单!C94 -> 0.09 | D39: 项 | E39: 1 | G39: 0
A40: 六 | B40: 合计 | D40: 项 | E40: 1 | G40: =G39+G38+G37 -> 95844.607

Sheet 材料设备参考品牌
A1: 3901材料设备参考品牌
A2: 序号 | B2: 专业 | C2: 材料名称 | D2: 中高档品牌，报两三个品牌 | E2: 备注
A3: 1 | B3: 装饰 | C3: 地砖 | D3: 玛格罗兰、简一
A4: 2 | B4: 装饰 | C4: 岩板（800*1600） | D4: 伊诺、玛格罗兰
A5: 3 | B5: 装饰 | C5: 木饰面 | D5: 定制
A6: 4 | B6: 装饰 | C6: 不锈钢 | D6: 国产优质
A7: 5 | B7: 装饰 | C7: 石膏板 | D7: 深耐福
A8: 6 | B8: 装饰 | C8: 夹板、阻燃板 | D8: 深耐福
A9: 7 | B9: 装饰 | C9: 艺术漆 | D9: =D6 -> 国产优质
A10: 8 | B10: 装饰 | C10: 乳胶漆 | D10: 立邦
A11: 9 | B11: 装饰 | C11: 腻子 | D11: 立邦
A12: 10 | B12: 安装 | C12: 照明，强电用线 | D12: 南洋
A13: 11 | B13: 安装 | C13: 灯具（射灯、筒灯） | D13: 三雄、欧普
A14: 12 | B14: 安装 | C14: LED灯带 | D14: 三雄、欧普
A15: 13 | B15: 安装 | C15: 照明开关 | D15: 公牛
A16: 14 | B16: 安装 | C16: 插座 | D16: 公牛
A17: 15 | B17: 安装 | C17: 网络插座 | D17: 公牛
A18: 16 | B18: 安装 | C18: 信号线、网线 | D18: 海康
A19: 17 | B19: 空调 | C19: 空调风机盘管 | D19: 麦克维尔
A20: 18 | B20: 安装 | C20: 电动窗帘电机 | D20: 国产杜亚
