Workbook

Sheet 报价汇总-装修工程
B1: 岁宝壹品苑D栋3206办公室装修汇总 装修工程
A2: 序号 | B2: 名称 | C2: 金额（元） | D2: 面积（㎡） | E2: 单方价格（元/㎡） | F2: 备注
A3: 一 | B3: 装饰工程 | C3: =不含空调消防清单!G3 -> 317676.81 | G3: 成本
A4: （一） | B4: 隔墙工程 | C4: =不含空调消防清单!G4 -> 24078.489 | G4: 装饰 | H4: 346675.71
A5: （二） | B5: 地面工程 | C5: =不含空调消防清单!G26 -> 137888 | G5: 空调 | H5: 30000
A6: （三） | B6: 天花工程 | C6: =不含空调消防清单!G31 -> 53883.904 | G6: 消防 | H6: 17789.3
A7: （四） | B7: 墙面工程 | C7: =不含空调消防清单!G43 -> 59987.487 | G7: 合计 | H7: =SUM(H4:H6) -> 394465.01
A8: （五） | B8: 固定家具及门窗工程 | C8: =不含空调消防清单!G55 -> 41838.936 | H8: =C13+C14+'报价汇总-空调消防'!C5+'报价汇总-空调消防'!C6 -> 475364.98
A9: 二 | B9: 安装工程 | C9: =不含空调消防清单!G78 -> 44640.75 | H9: =(H8-H7)/H7 -> 0.20508782
A10: （一） | B10: 强电工程 | C10: =不含空调消防清单!G79 -> 38883.45
A11: （二） | B11: 弱电工程 | C11: =不含空调消防清单!G94 -> 5757.3
A12: 三 | B12: 其他工程 | C12: =不含空调消防清单!G97 -> 27090.75
A13: 四 | B13: 小计：一+二+三 | C13: =C3+C9+C12 -> 389408.31
A14: 五 | B14: 管理费 | C14: =不含空调消防清单!G106 -> 19470.416
A15: 六 | B15: 税金 | C15: =不含空调消防清单!G107 -> 36799.086
A16: 七 | B16: 装饰合计=四+五+六 | C16: =C13+C14+C15 -> 445677.82 | D16: 156.78 | E16: =C16/D16 -> 2842.6956
A17: 八 | B17: 消防空调 | C17: ='报价汇总-空调消防'!C8 -> 72470.009 | D17: 156.78 | E17: =C17/D17 -> 462.24014
A18: 九 | B18: 总计: （装饰+消防空调） | C18: =C16+C17 -> 518147.82 | D18: 156.78 | E18: =C18/D18 -> 3304.9357
A19: 十 | B19: 施工图、效果图设计费 | C19: -24000
A20: 十一 | B20: 共计:九+十 | C20: =C18+C19 -> 494147.82 | D20: 156.78 | E20: =C20/D20 -> 3151.855

Sheet 不含空调消防清单
A1: 岁宝壹品苑D栋3206办公室装修清单（不含空调消防） | I1: =G108 -> 445677.82 | Q1: 1 | S1: =$Q$1 -> 1 | T1: =$Q$1 -> 1 | U1: =$Q$1 -> 1 | V1: ='报价汇总-装修工程'!G17 -> 0
A2: 序号 | B2: 项目名称 | C2: 项目特征 | D2: 单位 | E2: 工程量 | F2: 综合单价（不含税） | G2: 合价 | H2: 备注 | I2: 综合单价（不含税） | J2: 主材费 | K2: 主材损耗率 | L2: 人工费 | M2: 辅材费 | N2: 机械费 | O2: 合计 | P2: 成本价 | Q2: 主材费 | R2: 主材损耗率 | S2: 人工费 | T2: 辅材费 | U2: 机械费 | V2: 成本合计
A3: 一 | B3: 装饰工程 | G3: =SUBTOTAL(9,G4:G77) -> 317676.81
A4: （一） | B4: 隔墙工程 | G4: =SUBTOTAL(9,G5:G25) -> 24078.489
A5: 1.1 | B5: 拆除原有砖墙 （200mm厚） | C5: 1、人工拆除 2、机械设备 3、防护措施 4、垃圾清理装袋 | D5: ㎡ | E5: =0.9*2.8*2+1.63*0.4 -> 5.692 | F5: =I5 -> 100 | G5: =F5*E5 -> 569.2 | I5: =J5+J5*K5+L5+M5+N5 -> 100 | J5: =Q5*$Q$1 -> 0 | K5: =R5 -> 0 | L5: =S5*$S$1 -> 70 | M5: =T5*$T$1 -> 30 | N5: =U5*$U$1 -> 0 | O5: =E5*I5 -> 569.2 | P5: =Q5+Q5*R5+S5+T5+U5 -> 100 | S5: 70 | T5: 30 | V5: =E5*P5 -> 569.2
A6: 1.2 | B6: 横梁槽钢加固 | C6: 1、原墙面开门洞后横梁槽钢加固 | D6: m | E6: 3.4 | F6: =I6 -> 500 | G6: =F6*E6 -> 1700 | I6: =J6+J6*K6+L6+M6+N6 -> 500 | J6: =Q6*$Q$1 -> 300 | K6: =R6 -> 0 | L6: =S6*$S$1 -> 200 | M6: =T6*$T$1 -> 0 | N6: =U6*$U$1 -> 0 | O6: =E6*I6 -> 1700 | P6: =Q6+Q6*R6+S6+T6+U6 -> 500 | Q6: 300 | S6: 200 | V6: =E6*P6 -> 1700
A7: 1.3 | B7: 水泥砂浆修补 | C7: 1、门洞侧边水泥砂浆修补 | D7: m | E7: =(2.8*2+3.4) -> 9 | F7: =I7 -> 31.12 | G7: =F7*E7 -> 280.08 | I7: =J7+J7*K7+L7+M7+N7 -> 31.12 | J7: =Q7*$Q$1 -> 6 | K7: =R7 -> 0.02 | L7: =S7*$S$1 -> 25 | M7: =T7*$T$1 -> 0 | N7: =U7*$U$1 -> 0 | O7: =E7*I7 -> 280.08 | P7: =Q7+Q7*R7+S7+T7+U7 -> 31.12 | Q7: =12*0.5 -> 6 | R7: 0.02 | S7: 25 | V7: =E7*P7 -> 280.08
A8: 1.4 | B8: 12mm阻燃夹板封边 | C8: 1、原墙面开门洞后12mm阻燃夹板封边 | D8: m | E8: =(2.8*2+3.4) -> 9 | F8: =I8 -> 25.6 | G8: =F8*E8 -> 230.4 | I8: =J8+J8*K8+L8+M8+N8 -> 25.6 | J8: =Q8*$Q$1 -> 5.6 | K8: =R8 -> 0 | L8: =S8*$S$1 -> 20 | M8: =T8*$T$1 -> 0 | N8: =U8*$U$1 -> 0 | O8: =E8*I8 -> 230.4 | P8: =Q8+Q8*R8+S8+T8+U8 -> 25.6 | Q8: =28*0.2 -> 5.6 | S8: 20 | V8: =E8*P8 -> 230.4
A9: 2 | B9: 轻钢龙骨隔墙 | C9: 双层双面轻钢龙骨隔墙 1、墙厚120mm; 2、75mm轻钢龙骨； 3、50mm厚，48kg/m3的吸音棉； 4、12mm阻燃夹板+9.5mm厚石膏板 | D9: ㎡ | E9: =3.81*(2+0.57+6.23+0.75+2+0.35+0.6+4.93)-0.7*2.4 -> 64.7283 | I9: =J9+J9*K9+L9+M9+N9 -> 0 | J9: =Q9*$Q$1 -> 0 | K9: =R9 -> 0 | L9: =S9*$S$1 -> 0 | M9: =T9*$T$1 -> 0 | N9: =U9*$U$1 -> 0 | O9: =E9*I9 -> 0 | P9: =Q9+Q9*R9+S9+T9+U9 -> 0 | V9: =E9*P9 -> 0
A10: 2.1 | B10: 轻钢龙骨 | C10: 1、天地龙骨 2、竖龙骨 3、穿心龙骨 4、其他辅材 | D10: ㎡ | E10: =3.81*(2+0.57+6.23+0.75+2+0.35+0.6+4.93)-0.7*2.4 -> 64.7283 | F10: =I10 -> 53.5 | G10: =F10*E10 -> 3462.9641 | I10: =J10+J10*K10+L10+M10+N10 -> 53.5 | J10: =Q10*$Q$1 -> 26 | K10: =R10 -> 0 | L10: =S10*$S$1 -> 26 | M10: =T10*$T$1 -> 0 | N10: =U10*$U$1 -> 1.5 | O10: =E10*I10 -> 3462.9641 | P10: =Q10+Q10*R10+S10+T10+U10 -> 53.5 | Q10: 26 | S10: 26 | U10: 1.5 | V10: =E10*P10 -> 3462.9641
A11: 2.2 | B11: 50mm厚吸音棉 | C11: 1、50mm厚，48kg/m3的吸音棉 | D11: ㎡ | E11: =3.81*(2+0.57+6.23+0.75+2+0.35+0.6+4.93)-0.7*2.4 -> 64.7283 | F11: =I11 -> 21.65 | G11: =F11*E11 -> 1401.3677 | I11: =J11+J11*K11+L11+M11+N11 -> 21.65 | J11: =Q11*$Q$1 -> 11.65 | K11: =R11 -> 0 | L11: =S11*$S$1 -> 10 | M11: =T11*$T$1 -> 0 | N11: =U11*$U$1 -> 0 | O11: =E11*I11 -> 1401.3677 | P11: =Q11+Q11*R11+S11+T11+U11 -> 21.65 | Q11: 11.65 | S11: 10 | V11: =E11*P11 -> 1401.3677
A12: 2.3 | B12: 12mm阻燃夹板 | C12: 1、单层12mm阻燃夹板打底 | D12: ㎡ | E12: =3.81*(2+0.57+6.23+0.75+2+0.35+0.6+4.93)-0.7*2.4 -> 64.7283 | F12: =I12 -> 48.8 | G12: =F12*E12 -> 3158.741 | I12: =J12+J12*K12+L12+M12+N12 -> 48.8 | J12: =Q12*$Q$1 -> 28 | K12: =R12 -> 0 | L12: =S12*$S$1 -> 20 | M12: =T12*$T$1 -> 0.8 | N12: =U12*$U$1 -> 0 | O12: =E12*I12 -> 3158.741 | P12: =Q12+Q12*R12+S12+T12+U12 -> 48.8 | Q12: 28 | S12: 20 | T12: 0.8 | V12: =E12*P12 -> 3158.741
A13: 2.4 | B13: 9.5mm厚石膏板 | C13: 1、双面单层9.5mm厚石膏板 | D13: ㎡ | E13: =E10*2.5 -> 161.82075 | F13: =I13 -> 28.3 | G13: =F13*E13 -> 4579.5272 | I13: =J13+J13*K13+L13+M13+N13 -> 28.3 | J13: =Q13*$Q$1 -> 7.5 | K13: =R13 -> 0 | L13: =S13*$S$1 -> 20 | M13: =T13*$T$1 -> 0.8 | N13: =U13*$U$1 -> 0 | O13: =E13*I13 -> 4579.5272 | P13: =Q13+Q13*R13+S13+T13+U13 -> 28.3 | Q13: =7.5 -> 7.5 | S13: 20 | T13: 0.8 | V13: =E13*P13 -> 4579.5272
A14: 3.1 | B14: GL-01 10mm厚钢化玻璃隔断 （总裁办公室、大门处） | C14: 1、GL-01 10mm厚钢化玻璃; 2、玻璃胶收口 | D14: ㎡ | E14: =2.8*(7.73-0.6-1.7+0.89*2) -> 20.188 | F14: =I14 -> 181.6 | G14: =F14*E14 -> 3666.1408 | I14: =J14+J14*K14+L14+M14+N14 -> 181.6 | J14: =Q14*$Q$1 -> 110 | K14: =R14 -> 0.01 | L14: =S14*$S$1 -> 60 | M14: =T14*$T$1 -> 10.5 | N14: =U14*$U$1 -> 0 | O14: =E14*I14 -> 3666.1408 | P14: =Q14+Q14*R14+S14+T14+U14 -> 181.6 | Q14: =110 -> 110 | R14: 0.01 | S14: 60 | T14: 10.5 | V14: =E14*P14 -> 3666.1408
A15: 3.2 | B15: 不锈钢包边 （总裁办公室、大门处） | C15: 1、MT-01不锈钢 2、12mm厚阻燃夹板 | D15: ㎡ | E15: =0.2*(7.73-0.6-1.7+2.8*2+3.4+2.8*2) -> 4.006 | F15: =I15 -> 409.35 | G15: =F15*E15 -> 1639.8561 | I15: =J15+J15*K15+L15+M15+N15 -> 409.35 | J15: =Q15*$Q$1 -> 285 | K15: =R15 -> 0.01 | L15: =S15*$S$1 -> 90 | M15: =T15*$T$1 -> 31.5 | N15: =U15*$U$1 -> 0 | O15: =E15*I15 -> 1639.8561 | P15: =Q15+Q15*R15+S15+T15+U15 -> 409.35 | Q15: 285 | R15: 0.01 | S15: =30+60 -> 90 | T15: =28+3.5 -> 31.5 | V15: =E15*P15 -> 1639.8561
A16: 4 | B16: 钢化玻璃隔断上方封板 | C16: 双层双面钢结构龙骨隔墙 1、墙厚120mm; 2、钢结构龙骨； 3、50mm厚，48kg/m3的吸音棉； 4、12mm厚阻燃夹板+9.5mm厚石膏板 | D16: ㎡ | E16: =1.31*(7.73-0.6-1.7) -> 7.1133 | I16: =J16+J16*K16+L16+M16+N16 -> 0 | J16: =Q16*$Q$1 -> 0 | K16: =R16 -> 0 | L16: =S16*$S$1 -> 0 | M16: =T16*$T$1 -> 0 | N16: =U16*$U$1 -> 0 | O16: =E16*I16 -> 0 | V16: =E16*P16 -> 0
A17: 4.1 | B17: 钢结构龙骨 | C17: 1、钢结构龙骨 2、刷防锈漆 3、其他辅材 | D17: ㎡ | E17: =E16 -> 7.1133 | F17: =I17 -> 91.5 | G17: =F17*E17 -> 650.86695 | I17: =J17+J17*K17+L17+M17+N17 -> 91.5 | J17: =Q17*$Q$1 -> 55 | K17: =R17 -> 0 | L17: =S17*$S$1 -> 35 | M17: =T17*$T$1 -> 0 | N17: =U17*$U$1 -> 1.5 | O17: =E17*I17 -> 650.86695 | P17: =Q17+Q17*R17+S17+T17+U17 -> 91.5 | Q17: 55 | S17: 35 | U17: 1.5 | V17: =E17*P17 -> 650.86695
A18: 4.2 | B18: 50mm厚吸音棉 | C18: 1、50mm厚，48kg/m3的吸音棉 | D18: ㎡ | E18: =E16 -> 7.1133 | F18: =I18 -> 21.65 | G18: =F18*E18 -> 154.00295 | I18: =J18+J18*K18+L18+M18+N18 -> 21.65 | J18: =Q18*$Q$1 -> 11.65 | K18: =R18 -> 0 | L18: =S18*$S$1 -> 10 | M18: =T18*$T$1 -> 0 | N18: =U18*$U$1 -> 0 | O18: =E18*I18 -> 154.00295 | P18: =Q18+Q18*R18+S18+T18+U18 -> 21.65 | Q18: 11.65 | S18: 10 | V18: =E18*P18 -> 154.00295
A19: 4.3 | B19: 12mm阻燃夹板 | C19: 1、单层12mm阻燃夹板打底 | D19: ㎡ | E19: =E16*2 -> 14.2266 | F19: =I19 -> 48.8 | G19: =F19*E19 -> 694.25808 | I19: =J19+J19*K19+L19+M19+N19 -> 48.8 | J19: =Q19*$Q$1 -> 28 | K19: =R19 -> 0 | L19: =S19*$S$1 -> 20 | M19: =T19*$T$1 -> 0.8 | N19: =U19*$U$1 -> 0 | O19: =E19*I19 -> 694.25808 | P19: =Q19+Q19*R19+S19+T19+U19 -> 48.8 | Q19: 28 | S19: 20 | T19: 0.8 | V19: =E19*P19 -> 694.25808
A20: 4.4 | B20: 9.5mm厚石膏板 | C20: 1、双面单层9.5mm厚石膏板 | D20: ㎡ | E20: =E16*2 -> 14.2266 | F20: =I20 -> 28.3 | G20: =F20*E20 -> 402.61278 | I20: =J20+J20*K20+L20+M20+N20 -> 28.3 | J20: =Q20*$Q$1 -> 7.5 | K20: =R20 -> 0 | L20: =S20*$S$1 -> 20 | M20: =T20*$T$1 -> 0.8 | N20: =U20*$U$1 -> 0 | O20: =E20*I20 -> 402.61278 | P20: =Q20+Q20*R20+S20+T20+U20 -> 28.3 | Q20: =7.5 -> 7.5 | S20: 20 | T20: 0.8 | V20: =E20*P20 -> 402.61278
A21: 5 | B21: 隐藏式折叠门上方钢结构加固封板 | C21: 双层双面钢结构龙骨隔墙 1、墙厚120mm; 2、钢结构龙骨； 3、50mm厚，48kg/m3的吸音棉； 4、12mm厚阻燃夹板+9.5mm厚石膏板 | D21: ㎡ | E21: =1.31*4.25 -> 5.5675 | I21: =J21+J21*K21+L21+M21+N21 -> 171.4 | J21: =Q21*$Q$1 -> 90 | K21: =R21 -> 0.01 | L21: =S21*$S$1 -> 70 | M21: =T21*$T$1 -> 10.5 | N21: =U21*$U$1 -> 0 | O21: =E21*I21 -> 954.2695 | P21: =Q21+Q21*R21+S21+T21+U21 -> 171.4 | Q21: =35*2+10*2 -> 90 | R21: 0.01 | S21: 70 | T21: 10.5 | V21: =E21*P21 -> 954.2695
A22: 5.1 | B22: 钢结构龙骨 | C22: 1、钢结构龙骨 2、刷防锈漆 3、其他辅材 | D22: ㎡ | E22: =E21 -> 5.5675 | F22: =I22 -> 91.5 | G22: =F22*E22 -> 509.42625 | I22: =J22+J22*K22+L22+M22+N22 -> 91.5 | J22: =Q22*$Q$1 -> 55 | K22: =R22 -> 0 | L22: =S22*$S$1 -> 35 | M22: =T22*$T$1 -> 0 | N22: =U22*$U$1 -> 1.5 | O22: =E22*I22 -> 509.42625 | P22: =Q22+Q22*R22+S22+T22+U22 -> 91.5 | Q22: 55 | S22: =S17 -> 35 | U22: 1.5 | V22: =E22*P22 -> 509.42625
A23: 5.2 | B23: 50mm厚吸音棉 | C23: 1、50mm厚，48kg/m3的吸音棉 | D23: ㎡ | E23: =E21 -> 5.5675 | F23: =I23 -> 21.65 | G23: =F23*E23 -> 120.53638 | I23: =J23+J23*K23+L23+M23+N23 -> 21.65 | J23: =Q23*$Q$1 -> 11.65 | K23: =R23 -> 0 | L23: =S23*$S$1 -> 10 | M23: =T23*$T$1 -> 0 | N23: =U23*$U$1 -> 0 | O23: =E23*I23 -> 120.53638 | P23: =Q23+Q23*R23+S23+T23+U23 -> 21.65 | Q23: 11.65 | S23: =S18 -> 10 | V23: =E23*P23 -> 120.53638
A24: 5.3 | B24: 12mm阻燃夹板 | C24: 1、单层12mm阻燃夹板打底 | D24: ㎡ | E24: =E21*2 -> 11.135 | F24: =I24 -> 48.8 | G24: =F24*E24 -> 543.388 | I24: =J24+J24*K24+L24+M24+N24 -> 48.8 | J24: =Q24*$Q$1 -> 28 | K24: =R24 -> 0 | L24: =S24*$S$1 -> 20 | M24: =T24*$T$1 -> 0.8 | N24: =U24*$U$1 -> 0 | O24: =E24*I24 -> 543.388 | P24: =Q24+Q24*R24+S24+T24+U24 -> 48.8 | Q24: 28 | S24: =S19 -> 20 | T24: 0.8 | V24: =E24*P24 -> 543.388
A25: 5.4 | B25: 9.5mm厚石膏板 | C25: 1、双面单层9.5mm厚石膏板 | D25: ㎡ | E25: =E21*2 -> 11.135 | F25: =I25 -> 28.3 | G25: =F25*E25 -> 315.1205 | I25: =J25+J25*K25+L25+M25+N25 -> 28.3 | J25: =Q25*$Q$1 -> 7.5 | K25: =R25 -> 0 | L25: =S25*$S$1 -> 20 | M25: =T25*$T$1 -> 0.8 | N25: =U25*$U$1 -> 0 | O25: =E25*I25 -> 315.1205 | P25: =Q25+Q25*R25+S25+T25+U25 -> 28.3 | Q25: =7.5 -> 7.5 | S25: =S20 -> 20 | T25: 0.8 | V25: =E25*P25 -> 315.1205
A26: （二） | B26: 地面工程 | G26: =SUBTOTAL(9,G27:G30) -> 137888
A27: 1 | B27: 100mm厚陶粒拌混泥土垫层 | C27: 1、100mm厚陶粒拌混泥土垫层 | D27: ㎡ | E27: =158.91-1.96 -> 156.95 | F27: =I27 -> 76.93 | G27: =F27*E27 -> 12074.164 | I27: =J27+J27*K27+L27+M27+N27 -> 76.93 | J27: =Q27*$Q$1 -> 43 | K27: =R27 -> 0.01 | L27: =S27*$S$1 -> 30 | M27: =T27*$T$1 -> 3.5 | N27: =U27*$U$1 -> 0 | O27: =E27*I27 -> 12074.164 | P27: =Q27+Q27*R27+S27+T27+U27 -> 76.93 | Q27: 43 | R27: 0.01 | S27: 30 | T27: 3.5 | U27: 0 | V27: =E27*P27 -> 12074.164
A28: 2 | B28: 地面岩板 | C28: 1、CT-01岩板9mm厚 2、规格：800*1600 3、专用胶泥结合层，厚度包干，后期不因厚度调整价格； | D28: ㎡ | E28: =7.29+12.13+37.84+26.23+72.43+0.68+0.08+0.2+0.2+0.3-1.96 -> 155.42 | F28: =I28 -> 789 | G28: =F28*E28 -> 122626.38 | I28: =J28+J28*K28+L28+M28+N28 -> 789 | J28: =Q28*$Q$1 -> 650 | K28: =R28 -> 0.02 | L28: =S28*$S$1 -> 80 | M28: =T28*$T$1 -> 46 | N28: =U28*$U$1 -> 0 | O28: =E28*I28 -> 122626.38 | P28: =Q28+Q28*R28+S28+T28+U28 -> 789 | Q28: 650 | R28: 0.02 | S28: 80 | T28: 46 | V28: =E28*P28 -> 122626.38
A29: 3 | B29: 美缝 | C29: 1、专业美缝剂美缝 | D29: ㎡ | E29: =E28 -> 155.42 | F29: =I29 -> 20 | G29: =F29*E29 -> 3108.4 | I29: =J29+J29*K29+L29+M29+N29 -> 20 | J29: =Q29*$Q$1 -> 0 | K29: =R29 -> 0.02 | L29: =S29*$S$1 -> 16 | M29: =T29*$T$1 -> 4 | N29: =U29*$U$1 -> 0 | O29: =E29*I29 -> 3108.4 | P29: =Q29+Q29*R29+S29+T29+U29 -> 20 | R29: 0.02 | S29: 16 | T29: 4 | V29: =E29*P29 -> 3108.4
A30: 4 | B30: 5mm厚不锈钢地面收口条 | C30: 1、5mm厚不锈钢收口条 | D30: m | E30: 1.63 | F30: =I30 -> 48.5 | G30: =F30*E30 -> 79.055 | I30: =J30+J30*K30+L30+M30+N30 -> 48.5 | J30: =Q30*$Q$1 -> 35 | K30: =R30 -> 0.02 | L30: =S30*$S$1 -> 12 | M30: =T30*$T$1 -> 0.8 | N30: =U30*$U$1 -> 0 | O30: =E30*I30 -> 79.055 | P30: =Q30+Q30*R30+S30+T30+U30 -> 48.5 | Q30: 35 | R30: 0.02 | S30: 12 | T30: 0.8 | V30: =E30*P30 -> 79.055
A31: （三） | B31: 天花工程 | G31: =SUBTOTAL(9,G32:G42) -> 53883.904
A32: 1 | B32: 石膏板跌级天花吊顶 | C32: 1、吊顶形式：平级+跌级吊顶 2、基层：轻钢龙骨+双层9.5mm厚石膏板 3.含各种灯具、检修口、风口开口 | D32: ㎡ | E32: =7.29+12.13+37.84+26.23+72.43-1.96 -> 153.96 | I32: =J32+J32*K32+L32+M32+N32 -> 146.2 | J32: =Q32*$Q$1 -> 20 | K32: =R32 -> 0.01 | L32: =S32*$S$1 -> 100 | M32: =T32*$T$1 -> 26 | N32: =U32*$U$1 -> 0 | O32: =E32*I32 -> 22508.952 | P32: =Q32+Q32*R32+S32+T32+U32 -> 146.2 | Q32: 20 | R32: 0.01 | S32: 100 | T32: 26 | V32: =E32*P32 -> 22508.952
A33: 1.1 | B33: 轻钢龙骨 | C33: 1、轻钢龙骨吊顶 2、其他辅材 | D33: ㎡ | E33: =E32 -> 153.96 | F33: =I33 -> 71.5 | G33: =F33*E33 -> 11008.14 | I33: =J33+J33*K33+L33+M33+N33 -> 71.5 | J33: =Q33*$Q$1 -> 0 | K33: =R33 -> 0 | L33: =S33*$S$1 -> 35 | M33: =T33*$T$1 -> 35 | N33: =U33*$U$1 -> 1.5 | O33: =E33*I33 -> 11008.14 | P33: =Q33+Q33*R33+S33+T33+U33 -> 71.5 | S33: 35 | T33: 35 | U33: 1.5 | V33: =E33*P33 -> 11008.14
A34: 1.2 | B34: 12mm阻燃夹板 | C34: 1、12mm阻燃夹板 | D34: ㎡ | E34: =E32*0.15 -> 23.094 | F34: =I34 -> 48.8 | G34: =F34*E34 -> 1126.9872 | I34: =J34+J34*K34+L34+M34+N34 -> 48.8 | J34: =Q34*$Q$1 -> 28 | K34: =R34 -> 0 | L34: =S34*$S$1 -> 20 | M34: =T34*$T$1 -> 0.8 | N34: =U34*$U$1 -> 0 | O34: =E34*I34 -> 1126.9872 | P34: =Q34+Q34*R34+S34+T34+U34 -> 48.8 | Q34: 28 | S34: 20 | T34: 0.8 | V34: =E34*P34 -> 1126.9872
A35: 1.3 | B35: 9.5mm厚石膏板 | C35: 1、双面单层9.5mm厚石膏板 | D35: ㎡ | E35: =E33*2 -> 307.92 | F35: =I35 -> 28.3 | G35: =F35*E35 -> 8714.136 | I35: =J35+J35*K35+L35+M35+N35 -> 28.3 | J35: =Q35*$Q$1 -> 7.5 | K35: =R35 -> 0 | L35: =S35*$S$1 -> 20 | M35: =T35*$T$1 -> 0.8 | N35: =U35*$U$1 -> 0 | O35: =E35*I35 -> 8714.136 | P35: =Q35+Q35*R35+S35+T35+U35 -> 28.3 | Q35: =7.5 -> 7.5 | S35: 20 | T35: 0.8 | V35: =E35*P35 -> 8714.136
A36: 2 | B36: 天花板缝贴纸带刮平整 | D36: ㎡ | E36: =E32 -> 153.96 | F36: =I36 -> 8.5 | G36: =F36*E36 -> 1308.66 | I36: =J36+J36*K36+L36+M36+N36 -> 8.5 | J36: =Q36*$Q$1 -> 3.5 | K36: =R36 -> 0 | L36: =S36*$S$1 -> 5 | M36: =T36*$T$1 -> 0 | N36: =U36*$U$1 -> 0 | O36: =E36*I36 -> 1308.66 | P36: =Q36+Q36*R36+S36+T36+U36 -> 8.5 | Q36: 3.5 | R36: 0 | S36: 5 | T36: 0 | U36: 0 | V36: =E36*P36 -> 1308.66
A37: 3 | B37: 天花挂耐水腻子 | C37: 1、耐水腻子2道，含打磨、修补 | D37: ㎡ | E37: =153.96+83.5*0.2+22.43*0.4 -> 179.632 | F37: =I37 -> 23.5 | G37: =F37*E37 -> 4221.352 | I37: =J37+J37*K37+L37+M37+N37 -> 23.5 | J37: =Q37*$Q$1 -> 3.5 | K37: =R37 -> 0 | L37: =S37*$S$1 -> 20 | M37: =T37*$T$1 -> 0 | N37: =U37*$U$1 -> 0 | O37: =E37*I37 -> 4221.352 | P37: =Q37+Q37*R37+S37+T37+U37 -> 23.5 | Q37: 3.5 | R37: 0 | S37: 20 | T37: 0 | U37: 0 | V37: =E37*P37 -> 4221.352
A38: 4 | B38: 天棚乳胶漆 | C38: 1、面层：PT-01无机白色涂料一底二面 | D38: ㎡ | E38: =E37 -> 179.632 | F38: =I38 -> 13 | G38: =F38*E38 -> 2335.216 | I38: =J38+J38*K38+L38+M38+N38 -> 13 | J38: =Q38*$Q$1 -> 3 | K38: =R38 -> 0 | L38: =S38*$S$1 -> 10 | M38: =T38*$T$1 -> 0 | N38: =U38*$U$1 -> 0 | O38: =E38*I38 -> 2335.216 | P38: =Q38+Q38*R38+S38+T38+U38 -> 13 | Q38: 3 | R38: 0 | S38: 10 | T38: 0 | U38: 0 | V38: =E38*P38 -> 2335.216
A39: 5 | B39: 天花灯槽 | C39: 1、规格：100*100*100mm天花灯槽 2、基层：轻钢龙骨 3、面层：12mm厚阻燃夹板+9.5mm厚石膏板 | D39: m | E39: =9.7+22.68+19.24+31.88 -> 83.5 | F39: =I39 -> 70 | G39: =F39*E39 -> 5845 | I39: =J39+J39*K39+L39+M39+N39 -> 70 | J39: =Q39*$Q$1 -> 13.5 | K39: =R39 -> 0 | L39: =S39*$S$1 -> 55 | M39: =T39*$T$1 -> 1.5 | N39: =U39*$U$1 -> 0 | O39: =E39*I39 -> 5845 | P39: =Q39+Q39*R39+S39+T39+U39 -> 70 | Q39: =0.3*(35+10) -> 13.5 | S39: 55 | T39: 1.5 | V39: =E39*P39 -> 5845
A40: 6 | B40: 窗帘盒 | C40: 1、基层：钢结构龙骨+阻燃板基层 2、面层：9.5mm厚石膏板 | D40: m | E40: =5.28+5.02+12.13 -> 22.43 | F40: =I40 -> 195.17 | G40: =F40*E40 -> 4377.6631 | I40: =J40+J40*K40+L40+M40+N40 -> 195.17 | J40: =Q40*$Q$1 -> 131.67 | K40: =R40 -> 0 | L40: =S40*$S$1 -> 55 | M40: =T40*$T$1 -> 8.5 | N40: =U40*$U$1 -> 0 | O40: =E40*I40 -> 4377.6631 | P40: =Q40+Q40*R40+S40+T40+U40 -> 195.17 | Q40: =4.2*5.7*5.5 -> 131.67 | S40: 55 | T40: 8.5 | V40: =E40*P40 -> 4377.6631
...

Sheet 报价汇总-空调消防
B1: 岁宝壹品苑D栋3206办公室装修汇总 空调消防
A2: 序号 | B2: 名称 | C2: 金额（元） | D2: 面积（㎡） | E2: 单方价格（元/㎡） | F2: 备注
A3: 一 | B3: =空调消防清单!B3 -> 空调工程 | C3: =空调消防清单!G3 -> 31500
A4: 二 | B4: =空调消防清单!B5 -> 消防改造 | C4: =空调消防清单!G5 -> 31820.235
A5: 三 | B5: 合计：一+二 | C5: =C3+C4 -> 63320.235
A6: 四 | B6: 管理费 | C6: =空调消防清单!G37 -> 3166.0118
A7: 五 | B7: 税金 | C7: =空调消防清单!G38 -> 5983.7622
A8: 六 | B8: 合计=三+四+五 | C8: =C5+C6+C7 -> 72470.009 | D8: 156.78 | E8: =C8/D8 -> 462.24014

Sheet 空调消防清单
A1: 岁宝壹品苑D栋3206办公室装修清单 空调消防 | I1: =G39 -> 72470.009 | Q1: =不含空调消防清单!Q1 -> 1 | S1: =不含空调消防清单!S1 -> 1 | T1: =不含空调消防清单!T1 -> 1 | U1: =不含空调消防清单!U1 -> 1
A2: 序号 | B2: 项目名称 | C2: 项目特征 | D2: 单位 | E2: 工程量 | F2: 综合单价（不含税） | G2: 合价 | H2: 备注 | I2: 综合单价（不含税） | J2: 主材费 | K2: 主材损耗率 | L2: 人工费 | M2: 辅材费 | N2: 机械费 | O2: 合计 | P2: 成本价 | Q2: 主材费 | R2: 主材损耗率 | S2: 人工费 | T2: 辅材费 | U2: 机械费 | V2: 成本合计
A3: 一 | B3: 空调工程 | G3: =SUBTOTAL(9,G4:G4) -> 31500
A4: 1 | B4: 空调风机盘管2P | C4: 1、包含铝合金风口、空调管道、帆布、钢结构支架等 | D4: 台 | E4: 5 | F4: =I4 -> 6300 | G4: =F4*E4 -> 31500 | I4: =J4+J4*K4+L4+M4+N4 -> 6300 | J4: =Q4*$Q$1 -> 6300 | K4: =R4 -> 0 | L4: =S4*$S$1 -> 0 | M4: =T4*$T$1 -> 0 | N4: =U4*$U$1 -> 0 | O4: =E4*I4 -> 31500 | P4: =Q4+Q4*R4+S4+T4+U4 -> 6300 | Q4: 6300 | V4: =E4*P4 -> 31500
A5: 二 | B5: 消防改造 | G5: =SUBTOTAL(9,G7:G35) -> 31820.235
A6: （一） | B6: 火灾自动报警系统
A7: 1 | B7: 探测器拆除、安装 | C7: 1.名称：感烟 2.型号.规格： | D7: 套 | E7: 3 | F7: =I7 -> 191.4 | G7: =F7*E7 -> 574.2 | I7: 191.4 | J7: =Q7*$Q$1 -> 0 | K7: =R7 -> 0 | L7: =S7*$S$1 -> 0 | M7: =T7*$T$1 -> 0 | N7: =U7*$U$1 -> 0 | O7: =E7*I7 -> 574.2 | P7: =Q7+Q7*R7+S7+T7+U7 -> 0 | V7: =E7*P7 -> 0
A8: 2 | B8: 探测器新增、安装 | C8: 1.规格型号:感烟 2.其它：符合规范和设计要求 | D8: 套 | E8: 3 | F8: =I8 -> 261 | G8: =F8*E8 -> 783 | I8: 261 | J8: =Q8*$Q$1 -> 0 | K8: =R8 -> 0 | L8: =S8*$S$1 -> 0 | M8: =T8*$T$1 -> 0 | N8: =U8*$U$1 -> 0 | O8: =E8*I8 -> 783 | P8: =Q8+Q8*R8+S8+T8+U8 -> 0 | V8: =E8*P8 -> 0
A9: 3 | B9: 消防广播拆除、安装 | C9: 1.名称：消防广播 2.型号.规格： | D9: 套 | E9: 1 | F9: =I9 -> 191.4 | G9: =F9*E9 -> 191.4 | I9: 191.4 | J9: =Q9*$Q$1 -> 0 | K9: =R9 -> 0 | L9: =S9*$S$1 -> 0 | M9: =T9*$T$1 -> 0 | N9: =U9*$U$1 -> 0 | O9: =E9*I9 -> 191.4 | P9: =Q9+Q9*R9+S9+T9+U9 -> 0 | V9: =E9*P9 -> 0
A10: 4 | B10: 电气配管 | C10: 1.型号规格：JDG20 2.敷设形式：综合考虑 3.含接线盒 4.根据现场情况改造到位 | D10: 米 | E10: 25 | F10: =I10 -> 24.36 | G10: =F10*E10 -> 609 | I10: 24.36 | J10: =Q10*$Q$1 -> 0 | K10: =R10 -> 0 | L10: =S10*$S$1 -> 0 | M10: =T10*$T$1 -> 0 | N10: =U10*$U$1 -> 0 | O10: =E10*I10 -> 609 | P10: =Q10+Q10*R10+S10+T10+U10 -> 0 | V10: =E10*P10 -> 0
A11: 5 | B11: 金属软管 | C11: 1.型号规格：φ20 2.敷设形式：综合考虑 | D11: 米 | E11: 3 | F11: =I11 -> 10.44 | G11: =F11*E11 -> 31.32 | I11: 10.44 | J11: =Q11*$Q$1 -> 0 | K11: =R11 -> 0 | L11: =S11*$S$1 -> 0 | M11: =T11*$T$1 -> 0 | N11: =U11*$U$1 -> 0 | O11: =E11*I11 -> 31.32 | P11: =Q11+Q11*R11+S11+T11+U11 -> 0 | V11: =E11*P11 -> 0
A12: 6 | B12: 电气配线 | C12: 1.名称:阻燃屏蔽双绞线 2.型号规格：ZR-RVS-2*1.5mm 3.敷设方式：穿管及线槽敷设 | D12: 米 | E12: 45 | F12: =I12 -> 6.96 | G12: =F12*E12 -> 313.2 | I12: 6.96 | J12: =Q12*$Q$1 -> 0 | K12: =R12 -> 0 | L12: =S12*$S$1 -> 0 | M12: =T12*$T$1 -> 0 | N12: =U12*$U$1 -> 0 | O12: =E12*I12 -> 313.2 | P12: =Q12+Q12*R12+S12+T12+U12 -> 0 | V12: =E12*P12 -> 0
A13: 7 | B13: 报警系统调试 | C13: 1、仅限我司施工 的项目 | D13: 项 | E13: 1 | F13: =I13 -> 1000 | G13: =F13*E13 -> 1000 | I13: 1000 | J13: =Q13*$Q$1 -> 0 | K13: =R13 -> 0 | L13: =S13*$S$1 -> 0 | M13: =T13*$T$1 -> 0 | N13: =U13*$U$1 -> 0 | O13: =E13*I13 -> 1000 | P13: =Q13+Q13*R13+S13+T13+U13 -> 0 | V13: =E13*P13 -> 0
A14: 8 | B14: 编程入网、系统接驳 | C14: 1、由大厦原消防施工单位负责，物业统一收费 | D14: ㎡ | E14: 266.31 | F14: =I14 -> 30 | G14: =F14*E14 -> 7989.3 | H14: 不足4000元的按最低4000元计算。超过4000元的按建筑面积30元/㎡计算。 | I14: 30 | J14: =Q14*$Q$1 -> 0 | K14: =R14 -> 0 | L14: =S14*$S$1 -> 20 | M14: =T14*$T$1 -> 0 | N14: =U14*$U$1 -> 0 | O14: =E14*I14 -> 7989.3 | P14: =Q14+Q14*R14+S14+T14+U14 -> 20 | S14: 20 | V14: =E14*P14 -> 5326.2
A15: （二） | B15: 自动喷淋灭火系统 | G15: =F15*E15 -> 0
A16: 1 | B16: 保护性拆除明装喷头 | C16: 1.名称：上喷头保护性拆除 2.型号.规格： | D16: 个 | E16: 16 | F16: =I16 -> 174 | G16: =F16*E16 -> 2784 | I16: 174 | J16: =Q16*$Q$1 -> 0 | K16: =R16 -> 0 | L16: =S16*$S$1 -> 0 | M16: =T16*$T$1 -> 0 | N16: =U16*$U$1 -> 0 | O16: =E16*I16 -> 2784 | P16: =Q16+Q16*R16+S16+T16+U16 -> 0 | V16: =E16*P16 -> 0
A17: 2 | B17: 明装喷头 | C17: 1.名称：明装喷头 2.型号.规格： 3.其它：符合规范和设计要求 | D17: 个 | E17: 17 | F17: =I17 -> 217.5 | G17: =F17*E17 -> 3697.5 | I17: 217.5 | J17: =Q17*$Q$1 -> 0 | K17: =R17 -> 0 | L17: =S17*$S$1 -> 0 | M17: =T17*$T$1 -> 0 | N17: =U17*$U$1 -> 0 | O17: =E17*I17 -> 3697.5 | P17: =Q17+Q17*R17+S17+T17+U17 -> 0 | V17: =E17*P17 -> 0
A18: 3 | B18: 管网支吊架 | C18: 1、含钢制作、安装 | D18: KG | E18: 15 | F18: =I18 -> 21.75 | G18: =F18*E18 -> 326.25 | I18: 21.75 | J18: =Q18*$Q$1 -> 0 | K18: =R18 -> 0 | L18: =S18*$S$1 -> 0 | M18: =T18*$T$1 -> 0 | N18: =U18*$U$1 -> 0 | O18: =E18*I18 -> 326.25 | P18: =Q18+Q18*R18+S18+T18+U18 -> 0 | V18: =E18*P18 -> 0
A19: 4 | B19: 大红油漆（含人工及天那水） | C19: 1、含油漆、天那水、人工 | D19: 桶 | E19: 1 | F19: =I19 -> 435 | G19: =F19*E19 -> 435 | I19: 435 | J19: =Q19*$Q$1 -> 0 | K19: =R19 -> 0 | L19: =S19*$S$1 -> 0 | M19: =T19*$T$1 -> 0 | N19: =U19*$U$1 -> 0 | O19: =E19*I19 -> 435 | P19: =Q19+Q19*R19+S19+T19+U19 -> 0 | V19: =E19*P19 -> 0
A20: 5 | B20: 消防喷淋管 DN25 | C20: 1.安装部位：室内 2.介质:喷淋给水 3.材质、规格:内外壁热镀锌钢管DN25 4.连接方式:螺纹连接 含管件 5.其他要求:满足施工图纸技术规范要求 | D20: 米 | E20: 16.5 | F20: =I20 -> 50.46 | G20: =F20*E20 -> 832.59 | I20: 50.46 | J20: =Q20*$Q$1 -> 0 | K20: =R20 -> 0 | L20: =S20*$S$1 -> 0 | M20: =T20*$T$1 -> 0 | N20: =U20*$U$1 -> 0 | O20: =E20*I20 -> 832.59 | P20: =Q20+Q20*R20+S20+T20+U20 -> 0 | V20: =E20*P20 -> 0
A21: 6 | B21: 消防喷淋管 DN32 | C21: 1.安装部位：室内 2.介质:喷淋给水 3.材质、规格:内外壁热镀锌钢管DN32 4.连接方式:螺纹连接 含管件 5.其他要求:满足施工图纸技术规范要求 | D21: 米 | E21: 8.5 | F21: =I21 -> 56.55 | G21: =F21*E21 -> 480.675 | I21: 56.55 | J21: =Q21*$Q$1 -> 0 | K21: =R21 -> 0 | L21: =S21*$S$1 -> 0 | M21: =T21*$T$1 -> 0 | N21: =U21*$U$1 -> 0 | O21: =E21*I21 -> 480.675 | P21: =Q21+Q21*R21+S21+T21+U21 -> 0 | V21: =E21*P21 -> 0
A22: 7 | B22: 消防喷淋管 DN40 | C22: 1.安装部位：室内 2.介质:喷淋给水 3.材质、规格:内外壁热镀锌钢管DN40 4.连接方式:螺纹连接 含管件 5.其他要求:满足施工图纸技术规范要求 | D22: 米 | E22: 3.5 | F22: =I22 -> 65.25 | G22: =F22*E22 -> 228.375 | I22: 65.25 | J22: =Q22*$Q$1 -> 0 | K22: =R22 -> 0 | L22: =S22*$S$1 -> 0 | M22: =T22*$T$1 -> 0 | N22: =U22*$U$1 -> 0 | O22: =E22*I22 -> 228.375 | P22: =Q22+Q22*R22+S22+T22+U22 -> 0 | V22: =E22*P22 -> 0
A23: 8 | B23: 消防喷淋管 DN50 | C23: 1.安装部位：室内 2.介质:喷淋给水 3.材质、规格:内外壁热镀锌钢管DN50 4.连接方式:螺纹连接 含管件 5.其他要求:满足施工图纸技术规范要求 | D23: 米 | E23: 2.5 | F23: =I23 -> 80.91 | G23: =F23*E23 -> 202.275 | I23: 80.91 | J23: =Q23*$Q$1 -> 0 | K23: =R23 -> 0 | L23: =S23*$S$1 -> 0 | M23: =T23*$T$1 -> 0 | N23: =U23*$U$1 -> 0 | O23: =E23*I23 -> 202.275 | P23: =Q23+Q23*R23+S23+T23+U23 -> 0 | V23: =E23*P23 -> 0
A24: 9 | B24: 喷淋管网排水费 | C24: 1、含管网排水费及人工 | D24: 项 | E24: 1 | F24: =I24 -> 800 | G24: =F24*E24 -> 800 | I24: 800 | J24: =Q24*$Q$1 -> 0 | K24: =R24 -> 0 | L24: =S24*$S$1 -> 0 | M24: =T24*$T$1 -> 0 | N24: =U24*$U$1 -> 0 | O24: =E24*I24 -> 800 | P24: =Q24+Q24*R24+S24+T24+U24 -> 0 | V24: =E24*P24 -> 0
A25: 10 | B25: 喷淋管网试压 | C25: 1、管网冲洗、试压、调试 | D25: 项 | E25: 1 | F25: =I25 -> 870 | G25: =F25*E25 -> 870 | I25: 870 | J25: =Q25*$Q$1 -> 0 | K25: =R25 -> 0 | L25: =S25*$S$1 -> 0 | M25: =T25*$T$1 -> 0 | N25: =U25*$U$1 -> 0 | O25: =E25*I25 -> 870 | P25: =Q25+Q25*R25+S25+T25+U25 -> 0 | V25: =E25*P25 -> 0
A26: （三） | B26: 机械排烟系统
A27: 1 | B27: 镀锌风管拆除、移位 | D27: ㎡ | E27: 5.5 | F27: =I27 -> 156.6 | G27: =F27*E27 -> 861.3 | I27: 156.6 | J27: =Q27*$Q$1 -> 0 | K27: =R27 -> 0 | L27: =S27*$S$1 -> 0 | M27: =T27*$T$1 -> 0 | N27: =U27*$U$1 -> 0 | O27: =E27*I27 -> 861.3 | P27: =Q27+Q27*R27+S27+T27+U27 -> 0 | V27: =E27*P27 -> 0
A28: 2 | B28: 镀锌风管新增、安装 | C28: 1.风管的制作与安装 2.法兰、支架的制作、防锈与安装固定 | D28: ㎡ | E28: 1.5 | F28: =I28 -> 147.9 | G28: =F28*E28 -> 221.85 | I28: 147.9 | J28: =Q28*$Q$1 -> 0 | K28: =R28 -> 0 | L28: =S28*$S$1 -> 0 | M28: =T28*$T$1 -> 0 | N28: =U28*$U$1 -> 0 | O28: =E28*I28 -> 221.85 | P28: =Q28+Q28*R28+S28+T28+U28 -> 0 | V28: =E28*P28 -> 0
A29: 3 | B29: 风管防火包裹 | D29: ㎡ | E29: =E27+E28 -> 7 | F29: =I29 -> 87 | G29: =F29*E29 -> 609 | I29: 87 | J29: =Q29*$Q$1 -> 0 | K29: =R29 -> 0 | L29: =S29*$S$1 -> 0 | M29: =T29*$T$1 -> 0 | N29: =U29*$U$1 -> 0 | O29: =E29*I29 -> 609 | P29: =Q29+Q29*R29+S29+T29+U29 -> 0 | V29: =E29*P29 -> 0
A30: 4 | B30: 280℃防火阀拆除、安装 | C30: 1.型号：防火阀280℃ 2.包含设备及辅材安装费 3.包含电源线接驳 | D30: 套 | E30: 1 | F30: =I30 -> 870 | G30: =F30*E30 -> 870 | I30: 870 | J30: =Q30*$Q$1 -> 0 | K30: =R30 -> 0 | L30: =S30*$S$1 -> 0 | M30: =T30*$T$1 -> 0 | N30: =U30*$U$1 -> 0 | O30: =E30*I30 -> 870 | P30: =Q30+Q30*R30+S30+T30+U30 -> 0 | V30: =E30*P30 -> 0
A31: 5 | B31: 常开百叶风口 | C31: 1、规格：成品铝框架百叶风口供货及安装 2、包含但不限于编制说明、图纸、技术要求中的相关内容及完成该项目的一切所需 | D31: 个 | E31: 5 | F31: =I31 -> 348 | G31: =F31*E31 -> 1740 | I31: 348 | J31: =Q31*$Q$1 -> 0 | K31: =R31 -> 0 | L31: =S31*$S$1 -> 0 | M31: =T31*$T$1 -> 0 | N31: =U31*$U$1 -> 0 | O31: =E31*I31 -> 1740 | P31: =Q31+Q31*R31+S31+T31+U31 -> 0 | V31: =E31*P31 -> 0
A32: 6 | B32: 排烟系统调试 | D32: 项 | E32: 1 | F32: =I32 -> 1500 | G32: =F32*E32 -> 1500 | I32: 1500 | J32: =Q32*$Q$1 -> 0 | K32: =R32 -> 0 | L32: =S32*$S$1 -> 0 | M32: =T32*$T$1 -> 0 | N32: =U32*$U$1 -> 0 | O32: =E32*I32 -> 1500 | P32: =Q32+Q32*R32+S32+T32+U32 -> 0 | V32: =E32*P32 -> 0
A33: （四） | B33: 其他
A34: 1 | B34: 消防报验 | C34: 含相关部门收取的报验费用。 | D34: 项 | E34: 1 | F34: =I34 -> 3000 | G34: =F34*E34 -> 3000 | I34: 3000 | J34: =Q34*$Q$1 -> 0 | K34: =R34 -> 0 | L34: =S34*$S$1 -> 0 | M34: =T34*$T$1 -> 0 | N34: =U34*$U$1 -> 0 | O34: =E34*I34 -> 3000 | P34: =Q34+Q34*R34+S34+T34+U34 -> 0 | V34: =E34*P34 -> 0
A35: 2 | B35: 综合专业设计出图 | D35: 套 | E35: 1 | F35: =I35 -> 870 | G35: =F35*E35 -> 870 | I35: 870 | P35: =Q35+Q35*R35+S35+T35+U35 -> 0 | V35: =E35*P35 -> 0
A36: 三 | B36: 小计 | D36: 项 | E36: 1 | G36: =G3+G5 -> 63320.235 | I36: =SUBTOTAL(9,G3:G35) -> 63320.235
A37: 四 | B37: 管理费 | C37: =不含空调消防清单!C106 -> 0.05 | D37: 项 | E37: 1 | G37: =G36*C37 -> 3166.0118
A38: 五 | B38: 税金 | C38: =不含空调消防清单!C107 -> 0.09 | D38: 项 | E38: 1 | G38: =(G36+G37)*C38 -> 5983.7622
A39: 六 | B39: 合计 | D39: 项 | E39: 1 | G39: =G38+G37+G36 -> 72470.009

Sheet 材料设备参考品牌
A1: 3206材料设备参考品牌
A2: 序号 | B2: 专业 | C2: 材料名称 | D2: 中高档品牌，报两三个品牌 | E2: 备注
A3: 1 | B3: 装饰 | C3: 地砖 | D3: 玛格罗兰、简一
A4: 2 | B4: 装饰 | C4: 岩板（800*1600） | D4: 伊诺、玛格罗兰
A5: 3 | B5: 装饰 | C5: 木饰面 | D5: 定制
A6: 4 | B6: 装饰 | C6: 不锈钢 | D6: 国产优质
A7: 5 | B7: 装饰 | C7: 石膏板 | D7: 深耐福
A8: 6 | B8: 装饰 | C8: 夹板、阻燃板 | D8: 深耐福
A9: 7 | B9: 装饰 | C9: 艺术漆 | D9: =D6 -> 国产优质
A10: 8 | B10: 装饰 | C10: 乳胶漆 | D10: 立邦
A11: 9 | B11: 装饰 | C11: 腻子 | D11: 立邦
A12: 10 | B12: 安装 | C12: 照明，强电用线 | D12: 南洋
A13: 11 | B13: 安装 | C13: 灯具（射灯、筒灯） | D13: 三雄、欧普
A14: 12 | B14: 安装 | C14: LED灯带 | D14: 三雄、欧普
A15: 13 | B15: 安装 | C15: 照明开关 | D15: 公牛
A16: 14 | B16: 安装 | C16: 插座 | D16: 公牛
A17: 15 | B17: 安装 | C17: 网络插座 | D17: 公牛
A18: 16 | B18: 安装 | C18: 信号线、网线 | D18: 海康
A19: 17 | B19: 空调 | C19: 空调风机盘管 | D19: 麦克维尔
A20: 18 | B20: 安装 | C20: 电动窗帘电机 | D20: 国产杜亚
