Workbook

Sheet 汇总表
A1: 会所售楼部安装工程汇总表
A2: 序号 | B2: 单位工程 | C2: 含税合价 | D2: 不含税控制合价 | E2: 含税控制合价 | F2: 备注
A3: 1 | B3: 会所售楼部安装工程——电气 | C3: =电气工程!M63 -> 1055985.4 | D3: 472090.65 | E3: =D3*1.09 -> 514578.81
A4: 2 | B4: 会所售楼部安装工程——给排水 | C4: =给排水工程!M31 -> 37242.207 | D4: 102836 | E4: =D4*1.09 -> 112091.24
A5: 3 | B5: 会所售楼部安装工程——空调 | C5: =空调工程!M61 -> 634956.11 | D5: 322743.33 | E5: =D5*1.09 -> 351790.23
A8: 小计 | C8: =SUM(C3:C7) -> 1728183.7 | D8: =SUM(D3:D7) -> 897669.98 | E8: =SUM(E3:E7) -> 978460.28

Sheet 电气工程
A1: 会所售楼部电气工程工程量清单 | O1: 成本单价组成（投标人填写）
A2: 序号 | B2: 编码 | C2: 项目名称 | D2: 项目特征 | E2: 单位 | F2: 工程量 | G2: 人工费 | H2: 材料费 | I2: 机械费 | J2: 管理费 | K2: 利润 | L2: 不含税单价 | M2: 合价 | O2: 单价合计 | P2: 主材费 | Q2: 主材损耗率 | R2: 人工费 | S2: 辅材费 | T2: 机械费 | U2: 合计
J3: 0 | K3: 0 | P3: 1 | R3: 1 | S3: 1 | T3: 1
B4: 单位工程
C5: 电气工程
C6: 灯具、电器
A7: 1 | B7: 30413002001 | C7: L1 嵌入式LED可调射灯 | D7: 1.名称：L1 嵌入式LED可调射灯 2.规格：LED COB 15W 3000K±50 3.尺寸：φ77mm*H90mm 4.安装方式：嵌装 5.其他：包括但不限于满足图纸、招标文件、规范及验收要求等一切相关费用 | E7: 套 | F7: 68 | G7: =R7*$R$3 -> 18 | H7: =P7*(1+Q7)*$P$3+S7*$S$3 -> 87 | I7: =T7*$T$3 -> 4 | J7: =(G7+H7+I7)*$J$3 -> 0 | K7: =(G7+H7+I7+J7)*$K$3 -> 0 | L7: =G7+H7+I7+J7+K7 -> 109 | M7: =F7*L7 -> 7412 | O7: =P7*(1+Q7)+R7+S7+T7 -> 109 | P7: 85 | Q7: 0 | R7: 18 | S7: 2 | T7: 4 | U7: =F7*O7 -> 7412
A8: 2 | B8: 30413002002 | C8: L2 嵌入式LED筒灯 | D8: 1.名称：L2 嵌入式LED筒灯 2.规格：LED COB 15W 3000K±50 3.尺寸：φ77mm*H99mm 4.安装方式：嵌装 5.其他：包括但不限于满足图纸、招标文件、规范及验收要求等一切相关费用 | E8: 套 | F8: 16 | G8: =R8*$R$3 -> 18 | H8: =P8*(1+Q8)*$P$3+S8*$S$3 -> 91 | I8: =T8*$T$3 -> 8 | J8: =(G8+H8+I8)*$J$3 -> 0 | K8: =(G8+H8+I8+J8)*$K$3 -> 0 | L8: =G8+H8+I8+J8+K8 -> 117 | M8: =F8*L8 -> 1872 | O8: =P8*(1+Q8)+R8+S8+T8 -> 117 | P8: 85 | Q8: 0 | R8: 18 | S8: 6 | T8: 8 | U8: =F8*O8 -> 1872
A9: 3 | B9: 30413002003 | C9: L3 嵌入式LED可调射灯 | D9: 1.名称：L3 嵌入式LED可调射灯 2.规格：LED COB 7W 2700K±50 3.尺寸：φ77mm*H78mm 4.安装方式：嵌装 5.其他：包括但不限于满足图纸、招标文件、规范及验收要求等一切相关费用 | E9: 套 | F9: 156 | G9: =R9*$R$3 -> 18 | H9: =P9*(1+Q9)*$P$3+S9*$S$3 -> 87 | I9: =T9*$T$3 -> 4 | J9: =(G9+H9+I9)*$J$3 -> 0 | K9: =(G9+H9+I9+J9)*$K$3 -> 0 | L9: =G9+H9+I9+J9+K9 -> 109 | M9: =F9*L9 -> 17004 | O9: =P9*(1+Q9)+R9+S9+T9 -> 109 | P9: 85 | Q9: 0 | R9: 18 | S9: 2 | T9: 4 | U9: =F9*O9 -> 17004
A10: 4 | B10: 30413002004 | C10: L4 嵌入式LED可调射灯 | D10: 1.名称：L4 嵌入式LED可调射灯 2.规格：LED COB 9W 2700K±50 3.尺寸：φ77mm*H78mm 4.安装方式：嵌装 5.其他：包括但不限于满足图纸、招标文件、规范及验收要求等一切相关费用 | E10: 套 | F10: 21 | G10: =R10*$R$3 -> 18 | H10: =P10*(1+Q10)*$P$3+S10*$S$3 -> 87 | I10: =T10*$T$3 -> 4 | J10: =(G10+H10+I10)*$J$3 -> 0 | K10: =(G10+H10+I10+J10)*$K$3 -> 0 | L10: =G10+H10+I10+J10+K10 -> 109 | M10: =F10*L10 -> 2289 | O10: =P10*(1+Q10)+R10+S10+T10 -> 109 | P10: 85 | Q10: 0 | R10: 18 | S10: 2 | T10: 4 | U10: =F10*O10 -> 2289
A11: 5 | B11: 30413002005 | C11: L5 明装LED可调射灯 | D11: 1.名称：L5 明装LED可调射灯 2.规格：LED COB 15W 3500K±50 3.尺寸：L85mm*W85mm*H90mm 4.安装方式：明装 5.其他：包括但不限于满足图纸、招标文件、规范及验收要求等一切相关费用 | E11: 套 | F11: 4 | G11: =R11*$R$3 -> 18 | H11: =P11*(1+Q11)*$P$3+S11*$S$3 -> 87 | I11: =T11*$T$3 -> 4 | J11: =(G11+H11+I11)*$J$3 -> 0 | K11: =(G11+H11+I11+J11)*$K$3 -> 0 | L11: =G11+H11+I11+J11+K11 -> 109 | M11: =F11*L11 -> 436 | O11: =P11*(1+Q11)+R11+S11+T11 -> 109 | P11: 85 | Q11: 0 | R11: 18 | S11: 2 | T11: 4 | U11: =F11*O11 -> 436
A12: 6 | B12: 30413002006 | C12: L6 嵌入式LED可调射灯 | D12: 1.名称：L6 嵌入式LED可调射灯 2.规格：LED COB 12W 2700K±50 3.尺寸：φ77mm*H78mm 4.安装方式：嵌装 5.其他：包括但不限于满足图纸、招标文件、规范及验收要求等一切相关费用 | E12: 套 | F12: 2 | G12: =R12*$R$3 -> 18 | H12: =P12*(1+Q12)*$P$3+S12*$S$3 -> 87 | I12: =T12*$T$3 -> 4 | J12: =(G12+H12+I12)*$J$3 -> 0 | K12: =(G12+H12+I12+J12)*$K$3 -> 0 | L12: =G12+H12+I12+J12+K12 -> 109 | M12: =F12*L12 -> 218 | O12: =P12*(1+Q12)+R12+S12+T12 -> 109 | P12: 85 | Q12: 0 | R12: 18 | S12: 2 | T12: 4 | U12: =F12*O12 -> 218
A13: 7 | B13: 30413002007 | C13: L7 嵌入式LED可调射灯 | D13: 1.名称：L7 嵌入式LED可调射灯 2.规格：LED COB 12W 2700K±50 3.尺寸：φ77mm*H78mm 4.安装方式：嵌装 5.其他：包括但不限于满足图纸、招标文件、规范及验收要求等一切相关费用 | E13: 套 | F13: 11 | G13: =R13*$R$3 -> 18 | H13: =P13*(1+Q13)*$P$3+S13*$S$3 -> 87 | I13: =T13*$T$3 -> 4 | J13: =(G13+H13+I13)*$J$3 -> 0 | K13: =(G13+H13+I13+J13)*$K$3 -> 0 | L13: =G13+H13+I13+J13+K13 -> 109 | M13: =F13*L13 -> 1199 | O13: =P13*(1+Q13)+R13+S13+T13 -> 109 | P13: 85 | Q13: 0 | R13: 18 | S13: 2 | T13: 4 | U13: =F13*O13 -> 1199
A14: 8 | B14: 30413002008 | C14: L8 嵌入式LED可调射灯 | D14: 1.名称：L8 嵌入式LED可调射灯 2.规格：LED COB 7W 2700K±50 3.尺寸：φ77mm*H78mm 4.安装方式：嵌装 5.其他：包括但不限于满足图纸、招标文件、规范及验收要求等一切相关费用 | E14: 套 | F14: 7 | G14: =R14*$R$3 -> 18 | H14: =P14*(1+Q14)*$P$3+S14*$S$3 -> 87 | I14: =T14*$T$3 -> 4 | J14: =(G14+H14+I14)*$J$3 -> 0 | K14: =(G14+H14+I14+J14)*$K$3 -> 0 | L14: =G14+H14+I14+J14+K14 -> 109 | M14: =F14*L14 -> 763 | O14: =P14*(1+Q14)+R14+S14+T14 -> 109 | P14: 85 | Q14: 0 | R14: 18 | S14: 2 | T14: 4 | U14: =F14*O14 -> 763
A15: 9 | B15: 30413002009 | C15: L10 嵌入式LED可调射灯 | D15: 1.名称：L10 嵌入式LED可调射灯 2.规格：LED COB 7W 2700K±50 3.尺寸：φ77mm*H78mm 4.安装方式：嵌装 5.其他：包括但不限于满足图纸、招标文件、规范及验收要求等一切相关费用 | E15: 套 | F15: 20 | G15: =R15*$R$3 -> 18 | H15: =P15*(1+Q15)*$P$3+S15*$S$3 -> 87 | I15: =T15*$T$3 -> 4 | J15: =(G15+H15+I15)*$J$3 -> 0 | K15: =(G15+H15+I15+J15)*$K$3 -> 0 | L15: =G15+H15+I15+J15+K15 -> 109 | M15: =F15*L15 -> 2180 | O15: =P15*(1+Q15)+R15+S15+T15 -> 109 | P15: 85 | Q15: 0 | R15: 18 | S15: 2 | T15: 4 | U15: =F15*O15 -> 2180
A16: 10 | B16: 30413001001 | C16: L11 吊线办公灯 | D16: 1.名称：L11 吊线办公灯 2.规格：LED 30W 4000K±50 3.尺寸：L1206mm*W75mm*H73.5mm 4.安装方式：吊装 5.其他：包括但不限于满足图纸、招标文件、规范及验收要求等一切相关费用 | E16: 套 | F16: 7 | G16: =R16*$R$3 -> 18 | H16: =P16*(1+Q16)*$P$3+S16*$S$3 -> 126 | I16: =T16*$T$3 -> 8 | J16: =(G16+H16+I16)*$J$3 -> 0 | K16: =(G16+H16+I16+J16)*$K$3 -> 0 | L16: =G16+H16+I16+J16+K16 -> 152 | M16: =F16*L16 -> 1064 | O16: =P16*(1+Q16)+R16+S16+T16 -> 152 | P16: 120 | Q16: 0 | R16: 18 | S16: 6 | T16: 8 | U16: =F16*O16 -> 1064
A17: 11 | B17: 30413001002 | C17: L12 吸顶灯 | D17: 1.名称：L12 吸顶灯 2.规格：LED 18W 4000K±50 3.尺寸：Φ290mm*H54.5mm 4.安装方式：吸顶 5.其他：包括但不限于满足图纸、招标文件、规范及验收要求等一切相关费用 | E17: 套 | F17: 4 | G17: =R17*$R$3 -> 18 | H17: =P17*(1+Q17)*$P$3+S17*$S$3 -> 66 | I17: =T17*$T$3 -> 8 | J17: =(G17+H17+I17)*$J$3 -> 0 | K17: =(G17+H17+I17+J17)*$K$3 -> 0 | L17: =G17+H17+I17+J17+K17 -> 92 | M17: =F17*L17 -> 368 | O17: =P17*(1+Q17)+R17+S17+T17 -> 92 | P17: 60 | Q17: 0 | R17: 18 | S17: 6 | T17: 8 | U17: =F17*O17 -> 368
A18: 12 | B18: 30413004001 | C18: L13 LED地埋灯 | D18: 1.名称：L13 LED地埋灯 2.规格：LED 1W 2700K±50 3.尺寸：Φ42mm*H75mm 4.安装方式：埋地 5.其他：包括但不限于满足图纸、招标文件、规范及验收要求等一切相关费用 | E18: 套 | F18: 3 | G18: =R18*$R$3 -> 18 | H18: =P18*(1+Q18)*$P$3+S18*$S$3 -> 126 | I18: =T18*$T$3 -> 8 | J18: =(G18+H18+I18)*$J$3 -> 0 | K18: =(G18+H18+I18+J18)*$K$3 -> 0 | L18: =G18+H18+I18+J18+K18 -> 152 | M18: =F18*L18 -> 456 | O18: =P18*(1+Q18)+R18+S18+T18 -> 152 | P18: 120 | Q18: 0 | R18: 18 | S18: 6 | T18: 8 | U18: =F18*O18 -> 456
... A30: 24 | B30: 30405017001 | C30: 洗碗机 | D30: 1.名称：洗碗机 2.规格：- 3.尺寸：详见物料表 4.其他：包括但不限于满足图纸、招标文件、规范及验收要求等一切相关费用 | E30: 台 | F30: 1 | G30: =R30*$R$3 -> 250 | H30: =P30*(1+Q30)*$P$3+S30*$S$3 -> 4235 | I30: =T30*$T$3 -> 8.5 | J30: =(G30+H30+I30)*$J$3 -> 0 | K30: =(G30+H30+I30+J30)*$K$3 -> 0 | L30: =G30+H30+I30+J30+K30 -> 4493.5 | M30: =F30*L30 -> 4493.5 | O30: =P30*(1+Q30)+R30+S30+T30 -> 4493.5 | P30: 4200 | Q30: 0 | R30: 250 | S30: 35 | T30: 8.5 | U30: =F30*O30 -> 4493.5
C31: 开关插座
A32: 25 | B32: 30413013001 | C32: 照明开关 | D32: 1.名称：单联单控开关 2.规格：86*86mm 3.安装方式：暗装 4.其他：包括但不限于满足图纸、招标文件、规范及验收要求等一切相关费用 | E32: 套 | F32: 5 | G32: =R32*$R$3 -> 6.31 | H32: =P32*(1+Q32)*$P$3+S32*$S$3 -> 15.74 | I32: =T32*$T$3 -> 0 | J32: =(G32+H32+I32)*$J$3 -> 0 | K32: =(G32+H32+I32+J32)*$K$3 -> 0 | L32: =G32+H32+I32+J32+K32 -> 22.05 | M32: =F32*L32 -> 110.25 | O32: =P32*(1+Q32)+R32+S32+T32 -> 22.05 | P32: 14.62 | Q32: 0 | R32: 6.31 | S32: 1.12 | T32: 0 | U32: =F32*O32 -> 110.25
A33: 26 | B33: 30413013002 | C33: 照明开关 | D33: 1.名称：双联单控开关 2.规格：86*86mm 3.安装方式：暗装 4.其他：包括但不限于满足图纸、招标文件、规范及验收要求等一切相关费用 | E33: 套 | F33: 10 | G33: =R33*$R$3 -> 10 | H33: =P33*(1+Q33)*$P$3+S33*$S$3 -> 19.5 | I33: =T33*$T$3 -> 0 | J33: =(G33+H33+I33)*$J$3 -> 0 | K33: =(G33+H33+I33+J33)*$K$3 -> 0 | L33: =G33+H33+I33+J33+K33 -> 29.5 | M33: =F33*L33 -> 295 | O33: =P33*(1+Q33)+R33+S33+T33 -> 29.5 | P33: 18 | Q33: 0 | R33: 10 | S33: 1.5 | T33: 0 | U33: =F33*O33 -> 295
A34: 27 | B34: 30413013003 | C34: 照明开关 | D34: 1.名称：三联单控开关 2.规格：86*86mm 3.安装方式：暗装 4.其他：包括但不限于满足图纸、招标文件、规范及验收要求等一切相关费用 | E34: 套 | F34: 23 | G34: =R34*$R$3 -> 12 | H34: =P34*(1+Q34)*$P$3+S34*$S$3 -> 21.5 | I34: =T34*$T$3 -> 0 | J34: =(G34+H34+I34)*$J$3 -> 0 | K34: =(G34+H34+I34+J34)*$K$3 -> 0 | L34: =G34+H34+I34+J34+K34 -> 33.5 | M34: =F34*L34 -> 770.5 | O34: =P34*(1+Q34)+R34+S34+T34 -> 33.5 | P34: 20 | Q34: 0 | R34: 12 | S34: 1.5 | T34: 0 | U34: =F34*O34 -> 770.5
A35: 28 | B35: 30413013004 | C35: 照明开关 | D35: 1.名称：卫生间排风开关 2.规格：86*86mm 3.安装方式：暗装 4.其他：包括但不限于满足图纸、招标文件、规范及验收要求等一切相关费用 | E35: 套 | F35: 4 | G35: =R35*$R$3 -> 6.31 | H35: =P35*(1+Q35)*$P$3+S35*$S$3 -> 15.74 | I35: =T35*$T$3 -> 0 | J35: =(G35+H35+I35)*$J$3 -> 0 | K35: =(G35+H35+I35+J35)*$K$3 -> 0 | L35: =G35+H35+I35+J35+K35 -> 22.05 | M35: =F35*L35 -> 88.2 | O35: =P35*(1+Q35)+R35+S35+T35 -> 22.05 | P35: 14.62 | Q35: 0 | R35: 6.31 | S35: 1.12 | T35: 0 | U35: =F35*O35 -> 88.2
A36: 29 | B36: 30413014001 | C36: 插座 | D36: 1.名称：三孔插座 2.规格：86*86mm 3.安装方式：暗装 4.其他：包括但不限于满足图纸、招标文件、规范及验收要求等一切相关费用 | E36: 套 | F36: 2 | G36: =R36*$R$3 -> 6.31 | H36: =P36*(1+Q36)*$P$3+S36*$S$3 -> 15.74 | I36: =T36*$T$3 -> 0 | J36: =(G36+H36+I36)*$J$3 -> 0 | K36: =(G36+H36+I36+J36)*$K$3 -> 0 | L36: =G36+H36+I36+J36+K36 -> 22.05 | M36: =F36*L36 -> 44.1 | O36: =P36*(1+Q36)+R36+S36+T36 -> 22.05 | P36: 14.62 | Q36: 0 | R36: 6.31 | S36: 1.12 | T36: 0 | U36: =F36*O36 -> 44.1
A37: 30 | B37: 30413014002 | C37: 插座 | D37: 1.名称：五孔插座 2.规格：86*86mm 3.安装方式：暗装 4.其他：包括但不限于满足图纸、招标文件、规范及验收要求等一切相关费用 | E37: 套 | F37: 63 | G37: =R37*$R$3 -> 6.31 | H37: =P37*(1+Q37)*$P$3+S37*$S$3 -> 15.74 | I37: =T37*$T$3 -> 0 | J37: =(G37+H37+I37)*$J$3 -> 0 | K37: =(G37+H37+I37+J37)*$K$3 -> 0 | L37: =G37+H37+I37+J37+K37 -> 22.05 | M37: =F37*L37 -> 1389.15 | O37: =P37*(1+Q37)+R37+S37+T37 -> 22.05 | P37: 14.62 | Q37: 0 | R37: 6.31 | S37: 1.12 | T37: 0 | U37: =F37*O37 -> 1389.15
A38: 31 | B38: 30413014003 | C38: 插座 | D38: 1.名称：五孔插座（带防溅盒） 2.规格：86*86mm 3.安装方式：暗装 4.其他：包括但不限于满足图纸、招标文件、规范及验收要求等一切相关费用 | E38: 套 | F38: 15 | G38: =R38*$R$3 -> 6.31 | H38: =P38*(1+Q38)*$P$3+S38*$S$3 -> 15.74 | I38: =T38*$T$3 -> 0 | J38: =(G38+H38+I38)*$J$3 -> 0 | K38: =(G38+H38+I38+J38)*$K$3 -> 0 | L38: =G38+H38+I38+J38+K38 -> 22.05 | M38: =F38*L38 -> 330.75 | O38: =P38*(1+Q38)+R38+S38+T38 -> 22.05 | P38: 14.62 | Q38: 0 | R38: 6.31 | S38: 1.12 | T38: 0 | U38: =F38*O38 -> 330.75
A39: 32 | B39: 30413014004 | C39: 插座 | D39: 1.名称：五孔插座带开关 2.规格：86*86mm 3.安装方式：暗装 4.其他：包括但不限于满足图纸、招标文件、规范及验收要求等一切相关费用 | E39: 套 | F39: 21 | G39: =R39*$R$3 -> 6.31 | H39: =P39*(1+Q39)*$P$3+S39*$S$3 -> 15.74 | I39: =T39*$T$3 -> 0 | J39: =(G39+H39+I39)*$J$3 -> 0 | K39: =(G39+H39+I39+J39)*$K$3 -> 0 | L39: =G39+H39+I39+J39+K39 -> 22.05 | M39: =F39*L39 -> 463.05 | O39: =P39*(1+Q39)+R39+S39+T39 -> 22.05 | P39: 14.62 | Q39: 0 | R39: 6.31 | S39: 1.12 | T39: 0 | U39: =F39*O39 -> 463.05
A40: 33 | B40: 30413014005 | C40: 插座 | D40: 1.名称：五孔插座带开关（带防溅盒） 2.规格：86*86mm 3.安装方式：暗装 4.其他：包括但不限于满足图纸、招标文件、规范及验收要求等一切相关费用 | E40: 套 | F40: 4 | G40: =R40*$R$3 -> 6.31 | H40: =P40*(1+Q40)*$P$3+S40*$S$3 -> 15.74 | I40: =T40*$T$3 -> 0 | J40: =(G40+H40+I40)*$J$3 -> 0 | K40: =(G40+H40+I40+J40)*$K$3 -> 0 | L40: =G40+H40+I40+J40+K40 -> 22.05 | M40: =F40*L40 -> 88.2 | O40: =P40*(1+Q40)+R40+S40+T40 -> 22.05 | P40: 14.62 | Q40: 0 | R40: 6.31 | S40: 1.12 | T40: 0 | U40: =F40*O40 -> 88.2
A41: 34 | B41: 30413014006 | C41: 插座 | D41: 1.名称：五孔地面插座 2.规格：86*86mm 3.安装方式：暗装 4.其他：包括但不限于满足图纸、招标文件、规范及验收要求等一切相关费用 | E41: 套 | F41: 51 | G41: =R41*$R$3 -> 6.31 | H41: =P41*(1+Q41)*$P$3+S41*$S$3 -> 15.74 | I41: =T41*$T$3 -> 0 | J41: =(G41+H41+I41)*$J$3 -> 0 | K41: =(G41+H41+I41+J41)*$K$3 -> 0 | L41: =G41+H41+I41+J41+K41 -> 22.05 | M41: =F41*L41 -> 1124.55 | O41: =P41*(1+Q41)+R41+S41+T41 -> 22.05 | P41: 14.62 | Q41: 0 | R41: 6.31 | S41: 1.12 | T41: 0 | U41: =F41*O41 -> 1124.55
C42: 配管配线
A43: 35 | B43: 30412001001 | C43: 配管 | D43: 1.名称：电气配管 2.规格：JDG20 3.安装方式：暗装 4.其他：包括但不限于满足图纸、招标文件、规范及验收要求等一切相关费用 | E43: m | F43: 2169.81 | G43: =R43*$R$3 -> 2.61 | H43: =P43*(1+Q43)*$P$3+S43*$S$3 -> 1.8 | I43: =T43*$T$3 -> 0.09 | J43: =(G43+H43+I43)*$J$3 -> 0 | K43: =(G43+H43+I43+J43)*$K$3 -> 0 | L43: =G43+H43+I43+J43+K43 -> 4.5 | M43: =F43*L43 -> 9764.145 | O43: =P43*(1+Q43)+R43+S43+T43 -> 4.5 | P43: 1.57 | Q43: 0 | R43: 2.61 | S43: 0.23 | T43: 0.09 | U43: =F43*O43 -> 9764.145
A44: 36 | B44: 30412001002 | C44: 配管 | D44: 1.名称：电气配管 2.规格：JDG25 3.安装方式：暗装 4.其他：包括但不限于满足图纸、招标文件、规范及验收要求等一切相关费用 | E44: m | F44: 324.48 | G44: =R44*$R$3 -> 10.8 | H44: =P44*(1+Q44)*$P$3+S44*$S$3 -> 7.135 | I44: =T44*$T$3 -> 0.2 | J44: =(G44+H44+I44)*$J$3 -> 0 | K44: =(G44+H44+I44+J44)*$K$3 -> 0 | L44: =G44+H44+I44+J44+K44 -> 18.135 | M44: =F44*L44 -> 5884.4448 | O44: =P44*(1+Q44)+R44+S44+T44 -> 18.135 | P44: 6.5 | Q44: 0.03 | R44: 10.8 | S44: 0.44 | T44: 0.2 | U44: =F44*O44 -> 5884.4448
A45: 37 | B45: 30412001003 | C45: 配管 | D45: 1.名称：电气配管 2.规格：PC20 3.安装方式：暗装 4.其他：包括但不限于满足图纸、招标文件、规范及验收要求等一切相关费用 | E45: m | F45: 616.28 | G45: =R45*$R$3 -> 8.5 | H45: =P45*(1+Q45)*$P$3+S45*$S$3 -> 6.66 | I45: =T45*$T$3 -> 0.2 | J45: =(G45+H45+I45)*$J$3 -> 0 | K45: =(G45+H45+I45+J45)*$K$3 -> 0 | L45: =G45+H45+I45+J45+K45 -> 15.36 | M45: =F45*L45 -> 9466.0608 | O45: =P45*(1+Q45)+R45+S45+T45 -> 15.36 | P45: 6 | Q45: 0.03 | R45: 8.5 | S45: 0.48 | T45: 0.2 | U45: =F45*O45 -> 9466.0608
A46: 38 | B46: 30412001004 | C46: 配管 | D46: 1.名称：电气配管 2.规格：PC25 3.安装方式：暗装 4.其他：包括但不限于满足图纸、招标文件、规范及验收要求等一切相关费用 | E46: m | F46: 932.93 | G46: =R46*$R$3 -> 8.5 | H46: =P46*(1+Q46)*$P$3+S46*$S$3 -> 6.66 | I46: =T46*$T$3 -> 0.2 | J46: =(G46+H46+I46)*$J$3 -> 0 | K46: =(G46+H46+I46+J46)*$K$3 -> 0 | L46: =G46+H46+I46+J46+K46 -> 15.36 | M46: =F46*L46 -> 14329.805 | O46: =P46*(1+Q46)+R46+S46+T46 -> 15.36 | P46: 6 | Q46: 0.03 | R46: 8.5 | S46: 0.48 | T46: 0.2 | U46: =F46*O46 -> 14329.805
A47: 39 | B47: 30412001005 | C47: 配管 | D47: 1.名称：电气配管 2.规格：PC32 3.安装方式：暗装 4.其他：包括但不限于满足图纸、招标文件、规范及验收要求等一切相关费用 | E47: m | F47: 24.68 | G47: =R47*$R$3 -> 8.5 | H47: =P47*(1+Q47)*$P$3+S47*$S$3 -> 6.66 | I47: =T47*$T$3 -> 0.2 | J47: =(G47+H47+I47)*$J$3 -> 0 | K47: =(G47+H47+I47+J47)*$K$3 -> 0 | L47: =G47+H47+I47+J47+K47 -> 15.36 | M47: =F47*L47 -> 379.0848 | O47: =P47*(1+Q47)+R47+S47+T47 -> 15.36 | P47: 6 | Q47: 0.03 | R47: 8.5 | S47: 0.48 | T47: 0.2 | U47: =F47*O47 -> 379.0848
A48: 40 | B48: 30412001006 | C48: 配管 | D48: 1.名称：金属软管 2.规格：DN20 3.安装方式：吊顶内安装 4.其他：包括但不限于满足图纸、招标文件、规范及验收要求等一切相关费用 | E48: m | F48: 686.43 | G48: =R48*$R$3 -> 7.6 | H48: =P48*(1+Q48)*$P$3+S48*$S$3 -> 8.993 | I48: =T48*$T$3 -> 0.2 | J48: =(G48+H48+I48)*$J$3 -> 0 | K48: =(G48+H48+I48+J48)*$K$3 -> 0 | L48: =G48+H48+I48+J48+K48 -> 16.793 | M48: =F48*L48 -> 11527.219 | O48: =P48*(1+Q48)+R48+S48+T48 -> 16.793 | P48: 8.1 | Q48: 0.03 | R48: 7.6 | S48: 0.65 | T48: 0.2 | U48: =F48*O48 -> 11527.219
A49: 41 | B49: 30412001007 | C49: 配管 | D49: 1.名称：金属软管 2.规格：DN25 3.安装方式：吊顶内安装 4.其他：包括但不限于满足图纸、招标文件、规范及验收要求等一切相关费用 | E49: m | F49: 286.28 | G49: =R49*$R$3 -> 8.5 | H49: =P49*(1+Q49)*$P$3+S49*$S$3 -> 10.545 | I49: =T49*$T$3 -> 0.2 | J49: =(G49+H49+I49)*$J$3 -> 0 | K49: =(G49+H49+I49+J49)*$K$3 -> 0 | L49: =G49+H49+I49+J49+K49 -> 19.245 | M49: =F49*L49 -> 5509.4586 | O49: =P49*(1+Q49)+R49+S49+T49 -> 19.245 | P49: 9.5 | Q49: 0.03 | R49: 8.5 | S49: 0.76 | T49: 0.2 | U49: =F49*O49 -> 5509.4586
A50: 42 | B50: 31301001001 | C50: 凿槽及修复 | D50: 1.名称：凿槽及修复 2.规格：70*70 3.部位：砖、混凝土结构综合考虑 4.其他：包括但不限于满足图纸、招标文件、规范及验收要求等一切相关费用 | E50: m | F50: 606.51 | G50: =R50*$R$3 -> 17.65 | H50: =P50*(1+Q50)*$P$3+S50*$S$3 -> 0 | I50: =T50*$T$3 -> 2.41 | J50: =(G50+H50+I50)*$J$3 -> 0 | K50: =(G50+H50+I50+J50)*$K$3 -> 0 | L50: =G50+H50+I50+J50+K50 -> 20.06 | M50: =F50*L50 -> 12166.591 | O50: =P50*(1+Q50)+R50+S50+T50 -> 20.06 | P50: 0 | Q50: 0 | R50: 17.65 | S50: 0 | T50: 2.41 | U50: =F50*O50 -> 12166.591
A51: 43 | B51: 30412006001 | C51: 接线盒 | D51: 1.名称：接线盒 2.材质：钢制 3.安装方式：暗装 4.其他：包括但不限于满足图纸、招标文件、规范及验收要求等一切相关费用 | E51: 个 | F51: 861 | G51: =R51*$R$3 -> 2.17 | H51: =P51*(1+Q51)*$P$3+S51*$S$3 -> 2.58 | I51: =T51*$T$3 -> 0 | J51: =(G51+H51+I51)*$J$3 -> 0 | K51: =(G51+H51+I51+J51)*$K$3 -> 0 | L51: =G51+H51+I51+J51+K51 -> 4.75 | M51: =F51*L51 -> 4089.75 | O51: =P51*(1+Q51)+R51+S51+T51 -> 4.75 | P51: 2.28 | Q51: 0 | R51: 2.17 | S51: 0.3 | T51: 0 | U51: =F51*O51 -> 4089.75
...

Sheet 给排水工程
A1: 会所售楼部给排水工程工程量清单 | O1: 成本单价组成（投标人填写）
A2: 序号 | B2: 编码 | C2: 项目名称 | D2: 项目特征 | E2: 单位 | F2: 工程量 | G2: 人工费 | H2: 材料费 | I2: 机械费 | J2: 管理费 | K2: 利润 | L2: 不含税单价 | M2: 合价 | O2: 单价合计 | P2: 主材费 | Q2: 主材损耗率 | R2: 人工费 | S2: 辅材费 | T2: 机械费 | U2: 合计
J3: 0 | K3: 0 | P3: 1 | R3: 1 | S3: 1 | T3: 1
B4: 单位工程
C5: 给排水工程
C6: 给排水管
A7: 53 | B7: 31001008001 | C7: 冷水 PPR管 | D7: 1.名称：冷水 PPR管 2.规格：DN15 3.连接方式：热熔连接 4.压力试验及吹、洗要求：水压试验、水冲洗、消毒冲洗、管道标识等 5.其他：包括但不限于满足图纸、招标文件、规范及验收要求等一切相关费用 | E7: m | F7: 108.55 | G7: =R7*$R$3 -> 20 | H7: =P7*(1+Q7)*$P$3+S7*$S$3 -> 3.97 | I7: =T7*$T$3 -> 0.13 | J7: =(G7+H7+I7)*$J$3 -> 0 | K7: =(G7+H7+I7+J7)*$K$3 -> 0 | L7: =G7+H7+I7+J7+K7 -> 24.1 | M7: =F7*L7 -> 2616.055 | O7: =P7*(1+Q7)+R7+S7+T7 -> 24.1 | P7: 3.2 | Q7: 0 | R7: 20 | S7: 0.77 | T7: 0.13 | U7: =F7*O7 -> 2616.055
A8: 54 | B8: 31001008002 | C8: 冷水 PPR管 | D8: 1.名称：冷水 PPR管 2.规格：DN20 3.连接方式：热熔连接 4.压力试验及吹、洗要求：水压试验、水冲洗、消毒冲洗、管道标识等 5.其他：包括但不限于满足图纸、招标文件、规范及验收要求等一切相关费用 | E8: m | F8: 24.67 | G8: =R8*$R$3 -> 18 | H8: =P8*(1+Q8)*$P$3+S8*$S$3 -> 4.76 | I8: =T8*$T$3 -> 0.04 | J8: =(G8+H8+I8)*$J$3 -> 0 | K8: =(G8+H8+I8+J8)*$K$3 -> 0 | L8: =G8+H8+I8+J8+K8 -> 22.8 | M8: =F8*L8 -> 562.476 | O8: =P8*(1+Q8)+R8+S8+T8 -> 22.8 | P8: 4.5 | Q8: 0 | R8: 18 | S8: 0.26 | T8: 0.04 | U8: =F8*O8 -> 562.476
A9: 55 | B9: 31001008003 | C9: 冷水 PPR管 | D9: 1.名称：冷水 PPR管 2.规格：DN25 3.连接方式：热熔连接 4.压力试验及吹、洗要求：水压试验、水冲洗、消毒冲洗、管道标识等 5.其他：包括但不限于满足图纸、招标文件、规范及验收要求等一切相关费用 | E9: m | F9: 21.64 | G9: =R9*$R$3 -> 22.09 | H9: =P9*(1+Q9)*$P$3+S9*$S$3 -> 8.76 | I9: =T9*$T$3 -> 0.04 | J9: =(G9+H9+I9)*$J$3 -> 0 | K9: =(G9+H9+I9+J9)*$K$3 -> 0 | L9: =G9+H9+I9+J9+K9 -> 30.89 | M9: =F9*L9 -> 668.4596 | O9: =P9*(1+Q9)+R9+S9+T9 -> 30.89 | P9: 8.5 | Q9: 0 | R9: 22.09 | S9: 0.26 | T9: 0.04 | U9: =F9*O9 -> 668.4596
A10: 56 | B10: 31001008004 | C10: 冷水 PPR管 | D10: 1.名称：冷水 PPR管 2.规格：DN32 3.连接方式：热熔连接 4.压力试验及吹、洗要求：水压试验、水冲洗、消毒冲洗、管道标识等 5.其他：包括但不限于满足图纸、招标文件、规范及验收要求等一切相关费用 | E10: m | F10: 16.52 | G10: =R10*$R$3 -> 23.68 | H10: =P10*(1+Q10)*$P$3+S10*$S$3 -> 11.86 | I10: =T10*$T$3 -> 0.05 | J10: =(G10+H10+I10)*$J$3 -> 0 | K10: =(G10+H10+I10+J10)*$K$3 -> 0 | L10: =G10+H10+I10+J10+K10 -> 35.59 | M10: =F10*L10 -> 587.9468 | O10: =P10*(1+Q10)+R10+S10+T10 -> 35.59 | P10: 11.59 | Q10: 0 | R10: 23.68 | S10: 0.27 | T10: 0.05 | U10: =F10*O10 -> 587.9468
A11: 57 | B11: 31001008005 | C11: 热水 PPR管 | D11: 1.名称：热水 PPR管 2.规格：DN15 3.连接方式：热熔连接 4.压力试验及吹、洗要求：水压试验、水冲洗、消毒冲洗、管道标识等 5.其他：包括但不限于满足图纸、招标文件、规范及验收要求等一切相关费用 | E11: m | F11: 27.1 | G11: =R11*$R$3 -> 20 | H11: =P11*(1+Q11)*$P$3+S11*$S$3 -> 3.97 | I11: =T11*$T$3 -> 0.13 | J11: =(G11+H11+I11)*$J$3 -> 0 | K11: =(G11+H11+I11+J11)*$K$3 -> 0 | L11: =G11+H11+I11+J11+K11 -> 24.1 | M11: =F11*L11 -> 653.11 | O11: =P11*(1+Q11)+R11+S11+T11 -> 24.1 | P11: 3.2 | Q11: 0 | R11: 20 | S11: 0.77 | T11: 0.13 | U11: =F11*O11 -> 653.11
A12: 58 | B12: 31001008006 | C12: 热水 PPR管 | D12: 1.名称：热水 PPR管 2.规格：DN20 3.连接方式：热熔连接 4.压力试验及吹、洗要求：水压试验、水冲洗、消毒冲洗、管道标识等 5.其他：包括但不限于满足图纸、招标文件、规范及验收要求等一切相关费用 | E12: m | F12: 23.43 | G12: =R12*$R$3 -> 18 | H12: =P12*(1+Q12)*$P$3+S12*$S$3 -> 4.76 | I12: =T12*$T$3 -> 0.04 | J12: =(G12+H12+I12)*$J$3 -> 0 | K12: =(G12+H12+I12+J12)*$K$3 -> 0 | L12: =G12+H12+I12+J12+K12 -> 22.8 | M12: =F12*L12 -> 534.204 | O12: =P12*(1+Q12)+R12+S12+T12 -> 22.8 | P12: 4.5 | Q12: 0 | R12: 18 | S12: 0.26 | T12: 0.04 | U12: =F12*O12 -> 534.204
A13: 59 | B13: 31001008007 | C13: 热水 PPR管 | D13: 1.名称：热水 PPR管 2.规格：DN25 3.连接方式：热熔连接 4.压力试验及吹、洗要求：水压试验、水冲洗、消毒冲洗、管道标识等 5.其他：包括但不限于满足图纸、招标文件、规范及验收要求等一切相关费用 | E13: m | F13: 14.1 | G13: =R13*$R$3 -> 22.09 | H13: =P13*(1+Q13)*$P$3+S13*$S$3 -> 8.76 | I13: =T13*$T$3 -> 0.04 | J13: =(G13+H13+I13)*$J$3 -> 0 | K13: =(G13+H13+I13+J13)*$K$3 -> 0 | L13: =G13+H13+I13+J13+K13 -> 30.89 | M13: =F13*L13 -> 435.549 | O13: =P13*(1+Q13)+R13+S13+T13 -> 30.89 | P13: 8.5 | Q13: 0 | R13: 22.09 | S13: 0.26 | T13: 0.04 | U13: =F13*O13 -> 435.549
A14: 60 | B14: 31301001002 | C14: 凿槽及修复 | D14: 1.名称：凿槽及修复 2.规格：70*70 3.部位：砖、混凝土结构综合考虑 4.其他：包括但不限于满足图纸、招标文件、规范及验收要求等一切相关费用 | E14: m | F14: 51.2 | G14: =R14*$R$3 -> 17.65 | H14: =P14*(1+Q14)*$P$3+S14*$S$3 -> 0 | I14: =T14*$T$3 -> 2.41 | J14: =(G14+H14+I14)*$J$3 -> 0 | K14: =(G14+H14+I14+J14)*$K$3 -> 0 | L14: =G14+H14+I14+J14+K14 -> 20.06 | M14: =F14*L14 -> 1027.072 | O14: =P14*(1+Q14)+R14+S14+T14 -> 20.06 | P14: =电气工程!P50 -> 0 | Q14: =电气工程!Q50 -> 0 | R14: =电气工程!R50 -> 17.65 | S14: =电气工程!S50 -> 0 | T14: =电气工程!T50 -> 2.41 | U14: =F14*O14 -> 1027.072
A15: 61 | B15: 31001008008 | C15: UPVC排水管 | D15: 1.名称：UPVC排水管 2.规格：DN50 3.连接方式：粘接 4.压力试验及吹、洗要求：水压试验、管道标识等 5.其他：包括但不限于满足图纸、招标文件、规范及验收要求等一切相关费用 | E15: m | F15: 18.49 | G15: =R15*$R$3 -> 24 | H15: =P15*(1+Q15)*$P$3+S15*$S$3 -> 16.27 | I15: =T15*$T$3 -> 0.23 | J15: =(G15+H15+I15)*$J$3 -> 0 | K15: =(G15+H15+I15+J15)*$K$3 -> 0 | L15: =G15+H15+I15+J15+K15 -> 40.5 | M15: =F15*L15 -> 748.845 | O15: =P15*(1+Q15)+R15+S15+T15 -> 40.5 | P15: 15 | Q15: 0 | R15: 24 | S15: 1.27 | T15: 0.23 | U15: =F15*O15 -> 748.845
A16: 62 | B16: 31001008009 | C16: UPVC排水管 | D16: 1.名称：UPVC排水管 2.规格：DN75 3.连接方式：粘接 4.压力试验及吹、洗要求：水压试验、管道标识等 5.其他：包括但不限于满足图纸、招标文件、规范及验收要求等一切相关费用 | E16: m | F16: 41.77 | G16: =R16*$R$3 -> 55 | H16: =P16*(1+Q16)*$P$3+S16*$S$3 -> 28 | I16: =T16*$T$3 -> 3 | J16: =(G16+H16+I16)*$J$3 -> 0 | K16: =(G16+H16+I16+J16)*$K$3 -> 0 | L16: =G16+H16+I16+J16+K16 -> 86 | M16: =F16*L16 -> 3592.22 | O16: =P16*(1+Q16)+R16+S16+T16 -> 86 | P16: 25 | Q16: 0 | R16: 55 | S16: 3 | T16: 3 | U16: =F16*O16 -> 3592.22
A17: 63 | B17: 31001008010 | C17: UPVC排水管 | D17: 1.名称：UPVC排水管 2.规格：DN100 3.连接方式：粘接 4.压力试验及吹、洗要求：水压试验、管道标识等 5.其他：包括但不限于满足图纸、招标文件、规范及验收要求等一切相关费用 | E17: m | F17: 31.35 | G17: =R17*$R$3 -> 30 | H17: =P17*(1+Q17)*$P$3+S17*$S$3 -> 38.12 | I17: =T17*$T$3 -> 0.38 | J17: =(G17+H17+I17)*$J$3 -> 0 | K17: =(G17+H17+I17+J17)*$K$3 -> 0 | L17: =G17+H17+I17+J17+K17 -> 68.5 | M17: =F17*L17 -> 2147.475 | O17: =P17*(1+Q17)+R17+S17+T17 -> 68.5 | P17: 36 | Q17: 0 | R17: 30 | S17: 2.12 | T17: 0.38 | U17: =F17*O17 -> 2147.475
C18: 洁具五金
A19: 64 | B19: 31003006001 | C19: 轻智能马桶 | D19: 1.名称：轻智能马桶 2.型号规格：详见物料表 3.其他：包括但不限于满足图纸、招标文件、规范及验收要求等一切相关费用 | E19: 组 | F19: 7 | G19: =R19*$R$3 -> 100 | H19: =P19*(1+Q19)*$P$3+S19*$S$3 -> 120 | I19: =T19*$T$3 -> 0 | J19: =(G19+H19+I19)*$J$3 -> 0 | K19: =(G19+H19+I19+J19)*$K$3 -> 0 | L19: =G19+H19+I19+J19+K19 -> 220 | M19: =F19*L19 -> 1540 | O19: =P19*(1+Q19)+R19+S19+T19 -> 220 | P19: 0 | Q19: 0 | R19: 100 | S19: 120 | T19: 0 | U19: =F19*O19 -> 1540
A20: 65 | B20: 31003007001 | C20: 挂墙式自动感应小便器 | D20: 1.名称：挂墙式自动感应小便器 2.型号规格：详见物料表 3.其他：包括但不限于满足图纸、招标文件、规范及验收要求等一切相关费用 | E20: 组 | F20: 3 | G20: =R20*$R$3 -> 85 | H20: =P20*(1+Q20)*$P$3+S20*$S$3 -> 515 | I20: =T20*$T$3 -> 0 | J20: =(G20+H20+I20)*$J$3 -> 0 | K20: =(G20+H20+I20+J20)*$K$3 -> 0 | L20: =G20+H20+I20+J20+K20 -> 600 | M20: =F20*L20 -> 1800 | O20: =P20*(1+Q20)+R20+S20+T20 -> 600 | P20: 480 | Q20: 0 | R20: 85 | S20: 35 | T20: 0 | U20: =F20*O20 -> 1800
A21: 66 | B21: 31003010001 | C21: 淋浴器 | D21: 1.名称：淋浴花洒 2.型号规格：详见物料表 3.其他：包括但不限于满足图纸、招标文件、规范及验收要求等一切相关费用 | E21: 套 | F21: 2 | G21: =R21*$R$3 -> 90 | H21: =P21*(1+Q21)*$P$3+S21*$S$3 -> 1135 | I21: =T21*$T$3 -> 0 | J21: =(G21+H21+I21)*$J$3 -> 0 | K21: =(G21+H21+I21+J21)*$K$3 -> 0 | L21: =G21+H21+I21+J21+K21 -> 1225 | M21: =F21*L21 -> 2450 | O21: =P21*(1+Q21)+R21+S21+T21 -> 1225 | P21: 1100 | Q21: 0 | R21: 90 | S21: 35 | T21: 0 | U21: =F21*O21 -> 2450
A22: 67 | B22: 31003008001 | C22: 拖把池及龙头 | D22: 1.名称：拖把池及冷热龙头 2.型号规格：详见物料表 3.其他：包括但不限于满足图纸、招标文件、规范及验收要求等一切相关费用 | E22: 组 | F22: 1 | G22: =R22*$R$3 -> 65 | H22: =P22*(1+Q22)*$P$3+S22*$S$3 -> 375 | I22: =T22*$T$3 -> 0 | J22: =(G22+H22+I22)*$J$3 -> 0 | K22: =(G22+H22+I22+J22)*$K$3 -> 0 | L22: =G22+H22+I22+J22+K22 -> 440 | M22: =F22*L22 -> 440 | O22: =P22*(1+Q22)+R22+S22+T22 -> 440 | P22: 350 | Q22: 0 | R22: 65 | S22: 25 | T22: 0 | U22: =F22*O22 -> 440
A23: 68 | B23: 31003003001 | C23: 台下盆及龙头 | D23: 1.名称：洗手盆及冷热龙头 2.型号规格：详见物料表 3.其他：包括但不限于满足图纸、招标文件、规范及验收要求等一切相关费用 | E23: 组 | F23: 4 | G23: =R23*$R$3 -> 90 | H23: =P23*(1+Q23)*$P$3+S23*$S$3 -> 562 | I23: =T23*$T$3 -> 0 | J23: =(G23+H23+I23)*$J$3 -> 0 | K23: =(G23+H23+I23+J23)*$K$3 -> 0 | L23: =G23+H23+I23+J23+K23 -> 652 | M23: =F23*L23 -> 2608 | O23: =P23*(1+Q23)+R23+S23+T23 -> 652 | P23: 550 | Q23: 0 | R23: 90 | S23: 12 | T23: 0 | U23: =F23*O23 -> 2608
A24: 69 | B24: 31003004001 | C24: 吧台水槽及龙头 | D24: 1.名称：吧台水槽及冷热龙头 2.型号规格：详见物料表 3.其他：包括但不限于满足图纸、招标文件、规范及验收要求等一切相关费用 | E24: 组 | F24: 1 | G24: =R24*$R$3 -> 95 | H24: =P24*(1+Q24)*$P$3+S24*$S$3 -> 560 | I24: =T24*$T$3 -> 0 | J24: =(G24+H24+I24)*$J$3 -> 0 | K24: =(G24+H24+I24+J24)*$K$3 -> 0 | L24: =G24+H24+I24+J24+K24 -> 655 | M24: =F24*L24 -> 655 | O24: =P24*(1+Q24)+R24+S24+T24 -> 655 | P24: 520 | Q24: 0 | R24: 95 | S24: 40 | T24: 0 | U24: =F24*O24 -> 655
A25: 70 | B25: 31003014001 | C25: 隐藏地漏 | D25: 1.名称：隐藏地漏 2.型号规格：100*100*19mm 3.其他：包括但不限于满足图纸、招标文件、规范及验收要求等一切相关费用 | E25: 个 | F25: 14 | G25: =R25*$R$3 -> 18 | H25: =P25*(1+Q25)*$P$3+S25*$S$3 -> 40 | I25: =T25*$T$3 -> 0 | J25: =(G25+H25+I25)*$J$3 -> 0 | K25: =(G25+H25+I25+J25)*$K$3 -> 0 | L25: =G25+H25+I25+J25+K25 -> 58 | M25: =F25*L25 -> 812 | O25: =P25*(1+Q25)+R25+S25+T25 -> 58 | P25: 35 | Q25: 0 | R25: 18 | S25: 5 | T25: 0 | U25: =F25*O25 -> 812
A26: 71 | B26: 31002001001 | C26: 角阀 | D26: 1.名称：角阀（热水器、洗碗机、制冰机） 2.型号规格：DN15 3.其他：包括但不限于满足图纸、招标文件、规范及验收要求等一切相关费用 | E26: 个 | F26: 5 | G26: =R26*$R$3 -> 167.09 | H26: =P26*(1+Q26)*$P$3+S26*$S$3 -> 1504.2 | I26: =T26*$T$3 -> 12.03 | J26: =(G26+H26+I26)*$J$3 -> 0 | K26: =(G26+H26+I26+J26)*$K$3 -> 0 | L26: =G26+H26+I26+J26+K26 -> 1683.32 | M26: =F26*L26 -> 8416.6 | O26: =P26*(1+Q26)+R26+S26+T26 -> 1683.32 | P26: 1504.2 | Q26: 0 | R26: 167.09 | S26: 0 | T26: 12.03 | U26: =F26*O26 -> 8416.6
A27: 72 | B27: 31003014002 | C27: 纸巾架 | D27: 1.名称：纸巾架 2.型号规格：170*120*81mm 3.其他：包括但不限于满足图纸、招标文件、规范及验收要求等一切相关费用 | E27: 个 | F27: 7 | G27: =R27*$R$3 -> 34.95 | H27: =P27*(1+Q27)*$P$3+S27*$S$3 -> 193.39 | I27: =T27*$T$3 -> 4.66 | J27: =(G27+H27+I27)*$J$3 -> 0 | K27: =(G27+H27+I27+J27)*$K$3 -> 0 | L27: =G27+H27+I27+J27+K27 -> 233 | M27: =F27*L27 -> 1631 | O27: =P27*(1+Q27)+R27+S27+T27 -> 233 | P27: 181.74 | Q27: 0 | R27: 34.95 | S27: 11.65 | T27: 4.66 | U27: =F27*O27 -> 1631
A28: 73 | B28: 31003014003 | C28: 挂衣钩 | D28: 1.名称：挂衣钩 2.型号规格：详见物料表 3.其他：包括但不限于满足图纸、招标文件、规范及验收要求等一切相关费用 | E28: 个 | F28: 7 | G28: =R28*$R$3 -> 6.45 | H28: =P28*(1+Q28)*$P$3+S28*$S$3 -> 28 | I28: =T28*$T$3 -> 0 | J28: =(G28+H28+I28)*$J$3 -> 0 | K28: =(G28+H28+I28+J28)*$K$3 -> 0 | L28: =G28+H28+I28+J28+K28 -> 34.45 | M28: =F28*L28 -> 241.15 | O28: =P28*(1+Q28)+R28+S28+T28 -> 34.45 | P28: 28 | Q28: 0 | R28: 6.45 | S28: 0 | T28: 0 | U28: =F28*O28 -> 241.15
B29: 税前合价 | E29: 元 | M29: =SUM(M4:M28) -> 34167.162
B30: 税金 | E30: 元 | M30: =$M$29*0.09 -> 3075.0446
B31: 含税合价 | E31: 元 | M31: =$M$29+$M$30 -> 37242.207

Sheet 空调工程
A1: 会所售楼部空调工程工程量清单 | O1: 成本单价组成（投标人填写）
A2: 序号 | B2: 编码 | C2: 项目名称 | D2: 项目特征 | E2: 单位 | F2: 工程量 | G2: 人工费 | H2: 材料费 | I2: 机械费 | J2: 管理费 | K2: 利润 | L2: 不含税单价 | M2: 合价 | O2: 单价合计 | P2: 主材费 | Q2: 主材损耗率 | R2: 人工费 | S2: 辅材费 | T2: 机械费 | U2: 合计
J3: 0 | K3: 0 | P3: 1 | R3: 1 | S3: 1 | T3: 1
B4: 单位工程
C5: 多联机空调
C6: 设备
A7: 74 | B7: 30701003001 | C7: 风管机 | D7: 1.名称：风管机 F25 2.规格：制冷量2.5kW 制热量3.2kW 风量450m3/h 机外静压30Pa 额定功率0.10kW 运转噪音≤37dB(A) 带冷凝水提升水泵 3.安装方式：吊装 4.其他：包括但不限于满足图纸、招标文件、规范及验收要求等一切相关费用 | E7: 台 | F7: 2 | G7: =R7*$R$3 -> 1000 | H7: =P7*(1+Q7)*$P$3+S7*$S$3 -> 4800 | I7: =T7*$T$3 -> 45 | J7: =(G7+H7+I7)*$J$3 -> 0 | K7: =(G7+H7+I7+J7)*$K$3 -> 0 | L7: =G7+H7+I7+J7+K7 -> 5845 | M7: =F7*L7 -> 11690 | O7: =P7*(1+Q7)+R7+S7+T7 -> 5845 | P7: 3600 | Q7: 0 | R7: 1000 | S7: 1200 | T7: 45 | U7: =F7*O7 -> 11690
A8: 75 | B8: 30701003002 | C8: 风管机 | D8: 1.名称：风管机 F36 2.规格：制冷量3.6kW 制热量4.2kW 风量780m3/h 机外静压50Pa 额定功率0.10kW 运转噪音≤37dB(A) 带冷凝水提升水泵 3.安装方式：吊装 4.其他：包括但不限于满足图纸、招标文件、规范及验收要求等一切相关费用 | E8: 台 | F8: 1 | G8: =R8*$R$3 -> 1000 | H8: =P8*(1+Q8)*$P$3+S8*$S$3 -> 4800 | I8: =T8*$T$3 -> 45 | J8: =(G8+H8+I8)*$J$3 -> 0 | K8: =(G8+H8+I8+J8)*$K$3 -> 0 | L8: =G8+H8+I8+J8+K8 -> 5845 | M8: =F8*L8 -> 5845 | O8: =P8*(1+Q8)+R8+S8+T8 -> 5845 | P8: 3600 | Q8: 0 | R8: 1000 | S8: 1200 | T8: 45 | U8: =F8*O8 -> 5845
A9: 76 | B9: 30701003003 | C9: 风管机 | D9: 1.名称：风管机 F40 2.规格：制冷量4.0kW 制热量4.5kW 风量780m3/h 机外静压50Pa 额定功率0.14kW 运转噪音≤37dB(A) 带冷凝水提升水泵 3.安装方式：吊装 4.其他：包括但不限于满足图纸、招标文件、规范及验收要求等一切相关费用 | E9: 台 | F9: 3 | G9: =R9*$R$3 -> 1000 | H9: =P9*(1+Q9)*$P$3+S9*$S$3 -> 4800 | I9: =T9*$T$3 -> 45 | J9: =(G9+H9+I9)*$J$3 -> 0 | K9: =(G9+H9+I9+J9)*$K$3 -> 0 | L9: =G9+H9+I9+J9+K9 -> 5845 | M9: =F9*L9 -> 17535 | O9: =P9*(1+Q9)+R9+S9+T9 -> 5845 | P9: 3600 | Q9: 0 | R9: 1000 | S9: 1200 | T9: 45 | U9: =F9*O9 -> 17535
A10: 77 | B10: 30701003004 | C10: 风管机 | D10: 1.名称：风管机 F50 2.规格：制冷量5.0kW 制热量5.6kW 风量900m3/h 机外静压50Pa 额定功率0.17kW 运转噪音≤37dB(A) 带冷凝水提升水泵 3.安装方式：吊装 4.其他：包括但不限于满足图纸、招标文件、规范及验收要求等一切相关费用 | E10: 台 | F10: 3 | G10: =R10*$R$3 -> 1000 | H10: =P10*(1+Q10)*$P$3+S10*$S$3 -> 4800 | I10: =T10*$T$3 -> 45 | J10: =(G10+H10+I10)*$J$3 -> 0 | K10: =(G10+H10+I10+J10)*$K$3 -> 0 | L10: =G10+H10+I10+J10+K10 -> 5845 | M10: =F10*L10 -> 17535 | O10: =P10*(1+Q10)+R10+S10+T10 -> 5845 | P10: 3600 | Q10: 0 | R10: 1000 | S10: 1200 | T10: 45 | U10: =F10*O10 -> 17535
A11: 78 | B11: 30701003005 | C11: 风管机 | D11: 1.名称：风管机 F90 2.规格：制冷量9.0kW 制热量10kW 风量1000m3/h 机外静压50Pa 额定功率0.28kW 运转噪音≤40dB(A) 带冷凝水提升水泵 3.安装方式：吊装 4.其他：包括但不限于满足图纸、招标文件、规范及验收要求等一切相关费用 | E11: 台 | F11: 1 | G11: =R11*$R$3 -> 1000 | H11: =P11*(1+Q11)*$P$3+S11*$S$3 -> 4800 | I11: =T11*$T$3 -> 45 | J11: =(G11+H11+I11)*$J$3 -> 0 | K11: =(G11+H11+I11+J11)*$K$3 -> 0 | L11: =G11+H11+I11+J11+K11 -> 5845 | M11: =F11*L11 -> 5845 | O11: =P11*(1+Q11)+R11+S11+T11 -> 5845 | P11: 3600 | Q11: 0 | R11: 1000 | S11: 1200 | T11: 45 | U11: =F11*O11 -> 5845
A12: 79 | B12: 30701003006 | C12: 风管机 | D12: 1.名称：风管机 F100 2.规格：制冷量10.0kW 制热量11.2kW 风量1400m3/h 机外静压50Pa 额定功率0.28kW 运转噪音≤40dB(A) 带冷凝水提升水泵 3.安装方式：吊装 4.其他：包括但不限于满足图纸、招标文件、规范及验收要求等一切相关费用 | E12: 台 | F12: 3 | G12: =R12*$R$3 -> 1000 | H12: =P12*(1+Q12)*$P$3+S12*$S$3 -> 4800 | I12: =T12*$T$3 -> 45 | J12: =(G12+H12+I12)*$J$3 -> 0 | K12: =(G12+H12+I12+J12)*$K$3 -> 0 | L12: =G12+H12+I12+J12+K12 -> 5845 | M12: =F12*L12 -> 17535 | O12: =P12*(1+Q12)+R12+S12+T12 -> 5845 | P12: 3600 | Q12: 0 | R12: 1000 | S12: 1200 | T12: 45 | U12: =F12*O12 -> 17535
A13: 80 | B13: 30701003007 | C13: 风管机 | D13: 1.名称：风管机 F112 2.规格：制冷量11.2kW 制热量12.5kW 风量1400m3/h 机外静压50Pa 额定功率0.28kW 运转噪音≤40dB(A) 带冷凝水提升水泵 3.安装方式：吊装 4.其他：包括但不限于满足图纸、招标文件、规范及验收要求等一切相关费用 | E13: 台 | F13: 8 | G13: =R13*$R$3 -> 1000 | H13: =P13*(1+Q13)*$P$3+S13*$S$3 -> 4800 | I13: =T13*$T$3 -> 45 | J13: =(G13+H13+I13)*$J$3 -> 0 | K13: =(G13+H13+I13+J13)*$K$3 -> 0 | L13: =G13+H13+I13+J13+K13 -> 5845 | M13: =F13*L13 -> 46760 | O13: =P13*(1+Q13)+R13+S13+T13 -> 5845 | P13: 3600 | Q13: 0 | R13: 1000 | S13: 1200 | T13: 45 | U13: =F13*O13 -> 46760
A14: 81 | B14: 30701003008 | C14: 风管机 | D14: 1.名称：风管机 F140 2.规格：制冷量14.0kW 制热量16.3kW 风量2220m3/h 机外静压90Pa 额定功率0.28kW 运转噪音≤40dB(A) 带冷凝水提升水泵 3.安装方式：吊装 4.其他：包括但不限于满足图纸、招标文件、规范及验收要求等一切相关费用 | E14: 台 | F14: 3 | G14: =R14*$R$3 -> 1000 | H14: =P14*(1+Q14)*$P$3+S14*$S$3 -> 4800 | I14: =T14*$T$3 -> 45 | J14: =(G14+H14+I14)*$J$3 -> 0 | K14: =(G14+H14+I14+J14)*$K$3 -> 0 | L14: =G14+H14+I14+J14+K14 -> 5845 | M14: =F14*L14 -> 17535 | O14: =P14*(1+Q14)+R14+S14+T14 -> 5845 | P14: 3600 | Q14: 0 | R14: 1000 | S14: 1200 | T14: 45 | U14: =F14*O14 -> 17535
A15: 82 | B15: 30701003009 | C15: 风管机 | D15: 1.名称：风管机 F160 2.规格：制冷量16.0kW 制热量18.0kW 风量2300m3/h 机外静压90Pa 额定功率0.4kW 运转噪音≤45dB(A) 带冷凝水提升水泵 3.安装方式：吊装 4.其他：包括但不限于满足图纸、招标文件、规范及验收要求等一切相关费用 | E15: 台 | F15: 6 | G15: =R15*$R$3 -> 1000 | H15: =P15*(1+Q15)*$P$3+S15*$S$3 -> 4800 | I15: =T15*$T$3 -> 45 | J15: =(G15+H15+I15)*$J$3 -> 0 | K15: =(G15+H15+I15+J15)*$K$3 -> 0 | L15: =G15+H15+I15+J15+K15 -> 5845 | M15: =F15*L15 -> 35070 | O15: =P15*(1+Q15)+R15+S15+T15 -> 5845 | P15: 3600 | Q15: 0 | R15: 1000 | S15: 1200 | T15: 45 | U15: =F15*O15 -> 35070
A16: 83 | B16: 30701003010 | C16: 多联式室外机 | D16: 1.名称：多联式室外机 L-1 2.规格：制冷量170.0kW 制热量190.0kW 风量50400m3/h 机外静压-Pa 额定功率49.2kW 运转噪音≤61dB(A) 3.安装方式：落地 4.其他：包括但不限于满足图纸、招标文件、规范及验收要求等一切相关费用 | E16: 台 | F16: 1 | G16: =R16*$R$3 -> 800 | H16: =P16*(1+Q16)*$P$3+S16*$S$3 -> 12080 | I16: =T16*$T$3 -> 60 | J16: =(G16+H16+I16)*$J$3 -> 0 | K16: =(G16+H16+I16+J16)*$K$3 -> 0 | L16: =G16+H16+I16+J16+K16 -> 12940 | M16: =F16*L16 -> 12940 | O16: =P16*(1+Q16)+R16+S16+T16 -> 12940 | P16: 12000 | Q16: 0 | R16: 800 | S16: 80 | T16: 60 | U16: =F16*O16 -> 12940
A17: 84 | B17: 30701003011 | C17: 多联式室外机 | D17: 1.名称：多联式室外机 L-2 2.规格：制冷量61.5kW 制热量69.0kW 风量20700m3/h 机外静压-Pa 额定功率16.4kW 运转噪音≤61dB(A) 3.安装方式：落地 4.其他：包括但不限于满足图纸、招标文件、规范及验收要求等一切相关费用 | E17: 台 | F17: 1 | G17: =R17*$R$3 -> 800 | H17: =P17*(1+Q17)*$P$3+S17*$S$3 -> 12080 | I17: =T17*$T$3 -> 60 | J17: =(G17+H17+I17)*$J$3 -> 0 | K17: =(G17+H17+I17+J17)*$K$3 -> 0 | L17: =G17+H17+I17+J17+K17 -> 12940 | M17: =F17*L17 -> 12940 | O17: =P17*(1+Q17)+R17+S17+T17 -> 12940 | P17: 12000 | Q17: 0 | R17: 800 | S17: 80 | T17: 60 | U17: =F17*O17 -> 12940
A18: 85 | B18: 30701003012 | C18: 多联式室外机 | D18: 1.名称：多联式室外机 L-3 2.规格：制冷量68.0kW 制热量75.0kW 风量21000m3/h 机外静压-Pa 额定功率18.4kW 运转噪音≤61dB(A) 3.安装方式：落地 4.其他：包括但不限于满足图纸、招标文件、规范及验收要求等一切相关费用 | E18: 台 | F18: 1 | G18: =R18*$R$3 -> 800 | H18: =P18*(1+Q18)*$P$3+S18*$S$3 -> 12080 | I18: =T18*$T$3 -> 60 | J18: =(G18+H18+I18)*$J$3 -> 0 | K18: =(G18+H18+I18+J18)*$K$3 -> 0 | L18: =G18+H18+I18+J18+K18 -> 12940 | M18: =F18*L18 -> 12940 | O18: =P18*(1+Q18)+R18+S18+T18 -> 12940 | P18: 12000 | Q18: 0 | R18: 800 | S18: 80 | T18: 60 | U18: =F18*O18 -> 12940
A19: 86 | B19: 30413013005 | C19: 空调温控面板 | D19: 1.名称：空调温控面板 2.规格：86*86mm 3.安装方式：暗装 4.其他：包括但不限于满足图纸、招标文件、规范及验收要求等一切相关费用 | E19: 套 | F19: 30 | G19: =R19*$R$3 -> 35 | H19: =P19*(1+Q19)*$P$3+S19*$S$3 -> 103 | I19: =T19*$T$3 -> 0 | J19: =(G19+H19+I19)*$J$3 -> 0 | K19: =(G19+H19+I19+J19)*$K$3 -> 0 | L19: =G19+H19+I19+J19+K19 -> 138 | M19: =F19*L19 -> 4140 | O19: =P19*(1+Q19)+R19+S19+T19 -> 138 | P19: 95 | Q19: 0 | R19: 35 | S19: 8 | T19: 0 | U19: =F19*O19 -> 4140
C20: 风管
A21: 87 | B21: 30702001001 | C21: 碳钢通风管道 | D21: 1.名称：矩形风管 2.材质：镀锌薄钢板 3.厚度：0.6mm 4.长边：≤1000mm 5.其他：包括但不限于满足图纸、招标文件、规范及验收要求等一切相关费用 | E21: m2 | F21: 44.37 | G21: =R21*$R$3 -> 48 | H21: =P21*(1+Q21)*$P$3+S21*$S$3 -> 99.55 | I21: =T21*$T$3 -> 2 | J21: =(G21+H21+I21)*$J$3 -> 0 | K21: =(G21+H21+I21+J21)*$K$3 -> 0 | L21: =G21+H21+I21+J21+K21 -> 149.55 | M21: =F21*L21 -> 6635.5335 | O21: =P21*(1+Q21)+R21+S21+T21 -> 149.55 | P21: 85 | Q21: 0.03 | R21: 48 | S21: 12 | T21: 2 | U21: =F21*O21 -> 6635.5335
A22: 88 | B22: 30702001002 | C22: 碳钢通风管道 | D22: 1.名称：矩形风管 2.材质：镀锌薄钢板 3.厚度：0.75mm 4.长边：≤1000mm 5.其他：包括但不限于满足图纸、招标文件、规范及验收要求等一切相关费用 | E22: m2 | F22: 45.59 | G22: =R22*$R$3 -> 48 | H22: =P22*(1+Q22)*$P$3+S22*$S$3 -> 99.55 | I22: =T22*$T$3 -> 2 | J22: =(G22+H22+I22)*$J$3 -> 0 | K22: =(G22+H22+I22+J22)*$K$3 -> 0 | L22: =G22+H22+I22+J22+K22 -> 149.55 | M22: =F22*L22 -> 6817.9845 | O22: =P22*(1+Q22)+R22+S22+T22 -> 149.55 | P22: 85 | Q22: 0.03 | R22: 48 | S22: 12 | T22: 2 | U22: =F22*O22 -> 6817.9845
A23: 89 | B23: 30702001003 | C23: 碳钢通风管道 | D23: 1.名称：矩形风管 2.材质：镀锌薄钢板 3.厚度：1.0mm 4.长边：≤1250mm 5.其他：包括但不限于满足图纸、招标文件、规范及验收要求等一切相关费用 | E23: m2 | F23: 66.86 | G23: =R23*$R$3 -> 48 | H23: =P23*(1+Q23)*$P$3+S23*$S$3 -> 99.55 | I23: =T23*$T$3 -> 2 | J23: =(G23+H23+I23)*$J$3 -> 0 | K23: =(G23+H23+I23+J23)*$K$3 -> 0 | L23: =G23+H23+I23+J23+K23 -> 149.55 | M23: =F23*L23 -> 9998.913 | O23: =P23*(1+Q23)+R23+S23+T23 -> 149.55 | P23: 85 | Q23: 0.03 | R23: 48 | S23: 12 | T23: 2 | U23: =F23*O23 -> 9998.913
A24: 90 | B24: 30702001004 | C24: 碳钢通风管道 | D24: 1.名称：矩形风管 2.材质：镀锌薄钢板 3.厚度：1.0mm 4.长边：≤2000mm 5.其他：包括但不限于满足图纸、招标文件、规范及验收要求等一切相关费用 | E24: m2 | F24: 279.53 | G24: =R24*$R$3 -> 48 | H24: =P24*(1+Q24)*$P$3+S24*$S$3 -> 99.55 | I24: =T24*$T$3 -> 2 | J24: =(G24+H24+I24)*$J$3 -> 0 | K24: =(G24+H24+I24+J24)*$K$3 -> 0 | L24: =G24+H24+I24+J24+K24 -> 149.55 | M24: =F24*L24 -> 41803.711 | O24: =P24*(1+Q24)+R24+S24+T24 -> 149.55 | P24: 85 | Q24: 0.03 | R24: 48 | S24: 12 | T24: 2 | U24: =F24*O24 -> 41803.711
A25: 91 | B25: 30703019001 | C25: 柔性接口 | D25: 1.名称：帆布软接口 2.材质：帆布 3.厚度：满足验收要求 4.其他：包括但不限于满足图纸、招标文件、规范及验收要求等一切相关费用 | E25: m2 | F25: 32.82 | G25: =R25*$R$3 -> 55 | H25: =P25*(1+Q25)*$P$3+S25*$S$3 -> 78.89 | I25: =T25*$T$3 -> 2.75 | J25: =(G25+H25+I25)*$J$3 -> 0 | K25: =(G25+H25+I25+J25)*$K$3 -> 0 | L25: =G25+H25+I25+J25+K25 -> 136.64 | M25: =F25*L25 -> 4484.5248 | O25: =P25*(1+Q25)+R25+S25+T25 -> 136.64 | P25: 19.49 | Q25: 0 | R25: 55 | S25: 59.4 | T25: 2.75 | U25: =F25*O25 -> 4484.5248
A26: 92 | B26: 31301005001 | C26: 风管支架刷油 | D26: 1.名称：风管支架刷油 2.按图纸及规范要求 3.其他：包括但不限于以上内容，综合考虑按图纸、招标文件和规范要求而实施、完成这项工程的一切有关费用 | E26: kg | F26: 1884.04 | G26: =R26*$R$3 -> 5.77 | H26: =P26*(1+Q26)*$P$3+S26*$S$3 -> 6.87 | I26: =T26*$T$3 -> 1.21 | J26: =(G26+H26+I26)*$J$3 -> 0 | K26: =(G26+H26+I26+J26)*$K$3 -> 0 | L26: =G26+H26+I26+J26+K26 -> 13.85 | M26: =F26*L26 -> 26093.954 | O26: =P26*(1+Q26)+R26+S26+T26 -> 13.85 | P26: 6.87 | Q26: 0 | R26: 5.77 | S26: 0 | T26: 1.21 | U26: =F26*O26 -> 26093.954
A27: 93 | B27: 31208003001 | C27: 通风管道绝热 | D27: 1.名称：空调风管保温 2.材质：难燃级B1级橡塑保温材料，不燃A级铝箔贴面，湿阻因子≥10000，符合国家GB8624-2012中的管状绝热材料B标准 3.厚度：20mm 4.其他：包括但不限于满足图纸、招标文件、规范及验收要求等一切相关费用 | E27: m2 | F27: 469.67 | G27: =R27*$R$3 -> 48 | H27: =P27*(1+Q27)*$P$3+S27*$S$3 -> 412 | I27: =T27*$T$3 -> 2 | J27: =(G27+H27+I27)*$J$3 -> 0 | K27: =(G27+H27+I27+J27)*$K$3 -> 0 | L27: =G27+H27+I27+J27+K27 -> 462 | M27: =F27*L27 -> 216987.54 | O27: =P27*(1+Q27)+R27+S27+T27 -> 462 | P27: 400 | Q27: 0 | R27: 48 | S27: 12 | T27: 2 | U27: =F27*O27 -> 216987.54
A28: 94 | B28: 30704001001 | C28: 通风工程检测、调试 | D28: 1.名称：风管漏光试验、漏风试验 | E28: 系统 | F28: 1 | G28: =R28*$R$3 -> 380 | H28: =P28*(1+Q28)*$P$3+S28*$S$3 -> 600 | I28: =T28*$T$3 -> 20 | J28: =(G28+H28+I28)*$J$3 -> 0 | K28: =(G28+H28+I28+J28)*$K$3 -> 0 | L28: =G28+H28+I28+J28+K28 -> 1000 | M28: =F28*L28 -> 1000 | O28: =P28*(1+Q28)+R28+S28+T28 -> 1000 | P28: 400 | Q28: 0 | R28: 380 | S28: 200 | T28: 20 | U28: =F28*O28 -> 1000
C29: 风管部件
A30: 95 | B30: 30703007001 | C30: 单层百叶风口 | D30: 1.名称：单层百叶风口 2.周长：≤1800mm 3.规格：600*150 4.其他：包括但不限于满足图纸、招标文件、规范及验收要求等一切相关费用 | E30: 个 | F30: 12 | G30: =R30*$R$3 -> 20 | H30: =P30*(1+Q30)*$P$3+S30*$S$3 -> 81 | I30: =T30*$T$3 -> 0 | J30: =(G30+H30+I30)*$J$3 -> 0 | K30: =(G30+H30+I30+J30)*$K$3 -> 0 | L30: =G30+H30+I30+J30+K30 -> 101 | M30: =F30*L30 -> 1212 | O30: =P30*(1+Q30)+R30+S30+T30 -> 101 | P30: 75 | Q30: 0 | R30: 20 | S30: 6 | T30: 0 | U30: =F30*O30 -> 1212
A31: 96 | B31: 30703007002 | C31: 单层百叶风口 | D31: 1.名称：单层百叶风口 2.周长：≤2500mm 3.规格：800*150 4.其他：包括但不限于满足图纸、招标文件、规范及验收要求等一切相关费用 | E31: 个 | F31: 6 | G31: =R31*$R$3 -> 20 | H31: =P31*(1+Q31)*$P$3+S31*$S$3 -> 81 | I31: =T31*$T$3 -> 0 | J31: =(G31+H31+I31)*$J$3 -> 0 | K31: =(G31+H31+I31+J31)*$K$3 -> 0 | L31: =G31+H31+I31+J31+K31 -> 101 | M31: =F31*L31 -> 606 | O31: =P31*(1+Q31)+R31+S31+T31 -> 101 | P31: 75 | Q31: 0 | R31: 20 | S31: 6 | T31: 0 | U31: =F31*O31 -> 606
A32: 97 | B32: 30703007003 | C32: 单层百叶风口 | D32: 1.名称：单层百叶风口 2.周长：≤2500mm 3.规格：1000*120 4.其他：包括但不限于满足图纸、招标文件、规范及验收要求等一切相关费用 | E32: 个 | F32: 2 | G32: =R32*$R$3 -> 20 | H32: =P32*(1+Q32)*$P$3+S32*$S$3 -> 81 | I32: =T32*$T$3 -> 0 | J32: =(G32+H32+I32)*$J$3 -> 0 | K32: =(G32+H32+I32+J32)*$K$3 -> 0 | L32: =G32+H32+I32+J32+K32 -> 101 | M32: =F32*L32 -> 202 | O32: =P32*(1+Q32)+R32+S32+T32 -> 101 | P32: 75 | Q32: 0 | R32: 20 | S32: 6 | T32: 0 | U32: =F32*O32 -> 202
A33: 98 | B33: 30703007004 | C33: 单层百叶风口 | D33: 1.名称：单层百叶风口 2.周长：≤3300mm 3.规格：1400*150 4.其他：包括但不限于满足图纸、招标文件、规范及验收要求等一切相关费用 | E33: 个 | F33: 16 | G33: =R33*$R$3 -> 20 | H33: =P33*(1+Q33)*$P$3+S33*$S$3 -> 81 | I33: =T33*$T$3 -> 0 | J33: =(G33+H33+I33)*$J$3 -> 0 | K33: =(G33+H33+I33+J33)*$K$3 -> 0 | L33: =G33+H33+I33+J33+K33 -> 101 | M33: =F33*L33 -> 1616 | O33: =P33*(1+Q33)+R33+S33+T33 -> 101 | P33: 75 | Q33: 0 | R33: 20 | S33: 6 | T33: 0 | U33: =F33*O33 -> 1616
A34: 99 | B34: 30703007005 | C34: 单层百叶风口 | D34: 1.名称：单层百叶风口 2.周长：≤5200mm 3.规格：2000*150 4.其他：包括但不限于满足图纸、招标文件、规范及验收要求等一切相关费用 | E34: 个 | F34: 24 | G34: =R34*$R$3 -> 20 | H34: =P34*(1+Q34)*$P$3+S34*$S$3 -> 81 | I34: =T34*$T$3 -> 0 | J34: =(G34+H34+I34)*$J$3 -> 0 | K34: =(G34+H34+I34+J34)*$K$3 -> 0 | L34: =G34+H34+I34+J34+K34 -> 101 | M34: =F34*L34 -> 2424 | O34: =P34*(1+Q34)+R34+S34+T34 -> 101 | P34: 75 | Q34: 0 | R34: 20 | S34: 6 | T34: 0 | U34: =F34*O34 -> 2424
A35: 100 | B35: 30703021001 | C35: 连通管 | D35: 1.名称：连通管 2.规格：1200(L)*300(W)*300(H) 3.其他：包括但不限于满足图纸、招标文件、规范及验收要求等一切相关费用 | E35: 个 | F35: 2 | G35: =R35*$R$3 -> 10 | H35: =P35*(1+Q35)*$P$3+S35*$S$3 -> 47 | I35: =T35*$T$3 -> 1 | J35: =(G35+H35+I35)*$J$3 -> 0 | K35: =(G35+H35+I35+J35)*$K$3 -> 0 | L35: =G35+H35+I35+J35+K35 -> 58 | M35: =F35*L35 -> 116 | O35: =P35*(1+Q35)+R35+S35+T35 -> 58 | P35: 45 | Q35: 0 | R35: 10 | S35: 2 | T35: 1 | U35: =F35*O35 -> 116
A36: 101 | B36: 30703021002 | C36: 连通管 | D36: 1.名称：连通管 2.规格：1200(L)*250(W)*300(H) 3.其他：包括但不限于满足图纸、招标文件、规范及验收要求等一切相关费用 | E36: 个 | F36: 16 | G36: =R36*$R$3 -> 10 | H36: =P36*(1+Q36)*$P$3+S36*$S$3 -> 47 | I36: =T36*$T$3 -> 1 | J36: =(G36+H36+I36)*$J$3 -> 0 | K36: =(G36+H36+I36+J36)*$K$3 -> 0 | L36: =G36+H36+I36+J36+K36 -> 58 | M36: =F36*L36 -> 928 | O36: =P36*(1+Q36)+R36+S36+T36 -> 58 | P36: 45 | Q36: 0 | R36: 10 | S36: 2 | T36: 1 | U36: =F36*O36 -> 928
A37: 102 | B37: 30703021003 | C37: 连通管 | D37: 1.名称：连通管 2.规格：2200(L)*250(W)*300(H) 3.其他：包括但不限于满足图纸、招标文件、规范及验收要求等一切相关费用 | E37: 个 | F37: 24 | G37: =R37*$R$3 -> 10 | H37: =P37*(1+Q37)*$P$3+S37*$S$3 -> 47 | I37: =T37*$T$3 -> 1 | J37: =(G37+H37+I37)*$J$3 -> 0 | K37: =(G37+H37+I37+J37)*$K$3 -> 0 | L37: =G37+H37+I37+J37+K37 -> 58 | M37: =F37*L37 -> 1392 | O37: =P37*(1+Q37)+R37+S37+T37 -> 58 | P37: 45 | Q37: 0 | R37: 10 | S37: 2 | T37: 1 | U37: =F37*O37 -> 1392
C38: 水管
A39: 103 | B39: 31001005001 | C39: 铜管 | D39: 1.名称：紫铜管 2.规格：φ6.4 3.厚度：0.8mm 4.连接方式：钎焊连结 5.其他：包括但不限于满足图纸、招标文件、规范及验收要求等一切相关费用 | E39: m | F39: 37.15 | G39: =R39*$R$3 -> 9.64 | H39: =P39*(1+Q39)*$P$3+S39*$S$3 -> 13.1816 | I39: =T39*$T$3 -> 0 | J39: =(G39+H39+I39)*$J$3 -> 0 | K39: =(G39+H39+I39+J39)*$K$3 -> 0 | L39: =G39+H39+I39+J39+K39 -> 22.8216 | M39: =F39*L39 -> 847.82244 | O39: =P39*(1+Q39)+R39+S39+T39 -> 22.8216 | P39: 10.72 | Q39: 0.03 | R39: 9.64 | S39: 2.14 | T39: 0 | U39: =F39*O39 -> 847.82244
A40: 104 | B40: 31001005002 | C40: 铜管 | D40: 1.名称：紫铜管 2.规格：φ9.5 3.厚度：0.8mm 4.连接方式：钎焊连结 5.其他：包括但不限于满足图纸、招标文件、规范及验收要求等一切相关费用 | E40: m | F40: 95.8 | G40: =R40*$R$3 -> 14.29 | H40: =P40*(1+Q40)*$P$3+S40*$S$3 -> 17.7632 | I40: =T40*$T$3 -> 0 | J40: =(G40+H40+I40)*$J$3 -> 0 | K40: =(G40+H40+I40+J40)*$K$3 -> 0 | L40: =G40+H40+I40+J40+K40 -> 32.0532 | M40: =F40*L40 -> 3070.6966 | O40: =P40*(1+Q40)+R40+S40+T40 -> 32.0532 | P40: 14.44 | Q40: 0.03 | R40: 14.29 | S40: 2.89 | T40: 0 | U40: =F40*O40 -> 3070.6966
...
