Workbook

Sheet 汇总表
A1: 汇总表
A2: 序号 | B2: 单位工程 | C2: 含税合价 | D2: 不含税控制合价 | E2: 含税控制合价 | F2: 备注
A3: 1 | B3: 架空层安装工程 | C3: =架空层安装工程!M62 | D3: 88648.61 | E3: =D3*1.09
A4: 2 | B4: 会所售楼部安装工程 | C4: =会所售楼部安装工程!M141 | D4: 597991.63 | E4: =D4*1.09
A5: 3 | B5: 样板房安装工程 | C5: =样板房安装工程!M261 | D5: 177912.2 | E5: =D5*1.09
A6: 4 | B6: 公共区域安装工程 | C6: =公共区域安装工程!M25 | D6: 103574.11 | E6: =D6*1.09
A7: 5 | B7: 户内交标安装工程 | C7: =户内交标安装工程!M66 | D7: 1011928 | E7: =D7*1.09
A8: 6 | B8: 会所售楼处消防电工程 | C8: =会所售楼处消防电工程!M24 | D8: 19891.5 | E8: =D8*1.09
A9: 7 | B9: 会所售楼处消防水工程 | C9: =会所售楼处消防水工程!M20 | D9: 63764.22 | E9: =D9*1.09
A10: 小计 | D10: =SUM(D3:D9) | E10: =SUM(E3:E9)

Sheet 架空层安装工程
A1: 架空层安装工程工程量清单 | O1: 成本单价组成（投标人填写）
A2: 序号 | B2: 编码 | C2: 项目名称 | D2: 项目特征 | E2: 单位 | F2: 工程量 | G2: 人工费 | H2: 材料费 | I2: 机械费 | J2: 管理费 | K2: 利润 | L2: 不含税单价 | M2: 合价 | O2: 单价合计 | P2: 主材费 | Q2: 主材损耗率 | R2: 人工费 | S2: 辅材费 | T2: 机械费 | U2: 合计
J3: 0 | K3: 0 | P3: 1 | R3: 1 | S3: 1 | T3: 1
B4: 单位工程
C5: 电气工程
C6: 灯具
A7: 1 | B7: 30413002007 | C7: LA-01 筒灯 | D7: 1.名称：LA-01 筒灯 2.规格：12W 4000K 灯体尺寸Φ118*50mm 3.安装方式：嵌装 4.其他：包括但不限于满足图纸、招标文件、规范及验收要求等一切相关费用 | E7: 套 | F7: 100 | G7: =R7*$R$3 | H7: =P7*(1+Q7)*$P$3+S7*$S$3 | I7: =T7*$T$3 | J7: =(G7+H7+I7)*$J$3 | K7: =(G7+H7+I7+J7)*$K$3 | L7: =G7+H7+I7+J7+K7 | M7: =F7*L7 | O7: =P7*(1+Q7)+R7+S7+T7 | P7: 70 | Q7: 0 | R7: 20 | S7: 6 | T7: 0 | U7: =F7*O7
A8: 2 | B8: 30413002008 | C8: LA-06 LED明装筒灯 | D8: 1.名称：LA-06 LED明装筒灯 2.规格：9W 4000K 灯体尺寸Φ150*100mm 3.安装方式：明装 4.其他：包括但不限于满足图纸、招标文件、规范及验收要求等一切相关费用 | E8: 套 | F8: 93 | G8: =R8*$R$3 | H8: =P8*(1+Q8)*$P$3+S8*$S$3 | I8: =T8*$T$3 | J8: =(G8+H8+I8)*$J$3 | K8: =(G8+H8+I8+J8)*$K$3 | L8: =G8+H8+I8+J8+K8 | M8: =F8*L8 | O8: =P8*(1+Q8)+R8+S8+T8 | P8: 70 | Q8: 0 | R8: 20 | S8: 6 | T8: 0 | U8: =F8*O8
A9: 3 | B9: 30413002009 | C9: LA-03 LED灯带 | D9: 1.名称：LA-03 LED灯带 2.规格：8W/米 4000K 3.安装方式：天花 4.其他：包括但不限于满足图纸、招标文件、规范及验收要求等一切相关费用 | E9: m | F9: 63.63 | G9: =R9*$R$3 | H9: =P9*(1+Q9)*$P$3+S9*$S$3 | I9: =T9*$T$3 | J9: =(G9+H9+I9)*$J$3 | K9: =(G9+H9+I9+J9)*$K$3 | L9: =G9+H9+I9+J9+K9 | M9: =F9*L9 | O9: =P9*(1+Q9)+R9+S9+T9 | P9: 20.4 | Q9: 0 | R9: 12.5 | S9: 0.41 | T9: 0 | U9: =F9*O9
A10: 4 | B10: 30413009002 | C10: LED 灯带驱动电源 | D10: 1.名称：LED 灯带驱动电源 2.规格：60W 工作电压：220V 输出电压：24V 3.尺寸：L140*W45*H29mm 4.其他：包括但不限于满足图纸、招标文件、规范及验收要求等一切相关费用 | E10: 个 | F10: 8 | G10: =R10*$R$3 | H10: =P10*(1+Q10)*$P$3+S10*$S$3 | I10: =T10*$T$3 | J10: =(G10+H10+I10)*$J$3 | K10: =(G10+H10+I10+J10)*$K$3 | L10: =G10+H10+I10+J10+K10 | M10: =F10*L10 | O10: =P10*(1+Q10)+R10+S10+T10 | P10: 20 | Q10: 0 | R10: 3 | S10: 0.5 | T10: 0 | U10: =F10*O10
A11: 5 | B11: 30413002010 | C11: LA-05 吊装硬条灯 | D11: 1.名称：LA-05 吊装硬条灯 2.规格：4000K 3.安装方式：吊装 4.其他：包括但不限于满足图纸、招标文件、规范及验收要求等一切相关费用 | E11: m | F11: 79.02 | G11: =R11*$R$3 | H11: =P11*(1+Q11)*$P$3+S11*$S$3 | I11: =T11*$T$3 | J11: =(G11+H11+I11)*$J$3 | K11: =(G11+H11+I11+J11)*$K$3 | L11: =G11+H11+I11+J11+K11 | M11: =F11*L11 | O11: =P11*(1+Q11)+R11+S11+T11 | P11: 180 | Q11: 0 | R11: 15 | S11: 2 | T11: 0 | U11: =F11*O11
A12: 6 | B12: 30413002011 | C12: LA-04 艺术吊灯 | D12: 1.名称：LA-04 艺术吊灯 2.规格：铁艺+铝材+玻璃 颜色：磨砂黑+烟灰灯罩 色温4000K 3.安装方式：吊装 4.其他：包括但不限于满足图纸、招标文件、规范及验收要求等一切相关费用 | E12: 套 | F12: 1 | G12: =R12*$R$3 | H12: =P12*(1+Q12)*$P$3+S12*$S$3 | I12: =T12*$T$3 | J12: =(G12+H12+I12)*$J$3 | K12: =(G12+H12+I12+J12)*$K$3 | L12: =G12+H12+I12+J12+K12 | M12: =F12*L12 | O12: =P12*(1+Q12)+R12+S12+T12 | P12: 800 | Q12: 0 | R12: 30 | S12: 10 | T12: 0 | U12: =F12*O12
A13: 7 | B13: 30413002012 | C13: LA-07 LED云朵灯 | D13: 1.名称：LA-07 LED云朵灯 2.规格：48W 4000K 产品尺寸：L800*W35mm 3.安装方式：吊装 4.其他：包括但不限于满足图纸、招标文件、规范及验收要求等一切相关费用 | E13: 套 | F13: 2 | G13: =R13*$R$3 | H13: =P13*(1+Q13)*$P$3+S13*$S$3 | I13: =T13*$T$3 | J13: =(G13+H13+I13)*$J$3 | K13: =(G13+H13+I13+J13)*$K$3 | L13: =G13+H13+I13+J13+K13 | M13: =F13*L13 | O13: =P13*(1+Q13)+R13+S13+T13 | P13: 280 | Q13: 0 | R13: 20 | S13: 3 | T13: 0 | U13: =F13*O13
C14: 开关插座 | U14: =F14*O14
A15: 8 | B15: 30413013004 | C15: 照明开关 | D15: 1.名称：单联单控开关 2.规格：86*86mm 3.安装方式：暗装 4.其他：包括但不限于满足图纸、招标文件、规范及验收要求等一切相关费用 | E15: 套 | F15: 5 | G15: =R15*$R$3 | H15: =P15*(1+Q15)*$P$3+S15*$S$3 | I15: =T15*$T$3 | J15: =(G15+H15+I15)*$J$3 | K15: =(G15+H15+I15+J15)*$K$3 | L15: =G15+H15+I15+J15+K15 | M15: =F15*L15 | O15: =P15*(1+Q15)+R15+S15+T15 | P15: ='公共区域安装工程'!P14 | Q15: ='公共区域安装工程'!Q14 | R15: ='公共区域安装工程'!R14 | S15: ='公共区域安装工程'!S14 | T15: ='公共区域安装工程'!T14 | U15: =F15*O15
A16: 9 | B16: 30413013005 | C16: 照明开关 | D16: 1.名称：双联单控开关 2.规格：86*86mm 3.安装方式：暗装 4.其他：包括但不限于满足图纸、招标文件、规范及验收要求等一切相关费用 | E16: 套 | F16: 5 | G16: =R16*$R$3 | H16: =P16*(1+Q16)*$P$3+S16*$S$3 | I16: =T16*$T$3 | J16: =(G16+H16+I16)*$J$3 | K16: =(G16+H16+I16+J16)*$K$3 | L16: =G16+H16+I16+J16+K16 | M16: =F16*L16 | O16: =P16*(1+Q16)+R16+S16+T16 | P16: 18 | Q16: 0 | R16: 10 | S16: 1.5 | T16: 0 | U16: =F16*O16
A17: 10 | B17: 30413013006 | C17: 照明开关 | D17: 1.名称：三联单控开关 2.规格：86*86mm 3.安装方式：暗装 4.其他：包括但不限于满足图纸、招标文件、规范及验收要求等一切相关费用 | E17: 套 | F17: 10 | G17: =R17*$R$3 | H17: =P17*(1+Q17)*$P$3+S17*$S$3 | I17: =T17*$T$3 | J17: =(G17+H17+I17)*$J$3 | K17: =(G17+H17+I17+J17)*$K$3 | L17: =G17+H17+I17+J17+K17 | M17: =F17*L17 | O17: =P17*(1+Q17)+R17+S17+T17 | P17: ='公共区域安装工程'!P15 | Q17: ='公共区域安装工程'!Q15 | R17: ='公共区域安装工程'!R15 | S17: ='公共区域安装工程'!S15 | T17: ='公共区域安装工程'!T15 | U17: =F17*O17
A18: 11 | B18: 30413014001 | C18: 插座 | D18: 1.名称：五孔插座 2.规格：86*86mm 3.安装方式：暗装 4.其他：包括但不限于满足图纸、招标文件、规范及验收要求等一切相关费用 | E18: 套 | F18: 14 | G18: =R18*$R$3 | H18: =P18*(1+Q18)*$P$3+S18*$S$3 | I18: =T18*$T$3 | J18: =(G18+H18+I18)*$J$3 | K18: =(G18+H18+I18+J18)*$K$3 | L18: =G18+H18+I18+J18+K18 | M18: =F18*L18 | O18: =P18*(1+Q18)+R18+S18+T18 | P18: ='公共区域安装工程'!P16 | Q18: ='公共区域安装工程'!Q16 | R18: ='公共区域安装工程'!R16 | S18: ='公共区域安装工程'!S16 | T18: ='公共区域安装工程'!T16 | U18: =F18*O18
A19: 12 | B19: 30413014002 | C19: 插座 | D19: 1.名称：地面五孔插座 2.规格：86*86mm 3.安装方式：暗装 4.其他：包括但不限于满足图纸、招标文件、规范及验收要求等一切相关费用 | E19: 套 | F19: 6 | G19: =R19*$R$3 | H19: =P19*(1+Q19)*$P$3+S19*$S$3 | I19: =T19*$T$3 | J19: =(G19+H19+I19)*$J$3 | K19: =(G19+H19+I19+J19)*$K$3 | L19: =G19+H19+I19+J19+K19 | M19: =F19*L19 | O19: =P19*(1+Q19)+R19+S19+T19 | P19: 14.62 | Q19: 0 | R19: 6.31 | S19: 1.12 | T19: 0 | U19: =F19*O19
C20: 配线 | U20: =F20*O20
A21: 13 | B21: 30412004002 | C21: 配线 | D21: 1.名称：电气配线 2.型号规格：WDZC-BYJ-2.5 3.安装方式：管内穿线 4.其他：包括但不限于满足图纸、招标文件、规范及验收要求等一切相关费用 | E21: m | F21: 3020.18 | G21: =R21*$R$3 | H21: =P21*(1+Q21)*$P$3+S21*$S$3 | I21: =T21*$T$3 | J21: =(G21+H21+I21)*$J$3 | K21: =(G21+H21+I21+J21)*$K$3 | L21: =G21+H21+I21+J21+K21 | M21: =F21*L21 | O21: =P21*(1+Q21)+R21+S21+T21 | P21: ='公共区域安装工程'!P17 | Q21: ='公共区域安装工程'!Q17 | R21: ='公共区域安装工程'!R17 | S21: ='公共区域安装工程'!S17 | T21: ='公共区域安装工程'!T17 | U21: =F21*O21
A22: 14 | B22: 30412004003 | C22: 配线 | D22: 1.名称：电气配线 2.型号规格：WDZC-BYJ-6 3.安装方式：管内穿线 4.其他：包括但不限于满足图纸、招标文件、规范及验收要求等一切相关费用 | E22: m | F22: 372.91 | G22: =R22*$R$3 | H22: =P22*(1+Q22)*$P$3+S22*$S$3 | I22: =T22*$T$3 | J22: =(G22+H22+I22)*$J$3 | K22: =(G22+H22+I22+J22)*$K$3 | L22: =G22+H22+I22+J22+K22 | M22: =F22*L22 | O22: =P22*(1+Q22)+R22+S22+T22 | P22: 133.4 | Q22: 0.02 | R22: 15 | S22: 1.07 | T22: 1.07 | U22: =F22*O22
A23: 15 | B23: 30412004004 | C23: 配线 | D23: 1.名称：电气配线 2.型号规格：RVS-4*1.0 3.安装方式：管内穿线 4.其他：包括但不限于满足图纸、招标文件、规范及验收要求等一切相关费用 | E23: m | F23: 87.49 | G23: =R23*$R$3 | H23: =P23*(1+Q23)*$P$3+S23*$S$3 | I23: =T23*$T$3 | J23: =(G23+H23+I23)*$J$3 | K23: =(G23+H23+I23+J23)*$K$3 | L23: =G23+H23+I23+J23+K23 | M23: =F23*L23 | O23: =P23*(1+Q23)+R23+S23+T23 | P23: 3.8 | Q23: 0.02 | R23: 5.2 | S23: 0.23 | T23: 0.05 | U23: =F23*O23
C24: 空调工程 | U24: =F24*O24
C25: 设备 | U25: =F25*O25
A26: 16 | B26: 30701003001 | C26: 风管机 | D26: 1.名称：风管机 F22 2.规格：制冷量2.2kW 制热量2.6kW 风量480m3/h 机外静压10Pa 额定功率0.05kW 运转噪音≤37dB(A) 3.安装方式：吊装 4.其他：包括但不限于满足图纸、招标文件、规范及验收要求等一切相关费用 | E26: 台 | F26: 2 | G26: =R26*$R$3 | H26: =P26*(1+Q26)*$P$3+S26*$S$3 | I26: =T26*$T$3 | J26: =(G26+H26+I26)*$J$3 | K26: =(G26+H26+I26+J26)*$K$3 | L26: =G26+H26+I26+J26+K26 | M26: =F26*L26 | O26: =P26*(1+Q26)+R26+S26+T26 | P26: 3600 | Q26: 0 | R26: 1000 | S26: 1200 | T26: 45 | U26: =F26*O26
A27: 17 | B27: 30701003002 | C27: 风管机 | D27: 1.名称：风管机 F32 2.规格：制冷量3.2kW 制热量3.6kW 风量570m3/h 机外静压30Pa 额定功率0.05kW 运转噪音≤37dB(A) 3.安装方式：吊装 4.其他：包括但不限于满足图纸、招标文件、规范及验收要求等一切相关费用 | E27: 台 | F27: 1 | G27: =R27*$R$3 | H27: =P27*(1+Q27)*$P$3+S27*$S$3 | I27: =T27*$T$3 | J27: =(G27+H27+I27)*$J$3 | K27: =(G27+H27+I27+J27)*$K$3 | L27: =G27+H27+I27+J27+K27 | M27: =F27*L27 | O27: =P27*(1+Q27)+R27+S27+T27 | P27: 3600 | Q27: 0 | R27: 1000 | S27: 1200 | T27: 45 | U27: =F27*O27
A28: 18 | B28: 30701003003 | C28: 风管机 | D28: 1.名称：风管机 F45 2.规格：制冷量4.5kW 制热量5.0kW 风量800m3/h 机外静压30Pa 额定功率0.05kW 运转噪音≤37dB(A) 3.安装方式：吊装 4.其他：包括但不限于满足图纸、招标文件、规范及验收要求等一切相关费用 | E28: 台 | F28: 1 | G28: =R28*$R$3 | H28: =P28*(1+Q28)*$P$3+S28*$S$3 | I28: =T28*$T$3 | J28: =(G28+H28+I28)*$J$3 | K28: =(G28+H28+I28+J28)*$K$3 | L28: =G28+H28+I28+J28+K28 | M28: =F28*L28 | O28: =P28*(1+Q28)+R28+S28+T28 | P28: 3600 | Q28: 0 | R28: 1000 | S28: 1200 | T28: 45 | U28: =F28*O28
A29: 19 | B29: 30701003004 | C29: 风管机 | D29: 1.名称：风管机 F56 2.规格：制冷量5.6kW 制热量6.3kW 风量550m3/h 机外静压10Pa 额定功率0.05kW 运转噪音≤37dB(A) 3.安装方式：吊装 4.其他：包括但不限于满足图纸、招标文件、规范及验收要求等一切相关费用 | E29: 台 | F29: 4 | G29: =R29*$R$3 | H29: =P29*(1+Q29)*$P$3+S29*$S$3 | I29: =T29*$T$3 | J29: =(G29+H29+I29)*$J$3 | K29: =(G29+H29+I29+J29)*$K$3 | L29: =G29+H29+I29+J29+K29 | M29: =F29*L29 | O29: =P29*(1+Q29)+R29+S29+T29 | P29: 3600 | Q29: 0 | R29: 1000 | S29: 1200 | T29: 45 | U29: =F29*O29
A30: 20 | B30: 30701003006 | C30: 风管机 | D30: 1.名称：风管机 F63 2.规格：制冷量6.3kW 制热量7.1kW 风量1000m3/h 机外静压30Pa 额定功率0.11kW 运转噪音≤40dB(A) 3.安装方式：吊装 4.其他：包括但不限于满足图纸、招标文件、规范及验收要求等一切相关费用 | E30: 台 | F30: 1 | G30: =R30*$R$3 | H30: =P30*(1+Q30)*$P$3+S30*$S$3 | I30: =T30*$T$3 | J30: =(G30+H30+I30)*$J$3 | K30: =(G30+H30+I30+J30)*$K$3 | L30: =G30+H30+I30+J30+K30 | M30: =F30*L30 | O30: =P30*(1+Q30)+R30+S30+T30 | P30: 3600 | Q30: 0 | R30: 1000 | S30: 1200 | T30: 45 | U30: =F30*O30
A31: 21 | B31: 30701003007 | C31: 风管机 | D31: 1.名称：风管机 F90 2.规格：制冷量9.0kW 制热量10.0kW 风量1450m3/h 机外静压30Pa 额定功率0.11kW 运转噪音≤40dB(A) 3.安装方式：吊装 4.其他：包括但不限于满足图纸、招标文件、规范及验收要求等一切相关费用 | E31: 台 | F31: 1 | G31: =R31*$R$3 | H31: =P31*(1+Q31)*$P$3+S31*$S$3 | I31: =T31*$T$3 | J31: =(G31+H31+I31)*$J$3 | K31: =(G31+H31+I31+J31)*$K$3 | L31: =G31+H31+I31+J31+K31 | M31: =F31*L31 | O31: =P31*(1+Q31)+R31+S31+T31 | P31: 3600 | Q31: 0 | R31: 1000 | S31: 1200 | T31: 45 | U31: =F31*O31
A32: 22 | B32: 30701003005 | C32: 多联式室外机 | D32: 1.名称：多联式室外机 L-1#-1/2 2.规格：制冷量24.0kW 制热量26.0kW 风量10000m3/h 机外静压-Pa 额定功率7.6kW 运转噪音≤61dB(A) 3.安装方式：落地 4.其他：包括但不限于满足图纸、招标文件、规范及验收要求等一切相关费用 | E32: 台 | F32: 2 | G32: =R32*$R$3 | H32: =P32*(1+Q32)*$P$3+S32*$S$3 | I32: =T32*$T$3 | J32: =(G32+H32+I32)*$J$3 | K32: =(G32+H32+I32+J32)*$K$3 | L32: =G32+H32+I32+J32+K32 | M32: =F32*L32 | O32: =P32*(1+Q32)+R32+S32+T32 | P32: 12000 | Q32: 0 | R32: 800 | S32: 80 | T32: 60 | U32: =F32*O32
A33: 23 | B33: 30413013010 | C33: 空调温控面板 | D33: 1.名称：空调温控面板 2.规格：86*86mm 3.安装方式：暗装 4.其他：包括但不限于满足图纸、招标文件、规范及验收要求等一切相关费用 | E33: 套 | F33: 7 | G33: =R33*$R$3 | H33: =P33*(1+Q33)*$P$3+S33*$S$3 | I33: =T33*$T$3 | J33: =(G33+H33+I33)*$J$3 | K33: =(G33+H33+I33+J33)*$K$3 | L33: =G33+H33+I33+J33+K33 | M33: =F33*L33 | O33: =P33*(1+Q33)+R33+S33+T33 | P33: 95 | Q33: 0 | R33: 35 | S33: 8 | T33: 0 | U33: =F33*O33
A34: 24 | B34: 30703007001 | C34: 单层百叶风口 | D34: 1.名称：单层百叶风口 2.周长：≤1800mm 3.规格：500*150 4.其他：包括但不限于满足图纸、招标文件、规范及验收要求等一切相关费用 | E34: 个 | F34: 4 | G34: =R34*$R$3 | H34: =P34*(1+Q34)*$P$3+S34*$S$3 | I34: =T34*$T$3 | J34: =(G34+H34+I34)*$J$3 | K34: =(G34+H34+I34+J34)*$K$3 | L34: =G34+H34+I34+J34+K34 | M34: =F34*L34 | O34: =P34*(1+Q34)+R34+S34+T34 | P34: 75 | Q34: 0 | R34: 20 | S34: 6 | T34: 0 | U34: =F34*O34
A35: 25 | B35: 30703007006 | C35: 单层百叶风口 | D35: 1.名称：单层百叶风口 2.周长：≤1800mm 3.规格：600*150 4.其他：包括但不限于满足图纸、招标文件、规范及验收要求等一切相关费用 | E35: 个 | F35: 2 | G35: =R35*$R$3 | H35: =P35*(1+Q35)*$P$3+S35*$S$3 | I35: =T35*$T$3 | J35: =(G35+H35+I35)*$J$3 | K35: =(G35+H35+I35+J35)*$K$3 | L35: =G35+H35+I35+J35+K35 | M35: =F35*L35 | O35: =P35*(1+Q35)+R35+S35+T35 | P35: 75 | Q35: 0 | R35: 20 | S35: 6 | T35: 0 | U35: =F35*O35
A36: 26 | B36: 30703007007 | C36: 单层百叶风口 | D36: 1.名称：单层百叶风口 2.周长：≤1800mm 3.规格：700*150 4.其他：包括但不限于满足图纸、招标文件、规范及验收要求等一切相关费用 | E36: 个 | F36: 2 | G36: =R36*$R$3 | H36: =P36*(1+Q36)*$P$3+S36*$S$3 | I36: =T36*$T$3 | J36: =(G36+H36+I36)*$J$3 | K36: =(G36+H36+I36+J36)*$K$3 | L36: =G36+H36+I36+J36+K36 | M36: =F36*L36 | O36: =P36*(1+Q36)+R36+S36+T36 | P36: 75 | Q36: 0 | R36: 20 | S36: 6 | T36: 0 | U36: =F36*O36
A37: 27 | B37: 30703007004 | C37: 单层百叶风口 | D37: 1.名称：单层百叶风口 2.周长：≤3300mm 3.规格：900*150 4.其他：包括但不限于满足图纸、招标文件、规范及验收要求等一切相关费用 | E37: 个 | F37: 8 | G37: =R37*$R$3 | H37: =P37*(1+Q37)*$P$3+S37*$S$3 | I37: =T37*$T$3 | J37: =(G37+H37+I37)*$J$3 | K37: =(G37+H37+I37+J37)*$K$3 | L37: =G37+H37+I37+J37+K37 | M37: =F37*L37 | O37: =P37*(1+Q37)+R37+S37+T37 | P37: 75 | Q37: 0 | R37: 20 | S37: 6 | T37: 0 | U37: =F37*O37
A38: 28 | B38: 30703007008 | C38: 单层百叶风口 | D38: 1.名称：单层百叶风口 2.周长：≤4200mm 3.规格：1250*150 4.其他：包括但不限于满足图纸、招标文件、规范及验收要求等一切相关费用 | E38: 个 | F38: 4 | G38: =R38*$R$3 | H38: =P38*(1+Q38)*$P$3+S38*$S$3 | I38: =T38*$T$3 | J38: =(G38+H38+I38)*$J$3 | K38: =(G38+H38+I38+J38)*$K$3 | L38: =G38+H38+I38+J38+K38 | M38: =F38*L38 | O38: =P38*(1+Q38)+R38+S38+T38 | P38: 75 | Q38: 0 | R38: 20 | S38: 6 | T38: 0 | U38: =F38*O38
C39: 风管 | U39: =F39*O39
A40: 29 | B40: 30702001001 | C40: 碳钢通风管道 | D40: 1.名称：矩形风管 2.材质：镀锌薄钢板 3.厚度：0.6mm 4.长边：≤1000mm 5.其他：包括但不限于满足图纸、招标文件、规范及验收要求等一切相关费用 | E40: m2 | F40: 6.28 | G40: =R40*$R$3 | H40: =P40*(1+Q40)*$P$3+S40*$S$3 | I40: =T40*$T$3 | J40: =(G40+H40+I40)*$J$3 | K40: =(G40+H40+I40+J40)*$K$3 | L40: =G40+H40+I40+J40+K40 | M40: =F40*L40 | O40: =P40*(1+Q40)+R40+S40+T40 | P40: 85 | Q40: 0.03 | R40: 48 | S40: 12 | T40: 2 | U40: =F40*O40
...

Sheet 会所售楼部安装工程
A1: 会所售楼部安装工程工程量清单 | O1: 成本单价组成（投标人填写）
A2: 序号 | B2: 编码 | C2: 项目名称 | D2: 项目特征 | E2: 单位 | F2: 工程量 | G2: 人工费 | H2: 材料费 | I2: 机械费 | J2: 管理费 | K2: 利润 | L2: 不含税单价 | M2: 合价 | O2: 单价合计 | P2: 主材费 | Q2: 主材损耗率 | R2: 人工费 | S2: 辅材费 | T2: 机械费 | U2: 合计
J3: 0 | K3: 0 | P3: =架空层安装工程!$P$3 | R3: =架空层安装工程!$R$3 | S3: =架空层安装工程!$S$3 | T3: =架空层安装工程!$T$3
B4: 单位工程
C5: 电气工程
C6: 灯具、电器
A7: 1 | B7: 30413002001 | C7: L1 嵌入式LED可调射灯 | D7: 1.名称：L1 嵌入式LED可调射灯 2.规格：LED COB 15W 3000K±50 3.尺寸：φ77mm*H90mm 4.安装方式：嵌装 5.其他：包括但不限于满足图纸、招标文件、规范及验收要求等一切相关费用 | E7: 套 | F7: 68 | G7: =R7*$R$3 | H7: =P7*(1+Q7)*$P$3+S7*$S$3 | I7: =T7*$T$3 | J7: =(G7+H7+I7)*$J$3 | K7: =(G7+H7+I7+J7)*$K$3 | L7: =G7+H7+I7+J7+K7 | M7: =F7*L7 | O7: =P7*(1+Q7)+R7+S7+T7 | P7: 135 | Q7: 0 | R7: 115 | S7: 2 | T7: 4 | U7: =F7*O7
A8: 2 | B8: 30413002002 | C8: L2 嵌入式LED筒灯 | D8: 1.名称：L2 嵌入式LED筒灯 2.规格：LED COB 15W 3000K±50 3.尺寸：φ77mm*H99mm 4.安装方式：嵌装 5.其他：包括但不限于满足图纸、招标文件、规范及验收要求等一切相关费用 | E8: 套 | F8: 16 | G8: =R8*$R$3 | H8: =P8*(1+Q8)*$P$3+S8*$S$3 | I8: =T8*$T$3 | J8: =(G8+H8+I8)*$J$3 | K8: =(G8+H8+I8+J8)*$K$3 | L8: =G8+H8+I8+J8+K8 | M8: =F8*L8 | O8: =P8*(1+Q8)+R8+S8+T8 | P8: 120 | Q8: 0 | R8: 18 | S8: 6 | T8: 8 | U8: =F8*O8
A9: 3 | B9: 30413002003 | C9: L3 嵌入式LED可调射灯 | D9: 1.名称：L3 嵌入式LED可调射灯 2.规格：LED COB 7W 2700K±50 3.尺寸：φ77mm*H78mm 4.安装方式：嵌装 5.其他：包括但不限于满足图纸、招标文件、规范及验收要求等一切相关费用 | E9: 套 | F9: 156 | G9: =R9*$R$3 | H9: =P9*(1+Q9)*$P$3+S9*$S$3 | I9: =T9*$T$3 | J9: =(G9+H9+I9)*$J$3 | K9: =(G9+H9+I9+J9)*$K$3 | L9: =G9+H9+I9+J9+K9 | M9: =F9*L9 | O9: =P9*(1+Q9)+R9+S9+T9 | P9: 135 | Q9: 0 | R9: 115 | S9: 2 | T9: 4 | U9: =F9*O9
A10: 4 | B10: 30413002004 | C10: L4 嵌入式LED可调射灯 | D10: 1.名称：L4 嵌入式LED可调射灯 2.规格：LED COB 9W 2700K±50 3.尺寸：φ77mm*H78mm 4.安装方式：嵌装 5.其他：包括但不限于满足图纸、招标文件、规范及验收要求等一切相关费用 | E10: 套 | F10: 21 | G10: =R10*$R$3 | H10: =P10*(1+Q10)*$P$3+S10*$S$3 | I10: =T10*$T$3 | J10: =(G10+H10+I10)*$J$3 | K10: =(G10+H10+I10+J10)*$K$3 | L10: =G10+H10+I10+J10+K10 | M10: =F10*L10 | O10: =P10*(1+Q10)+R10+S10+T10 | P10: 135 | Q10: 0 | R10: 115 | S10: 2 | T10: 4 | U10: =F10*O10
A11: 5 | B11: 30413002005 | C11: L5 明装LED可调射灯 | D11: 1.名称：L5 明装LED可调射灯 2.规格：LED COB 15W 3500K±50 3.尺寸：L85mm*W85mm*H90mm 4.安装方式：明装 5.其他：包括但不限于满足图纸、招标文件、规范及验收要求等一切相关费用 | E11: 套 | F11: 4 | G11: =R11*$R$3 | H11: =P11*(1+Q11)*$P$3+S11*$S$3 | I11: =T11*$T$3 | J11: =(G11+H11+I11)*$J$3 | K11: =(G11+H11+I11+J11)*$K$3 | L11: =G11+H11+I11+J11+K11 | M11: =F11*L11 | O11: =P11*(1+Q11)+R11+S11+T11 | P11: 135 | Q11: 0 | R11: 115 | S11: 2 | T11: 4 | U11: =F11*O11
A12: 6 | B12: 30413002006 | C12: L6 嵌入式LED可调射灯 | D12: 1.名称：L6 嵌入式LED可调射灯 2.规格：LED COB 12W 2700K±50 3.尺寸：φ77mm*H78mm 4.安装方式：嵌装 5.其他：包括但不限于满足图纸、招标文件、规范及验收要求等一切相关费用 | E12: 套 | F12: 2 | G12: =R12*$R$3 | H12: =P12*(1+Q12)*$P$3+S12*$S$3 | I12: =T12*$T$3 | J12: =(G12+H12+I12)*$J$3 | K12: =(G12+H12+I12+J12)*$K$3 | L12: =G12+H12+I12+J12+K12 | M12: =F12*L12 | O12: =P12*(1+Q12)+R12+S12+T12 | P12: 135 | Q12: 0 | R12: 115 | S12: 2 | T12: 4 | U12: =F12*O12
A13: 7 | B13: 30413002007 | C13: L7 嵌入式LED可调射灯 | D13: 1.名称：L7 嵌入式LED可调射灯 2.规格：LED COB 12W 2700K±50 3.尺寸：φ77mm*H78mm 4.安装方式：嵌装 5.其他：包括但不限于满足图纸、招标文件、规范及验收要求等一切相关费用 | E13: 套 | F13: 11 | G13: =R13*$R$3 | H13: =P13*(1+Q13)*$P$3+S13*$S$3 | I13: =T13*$T$3 | J13: =(G13+H13+I13)*$J$3 | K13: =(G13+H13+I13+J13)*$K$3 | L13: =G13+H13+I13+J13+K13 | M13: =F13*L13 | O13: =P13*(1+Q13)+R13+S13+T13 | P13: 135 | Q13: 0 | R13: 115 | S13: 2 | T13: 4 | U13: =F13*O13
A14: 8 | B14: 30413002008 | C14: L8 嵌入式LED可调射灯 | D14: 1.名称：L8 嵌入式LED可调射灯 2.规格：LED COB 7W 2700K±50 3.尺寸：φ77mm*H78mm 4.安装方式：嵌装 5.其他：包括但不限于满足图纸、招标文件、规范及验收要求等一切相关费用 | E14: 套 | F14: 7 | G14: =R14*$R$3 | H14: =P14*(1+Q14)*$P$3+S14*$S$3 | I14: =T14*$T$3 | J14: =(G14+H14+I14)*$J$3 | K14: =(G14+H14+I14+J14)*$K$3 | L14: =G14+H14+I14+J14+K14 | M14: =F14*L14 | O14: =P14*(1+Q14)+R14+S14+T14 | P14: 135 | Q14: 0 | R14: 115 | S14: 2 | T14: 4 | U14: =F14*O14
A15: 9 | B15: 30413002009 | C15: L10 嵌入式LED可调射灯 | D15: 1.名称：L10 嵌入式LED可调射灯 2.规格：LED COB 7W 2700K±50 3.尺寸：φ77mm*H78mm 4.安装方式：嵌装 5.其他：包括但不限于满足图纸、招标文件、规范及验收要求等一切相关费用 | E15: 套 | F15: 20 | G15: =R15*$R$3 | H15: =P15*(1+Q15)*$P$3+S15*$S$3 | I15: =T15*$T$3 | J15: =(G15+H15+I15)*$J$3 | K15: =(G15+H15+I15+J15)*$K$3 | L15: =G15+H15+I15+J15+K15 | M15: =F15*L15 | O15: =P15*(1+Q15)+R15+S15+T15 | P15: 135 | Q15: 0 | R15: 115 | S15: 2 | T15: 4 | U15: =F15*O15
A16: 10 | B16: 30413001001 | C16: L11 吊线办公灯 | D16: 1.名称：L11 吊线办公灯 2.规格：LED 30W 4000K±50 3.尺寸：L1206mm*W75mm*H73.5mm 4.安装方式：吊装 5.其他：包括但不限于满足图纸、招标文件、规范及验收要求等一切相关费用 | E16: 套 | F16: 7 | G16: =R16*$R$3 | H16: =P16*(1+Q16)*$P$3+S16*$S$3 | I16: =T16*$T$3 | J16: =(G16+H16+I16)*$J$3 | K16: =(G16+H16+I16+J16)*$K$3 | L16: =G16+H16+I16+J16+K16 | M16: =F16*L16 | O16: =P16*(1+Q16)+R16+S16+T16 | P16: 120 | Q16: 0 | R16: 18 | S16: 6 | T16: 8 | U16: =F16*O16
A17: 11 | B17: 30413001002 | C17: L12 吸顶灯 | D17: 1.名称：L12 吸顶灯 2.规格：LED 18W 4000K±50 3.尺寸：Φ290mm*H54.5mm 4.安装方式：吸顶 5.其他：包括但不限于满足图纸、招标文件、规范及验收要求等一切相关费用 | E17: 套 | F17: 4 | G17: =R17*$R$3 | H17: =P17*(1+Q17)*$P$3+S17*$S$3 | I17: =T17*$T$3 | J17: =(G17+H17+I17)*$J$3 | K17: =(G17+H17+I17+J17)*$K$3 | L17: =G17+H17+I17+J17+K17 | M17: =F17*L17 | O17: =P17*(1+Q17)+R17+S17+T17 | P17: 60 | Q17: 0 | R17: 18 | S17: 6 | T17: 8 | U17: =F17*O17
A18: 12 | B18: 30413004001 | C18: L13 LED地埋灯 | D18: 1.名称：L13 LED地埋灯 2.规格：LED 1W 2700K±50 3.尺寸：Φ42mm*H75mm 4.安装方式：埋地 5.其他：包括但不限于满足图纸、招标文件、规范及验收要求等一切相关费用 | E18: 套 | F18: 3 | G18: =R18*$R$3 | H18: =P18*(1+Q18)*$P$3+S18*$S$3 | I18: =T18*$T$3 | J18: =(G18+H18+I18)*$J$3 | K18: =(G18+H18+I18+J18)*$K$3 | L18: =G18+H18+I18+J18+K18 | M18: =F18*L18 | O18: =P18*(1+Q18)+R18+S18+T18 | P18: 120 | Q18: 0 | R18: 18 | S18: 6 | T18: 8 | U18: =F18*O18
... A28: 22 | B28: 30413002018 | C28: R7 地面洗墙灯 | D28: 1.名称：R7 地面洗墙灯 2.规格：LED 18W 2700K±50 3.尺寸：1000*43*53mm，灯体截面29*45mm 4.安装方式：地面 5.其他：包括但不限于满足图纸、招标文件、规范及验收要求等一切相关费用 | E28: m | F28: 4 | G28: =R28*$R$3 | H28: =P28*(1+Q28)*$P$3+S28*$S$3 | I28: =T28*$T$3 | J28: =(G28+H28+I28)*$J$3 | K28: =(G28+H28+I28+J28)*$K$3 | L28: =G28+H28+I28+J28+K28 | M28: =F28*L28 | O28: =P28*(1+Q28)+R28+S28+T28 | P28: 85 | Q28: 0 | R28: 22 | S28: 6 | T28: 4 | U28: =F28*O28
A29: 23 | B29: 30413009001 | C29: LED 灯带驱动电源 | D29: 1.名称：LED 灯带驱动电源 2.规格：60W 工作电压：220V 输出电压：24V 3.尺寸：L140*W45*H29mm 4.其他：包括但不限于满足图纸、招标文件、规范及验收要求等一切相关费用 | E29: 个 | F29: 280 | G29: =R29*$R$3 | H29: =P29*(1+Q29)*$P$3+S29*$S$3 | I29: =T29*$T$3 | J29: =(G29+H29+I29)*$J$3 | K29: =(G29+H29+I29+J29)*$K$3 | L29: =G29+H29+I29+J29+K29 | M29: =F29*L29 | O29: =P29*(1+Q29)+R29+S29+T29 | P29: ='架空层安装工程'!P10 | Q29: ='架空层安装工程'!Q10 | R29: ='架空层安装工程'!R10 | S29: ='架空层安装工程'!S10 | T29: ='架空层安装工程'!T10 | U29: =F29*O29
A30: 24 | B30: 30405017001 | C30: 洗碗机 | D30: 1.名称：洗碗机 2.规格：- 3.尺寸：详见物料表 4.其他：包括但不限于满足图纸、招标文件、规范及验收要求等一切相关费用 | E30: 台 | F30: 1 | G30: =R30*$R$3 | H30: =P30*(1+Q30)*$P$3+S30*$S$3 | I30: =T30*$T$3 | J30: =(G30+H30+I30)*$J$3 | K30: =(G30+H30+I30+J30)*$K$3 | L30: =G30+H30+I30+J30+K30 | M30: =F30*L30 | O30: =P30*(1+Q30)+R30+S30+T30 | P30: ='样板房安装工程'!P19 | Q30: ='样板房安装工程'!Q19 | R30: ='样板房安装工程'!R19 | S30: ='样板房安装工程'!S19 | T30: ='样板房安装工程'!T19 | U30: =F30*O30
C31: 开关插座
A32: 25 | B32: 30413013001 | C32: 照明开关 | D32: 1.名称：单联单控开关 2.规格：86*86mm 3.安装方式：暗装 4.其他：包括但不限于满足图纸、招标文件、规范及验收要求等一切相关费用 | E32: 套 | F32: 5 | G32: =R32*$R$3 | H32: =P32*(1+Q32)*$P$3+S32*$S$3 | I32: =T32*$T$3 | J32: =(G32+H32+I32)*$J$3 | K32: =(G32+H32+I32+J32)*$K$3 | L32: =G32+H32+I32+J32+K32 | M32: =F32*L32 | O32: =P32*(1+Q32)+R32+S32+T32 | P32: ='公共区域安装工程'!P14 | Q32: ='公共区域安装工程'!Q14 | R32: ='公共区域安装工程'!R14 | S32: ='公共区域安装工程'!S14 | T32: ='公共区域安装工程'!T14 | U32: =F32*O32
A33: 26 | B33: 30413013002 | C33: 照明开关 | D33: 1.名称：双联单控开关 2.规格：86*86mm 3.安装方式：暗装 4.其他：包括但不限于满足图纸、招标文件、规范及验收要求等一切相关费用 | E33: 套 | F33: 10 | G33: =R33*$R$3 | H33: =P33*(1+Q33)*$P$3+S33*$S$3 | I33: =T33*$T$3 | J33: =(G33+H33+I33)*$J$3 | K33: =(G33+H33+I33+J33)*$K$3 | L33: =G33+H33+I33+J33+K33 | M33: =F33*L33 | O33: =P33*(1+Q33)+R33+S33+T33 | P33: ='架空层安装工程'!P16 | Q33: ='架空层安装工程'!Q16 | R33: ='架空层安装工程'!R16 | S33: ='架空层安装工程'!S16 | T33: ='架空层安装工程'!T16 | U33: =F33*O33
A34: 27 | B34: 30413013003 | C34: 照明开关 | D34: 1.名称：三联单控开关 2.规格：86*86mm 3.安装方式：暗装 4.其他：包括但不限于满足图纸、招标文件、规范及验收要求等一切相关费用 | E34: 套 | F34: 23 | G34: =R34*$R$3 | H34: =P34*(1+Q34)*$P$3+S34*$S$3 | I34: =T34*$T$3 | J34: =(G34+H34+I34)*$J$3 | K34: =(G34+H34+I34+J34)*$K$3 | L34: =G34+H34+I34+J34+K34 | M34: =F34*L34 | O34: =P34*(1+Q34)+R34+S34+T34 | P34: ='公共区域安装工程'!P15 | Q34: ='公共区域安装工程'!Q15 | R34: ='公共区域安装工程'!R15 | S34: ='公共区域安装工程'!S15 | T34: ='公共区域安装工程'!T15 | U34: =F34*O34
A35: 28 | B35: 30413013004 | C35: 照明开关 | D35: 1.名称：卫生间排风开关 2.规格：86*86mm 3.安装方式：暗装 4.其他：包括但不限于满足图纸、招标文件、规范及验收要求等一切相关费用 | E35: 套 | F35: 4 | G35: =R35*$R$3 | H35: =P35*(1+Q35)*$P$3+S35*$S$3 | I35: =T35*$T$3 | J35: =(G35+H35+I35)*$J$3 | K35: =(G35+H35+I35+J35)*$K$3 | L35: =G35+H35+I35+J35+K35 | M35: =F35*L35 | O35: =P35*(1+Q35)+R35+S35+T35 | P35: 14.62 | Q35: 0 | R35: 6.31 | S35: 1.12 | T35: 0 | U35: =F35*O35
A36: 29 | B36: 30413014001 | C36: 插座 | D36: 1.名称：三孔插座 2.规格：86*86mm 3.安装方式：暗装 4.其他：包括但不限于满足图纸、招标文件、规范及验收要求等一切相关费用 | E36: 套 | F36: 2 | G36: =R36*$R$3 | H36: =P36*(1+Q36)*$P$3+S36*$S$3 | I36: =T36*$T$3 | J36: =(G36+H36+I36)*$J$3 | K36: =(G36+H36+I36+J36)*$K$3 | L36: =G36+H36+I36+J36+K36 | M36: =F36*L36 | O36: =P36*(1+Q36)+R36+S36+T36 | P36: ='户内交标安装工程'!P27 | Q36: ='户内交标安装工程'!Q27 | R36: ='户内交标安装工程'!R27 | S36: ='户内交标安装工程'!S27 | T36: ='户内交标安装工程'!T27 | U36: =F36*O36
A37: 30 | B37: 30413014002 | C37: 插座 | D37: 1.名称：五孔插座 2.规格：86*86mm 3.安装方式：暗装 4.其他：包括但不限于满足图纸、招标文件、规范及验收要求等一切相关费用 | E37: 套 | F37: 63 | G37: =R37*$R$3 | H37: =P37*(1+Q37)*$P$3+S37*$S$3 | I37: =T37*$T$3 | J37: =(G37+H37+I37)*$J$3 | K37: =(G37+H37+I37+J37)*$K$3 | L37: =G37+H37+I37+J37+K37 | M37: =F37*L37 | O37: =P37*(1+Q37)+R37+S37+T37 | P37: ='公共区域安装工程'!P16 | Q37: ='公共区域安装工程'!Q16 | R37: ='公共区域安装工程'!R16 | S37: ='公共区域安装工程'!S16 | T37: ='公共区域安装工程'!T16 | U37: =F37*O37
A38: 31 | B38: 30413014003 | C38: 插座 | D38: 1.名称：五孔插座（带防溅盒） 2.规格：86*86mm 3.安装方式：暗装 4.其他：包括但不限于满足图纸、招标文件、规范及验收要求等一切相关费用 | E38: 套 | F38: 15 | G38: =R38*$R$3 | H38: =P38*(1+Q38)*$P$3+S38*$S$3 | I38: =T38*$T$3 | J38: =(G38+H38+I38)*$J$3 | K38: =(G38+H38+I38+J38)*$K$3 | L38: =G38+H38+I38+J38+K38 | M38: =F38*L38 | O38: =P38*(1+Q38)+R38+S38+T38 | P38: ='样板房安装工程'!P28 | Q38: ='样板房安装工程'!Q28 | R38: ='样板房安装工程'!R28 | S38: ='样板房安装工程'!S28 | T38: ='样板房安装工程'!T28 | U38: =F38*O38
A39: 32 | B39: 30413014004 | C39: 插座 | D39: 1.名称：五孔插座带开关 2.规格：86*86mm 3.安装方式：暗装 4.其他：包括但不限于满足图纸、招标文件、规范及验收要求等一切相关费用 | E39: 套 | F39: 21 | G39: =R39*$R$3 | H39: =P39*(1+Q39)*$P$3+S39*$S$3 | I39: =T39*$T$3 | J39: =(G39+H39+I39)*$J$3 | K39: =(G39+H39+I39+J39)*$K$3 | L39: =G39+H39+I39+J39+K39 | M39: =F39*L39 | O39: =P39*(1+Q39)+R39+S39+T39 | P39: ='户内交标安装工程'!P25 | Q39: ='户内交标安装工程'!Q25 | R39: ='户内交标安装工程'!R25 | S39: ='户内交标安装工程'!S25 | T39: ='户内交标安装工程'!T25 | U39: =F39*O39
A40: 33 | B40: 30413014005 | C40: 插座 | D40: 1.名称：五孔插座带开关（带防溅盒） 2.规格：86*86mm 3.安装方式：暗装 4.其他：包括但不限于满足图纸、招标文件、规范及验收要求等一切相关费用 | E40: 套 | F40: 4 | G40: =R40*$R$3 | H40: =P40*(1+Q40)*$P$3+S40*$S$3 | I40: =T40*$T$3 | J40: =(G40+H40+I40)*$J$3 | K40: =(G40+H40+I40+J40)*$K$3 | L40: =G40+H40+I40+J40+K40 | M40: =F40*L40 | O40: =P40*(1+Q40)+R40+S40+T40 | P40: ='样板房安装工程'!P31 | Q40: ='样板房安装工程'!Q31 | R40: ='样板房安装工程'!R31 | S40: ='样板房安装工程'!S31 | T40: ='样板房安装工程'!T31 | U40: =F40*O40
A41: 34 | B41: 30413014006 | C41: 插座 | D41: 1.名称：五孔地面插座 2.规格：86*86mm 3.安装方式：暗装 4.其他：包括但不限于满足图纸、招标文件、规范及验收要求等一切相关费用 | E41: 套 | F41: 51 | G41: =R41*$R$3 | H41: =P41*(1+Q41)*$P$3+S41*$S$3 | I41: =T41*$T$3 | J41: =(G41+H41+I41)*$J$3 | K41: =(G41+H41+I41+J41)*$K$3 | L41: =G41+H41+I41+J41+K41 | M41: =F41*L41 | O41: =P41*(1+Q41)+R41+S41+T41 | P41: 14.62 | Q41: 0 | R41: 6.31 | S41: 1.12 | T41: 0 | U41: =F41*O41
C42: 配管配线
A43: 35 | B43: 30412001001 | C43: 配管 | D43: 1.名称：电气配管 2.规格：JDG20 3.安装方式：暗装 4.其他：包括但不限于满足图纸、招标文件、规范及验收要求等一切相关费用 | E43: m | F43: 2169.81 | G43: =R43*$R$3 | H43: =P43*(1+Q43)*$P$3+S43*$S$3 | I43: =T43*$T$3 | J43: =(G43+H43+I43)*$J$3 | K43: =(G43+H43+I43+J43)*$K$3 | L43: =G43+H43+I43+J43+K43 | M43: =F43*L43 | O43: =P43*(1+Q43)+R43+S43+T43 | P43: 1.57 | Q43: 0 | R43: 2.61 | S43: 0.23 | T43: 0.09 | U43: =F43*O43
A44: 36 | B44: 30412001002 | C44: 配管 | D44: 1.名称：电气配管 2.规格：JDG25 3.安装方式：暗装 4.其他：包括但不限于满足图纸、招标文件、规范及验收要求等一切相关费用 | E44: m | F44: 324.48 | G44: =R44*$R$3 | H44: =P44*(1+Q44)*$P$3+S44*$S$3 | I44: =T44*$T$3 | J44: =(G44+H44+I44)*$J$3 | K44: =(G44+H44+I44+J44)*$K$3 | L44: =G44+H44+I44+J44+K44 | M44: =F44*L44 | O44: =P44*(1+Q44)+R44+S44+T44 | P44: 6.5 | Q44: 0.03 | R44: 10.8 | S44: 0.44 | T44: 0.2 | U44: =F44*O44
A45: 37 | B45: 30412001003 | C45: 配管 | D45: 1.名称：电气配管 2.规格：PC20 3.安装方式：暗装 4.其他：包括但不限于满足图纸、招标文件、规范及验收要求等一切相关费用 | E45: m | F45: 616.28 | G45: =R45*$R$3 | H45: =P45*(1+Q45)*$P$3+S45*$S$3 | I45: =T45*$T$3 | J45: =(G45+H45+I45)*$J$3 | K45: =(G45+H45+I45+J45)*$K$3 | L45: =G45+H45+I45+J45+K45 | M45: =F45*L45 | O45: =P45*(1+Q45)+R45+S45+T45 | P45: 6 | Q45: 0.03 | R45: 8.5 | S45: 0.48 | T45: 0.2 | U45: =F45*O45
A46: 38 | B46: 30412001004 | C46: 配管 | D46: 1.名称：电气配管 2.规格：PC25 3.安装方式：暗装 4.其他：包括但不限于满足图纸、招标文件、规范及验收要求等一切相关费用 | E46: m | F46: 932.93 | G46: =R46*$R$3 | H46: =P46*(1+Q46)*$P$3+S46*$S$3 | I46: =T46*$T$3 | J46: =(G46+H46+I46)*$J$3 | K46: =(G46+H46+I46+J46)*$K$3 | L46: =G46+H46+I46+J46+K46 | M46: =F46*L46 | O46: =P46*(1+Q46)+R46+S46+T46 | P46: 6 | Q46: 0.03 | R46: 8.5 | S46: 0.48 | T46: 0.2 | U46: =F46*O46
A47: 39 | B47: 30412001005 | C47: 配管 | D47: 1.名称：电气配管 2.规格：PC32 3.安装方式：暗装 4.其他：包括但不限于满足图纸、招标文件、规范及验收要求等一切相关费用 | E47: m | F47: 24.68 | G47: =R47*$R$3 | H47: =P47*(1+Q47)*$P$3+S47*$S$3 | I47: =T47*$T$3 | J47: =(G47+H47+I47)*$J$3 | K47: =(G47+H47+I47+J47)*$K$3 | L47: =G47+H47+I47+J47+K47 | M47: =F47*L47 | O47: =P47*(1+Q47)+R47+S47+T47 | P47: 6 | Q47: 0.03 | R47: 8.5 | S47: 0.48 | T47: 0.2 | U47: =F47*O47
A48: 40 | B48: 30412001006 | C48: 配管 | D48: 1.名称：金属软管 2.规格：DN20 3.安装方式：吊顶内安装 4.其他：包括但不限于满足图纸、招标文件、规范及验收要求等一切相关费用 | E48: m | F48: 686.43 | G48: =R48*$R$3 | H48: =P48*(1+Q48)*$P$3+S48*$S$3 | I48: =T48*$T$3 | J48: =(G48+H48+I48)*$J$3 | K48: =(G48+H48+I48+J48)*$K$3 | L48: =G48+H48+I48+J48+K48 | M48: =F48*L48 | O48: =P48*(1+Q48)+R48+S48+T48 | P48: 8.1 | Q48: 0.03 | R48: 7.6 | S48: 0.65 | T48: 0.2 | U48: =F48*O48
A49: 41 | B49: 30412001007 | C49: 配管 | D49: 1.名称：金属软管 2.规格：DN25 3.安装方式：吊顶内安装 4.其他：包括但不限于满足图纸、招标文件、规范及验收要求等一切相关费用 | E49: m | F49: 286.28 | G49: =R49*$R$3 | H49: =P49*(1+Q49)*$P$3+S49*$S$3 | I49: =T49*$T$3 | J49: =(G49+H49+I49)*$J$3 | K49: =(G49+H49+I49+J49)*$K$3 | L49: =G49+H49+I49+J49+K49 | M49: =F49*L49 | O49: =P49*(1+Q49)+R49+S49+T49 | P49: 9.5 | Q49: 0.03 | R49: 8.5 | S49: 0.76 | T49: 0.2 | U49: =F49*O49
...

Sheet 样板房安装工程
A1: 样板房安装工程工程量清单 | O1: 成本单价组成（投标人填写）
A2: 序号 | B2: 编码 | C2: 项目名称 | D2: 项目特征 | E2: 单位 | F2: 工程量 | G2: 人工费 | H2: 材料费 | I2: 机械费 | J2: 管理费 | K2: 利润 | L2: 不含税单价 | M2: 合价 | O2: 单价合计 | P2: 主材费 | Q2: 主材损耗率 | R2: 人工费 | S2: 辅材费 | T2: 机械费 | U2: 合计
J3: 0 | K3: 0 | P3: =架空层安装工程!$P$3 | R3: =架空层安装工程!$R$3 | S3: =架空层安装工程!$S$3 | T3: =架空层安装工程!$T$3
B4: 单位工程
C5: 109户型
C6: 电气工程
C7: 灯具、电器
A8: 1 | B8: 30413002001 | C8: R1 LED嵌入式射灯 | D8: 1.名称：R1 LED嵌入式射灯 2.规格：12W、3000K、光束角36° 3.安装方式：嵌装 4.其他：包括但不限于满足图纸、招标文件、规范及验收要求等一切相关费用 | E8: 套 | F8: 20 | G8: =R8*$R$3 | H8: =P8*(1+Q8)*$P$3+S8*$S$3 | I8: =T8*$T$3 | J8: =(G8+H8+I8)*$J$3 | K8: =(G8+H8+I8+J8)*$K$3 | L8: =G8+H8+I8+J8+K8 | M8: =F8*L8 | O8: =P8*(1+Q8)+R8+S8+T8 | P8: 120 | Q8: 0 | R8: 18 | S8: 6 | T8: 8 | U8: =F8*O8
A9: 2 | B9: 30413002002 | C9: R2 LED嵌入式可调角射灯 | D9: 1.名称：R2 LED嵌入式可调角射灯 2.规格：12W、3000K、光束角24° 3.安装方式：嵌装 4.其他：包括但不限于满足图纸、招标文件、规范及验收要求等一切相关费用 | E9: 套 | F9: 4 | G9: =R9*$R$3 | H9: =P9*(1+Q9)*$P$3+S9*$S$3 | I9: =T9*$T$3 | J9: =(G9+H9+I9)*$J$3 | K9: =(G9+H9+I9+J9)*$K$3 | L9: =G9+H9+I9+J9+K9 | M9: =F9*L9 | O9: =P9*(1+Q9)+R9+S9+T9 | P9: 120 | Q9: 0 | R9: 18 | S9: 6 | T9: 8 | U9: =F9*O9
A10: 3 | B10: 30413002003 | C10: R3 嵌入式防雾射灯 | D10: 1.名称：R3 嵌入式防雾射灯 2.规格：12W、3000K、光束角36° 3.安装方式：嵌装 4.其他：包括但不限于满足图纸、招标文件、规范及验收要求等一切相关费用 | E10: 套 | F10: 6 | G10: =R10*$R$3 | H10: =P10*(1+Q10)*$P$3+S10*$S$3 | I10: =T10*$T$3 | J10: =(G10+H10+I10)*$J$3 | K10: =(G10+H10+I10+J10)*$K$3 | L10: =G10+H10+I10+J10+K10 | M10: =F10*L10 | O10: =P10*(1+Q10)+R10+S10+T10 | P10: 120 | Q10: 0 | R10: 18 | S10: 6 | T10: 8 | U10: =F10*O10
A11: 4 | B11: 30413002004 | C11: R4 明装双头射灯 | D11: 1.名称：R4 明装双头射灯 2.规格：12W、3000K、光束角36° 3.安装方式：嵌装 4.其他：包括但不限于满足图纸、招标文件、规范及验收要求等一切相关费用 | E11: 套 | F11: 3 | G11: =R11*$R$3 | H11: =P11*(1+Q11)*$P$3+S11*$S$3 | I11: =T11*$T$3 | J11: =(G11+H11+I11)*$J$3 | K11: =(G11+H11+I11+J11)*$K$3 | L11: =G11+H11+I11+J11+K11 | M11: =F11*L11 | O11: =P11*(1+Q11)+R11+S11+T11 | P11: 120 | Q11: 0 | R11: 18 | S11: 6 | T11: 8 | U11: =F11*O11
A12: 5 | B12: 30413002005 | C12: R5 明装单头射灯 | D12: 1.名称：R5 明装单头射灯 2.规格：12W、3000K、光束角36° 3.安装方式：嵌装 4.其他：包括但不限于满足图纸、招标文件、规范及验收要求等一切相关费用 | E12: 套 | F12: 5 | G12: =R12*$R$3 | H12: =P12*(1+Q12)*$P$3+S12*$S$3 | I12: =T12*$T$3 | J12: =(G12+H12+I12)*$J$3 | K12: =(G12+H12+I12+J12)*$K$3 | L12: =G12+H12+I12+J12+K12 | M12: =F12*L12 | O12: =P12*(1+Q12)+R12+S12+T12 | P12: 120 | Q12: 0 | R12: 18 | S12: 6 | T12: 8 | U12: =F12*O12
A13: 6 | B13: 30413002006 | C13: L1 LED灯条（天花） | D13: 1.名称：L1 LED灯条（天花） 2.规格：14W/米,3000K,120珠/米 3.安装方式：天花 4.其他：包括但不限于满足图纸、招标文件、规范及验收要求等一切相关费用 | E13: m | F13: 72.19 | G13: =R13*$R$3 | H13: =P13*(1+Q13)*$P$3+S13*$S$3 | I13: =T13*$T$3 | J13: =(G13+H13+I13)*$J$3 | K13: =(G13+H13+I13+J13)*$K$3 | L13: =G13+H13+I13+J13+K13 | M13: =F13*L13 | O13: =P13*(1+Q13)+R13+S13+T13 | P13: 12 | Q13: 0 | R13: 2.5 | S13: 0.5 | T13: 0 | U13: =F13*O13
A14: 7 | B14: 30413002007 | C14: L2 LED灯条（墙立面） | D14: 1.名称：L2 LED灯条（墙立面） 2.规格：7W/米,3000K,120珠/米 3.安装方式：天花 4.其他：包括但不限于满足图纸、招标文件、规范及验收要求等一切相关费用 | E14: m | F14: 22.14 | G14: =R14*$R$3 | H14: =P14*(1+Q14)*$P$3+S14*$S$3 | I14: =T14*$T$3 | J14: =(G14+H14+I14)*$J$3 | K14: =(G14+H14+I14+J14)*$K$3 | L14: =G14+H14+I14+J14+K14 | M14: =F14*L14 | O14: =P14*(1+Q14)+R14+S14+T14 | P14: 12 | Q14: 0 | R14: 2.5 | S14: 0.5 | T14: 0 | U14: =F14*O14
A15: 8 | B15: 30413002008 | C15: L3 LED灯条（柜子） | D15: 1.名称：L3 LED灯条（柜子） 2.规格：4W/米,3000K,120珠/米 3.安装方式：天花 4.其他：包括但不限于满足图纸、招标文件、规范及验收要求等一切相关费用 | E15: m | F15: 15.01 | G15: =R15*$R$3 | H15: =P15*(1+Q15)*$P$3+S15*$S$3 | I15: =T15*$T$3 | J15: =(G15+H15+I15)*$J$3 | K15: =(G15+H15+I15+J15)*$K$3 | L15: =G15+H15+I15+J15+K15 | M15: =F15*L15 | O15: =P15*(1+Q15)+R15+S15+T15 | P15: 12 | Q15: 0 | R15: 2.5 | S15: 0.5 | T15: 0 | U15: =F15*O15
A16: 9 | B16: 30413009001 | C16: LED 灯带驱动电源 | D16: 1.名称：LED 灯带驱动电源 2.规格：60W 工作电压：220V 输出电压：24V 3.尺寸：L140*W45*H29mm 4.其他：包括但不限于满足图纸、招标文件、规范及验收要求等一切相关费用 | E16: 个 | F16: 26 | G16: =R16*$R$3 | H16: =P16*(1+Q16)*$P$3+S16*$S$3 | I16: =T16*$T$3 | J16: =(G16+H16+I16)*$J$3 | K16: =(G16+H16+I16+J16)*$K$3 | L16: =G16+H16+I16+J16+K16 | M16: =F16*L16 | O16: =P16*(1+Q16)+R16+S16+T16 | P16: ='架空层安装工程'!P10 | Q16: ='架空层安装工程'!Q10 | R16: ='架空层安装工程'!R10 | S16: ='架空层安装工程'!S10 | T16: ='架空层安装工程'!T10 | U16: =F16*O16
A17: 10 | B17: 30405015001 | C17: 线型凉霸及开关 | D17: 1.名称：线型凉霸及开关 2.规格：34W 3.尺寸：详见物料表 4.其他：包括但不限于满足图纸、招标文件、规范及验收要求等一切相关费用 | E17: 台 | F17: 1 | G17: =R17*$R$3 | H17: =P17*(1+Q17)*$P$3+S17*$S$3 | I17: =T17*$T$3 | J17: =(G17+H17+I17)*$J$3 | K17: =(G17+H17+I17+J17)*$K$3 | L17: =G17+H17+I17+J17+K17 | M17: =F17*L17 | O17: =P17*(1+Q17)+R17+S17+T17 | P17: 280 | Q17: 0 | R17: 25 | S17: 3 | T17: 0 | U17: =F17*O17
A18: 11 | B18: 30405015002 | C18: 线型浴霸及开关 | D18: 1.名称：线型浴霸及开关 2.规格：40W 3.尺寸：详见物料表 4.其他：包括但不限于满足图纸、招标文件、规范及验收要求等一切相关费用 | E18: 台 | F18: 2 | G18: =R18*$R$3 | H18: =P18*(1+Q18)*$P$3+S18*$S$3 | I18: =T18*$T$3 | J18: =(G18+H18+I18)*$J$3 | K18: =(G18+H18+I18+J18)*$K$3 | L18: =G18+H18+I18+J18+K18 | M18: =F18*L18 | O18: =P18*(1+Q18)+R18+S18+T18 | P18: 450 | Q18: 0 | R18: 30 | S18: 3 | T18: 0 | U18: =F18*O18
A19: 12 | B19: 30405017001 | C19: 洗碗机 | D19: 1.名称：洗碗机 2.规格：- 3.尺寸：详见物料表 4.其他：包括但不限于满足图纸、招标文件、规范及验收要求等一切相关费用 | E19: 台 | F19: 1 | G19: =R19*$R$3 | H19: =P19*(1+Q19)*$P$3+S19*$S$3 | I19: =T19*$T$3 | J19: =(G19+H19+I19)*$J$3 | K19: =(G19+H19+I19+J19)*$K$3 | L19: =G19+H19+I19+J19+K19 | M19: =F19*L19 | O19: =P19*(1+Q19)+R19+S19+T19 | P19: 4200 | Q19: 0 | R19: 250 | S19: 35 | T19: 8.5 | U19: =F19*O19
C20: 开关插座 | O20: =P20*(1+Q20)+R20+S20+T20 | U20: =F20*O20
A21: 13 | B21: 30413013001 | C21: 照明开关 | D21: 1.名称：单联单控开关 2.规格：86*86mm 3.安装方式：暗装 4.其他：包括但不限于满足图纸、招标文件、规范及验收要求等一切相关费用 | E21: 套 | F21: 2 | G21: =R21*$R$3 | H21: =P21*(1+Q21)*$P$3+S21*$S$3 | I21: =T21*$T$3 | J21: =(G21+H21+I21)*$J$3 | K21: =(G21+H21+I21+J21)*$K$3 | L21: =G21+H21+I21+J21+K21 | M21: =F21*L21 | O21: =P21*(1+Q21)+R21+S21+T21 | P21: ='公共区域安装工程'!P14 | Q21: ='公共区域安装工程'!Q14 | R21: ='公共区域安装工程'!R14 | S21: ='公共区域安装工程'!S14 | T21: ='公共区域安装工程'!T14 | U21: =F21*O21
A22: 14 | B22: 30413013002 | C22: 照明开关 | D22: 1.名称：双联单控开关 2.规格：86*86mm 3.安装方式：暗装 4.其他：包括但不限于满足图纸、招标文件、规范及验收要求等一切相关费用 | E22: 套 | F22: 1 | G22: =R22*$R$3 | H22: =P22*(1+Q22)*$P$3+S22*$S$3 | I22: =T22*$T$3 | J22: =(G22+H22+I22)*$J$3 | K22: =(G22+H22+I22+J22)*$K$3 | L22: =G22+H22+I22+J22+K22 | M22: =F22*L22 | O22: =P22*(1+Q22)+R22+S22+T22 | P22: ='架空层安装工程'!P16 | Q22: ='架空层安装工程'!Q16 | R22: ='架空层安装工程'!R16 | S22: ='架空层安装工程'!S16 | T22: ='架空层安装工程'!T16 | U22: =F22*O22
A23: 15 | B23: 30413013003 | C23: 照明开关 | D23: 1.名称：三联单控开关 2.规格：86*86mm 3.安装方式：暗装 4.其他：包括但不限于满足图纸、招标文件、规范及验收要求等一切相关费用 | E23: 套 | F23: 2 | G23: =R23*$R$3 | H23: =P23*(1+Q23)*$P$3+S23*$S$3 | I23: =T23*$T$3 | J23: =(G23+H23+I23)*$J$3 | K23: =(G23+H23+I23+J23)*$K$3 | L23: =G23+H23+I23+J23+K23 | M23: =F23*L23 | O23: =P23*(1+Q23)+R23+S23+T23 | P23: ='公共区域安装工程'!P15 | Q23: ='公共区域安装工程'!Q15 | R23: ='公共区域安装工程'!R15 | S23: ='公共区域安装工程'!S15 | T23: ='公共区域安装工程'!T15 | U23: =F23*O23
A24: 16 | B24: 30413013004 | C24: 照明开关 | D24: 1.名称：双联双控开关 2.规格：86*86mm 3.安装方式：暗装 4.其他：包括但不限于满足图纸、招标文件、规范及验收要求等一切相关费用 | E24: 套 | F24: 2 | G24: =R24*$R$3 | H24: =P24*(1+Q24)*$P$3+S24*$S$3 | I24: =T24*$T$3 | J24: =(G24+H24+I24)*$J$3 | K24: =(G24+H24+I24+J24)*$K$3 | L24: =G24+H24+I24+J24+K24 | M24: =F24*L24 | O24: =P24*(1+Q24)+R24+S24+T24 | P24: ='户内交标安装工程'!P21 | Q24: ='户内交标安装工程'!Q21 | R24: ='户内交标安装工程'!R21 | S24: ='户内交标安装工程'!S21 | T24: ='户内交标安装工程'!T21 | U24: =F24*O24
A25: 17 | B25: 30413013005 | C25: 照明开关 | D25: 1.名称：三联双控开关 2.规格：86*86mm 3.安装方式：暗装 4.其他：包括但不限于满足图纸、招标文件、规范及验收要求等一切相关费用 | E25: 套 | F25: 8 | G25: =R25*$R$3 | H25: =P25*(1+Q25)*$P$3+S25*$S$3 | I25: =T25*$T$3 | J25: =(G25+H25+I25)*$J$3 | K25: =(G25+H25+I25+J25)*$K$3 | L25: =G25+H25+I25+J25+K25 | M25: =F25*L25 | O25: =P25*(1+Q25)+R25+S25+T25 | P25: ='户内交标安装工程'!P22 | Q25: ='户内交标安装工程'!Q22 | R25: ='户内交标安装工程'!R22 | S25: ='户内交标安装工程'!S22 | T25: ='户内交标安装工程'!T22 | U25: =F25*O25
A26: 18 | B26: 30413013006 | C26: 照明开关 | D26: 1.名称：四联双控开关 2.规格：86*86mm 3.安装方式：暗装 4.其他：包括但不限于满足图纸、招标文件、规范及验收要求等一切相关费用 | E26: 套 | F26: 4 | G26: =R26*$R$3 | H26: =P26*(1+Q26)*$P$3+S26*$S$3 | I26: =T26*$T$3 | J26: =(G26+H26+I26)*$J$3 | K26: =(G26+H26+I26+J26)*$K$3 | L26: =G26+H26+I26+J26+K26 | M26: =F26*L26 | O26: =P26*(1+Q26)+R26+S26+T26 | P26: 14.62 | Q26: 0 | R26: 6.31 | S26: 1.12 | T26: 0 | U26: =F26*O26
A27: 19 | B27: 30413014001 | C27: 插座 | D27: 1.名称：五孔插座 2.规格：86*86mm 3.安装方式：暗装 4.其他：包括但不限于满足图纸、招标文件、规范及验收要求等一切相关费用 | E27: 套 | F27: 31 | G27: =R27*$R$3 | H27: =P27*(1+Q27)*$P$3+S27*$S$3 | I27: =T27*$T$3 | J27: =(G27+H27+I27)*$J$3 | K27: =(G27+H27+I27+J27)*$K$3 | L27: =G27+H27+I27+J27+K27 | M27: =F27*L27 | O27: =P27*(1+Q27)+R27+S27+T27 | P27: ='公共区域安装工程'!P16 | Q27: ='公共区域安装工程'!Q16 | R27: ='公共区域安装工程'!R16 | S27: ='公共区域安装工程'!S16 | T27: ='公共区域安装工程'!T16 | U27: =F27*O27
A28: 20 | B28: 30413014002 | C28: 插座 | D28: 1.名称：五孔插座（带防溅盒） 2.规格：86*86mm 3.安装方式：暗装 4.其他：包括但不限于满足图纸、招标文件、规范及验收要求等一切相关费用 | E28: 套 | F28: 12 | G28: =R28*$R$3 | H28: =P28*(1+Q28)*$P$3+S28*$S$3 | I28: =T28*$T$3 | J28: =(G28+H28+I28)*$J$3 | K28: =(G28+H28+I28+J28)*$K$3 | L28: =G28+H28+I28+J28+K28 | M28: =F28*L28 | O28: =P28*(1+Q28)+R28+S28+T28 | P28: 14.62 | Q28: 0 | R28: 6.31 | S28: 1.12 | T28: 0 | U28: =F28*O28
A29: 21 | B29: 30413014003 | C29: 插座 | D29: 1.名称：五孔插座带USB 2.规格：86*86mm 3.安装方式：暗装 4.其他：包括但不限于满足图纸、招标文件、规范及验收要求等一切相关费用 | E29: 套 | F29: 3 | G29: =R29*$R$3 | H29: =P29*(1+Q29)*$P$3+S29*$S$3 | I29: =T29*$T$3 | J29: =(G29+H29+I29)*$J$3 | K29: =(G29+H29+I29+J29)*$K$3 | L29: =G29+H29+I29+J29+K29 | M29: =F29*L29 | O29: =P29*(1+Q29)+R29+S29+T29 | P29: 14.62 | Q29: 0 | R29: 6.31 | S29: 1.12 | T29: 0 | U29: =F29*O29
A30: 22 | B30: 30413014004 | C30: 插座 | D30: 1.名称：五孔插座带开关 2.规格：86*86mm 3.安装方式：暗装 4.其他：包括但不限于满足图纸、招标文件、规范及验收要求等一切相关费用 | E30: 套 | F30: 2 | G30: =R30*$R$3 | H30: =P30*(1+Q30)*$P$3+S30*$S$3 | I30: =T30*$T$3 | J30: =(G30+H30+I30)*$J$3 | K30: =(G30+H30+I30+J30)*$K$3 | L30: =G30+H30+I30+J30+K30 | M30: =F30*L30 | O30: =P30*(1+Q30)+R30+S30+T30 | P30: ='户内交标安装工程'!P25 | Q30: ='户内交标安装工程'!Q25 | R30: ='户内交标安装工程'!R25 | S30: ='户内交标安装工程'!S25 | T30: ='户内交标安装工程'!T25 | U30: =F30*O30
A31: 23 | B31: 30413014005 | C31: 插座 | D31: 1.名称：五孔插座带开关（带防溅盒） 2.规格：86*86mm 3.安装方式：暗装 4.其他：包括但不限于满足图纸、招标文件、规范及验收要求等一切相关费用 | E31: 套 | F31: 2 | G31: =R31*$R$3 | H31: =P31*(1+Q31)*$P$3+S31*$S$3 | I31: =T31*$T$3 | J31: =(G31+H31+I31)*$J$3 | K31: =(G31+H31+I31+J31)*$K$3 | L31: =G31+H31+I31+J31+K31 | M31: =F31*L31 | O31: =P31*(1+Q31)+R31+S31+T31 | P31: 14.62 | Q31: 0 | R31: 6.31 | S31: 1.12 | T31: 0 | U31: =F31*O31
A32: 24 | B32: 30413014006 | C32: 插座 | D32: 1.名称：地面五孔插座 2.规格：86*86mm 3.安装方式：暗装 4.其他：包括但不限于满足图纸、招标文件、规范及验收要求等一切相关费用 | E32: 套 | F32: 2 | G32: =R32*$R$3 | H32: =P32*(1+Q32)*$P$3+S32*$S$3 | I32: =T32*$T$3 | J32: =(G32+H32+I32)*$J$3 | K32: =(G32+H32+I32+J32)*$K$3 | L32: =G32+H32+I32+J32+K32 | M32: =F32*L32 | O32: =P32*(1+Q32)+R32+S32+T32 | P32: ='架空层安装工程'!P19 | Q32: ='架空层安装工程'!Q19 | R32: ='架空层安装工程'!R19 | S32: ='架空层安装工程'!S19 | T32: ='架空层安装工程'!T19 | U32: =F32*O32
C33: 配管配线 | O33: =P33*(1+Q33)+R33+S33+T33 | U33: =F33*O33
A34: 25 | B34: 30412004001 | C34: 配线 | D34: 1.名称：电气配线 2.型号规格：BV-1.5 3.安装方式：管内穿线 4.其他：包括但不限于满足图纸、招标文件、规范及验收要求等一切相关费用 | E34: m | F34: 278.13 | G34: =R34*$R$3 | H34: =P34*(1+Q34)*$P$3+S34*$S$3 | I34: =T34*$T$3 | J34: =(G34+H34+I34)*$J$3 | K34: =(G34+H34+I34+J34)*$K$3 | L34: =G34+H34+I34+J34+K34 | M34: =F34*L34 | O34: =P34*(1+Q34)+R34+S34+T34 | P34: 1.9 | Q34: 0.02 | R34: 1.58 | S34: 0.19 | T34: 0.02 | U34: =F34*O34
A35: 26 | B35: 30412004002 | C35: 配线 | D35: 1.名称：电气配线 2.型号规格：BV-2.5 3.安装方式：管内穿线 4.其他：包括但不限于满足图纸、招标文件、规范及验收要求等一切相关费用 | E35: m | F35: 1134.55 | G35: =R35*$R$3 | H35: =P35*(1+Q35)*$P$3+S35*$S$3 | I35: =T35*$T$3 | J35: =(G35+H35+I35)*$J$3 | K35: =(G35+H35+I35+J35)*$K$3 | L35: =G35+H35+I35+J35+K35 | M35: =F35*L35 | O35: =P35*(1+Q35)+R35+S35+T35 | P35: ='公共区域安装工程'!P22 | Q35: ='公共区域安装工程'!Q22 | R35: ='公共区域安装工程'!R22 | S35: ='公共区域安装工程'!S22 | T35: ='公共区域安装工程'!T22 | U35: =F35*O35
A36: 27 | B36: 30412004003 | C36: 配线 | D36: 1.名称：电气配线 2.型号规格：BV-4 3.安装方式：管内穿线 4.其他：包括但不限于满足图纸、招标文件、规范及验收要求等一切相关费用 | E36: m | F36: 720.6 | G36: =R36*$R$3 | H36: =P36*(1+Q36)*$P$3+S36*$S$3 | I36: =T36*$T$3 | J36: =(G36+H36+I36)*$J$3 | K36: =(G36+H36+I36+J36)*$K$3 | L36: =G36+H36+I36+J36+K36 | M36: =F36*L36 | O36: =P36*(1+Q36)+R36+S36+T36 | P36: ='户内交标安装工程'!P32 | Q36: ='户内交标安装工程'!Q32 | R36: ='户内交标安装工程'!R32 | S36: ='户内交标安装工程'!S32 | T36: ='户内交标安装工程'!T32 | U36: =F36*O36
A37: 28 | B37: 30412004004 | C37: 配线 | D37: 1.名称：电气配线 2.型号规格：BV-10 3.安装方式：管内穿线 4.其他：包括但不限于满足图纸、招标文件、规范及验收要求等一切相关费用 | E37: m | F37: 31.52 | G37: =R37*$R$3 | H37: =P37*(1+Q37)*$P$3+S37*$S$3 | I37: =T37*$T$3 | J37: =(G37+H37+I37)*$J$3 | K37: =(G37+H37+I37+J37)*$K$3 | L37: =G37+H37+I37+J37+K37 | M37: =F37*L37 | O37: =P37*(1+Q37)+R37+S37+T37 | P37: 9 | Q37: 0.02 | R37: 2 | S37: 0.33 | T37: 0.02 | U37: =F37*O37
C38: 弱电工程 | O38: =P38*(1+Q38)+R38+S38+T38 | U38: =F38*O38
A39: 29 | B39: 30413014007 | C39: 插座 | D39: 1.名称：网络插座 2.规格：86*86mm 3.安装方式：暗装 4.其他：包括但不限于满足图纸、招标文件、规范及验收要求等一切相关费用 | E39: 套 | F39: 4 | G39: =R39*$R$3 | H39: =P39*(1+Q39)*$P$3+S39*$S$3 | I39: =T39*$T$3 | J39: =(G39+H39+I39)*$J$3 | K39: =(G39+H39+I39+J39)*$K$3 | L39: =G39+H39+I39+J39+K39 | M39: =F39*L39 | O39: =P39*(1+Q39)+R39+S39+T39 | P39: 14.62 | Q39: 0 | R39: 6.31 | S39: 1.12 | T39: 0 | U39: =F39*O39
A40: 30 | B40: 30413014008 | C40: 插座 | D40: 1.名称：电视插座 2.规格：86*86mm 3.安装方式：暗装 4.其他：包括但不限于满足图纸、招标文件、规范及验收要求等一切相关费用 | E40: 套 | F40: 2 | G40: =R40*$R$3 | H40: =P40*(1+Q40)*$P$3+S40*$S$3 | I40: =T40*$T$3 | J40: =(G40+H40+I40)*$J$3 | K40: =(G40+H40+I40+J40)*$K$3 | L40: =G40+H40+I40+J40+K40 | M40: =F40*L40 | O40: =P40*(1+Q40)+R40+S40+T40 | P40: 14.62 | Q40: 0 | R40: 6.31 | S40: 1.12 | T40: 0 | U40: =F40*O40
...

Sheet 公共区域安装工程
A1: 公共区域安装工程工程量清单 | O1: 成本单价组成（投标人填写）
A2: 序号 | B2: 编码 | C2: 项目名称 | D2: 项目特征 | E2: 单位 | F2: 工程量 | G2: 人工费 | H2: 材料费 | I2: 机械费 | J2: 管理费 | K2: 利润 | L2: 不含税单价 | M2: 合价 | O2: 单价合计 | P2: 主材费 | Q2: 主材损耗率 | R2: 人工费 | S2: 辅材费 | T2: 机械费 | U2: 合计
J3: 0 | K3: 0 | P3: =架空层安装工程!$P$3 | R3: =架空层安装工程!$R$3 | S3: =架空层安装工程!$S$3 | T3: =架空层安装工程!$T$3
B4: 单位工程
C5: 批量公区
A6: 1 | B6: 30413002001 | C6: LA-01 嵌入式筒灯 | D6: 1.名称：LA-01 嵌入式筒灯 2.规格：12W 4000K 灯体尺寸Φ118*50mm 3.安装方式：嵌装 4.其他：包括但不限于满足图纸、招标文件、规范及验收要求等一切相关费用 | E6: 套 | F6: 65 | G6: =R6*$R$3 | H6: =P6*(1+Q6)*$P$3+S6*$S$3 | I6: =T6*$T$3 | J6: =(G6+H6+I6)*$J$3 | K6: =(G6+H6+I6+J6)*$K$3 | L6: =G6+H6+I6+J6+K6 | M6: =F6*L6 | O6: =P6*(1+Q6)+R6+S6+T6 | P6: 70 | Q6: 0 | R6: 20 | S6: 6 | T6: 0 | U6: =F6*O6
A7: 2 | B7: 30413002002 | C7: LA-02 射灯 | D7: 1.名称：LA-02 射灯 2.规格：12W 4000K 灯体尺寸Φ118*50mm 3.安装方式：嵌装 4.其他：包括但不限于满足图纸、招标文件、规范及验收要求等一切相关费用 | E7: 套 | F7: 61 | G7: =R7*$R$3 | H7: =P7*(1+Q7)*$P$3+S7*$S$3 | I7: =T7*$T$3 | J7: =(G7+H7+I7)*$J$3 | K7: =(G7+H7+I7+J7)*$K$3 | L7: =G7+H7+I7+J7+K7 | M7: =F7*L7 | O7: =P7*(1+Q7)+R7+S7+T7 | P7: 120 | Q7: 0 | R7: 18 | S7: 3.5 | T7: 0.5 | U7: =F7*O7
A8: 3 | B8: 30413002003 | C8: LA-04 红外人体感应筒灯 | D8: 1.名称：LA-04 红外人体感应筒灯 2.规格：9W 4000K 灯体尺寸Φ118*50mm 3.安装方式：嵌装 4.其他：包括但不限于满足图纸、招标文件、规范及验收要求等一切相关费用 | E8: 套 | F8: 10 | G8: =R8*$R$3 | H8: =P8*(1+Q8)*$P$3+S8*$S$3 | I8: =T8*$T$3 | J8: =(G8+H8+I8)*$J$3 | K8: =(G8+H8+I8+J8)*$K$3 | L8: =G8+H8+I8+J8+K8 | M8: =F8*L8 | O8: =P8*(1+Q8)+R8+S8+T8 | P8: 70 | Q8: 0 | R8: 20 | S8: 6 | T8: 0 | U8: =F8*O8
A9: 4 | B9: 30413002004 | C9: LA-05 明装红外人体感应筒灯 | D9: 1.名称：LA-05 明装红外人体感应筒灯 2.规格：9W 4000K 灯体尺寸Φ150*100mm 3.安装方式：明装 4.其他：包括但不限于满足图纸、招标文件、规范及验收要求等一切相关费用 | E9: 套 | F9: 100 | G9: =R9*$R$3 | H9: =P9*(1+Q9)*$P$3+S9*$S$3 | I9: =T9*$T$3 | J9: =(G9+H9+I9)*$J$3 | K9: =(G9+H9+I9+J9)*$K$3 | L9: =G9+H9+I9+J9+K9 | M9: =F9*L9 | O9: =P9*(1+Q9)+R9+S9+T9 | P9: 70 | Q9: 0 | R9: 20 | S9: 6 | T9: 0 | U9: =F9*O9
A10: 5 | B10: 30413002005 | C10: LA-06 LED明装筒灯 | D10: 1.名称：LA-06 LED明装筒灯 2.规格：9W 4000K 灯体尺寸Φ150*100mm 3.安装方式：明装 4.其他：包括但不限于满足图纸、招标文件、规范及验收要求等一切相关费用 | E10: 套 | F10: 117 | G10: =R10*$R$3 | H10: =P10*(1+Q10)*$P$3+S10*$S$3 | I10: =T10*$T$3 | J10: =(G10+H10+I10)*$J$3 | K10: =(G10+H10+I10+J10)*$K$3 | L10: =G10+H10+I10+J10+K10 | M10: =F10*L10 | O10: =P10*(1+Q10)+R10+S10+T10 | P10: ='架空层安装工程'!P8 | Q10: ='架空层安装工程'!Q8 | R10: ='架空层安装工程'!R8 | S10: ='架空层安装工程'!S8 | T10: ='架空层安装工程'!T8 | U10: =F10*O10
A11: 6 | B11: 30413002006 | C11: LA-07 LED明装筒灯(带红外感应) | D11: 1.名称：LA-07 LED明装筒灯(带红外感应) 2.规格：9W 4000K 灯体尺寸Φ150*100mm 3.安装方式：明装 4.其他：包括但不限于满足图纸、招标文件、规范及验收要求等一切相关费用 | E11: 套 | F11: 233 | G11: =R11*$R$3 | H11: =P11*(1+Q11)*$P$3+S11*$S$3 | I11: =T11*$T$3 | J11: =(G11+H11+I11)*$J$3 | K11: =(G11+H11+I11+J11)*$K$3 | L11: =G11+H11+I11+J11+K11 | M11: =F11*L11 | O11: =P11*(1+Q11)+R11+S11+T11 | P11: 70 | Q11: 0 | R11: 20 | S11: 6 | T11: 0 | U11: =F11*O11
A12: 7 | B12: 30413002007 | C12: LA-03 LED灯带 | D12: 1.名称：LA-03 LED灯带 2.规格：8W/米 4000K L170*W170*H25mm 3.安装方式：天花 4.其他：包括但不限于满足图纸、招标文件、规范及验收要求等一切相关费用 | E12: m | F12: 1471 | G12: =R12*$R$3 | H12: =P12*(1+Q12)*$P$3+S12*$S$3 | I12: =T12*$T$3 | J12: =(G12+H12+I12)*$J$3 | K12: =(G12+H12+I12+J12)*$K$3 | L12: =G12+H12+I12+J12+K12 | M12: =F12*L12 | O12: =P12*(1+Q12)+R12+S12+T12 | P12: 20.4 | Q12: 0 | R12: 12.5 | S12: 0.41 | T12: 0 | U12: =F12*O12
A13: 8 | B13: 30413009001 | C13: LED 灯带驱动电源 | D13: 1.名称：LED 灯带驱动电源 2.规格：60W 工作电压：220V 输出电压：24V 3.尺寸：L140*W45*H29mm 4.其他：包括但不限于满足图纸、招标文件、规范及验收要求等一切相关费用 | E13: 个 | F13: 2245 | G13: =R13*$R$3 | H13: =P13*(1+Q13)*$P$3+S13*$S$3 | I13: =T13*$T$3 | J13: =(G13+H13+I13)*$J$3 | K13: =(G13+H13+I13+J13)*$K$3 | L13: =G13+H13+I13+J13+K13 | M13: =F13*L13 | O13: =P13*(1+Q13)+R13+S13+T13 | P13: ='架空层安装工程'!P10 | Q13: ='架空层安装工程'!Q10 | R13: ='架空层安装工程'!R10 | S13: ='架空层安装工程'!S10 | T13: ='架空层安装工程'!T10 | U13: =F13*O13
A14: 9 | B14: 30413013001 | C14: 照明开关 | D14: 1.名称：单联单控开关 2.规格：86*86mm 3.安装方式：暗装 4.其他：包括但不限于满足图纸、招标文件、规范及验收要求等一切相关费用 | E14: 套 | F14: 117 | G14: =R14*$R$3 | H14: =P14*(1+Q14)*$P$3+S14*$S$3 | I14: =T14*$T$3 | J14: =(G14+H14+I14)*$J$3 | K14: =(G14+H14+I14+J14)*$K$3 | L14: =G14+H14+I14+J14+K14 | M14: =F14*L14 | O14: =P14*(1+Q14)+R14+S14+T14 | P14: 14.62 | Q14: 0 | R14: 6.31 | S14: 1.12 | T14: 0 | U14: =F14*O14
A15: 10 | B15: 30413013003 | C15: 照明开关 | D15: 1.名称：三联单控开关 2.规格：86*86mm 3.安装方式：暗装 4.其他：包括但不限于满足图纸、招标文件、规范及验收要求等一切相关费用 | E15: 套 | F15: 4 | G15: =R15*$R$3 | H15: =P15*(1+Q15)*$P$3+S15*$S$3 | I15: =T15*$T$3 | J15: =(G15+H15+I15)*$J$3 | K15: =(G15+H15+I15+J15)*$K$3 | L15: =G15+H15+I15+J15+K15 | M15: =F15*L15 | O15: =P15*(1+Q15)+R15+S15+T15 | P15: 20 | Q15: 0 | R15: 12 | S15: 1.5 | T15: 0 | U15: =F15*O15
A16: 11 | B16: 30413014001 | C16: 插座 | D16: 1.名称：五孔插座 2.规格：86*86mm 3.安装方式：暗装 4.其他：包括但不限于满足图纸、招标文件、规范及验收要求等一切相关费用 | E16: 套 | F16: 2 | G16: =R16*$R$3 | H16: =P16*(1+Q16)*$P$3+S16*$S$3 | I16: =T16*$T$3 | J16: =(G16+H16+I16)*$J$3 | K16: =(G16+H16+I16+J16)*$K$3 | L16: =G16+H16+I16+J16+K16 | M16: =F16*L16 | O16: =P16*(1+Q16)+R16+S16+T16 | P16: 14.62 | Q16: 0 | R16: 6.31 | S16: 1.12 | T16: 0 | U16: =F16*O16
A17: 12 | B17: 30412004001 | C17: 配线 | D17: 1.名称：电气配线 2.型号规格：WDZC-BYJ-2.5 3.安装方式：管内穿线 4.其他：包括但不限于满足图纸、招标文件、规范及验收要求等一切相关费用 | E17: m | F17: 11412 | G17: =R17*$R$3 | H17: =P17*(1+Q17)*$P$3+S17*$S$3 | I17: =T17*$T$3 | J17: =(G17+H17+I17)*$J$3 | K17: =(G17+H17+I17+J17)*$K$3 | L17: =G17+H17+I17+J17+K17 | M17: =F17*L17 | O17: =P17*(1+Q17)+R17+S17+T17 | P17: 2.92 | Q17: 0.02 | R17: 2.2 | S17: 0.21 | T17: 0.02 | U17: =F17*O17
C18: 电梯轿厢
A19: 13 | B19: 30413002008 | C19: 嵌入式筒灯 | D19: 1.名称：嵌入式筒灯 2.规格：- 3.安装方式：嵌装 4.其他：包括但不限于满足图纸、招标文件、规范及验收要求等一切相关费用 | E19: 套 | F19: 8 | G19: =R19*$R$3 | H19: =P19*(1+Q19)*$P$3+S19*$S$3 | I19: =T19*$T$3 | J19: =(G19+H19+I19)*$J$3 | K19: =(G19+H19+I19+J19)*$K$3 | L19: =G19+H19+I19+J19+K19 | M19: =F19*L19 | O19: =P19*(1+Q19)+R19+S19+T19 | P19: 70 | Q19: 0 | R19: 20 | S19: 6 | T19: 0 | U19: =F19*O19
A20: 14 | B20: 30413002009 | C20: LED灯带 | D20: 1.名称：LED灯带 2.规格：8W/米 4000K L170*W170*H25mm 3.安装方式：天花 4.其他：包括但不限于满足图纸、招标文件、规范及验收要求等一切相关费用 | E20: m | F20: 39.68 | G20: =R20*$R$3 | H20: =P20*(1+Q20)*$P$3+S20*$S$3 | I20: =T20*$T$3 | J20: =(G20+H20+I20)*$J$3 | K20: =(G20+H20+I20+J20)*$K$3 | L20: =G20+H20+I20+J20+K20 | M20: =F20*L20 | O20: =P20*(1+Q20)+R20+S20+T20 | P20: 20.4 | Q20: 0 | R20: 12.5 | S20: 0.41 | T20: 0 | U20: =F20*O20
A21: 15 | B21: 30413009002 | C21: LED 灯带驱动电源 | D21: 1.名称：LED 灯带驱动电源 2.规格：60W 工作电压：220V 输出电压：24V 3.尺寸：L140*W45*H29mm 4.其他：包括但不限于满足图纸、招标文件、规范及验收要求等一切相关费用 | E21: 个 | F21: 8 | G21: =R21*$R$3 | H21: =P21*(1+Q21)*$P$3+S21*$S$3 | I21: =T21*$T$3 | J21: =(G21+H21+I21)*$J$3 | K21: =(G21+H21+I21+J21)*$K$3 | L21: =G21+H21+I21+J21+K21 | M21: =F21*L21 | O21: =P21*(1+Q21)+R21+S21+T21 | P21: ='架空层安装工程'!P10 | Q21: ='架空层安装工程'!Q10 | R21: ='架空层安装工程'!R10 | S21: ='架空层安装工程'!S10 | T21: ='架空层安装工程'!T10 | U21: =F21*O21
A22: 16 | B22: 30412004002 | C22: 配线 | D22: 1.名称：电气配线 2.型号规格：BV-2.5 3.安装方式：管内穿线 4.其他：包括但不限于满足图纸、招标文件、规范及验收要求等一切相关费用 | E22: m | F22: 240 | G22: =R22*$R$3 | H22: =P22*(1+Q22)*$P$3+S22*$S$3 | I22: =T22*$T$3 | J22: =(G22+H22+I22)*$J$3 | K22: =(G22+H22+I22+J22)*$K$3 | L22: =G22+H22+I22+J22+K22 | M22: =F22*L22 | O22: =P22*(1+Q22)+R22+S22+T22 | P22: 2.77 | Q22: 0.02 | R22: 2.1 | S22: 0.21 | T22: 0.02 | U22: =F22*O22
B23: 税前合价 | E23: 元 | M23: =SUM(M4:M22)
B24: 税金 | E24: 元 | M24: =M23*0.09
B25: 含税合价 | E25: 元 | M25: =M23+M24

Sheet 户内交标安装工程
A1: 户内交标安装工程工程量清单 | O1: 成本单价组成（投标人填写）
A2: 序号 | B2: 编码 | C2: 项目名称 | D2: 项目特征 | E2: 单位 | F2: 工程量 | G2: 人工费 | H2: 材料费 | I2: 机械费 | J2: 管理费 | K2: 利润 | L2: 不含税单价 | M2: 合价 | O2: 单价合计 | P2: 主材费 | Q2: 主材损耗率 | R2: 人工费 | S2: 辅材费 | T2: 机械费 | U2: 合计
J3: 0 | K3: 0 | P3: =架空层安装工程!$P$3 | R3: =架空层安装工程!$R$3 | S3: =架空层安装工程!$S$3 | T3: =架空层安装工程!$T$3
B4: 单位工程
C5: 电气
A6: 1 | B6: 30413002001 | C6: LA-01 筒灯 | D6: 1.名称：LA-01 筒灯 2.规格：8.5W 4000K 尺寸Φ138*32mm 3.安装方式：嵌装 4.其他：包括但不限于满足图纸、招标文件、规范及验收要求等一切相关费用 | E6: 套 | F6: 730.33333 | G6: =R6*$R$3 | H6: =P6*(1+Q6)*$P$3+S6*$S$3 | I6: =T6*$T$3 | J6: =(G6+H6+I6)*$J$3 | K6: =(G6+H6+I6+J6)*$K$3 | L6: =G6+H6+I6+J6+K6 | M6: =F6*L6 | O6: =P6*(1+Q6)+R6+S6+T6 | P6: 70 | Q6: 0 | R6: 20 | S6: 6 | T6: 0 | U6: =F6*O6
A7: 2 | B7: 30413002002 | C7: LA-02 LED嵌入式射灯 | D7: 1.名称：LA-02 LED嵌入式射灯 2.规格：7.5W 4000K 尺寸Φ85*57mm 3.安装方式：嵌装 4.其他：包括但不限于满足图纸、招标文件、规范及验收要求等一切相关费用 | E7: 套 | F7: 254 | G7: =R7*$R$3 | H7: =P7*(1+Q7)*$P$3+S7*$S$3 | I7: =T7*$T$3 | J7: =(G7+H7+I7)*$J$3 | K7: =(G7+H7+I7+J7)*$K$3 | L7: =G7+H7+I7+J7+K7 | M7: =F7*L7 | O7: =P7*(1+Q7)+R7+S7+T7 | P7: 120 | Q7: 0 | R7: 18 | S7: 3.5 | T7: 0.5 | U7: =F7*O7
A8: 3 | B8: 30413002003 | C8: LA-03 防雾射灯 | D8: 1.名称：LA-03 防雾射灯 2.规格：7W 3500K 尺寸Φ86*86mm 3.安装方式：嵌装 4.其他：包括但不限于满足图纸、招标文件、规范及验收要求等一切相关费用 | E8: 套 | F8: 231 | G8: =R8*$R$3 | H8: =P8*(1+Q8)*$P$3+S8*$S$3 | I8: =T8*$T$3 | J8: =(G8+H8+I8)*$J$3 | K8: =(G8+H8+I8+J8)*$K$3 | L8: =G8+H8+I8+J8+K8 | M8: =F8*L8 | O8: =P8*(1+Q8)+R8+S8+T8 | P8: 120 | Q8: 0 | R8: 18 | S8: 3.5 | T8: 0.5 | U8: =F8*O8
A9: 4 | B9: 30413002004 | C9: LA-05 平板灯300*600 | D9: 1.名称：LA-05 平板灯300*600 2.规格：12W 4000K 尺寸300*600mm 3.安装方式：嵌装 4.其他：包括但不限于满足图纸、招标文件、规范及验收要求等一切相关费用 | E9: 套 | F9: 403.33333 | G9: =R9*$R$3 | H9: =P9*(1+Q9)*$P$3+S9*$S$3 | I9: =T9*$T$3 | J9: =(G9+H9+I9)*$J$3 | K9: =(G9+H9+I9+J9)*$K$3 | L9: =G9+H9+I9+J9+K9 | M9: =F9*L9 | O9: =P9*(1+Q9)+R9+S9+T9 | P9: 125 | Q9: 0 | R9: 38 | S9: 8 | T9: 0 | U9: =F9*O9
A10: 5 | B10: 30413001001 | C10: LA-06 吸顶灯 | D10: 1.名称：LA-06 吸顶灯 2.规格：18W 4000K 尺寸φ330*H48mm 3.安装方式：嵌装 4.其他：包括但不限于满足图纸、招标文件、规范及验收要求等一切相关费用 | E10: 套 | F10: 185 | G10: =R10*$R$3 | H10: =P10*(1+Q10)*$P$3+S10*$S$3 | I10: =T10*$T$3 | J10: =(G10+H10+I10)*$J$3 | K10: =(G10+H10+I10+J10)*$K$3 | L10: =G10+H10+I10+J10+K10 | M10: =F10*L10 | O10: =P10*(1+Q10)+R10+S10+T10 | P10: 60 | Q10: 0 | R10: 10 | S10: 2 | T10: 0 | U10: =F10*O10
A11: 6 | B11: 30413001003 | C11: 普通灯具 | D11: 1.名称：LA-08 LED灯泡+灯座 2.规格：5W 4000K 86*86mm E27螺口 3.安装方式：嵌装 4.其他：包括但不限于满足图纸、招标文件、规范及验收要求等一切相关费用 | E11: 套 | F11: 756.33333 | G11: =R11*$R$3 | H11: =P11*(1+Q11)*$P$3+S11*$S$3 | I11: =T11*$T$3 | J11: =(G11+H11+I11)*$J$3 | K11: =(G11+H11+I11+J11)*$K$3 | L11: =G11+H11+I11+J11+K11 | M11: =F11*L11 | O11: =P11*(1+Q11)+R11+S11+T11 | P11: 48 | Q11: 0 | R11: 18 | S11: 1.5 | T11: 0.2 | U11: =F11*O11
A12: 7 | B12: 30413002005 | C12: LA-04 线条灯 | D12: 1.名称：LA-04 线条灯 2.规格：12W/m 尺寸20*10mm 3.安装方式：吊装 4.其他：包括但不限于满足图纸、招标文件、规范及验收要求等一切相关费用 | E12: m | F12: 230.34 | G12: =R12*$R$3 | H12: =P12*(1+Q12)*$P$3+S12*$S$3 | I12: =T12*$T$3 | J12: =(G12+H12+I12)*$J$3 | K12: =(G12+H12+I12+J12)*$K$3 | L12: =G12+H12+I12+J12+K12 | M12: =F12*L12 | O12: =P12*(1+Q12)+R12+S12+T12 | P12: 40 | Q12: 0 | R12: 5 | S12: 1 | T12: 0 | U12: =F12*O12
A13: 8 | B13: 30413002006 | C13: LA-07 LED灯带 | D13: 1.名称：LA-07 LED灯带 2.规格：8W/米 4000K 3.安装方式：天花 4.其他：包括但不限于满足图纸、招标文件、规范及验收要求等一切相关费用 | E13: m | F13: 818.02333 | G13: =R13*$R$3 | H13: =P13*(1+Q13)*$P$3+S13*$S$3 | I13: =T13*$T$3 | J13: =(G13+H13+I13)*$J$3 | K13: =(G13+H13+I13+J13)*$K$3 | L13: =G13+H13+I13+J13+K13 | M13: =F13*L13 | O13: =P13*(1+Q13)+R13+S13+T13 | P13: 20.4 | Q13: 0 | R13: 12.5 | S13: 0.41 | T13: 0 | U13: =F13*O13
A14: 9 | B14: 30413009001 | C14: LED 灯带驱动电源 | D14: 1.名称：LED 灯带驱动电源 2.规格：60W 工作电压：220V 输出电压：24V 3.尺寸：L140*W45*H29mm 4.其他：包括但不限于满足图纸、招标文件、规范及验收要求等一切相关费用 | E14: 个 | F14: 136.33333 | G14: =R14*$R$3 | H14: =P14*(1+Q14)*$P$3+S14*$S$3 | I14: =T14*$T$3 | J14: =(G14+H14+I14)*$J$3 | K14: =(G14+H14+I14+J14)*$K$3 | L14: =G14+H14+I14+J14+K14 | M14: =F14*L14 | O14: =P14*(1+Q14)+R14+S14+T14 | P14: ='架空层安装工程'!P10 | Q14: ='架空层安装工程'!Q10 | R14: ='架空层安装工程'!R10 | S14: ='架空层安装工程'!S10 | T14: ='架空层安装工程'!T10 | U14: =F14*O14
A15: 10 | B15: 30405015001 | C15: 排气扇 | D15: 1.名称：排气扇 2.规格：40W 风量235m3/h 3.尺寸：详见物料表 4.其他：包括但不限于满足图纸、招标文件、规范及验收要求等一切相关费用 | E15: 台 | F15: 268 | G15: =R15*$R$3 | H15: =P15*(1+Q15)*$P$3+S15*$S$3 | I15: =T15*$T$3 | J15: =(G15+H15+I15)*$J$3 | K15: =(G15+H15+I15+J15)*$K$3 | L15: =G15+H15+I15+J15+K15 | M15: =F15*L15 | O15: =P15*(1+Q15)+R15+S15+T15 | P15: 155 | Q15: 0 | R15: 21 | S15: 2 | T15: 0 | U15: =F15*O15
A16: 11 | B16: 30413013001 | C16: 照明开关 | D16: 1.名称：一键开关 2.规格：86*86mm 3.安装方式：暗装 4.其他：包括但不限于满足图纸、招标文件、规范及验收要求等一切相关费用 | E16: 套 | F16: 117.66667 | G16: =R16*$R$3 | H16: =P16*(1+Q16)*$P$3+S16*$S$3 | I16: =T16*$T$3 | J16: =(G16+H16+I16)*$J$3 | K16: =(G16+H16+I16+J16)*$K$3 | L16: =G16+H16+I16+J16+K16 | M16: =F16*L16 | O16: =P16*(1+Q16)+R16+S16+T16 | P16: 14.62 | Q16: 0 | R16: 6.31 | S16: 1.12 | T16: 0 | U16: =F16*O16
A17: 12 | B17: 30413013002 | C17: 照明开关 | D17: 1.名称：单联单控开关 2.规格：86*86mm 3.安装方式：暗装 4.其他：包括但不限于满足图纸、招标文件、规范及验收要求等一切相关费用 | E17: 套 | F17: 386 | G17: =R17*$R$3 | H17: =P17*(1+Q17)*$P$3+S17*$S$3 | I17: =T17*$T$3 | J17: =(G17+H17+I17)*$J$3 | K17: =(G17+H17+I17+J17)*$K$3 | L17: =G17+H17+I17+J17+K17 | M17: =F17*L17 | O17: =P17*(1+Q17)+R17+S17+T17 | P17: ='公共区域安装工程'!P14 | Q17: ='公共区域安装工程'!Q14 | R17: ='公共区域安装工程'!R14 | S17: ='公共区域安装工程'!S14 | T17: ='公共区域安装工程'!T14 | U17: =F17*O17
A18: 13 | B18: 30413013003 | C18: 照明开关 | D18: 1.名称：双联单控开关 2.规格：86*86mm 3.安装方式：暗装 4.其他：包括但不限于满足图纸、招标文件、规范及验收要求等一切相关费用 | E18: 套 | F18: 234 | G18: =R18*$R$3 | H18: =P18*(1+Q18)*$P$3+S18*$S$3 | I18: =T18*$T$3 | J18: =(G18+H18+I18)*$J$3 | K18: =(G18+H18+I18+J18)*$K$3 | L18: =G18+H18+I18+J18+K18 | M18: =F18*L18 | O18: =P18*(1+Q18)+R18+S18+T18 | P18: ='架空层安装工程'!P16 | Q18: ='架空层安装工程'!Q16 | R18: ='架空层安装工程'!R16 | S18: ='架空层安装工程'!S16 | T18: ='架空层安装工程'!T16 | U18: =F18*O18
A19: 14 | B19: 30413013004 | C19: 照明开关 | D19: 1.名称：三联单控开关 2.规格：86*86mm 3.安装方式：暗装 4.其他：包括但不限于满足图纸、招标文件、规范及验收要求等一切相关费用 | E19: 套 | F19: 100.33333 | G19: =R19*$R$3 | H19: =P19*(1+Q19)*$P$3+S19*$S$3 | I19: =T19*$T$3 | J19: =(G19+H19+I19)*$J$3 | K19: =(G19+H19+I19+J19)*$K$3 | L19: =G19+H19+I19+J19+K19 | M19: =F19*L19 | O19: =P19*(1+Q19)+R19+S19+T19 | P19: ='公共区域安装工程'!P15 | Q19: ='公共区域安装工程'!Q15 | R19: ='公共区域安装工程'!R15 | S19: ='公共区域安装工程'!S15 | T19: ='公共区域安装工程'!T15 | U19: =F19*O19
A20: 15 | B20: 30413013005 | C20: 照明开关 | D20: 1.名称：单联双控开关 2.规格：86*86mm 3.安装方式：暗装 4.其他：包括但不限于满足图纸、招标文件、规范及验收要求等一切相关费用 | E20: 套 | F20: 708.66667 | G20: =R20*$R$3 | H20: =P20*(1+Q20)*$P$3+S20*$S$3 | I20: =T20*$T$3 | J20: =(G20+H20+I20)*$J$3 | K20: =(G20+H20+I20+J20)*$K$3 | L20: =G20+H20+I20+J20+K20 | M20: =F20*L20 | O20: =P20*(1+Q20)+R20+S20+T20 | P20: 14.62 | Q20: 0 | R20: 6.31 | S20: 1.12 | T20: 0 | U20: =F20*O20
A21: 16 | B21: 30413013006 | C21: 照明开关 | D21: 1.名称：双联双控开关 2.规格：86*86mm 3.安装方式：暗装 4.其他：包括但不限于满足图纸、招标文件、规范及验收要求等一切相关费用 | E21: 套 | F21: 463.66667 | G21: =R21*$R$3 | H21: =P21*(1+Q21)*$P$3+S21*$S$3 | I21: =T21*$T$3 | J21: =(G21+H21+I21)*$J$3 | K21: =(G21+H21+I21+J21)*$K$3 | L21: =G21+H21+I21+J21+K21 | M21: =F21*L21 | O21: =P21*(1+Q21)+R21+S21+T21 | P21: 18 | Q21: 0 | R21: 10 | S21: 1.5 | T21: 0 | U21: =F21*O21
A22: 17 | B22: 30413013007 | C22: 照明开关 | D22: 1.名称：三联双控开关 2.规格：86*86mm 3.安装方式：暗装 4.其他：包括但不限于满足图纸、招标文件、规范及验收要求等一切相关费用 | E22: 套 | F22: 169.33333 | G22: =R22*$R$3 | H22: =P22*(1+Q22)*$P$3+S22*$S$3 | I22: =T22*$T$3 | J22: =(G22+H22+I22)*$J$3 | K22: =(G22+H22+I22+J22)*$K$3 | L22: =G22+H22+I22+J22+K22 | M22: =F22*L22 | O22: =P22*(1+Q22)+R22+S22+T22 | P22: 20 | Q22: 0 | R22: 12 | S22: 1.5 | T22: 0 | U22: =F22*O22
A23: 18 | B23: 30413014001 | C23: 插座 | D23: 1.名称：五孔插座 2.规格：86*86mm 3.安装方式：暗装 4.其他：包括但不限于满足图纸、招标文件、规范及验收要求等一切相关费用 | E23: 套 | F23: 2499 | G23: =R23*$R$3 | H23: =P23*(1+Q23)*$P$3+S23*$S$3 | I23: =T23*$T$3 | J23: =(G23+H23+I23)*$J$3 | K23: =(G23+H23+I23+J23)*$K$3 | L23: =G23+H23+I23+J23+K23 | M23: =F23*L23 | O23: =P23*(1+Q23)+R23+S23+T23 | P23: ='公共区域安装工程'!P16 | Q23: ='公共区域安装工程'!Q16 | R23: ='公共区域安装工程'!R16 | S23: ='公共区域安装工程'!S16 | T23: ='公共区域安装工程'!T16 | U23: =F23*O23
A24: 19 | B24: 30413014002 | C24: 插座 | D24: 1.名称：五孔插座（防溅） 2.规格：86*86mm 3.安装方式：暗装 4.其他：包括但不限于满足图纸、招标文件、规范及验收要求等一切相关费用 | E24: 套 | F24: 871 | G24: =R24*$R$3 | H24: =P24*(1+Q24)*$P$3+S24*$S$3 | I24: =T24*$T$3 | J24: =(G24+H24+I24)*$J$3 | K24: =(G24+H24+I24+J24)*$K$3 | L24: =G24+H24+I24+J24+K24 | M24: =F24*L24 | O24: =P24*(1+Q24)+R24+S24+T24 | P24: 14.62 | Q24: 0 | R24: 6.31 | S24: 1.12 | T24: 0 | U24: =F24*O24
A25: 20 | B25: 30413014003 | C25: 插座 | D25: 1.名称：五孔插座带开关 2.规格：86*86mm 3.安装方式：暗装 4.其他：包括但不限于满足图纸、招标文件、规范及验收要求等一切相关费用 | E25: 套 | F25: 235.33333 | G25: =R25*$R$3 | H25: =P25*(1+Q25)*$P$3+S25*$S$3 | I25: =T25*$T$3 | J25: =(G25+H25+I25)*$J$3 | K25: =(G25+H25+I25+J25)*$K$3 | L25: =G25+H25+I25+J25+K25 | M25: =F25*L25 | O25: =P25*(1+Q25)+R25+S25+T25 | P25: 14.62 | Q25: 0 | R25: 6.31 | S25: 1.12 | T25: 0 | U25: =F25*O25
A26: 21 | B26: 30413014004 | C26: 插座 | D26: 1.名称：五孔插座带USB接口 2.规格：86*86mm 3.安装方式：暗装 4.其他：包括但不限于满足图纸、招标文件、规范及验收要求等一切相关费用 | E26: 套 | F26: 200.33333 | G26: =R26*$R$3 | H26: =P26*(1+Q26)*$P$3+S26*$S$3 | I26: =T26*$T$3 | J26: =(G26+H26+I26)*$J$3 | K26: =(G26+H26+I26+J26)*$K$3 | L26: =G26+H26+I26+J26+K26 | M26: =F26*L26 | O26: =P26*(1+Q26)+R26+S26+T26 | P26: 14.62 | Q26: 0 | R26: 6.31 | S26: 1.12 | T26: 0 | U26: =F26*O26
A27: 22 | B27: 30413014005 | C27: 插座 | D27: 1.名称：三孔插座 2.规格：86*86mm 3.安装方式：暗装 4.其他：包括但不限于满足图纸、招标文件、规范及验收要求等一切相关费用 | E27: 套 | F27: 691.66667 | G27: =R27*$R$3 | H27: =P27*(1+Q27)*$P$3+S27*$S$3 | I27: =T27*$T$3 | J27: =(G27+H27+I27)*$J$3 | K27: =(G27+H27+I27+J27)*$K$3 | L27: =G27+H27+I27+J27+K27 | M27: =F27*L27 | O27: =P27*(1+Q27)+R27+S27+T27 | P27: 14.62 | Q27: 0 | R27: 6.31 | S27: 1.12 | T27: 0 | U27: =F27*O27
A28: 23 | B28: 30413014006 | C28: 插座 | D28: 1.名称：三孔插座 16A 2.规格：86*86mm 3.安装方式：暗装 4.其他：包括但不限于满足图纸、招标文件、规范及验收要求等一切相关费用 | E28: 套 | F28: 2.6666667 | G28: =R28*$R$3 | H28: =P28*(1+Q28)*$P$3+S28*$S$3 | I28: =T28*$T$3 | J28: =(G28+H28+I28)*$J$3 | K28: =(G28+H28+I28+J28)*$K$3 | L28: =G28+H28+I28+J28+K28 | M28: =F28*L28 | O28: =P28*(1+Q28)+R28+S28+T28 | P28: 14.62 | Q28: 0 | R28: 6.31 | S28: 1.12 | T28: 0 | U28: =F28*O28
A29: 24 | B29: 30413014007 | C29: 插座 | D29: 1.名称：三孔插座带开关（防溅） 2.规格：86*86mm 3.安装方式：暗装 4.其他：包括但不限于满足图纸、招标文件、规范及验收要求等一切相关费用 | E29: 套 | F29: 117.66667 | G29: =R29*$R$3 | H29: =P29*(1+Q29)*$P$3+S29*$S$3 | I29: =T29*$T$3 | J29: =(G29+H29+I29)*$J$3 | K29: =(G29+H29+I29+J29)*$K$3 | L29: =G29+H29+I29+J29+K29 | M29: =F29*L29 | O29: =P29*(1+Q29)+R29+S29+T29 | P29: 14.62 | Q29: 0 | R29: 6.31 | S29: 1.12 | T29: 0 | U29: =F29*O29
A30: 25 | B30: 30413014008 | C30: 小夜灯 | D30: 1.名称：小夜灯 2.规格：86*86mm 3.安装方式：暗装 4.其他：包括但不限于满足图纸、招标文件、规范及验收要求等一切相关费用 | E30: 套 | F30: 115.66667 | G30: =R30*$R$3 | H30: =P30*(1+Q30)*$P$3+S30*$S$3 | I30: =T30*$T$3 | J30: =(G30+H30+I30)*$J$3 | K30: =(G30+H30+I30+J30)*$K$3 | L30: =G30+H30+I30+J30+K30 | M30: =F30*L30 | O30: =P30*(1+Q30)+R30+S30+T30 | P30: 15 | Q30: 0 | R30: 5 | S30: 0.5 | T30: 0 | U30: =F30*O30
