Workbook

Sheet 汇总表
A1: 会所售楼部安装工程汇总表
A2: 序号 | B2: 单位工程 | C2: 含税合价 | D2: 不含税控制合价 | E2: 含税控制合价 | F2: 备注
A3: 1 | B3: 会所售楼部安装工程——电气 | C3: =电气工程!M63 -> 478159.02 | D3: 472090.65 | E3: =D3*1.09 -> 514578.81
A4: 2 | B4: 会所售楼部安装工程——给排水 | C4: =给排水工程!M31 -> 93179.407 | D4: 102836 | E4: =D4*1.09 -> 112091.24
A5: 3 | B5: 会所售楼部安装工程——空调 | C5: =空调工程!M61 -> 341307.93 | D5: 322743.33 | E5: =D5*1.09 -> 351790.23
A8: 小计 | C8: =SUM(C3:C7) -> 912646.35 | D8: =SUM(D3:D7) -> 897669.98 | E8: =SUM(E3:E7) -> 978460.28

Sheet 电气工程
A1: 会所售楼部电气工程工程量清单
A2: 序号 | B2: 编码 | C2: 项目名称 | D2: 项目特征 | E2: 单位 | F2: 工程量 | G2: 人工费 | H2: 材料费 | I2: 机械费 | J2: 管理费 | K2: 利润 | L2: 不含税单价 | M2: 合价
J3: =[1]清单表!$K$3 -> 0.02 | K3: =[1]清单表!$L$3 -> 0.0315
B4: 单位工程
C5: 电气工程
C6: 灯具、电器
A7: 1 | B7: 30413002001 | C7: L1 嵌入式LED可调射灯 | D7: 1.名称：L1 嵌入式LED可调射灯 2.规格：LED COB 15W 3000K±50 3.尺寸：φ77mm*H90mm 4.安装方式：嵌装 5.其他：包括但不限于满足图纸、招标文件、规范及验收要求等一切相关费用 | E7: 套 | F7: 68 | G7: 22 | H7: 116.5 | I7: 0.3 | J7: =(G7+H7+I7)*$J$3 -> 2.776 | K7: =(G7+H7+I7+J7)*$K$3 -> 4.459644 | L7: =G7+H7+I7+J7+K7 -> 146.03564 | M7: =F7*L7 -> 9930.4238
A8: 2 | B8: 30413002002 | C8: L2 嵌入式LED筒灯 | D8: 1.名称：L2 嵌入式LED筒灯 2.规格：LED COB 15W 3000K±50 3.尺寸：φ77mm*H99mm 4.安装方式：嵌装 5.其他：包括但不限于满足图纸、招标文件、规范及验收要求等一切相关费用 | E8: 套 | F8: 16 | G8: 22 | H8: 116.5 | I8: 0.3 | J8: =(G8+H8+I8)*$J$3 -> 2.776 | K8: =(G8+H8+I8+J8)*$K$3 -> 4.459644 | L8: =G8+H8+I8+J8+K8 -> 146.03564 | M8: =F8*L8 -> 2336.5703
A9: 3 | B9: 30413002003 | C9: L3 嵌入式LED可调射灯 | D9: 1.名称：L3 嵌入式LED可调射灯 2.规格：LED COB 7W 2700K±50 3.尺寸：φ77mm*H78mm 4.安装方式：嵌装 5.其他：包括但不限于满足图纸、招标文件、规范及验收要求等一切相关费用 | E9: 套 | F9: 156 | G9: 22 | H9: 86.5 | I9: 0.3 | J9: =(G9+H9+I9)*$J$3 -> 2.176 | K9: =(G9+H9+I9+J9)*$K$3 -> 3.495744 | L9: =G9+H9+I9+J9+K9 -> 114.47174 | M9: =F9*L9 -> 17857.592
A10: 4 | B10: 30413002004 | C10: L4 嵌入式LED可调射灯 | D10: 1.名称：L4 嵌入式LED可调射灯 2.规格：LED COB 9W 2700K±50 3.尺寸：φ77mm*H78mm 4.安装方式：嵌装 5.其他：包括但不限于满足图纸、招标文件、规范及验收要求等一切相关费用 | E10: 套 | F10: 21 | G10: 22 | H10: 93.5 | I10: 0.3 | J10: =(G10+H10+I10)*$J$3 -> 2.316 | K10: =(G10+H10+I10+J10)*$K$3 -> 3.720654 | L10: =G10+H10+I10+J10+K10 -> 121.83665 | M10: =F10*L10 -> 2558.5697
A11: 5 | B11: 30413002005 | C11: L5 明装LED可调射灯 | D11: 1.名称：L5 明装LED可调射灯 2.规格：LED COB 15W 3500K±50 3.尺寸：L85mm*W85mm*H90mm 4.安装方式：明装 5.其他：包括但不限于满足图纸、招标文件、规范及验收要求等一切相关费用 | E11: 套 | F11: 4 | G11: 22 | H11: 263.5 | I11: 0.3 | J11: =(G11+H11+I11)*$J$3 -> 5.716 | K11: =(G11+H11+I11+J11)*$K$3 -> 9.182754 | L11: =G11+H11+I11+J11+K11 -> 300.69875 | M11: =F11*L11 -> 1202.795
A12: 6 | B12: 30413002006 | C12: L6 嵌入式LED可调射灯 | D12: 1.名称：L6 嵌入式LED可调射灯 2.规格：LED COB 12W 2700K±50 3.尺寸：φ77mm*H78mm 4.安装方式：嵌装 5.其他：包括但不限于满足图纸、招标文件、规范及验收要求等一切相关费用 | E12: 套 | F12: 2 | G12: 22 | H12: 116.5 | I12: 0.3 | J12: =(G12+H12+I12)*$J$3 -> 2.776 | K12: =(G12+H12+I12+J12)*$K$3 -> 4.459644 | L12: =G12+H12+I12+J12+K12 -> 146.03564 | M12: =F12*L12 -> 292.07129
A13: 7 | B13: 30413002007 | C13: L7 嵌入式LED可调射灯 | D13: 1.名称：L7 嵌入式LED可调射灯 2.规格：LED COB 12W 2700K±50 3.尺寸：φ77mm*H78mm 4.安装方式：嵌装 5.其他：包括但不限于满足图纸、招标文件、规范及验收要求等一切相关费用 | E13: 套 | F13: 11 | G13: 22 | H13: 116.5 | I13: 0.3 | J13: =(G13+H13+I13)*$J$3 -> 2.776 | K13: =(G13+H13+I13+J13)*$K$3 -> 4.459644 | L13: =G13+H13+I13+J13+K13 -> 146.03564 | M13: =F13*L13 -> 1606.3921
A14: 8 | B14: 30413002008 | C14: L8 嵌入式LED可调射灯 | D14: 1.名称：L8 嵌入式LED可调射灯 2.规格：LED COB 7W 2700K±50 3.尺寸：φ77mm*H78mm 4.安装方式：嵌装 5.其他：包括但不限于满足图纸、招标文件、规范及验收要求等一切相关费用 | E14: 套 | F14: 7 | G14: 22 | H14: 86.5 | I14: 0.3 | J14: =(G14+H14+I14)*$J$3 -> 2.176 | K14: =(G14+H14+I14+J14)*$K$3 -> 3.495744 | L14: =G14+H14+I14+J14+K14 -> 114.47174 | M14: =F14*L14 -> 801.30221
A15: 9 | B15: 30413002009 | C15: L10 嵌入式LED可调射灯 | D15: 1.名称：L10 嵌入式LED可调射灯 2.规格：LED COB 7W 2700K±50 3.尺寸：φ77mm*H78mm 4.安装方式：嵌装 5.其他：包括但不限于满足图纸、招标文件、规范及验收要求等一切相关费用 | E15: 套 | F15: 20 | G15: 22 | H15: 136.5 | I15: 0.3 | J15: =(G15+H15+I15)*$J$3 -> 3.176 | K15: =(G15+H15+I15+J15)*$K$3 -> 5.102244 | L15: =G15+H15+I15+J15+K15 -> 167.07824 | M15: =F15*L15 -> 3341.5649
A16: 10 | B16: 30413001001 | C16: L11 吊线办公灯 | D16: 1.名称：L11 吊线办公灯 2.规格：LED 30W 4000K±50 3.尺寸：L1206mm*W75mm*H73.5mm 4.安装方式：吊装 5.其他：包括但不限于满足图纸、招标文件、规范及验收要求等一切相关费用 | E16: 套 | F16: 7 | G16: 55 | H16: 923 | I16: 0.3 | J16: =(G16+H16+I16)*$J$3 -> 19.566 | K16: =(G16+H16+I16+J16)*$K$3 -> 31.432779 | L16: =G16+H16+I16+J16+K16 -> 1029.2988 | M16: =F16*L16 -> 7205.0915
A17: 11 | B17: 30413001002 | C17: L12 吸顶灯 | D17: 1.名称：L12 吸顶灯 2.规格：LED 18W 4000K±50 3.尺寸：Φ290mm*H54.5mm 4.安装方式：吸顶 5.其他：包括但不限于满足图纸、招标文件、规范及验收要求等一切相关费用 | E17: 套 | F17: 4 | G17: 22 | H17: 66.5 | I17: 0.3 | J17: =(G17+H17+I17)*$J$3 -> 1.776 | K17: =(G17+H17+I17+J17)*$K$3 -> 2.853144 | L17: =G17+H17+I17+J17+K17 -> 93.429144 | M17: =F17*L17 -> 373.71658
A18: 12 | B18: 30413004001 | C18: L13 LED地埋灯 | D18: 1.名称：L13 LED地埋灯 2.规格：LED 1W 2700K±50 3.尺寸：Φ42mm*H75mm 4.安装方式：埋地 5.其他：包括但不限于满足图纸、招标文件、规范及验收要求等一切相关费用 | E18: 套 | F18: 3 | G18: 22 | H18: 87 | I18: 0.3 | J18: =(G18+H18+I18)*$J$3 -> 2.186 | K18: =(G18+H18+I18+J18)*$K$3 -> 3.511809 | L18: =G18+H18+I18+J18+K18 -> 114.99781 | M18: =F18*L18 -> 344.99343
... A30: 24 | B30: 30405017001 | C30: 洗碗机 | D30: 1.名称：洗碗机 2.规格：- 3.尺寸：详见物料表 4.其他：包括但不限于满足图纸、招标文件、规范及验收要求等一切相关费用 | E30: 台 | F30: 1 | G30: 450 | H30: 6725 | I30: 5.5 | J30: =(G30+H30+I30)*$J$3 -> 143.61 | K30: =(G30+H30+I30+J30)*$K$3 -> 230.70946 | L30: =G30+H30+I30+J30+K30 -> 7554.8195 | M30: =F30*L30 -> 7554.8195
C31: 开关插座
A32: 25 | B32: 30413013001 | C32: 照明开关 | D32: 1.名称：单联单控开关 2.规格：86*86mm 3.安装方式：暗装 4.其他：包括但不限于满足图纸、招标文件、规范及验收要求等一切相关费用 | E32: 套 | F32: 5 | G32: 12 | H32: 20.1 | I32: 0.2 | J32: =(G32+H32+I32)*$J$3 -> 0.646 | K32: =(G32+H32+I32+J32)*$K$3 -> 1.037799 | L32: =G32+H32+I32+J32+K32 -> 33.983799 | M32: =F32*L32 -> 169.91899
A33: 26 | B33: 30413013002 | C33: 照明开关 | D33: 1.名称：双联单控开关 2.规格：86*86mm 3.安装方式：暗装 4.其他：包括但不限于满足图纸、招标文件、规范及验收要求等一切相关费用 | E33: 套 | F33: 10 | G33: 12 | H33: 22.5 | I33: 0.2 | J33: =(G33+H33+I33)*$J$3 -> 0.694 | K33: =(G33+H33+I33+J33)*$K$3 -> 1.114911 | L33: =G33+H33+I33+J33+K33 -> 36.508911 | M33: =F33*L33 -> 365.08911
A34: 27 | B34: 30413013003 | C34: 照明开关 | D34: 1.名称：三联单控开关 2.规格：86*86mm 3.安装方式：暗装 4.其他：包括但不限于满足图纸、招标文件、规范及验收要求等一切相关费用 | E34: 套 | F34: 23 | G34: 12 | H34: 22.5 | I34: 0.2 | J34: =(G34+H34+I34)*$J$3 -> 0.694 | K34: =(G34+H34+I34+J34)*$K$3 -> 1.114911 | L34: =G34+H34+I34+J34+K34 -> 36.508911 | M34: =F34*L34 -> 839.70495
A35: 28 | B35: 30413013004 | C35: 照明开关 | D35: 1.名称：卫生间排风开关 2.规格：86*86mm 3.安装方式：暗装 4.其他：包括但不限于满足图纸、招标文件、规范及验收要求等一切相关费用 | E35: 套 | F35: 4 | G35: 12 | H35: 35.5 | I35: 0.2 | J35: =(G35+H35+I35)*$J$3 -> 0.954 | K35: =(G35+H35+I35+J35)*$K$3 -> 1.532601 | L35: =G35+H35+I35+J35+K35 -> 50.186601 | M35: =F35*L35 -> 200.7464
A36: 29 | B36: 30413014001 | C36: 插座 | D36: 1.名称：三孔插座 2.规格：86*86mm 3.安装方式：暗装 4.其他：包括但不限于满足图纸、招标文件、规范及验收要求等一切相关费用 | E36: 套 | F36: 2 | G36: 12 | H36: 23.5 | I36: 0.2 | J36: =(G36+H36+I36)*$J$3 -> 0.714 | K36: =(G36+H36+I36+J36)*$K$3 -> 1.147041 | L36: =G36+H36+I36+J36+K36 -> 37.561041 | M36: =F36*L36 -> 75.122082
A37: 30 | B37: 30413014002 | C37: 插座 | D37: 1.名称：五孔插座 2.规格：86*86mm 3.安装方式：暗装 4.其他：包括但不限于满足图纸、招标文件、规范及验收要求等一切相关费用 | E37: 套 | F37: 63 | G37: 12 | H37: 12.5 | I37: 0.2 | J37: =(G37+H37+I37)*$J$3 -> 0.494 | K37: =(G37+H37+I37+J37)*$K$3 -> 0.793611 | L37: =G37+H37+I37+J37+K37 -> 25.987611 | M37: =F37*L37 -> 1637.2195
A38: 31 | B38: 30413014003 | C38: 插座 | D38: 1.名称：五孔插座（带防溅盒） 2.规格：86*86mm 3.安装方式：暗装 4.其他：包括但不限于满足图纸、招标文件、规范及验收要求等一切相关费用 | E38: 套 | F38: 15 | G38: 12 | H38: 26.5 | I38: 0.2 | J38: =(G38+H38+I38)*$J$3 -> 0.774 | K38: =(G38+H38+I38+J38)*$K$3 -> 1.243431 | L38: =G38+H38+I38+J38+K38 -> 40.717431 | M38: =F38*L38 -> 610.76147
A39: 32 | B39: 30413014004 | C39: 插座 | D39: 1.名称：五孔插座带开关 2.规格：86*86mm 3.安装方式：暗装 4.其他：包括但不限于满足图纸、招标文件、规范及验收要求等一切相关费用 | E39: 套 | F39: 21 | G39: 12 | H39: 20.5 | I39: 0.2 | J39: =(G39+H39+I39)*$J$3 -> 0.654 | K39: =(G39+H39+I39+J39)*$K$3 -> 1.050651 | L39: =G39+H39+I39+J39+K39 -> 34.404651 | M39: =F39*L39 -> 722.49767
A40: 33 | B40: 30413014005 | C40: 插座 | D40: 1.名称：五孔插座带开关（带防溅盒） 2.规格：86*86mm 3.安装方式：暗装 4.其他：包括但不限于满足图纸、招标文件、规范及验收要求等一切相关费用 | E40: 套 | F40: 4 | G40: 12 | H40: 26.5 | I40: 0.2 | J40: =(G40+H40+I40)*$J$3 -> 0.774 | K40: =(G40+H40+I40+J40)*$K$3 -> 1.243431 | L40: =G40+H40+I40+J40+K40 -> 40.717431 | M40: =F40*L40 -> 162.86972
A41: 34 | B41: 30413014006 | C41: 插座 | D41: 1.名称：五孔地面插座 2.规格：86*86mm 3.安装方式：暗装 4.其他：包括但不限于满足图纸、招标文件、规范及验收要求等一切相关费用 | E41: 套 | F41: 51 | G41: 12 | H41: 125.5 | I41: 0.2 | J41: =(G41+H41+I41)*$J$3 -> 2.754 | K41: =(G41+H41+I41+J41)*$K$3 -> 4.424301 | L41: =G41+H41+I41+J41+K41 -> 144.8783 | M41: =F41*L41 -> 7388.7934
C42: 配管配线
A43: 35 | B43: 30412001001 | C43: 配管 | D43: 1.名称：电气配管 2.规格：JDG20 3.安装方式：暗装 4.其他：包括但不限于满足图纸、招标文件、规范及验收要求等一切相关费用 | E43: m | F43: 2169.81 | G43: 8.5 | H43: 7.052 | I43: 0.1 | J43: =(G43+H43+I43)*$J$3 -> 0.31304 | K43: =(G43+H43+I43+J43)*$K$3 -> 0.50289876 | L43: =G43+H43+I43+J43+K43 -> 16.467939 | M43: =F43*L43 -> 35732.298
A44: 36 | B44: 30412001002 | C44: 配管 | D44: 1.名称：电气配管 2.规格：JDG25 3.安装方式：暗装 4.其他：包括但不限于满足图纸、招标文件、规范及验收要求等一切相关费用 | E44: m | F44: 324.48 | G44: 8.5 | H44: 8.567 | I44: 0.1 | J44: =(G44+H44+I44)*$J$3 -> 0.34334 | K44: =(G44+H44+I44+J44)*$K$3 -> 0.55157571 | L44: =G44+H44+I44+J44+K44 -> 18.061916 | M44: =F44*L44 -> 5860.7304
A45: 37 | B45: 30412001003 | C45: 配管 | D45: 1.名称：电气配管 2.规格：PC20 3.安装方式：暗装 4.其他：包括但不限于满足图纸、招标文件、规范及验收要求等一切相关费用 | E45: m | F45: 616.28 | G45: 8.5 | H45: 6.749 | I45: 0.1 | J45: =(G45+H45+I45)*$J$3 -> 0.30698 | K45: =(G45+H45+I45+J45)*$K$3 -> 0.49316337 | L45: =G45+H45+I45+J45+K45 -> 16.149143 | M45: =F45*L45 -> 9952.3941
A46: 38 | B46: 30412001004 | C46: 配管 | D46: 1.名称：电气配管 2.规格：PC25 3.安装方式：暗装 4.其他：包括但不限于满足图纸、招标文件、规范及验收要求等一切相关费用 | E46: m | F46: 932.93 | G46: 8.5 | H46: 8.365 | I46: 0.1 | J46: =(G46+H46+I46)*$J$3 -> 0.3393 | K46: =(G46+H46+I46+J46)*$K$3 -> 0.54508545 | L46: =G46+H46+I46+J46+K46 -> 17.849385 | M46: =F46*L46 -> 16652.227
A47: 39 | B47: 30412001005 | C47: 配管 | D47: 1.名称：电气配管 2.规格：PC32 3.安装方式：暗装 4.其他：包括但不限于满足图纸、招标文件、规范及验收要求等一切相关费用 | E47: m | F47: 24.68 | G47: 8.5 | H47: 10.688 | I47: 0.1 | J47: =(G47+H47+I47)*$J$3 -> 0.38576 | K47: =(G47+H47+I47+J47)*$K$3 -> 0.61972344 | L47: =G47+H47+I47+J47+K47 -> 20.293483 | M47: =F47*L47 -> 500.84317
A48: 40 | B48: 30412001006 | C48: 配管 | D48: 1.名称：金属软管 2.规格：DN20 3.安装方式：吊顶内安装 4.其他：包括但不限于满足图纸、招标文件、规范及验收要求等一切相关费用 | E48: m | F48: 686.43 | G48: 6 | H48: 6.5 | I48: 0.1 | J48: =(G48+H48+I48)*$J$3 -> 0.252 | K48: =(G48+H48+I48+J48)*$K$3 -> 0.404838 | L48: =G48+H48+I48+J48+K48 -> 13.256838 | M48: =F48*L48 -> 9099.8913
A49: 41 | B49: 30412001007 | C49: 配管 | D49: 1.名称：金属软管 2.规格：DN25 3.安装方式：吊顶内安装 4.其他：包括但不限于满足图纸、招标文件、规范及验收要求等一切相关费用 | E49: m | F49: 286.28 | G49: 6.5 | H49: 8.1 | I49: 0.1 | J49: =(G49+H49+I49)*$J$3 -> 0.294 | K49: =(G49+H49+I49+J49)*$K$3 -> 0.472311 | L49: =G49+H49+I49+J49+K49 -> 15.466311 | M49: =F49*L49 -> 4427.6955
A50: 42 | B50: 31301001001 | C50: 凿槽及修复 | D50: 1.名称：凿槽及修复 2.规格：70*70 3.部位：砖、混凝土结构综合考虑 4.其他：包括但不限于满足图纸、招标文件、规范及验收要求等一切相关费用 | E50: m | F50: 606.51 | G50: 20 | H50: 2 | I50: 0.1 | J50: =(G50+H50+I50)*$J$3 -> 0.442 | K50: =(G50+H50+I50+J50)*$K$3 -> 0.710073 | L50: =G50+H50+I50+J50+K50 -> 23.252073 | M50: =F50*L50 -> 14102.615
A51: 43 | B51: 30412006001 | C51: 接线盒 | D51: 1.名称：接线盒 2.材质：钢制 3.安装方式：暗装 4.其他：包括但不限于满足图纸、招标文件、规范及验收要求等一切相关费用 | E51: 个 | F51: 861 | G51: 3.5 | H51: 1.7 | I51: 0.1 | J51: =(G51+H51+I51)*$J$3 -> 0.106 | K51: =(G51+H51+I51+J51)*$K$3 -> 0.170289 | L51: =G51+H51+I51+J51+K51 -> 5.576289 | M51: =F51*L51 -> 4801.1848
...

Sheet 给排水工程
A1: 会所售楼部给排水工程工程量清单
A2: 序号 | B2: 编码 | C2: 项目名称 | D2: 项目特征 | E2: 单位 | F2: 工程量 | G2: 人工费 | H2: 材料费 | I2: 机械费 | J2: 管理费 | K2: 利润 | L2: 不含税单价 | M2: 合价
J3: =电气工程!$J$3 -> 0.02 | K3: =电气工程!$K$3 -> 0.0315
B4: 单位工程
C5: 给排水工程
C6: 给排水管
A7: 53 | B7: 31001008001 | C7: 冷水 PPR管 | D7: 1.名称：冷水 PPR管 2.规格：DN15 3.连接方式：热熔连接 4.压力试验及吹、洗要求：水压试验、水冲洗、消毒冲洗、管道标识等 5.其他：包括但不限于满足图纸、招标文件、规范及验收要求等一切相关费用 | E7: m | F7: 108.55 | G7: 20 | H7: 4.405 | I7: 0.2 | J7: =(G7+H7+I7)*$J$3 -> 0.4921 | K7: =(G7+H7+I7+J7)*$K$3 -> 0.79055865 | L7: =G7+H7+I7+J7+K7 -> 25.887659 | M7: =F7*L7 -> 2810.1053
A8: 54 | B8: 31001008002 | C8: 冷水 PPR管 | D8: 1.名称：冷水 PPR管 2.规格：DN20 3.连接方式：热熔连接 4.压力试验及吹、洗要求：水压试验、水冲洗、消毒冲洗、管道标识等 5.其他：包括但不限于满足图纸、招标文件、规范及验收要求等一切相关费用 | E8: m | F8: 24.67 | G8: 20 | H8: 5.847 | I8: 0.2 | J8: =(G8+H8+I8)*$J$3 -> 0.52094 | K8: =(G8+H8+I8+J8)*$K$3 -> 0.83689011 | L8: =G8+H8+I8+J8+K8 -> 27.40483 | M8: =F8*L8 -> 676.07716
A9: 55 | B9: 31001008003 | C9: 冷水 PPR管 | D9: 1.名称：冷水 PPR管 2.规格：DN25 3.连接方式：热熔连接 4.压力试验及吹、洗要求：水压试验、水冲洗、消毒冲洗、管道标识等 5.其他：包括但不限于满足图纸、招标文件、规范及验收要求等一切相关费用 | E9: m | F9: 21.64 | G9: 20 | H9: 8.834 | I9: 0.2 | J9: =(G9+H9+I9)*$J$3 -> 0.58068 | K9: =(G9+H9+I9+J9)*$K$3 -> 0.93286242 | L9: =G9+H9+I9+J9+K9 -> 30.547542 | M9: =F9*L9 -> 661.04882
A10: 56 | B10: 31001008004 | C10: 冷水 PPR管 | D10: 1.名称：冷水 PPR管 2.规格：DN32 3.连接方式：热熔连接 4.压力试验及吹、洗要求：水压试验、水冲洗、消毒冲洗、管道标识等 5.其他：包括但不限于满足图纸、招标文件、规范及验收要求等一切相关费用 | E10: m | F10: 16.52 | G10: 20 | H10: 13.057 | I10: 0.2 | J10: =(G10+H10+I10)*$J$3 -> 0.66514 | K10: =(G10+H10+I10+J10)*$K$3 -> 1.0685474 | L10: =G10+H10+I10+J10+K10 -> 34.990687 | M10: =F10*L10 -> 578.04616
A11: 57 | B11: 31001008005 | C11: 热水 PPR管 | D11: 1.名称：热水 PPR管 2.规格：DN15 3.连接方式：热熔连接 4.压力试验及吹、洗要求：水压试验、水冲洗、消毒冲洗、管道标识等 5.其他：包括但不限于满足图纸、招标文件、规范及验收要求等一切相关费用 | E11: m | F11: 27.1 | G11: 20 | H11: 4.8685 | I11: 0.2 | J11: =(G11+H11+I11)*$J$3 -> 0.50137 | K11: =(G11+H11+I11+J11)*$K$3 -> 0.80545091 | L11: =G11+H11+I11+J11+K11 -> 26.375321 | M11: =F11*L11 -> 714.7712
A12: 58 | B12: 31001008006 | C12: 热水 PPR管 | D12: 1.名称：热水 PPR管 2.规格：DN20 3.连接方式：热熔连接 4.压力试验及吹、洗要求：水压试验、水冲洗、消毒冲洗、管道标识等 5.其他：包括但不限于满足图纸、招标文件、规范及验收要求等一切相关费用 | E12: m | F12: 23.43 | G12: 20 | H12: 6.0736 | I12: 0.2 | J12: =(G12+H12+I12)*$J$3 -> 0.525472 | K12: =(G12+H12+I12+J12)*$K$3 -> 0.84417077 | L12: =G12+H12+I12+J12+K12 -> 27.643243 | M12: =F12*L12 -> 647.68118
A13: 59 | B13: 31001008007 | C13: 热水 PPR管 | D13: 1.名称：热水 PPR管 2.规格：DN25 3.连接方式：热熔连接 4.压力试验及吹、洗要求：水压试验、水冲洗、消毒冲洗、管道标识等 5.其他：包括但不限于满足图纸、招标文件、规范及验收要求等一切相关费用 | E13: m | F13: 14.1 | G13: 20 | H13: 9.1945 | I13: 0.2 | J13: =(G13+H13+I13)*$J$3 -> 0.58789 | K13: =(G13+H13+I13+J13)*$K$3 -> 0.94444529 | L13: =G13+H13+I13+J13+K13 -> 30.926835 | M13: =F13*L13 -> 436.06838
A14: 60 | B14: 31301001002 | C14: 凿槽及修复 | D14: 1.名称：凿槽及修复 2.规格：70*70 3.部位：砖、混凝土结构综合考虑 4.其他：包括但不限于满足图纸、招标文件、规范及验收要求等一切相关费用 | E14: m | F14: 51.2 | G14: 20 | H14: 2 | I14: 1.2 | J14: =(G14+H14+I14)*$J$3 -> 0.464 | K14: =(G14+H14+I14+J14)*$K$3 -> 0.745416 | L14: =G14+H14+I14+J14+K14 -> 24.409416 | M14: =F14*L14 -> 1249.7621
A15: 61 | B15: 31001008008 | C15: UPVC排水管 | D15: 1.名称：UPVC排水管 2.规格：DN50 3.连接方式：粘接 4.压力试验及吹、洗要求：水压试验、管道标识等 5.其他：包括但不限于满足图纸、招标文件、规范及验收要求等一切相关费用 | E15: m | F15: 18.49 | G15: 20 | H15: 11.7 | I15: 0.2 | J15: =(G15+H15+I15)*$J$3 -> 0.638 | K15: =(G15+H15+I15+J15)*$K$3 -> 1.024947 | L15: =G15+H15+I15+J15+K15 -> 33.562947 | M15: =F15*L15 -> 620.57889
A16: 62 | B16: 31001008009 | C16: UPVC排水管 | D16: 1.名称：UPVC排水管 2.规格：DN75 3.连接方式：粘接 4.压力试验及吹、洗要求：水压试验、管道标识等 5.其他：包括但不限于满足图纸、招标文件、规范及验收要求等一切相关费用 | E16: m | F16: 41.77 | G16: 45 | H16: 20.4 | I16: 0.2 | J16: =(G16+H16+I16)*$J$3 -> 1.312 | K16: =(G16+H16+I16+J16)*$K$3 -> 2.107728 | L16: =G16+H16+I16+J16+K16 -> 69.019728 | M16: =F16*L16 -> 2882.954
A17: 63 | B17: 31001008010 | C17: UPVC排水管 | D17: 1.名称：UPVC排水管 2.规格：DN100 3.连接方式：粘接 4.压力试验及吹、洗要求：水压试验、管道标识等 5.其他：包括但不限于满足图纸、招标文件、规范及验收要求等一切相关费用 | E17: m | F17: 31.35 | G17: 55 | H17: 39.6 | I17: 0.2 | J17: =(G17+H17+I17)*$J$3 -> 1.896 | K17: =(G17+H17+I17+J17)*$K$3 -> 3.045924 | L17: =G17+H17+I17+J17+K17 -> 99.741924 | M17: =F17*L17 -> 3126.9093
C18: 洁具五金
A19: 64 | B19: 31003006001 | C19: 轻智能马桶 （品牌：科勒） | D19: 1.名称：轻智能马桶 2.型号规格：详见物料表 3.其他：包括但不限于满足图纸、招标文件、规范及验收要求等一切相关费用 | E19: 组 | F19: 7 | G19: 150 | H19: 4460 | I19: 12 | J19: =(G19+H19+I19)*$J$3 -> 92.44 | K19: =(G19+H19+I19+J19)*$K$3 -> 148.50486 | L19: =G19+H19+I19+J19+K19 -> 4862.9449 | M19: =F19*L19 -> 34040.614
A20: 65 | B20: 31003007001 | C20: 挂墙式自动感应小便器（品牌：科勒） | D20: 1.名称：挂墙式自动感应小便器 2.型号规格：详见物料表 3.其他：包括但不限于满足图纸、招标文件、规范及验收要求等一切相关费用 | E20: 组 | F20: 3 | G20: 150 | H20: 4385 | I20: 12 | J20: =(G20+H20+I20)*$J$3 -> 90.94 | K20: =(G20+H20+I20+J20)*$K$3 -> 146.09511 | L20: =G20+H20+I20+J20+K20 -> 4784.0351 | M20: =F20*L20 -> 14352.105
A21: 66 | B21: 31003010001 | C21: 淋浴器（品牌：科勒） | D21: 1.名称：淋浴花洒 2.型号规格：详见物料表 3.其他：包括但不限于满足图纸、招标文件、规范及验收要求等一切相关费用 | E21: 套 | F21: 2 | G21: 115 | H21: 1675 | I21: 8.5 | J21: =(G21+H21+I21)*$J$3 -> 35.97 | K21: =(G21+H21+I21+J21)*$K$3 -> 57.785805 | L21: =G21+H21+I21+J21+K21 -> 1892.2558 | M21: =F21*L21 -> 3784.5116
A22: 67 | B22: 31003008001 | C22: 拖把池及龙头（品牌：科勒） | D22: 1.名称：拖把池及冷热龙头 2.型号规格：详见物料表 3.其他：包括但不限于满足图纸、招标文件、规范及验收要求等一切相关费用 | E22: 组 | F22: 1 | G22: 115 | H22: 1045 | I22: 12 | J22: =(G22+H22+I22)*$J$3 -> 23.44 | K22: =(G22+H22+I22+J22)*$K$3 -> 37.65636 | L22: =G22+H22+I22+J22+K22 -> 1233.0964 | M22: =F22*L22 -> 1233.0964
A23: 68 | B23: 31003003001 | C23: 台下盆及龙头（品牌：TOTO龙头+科勒台下盆） | D23: 1.名称：洗手盆及冷热龙头 2.型号规格：详见物料表 3.其他：包括但不限于满足图纸、招标文件、规范及验收要求等一切相关费用 | E23: 组 | F23: 4 | G23: 115 | H23: 2040 | I23: 12 | J23: =(G23+H23+I23)*$J$3 -> 43.34 | K23: =(G23+H23+I23+J23)*$K$3 -> 69.62571 | L23: =G23+H23+I23+J23+K23 -> 2279.9657 | M23: =F23*L23 -> 9119.8628
A24: 69 | B24: 31003004001 | C24: 吧台水槽及龙头（品牌：科勒） | D24: 1.名称：吧台水槽及冷热龙头 2.型号规格：详见物料表 3.其他：包括但不限于满足图纸、招标文件、规范及验收要求等一切相关费用 | E24: 组 | F24: 1 | G24: 115 | H24: 2855 | I24: 12 | J24: =(G24+H24+I24)*$J$3 -> 59.64 | K24: =(G24+H24+I24+J24)*$K$3 -> 95.81166 | L24: =G24+H24+I24+J24+K24 -> 3137.4517 | M24: =F24*L24 -> 3137.4517
A25: 70 | B25: 31003014001 | C25: 隐藏地漏 | D25: 1.名称：隐藏地漏 2.型号规格：100*100*19mm 3.其他：包括但不限于满足图纸、招标文件、规范及验收要求等一切相关费用 | E25: 个 | F25: 14 | G25: 25 | H25: 68 | I25: 0.5 | J25: =(G25+H25+I25)*$J$3 -> 1.87 | K25: =(G25+H25+I25+J25)*$K$3 -> 3.004155 | L25: =G25+H25+I25+J25+K25 -> 98.374155 | M25: =F25*L25 -> 1377.2382
A26: 71 | B26: 31002001001 | C26: 角阀 | D26: 1.名称：角阀（热水器、洗碗机、制冰机） 2.型号规格：DN15 3.其他：包括但不限于满足图纸、招标文件、规范及验收要求等一切相关费用 | E26: 个 | F26: 5 | G26: 20 | H26: 27 | I26: 0.2 | J26: =(G26+H26+I26)*$J$3 -> 0.944 | K26: =(G26+H26+I26+J26)*$K$3 -> 1.516536 | L26: =G26+H26+I26+J26+K26 -> 49.660536 | M26: =F26*L26 -> 248.30268
A27: 72 | B27: 31003014002 | C27: 纸巾架 | D27: 1.名称：纸巾架 2.型号规格：170*120*81mm 3.其他：包括但不限于满足图纸、招标文件、规范及验收要求等一切相关费用 | E27: 个 | F27: 7 | G27: 20 | H27: 153 | I27: 0.2 | J27: =(G27+H27+I27)*$J$3 -> 3.464 | K27: =(G27+H27+I27+J27)*$K$3 -> 5.564916 | L27: =G27+H27+I27+J27+K27 -> 182.22892 | M27: =F27*L27 -> 1275.6024
A28: 73 | B28: 31003014003 | C28: 挂衣钩（品牌：科勒） | D28: 1.名称：挂衣钩 2.型号规格：详见物料表 3.其他：包括但不限于满足图纸、招标文件、规范及验收要求等一切相关费用 | E28: 个 | F28: 7 | G28: 15 | H28: 326 | I28: 0.2 | J28: =(G28+H28+I28)*$J$3 -> 6.824 | K28: =(G28+H28+I28+J28)*$K$3 -> 10.962756 | L28: =G28+H28+I28+J28+K28 -> 358.98676 | M28: =F28*L28 -> 2512.9073
B29: 税前合价 | E29: 元 | M29: =SUM(M4:M28) -> 85485.695
B30: 税金 | E30: 元 | M30: =$M$29*0.09 -> 7693.7125
B31: 含税合价 | E31: 元 | M31: =$M$29+$M$30 -> 93179.407

Sheet 空调工程
A1: 会所售楼部空调工程工程量清单
A2: 序号 | B2: 编码 | C2: 项目名称 | D2: 项目特征 | E2: 单位 | F2: 工程量 | G2: 人工费 | H2: 材料费 | I2: 机械费 | J2: 管理费 | K2: 利润 | L2: 不含税单价 | M2: 合价
J3: =电气工程!$J$3 -> 0.02 | K3: =电气工程!$K$3 -> 0.0315
B4: 单位工程
C5: 多联机空调
C6: 设备
A7: 74 | B7: 30701003001 | C7: 风管机 | D7: 1.名称：风管机 F25 2.规格：制冷量2.5kW 制热量3.2kW 风量450m3/h 机外静压30Pa 额定功率0.10kW 运转噪音≤37dB(A) 带冷凝水提升水泵 3.安装方式：吊装 4.其他：包括但不限于满足图纸、招标文件、规范及验收要求等一切相关费用 | E7: 台 | F7: 2 | G7: 148 | H7: 1181.625 | I7: 5.5 | J7: =(G7+H7+I7)*$J$3 -> 26.7025 | K7: =(G7+H7+I7+J7)*$K$3 -> 42.897566 | L7: =G7+H7+I7+J7+K7 -> 1404.7251 | M7: =F7*L7 -> 2809.4501
A8: 75 | B8: 30701003002 | C8: 风管机 | D8: 1.名称：风管机 F36 2.规格：制冷量3.6kW 制热量4.2kW 风量780m3/h 机外静压50Pa 额定功率0.10kW 运转噪音≤37dB(A) 带冷凝水提升水泵 3.安装方式：吊装 4.其他：包括但不限于满足图纸、招标文件、规范及验收要求等一切相关费用 | E8: 台 | F8: 1 | G8: 148 | H8: 1267.125 | I8: 5.5 | J8: =(G8+H8+I8)*$J$3 -> 28.4125 | K8: =(G8+H8+I8+J8)*$K$3 -> 45.644681 | L8: =G8+H8+I8+J8+K8 -> 1494.6822 | M8: =F8*L8 -> 1494.6822
A9: 76 | B9: 30701003003 | C9: 风管机 | D9: 1.名称：风管机 F40 2.规格：制冷量4.0kW 制热量4.5kW 风量780m3/h 机外静压50Pa 额定功率0.14kW 运转噪音≤37dB(A) 带冷凝水提升水泵 3.安装方式：吊装 4.其他：包括但不限于满足图纸、招标文件、规范及验收要求等一切相关费用 | E9: 台 | F9: 3 | G9: 148 | H9: 1291.875 | I9: 5.5 | J9: =(G9+H9+I9)*$J$3 -> 28.9075 | K9: =(G9+H9+I9+J9)*$K$3 -> 46.439899 | L9: =G9+H9+I9+J9+K9 -> 1520.7224 | M9: =F9*L9 -> 4562.1672
A10: 77 | B10: 30701003004 | C10: 风管机 | D10: 1.名称：风管机 F50 2.规格：制冷量5.0kW 制热量5.6kW 风量900m3/h 机外静压50Pa 额定功率0.17kW 运转噪音≤37dB(A) 带冷凝水提升水泵 3.安装方式：吊装 4.其他：包括但不限于满足图纸、招标文件、规范及验收要求等一切相关费用 | E10: 台 | F10: 3 | G10: 148 | H10: 1392.375 | I10: 5.5 | J10: =(G10+H10+I10)*$J$3 -> 30.9175 | K10: =(G10+H10+I10+J10)*$K$3 -> 49.668964 | L10: =G10+H10+I10+J10+K10 -> 1626.4615 | M10: =F10*L10 -> 4879.3844
A11: 78 | B11: 30701003005 | C11: 风管机 | D11: 1.名称：风管机 F90 2.规格：制冷量9.0kW 制热量10kW 风量1000m3/h 机外静压50Pa 额定功率0.28kW 运转噪音≤40dB(A) 带冷凝水提升水泵 3.安装方式：吊装 4.其他：包括但不限于满足图纸、招标文件、规范及验收要求等一切相关费用 | E11: 台 | F11: 1 | G11: 148 | H11: 2089.875 | I11: 5.5 | J11: =(G11+H11+I11)*$J$3 -> 44.8675 | K11: =(G11+H11+I11+J11)*$K$3 -> 72.079639 | L11: =G11+H11+I11+J11+K11 -> 2360.3221 | M11: =F11*L11 -> 2360.3221
A12: 79 | B12: 30701003006 | C12: 风管机 | D12: 1.名称：风管机 F100 2.规格：制冷量10.0kW 制热量11.2kW 风量1400m3/h 机外静压50Pa 额定功率0.28kW 运转噪音≤40dB(A) 带冷凝水提升水泵 3.安装方式：吊装 4.其他：包括但不限于满足图纸、招标文件、规范及验收要求等一切相关费用 | E12: 台 | F12: 3 | G12: 148 | H12: 2175.375 | I12: 5.5 | J12: =(G12+H12+I12)*$J$3 -> 46.5775 | K12: =(G12+H12+I12+J12)*$K$3 -> 74.826754 | L12: =G12+H12+I12+J12+K12 -> 2450.2793 | M12: =F12*L12 -> 7350.8378
A13: 80 | B13: 30701003007 | C13: 风管机 | D13: 1.名称：风管机 F112 2.规格：制冷量11.2kW 制热量12.5kW 风量1400m3/h 机外静压50Pa 额定功率0.28kW 运转噪音≤40dB(A) 带冷凝水提升水泵 3.安装方式：吊装 4.其他：包括但不限于满足图纸、招标文件、规范及验收要求等一切相关费用 | E13: 台 | F13: 8 | G13: 148 | H13: 2215.875 | I13: 5.5 | J13: =(G13+H13+I13)*$J$3 -> 47.3875 | K13: =(G13+H13+I13+J13)*$K$3 -> 76.128019 | L13: =G13+H13+I13+J13+K13 -> 2492.8905 | M13: =F13*L13 -> 19943.124
A14: 81 | B14: 30701003008 | C14: 风管机 | D14: 1.名称：风管机 F140 2.规格：制冷量14.0kW 制热量16.3kW 风量2220m3/h 机外静压90Pa 额定功率0.28kW 运转噪音≤40dB(A) 带冷凝水提升水泵 3.安装方式：吊装 4.其他：包括但不限于满足图纸、招标文件、规范及验收要求等一切相关费用 | E14: 台 | F14: 3 | G14: 148 | H14: 2337.375 | I14: 5.5 | J14: =(G14+H14+I14)*$J$3 -> 49.8175 | K14: =(G14+H14+I14+J14)*$K$3 -> 80.031814 | L14: =G14+H14+I14+J14+K14 -> 2620.7243 | M14: =F14*L14 -> 7862.1729
A15: 82 | B15: 30701003009 | C15: 风管机 | D15: 1.名称：风管机 F160 2.规格：制冷量16.0kW 制热量18.0kW 风量2300m3/h 机外静压90Pa 额定功率0.4kW 运转噪音≤45dB(A) 带冷凝水提升水泵 3.安装方式：吊装 4.其他：包括但不限于满足图纸、招标文件、规范及验收要求等一切相关费用 | E15: 台 | F15: 6 | G15: 148 | H15: 2581.125 | I15: 5.5 | J15: =(G15+H15+I15)*$J$3 -> 54.6925 | K15: =(G15+H15+I15+J15)*$K$3 -> 87.863501 | L15: =G15+H15+I15+J15+K15 -> 2877.181 | M15: =F15*L15 -> 17263.086
A16: 83 | B16: 30701003010 | C16: 多联式室外机 | D16: 1.名称：多联式室外机 L-1 2.规格：制冷量170.0kW 制热量190.0kW 风量50400m3/h 机外静压-Pa 额定功率49.2kW 运转噪音≤61dB(A) 3.安装方式：落地 4.其他：包括但不限于满足图纸、招标文件、规范及验收要求等一切相关费用 | E16: 台 | F16: 1 | G16: 480 | H16: 57866.875 | I16: 10.5 | J16: =(G16+H16+I16)*$J$3 -> 1167.1475 | K16: =(G16+H16+I16+J16)*$K$3 -> 1875.0225 | L16: =G16+H16+I16+J16+K16 -> 61399.545 | M16: =F16*L16 -> 61399.545
A17: 84 | B17: 30701003011 | C17: 多联式室外机 | D17: 1.名称：多联式室外机 L-2 2.规格：制冷量61.5kW 制热量69.0kW 风量20700m3/h 机外静压-Pa 额定功率16.4kW 运转噪音≤61dB(A) 3.安装方式：落地 4.其他：包括但不限于满足图纸、招标文件、规范及验收要求等一切相关费用 | E17: 台 | F17: 1 | G17: 480 | H17: 19043.125 | I17: 10.5 | J17: =(G17+H17+I17)*$J$3 -> 390.6725 | K17: =(G17+H17+I17+J17)*$K$3 -> 627.61537 | L17: =G17+H17+I17+J17+K17 -> 20551.913 | M17: =F17*L17 -> 20551.913
A18: 85 | B18: 30701003012 | C18: 多联式室外机 | D18: 1.名称：多联式室外机 L-3 2.规格：制冷量68.0kW 制热量75.0kW 风量21000m3/h 机外静压-Pa 额定功率18.4kW 运转噪音≤61dB(A) 3.安装方式：落地 4.其他：包括但不限于满足图纸、招标文件、规范及验收要求等一切相关费用 | E18: 台 | F18: 1 | G18: 480 | H18: 20325.625 | I18: 10.5 | J18: =(G18+H18+I18)*$J$3 -> 416.3225 | K18: =(G18+H18+I18+J18)*$K$3 -> 668.8221 | L18: =G18+H18+I18+J18+K18 -> 21901.27 | M18: =F18*L18 -> 21901.27
A19: 86 | B19: 30413013005 | C19: 空调温控面板 | D19: 1.名称：空调温控面板 2.规格：86*86mm 3.安装方式：暗装 4.其他：包括但不限于满足图纸、招标文件、规范及验收要求等一切相关费用 | E19: 套 | F19: 30 | G19: 14.4 | H19: 122.225 | I19: 0.2 | J19: =(G19+H19+I19)*$J$3 -> 2.7365 | K19: =(G19+H19+I19+J19)*$K$3 -> 4.3961872 | L19: =G19+H19+I19+J19+K19 -> 143.95769 | M19: =F19*L19 -> 4318.7306
C20: 风管
A21: 87 | B21: 30702001001 | C21: 碳钢通风管道 | D21: 1.名称：矩形风管 2.材质：镀锌薄钢板 3.厚度：0.6mm 4.长边：≤1000mm 5.其他：包括但不限于满足图纸、招标文件、规范及验收要求等一切相关费用 | E21: m2 | F21: 44.37 | G21: 28 | H21: 60.62 | I21: 2 | J21: =(G21+H21+I21)*$J$3 -> 1.8124 | K21: =(G21+H21+I21+J21)*$K$3 -> 2.9116206 | L21: =G21+H21+I21+J21+K21 -> 95.344021 | M21: =F21*L21 -> 4230.4142
A22: 88 | B22: 30702001002 | C22: 碳钢通风管道 | D22: 1.名称：矩形风管 2.材质：镀锌薄钢板 3.厚度：0.75mm 4.长边：≤1000mm 5.其他：包括但不限于满足图纸、招标文件、规范及验收要求等一切相关费用 | E22: m2 | F22: 45.59 | G22: 28 | H22: 68.345 | I22: 2 | J22: =(G22+H22+I22)*$J$3 -> 1.9669 | K22: =(G22+H22+I22+J22)*$K$3 -> 3.1598249 | L22: =G22+H22+I22+J22+K22 -> 103.47172 | M22: =F22*L22 -> 4717.2759
A23: 89 | B23: 30702001003 | C23: 碳钢通风管道 | D23: 1.名称：矩形风管 2.材质：镀锌薄钢板 3.厚度：1.0mm 4.长边：≤1250mm 5.其他：包括但不限于满足图纸、招标文件、规范及验收要求等一切相关费用 | E23: m2 | F23: 66.86 | G23: 28 | H23: 76.07 | I23: 2 | J23: =(G23+H23+I23)*$J$3 -> 2.1214 | K23: =(G23+H23+I23+J23)*$K$3 -> 3.4080291 | L23: =G23+H23+I23+J23+K23 -> 111.59943 | M23: =F23*L23 -> 7461.5378
A24: 90 | B24: 30702001004 | C24: 碳钢通风管道 | D24: 1.名称：矩形风管 2.材质：镀锌薄钢板 3.厚度：1.0mm 4.长边：≤2000mm 5.其他：包括但不限于满足图纸、招标文件、规范及验收要求等一切相关费用 | E24: m2 | F24: 279.53 | G24: 28 | H24: 76.07 | I24: 2 | J24: =(G24+H24+I24)*$J$3 -> 2.1214 | K24: =(G24+H24+I24+J24)*$K$3 -> 3.4080291 | L24: =G24+H24+I24+J24+K24 -> 111.59943 | M24: =F24*L24 -> 31195.388
A25: 91 | B25: 30703019001 | C25: 柔性接口 | D25: 1.名称：帆布软接口 2.材质：帆布 3.厚度：满足验收要求 4.其他：包括但不限于满足图纸、招标文件、规范及验收要求等一切相关费用 | E25: m2 | F25: 32.82 | G25: 24 | H25: 113.5 | I25: 2 | J25: =(G25+H25+I25)*$J$3 -> 2.79 | K25: =(G25+H25+I25+J25)*$K$3 -> 4.482135 | L25: =G25+H25+I25+J25+K25 -> 146.77213 | M25: =F25*L25 -> 4817.0615
A26: 92 | B26: 31301005001 | C26: 风管支架刷油 | D26: 1.名称：风管支架刷油 2.按图纸及规范要求 3.其他：包括但不限于以上内容，综合考虑按图纸、招标文件和规范要求而实施、完成这项工程的一切有关费用 | E26: kg | F26: 1884.04 | G26: 2 | H26: 2.175 | I26: 0.2 | J26: =(G26+H26+I26)*$J$3 -> 0.0875 | K26: =(G26+H26+I26+J26)*$K$3 -> 0.14056875 | L26: =G26+H26+I26+J26+K26 -> 4.6030688 | M26: =F26*L26 -> 8672.3656
A27: 93 | B27: 31208003001 | C27: 通风管道绝热 | D27: 1.名称：空调风管保温 2.材质：难燃级B1级橡塑保温材料，不燃A级铝箔贴面，湿阻因子≥10000，符合国家GB8624-2012中的管状绝热材料B标准 3.厚度：20mm 4.其他：包括但不限于满足图纸、招标文件、规范及验收要求等一切相关费用 | E27: m2 | F27: 469.67 | G27: 14.4 | H27: 24.5 | I27: 1 | J27: =(G27+H27+I27)*$J$3 -> 0.798 | K27: =(G27+H27+I27+J27)*$K$3 -> 1.281987 | L27: =G27+H27+I27+J27+K27 -> 41.979987 | M27: =F27*L27 -> 19716.74
A28: 94 | B28: 30704001001 | C28: 通风工程检测、调试 | D28: 1.名称：风管漏光试验、漏风试验 | E28: 系统 | F28: 1 | G28: 2880 | H28: 250 | I28: 20 | J28: =(G28+H28+I28)*$J$3 -> 63 | K28: =(G28+H28+I28+J28)*$K$3 -> 101.2095 | L28: =G28+H28+I28+J28+K28 -> 3314.2095 | M28: =F28*L28 -> 3314.2095
C29: 风管部件
A30: 95 | B30: 30703007001 | C30: 单层百叶风口 | D30: 1.名称：单层百叶风口 2.周长：≤1800mm 3.规格：600*150 4.其他：包括但不限于满足图纸、招标文件、规范及验收要求等一切相关费用 | E30: 个 | F30: 12 | G30: 20 | H30: 33.85 | I30: 0.5 | J30: =(G30+H30+I30)*$J$3 -> 1.087 | K30: =(G30+H30+I30+J30)*$K$3 -> 1.7462655 | L30: =G30+H30+I30+J30+K30 -> 57.183265 | M30: =F30*L30 -> 686.19919
A31: 96 | B31: 30703007002 | C31: 单层百叶风口 | D31: 1.名称：单层百叶风口 2.周长：≤2500mm 3.规格：800*150 4.其他：包括但不限于满足图纸、招标文件、规范及验收要求等一切相关费用 | E31: 个 | F31: 6 | G31: 20 | H31: 43.3 | I31: 0.5 | J31: =(G31+H31+I31)*$J$3 -> 1.276 | K31: =(G31+H31+I31+J31)*$K$3 -> 2.049894 | L31: =G31+H31+I31+J31+K31 -> 67.125894 | M31: =F31*L31 -> 402.75536
A32: 97 | B32: 30703007003 | C32: 单层百叶风口 | D32: 1.名称：单层百叶风口 2.周长：≤2500mm 3.规格：1000*120 4.其他：包括但不限于满足图纸、招标文件、规范及验收要求等一切相关费用 | E32: 个 | F32: 2 | G32: 22.4 | H32: 58.42 | I32: 0.5 | J32: =(G32+H32+I32)*$J$3 -> 1.6264 | K32: =(G32+H32+I32+J32)*$K$3 -> 2.6128116 | L32: =G32+H32+I32+J32+K32 -> 85.559212 | M32: =F32*L32 -> 171.11842
A33: 98 | B33: 30703007004 | C33: 单层百叶风口 | D33: 1.名称：单层百叶风口 2.周长：≤3300mm 3.规格：1400*150 4.其他：包括但不限于满足图纸、招标文件、规范及验收要求等一切相关费用 | E33: 个 | F33: 16 | G33: 20 | H33: 90.55 | I33: 0.5 | J33: =(G33+H33+I33)*$J$3 -> 2.221 | K33: =(G33+H33+I33+J33)*$K$3 -> 3.5680365 | L33: =G33+H33+I33+J33+K33 -> 116.83904 | M33: =F33*L33 -> 1869.4246
A34: 99 | B34: 30703007005 | C34: 单层百叶风口 | D34: 1.名称：单层百叶风口 2.周长：≤5200mm 3.规格：2000*150 4.其他：包括但不限于满足图纸、招标文件、规范及验收要求等一切相关费用 | E34: 个 | F34: 24 | G34: 36 | H34: 104.725 | I34: 0.5 | J34: =(G34+H34+I34)*$J$3 -> 2.8245 | K34: =(G34+H34+I34+J34)*$K$3 -> 4.5375593 | L34: =G34+H34+I34+J34+K34 -> 148.58706 | M34: =F34*L34 -> 3566.0894
A35: 100 | B35: 30703021001 | C35: 连通管 | D35: 1.名称：连通管 2.规格：1200(L)*300(W)*300(H) 3.其他：包括但不限于满足图纸、招标文件、规范及验收要求等一切相关费用 | E35: 个 | F35: 2 | G35: 32 | H35: 131.25 | I35: 5 | J35: =(G35+H35+I35)*$J$3 -> 3.365 | K35: =(G35+H35+I35+J35)*$K$3 -> 5.4058725 | L35: =G35+H35+I35+J35+K35 -> 177.02087 | M35: =F35*L35 -> 354.04174
A36: 101 | B36: 30703021002 | C36: 连通管 | D36: 1.名称：连通管 2.规格：1200(L)*250(W)*300(H) 3.其他：包括但不限于满足图纸、招标文件、规范及验收要求等一切相关费用 | E36: 个 | F36: 16 | G36: 30.4 | H36: 119 | I36: 5 | J36: =(G36+H36+I36)*$J$3 -> 3.088 | K36: =(G36+H36+I36+J36)*$K$3 -> 4.960872 | L36: =G36+H36+I36+J36+K36 -> 162.44887 | M36: =F36*L36 -> 2599.182
A37: 102 | B37: 30703021003 | C37: 连通管 | D37: 1.名称：连通管 2.规格：2200(L)*250(W)*300(H) 3.其他：包括但不限于满足图纸、招标文件、规范及验收要求等一切相关费用 | E37: 个 | F37: 24 | G37: 44 | H37: 230 | I37: 6 | J37: =(G37+H37+I37)*$J$3 -> 5.6 | K37: =(G37+H37+I37+J37)*$K$3 -> 8.9964 | L37: =G37+H37+I37+J37+K37 -> 294.5964 | M37: =F37*L37 -> 7070.3136
C38: 水管
A39: 103 | B39: 31001005001 | C39: 铜管 | D39: 1.名称：紫铜管 2.规格：φ6.4 3.厚度：0.8mm 4.连接方式：钎焊连结 5.其他：包括但不限于满足图纸、招标文件、规范及验收要求等一切相关费用 | E39: m | F39: 37.15 | G39: 7.712 | H39: 10.18 | I39: 0.2 | J39: =(G39+H39+I39)*$J$3 -> 0.36184 | K39: =(G39+H39+I39+J39)*$K$3 -> 0.58129596 | L39: =G39+H39+I39+J39+K39 -> 19.035136 | M39: =F39*L39 -> 707.1553
A40: 104 | B40: 31001005002 | C40: 铜管 | D40: 1.名称：紫铜管 2.规格：φ9.5 3.厚度：0.8mm 4.连接方式：钎焊连结 5.其他：包括但不限于满足图纸、招标文件、规范及验收要求等一切相关费用 | E40: m | F40: 95.8 | G40: 11.432 | H40: 17.47 | I40: 0.2 | J40: =(G40+H40+I40)*$J$3 -> 0.58204 | K40: =(G40+H40+I40+J40)*$K$3 -> 0.93504726 | L40: =G40+H40+I40+J40+K40 -> 30.619087 | M40: =F40*L40 -> 2933.3086
...
