Workbook
Name cap: #REF!
Name cola: #REF!
Name colb: #REF!
Name lap: [1]General!$B$2:$G$9
Name 结果: EVALUAT=evaluateE(#REF!)
Name AA: EVALUATE(SUBSTITUTE(SUBSTITUTE(#REF!,"【","*ISTEXT(""【"),"】","】"")"))
Name CC: EVALUATE('[3]BQ7.2（A1-2G户型）'!XFD1)
Name DD: EVALUATE('[3]BQ7.3（A2-2户型）'!XFD1)
Name EE: EVALUATE('[3]BQ7.4（A4-1G户型）'!XFD1)
Name FF: EVALUATE('[3]BQ7.5（A4-2户型）'!XFD1)
Name cap: #REF!
Name cola: #REF!
Name colb: #REF!
Name 结果: EVALUAT=evaluateE(#REF!)
Name AA: EVALUATE(SUBSTITUTE(SUBSTITUTE(#REF!,"【","*ISTEXT(""【"),"】","】"")"))
Name cap: #REF!
Name cola: #REF!
Name colb: #REF!
Name lap: [2]General!$B$2:$G$9
Name 结果: EVALUAT=evaluateE(#REF!)
Name AA: EVALUATE(SUBSTITUTE(SUBSTITUTE(#REF!,"【","*ISTEXT(""【"),"】","】"")"))
Name cap: #REF!
Name cola: #REF!
Name colb: #REF!
Name lap: [2]General!$B$2:$G$9
Name 结果: EVALUAT=evaluateE(#REF!)
Name AA: EVALUATE(SUBSTITUTE(SUBSTITUTE(#REF!,"【","*ISTEXT(""【"),"】","】"")"))
Name 结果: EVALUAT=evaluateE(#REF!)
Name aaaaaa: #REF!
Name aaaaaaaa: #REF!
Name aaaaaaaaa: [5]MOHKG!#REF!
Name cr: [6]main!$B$8
Name data: [7]coa!$1:$1048576
Name gg: [8]钢材单重!$A496:$A1048574
Name LLL: #REF!
Name page1: #N/A
Name page10: #REF!
Name page11: #REF!
Name page2: #REF!
Name page3: #REF!
Name page4: #REF!
Name page5: #REF!
Name page6: #REF!
Name page7: #REF!
Name Room2Br: [5]MOHKG!#REF!
Name WTP: #REF!
Name 北京中远广田装饰工程有限公司: #REF!
Name 橱柜报价清单工程量反馈: #REF!
Name 建筑面积: #REF!
Name 时: #REF!
Name 结果: EVALUAT=evaluateE(#REF!)
Name cap: #REF!
Name cola: #REF!
Name colb: #REF!
Name 结果: EVALUAT=evaluateE(#REF!)
Name AA: EVALUATE(SUBSTITUTE(SUBSTITUTE(#REF!,"【","*ISTEXT(""【"),"】","】"")"))
Name CC: EVALUATE('[4]BQ7.2（A1-2G户型）'!XFD1)
Name DD: EVALUATE('[4]BQ7.3（A2-2户型）'!XFD1)
Name EE: EVALUATE('[4]BQ7.4（A4-1G户型）'!XFD1)
Name FF: EVALUATE('[4]BQ7.5（A4-2户型）'!XFD1)

Sheet 汇总 
A1: 岁宝壹品苑一期
A2: C栋32层会所精装修工程
A3: 投标价目总计
A6: 序号 | C6: 说明 | E6: 总价
C10: 投标价目总计
B12: 一、 | C12: 开办费 | E12: =+一、开办费明细!C63 -> 0
B14: 二、 | C14: 实体工程费
C15: 01号清单 精装工程 | E15: =+'二、01 精装清单'!P400 -> 0
C16: 02号清单 室内机电 | E16: =+二、02机电清单!N224 -> 0
C17: 03号清单 结构及其他零星工程 | E17: =+二、03结构及其他零星工程清单!P45 -> 0
C18: 04厨房设备供货安装工程 | E18: =+二、04厨房设备供货安装工程清单!O41 -> 0
C19: 05干蒸房工程 | E19: =+二、05干蒸房工程量清单!I36 -> 0
C20: 06湿蒸房工程 | E20: =+二、06湿蒸房工程量清单!I31 -> 0
C22: 投标总计： | D22: (人民币/元)
B23: （大写） | C23: =IF(E23<0,"负","")&SUBSTITUTE(SUBSTITUTE(TEXT(TRUNC(FIXED(ABS(E23))),"[>0][dbnum2];;")&TEXT(RIGHT(FIXED(E23),2),"元[dbnum2]0角0分;;"&IF(ABS(E23)>1%,"元整",)),"零角",IF(ABS(E23)<1,,"零")),"零分","整") | E23: =SUM(E12:E22) -> 0
C28: 投标人法人代表签章
C31: 日期

Sheet 编制说明 
A1: 岁宝壹品苑一期
A2: C栋32层会所精装修工程
A3: 编制说明
A4: 序号 | B4: 编制说明
A5: 1 | B5: 本工程量清单由开办费项目、实物工程量项目组成。
A6: 2 | B6: 本工程量清单应与承包范围、工程施工技术要求、合同图纸、工程量清单计算规则等其他合同文本一并理解，并不能视为完整无缺的，合同承包范围应以合同文本、图纸及工程施工技术要求为准。
A7: 3 | B7: 综合单价已包含施工现场物业管理要求、工程施工技术要求的内容、满足图纸、规范及招标文件等一切要求。
A8: 4 | B8: 对于适宜于在实物工程量的单价内考虑的费用，则可计算在工程单价内，对于适宜独立计算的费用，则可计算／投价于工程量清单中“开办费”中的对应项目内。对于任何没有填上价款的项目，其所需费用在本合同中视作已包括在开办费的价款或工程单价中，不再另外计取费用。
A9: 5 | B9: 开办费项目旨在说明工程的概况及发包人／设计单位对本工程的基本要求，以便让承包人对整个项目以及各种可能影响单价的因素有一个全面的了解。所以承包人在投标时及以后作为承包人在施工时应注意及遵从本部分的综合要求。
A10: 6 | B10: 对于完成以下项目所须采取之任何必要的措施（包括但不限于材料检验检测、安全施工、文明施工措施及取得政府相关部门的批准等）或须用到的任何机械设备、脚手架、临时水电等的费用均应包含于投标总价内；承包人可在本工程量清单第一章“开办费”的相应项目内对本工程须采取的措施项目整项报价；对于“开办费”项目中未开列的措施项目，承包人可自行增补项目补充报价亦可在本章清单中的对应项目之综合单价内报价。
A11: 7 | B11: “开办费”在本合同中是一项固定的费用，除非日后发包人指令导致开办费项目某项整项取消外，无论实物工程量有否变化，该费用不能更改。同时，“开办费”适用于本合同内的所有工作内容，承包人所投的单价视为可应用在所有相同的工作项目上以及合同范围内的一切工程变更中。
A12: 8 | B12: 实物工程量清单的单价，须同时满足承包范围、图纸及工程施工技术要求的要求，并将工程量计算规则及单价说明中的各项费用包含在内。未填报的单价和合价，视为已包括在工程量清单的其他单价和合价中。
A13: 9 | B13: 除特别注明“XXX材料甲供”外，为完成项目所需的材料（包括所必须的辅助材料）均由承包人供货及安装。
A14: 10 | B14: 当工程量清单数量单位中出现‘项'字样，则该项的造价由承包人承担风险，结算时不作调整，若此项目没有报价，视为已包括在其它项目单价中。
A15: 11 | B15: 实物工程量项目除厨房设备供货安装工程、干蒸房工程、湿蒸房工程为固定总价包干外，其他清单为暂定工程量，承包人不能修改其已作暂定数量，该类项目将按所报的单价和今后实际发生的数量来结算费用。
A16: 12 | B16: 工程量清单之计价格式中的任何内容不得删除或涂改，补充项目应于规定的页面上填写。
... A21: 17 | B21: 二次消防改造工程为暂定工程量，现场实际实施时，需充分考虑保护性拆除并利旧安装的方案，最终方案以甲方批复为准，承包人不得以任何理由拒绝甲方批复的改造方案。

Sheet 一、开办费明细
A1: 岁宝壹品苑一期
A2: C栋32层会所精装修工程
A3: 第一章 - 开办费
A5: 序号 | B5: 项目名称 | C5: 合价
A7: 1 | B7: 安全施工
A9: 2 | B9: 文明施工及现场标识 | C9: =SUM(C10:C16) -> 0
A10: 2.01 | B10: 垃圾清理与消纳费用
A11: 2.02 | B11: 竣工清理费用
A12: 2.03 | B12: 防止鼠蚁、蚊虫滋生费用（含白蚁防治）
A13: 2.04 | B13: 现场标识布置与维护费用
A14: 2.05 | B14: 其他安全文明施工环境创建与保持费用（如有）
A15: 2.06 | B15: 施工现场配备适量质量合格的消防设备/设施费用
A16: 2.07 | B16: 配备1名专职保洁人员，负责日常清扫、垃圾归集、扬尘及污渍清理、卫生巡查和整改维护
A18: 3 | B18: 冬雨季、严寒/热及夜间下施工费用
A20: 4 | B20: 临时设施 | C20: =SUM(C21:C23) -> 0
A21: 4.01 | B21: 承包人的办公室修建与维护费用
A22: 4.02 | B22: 工人生活区修建及维护费用
A23: 4.03 | B23: 临时围护设施（含电梯洞口挡水槛制作及拆除等）
A25: 5 | B25: 脚手架费用
A27: 6 | B27: 保护、保安 | C27: =C28+C29 -> 0
A28: 6.01 | B28: 对成品、半成品及工程材料的保护费用
A29: 6.02 | B29: 用于施工的正式电梯费用、垂直运输费用（司机费用、日常维修维保费用、电梯使用产生电费）
A31: 7 | B31: 保函、保险 | C31: =SUM(C32:C33) -> 0
A32: 7.01 | B32: 履约保函费用
A33: 7.02 | B33: 施工人员意外伤害保险费用
A35: 8 | B35: 检验、检测 | C35: =SUM(C36:C37) -> 0
A36: 8.01 | B36: 承包人供应材料的检测费用
A37: 8.02 | B37: 发包人供应材料的检测费用
A39: 9 | B39: 其他 | C39: =SUM(C40:C50) -> 0
A40: 9.01 | B40: 水电费用
A41: 9.02 | B41: 电梯及其他公共设备的使用费和电费
A42: 9.03 | B42: 协调管理费用
A43: 9.04 | B43: 甲分包单位配合管理费
A44: 9.05 | B44: 甲供材配合管理费
A45: 9.06 | B45: 出入证工本费、消防改管放水费等物业管求费用
A46: 9.07 | B46: 其他测评费用
A47: 9.08 | B47: 材料设备保护性拆除后的保管仓储费用
A48: 9.09 | B48: 按现状接收后涉及的为满足施工图纸、设计效果、技术要求、验收标准及交付标准所需的墙面找平、墙面空鼓修复、管线开孔、封堵、补强、吊洞
A49: 9.1 | B49: 与幕墙饰面、门窗接驳口收边收口（含打胶、同原建筑幕墙颜色的铝板收边收口）
A50: 9.11 | B50: 按现状接收后原单位遗漏的垃圾清运（30-32层）
...

Sheet 二、01 精装清单
A1: 岁宝壹品苑一期
A2: C栋32层会所精装修工程
A3: 第二章 - 01号清单 精装清单
A4: 分部分项工程量清单
A5: 序号 | B5: 工程名称 | C5: 工作内容 | D5: 图片 | E5: 计算规则 | F5: 单位 | G5: 工程量 | H5: 综合单价构成（元） | O5: 综合单价 (含税) （元） | P5: 合价 (含税)（元）
H6: 主材费 （含损耗） | I6: 辅材费 | J6: 人工费 | K6: 机械费 | L6: 管理费 | M6: 利润 | N6: 税金
N7: 0.09
A8: 一 | B8: 装饰工程
A9: （一） | B9: 地面工程 | C9: 地面工程包含但不仅限于清理基层、找平、结合层/粘结层，二次搬运，现场修边切割和开洞，铺设石材饰面，填缝、擦缝、养护。清理净面等一切所需工作内容；
B10: 接待前厅
A11: =IF(G11="","",COUNT(A$1:A10)+1) -> 1 | B11: 石材ST-101B 厚度：20mm （含门槛石） | C11: 1、面层石材铺贴，石材专用粘结剂，同色填缝，石材乙供； 2、1:2.5干硬性防水水泥砂浆找平，找平厚度20mm及以内； 3、详见图纸； 4、包含但不限于编制说明、图纸、技术要求中的相关内容及完成该项目的一切所需； | D11: / | E11: 按设计图示尺寸以投影面积计算 | F11: m2 | G11: =46.56+1.36-G12 -> 46.494 | L11: =(H11+I11+J11+K11)*$L$7 -> 0 | M11: =(H11+I11+J11+K11+L11)*$M$7 -> 0 | N11: =(H11+I11+J11+K11+L11+M11)*$N$7 -> 0 | O11: =H11+I11+J11+K11+L11+M11+N11 -> 0 | P11: =G11*O11 -> 0
A12: =IF(G12="","",COUNT(A$1:A11)+1) -> 2 | B12: 黑色砾石地面 | C12: 1、面层黑色砾石，含5mm实心古铜条； 2、1:2.5干硬性防水水泥砂浆找平，找平厚度20mm及以内； 3、详见图纸； 4、包含但不限于编制说明、图纸、技术要求中的相关内容及完成该项目的一切所需； | D12: / | E12: 按设计图示尺寸以投影面积计算 | F12: m2 | G12: 1.426 | L12: =(H12+I12+J12+K12)*$L$7 -> 0 | M12: =(H12+I12+J12+K12+L12)*$M$7 -> 0 | N12: =(H12+I12+J12+K12+L12+M12)*$N$7 -> 0 | O12: =H12+I12+J12+K12+L12+M12+N12 -> 0 | P12: =G12*O12 -> 0
A13: =IF(G13="","",COUNT(A$1:A12)+1) -> 3 | B13: 陶粒回填 | C13: 1.找平层：综合各类混凝土类型、强度等级及找平厚度； 2.基层清理、界面剂； 3.包含但不限于编制说明、图纸、技术要求中的相关内容及完成该项目的一切所需； 4.需进行三方现场收方，否则不予计取。 | D13: / | E13: 按设计图示尺寸以体积计算 | F13: m³ | G13: =+(G11+G12)*0.2 -> 9.584 | L13: =(H13+I13+J13+K13)*$L$7 -> 0 | M13: =(H13+I13+J13+K13+L13)*$M$7 -> 0 | N13: =(H13+I13+J13+K13+L13+M13)*$N$7 -> 0 | O13: =H13+I13+J13+K13+L13+M13+N13 -> 0 | P13: =G13*O13 -> 0
A14: =IF(G14="","",COUNT(A$1:A13)+1) -> 4 | B14: 石材结晶处理 | C14: 石材打磨结晶处理 | E14: 按设计图示尺寸以投影面积计算 | F14: m2 | G14: =+G11 -> 46.494 | L14: =(H14+I14+J14+K14)*$L$7 -> 0 | M14: =(H14+I14+J14+K14+L14)*$M$7 -> 0 | N14: =(H14+I14+J14+K14+L14+M14)*$N$7 -> 0 | O14: =H14+I14+J14+K14+L14+M14+N14 -> 0 | P14: =G14*O14 -> 0
A15: =IF(G15="","",COUNT(A$1:A14)+1) | B15: 走廊及电梯厅
A16: =IF(G16="","",COUNT(A$1:A15)+1) -> 5 | B16: 石材ST-101B 厚度：20mm （含门槛石） | C16: 1、面层石材铺贴，石材专用粘结剂，同色填缝，石材乙供； 2、1:2.5干硬性防水水泥砂浆找平，找平厚度20mm及以内； 3、详见图纸； 4、包含但不限于编制说明、图纸、技术要求中的相关内容及完成该项目的一切所需； | D16: / | E16: 按设计图示尺寸以投影面积计算 | F16: m2 | G16: =141.05-1.31*1.65-4.36 -> 134.5285 | H16: =+$H$11 -> 0 | I16: =+$I$11 -> 0 | J16: =+$J$11 -> 0 | K16: =+$K$11 -> 0 | L16: =(H16+I16+J16+K16)*$L$7 -> 0 | M16: =(H16+I16+J16+K16+L16)*$M$7 -> 0 | N16: =(H16+I16+J16+K16+L16+M16)*$N$7 -> 0 | O16: =H16+I16+J16+K16+L16+M16+N16 -> 0 | P16: =G16*O16 -> 0
A17: =IF(G17="","",COUNT(A$1:A16)+1) -> 6 | B17: 陶粒回填 | C17: 1.找平层：综合各类混凝土类型、强度等级及找平厚度； 2.基层清理、界面剂； 3.包含但不限于编制说明、图纸、技术要求中的相关内容及完成该项目的一切所需； 4.需进行三方现场收方，否则不予计取。 | D17: / | E17: 按设计图示尺寸以体积计算 | F17: m³ | G17: =+(G16+G18)*0.2 -> 28.1877 | H17: =+H13 -> 0 | I17: =+I13 -> 0 | J17: =+J13 -> 0 | K17: =+K13 -> 0 | L17: =(H17+I17+J17+K17)*$L$7 -> 0 | M17: =(H17+I17+J17+K17+L17)*$M$7 -> 0 | N17: =(H17+I17+J17+K17+L17+M17)*$N$7 -> 0 | O17: =H17+I17+J17+K17+L17+M17+N17 -> 0 | P17: =G17*O17 -> 0
A18: =IF(G18="","",COUNT(A$1:A17)+1) -> 7 | B18: 瓷砖地面T-101 | C18: 1、面层瓷砖铺贴，专用粘结剂，同色填缝； 2、1:2.5干硬性防水水泥砂浆找平，找平厚度20mm及以内； 3、详图纸； 4、包含但不限于编制说明、图纸、技术要求中的相关内容及完成该项目的一切所需； | D18: / | E18: 按设计图示尺寸以展开面积计算 | F18: m2 | G18: =2.05+4.36 -> 6.41 | L18: =(H18+I18+J18+K18)*$L$7 -> 0 | M18: =(H18+I18+J18+K18+L18)*$M$7 -> 0 | N18: =(H18+I18+J18+K18+L18+M18)*$N$7 -> 0 | O18: =H18+I18+J18+K18+L18+M18+N18 -> 0 | P18: =G18*O18 -> 0
A19: =IF(G19="","",COUNT(A$1:A18)+1) -> 8 | B19: 石材结晶处理 | C19: 石材打磨结晶处理 | E19: 按设计图示尺寸以投影面积计算 | F19: m2 | G19: =+G16 -> 134.5285 | H19: =+H14 -> 0 | I19: =+I14 -> 0 | J19: =+J14 -> 0 | K19: =+K14 -> 0 | L19: =(H19+I19+J19+K19)*$L$7 -> 0 | M19: =(H19+I19+J19+K19+L19)*$M$7 -> 0 | N19: =(H19+I19+J19+K19+L19+M19)*$N$7 -> 0 | O19: =H19+I19+J19+K19+L19+M19+N19 -> 0 | P19: =G19*O19 -> 0
A20: =IF(G20="","",COUNT(A$1:A19)+1) | B20: 茶室/棋牌室1
A21: =IF(G21="","",COUNT(A$1:A20)+1) -> 9 | B21: 石材ST-101B 厚度：20mm （含门槛石） | C21: 1、面层石材铺贴，石材专用粘结剂，同色填缝，石材乙供； 2、1:2.5干硬性防水水泥砂浆找平，找平厚度20mm及以内； 3、详见图纸； 4、包含但不限于编制说明、图纸、技术要求中的相关内容及完成该项目的一切所需； | D21: / | E21: 按设计图示尺寸以投影面积计算 | F21: m2 | G21: =16.59 -> 16.59 | H21: =+$H$11 -> 0 | I21: =+$I$11 -> 0 | J21: =+$J$11 -> 0 | K21: =+$K$11 -> 0 | L21: =(H21+I21+J21+K21)*$L$7 -> 0 | M21: =(H21+I21+J21+K21+L21)*$M$7 -> 0 | N21: =(H21+I21+J21+K21+L21+M21)*$N$7 -> 0 | O21: =H21+I21+J21+K21+L21+M21+N21 -> 0 | P21: =G21*O21 -> 0
A22: =IF(G22="","",COUNT(A$1:A21)+1) -> 10 | B22: 瓷砖地面T-101 | C22: 1、面层瓷砖铺贴，专用粘结剂，同色填缝； 2、1:2.5干硬性防水水泥砂浆找平，找平厚度20mm及以内； 3、详图纸； 4、包含但不限于编制说明、图纸、技术要求中的相关内容及完成该项目的一切所需； | D22: / | E22: 按设计图示尺寸以展开面积计算 | F22: m2 | G22: 4.33 | H22: =+$H$18 -> 0 | I22: =+$I$18 -> 0 | J22: =+$J$18 -> 0 | K22: =+$K$18 -> 0 | L22: =(H22+I22+J22+K22)*$L$7 -> 0 | M22: =(H22+I22+J22+K22+L22)*$M$7 -> 0 | N22: =(H22+I22+J22+K22+L22+M22)*$N$7 -> 0 | O22: =H22+I22+J22+K22+L22+M22+N22 -> 0 | P22: =G22*O22 -> 0
A23: =IF(G23="","",COUNT(A$1:A22)+1) -> 11 | B23: 陶粒回填 | C23: 1.找平层：综合各类混凝土类型、强度等级及找平厚度； 2.基层清理、界面剂； 3.包含但不限于编制说明、图纸、技术要求中的相关内容及完成该项目的一切所需； 4.需进行三方现场收方，否则不予计取。 | D23: / | E23: 按设计图示尺寸以体积计算 | F23: m³ | G23: =+G21*0.2+G22*0.018 -> 3.39594 | H23: =+H13 -> 0 | I23: =+I13 -> 0 | J23: =+J13 -> 0 | K23: =+K13 -> 0 | L23: =(H23+I23+J23+K23)*$L$7 -> 0 | M23: =(H23+I23+J23+K23+L23)*$M$7 -> 0 | N23: =(H23+I23+J23+K23+L23+M23)*$N$7 -> 0 | O23: =H23+I23+J23+K23+L23+M23+N23 -> 0 | P23: =G23*O23 -> 0
A24: =IF(G24="","",COUNT(A$1:A23)+1) -> 12 | B24: 石材结晶处理 | C24: 石材打磨结晶处理 | E24: 按设计图示尺寸以投影面积计算 | F24: m2 | G24: =+G21 -> 16.59 | H24: =+H14 -> 0 | I24: =+I14 -> 0 | J24: =+J14 -> 0 | K24: =+K14 -> 0 | L24: =(H24+I24+J24+K24)*$L$7 -> 0 | M24: =(H24+I24+J24+K24+L24)*$M$7 -> 0 | N24: =(H24+I24+J24+K24+L24+M24)*$N$7 -> 0 | O24: =H24+I24+J24+K24+L24+M24+N24 -> 0 | P24: =G24*O24 -> 0
A25: =IF(G25="","",COUNT(A$1:A24)+1) | B25: 茶室/棋牌室2
A26: =IF(G26="","",COUNT(A$1:A25)+1) -> 13 | B26: 石材ST-101B 厚度：20mm （含门槛石） | C26: 1、面层石材铺贴，石材专用粘结剂，同色填缝，石材乙供； 2、1:2.5干硬性防水水泥砂浆找平，找平厚度20mm及以内； 3、详见图纸； 4、包含但不限于编制说明、图纸、技术要求中的相关内容及完成该项目的一切所需； | D26: / | E26: 按设计图示尺寸以投影面积计算 | F26: m2 | G26: =15.06 -> 15.06 | H26: =+$H$11 -> 0 | I26: =+$I$11 -> 0 | J26: =+$J$11 -> 0 | K26: =+$K$11 -> 0 | L26: =(H26+I26+J26+K26)*$L$7 -> 0 | M26: =(H26+I26+J26+K26+L26)*$M$7 -> 0 | N26: =(H26+I26+J26+K26+L26+M26)*$N$7 -> 0 | O26: =H26+I26+J26+K26+L26+M26+N26 -> 0 | P26: =G26*O26 -> 0
A27: =IF(G27="","",COUNT(A$1:A26)+1) -> 14 | B27: 瓷砖地面T-101 | C27: 1、面层瓷砖铺贴，专用粘结剂，同色填缝； 2、1:2.5干硬性防水水泥砂浆找平，找平厚度20mm及以内； 3、详图纸； 4、包含但不限于编制说明、图纸、技术要求中的相关内容及完成该项目的一切所需； | D27: / | E27: 按设计图示尺寸以展开面积计算 | F27: m2 | G27: 3.55 | H27: =+$H$18 -> 0 | I27: =+$I$18 -> 0 | J27: =+$J$18 -> 0 | K27: =+$K$18 -> 0 | L27: =(H27+I27+J27+K27)*$L$7 -> 0 | M27: =(H27+I27+J27+K27+L27)*$M$7 -> 0 | N27: =(H27+I27+J27+K27+L27+M27)*$N$7 -> 0 | O27: =H27+I27+J27+K27+L27+M27+N27 -> 0 | P27: =G27*O27 -> 0
A28: =IF(G28="","",COUNT(A$1:A27)+1) -> 15 | B28: 陶粒回填 | C28: 1.找平层：综合各类混凝土类型、强度等级及找平厚度； 2.基层清理、界面剂； 3.包含但不限于编制说明、图纸、技术要求中的相关内容及完成该项目的一切所需； 4.需进行三方现场收方，否则不予计取。 | D28: / | E28: 按设计图示尺寸以体积计算 | F28: m³ | G28: =+G26*0.2+G27*0.18 -> 3.651 | H28: =+H13 -> 0 | I28: =+I13 -> 0 | J28: =+J13 -> 0 | K28: =+K13 -> 0 | L28: =(H28+I28+J28+K28)*$L$7 -> 0 | M28: =(H28+I28+J28+K28+L28)*$M$7 -> 0 | N28: =(H28+I28+J28+K28+L28+M28)*$N$7 -> 0 | O28: =H28+I28+J28+K28+L28+M28+N28 -> 0 | P28: =G28*O28 -> 0
A29: =IF(G29="","",COUNT(A$1:A28)+1) -> 16 | B29: 石材结晶处理 | C29: 石材打磨结晶处理 | E29: 按设计图示尺寸以投影面积计算 | F29: m2 | G29: =+G26 -> 15.06 | H29: =+H14 -> 0 | I29: =+I14 -> 0 | J29: =+J14 -> 0 | K29: =+K14 -> 0 | L29: =(H29+I29+J29+K29)*$L$7 -> 0 | M29: =(H29+I29+J29+K29+L29)*$M$7 -> 0 | N29: =(H29+I29+J29+K29+L29+M29)*$N$7 -> 0 | O29: =H29+I29+J29+K29+L29+M29+N29 -> 0 | P29: =G29*O29 -> 0
A30: =IF(G30="","",COUNT(A$1:A29)+1) | B30: 多功能室
A31: =IF(G31="","",COUNT(A$1:A30)+1) -> 17 | B31: 石材ST-101B 厚度：20mm （含门槛石） | C31: 1、面层石材铺贴，石材专用粘结剂，同色填缝，石材乙供； 2、1:2.5干硬性防水水泥砂浆找平，找平厚度20mm及以内； 3、详见图纸； 4、包含但不限于编制说明、图纸、技术要求中的相关内容及完成该项目的一切所需； | D31: / | E31: 按设计图示尺寸以投影面积计算 | F31: m2 | G31: =16.23 -> 16.23 | H31: =+$H$11 -> 0 | I31: =+$I$11 -> 0 | J31: =+$J$11 -> 0 | K31: =+$K$11 -> 0 | L31: =(H31+I31+J31+K31)*$L$7 -> 0 | M31: =(H31+I31+J31+K31+L31)*$M$7 -> 0 | N31: =(H31+I31+J31+K31+L31+M31)*$N$7 -> 0 | O31: =H31+I31+J31+K31+L31+M31+N31 -> 0 | P31: =G31*O31 -> 0
A32: =IF(G32="","",COUNT(A$1:A31)+1) -> 18 | B32: 瓷砖地面T-101 | C32: 1、面层瓷砖铺贴，专用粘结剂，同色填缝； 2、1:2.5干硬性防水水泥砂浆找平，找平厚度20mm及以内； 3、详图纸； 4、包含但不限于编制说明、图纸、技术要求中的相关内容及完成该项目的一切所需； | D32: / | E32: 按设计图示尺寸以展开面积计算 | F32: m2 | G32: 3.34 | H32: =+$H$18 -> 0 | I32: =+$I$18 -> 0 | J32: =+$J$18 -> 0 | K32: =+$K$18 -> 0 | L32: =(H32+I32+J32+K32)*$L$7 -> 0 | M32: =(H32+I32+J32+K32+L32)*$M$7 -> 0 | N32: =(H32+I32+J32+K32+L32+M32)*$N$7 -> 0 | O32: =H32+I32+J32+K32+L32+M32+N32 -> 0 | P32: =G32*O32 -> 0
A33: =IF(G33="","",COUNT(A$1:A32)+1) -> 19 | B33: 陶粒回填 | C33: 1.找平层：综合各类混凝土类型、强度等级及找平厚度； 2.基层清理、界面剂； 3.包含但不限于编制说明、图纸、技术要求中的相关内容及完成该项目的一切所需； 4.需进行三方现场收方，否则不予计取。 | D33: / | E33: 按设计图示尺寸以体积计算 | F33: m³ | G33: =+G31*0.2+G32*0.18 -> 3.8472 | H33: =+H13 -> 0 | I33: =+I13 -> 0 | J33: =+J13 -> 0 | K33: =+K13 -> 0 | L33: =(H33+I33+J33+K33)*$L$7 -> 0 | M33: =(H33+I33+J33+K33+L33)*$M$7 -> 0 | N33: =(H33+I33+J33+K33+L33+M33)*$N$7 -> 0 | O33: =H33+I33+J33+K33+L33+M33+N33 -> 0 | P33: =G33*O33 -> 0
A34: =IF(G34="","",COUNT(A$1:A33)+1) -> 20 | B34: 石材结晶处理 | C34: 石材打磨结晶处理 | E34: 按设计图示尺寸以投影面积计算 | F34: m2 | G34: =+G31 -> 16.23 | H34: =+H14 -> 0 | I34: =+I14 -> 0 | J34: =+J14 -> 0 | K34: =+K14 -> 0 | L34: =(H34+I34+J34+K34)*$L$7 -> 0 | M34: =(H34+I34+J34+K34+L34)*$M$7 -> 0 | N34: =(H34+I34+J34+K34+L34+M34)*$N$7 -> 0 | O34: =H34+I34+J34+K34+L34+M34+N34 -> 0 | P34: =G34*O34 -> 0
A35: =IF(G35="","",COUNT(A$1:A34)+1) | B35: 男/女更衣室
A36: =IF(G36="","",COUNT(A$1:A35)+1) -> 21 | B36: 石材ST-101B 厚度：20mm （含门槛石） | C36: 1、面层石材铺贴，石材专用粘结剂，同色填缝，石材乙供； 2、1:2.5干硬性防水水泥砂浆找平，找平厚度20mm及以内； 3、详见图纸； 4、包含但不限于编制说明、图纸、技术要求中的相关内容及完成该项目的一切所需； | D36: / | E36: 按设计图示尺寸以投影面积计算 | F36: m2 | G36: =25.61+0.238+25.35-0.99 -> 50.208 | H36: =+$H$11 -> 0 | I36: =+$I$11 -> 0 | J36: =+$J$11 -> 0 | K36: =+$K$11 -> 0 | L36: =(H36+I36+J36+K36)*$L$7 -> 0 | M36: =(H36+I36+J36+K36+L36)*$M$7 -> 0 | N36: =(H36+I36+J36+K36+L36+M36)*$N$7 -> 0 | O36: =H36+I36+J36+K36+L36+M36+N36 -> 0 | P36: =G36*O36 -> 0
A37: =IF(G37="","",COUNT(A$1:A36)+1) -> 22 | B37: 石材ST-101A(水洗面） 厚度：20mm | C37: 1、面层石材铺贴，石材专用粘结剂，同色填缝，石材乙供； 2、1:2.5干硬性防水水泥砂浆找平，找平厚度20mm及以内； 3、详见图纸； 4、包含但不限于编制说明、图纸、技术要求中的相关内容及完成该项目的一切所需； | D37: / | E37: 按设计图示尺寸以投影面积计算 | F37: m2 | G37: =1.05+0.78+0.8+1.048+0.824+1.605 -> 6.107 | L37: =(H37+I37+J37+K37)*$L$7 -> 0 | M37: =(H37+I37+J37+K37+L37)*$M$7 -> 0 | N37: =(H37+I37+J37+K37+L37+M37)*$N$7 -> 0 | O37: =H37+I37+J37+K37+L37+M37+N37 -> 0 | P37: =G37*O37 -> 0
A38: =IF(G38="","",COUNT(A$1:A37)+1) -> 23 | B38: 陶粒回填 | C38: 1.找平层：综合各类混凝土类型、强度等级及找平厚度； 2.基层清理、界面剂； 3.包含但不限于编制说明、图纸、技术要求中的相关内容及完成该项目的一切所需； 4.需进行三方现场收方，否则不予计取。 | D38: / | E38: 按设计图示尺寸以体积计算 | F38: m³ | G38: =+(G36+G37)*(0.2+0.13-0.02) -> 17.45765 | H38: =+H13 -> 0 | I38: =+I13 -> 0 | J38: =+J13 -> 0 | K38: =+K13 -> 0 | L38: =(H38+I38+J38+K38)*$L$7 -> 0 | M38: =(H38+I38+J38+K38+L38)*$M$7 -> 0 | N38: =(H38+I38+J38+K38+L38+M38)*$N$7 -> 0 | O38: =H38+I38+J38+K38+L38+M38+N38 -> 0 | P38: =G38*O38 -> 0
A39: =IF(G39="","",COUNT(A$1:A38)+1) -> 24 | B39: 石材结晶处理 | C39: 石材打磨结晶处理 | E39: 按设计图示尺寸以投影面积计算 | F39: m2 | G39: =+G36 -> 50.208 | H39: =+H14 -> 0 | I39: =+I14 -> 0 | J39: =+J14 -> 0 | K39: =+K14 -> 0 | L39: =(H39+I39+J39+K39)*$L$7 -> 0 | M39: =(H39+I39+J39+K39+L39)*$M$7 -> 0 | N39: =(H39+I39+J39+K39+L39+M39)*$N$7 -> 0 | O39: =H39+I39+J39+K39+L39+M39+N39 -> 0 | P39: =G39*O39 -> 0
A40: =IF(G40="","",COUNT(A$1:A39)+1) -> 25 | B40: 水泥砂浆找平（柜体下） | C40: 1、水泥砂浆找平，找平厚度综合考虑； 2、包含但不限于编制说明、图纸、技术要求中的相关内容及完成该项目的一切所需； | D40: / | E40: 按设计图示尺寸以面积计算 | F40: m2 | G40: =2.55+0.75+0.195+1.36 -> 4.855 | L40: =(H40+I40+J40+K40)*$L$7 -> 0 | M40: =(H40+I40+J40+K40+L40)*$M$7 -> 0 | N40: =(H40+I40+J40+K40+L40+M40)*$N$7 -> 0 | O40: =H40+I40+J40+K40+L40+M40+N40 -> 0 | P40: =G40*O40 -> 0
...

Sheet 二、02机电清单
A1: 岁宝壹品苑一期
A2: C栋32层会所精装修工程
A3: 第二章 - 02号清单 机电清单
A4: 分部分项工程量清单
A5: 序号 | B5: 项目名称 | C5: 工作内容 | D5: 单位 | E5: 工程量 | F5: 综合单价构成（元） | M5: 综合单价 (含税) （元） | N5: 合价 (含税)（元）
F6: 主材费 （含损耗） | G6: 辅材费 | H6: 人工费 | I6: 机械费 | J6: 管理费 | K6: 利润 | L6: 税金
L7: 0.09
A8: 一 | B8: 强电工程 | N8: =SUM(N10:N53) -> 0
A9: （一） | B9: 照明系统
A10: 1 | B10: 弱电箱移位 | C10: 1.名称:弱电箱 2.规格型号:详见图纸及物料表 3.安装高度:详设计 4.包含智能模板安装接线 | D10: 套 | E10: 1 | J10: =(F10+G10+H10+I10)*$J$7 -> 0 | K10: =(F10+G10+H10+I10+J10)*$K$7 -> 0 | L10: =(F10+G10+H10+I10+J10+K10)*$L$7 -> 0 | M10: =F10+G10+H10+I10+J10+K10+L10 -> 0 | N10: =E10*M10 -> 0
A11: 2 | B11: 强电箱 | C11: 1.名称:厨房配电箱3-32ALCF/20kw 2.规格型号:详见图纸及物料表 3.安装高度:详设计 | D11: 套 | E11: 1 | J11: =(F11+G11+H11+I11)*$J$7 -> 0 | K11: =(F11+G11+H11+I11+J11)*$K$7 -> 0 | L11: =(F11+G11+H11+I11+J11+K11)*$L$7 -> 0 | M11: =F11+G11+H11+I11+J11+K11+L11 -> 0 | N11: =E11*M11 -> 0
A12: 3 | B12: D02b嵌入式下照筒灯 | C12: 1.名称:嵌入式下照筒灯8W 2.规格型号:详见图纸及物料表 3.安装高度:详设计 | D12: 套 | E12: =96+39 -> 135 | J12: =(F12+G12+H12+I12)*$J$7 -> 0 | K12: =(F12+G12+H12+I12+J12)*$K$7 -> 0 | L12: =(F12+G12+H12+I12+J12+K12)*$L$7 -> 0 | M12: =F12+G12+H12+I12+J12+K12+L12 -> 0 | N12: =E12*M12 -> 0
A13: 4 | B13: A02a嵌入式射灯 | C13: 1.名称:嵌入式射灯8W 2.规格型号:详见图纸及物料表 3.安装高度:详设计 | D13: 套 | E13: 151 | J13: =(F13+G13+H13+I13)*$J$7 -> 0 | K13: =(F13+G13+H13+I13+J13)*$K$7 -> 0 | L13: =(F13+G13+H13+I13+J13+K13)*$L$7 -> 0 | M13: =F13+G13+H13+I13+J13+K13+L13 -> 0 | N13: =E13*M13 -> 0
A14: 5 | B14: X02LED埋地灯 | C14: 1.名称:X02LED埋地灯3W 2.规格型号:详见图纸及物料表 3.安装高度:详设计 | D14: 套 | E14: 9 | J14: =(F14+G14+H14+I14)*$J$7 -> 0 | K14: =(F14+G14+H14+I14+J14)*$K$7 -> 0 | L14: =(F14+G14+H14+I14+J14+K14)*$L$7 -> 0 | M14: =F14+G14+H14+I14+J14+K14+L14 -> 0 | N14: =E14*M14 -> 0
A15: 6 | B15: G05d五头格栅射灯 | C15: 1.名称:G05d五头格栅射灯5W*5 2.规格型号:详见图纸及物料表 3.安装高度:详设计 | D15: 套 | E15: 6 | J15: =(F15+G15+H15+I15)*$J$7 -> 0 | K15: =(F15+G15+H15+I15+J15)*$K$7 -> 0 | L15: =(F15+G15+H15+I15+J15+K15)*$L$7 -> 0 | M15: =F15+G15+H15+I15+J15+K15+L15 -> 0 | N15: =E15*M15 -> 0
A16: 7 | B16: C04嵌入式线型灯 | C16: 1.名称:LED嵌入式线型灯36W 2.规格型号:详见图纸及物料表 3.安装高度:详设计 | D16: 套 | E16: 18 | J16: =(F16+G16+H16+I16)*$J$7 -> 0 | K16: =(F16+G16+H16+I16+J16)*$K$7 -> 0 | L16: =(F16+G16+H16+I16+J16+K16)*$L$7 -> 0 | M16: =F16+G16+H16+I16+J16+K16+L16 -> 0 | N16: =E16*M16 -> 0
A17: 8 | B17: L01天花暗藏LED灯带 | C17: 1.名称:LL1线性洗墙灯18W/M 2.规格型号:详见图纸及物料表 3.安装高度:详设计 | D17: m | E17: 47 | J17: =(F17+G17+H17+I17)*$J$7 -> 0 | K17: =(F17+G17+H17+I17+J17)*$K$7 -> 0 | L17: =(F17+G17+H17+I17+J17+K17)*$L$7 -> 0 | M17: =F17+G17+H17+I17+J17+K17+L17 -> 0 | N17: =E17*M17 -> 0
A18: 9 | B18: 排气扇/暖风机开关面板 | C18: 1.名称:排气扇/暖风机开关面板（主材甲指乙供） 2.规格:详见图纸的材料手册 3.安装高度:详设计 | D18: 个 | E18: 14 | J18: =(F18+G18+H18+I18)*$J$7 -> 0 | K18: =(F18+G18+H18+I18+J18)*$K$7 -> 0 | L18: =(F18+G18+H18+I18+J18+K18)*$L$7 -> 0 | M18: =F18+G18+H18+I18+J18+K18+L18 -> 0 | N18: =E18*M18 -> 0
A19: 10 | B19: 单相二三极插座 | C19: 1.名称:单相二三极插座 2.规格:详见图纸的材料手册 3.安装高度:详设计 | D19: 个 | E19: 100 | J19: =(F19+G19+H19+I19)*$J$7 -> 0 | K19: =(F19+G19+H19+I19+J19)*$K$7 -> 0 | L19: =(F19+G19+H19+I19+J19+K19)*$L$7 -> 0 | M19: =F19+G19+H19+I19+J19+K19+L19 -> 0 | N19: =E19*M19 -> 0
A20: 11 | B20: 单相二三极插座（带USB） | C20: 1.名称:单相二三极插座（带USB） 2.规格:详见图纸的材料手册 3.安装高度:详设计 | D20: 个 | J20: =(F20+G20+H20+I20)*$J$7 -> 0 | K20: =(F20+G20+H20+I20+J20)*$K$7 -> 0 | L20: =(F20+G20+H20+I20+J20+K20)*$L$7 -> 0 | M20: =F20+G20+H20+I20+J20+K20+L20 -> 0 | N20: =E20*M20 -> 0
A21: 12 | B21: 单相二三极插座(带防水) | C21: 1.名称:单相二三极插座(带防水) 2.规格:详见图纸的材料手册 3.安装高度:详设计 | D21: 个 | E21: 48 | J21: =(F21+G21+H21+I21)*$J$7 -> 0 | K21: =(F21+G21+H21+I21+J21)*$K$7 -> 0 | L21: =(F21+G21+H21+I21+J21+K21)*$L$7 -> 0 | M21: =F21+G21+H21+I21+J21+K21+L21 -> 0 | N21: =E21*M21 -> 0
A22: 13 | B22: 电视+网络双孔插座 | C22: 1.名称:电视+网络双孔插座 2.规格:详见图纸的材料手册 3.安装高度:详设计 | D22: 个 | J22: =(F22+G22+H22+I22)*$J$7 -> 0 | K22: =(F22+G22+H22+I22+J22)*$K$7 -> 0 | L22: =(F22+G22+H22+I22+J22+K22)*$L$7 -> 0 | M22: =F22+G22+H22+I22+J22+K22+L22 -> 0 | N22: =E22*M22 -> 0
A23: 14 | B23: 接线盒（含预留接线盒） | C23: 1.名称:电源接线盒 2.型号: 3.规格:详见图纸的材料手册 4.安装高度:详设计 | D23: 个 | E23: =410+153 -> 563 | J23: =(F23+G23+H23+I23)*$J$7 -> 0 | K23: =(F23+G23+H23+I23+J23)*$K$7 -> 0 | L23: =(F23+G23+H23+I23+J23+K23)*$L$7 -> 0 | M23: =F23+G23+H23+I23+J23+K23+L23 -> 0 | N23: =E23*M23 -> 0
A24: 15 | B24: 等电位端子箱 | C24: 1.名称:等电位端子箱 2.型号: 3.规格:详见图纸的材料手册 4.安装高度:详设计 | D24: 个 | E24: 4 | J24: =(F24+G24+H24+I24)*$J$7 -> 0 | K24: =(F24+G24+H24+I24+J24)*$K$7 -> 0 | L24: =(F24+G24+H24+I24+J24+K24)*$L$7 -> 0 | M24: =F24+G24+H24+I24+J24+K24+L24 -> 0 | N24: =E24*M24 -> 0
A25: 16 | B25: 热浸镀锌桥架 100*100*1.0mm | C25: 1.桥架及弯头、三通、盖板等所有附件，防雷接地连接。 2.预留洞口及防火封堵。 3.支、吊架制作安装。 | D25: m | E25: =1.47+7.15+1.94+5.76+1.8 -> 18.12 | J25: =(F25+G25+H25+I25)*$J$7 -> 0 | K25: =(F25+G25+H25+I25+J25)*$K$7 -> 0 | L25: =(F25+G25+H25+I25+J25+K25)*$L$7 -> 0 | M25: =F25+G25+H25+I25+J25+K25+L25 -> 0 | N25: =E25*M25 -> 0
A26: 17 | B26: 热浸镀锌桥架 200*100*1.2mm | C26: 1.桥架及弯头、三通、盖板等所有附件，防雷接地连接。 2.预留洞口及防火封堵。 3.支、吊架制作安装。 | D26: m | E26: 24.3 | J26: =(F26+G26+H26+I26)*$J$7 -> 0 | K26: =(F26+G26+H26+I26+J26)*$K$7 -> 0 | L26: =(F26+G26+H26+I26+J26+K26)*$L$7 -> 0 | M26: =F26+G26+H26+I26+J26+K26+L26 -> 0 | N26: =E26*M26 -> 0
A27: 18 | B27: 电气配管 | C27: 1.型号规格：JDG20 2.敷设形式：综合考虑 3.含接线盒.管道凿槽及恢复 | D27: m | E27: 1611.36 | J27: =(F27+G27+H27+I27)*$J$7 -> 0 | K27: =(F27+G27+H27+I27+J27)*$K$7 -> 0 | L27: =(F27+G27+H27+I27+J27+K27)*$L$7 -> 0 | M27: =F27+G27+H27+I27+J27+K27+L27 -> 0 | N27: =E27*M27 -> 0
A28: 19 | B28: 电气配管 | C28: 1.型号规格：JDG25 2.敷设形式：综合考虑 3.含接线盒.管道凿槽及恢复 | D28: m | E28: 555.6 | J28: =(F28+G28+H28+I28)*$J$7 -> 0 | K28: =(F28+G28+H28+I28+J28)*$K$7 -> 0 | L28: =(F28+G28+H28+I28+J28+K28)*$L$7 -> 0 | M28: =F28+G28+H28+I28+J28+K28+L28 -> 0 | N28: =E28*M28 -> 0
A29: 20 | B29: 电气配管 | C29: 1.型号规格：JDG40 2.敷设形式：综合考虑 3.含接线盒.管道凿槽及恢复 | D29: m | E29: 29.04 | J29: =(F29+G29+H29+I29)*$J$7 -> 0 | K29: =(F29+G29+H29+I29+J29)*$K$7 -> 0 | L29: =(F29+G29+H29+I29+J29+K29)*$L$7 -> 0 | M29: =F29+G29+H29+I29+J29+K29+L29 -> 0 | N29: =E29*M29 -> 0
A30: 21 | B30: 电气配线 | C30: 1.型号规格：WDZ-BYJ-3*4mm2 2.敷设方式：穿管及线槽敷设 | D30: m | E30: 1539.96 | J30: =(F30+G30+H30+I30)*$J$7 -> 0 | K30: =(F30+G30+H30+I30+J30)*$K$7 -> 0 | L30: =(F30+G30+H30+I30+J30+K30)*$L$7 -> 0 | M30: =F30+G30+H30+I30+J30+K30+L30 -> 0 | N30: =E30*M30 -> 0
A31: 22 | B31: 电气配线 | C31: 1.型号规格：WDZ-BYJ-3*6mm2 2.敷设方式：穿管及线槽敷设 | D31: m | E31: 76.2 | J31: =(F31+G31+H31+I31)*$J$7 -> 0 | K31: =(F31+G31+H31+I31+J31)*$K$7 -> 0 | L31: =(F31+G31+H31+I31+J31+K31)*$L$7 -> 0 | M31: =F31+G31+H31+I31+J31+K31+L31 -> 0 | N31: =E31*M31 -> 0
A32: 23 | B32: 电气配线 | C32: 1.型号规格：WDZ-BYJ-5*4mm2 2.敷设方式：穿管及线槽敷设 | D32: m | E32: 84.4 | J32: =(F32+G32+H32+I32)*$J$7 -> 0 | K32: =(F32+G32+H32+I32+J32)*$K$7 -> 0 | L32: =(F32+G32+H32+I32+J32+K32)*$L$7 -> 0 | M32: =F32+G32+H32+I32+J32+K32+L32 -> 0 | N32: =E32*M32 -> 0
A33: 24 | B33: 电气配线 | C33: 1.型号规格：WDZ-BYJ-5*10mm2 2.敷设方式：穿管及线槽敷设 | D33: m | E33: 145.21 | J33: =(F33+G33+H33+I33)*$J$7 -> 0 | K33: =(F33+G33+H33+I33+J33)*$K$7 -> 0 | L33: =(F33+G33+H33+I33+J33+K33)*$L$7 -> 0 | M33: =F33+G33+H33+I33+J33+K33+L33 -> 0 | N33: =E33*M33 -> 0
A34: 25 | B34: 管道支架制作（铁构件） | D34: kg | E34: 83.2 | J34: =(F34+G34+H34+I34)*$J$7 -> 0 | K34: =(F34+G34+H34+I34+J34)*$K$7 -> 0 | L34: =(F34+G34+H34+I34+J34+K34)*$L$7 -> 0 | M34: =F34+G34+H34+I34+J34+K34+L34 -> 0 | N34: =E34*M34 -> 0
A35: 26 | B35: 凿槽、刨沟 | D35: m | E35: 41.17 | J35: =(F35+G35+H35+I35)*$J$7 -> 0 | K35: =(F35+G35+H35+I35+J35)*$K$7 -> 0 | L35: =(F35+G35+H35+I35+J35+K35)*$L$7 -> 0 | M35: =F35+G35+H35+I35+J35+K35+L35 -> 0 | N35: =E35*M35 -> 0
A36: 27 | B36: 跨接地线（BVR-4mm²） | D36: m | E36: 44.1 | J36: =(F36+G36+H36+I36)*$J$7 -> 0 | K36: =(F36+G36+H36+I36+J36)*$K$7 -> 0 | L36: =(F36+G36+H36+I36+J36+K36)*$L$7 -> 0 | M36: =F36+G36+H36+I36+J36+K36+L36 -> 0 | N36: =E36*M36 -> 0
A37: 28 | B37: 接地端子（爪型螺母） | D37: 个 | E37: 294 | J37: =(F37+G37+H37+I37)*$J$7 -> 0 | K37: =(F37+G37+H37+I37+J37)*$K$7 -> 0 | L37: =(F37+G37+H37+I37+J37+K37)*$L$7 -> 0 | M37: =F37+G37+H37+I37+J37+K37+L37 -> 0 | N37: =E37*M37 -> 0
A38: （二） | B38: 应急照明
A39: 1 | B39: 消防应急照明灯具（6W，DC36V） | D39: 套 | E39: 34 | J39: =(F39+G39+H39+I39)*$J$7 -> 0 | K39: =(F39+G39+H39+I39+J39)*$K$7 -> 0 | L39: =(F39+G39+H39+I39+J39+K39)*$L$7 -> 0 | M39: =F39+G39+H39+I39+J39+K39+L39 -> 0 | N39: =E39*M39 -> 0
A40: 2 | B40: 安全出口标志灯 | D40: 套 | E40: 12 | J40: =(F40+G40+H40+I40)*$J$7 -> 0 | K40: =(F40+G40+H40+I40+J40)*$K$7 -> 0 | L40: =(F40+G40+H40+I40+J40+K40)*$L$7 -> 0 | M40: =F40+G40+H40+I40+J40+K40+L40 -> 0 | N40: =E40*M40 -> 0
...

Sheet 二、03结构及其他零星工程清单
A1: 岁宝壹品苑一期
A2: C栋32层会所精装修工程
A3: 第二章 - 03号清单 结构工程清单
A4: 分部分项工程量清单
A5: 序号 | B5: 工程名称 | C5: 工作内容 | D5: 图片 | E5: 计算规则 | F5: 单位 | G5: 工程量 | H5: 综合单价构成（元） | O5: 综合单价 (含税) （元） | P5: 合价 (含税)（元）
H6: 主材费 （含损耗） | I6: 辅材费 | J6: 人工费 | K6: 机械费 | L6: 管理费 | M6: 利润 | N6: 税金
N7: 0.09
A8: （一） | B8: 结构工程
A9: =IF(G9="","",COUNT(A$1:A8)+1) -> 1 | B9: 新增桁架楼层板 | C9: 1、原墙梁结构表面凿毛； 2、支模板； 3、角钢L90*5，化学锚栓、后置埋板； 4、直径10mm@200双层双向钢筋绑扎； 5、涂界面粘合剂； 6、120厚C40补充收缩细石混凝土； 7、包含但不限于编制说明、图纸、技术要求中的相关内容及完成该项目的一切所需； | D9: / | E9: 按设计图示尺寸以投影面积计算 | F9: m2 | G9: =17.72+1.29 -> 19.01 | L9: =(H9+I9+J9+K9)*$L$7 -> 0 | M9: =(H9+I9+J9+K9+L9)*$M$7 -> 0 | N9: =(H9+I9+J9+K9+L9+M9)*$N$7 -> 0 | O9: =H9+I9+J9+K9+L9+M9+N9 -> 0 | P9: =G9*O9 -> 0
A10: =IF(G10="","",COUNT(A$1:A9)+1) -> 2 | B10: 植筋Փ10 | C10: 1、静力钻孔； 2、综合不同长度； 3、植筋废孔采用植筋胶填实填满； 4、包含但不限于编制说明、图纸、技术要求中的相关内容及完成该项目的一切所需； | D10: / | E10: 按设计图示尺寸以根计算 | F10: 根 | G10: =ROUNDUP((17.55+4.8)/0.2,0)*2 -> 224 | L10: =(H10+I10+J10+K10)*$L$7 -> 0 | M10: =(H10+I10+J10+K10+L10)*$M$7 -> 0 | N10: =(H10+I10+J10+K10+L10+M10)*$N$7 -> 0 | O10: =H10+I10+J10+K10+L10+M10+N10 -> 0 | P10: =G10*O10 -> 0
A11: =IF(G11="","",COUNT(A$1:A10)+1) -> 3 | B11: 脚手架搭设及模板临时支撑费 | C11: 1、满堂脚手架搭设，综合不同高度； 2、模板临时支撑，综合不同高度； 3、含高支模专家论证费； | D11: / | E11: 按项计算 | F11: 项 | G11: 1 | L11: =(H11+I11+J11+K11)*$L$7 -> 0 | M11: =(H11+I11+J11+K11+L11)*$M$7 -> 0 | N11: =(H11+I11+J11+K11+L11+M11)*$N$7 -> 0 | O11: =H11+I11+J11+K11+L11+M11+N11 -> 0 | P11: =G11*O11 -> 0
A12: =IF(G12="","",COUNT(A$1:A11)+1) -> 4 | B12: 植筋现场抗拉、抗剪检测 | C12: 1、植筋现场抗拉、抗剪检测； 2、根据现场实际情况及数量计算 | D12: / | E12: 按个计算 | F12: 个 | G12: 6 | L12: =(H12+I12+J12+K12)*$L$7 -> 0 | M12: =(H12+I12+J12+K12+L12)*$M$7 -> 0 | N12: =(H12+I12+J12+K12+L12+M12)*$N$7 -> 0 | O12: =H12+I12+J12+K12+L12+M12+N12 -> 0 | P12: =G12*O12 -> 0
A13: =IF(G13="","",COUNT(A$1:A12)+1) -> 5 | B13: 钢楼梯 | C13: 1、钢梯、钢梁、埋板、踏步板、加劲板等； 2、化学螺栓； 3、防腐、防火涂料； 4、钢板原结构间的缝隙及其他穿孔部位应灌注胶粘实； 5、包含但不限于编制说明、图纸、技术要求中的相关内容及完成该项目的一切所需； | D13: / | E13: 按钢结构重量计算，化学螺栓不另算 | F13: t | G13: =+((2.7+3.5)*91+(2.665*2+4.265+1.501*3+1.04+2.076+2.327)*42.42+9*1.5*5.397+7.85*6*(11.7+(142.75-139.975)*1.35))/1000*1.1 -> 2.4128578 | L13: =(H13+I13+J13+K13)*$L$7 -> 0 | M13: =(H13+I13+J13+K13+L13)*$M$7 -> 0 | N13: =(H13+I13+J13+K13+L13+M13)*$N$7 -> 0 | O13: =H13+I13+J13+K13+L13+M13+N13 -> 0 | P13: =G13*O13 -> 0
A14: =IF(G14="","",COUNT(A$1:A13)+1) -> 6 | B14: 防护栏杆 | C14: 1、1.15m不锈钢防护栏杆； 2、综合不同直径、不同壁厚、不同形式的不锈钢材质； 3、包含但不限于编制说明、图纸、技术要求中的相关内容及完成该项目的一切所需； | D14: / | E14: 按设计图示尺寸以延长米计算 | F14: m | G14: 12 | L14: =(H14+I14+J14+K14)*$L$7 -> 0 | M14: =(H14+I14+J14+K14+L14)*$M$7 -> 0 | N14: =(H14+I14+J14+K14+L14+M14)*$N$7 -> 0 | O14: =H14+I14+J14+K14+L14+M14+N14 -> 0 | P14: =G14*O14 -> 0
A15: （二） | B15: 其他零星工程
A16: =IF(G16="","",COUNT(A$1:A15)+1) -> 7 | B16: 原混凝土反坎拆除（棋牌室位置） | C16: 1、原反坎拆除； 2、垃圾清运； 3、需进行三方现场收方，否则不予计取。 | D16: / | E16: 按体积计算 | F16: m3 | G16: =+(5+4+2)*0.2*0.4 -> 0.88 | L16: =(H16+I16+J16+K16)*$L$7 -> 0 | M16: =(H16+I16+J16+K16+L16)*$M$7 -> 0 | N16: =(H16+I16+J16+K16+L16+M16)*$N$7 -> 0 | O16: =H16+I16+J16+K16+L16+M16+N16 -> 0 | P16: =G16*O16 -> 0
A17: =IF(G17="","",COUNT(A$1:A16)+1) -> 8 | B17: 新增C30混凝土反坎（门窗底部） | C17: 1、支模板； 2、C30以上细石混凝土； 3、包含但不限于编制说明、图纸、技术要求中的相关内容及完成该项目的一切所需； | D17: / | E17: 按体积计算 | F17: m3 | G17: =+(6.37+4.23+1.74+3.19+2.935+4.15+3.77+5.56+4.12+4.41+4.8+4.3)*0.2*0.18 -> 1.7847 | L17: =(H17+I17+J17+K17)*$L$7 -> 0 | M17: =(H17+I17+J17+K17+L17)*$M$7 -> 0 | N17: =(H17+I17+J17+K17+L17+M17)*$N$7 -> 0 | O17: =H17+I17+J17+K17+L17+M17+N17 -> 0 | P17: =G17*O17 -> 0
A18: =IF(G18="","",COUNT(A$1:A17)+1) -> 9 | B18: 30层楼板遗留钢筋头除锈及防锈处理 | C18: 1、30层楼板遗留钢筋头除锈 2、防锈处理 3、包含但不限于编制说明、图纸、技术要求中的相关内容及完成该项目的一切所需； | D18: / | E18: 按项计算 | F18: 项 | G18: 1 | L18: =(H18+I18+J18+K18)*$L$7 -> 0 | M18: =(H18+I18+J18+K18+L18)*$M$7 -> 0 | N18: =(H18+I18+J18+K18+L18+M18)*$N$7 -> 0 | O18: =H18+I18+J18+K18+L18+M18+N18 -> 0 | P18: =G18*O18 -> 0
A19: =IF(G19="","",COUNT(A$1:A18)+1) -> 10 | B19: 30-32层现场材料清理及回收 | C19: 1、现场材料（钢筋、方钢、钢筋桁架）整理、截断、下楼、回收、清运； 2、需进行三方现场称重，否则不予计取。 | D19: / | E19: 按重量计算 | F19: t | G19: 11 | L19: =(H19+I19+J19+K19)*$L$7 -> 0 | M19: =(H19+I19+J19+K19+L19)*$M$7 -> 0 | N19: =(H19+I19+J19+K19+L19+M19)*$N$7 -> 0 | O19: =H19+I19+J19+K19+L19+M19+N19 -> 0 | P19: =G19*O19 -> 0
A20: =IF(G20="","",COUNT(A$1:A19)+1) -> 11 | B20: 30层天花、墙面喷深灰色涂料 | C20: 1、1遍深灰色涂料喷涂； 2、包含但不限于编制说明、图纸、技术要求中的相关内容及完成该项目的一切所需； | D20: / | E20: 按面积计算 | F20: m2 | G20: =63+8.5*(6.3+19.8) -> 284.85 | L20: =(H20+I20+J20+K20)*$L$7 -> 0 | M20: =(H20+I20+J20+K20+L20)*$M$7 -> 0 | N20: =(H20+I20+J20+K20+L20+M20)*$N$7 -> 0 | O20: =H20+I20+J20+K20+L20+M20+N20 -> 0 | P20: =G20*O20 -> 0
A21: =IF(G21="","",COUNT(A$1:A20)+1) -> 12 | B21: 30层地面水泥砂浆找平 | C21: 1、1：2.5水泥砂浆找平层，15~20mm厚，表面抹光； 2、包含但不限于编制说明、图纸、技术要求中的相关内容及完成该项目的一切所需； | D21: / | E21: 按面积计算 | F21: m2 | G21: =63 -> 63 | H21: =+'二、01 精装清单'!H398 -> 0 | I21: =+'二、01 精装清单'!I398 -> 0 | J21: =+'二、01 精装清单'!J398 -> 0 | K21: =+'二、01 精装清单'!K398 -> 0 | L21: =(H21+I21+J21+K21)*$L$7 -> 0 | M21: =(H21+I21+J21+K21+L21)*$M$7 -> 0 | N21: =(H21+I21+J21+K21+L21+M21)*$N$7 -> 0 | O21: =H21+I21+J21+K21+L21+M21+N21 -> 0 | P21: =G21*O21 -> 0
A22: =IF(G22="","",COUNT(A$1:A21)+1) -> 13 | B22: 泳池地面原有钢筋折弯、除锈 | C22: 1、泳池地面原有钢筋折弯、除锈 2、包含但不限于编制说明、图纸、技术要求中的相关内容及完成该项目的一切所需； | D22: / | E22: 按项计算 | F22: 项 | G22: 1 | L22: =(H22+I22+J22+K22)*$L$7 -> 0 | M22: =(H22+I22+J22+K22+L22)*$M$7 -> 0 | N22: =(H22+I22+J22+K22+L22+M22)*$N$7 -> 0 | O22: =H22+I22+J22+K22+L22+M22+N22 -> 0 | P22: =G22*O22 -> 0
A23: =IF(G23="","",COUNT(A$1:A22)+1) -> 14 | B23: 原有混凝土墙面C60混凝土找平（泳池钢筋外露部位） | C23: 1、墙面钢筋外漏部位钢筋除锈； 2、C60混凝土找平； 3、需进行三方现场收方，否则不予计取。 | D23: / | E23: 按面积计算 | F23: m2 | G23: =10*0.5 -> 5 | L23: =(H23+I23+J23+K23)*$L$7 -> 0 | M23: =(H23+I23+J23+K23+L23)*$M$7 -> 0 | N23: =(H23+I23+J23+K23+L23+M23)*$N$7 -> 0 | O23: =H23+I23+J23+K23+L23+M23+N23 -> 0 | P23: =G23*O23 -> 0
A24: =IF(G24="","",COUNT(A$1:A23)+1) -> 15 | B24: 地面回填120mm高陶粒混凝土（楼梯前室、楼梯平台位置） | C24: 1.地面回填100mm高陶粒混凝土； 2.需进行三方现场收方，否则不予计取。 | D24: / | E24: 按体积计算 | F24: m³ | G24: =10*0.1 -> 1 | H24: =+'二、01 精装清单'!H13 -> 0 | I24: =+'二、01 精装清单'!I13 -> 0 | J24: =+'二、01 精装清单'!J13 -> 0 | K24: =+'二、01 精装清单'!K13 -> 0 | L24: =(H24+I24+J24+K24)*$L$7 -> 0 | M24: =(H24+I24+J24+K24+L24)*$M$7 -> 0 | N24: =(H24+I24+J24+K24+L24+M24)*$N$7 -> 0 | O24: =H24+I24+J24+K24+L24+M24+N24 -> 0 | P24: =G24*O24 -> 0
A25: =IF(G25="","",COUNT(A$1:A24)+1) -> 16 | B25: 瓷砖地面（同原瓷砖颜色） | C25: 1、面层瓷砖铺贴，专用粘结剂，同色填缝； 2、1:2.5干硬性防水水泥砂浆找平，找平厚度20mm及以内； 3、详图纸； 4、包含但不限于编制说明、图纸、技术要求中的相关内容及完成该项目的一切所需； | D25: / | E25: 按面积计算 | F25: m2 | G25: =10+2.8*0.15+3 -> 13.42 | L25: =(H25+I25+J25+K25)*$L$7 -> 0 | M25: =(H25+I25+J25+K25+L25)*$M$7 -> 0 | N25: =(H25+I25+J25+K25+L25+M25)*$N$7 -> 0 | O25: =H25+I25+J25+K25+L25+M25+N25 -> 0 | P25: =G25*O25 -> 0
A26: =IF(G26="","",COUNT(A$1:A25)+1) -> 17 | B26: 瓷砖踢脚线 | C26: 1、面层瓷砖铺贴，专用粘结剂，同色填缝； 2、1:2.5干硬性防水水泥砂浆找平，找平厚度20mm及以内； 3、详图纸； 4、包含但不限于编制说明、图纸、技术要求中的相关内容及完成该项目的一切所需； | D26: / | E26: 按延长米计算 | F26: m | G26: =17-2.8+3 -> 17.2 | L26: =(H26+I26+J26+K26)*$L$7 -> 0 | M26: =(H26+I26+J26+K26+L26)*$M$7 -> 0 | N26: =(H26+I26+J26+K26+L26+M26)*$N$7 -> 0 | O26: =H26+I26+J26+K26+L26+M26+N26 -> 0 | P26: =G26*O26 -> 0
A27: =IF(G27="","",COUNT(A$1:A26)+1) -> 18 | B27: 防火门及消火栓抬高 | C27: 1、防火门保护性拆除； 2、门头打凿、门头边修复； 3、防火门门框制作安装、塞缝及收边、防火门门扇重新安装； 4、消防栓拆除、抬高重新安装； 5、消防指示灯、烟感器移位； 6、包含但不限于编制说明、图纸、技术要求中的相关内容及完成该项目的一切所需； | D27: / | E27: 按樘计算 | F27: 樘 | G27: 4 | L27: =(H27+I27+J27+K27)*$L$7 -> 0 | M27: =(H27+I27+J27+K27+L27)*$M$7 -> 0 | N27: =(H27+I27+J27+K27+L27+M27)*$N$7 -> 0 | O27: =H27+I27+J27+K27+L27+M27+N27 -> 0 | P27: =G27*O27 -> 0
A28: =IF(G28="","",COUNT(A$1:A27)+1) -> 19 | B28: 墙面洞口封堵 （31层泳池热泵空调机房） | C28: 1、墙洞口用加气混凝土砌块封堵； 2、墙面水泥砂浆找平； 3、满刮腻子两遍； 4、刷白色防水无机涂料PT-102底油一遍、面漆两遍； 5、包含但不限于编制说明、图纸、技术要求中的相关内容及完成该项目的一切所需； | D28: / | E28: 按面积计算 | F28: m2 | G28: =1*1.2 -> 1.2 | L28: =(H28+I28+J28+K28)*$L$7 -> 0 | M28: =(H28+I28+J28+K28+L28)*$M$7 -> 0 | N28: =(H28+I28+J28+K28+L28+M28)*$N$7 -> 0 | O28: =H28+I28+J28+K28+L28+M28+N28 -> 0 | P28: =G28*O28 -> 0
A29: =IF(G29="","",COUNT(A$1:A28)+1) -> 20 | B29: 吸音板天花吊顶恢复 （31F泳池热泵空调机房） | C29: 1、600*600mm吸音板采购及安装； 2、包含但不限于编制说明、图纸、技术要求中的相关内容及完成该项目的一切所需； | D29: / | E29: 按面积计算 | F29: m2 | G29: =1*2.4 -> 2.4 | L29: =(H29+I29+J29+K29)*$L$7 -> 0 | M29: =(H29+I29+J29+K29+L29)*$M$7 -> 0 | N29: =(H29+I29+J29+K29+L29+M29)*$N$7 -> 0 | O29: =H29+I29+J29+K29+L29+M29+N29 -> 0 | P29: =G29*O29 -> 0
A30: =IF(G30="","",COUNT(A$1:A29)+1) -> 21 | B30: 消防喷淋管 DN25 | C30: 1.安装部位：室内 2.介质:喷淋给水 3.材质、规格:内外壁热镀锌钢管DN25 4.连接方式:螺纹连接 含管件 5.其他要求:满足施工图纸技术规范要求 | D30: / | E30: 按长度计算 | F30: m | G30: 10 | L30: =(H30+I30+J30+K30)*$L$7 -> 0 | M30: =(H30+I30+J30+K30+L30)*$M$7 -> 0 | N30: =(H30+I30+J30+K30+L30+M30)*$N$7 -> 0 | O30: =H30+I30+J30+K30+L30+M30+N30 -> 0 | P30: =G30*O30 -> 0
A31: =IF(G31="","",COUNT(A$1:A30)+1) -> 22 | B31: 消防喷淋管 DN32 | C31: 1.安装部位：室内 2.介质:喷淋给水 3.材质、规格:内外壁热镀锌钢管DN32 4.连接方式:螺纹连接 含管件 5.其他要求:满足施工图纸技术规范要求 | D31: / | E31: 按长度计算 | F31: m | G31: 3.1 | L31: =(H31+I31+J31+K31)*$L$7 -> 0 | M31: =(H31+I31+J31+K31+L31)*$M$7 -> 0 | N31: =(H31+I31+J31+K31+L31+M31)*$N$7 -> 0 | O31: =H31+I31+J31+K31+L31+M31+N31 -> 0 | P31: =G31*O31 -> 0
A32: =IF(G32="","",COUNT(A$1:A31)+1) -> 23 | B32: 消防喷淋管 DN50 | C32: 1.安装部位：室内 2.介质:喷淋给水 3.材质、规格:内外壁热镀锌钢管DN50 4.连接方式:螺纹连接 含管件 5.其他要求:满足施工图纸技术规范要求 | D32: / | E32: 按长度计算 | F32: m | G32: 3.3 | L32: =(H32+I32+J32+K32)*$L$7 -> 0 | M32: =(H32+I32+J32+K32+L32)*$M$7 -> 0 | N32: =(H32+I32+J32+K32+L32+M32)*$N$7 -> 0 | O32: =H32+I32+J32+K32+L32+M32+N32 -> 0 | P32: =G32*O32 -> 0
A33: =IF(G33="","",COUNT(A$1:A32)+1) -> 24 | B33: 消防喷淋管 DN65 | C33: 1.安装部位：室内 2.介质:喷淋给水 3.材质、规格:内外壁热镀锌钢管DN65 4.连接方式:螺纹连接 含管件 5.其他要求:满足施工图纸技术规范要求 | D33: / | E33: 按长度计算 | F33: m | G33: 2 | L33: =(H33+I33+J33+K33)*$L$7 -> 0 | M33: =(H33+I33+J33+K33+L33)*$M$7 -> 0 | N33: =(H33+I33+J33+K33+L33+M33)*$N$7 -> 0 | O33: =H33+I33+J33+K33+L33+M33+N33 -> 0 | P33: =G33*O33 -> 0
A34: =IF(G34="","",COUNT(A$1:A33)+1) -> 25 | B34: 墙体拆除 （31F泳池热泵空调机房） | C34: 1、原有砌体墙拆除； 2、垃圾清运； 3、洞口周边水泥砂浆抹灰、刷乳胶漆； 4、包含但不限于编制说明、图纸、技术要求中的相关内容及完成该项目的一切所需； | D34: / | E34: 按面积计算 | F34: m2 | G34: =5*3.5*2 -> 35 | L34: =(H34+I34+J34+K34)*$L$7 -> 0 | M34: =(H34+I34+J34+K34+L34)*$M$7 -> 0 | N34: =(H34+I34+J34+K34+L34+M34)*$N$7 -> 0 | O34: =H34+I34+J34+K34+L34+M34+N34 -> 0 | P34: =G34*O34 -> 0
A35: =IF(G35="","",COUNT(A$1:A34)+1) -> 26 | B35: 地面回填100mm高陶粒混凝土（游泳热泵空调机房） | C35: 1.地面回填100mm高陶粒混凝土； 2.需进行三方现场收方，否则不予计取。 | D35: / | E35: 按体积计算 | F35: m³ | G35: =45.9*0.1 -> 4.59 | H35: =+H24 -> 0 | I35: =+I24 -> 0 | J35: =+J24 -> 0 | K35: =+K24 -> 0 | L35: =(H35+I35+J35+K35)*$L$7 -> 0 | M35: =(H35+I35+J35+K35+L35)*$M$7 -> 0 | N35: =(H35+I35+J35+K35+L35+M35)*$N$7 -> 0 | O35: =H35+I35+J35+K35+L35+M35+N35 -> 0 | P35: =G35*O35 -> 0
A36: =IF(G36="","",COUNT(A$1:A35)+1) -> 27 | B36: 地面水泥砂浆找平 （游泳热泵空调机房和泳池水处理机房） | C36: 1、1：2.5水泥砂浆找平层，15~20mm厚，阴阳角抹小圆角； 2、包含但不限于编制说明、图纸、技术要求中的相关内容及完成该项目的一切所需； | D36: / | E36: 按面积计算 | F36: m2 | G36: =35.49+45.9 -> 81.39 | H36: =+H21 -> 0 | I36: =+I21 -> 0 | J36: =+J21 -> 0 | K36: =+K21 -> 0 | L36: =(H36+I36+J36+K36)*$L$7 -> 0 | M36: =(H36+I36+J36+K36+L36)*$M$7 -> 0 | N36: =(H36+I36+J36+K36+L36+M36)*$N$7 -> 0 | O36: =H36+I36+J36+K36+L36+M36+N36 -> 0 | P36: =G36*O36 -> 0
A37: =IF(G37="","",COUNT(A$1:A36)+1) -> 28 | B37: 防水涂料 （游泳热泵空调机房和泳池水处理机房） | C37: 1、1.5厚单组份聚氨酯（I型）防水涂膜； | D37: / | E37: 按面积计算 | F37: m2 | G37: =35.49+45.9+(27-1.5+26-1.5)*0.3 -> 96.39 | H37: =+'二、01 精装清单'!H389 -> 0 | I37: =+'二、01 精装清单'!I389 -> 0 | J37: =+'二、01 精装清单'!J389 -> 0 | K37: =+'二、01 精装清单'!K389 -> 0 | L37: =(H37+I37+J37+K37)*$L$7 -> 0 | M37: =(H37+I37+J37+K37+L37)*$M$7 -> 0 | N37: =(H37+I37+J37+K37+L37+M37)*$N$7 -> 0 | O37: =H37+I37+J37+K37+L37+M37+N37 -> 0 | P37: =G37*O37 -> 0
A38: =IF(G38="","",COUNT(A$1:A37)+1) -> 29 | B38: 地面水泥砂浆保护层 （游泳热泵空调机房和泳池水处理机房） | C38: 1、1：2.5水泥砂浆找平层，15~20mm厚，表面抹光； 2、包含但不限于编制说明、图纸、技术要求中的相关内容及完成该项目的一切所需； | D38: / | E38: 按面积计算 | F38: m2 | G38: =45.9 -> 45.9 | H38: =+'二、01 精装清单'!H399 -> 0 | I38: =+'二、01 精装清单'!I399 -> 0 | J38: =+'二、01 精装清单'!J399 -> 0 | K38: =+'二、01 精装清单'!K399 -> 0 | L38: =(H38+I38+J38+K38)*$L$7 -> 0 | M38: =(H38+I38+J38+K38+L38)*$M$7 -> 0 | N38: =(H38+I38+J38+K38+L38+M38)*$N$7 -> 0 | O38: =H38+I38+J38+K38+L38+M38+N38 -> 0 | P38: =G38*O38 -> 0
A39: =IF(G39="","",COUNT(A$1:A38)+1) -> 30 | B39: 排水沟砌筑 | C39: 1、灰砂砖砌筑排水沟； 2、水泥砂浆找平； 3、包含但不限于编制说明、图纸、技术要求中的相关内容及完成该项目的一切所需； | D39: / | E39: 按长度计算 | F39: m | G39: =4.46+5.2 -> 9.66 | L39: =(H39+I39+J39+K39)*$L$7 -> 0 | M39: =(H39+I39+J39+K39+L39)*$M$7 -> 0 | N39: =(H39+I39+J39+K39+L39+M39)*$N$7 -> 0 | O39: =H39+I39+J39+K39+L39+M39+N39 -> 0 | P39: =G39*O39 -> 0
A40: =IF(G40="","",COUNT(A$1:A39)+1) -> 31 | B40: 排水沟盖板 | C40: 1、300mm宽不锈钢排水沟盖板 2、包含但不限于编制说明、图纸、技术要求中的相关内容及完成该项目的一切所需； | D40: / | E40: 按长度计算 | F40: m | G40: =4.46+5.2 -> 9.66 | L40: =(H40+I40+J40+K40)*$L$7 -> 0 | M40: =(H40+I40+J40+K40+L40)*$M$7 -> 0 | N40: =(H40+I40+J40+K40+L40+M40)*$N$7 -> 0 | O40: =H40+I40+J40+K40+L40+M40+N40 -> 0 | P40: =G40*O40 -> 0
...

Sheet 二、04厨房设备供货安装工程清单
A1: 岁宝壹品苑一期
A2: C栋32层会所精装修工程
A3: 第二章 - 04号清单 厨房设备供货安装工程清单
A4: 分部分项工程量清单
A5: 序号 | B5: 产品款型 | C5: 技术指标 | D5: 产品规格 | E5: 单位 | F5: 数量 | G5: 综合单价构成（元） | N5: 综合单价 (含税) （元） | O5: 合价 (含税)（元） | P5: 备注
G6: 主材费 （含损耗） | H6: 辅材费 | I6: 人工费 | J6: 机械费 | K6: 管理费 | L6: 利润 | M6: 税金
M7: 0.09
A8: 1 | B8: 单头小炒炉 | C8: 炉面采用304#1.2mm厚不锈钢板，侧 板0.8mm制作，配可调节脚，带熄火 保护3C认证 | D8: 1100*950*800+450 | E8: 台 | F8: 2 | K8: =(G8+H8+I8+J8)*$K$7 -> 0 | L8: =(G8+H8+I8+J8+K8)*$L$7 -> 0 | M8: =(G8+H8+I8+J8+K8+L8)*$M$7 -> 0 | N8: =G8+H8+I8+J8+K8+L8+M8 -> 0 | O8: =F8*N8 -> 0 | P8: 1、中汇或国产一线品牌 2、拟投标产品品牌、型号及详细规格参数在技术标中报审
A9: 2 | B9: 双头煲仔炉 | C9: 炉面采用304#1.2mm厚不锈钢板，侧 板0.8mm制作，配可调节脚，带熄火 保护3C认证 | D9: 400*800*800 | E9: 台 | F9: 1 | K9: =(G9+H9+I9+J9)*$K$7 -> 0 | L9: =(G9+H9+I9+J9+K9)*$L$7 -> 0 | M9: =(G9+H9+I9+J9+K9+L9)*$M$7 -> 0 | N9: =G9+H9+I9+J9+K9+L9+M9 -> 0 | O9: =F9*N9 -> 0 | P9: 1、中汇或国产一线品牌 2、拟投标产品品牌、型号及详细规格参数在技术标中报审
A10: 3 | B10: 蒸柜 | C10: 采用304#1.2mm厚不锈钢板，侧板 0.8mm制作，配可调节脚，带熄火保 护3C认证 | D10: 900*900* 1850 | E10: 台 | F10: 1 | K10: =(G10+H10+I10+J10)*$K$7 -> 0 | L10: =(G10+H10+I10+J10+K10)*$L$7 -> 0 | M10: =(G10+H10+I10+J10+K10+L10)*$M$7 -> 0 | N10: =G10+H10+I10+J10+K10+L10+M10 -> 0 | O10: =F10*N10 -> 0 | P10: 1、中汇或国产一线品牌 2、拟投标产品品牌、型号及详细规格参数在技术标中报审
A11: 4 | B11: 四门高身雪柜 | C11: 1.整机为不锈钢工艺 2.优质压缩机，数字温控器； 3.温度:-15℃~-6℃/0℃~10℃; 4.功率:350W/220V； 5.制冷方式:直冷； | D11: 1220x760x1910 | E11: 台 | F11: 1 | K11: =(G11+H11+I11+J11)*$K$7 -> 0 | L11: =(G11+H11+I11+J11+K11)*$L$7 -> 0 | M11: =(G11+H11+I11+J11+K11+L11)*$M$7 -> 0 | N11: =G11+H11+I11+J11+K11+L11+M11 -> 0 | O11: =F11*N11 -> 0 | P11: 1、信而达或国产一线品牌 2、拟投标产品品牌、型号及详细规格参数在技术标中报审
A12: 5 | B12: 工作台雪柜 | C12: 1.整机为不锈钢工艺 2.优质压缩机，数字温控器； 3.温度:-15℃~-6℃/0℃~10℃; 4.功率:350W/220V； 5.制冷方式:直冷； | D12: 1800x700x800 | E12: 台 | F12: 1 | K12: =(G12+H12+I12+J12)*$K$7 -> 0 | L12: =(G12+H12+I12+J12+K12)*$L$7 -> 0 | M12: =(G12+H12+I12+J12+K12+L12)*$M$7 -> 0 | N12: =G12+H12+I12+J12+K12+L12+M12 -> 0 | O12: =F12*N12 -> 0 | P12: 1、信而达或国产一线品牌 2、拟投标产品品牌、型号及详细规格参数在技术标中报审
A13: 6 | B13: 灭蝇灯 | E13: 台 | F13: 1 | K13: =(G13+H13+I13+J13)*$K$7 -> 0 | L13: =(G13+H13+I13+J13+K13)*$L$7 -> 0 | M13: =(G13+H13+I13+J13+K13+L13)*$M$7 -> 0 | N13: =G13+H13+I13+J13+K13+L13+M13 -> 0 | O13: =F13*N13 -> 0 | P13: 1、三川或国产一线品牌 2、拟投标产品品牌、型号及详细规格参数在技术标中报审
A14: 7 | B14: 挂墙开水器 | C14: 功率6KW/380V,容量80L | D14: 450*400*960 | E14: 台 | F14: 1 | K14: =(G14+H14+I14+J14)*$K$7 -> 0 | L14: =(G14+H14+I14+J14+K14)*$L$7 -> 0 | M14: =(G14+H14+I14+J14+K14+L14)*$M$7 -> 0 | N14: =G14+H14+I14+J14+K14+L14+M14 -> 0 | O14: =F14*N14 -> 0 | P14: 1、裕豪或国产一线品牌 2、拟投标产品品牌、型号及详细规格参数在技术标中报审
A15: 8 | B15: 烤箱 | C15: 电压：220V；功率：3.4KW | D15: 850*630*440 | E15: 台 | F15: 1 | K15: =(G15+H15+I15+J15)*$K$7 -> 0 | L15: =(G15+H15+I15+J15+K15)*$L$7 -> 0 | M15: =(G15+H15+I15+J15+K15+L15)*$M$7 -> 0 | N15: =G15+H15+I15+J15+K15+L15+M15 -> 0 | O15: =F15*N15 -> 0 | P15: 1、佳斯特或国产一线品牌 2、拟投标产品品牌、型号及详细规格参数在技术标中报审
A16: 9 | B16: 消毒柜 | C16: 201不锈钢, 中温消毒柜，1400W/220V | D16: 1200*585*1780 | E16: 台 | F16: 2 | K16: =(G16+H16+I16+J16)*$K$7 -> 0 | L16: =(G16+H16+I16+J16+K16)*$L$7 -> 0 | M16: =(G16+H16+I16+J16+K16+L16)*$M$7 -> 0 | N16: =G16+H16+I16+J16+K16+L16+M16 -> 0 | O16: =F16*N16 -> 0 | P16: 1、康宝或国产一线品牌 2、拟投标产品品牌、型号及详细规格参数在技术标中报审
A17: 10 | B17: 炉拼台 | C17: 1.台面采用304#1.2mm厚不锈钢板下 加不锈钢加强码仔； 2.靠背采用0.9mm不锈钢板； | D17: 400*950*800 | E17: 台 | F17: 2 | K17: =(G17+H17+I17+J17)*$K$7 -> 0 | L17: =(G17+H17+I17+J17+K17)*$L$7 -> 0 | M17: =(G17+H17+I17+J17+K17+L17)*$M$7 -> 0 | N17: =G17+H17+I17+J17+K17+L17+M17 -> 0 | O17: =F17*N17 -> 0 | P17: 厂制品
A18: 11 | B18: 双层工作台 | C18: 1.台面采用304#1.2mm厚不锈钢板； 2.台面加不锈钢加强码仔； 3.台脚采用38×38mm不锈钢方通； 4.配全钢可调性子弹脚； | D18: 1000*950*800 | E18: 台 | F18: 1 | K18: =(G18+H18+I18+J18)*$K$7 -> 0 | L18: =(G18+H18+I18+J18+K18)*$L$7 -> 0 | M18: =(G18+H18+I18+J18+K18+L18)*$M$7 -> 0 | N18: =G18+H18+I18+J18+K18+L18+M18 -> 0 | O18: =F18*N18 -> 0 | P18: 厂制品
A19: 12 | B19: 四层管架 （四腿） | C19: 1.主架用304#1.2mm38*38不锈钢方通 2.横桶38*25 ，层条用25* 13不锈钢制作 | D19: 1200*500* 1500 | E19: 台 | F19: 1 | K19: =(G19+H19+I19+J19)*$K$7 -> 0 | L19: =(G19+H19+I19+J19+K19)*$L$7 -> 0 | M19: =(G19+H19+I19+J19+K19+L19)*$M$7 -> 0 | N19: =G19+H19+I19+J19+K19+L19+M19 -> 0 | O19: =F19*N19 -> 0 | P19: 厂制品
A20: 13 | B20: 双通荷台柜 | C20: 1.台面采用304#1.2mm厚不锈钢板； 2.台面加不锈钢加强码仔； 3.台脚采用38×38mm不锈钢方通； 4.配全钢可调性子弹脚； | D20: 1800*700*800 | E20: 台 | F20: 1 | K20: =(G20+H20+I20+J20)*$K$7 -> 0 | L20: =(G20+H20+I20+J20+K20)*$L$7 -> 0 | M20: =(G20+H20+I20+J20+K20+L20)*$M$7 -> 0 | N20: =G20+H20+I20+J20+K20+L20+M20 -> 0 | O20: =F20*N20 -> 0 | P20: 厂制品
A21: 14 | B21: 三星盆台 | C21: 1.台面用304#1.2mm厚不锈钢板下加 不锈钢加强筋； 2.星盆用1.0mm； 3.横通25*25mm不锈钢方通； 4.脚通38*38mm ，配全钢可调性子弹 脚； 5.带自动溢水功能； | D21: 1800x760x800 | E21: 台 | F21: 1 | K21: =(G21+H21+I21+J21)*$K$7 -> 0 | L21: =(G21+H21+I21+J21+K21)*$L$7 -> 0 | M21: =(G21+H21+I21+J21+K21+L21)*$M$7 -> 0 | N21: =G21+H21+I21+J21+K21+L21+M21 -> 0 | O21: =F21*N21 -> 0 | P21: 厂制品
A22: 15 | B22: 双层工作台 | C22: 1. 台面采用304#1.2mm厚不锈钢板； 2. 台面加不锈钢加强码仔； 3. 台脚采用38×38mm不锈钢方通； 4.配全钢可调性子弹脚； | D22: 1000*760*800 | E22: 台 | F22: 1 | K22: =(G22+H22+I22+J22)*$K$7 -> 0 | L22: =(G22+H22+I22+J22+K22)*$L$7 -> 0 | M22: =(G22+H22+I22+J22+K22+L22)*$M$7 -> 0 | N22: =G22+H22+I22+J22+K22+L22+M22 -> 0 | O22: =F22*N22 -> 0 | P22: 厂制品
A23: 16 | B23: 双层挂墙架 | C23: 1.采用304#1.0mm厚不锈钢板； | D23: 1400*300*690 | E23: 台 | F23: 2 | K23: =(G23+H23+I23+J23)*$K$7 -> 0 | L23: =(G23+H23+I23+J23+K23)*$L$7 -> 0 | M23: =(G23+H23+I23+J23+K23+L23)*$M$7 -> 0 | N23: =G23+H23+I23+J23+K23+L23+M23 -> 0 | O23: =F23*N23 -> 0 | P23: 厂制品
A24: 17 | B24: 紫外线消毒灯 | C24: 国产灯架，飞利浦灯管 | E24: 台 | F24: 1 | K24: =(G24+H24+I24+J24)*$K$7 -> 0 | L24: =(G24+H24+I24+J24+K24)*$L$7 -> 0 | M24: =(G24+H24+I24+J24+K24+L24)*$M$7 -> 0 | N24: =G24+H24+I24+J24+K24+L24+M24 -> 0 | O24: =F24*N24 -> 0 | P24: 厂制品
A25: 18 | B25: 带油网烟罩 | C25: 1.用304#1.0mm厚不锈钢 | D25: 5350*1100*500 | E25: 米 | F25: 5.4 | K25: =(G25+H25+I25+J25)*$K$7 -> 0 | L25: =(G25+H25+I25+J25+K25)*$L$7 -> 0 | M25: =(G25+H25+I25+J25+K25+L25)*$M$7 -> 0 | N25: =G25+H25+I25+J25+K25+L25+M25 -> 0 | O25: =F25*N25 -> 0 | P25: 厂制品
A26: 19 | B26: 封墙板 | C26: 1.用304#1.0mm厚不锈钢 | D26: 5350*1100*500 | E26: 米 | F26: 5.4 | K26: =(G26+H26+I26+J26)*$K$7 -> 0 | L26: =(G26+H26+I26+J26+K26)*$L$7 -> 0 | M26: =(G26+H26+I26+J26+K26+L26)*$M$7 -> 0 | N26: =G26+H26+I26+J26+K26+L26+M26 -> 0 | O26: =F26*N26 -> 0 | P26: 厂制品
A27: 20 | B27: 隔油池 | C27: 1.用304#1.0mm厚不锈钢 | D27: 600*400*280 | E27: 个 | F27: 1 | K27: =(G27+H27+I27+J27)*$K$7 -> 0 | L27: =(G27+H27+I27+J27+K27)*$L$7 -> 0 | M27: =(G27+H27+I27+J27+K27+L27)*$M$7 -> 0 | N27: =G27+H27+I27+J27+K27+L27+M27 -> 0 | O27: =F27*N27 -> 0 | P27: 厂制品
A28: 21 | B28: 排烟风机 | C28: 风量7060m³/H电压：380V；功率：2.2KW | E28: 台 | F28: 1 | K28: =(G28+H28+I28+J28)*$K$7 -> 0 | L28: =(G28+H28+I28+J28+K28)*$L$7 -> 0 | M28: =(G28+H28+I28+J28+K28+L28)*$M$7 -> 0 | N28: =G28+H28+I28+J28+K28+L28+M28 -> 0 | O28: =F28*N28 -> 0
A29: 22 | B29: 风机支架 | C29: 1.国标角铁50*50 | E29: 个 | F29: 1 | K29: =(G29+H29+I29+J29)*$K$7 -> 0 | L29: =(G29+H29+I29+J29+K29)*$L$7 -> 0 | M29: =(G29+H29+I29+J29+K29+L29)*$M$7 -> 0 | N29: =G29+H29+I29+J29+K29+L29+M29 -> 0 | O29: =F29*N29 -> 0 | P29: 厂制品
A30: 23 | B30: 帆布软连接 | C30: 优质帆布 | E30: 个 | F30: 1 | K30: =(G30+H30+I30+J30)*$K$7 -> 0 | L30: =(G30+H30+I30+J30+K30)*$L$7 -> 0 | M30: =(G30+H30+I30+J30+K30+L30)*$M$7 -> 0 | N30: =G30+H30+I30+J30+K30+L30+M30 -> 0 | O30: =F30*N30 -> 0 | P30: 厂制品
A31: 24 | B31: 风机启动控制器 | C31: 过载启动保护，配套风机4KW | E31: 个 | F31: 1 | K31: =(G31+H31+I31+J31)*$K$7 -> 0 | L31: =(G31+H31+I31+J31+K31)*$L$7 -> 0 | M31: =(G31+H31+I31+J31+K31+L31)*$M$7 -> 0 | N31: =G31+H31+I31+J31+K31+L31+M31 -> 0 | O31: =F31*N31 -> 0 | P31: 厂制品
A32: 25 | B32: 排烟风管 | C32: 600*600/500*500 | D32: 采用镀锌板#1.0mm厚板材制作 | E32: 平方 | F32: 52 | K32: =(G32+H32+I32+J32)*$K$7 -> 0 | L32: =(G32+H32+I32+J32+K32)*$L$7 -> 0 | M32: =(G32+H32+I32+J32+K32+L32)*$M$7 -> 0 | N32: =G32+H32+I32+J32+K32+L32+M32 -> 0 | O32: =F32*N32 -> 0 | P32: 厂制品
A33: 26 | B33: 补风风机 | C33: 风量6000m³/H电压：220V；功率：1.1KW | E33: 台 | F33: 1 | K33: =(G33+H33+I33+J33)*$K$7 -> 0 | L33: =(G33+H33+I33+J33+K33)*$L$7 -> 0 | M33: =(G33+H33+I33+J33+K33+L33)*$M$7 -> 0 | N33: =G33+H33+I33+J33+K33+L33+M33 -> 0 | O33: =F33*N33 -> 0
A34: 27 | B34: 风机支架 | C34: 1.国标角铁50*50 | E34: 个 | F34: 1 | K34: =(G34+H34+I34+J34)*$K$7 -> 0 | L34: =(G34+H34+I34+J34+K34)*$L$7 -> 0 | M34: =(G34+H34+I34+J34+K34+L34)*$M$7 -> 0 | N34: =G34+H34+I34+J34+K34+L34+M34 -> 0 | O34: =F34*N34 -> 0 | P34: 厂制品
A35: 28 | B35: 风机启动控制器 | C35: 过载启动保护,配套风机1.1KW | E35: 个 | F35: 1 | K35: =(G35+H35+I35+J35)*$K$7 -> 0 | L35: =(G35+H35+I35+J35+K35)*$L$7 -> 0 | M35: =(G35+H35+I35+J35+K35+L35)*$M$7 -> 0 | N35: =G35+H35+I35+J35+K35+L35+M35 -> 0 | O35: =F35*N35 -> 0 | P35: 厂制品
A36: 29 | B36: 帆布软连接 | C36: 优质帆布 | E36: 个 | F36: 1 | K36: =(G36+H36+I36+J36)*$K$7 -> 0 | L36: =(G36+H36+I36+J36+K36)*$L$7 -> 0 | M36: =(G36+H36+I36+J36+K36+L36)*$M$7 -> 0 | N36: =G36+H36+I36+J36+K36+L36+M36 -> 0 | O36: =F36*N36 -> 0 | P36: 厂制品
A37: 30 | B37: 补风风管 | C37: 300*300 | D37: 采用镀锌板#1.0mm厚板材制作 | E37: 平方 | F37: 36 | K37: =(G37+H37+I37+J37)*$K$7 -> 0 | L37: =(G37+H37+I37+J37+K37)*$L$7 -> 0 | M37: =(G37+H37+I37+J37+K37+L37)*$M$7 -> 0 | N37: =G37+H37+I37+J37+K37+L37+M37 -> 0 | O37: =F37*N37 -> 0 | P37: 厂制品
A38: 31 | B38: 风嘴 | D38: 优质不锈钢 | E38: 个 | F38: 4 | K38: =(G38+H38+I38+J38)*$K$7 -> 0 | L38: =(G38+H38+I38+J38+K38)*$L$7 -> 0 | M38: =(G38+H38+I38+J38+K38+L38)*$M$7 -> 0 | N38: =G38+H38+I38+J38+K38+L38+M38 -> 0 | O38: =F38*N38 -> 0 | P38: 厂制品
A39: 32 | B39: 五金配件 | E39: 项 | F39: 1 | K39: =(G39+H39+I39+J39)*$K$7 -> 0 | L39: =(G39+H39+I39+J39+K39)*$L$7 -> 0 | M39: =(G39+H39+I39+J39+K39+L39)*$M$7 -> 0 | N39: =G39+H39+I39+J39+K39+L39+M39 -> 0 | O39: =F39*N39 -> 0 | P39: 厂制品
A40: 33 | B40: 安装费 | E40: 项 | F40: 1 | K40: =(G40+H40+I40+J40)*$K$7 -> 0 | L40: =(G40+H40+I40+J40+K40)*$L$7 -> 0 | M40: =(G40+H40+I40+J40+K40+L40)*$M$7 -> 0 | N40: =G40+H40+I40+J40+K40+L40+M40 -> 0 | O40: =F40*N40 -> 0
...

Sheet 二、05干蒸房工程量清单
A1: 岁宝壹品苑一期
A2: C栋32层会所精装修工程
A3: 第二章 - 05号清单 干蒸房工程量清单
A4: 分部分项工程量清单
A5: 序号 | B5: 产品图片 | C5: 产品名称 | D5: 产地 | E5: 规 格 说 明 | F5: 单位 | G5: 数量 | H5: 含税综合单价（元） | I5: 含税合价（元） | J5: 备注
A6: 1 | C6: 加拿大铁杉桑拿房体 | D6: 加拿大 | E6: 1.墙面内饰板材：加拿大进口铁杉木12mm厚 2.墙面外饰板材：加拿大进口铁杉木12mm厚 3.框架结构：芬兰松木40mm厚 4.座板材料：加拿大进口铁杉木20mm厚 5.靠背材料：加拿大进口铁杉木20mm厚 6.见光面加拿大进口香杉木原 加拿大： 铁杉易于防火处理具有较高的抗弯强度及自然的防腐能力，质地细密，纹理直且均匀，木纹清晰漂亮是桑拿房的最佳选材. 坚固的木架结构，在任何季节都具有超强的隔热和抗阻能力。桑拿房简洁而优雅，私人桑拿房可享受10年保修，施工由我们训练有素的专业人员进行。 | F6: 平方 | G6: 10.64 | I6: =G6*H6 -> 0
A7: 2 | C7: 加拿大铁杉座板 | D7: 加拿大 | E7: 座板材料：加拿大进口铁杉木20mm厚 厚实木板才20mm顶级无节、光滑平整度高，无树脂渗出，纯白色无色差， 色彩的整体与和谐是这种设计的核心。对于较小的房间，我们有独一无二的长椅和凳子设计。一致性是桑度的基本要求。因此，再也看不到其他种类的木材了。 爱细节才是最重要的 | F7: 米 | G7: 1.7 | I7: =G7*H7 -> 0
A8: 3 | C8: Virta 11KW | D8: 芬兰 | E8: Harvia Virta加热器坚固的结构和特别容易维护，使它非常适合那些经常使用桑拿，喜欢长时间享受蒸汽的人。所有与Virta加热器的连接都是通过前面的维修舱口进行的。连接处周围有足够的空间。加热元件与石材分离，使加热元件寿命长。如果你需要更换一个加热元件，这是一个快速而简单的任务，因为你只需要拔出整个加热元件模块。其他维护措施包括 | F8: 台 | G8: 1 | I8: =G8*H8 -> 0
A9: 4 | C9: 麦饭石 | D9: 德国 | E9: 麦饭石富含多种微量元素，常量元素 安全性高，高温不爆裂 使用寿命长，可商用24小时加热 | F9: 公斤 | G9: 20 | I9: =G9*H9 -> 0
A10: 5 | C10: 防烫伤炉架 | D10: 德国 | E10: 材料：加拿大进口铁杉木 防烫伤桑拿炉架材料：加拿大进口铁杉木22*400mm 外观精致时尚，简约典雅，精工细作，浑然天成，选用加拿大进口铁杉木材质更加浸润人体肌肤，彰显时尚的气息。 | F10: 个 | G10: 1 | I10: =G10*H10 -> 0
A11: 6 | C11: EOS灯罩 | D11: 德国 | E11: 铁杉木加304不锈钢 | F11: 个 | G11: 2 | I11: =G11*H11 -> 0
A12: 7 | C12: 室外控制器 | D12: 德国 | E12: lles im Griff – am Display und mobil.Entspannung per Fingertipp Die EOS U-Command zeigt nur das, was wirklich zählt: Start, Temperatur, Feuchte, Laufzeit – klar, logisch, auf einen Blick und mit einem Fingertipp starten Sie das Wellnesserlebnis. Nutzerprofile speichern persönliche Vorlieben, machen die Bedienung noch komfortabler und passen es an Ihre Wünsche an. Multi-Cabin Support Bedienen Sie bis zu zwei Kabinen mit nur einem Bedienteil – übersichtlich und sicher. Ob Sauna, Infrarot, Hybridsauna, Dampfbad oder Hammam: Sie nutzen eine Bedienlogik für alles. | F12: 块 | G12: 1 | I12: =G12*H12 -> 0
A13: 8 | C13: EOS远红外背部理疗器 | D13: 德国 | E13: 用于桑拿和IR热室的红外热辐射器。 就像EOS Vitae，但是缩短的建筑形状- ca。长745毫米. 采用EOS玻璃石英玻璃发射器350，500，750瓦。IR-A、IR-B和IR-C全光谱热辐射，在不到1秒的时间内完成性能折叠。 500瓦和750瓦版本，带集成启动电流限制器。 机箱和反射器。防护絮凝剂复盖网(黑色)。 完全预装3 m硅胶连接器线3x 1.5mm。 可选择安装在90度角或墙嵌板中。墙嵌板中的安装深度为50 mm | F13: 套 | G13: 2 | I13: =G13*H13 -> 0
A14: 9 | C14: 自动洒水装置 | D14: 中国 | E14: 桑拿炉自动喷淋装置的原理 桑拿炉自动喷淋装置是桑拿房中常见的一个组件，其作用是在桑拿房内产生水蒸气，增加室内温度和湿度，提高桑拿效果。该装置包括计时器、电磁阀、水泵和喷嘴等组成部分。当计时器到达设定时间后，电磁阀开启，水泵开启，水被喷嘴喷出，形成水蒸气。 | F14: 套 | G14: 1 | I14: =G14*H14 -> 0
A15: 10 | C15: 防臭地漏 | D15: 中国 | E15: 深水封地漏‌：靠底部存水形成水封隔绝臭气，防臭效果最稳定，但需要经常有水补充，‌适合淋浴区等湿区使用‌。 ‌重力翻板地漏‌：排水时水流冲开翻板，没水时靠重力自动闭合，‌干区和厨房用这个更合适‌，不用依赖存水。 ‌磁吸自封地漏‌：靠磁力吸合密封垫，排水时冲开，闭合时防臭，但磁力可能随时间减弱，‌适合短期使用或备用‌。 | F15: 只 | G15: 1 | I15: =G15*H15 -> 0
A16: 11 | C16: EOS 木桶木勺 | D16: 德国 | E16: 桑拿原木桶材料：加拿大铁杉木260*200mm 一桶水3000ml半个小时用完，欧洲人所称之为一个疗程 经典款木桶木勺，木质外观，带防漏内胆，钣金扣边.最简洁的设计，最复古的感 觉,带给您原始桑拿的意境. | F16: 套 | G16: 1 | I16: =G16*H16 -> 0
A17: 12 | C17: 防烫伤拉手 | D17: 德国 | E17: 特制玻璃门拉手，隐藏式安装工艺，机床精密车削加工，内木质囿柱，合理设计，内高温木质不烫手。 | F17: 副 | G17: 1 | I17: =G17*H17 -> 0
... A19: 14 | C19: 头枕 | D19: 德国 | E19: 多功能头枕. 加拿大铁杉木材质，平放可以垫头、立放可以垫腰、挂置可以靠背.人体背部曲线设计. | F19: 个 | G19: 2 | I19: =G19*H19 -> 0
A20: 15 | B20: EOS温度湿度表 | C20: EOS温湿表 | D20: 德国 | E20: 专为具有特殊设计和功能需求的客户设计的独家气候测量站。 圆形测量仪器 100 mm温度计和湿度计，测量范围为0 ~ 120°c。0 - 100 %继电器，空气湿度。尺寸340×195mm。墙面挂载。 | F20: 个 | G20: 1 | I20: =G20*H20 -> 0
A21: 16 | C21: 茶水架 | D21: 德国 | E21: 汗蒸时可带水放到茶水架中，集工艺设计与实用便利于一体，原生态木材品质，极简主义淋漓尽致。简单即是优雅。 | F21: 个 | G21: 2 | I21: =G21*H21 -> 0
A22: 17 | C22: 4英寸同轴防水耐高温喇叭 | D22: 德国 | E22: 外部尺寸133×59mm 安装桑拿和蒸汽浴室的扬声器 25 W额定电阻(8欧姆、10公分(4英寸)、玻璃纤维膜、120 °C温度规格–适用于桑拿、户外使用、防水。白色的复盖框。 IP65保护类。 | F22: 只 | G22: 2 | I22: =G22*H22 -> 0
A23: 18 | C23: RGB顶灯 | D23: 德国 | E23: 优质青光玱璃灯罩可对照明设备进行二次防护，防腐、防锈、 德国工艺精工制作。照明设备不德国白杉灯罩完美结合，传递出时尚不潮流，幵带您感受芬兰桑拿文化所传递的艺术美感。 | F23: 套 | G23: 1 | I23: =G23*H23 -> 0
A24: 19 | C24: EOS高温灯带 | D24: 德国 | E24: 坐板凳暖光灯 LED光束专用灵活的版本，专为蒸汽浴和潮湿环境而设计。24伏直流，60瓦。ip 68 . dimmbar保护类(基于电压)。长度约5米，两侧有5 m的接头线。自我修复，加上可靠的支架机械固定。提供RGB和白色(3000 K)两种类型。以10厘米为增量进行分割/修剪。 | F24: 米 | G24: 3.4 | I24: =G24*H24 -> 0
A25: 20 | C25: EOS 高温整流器 | D25: 德国 | E25: LED条纹和LED斑点的电子流量。60瓦运行-输入230-240 vac(0.36 a)/输出24 V DC (2500 mA)。铝制外壳，IP65保护等级，含ca。两侧15厘米接头导线。执行30 W-交流输入220-240v/直流输出24v(2500ma)。塑料外壳。IP20保护类。例如，建议使用。用于白色LED带，并连接到Saunders设备。 | F25: 个 | G25: 1 | I25: =G25*H25 -> 0
A26: 21 | C26: 安全温感探头及耐高温控制线、电缆线 | D26: 德国 | E26: 耐高温控制线 温度探头采用即时数据传输设计，探点式结 极，保证温度数据传输的同 时，配置有过温保险丝。在温度超过设定范围后，保险丝自动熔断所有工作停止，以保证用户的绝对安全。 电缆线采用耐热硅橡胶护套的优质接线盒(红色)。非常适合连接桑拿浴技术。不同的横截面和长度。如果需要，长度也应大于指定的装运长度。 | F26: 批 | G26: 1 | I26: =G26*H26 -> 0
A27: 22 | C27: EOS 主机控电箱 | D27: 德国 | E27: 定制桑拿房专用主电控系统，自带高精度开关电源，微电脑智能控制系统，兼容220V，380V交流电压。自身能有效进行过热、过载、断路等多重保护。 | F27: 套 | G27: 1 | I27: =G27*H27 -> 0
A28: 23 | C28: 安全门磁吸 | D28: 中国 | E28: 6 mm和8 mm玻璃门的u形对接板，不锈钢磁吸 6-8mm 铝/锌合金玻璃门。承载能力:28公斤/件。尺寸B x H: 0.8毫米x 2200毫米 | F28: 个 | G28: 1 | I28: =G28*H28 -> 0
A29: 24 | C29: 哈维亚专用安全门 | D29: 芬兰 | E29: 天地轴/极窄边框/钢化/单玻/桑拿安全门（800*2200*8mm） | F29: 平方 | G29: 1.76 | I29: =G29*H29 -> 0
A30: 25 | C30: 紧急报警 | D30: 中国 | E30: 智能家居紧急按钮‌：卧室、浴室可安装紧急报警按钮，触发后能发出高分贝警报并自动拨打预设联系人。 | F30: 个 | G30: 1 | I30: =G30*H30 -> 0
A31: 26 | C31: 配电箱 | D31: 中国 | E31: 定制桑拿房专用主电控系统，自带高精度开关电源，微电脑智能控制系统，兼容220V，380V交流电压。自身能有效进行过热、过载、断路等多重保护。 | F31: 套 | G31: 1 | I31: =G31*H31 -> 0
A32: 27 | C32: 瓦工服务 | D32: 桑度 | E32: 地面做排水，水平瓷砖铺贴 | F32: 项 | G32: 1 | I32: =G32*H32 -> 0
... A35: 30 | C35: 1年免费认证电工服务 | D35: 桑度 | E35: 1、拥有专业的安装售后团队， 能快速、有效地提供强大的技术支持； 2、服务内容：售前的技术咨询，专业人员进行场地的设计、规划、系统安装、调试、培训； 3、项目实施过程中的装修指导；设备的 安装与调试；售后支持。 | F35: 年 | G35: 1 | I35: =G35*H35 -> 0
A36: 31 | B36: 合计： | I36: =SUM(I6:I35) -> 0
