Workbook
Name ___________________N81020: [1]地梁!#REF!
Name dw: #REF!
Name dw: #REF!
Name dw: #REF!
Name A: EVALUATE(SUBSTITUTE(SUBSTITUTE(#REF!,"[","*ISTEXT(""["),"]","]"")"))
Name A: EVALUATE(SUBSTITUTE(SUBSTITUTE(#REF!,"[","*ISTEXT(""["),"]","]"")"))

Sheet 编制说明
A1: 编制说明
A2: 1、工程概况：
A3: 1）、工程名称：珠海丹田海德公馆会所精装修工程
A4: 2）、建设单位：丹田海德公馆
A5: 3）、工程内容：会所、公区装修及机电
A6: 2、编制依据：
A7: 1）、按建设单位提供的《珠海海德公馆会所项目施工图20260529》及《珠海丹田海德公馆会所施工手册》、《酒窖深化图》；
A8: 3、编制范围：
A9: 1）、海德公馆大堂、电梯厅、电梯轿厢、三楼会所、健身房等室内装修工程。 包括：大堂、电梯厅、电梯轿厢、会所、健身房地面、墙面、天花等；
A10: 4、计价说明：
A11: 1）、综合单价综合考虑人工费、各类材料费（含损耗）、机械费、项目措施费（地下暗室施工费、技术措施费、安全文明施工费、临时设施费）、成品保护费、运输装卸费、材料设备场内二次运输费[在合同总工期内施工过程中因各种因素导致需二次运输作业，搬运距离，自行勘察现场]、材料检测试验费、检测费、调试费、验收费、保险费（不包含甲方已购买保险）、规费、管理费、利润、国家强制性收费、风险责任、施工水电费、克服施工现场苛刻条件及难度费用等除监理费之外的全部费用除非另有约定，结算时该综合单价不调整、税金在汇总单独计算。
A12: 5、其他说明
... A15: 3、根据图纸设计说明墙面瓷砖瓷砖大于400*800规格采用C2T等级增强型水泥基胶粘剂,由于项目中不同区域使用的瓷砖规格大小有不一,清单中统一描述为C1T等级增强型水泥基胶粘剂,最终根据项目中各区域使用的瓷砖规格选择相应规格胶粘剂；

Sheet 汇总表
A1: 报价汇总表
A2: 工程名称：珠海丹田海德公馆会所精装修工程
A3: 序号 | B3: 名称 | C3: 单层装修面积（m2） | D3: 层数 | E3: 单层造价（元） | F3: 总造价（元） | G3: 单方指标 | H3: 备注
A4: 1 | B4: 首层装修部分（北向） | C4: 274.13 | D4: 1 | E4: =+地上装修工程!K4 -> 0 | F4: =E4*D4 -> 0 | G4: =+E4/C4 -> 0
A5: 2 | B5: 首层装修部分（南向） | C5: 303.3 | D5: 1 | E5: =+地上装修工程!K168 -> 0 | F5: =E5*D5 -> 0 | G5: =+E5/C5 -> 0
A6: 3 | B6: 标准层装修部分(四~三十一层) | C6: 59.41 | D6: 28 | E6: =+地上装修工程!K336 -> 0 | F6: =E6*D6 -> 0 | G6: =+E6/C6 -> 0
A7: 4 | B7: 会所装修部分（三层） | C7: 887.57 | D7: 1 | E7: =+地上装修工程!K448 -> 0 | F7: =E7*D7 -> 0 | G7: =+E7/C7 -> 0
A8: 5 | B8: 健身房装修部分（三层） | C8: 278.86 | D8: 1 | E8: =+地上装修工程!K911 -> 0 | F8: =E8*D8 -> 0 | G8: =+E8/C8 -> 0
A9: 6 | B9: 负一层装修部分 | C9: 103.84 | D9: 1 | E9: =+地下室装修工程!K4 -> 0 | F9: =E9*D9 -> 0 | G9: =+E9/C9 -> 0
A10: 7 | B10: 负二层装修部分 | C10: 92.34 | D10: 1 | E10: =+地下室装修工程!K105 -> 0 | F10: =E10*D10 -> 0 | G10: =+E10/C10 -> 0
A11: 8 | B11: 负三层装修部分 | C11: 77.93 | D11: 1 | E11: =+地下室装修工程!K204 -> 0 | F11: =E11*D11 -> 0 | G11: =+E11/C11 -> 0
A12: 9 | B12: 电梯轿厢 | C12: =2.34*2 -> 4.68 | D12: 4 | E12: =+电梯轿厢装修工程!K44 -> 0 | F12: =E12*D12 -> 0 | G12: =+E12/C12 -> 0 | H12: 1个电梯轿厢+1个无障碍电梯轿厢
A13: 10 | B13: 安装工程 | C13: =C4+C5+C6*D6+C7+C8+C9+C10+C11+C12*D12 -> 3700.17 | D13: 1 | E13: =会所安装工程量清单!K223 -> 0 | F13: =E13*D13 -> 0 | G13: =+E13/C13 -> 0
A14: 11 | B14: 措施费 | C14: =C13 -> 3700.17 | D14: 1 | E14: =+措施费!K7 -> 0 | F14: =E14*D14 -> 0 | G14: =+E14/C14 -> 0
A15: 12 | B15: 小计 | C15: =+$C$14 -> 3700.17 | F15: =SUM(F4:F14) -> 0 | G15: =+E15/C15 -> 0
A16: 13 | B16: 税金（9%） | C16: =+$C$14 -> 3700.17 | F16: =+F15*9% -> 0 | G16: =+E16/C16 -> 0
B17: 总计 | C17: =+$C$14 -> 3700.17 | F17: =+F15+F16 -> 0 | G17: =+E17/C17 -> 0

Sheet 地上装修工程
A1: 珠海海德公馆会所项目-工程量清单
A2: 序号 | B2: 项目名称 | C2: 项目特征 | D2: 单位 | E2: 工程量 | F2: 人工 | G2: 主材 | H2: 辅材及机械费 | I2: 管理及利润取费 | J2: 综合单价 （不含税） | K2: 合价 （不含税） | L2: 备注 | M2: 检查
M3: 1 | N3: 2
A4: A | B4: 首层装修部分（北向） | K4: =SUM(K5:K167) -> 0
A5: 一 | B5: 一层电梯厅、设备间（DT1） | O5: =_xlfn.DISPIMG("ID_7F15BB9A08234B43B10CC616E0663C90",1) -> =DISPIMG("ID_7F15BB9A08234B43B10CC616E0663C90",1)
B6: 地面工程
A7: =1+N(A6) -> 1 | B7: 地面铺贴大理石ST-01 | C7: 1.地面20mm大理石ST-01、铺贴、厚度及样式按物料书为准； 2.10mm厚石材专用粘结剂； 3.70mm厚DS-M15干混砂浆找平； 4.基层清理、石材六面防护、背面刷胶封闭,同色云石胶补缝； 5.含开槽、磨边、倒角、拼接等处理； 6.包含完成该项内容所有工作及费用并满足设计图纸、规范等要求； | D7: m2 | E7: 18.57 | I7: =(F7+G7+H7)*$I$3 -> 0 | J7: =ROUND(SUM(F7:I7),2) -> 0 | K7: =ROUND(J7*E7,2) -> 0 | M7: 1
A8: =1+N(A7) -> 2 | B8: 地面铺贴大理石ST-01.02拼花 | C8: 1.地面20mm大理石拼花、参考3F-DF-01样式、ST-01、ST-02按物料书为准； 2.10mm厚石材专用粘结剂； 3.70mm厚DS-M15干混砂浆找平； 4.基层清理、石材六面防护、背面刷胶封闭,同色云石胶补缝； 5.含开槽、磨边、倒角、拼接等处理； 6.包含完成该项内容所有工作及费用并满足设计图纸、规范等要求； | D8: m2 | E8: 10.62 | I8: =(F8+G8+H8)*$I$3 -> 0 | J8: =ROUND(SUM(F8:I8),2) -> 0 | K8: =ROUND(J8*E8,2) -> 0 | M8: 1
A9: =1+N(A8) -> 3 | B9: 地面地砖 CT-06 | C9: 1.地面花砖CT-06； 2.10mm厚专用粘结剂； 3.80mm厚DS-M15干混砂浆找平； 4.基层清理； 5.含切边、倒角、拼接等处理； 6.包含完成该项内容所有工作及费用并满足设计图纸、规范等要求； | D9: m2 | E9: 2.58 | I9: =(F9+G9+H9)*$I$3 -> 0 | J9: =ROUND(SUM(F9:I9),2) -> 0 | K9: =ROUND(J9*E9,2) -> 0 | M9: 1
A10: =1+N(A9) -> 4 | B10: 实心铜条5mm宽 | C10: 1.实心铜条5mm宽； 2.包含完成该项内容所有工作及费用并满足设计图纸、规范等要求； | D10: m | E10: 12.77 | I10: =(F10+G10+H10)*$I$3 -> 0 | J10: =ROUND(SUM(F10:I10),2) -> 0 | K10: =ROUND(J10*E10,2) -> 0 | M10: 1
A11: =1+N(A10) -> 5 | B11: 地面石材晶面处理 | C11: 1.石材结晶处理(结晶水及石材保养剂,中性清洁剂)； 2.包含完成该项内容所有工作及费用并满足设计图纸、规范等要求； | D11: m2 | E11: 14.77 | I11: =(F11+G11+H11)*$I$3 -> 0 | J11: =ROUND(SUM(F11:I11),2) -> 0 | K11: =ROUND(J11*E11,2) -> 0 | M11: 1
B12: 墙柱面工程
A13: =1+N(A12) -> 1 | B13: 墙面湿贴石材ST-05 | C13: 1、墙面湿贴石材ST-05 2、8mm厚石材专用胶粘剂WC粘结层 3、界面剂拉毛处理 4、石材的开槽、磨边、倒角、粘接、形成所需之凹坑、抛光、六面防污防渗等一切处理费用均在主材费中考虑，不再另行计取 5、包含完成该项内容所有工作及费用并满足设计图纸、规范等要求 | D13: m2 | E13: 12.933 | I13: =(F13+G13+H13)*$I$3 -> 0 | J13: =ROUND(SUM(F13:I13),2) -> 0 | K13: =ROUND(J13*E13,2) -> 0 | M13: 1
A14: =1+N(A13) -> 2 | B14: 墙面干挂ST-05石材 | C14: 1、墙面干挂ST-05石材 2、不锈钢背栓挂件安装，云石胶+AB胶固定 3、镀锌角钢钢架(高度超4m、完成面超150mm采用槽钢基层加固)，钢架防锈处理 4、膨胀螺栓固定预埋铁件(轻质砖墙体需要穿墙螺栓固定) 5、石材的开槽、磨边、倒角、粘接、形成所需之凹坑、抛光、六面防污防渗等一切处理费用均在主材费中考虑，不再另行计取 6、包含完成该项内容所有工作及费用并满足设计图纸、规范等要求 | D14: m2 | E14: =58.817+0.727 -> 59.544 | I14: =(F14+G14+H14)*$I$3 -> 0 | J14: =ROUND(SUM(F14:I14),2) -> 0 | K14: =ROUND(J14*E14,2) -> 0 | M14: 1
A15: =1+N(A14) -> 3 | B15: 墙面干挂ST-05石材（波浪造型） | C15: 1、墙面干挂ST-05石材（波浪造型） 2、不锈钢背栓挂件安装，云石胶+AB胶固定 3、镀锌角钢钢架(高度超4m、完成面超150mm采用槽钢基层加固)，钢架防锈处理 4、膨胀螺栓固定预埋铁件(轻质砖墙体需要穿墙螺栓固定) 5、石材的开槽、磨边、倒角、粘接、形成所需之凹坑、抛光、六面防污防渗等一切处理费用均在主材费中考虑，不再另行计取 6、包含完成该项内容所有工作及费用并满足设计图纸、规范等要求 | D15: m2 | E15: 2.91 | I15: =(F15+G15+H15)*$I$3 -> 0 | J15: =ROUND(SUM(F15:I15),2) -> 0 | K15: =ROUND(J15*E15,2) -> 0 | M15: 1
A16: =1+N(A15) -> 4 | B16: 墙面PT-02白色防水无机涂料 | C16: 1、墙面PT-02白色防水无机涂料(底漆1遍，面漆2遍) 2、刮白胶腻子找平二遍，打磨 3、阴、阳角护角收边 4、双层9.5mm纸面石膏板 5、轻钢龙骨基层找平 6、包含完成该项内容所有工作及费用并满足设计图纸、规范等要求 | D16: m2 | E16: =16.107+1*(3-2) -> 17.107 | I16: =(F16+G16+H16)*$I$3 -> 0 | J16: =ROUND(SUM(F16:I16),2) -> 0 | K16: =ROUND(J16*E16,2) -> 0 | M16: 1
A17: =1+N(A16) -> 5 | B17: 不锈钢门套 | C17: 1、1.2mm厚 MT-01古铜不锈钢门套，结构胶固定 2、9厘玻镁板基层 3、工程量以展开面积计算 4、包含完成该项内容所有工作及费用并满足设计图纸、规范等要求 | D17: m2 | E17: =0.29*2*2+0.98*0.26 -> 1.4148 | I17: =(F17+G17+H17)*$I$3 -> 0 | J17: =ROUND(SUM(F17:I17),2) -> 0 | K17: =ROUND(J17*E17,2) -> 0 | M17: 1
A18: =1+N(A17) -> 6 | B18: 电梯不锈钢门套 | C18: 1、1.2mm厚 MT-01古铜不锈钢门套，结构胶固定 2、9厘玻镁板基层 3、工程量以展开面积计算 4、包含完成该项内容所有工作及费用并满足设计图纸、规范等要求 | D18: m2 | E18: =0.296*3*2*2 -> 3.552 | I18: =(F18+G18+H18)*$I$3 -> 0 | J18: =ROUND(SUM(F18:I18),2) -> 0 | K18: =ROUND(J18*E18,2) -> 0 | M18: 1
A19: =1+N(A18) -> 7 | B19: 电梯不锈钢门头 | C19: 1、1.2mm厚 MT-01古铜不锈钢门头，结构胶固定 2、12mm阻燃板，轻钢副龙骨@400 3、电梯门顶内置亚克力，内部面层刮白处理 4、工程量以展开面积计算 5、包含完成该项内容所有工作及费用并满足设计图纸、规范等要求 | D19: m2 | E19: =+(0.061+0.72+0.114+0.074)*0.95*2 -> 1.8411 | I19: =(F19+G19+H19)*$I$3 -> 0 | J19: =ROUND(SUM(F19:I19),2) -> 0 | K19: =ROUND(J19*E19,2) -> 0 | M19: 1
A20: =1+N(A19) -> 8 | B20: MT-01古铜不锈钢饰面（电梯按钮处） | C20: 1、1.2mm厚 MT-01古铜不锈钢饰面 2、12mm阻燃板基层，轻钢副龙骨@400 3、工程量以展开面积计算 4、包含完成该项内容所有工作及费用并满足设计图纸、规范等要求 | D20: m2 | E20: 0.252 | I20: =(F20+G20+H20)*$I$3 -> 0 | J20: =ROUND(SUM(F20:I20),2) -> 0 | K20: =ROUND(J20*E20,2) -> 0 | M20: 1
A21: =1+N(A20) -> 9 | B21: 50mm CT-06瓷砖踢脚 | C21: 1、50mm CT-06瓷砖踢脚,瓷砖填缝剂处理 2、背覆胶处理 3、C1T等级抗滑移水泥基胶粘剂 4、界面剂拉毛处理 5、包含完成该项内容所有工作及费用并满足设计图纸、规范等要求 | D21: m2 | E21: 0.273 | I21: =(F21+G21+H21)*$I$3 -> 0 | J21: =ROUND(SUM(F21:I21),2) -> 0 | K21: =ROUND(J21*E21,2) -> 0 | M21: 1
A22: =1+N(A21) -> 10 | B22: MT-01古铜不锈钢踢脚线（高20mm） | C22: 1、1.2mm厚 MT-01古铜不锈钢踢脚线（高20mm，展开面为46mm），结构胶固定 2、9厘玻镁板基层 3、包含完成该项内容所有工作及费用并满足设计图纸、规范等要求 | D22: m | E22: 25.71 | I22: =(F22+G22+H22)*$I$3 -> 0 | J22: =ROUND(SUM(F22:I22),2) -> 0 | K22: =ROUND(J22*E22,2) -> 0 | M22: 1
A23: =1+N(A22) -> 11 | B23: MT-01古铜不锈钢线条（展开面为54mm） | C23: 1、1.2mm厚 MT-01古铜不锈钢线条（展开面为54mm），结构胶固定 2、9厘玻镁板基层 3、包含完成该项内容所有工作及费用并满足设计图纸、规范等要求 | D23: m | E23: =0.17*2 -> 0.34 | I23: =(F23+G23+H23)*$I$3 -> 0 | J23: =ROUND(SUM(F23:I23),2) -> 0 | K23: =ROUND(J23*E23,2) -> 0 | M23: 1
A24: =1+N(A23) -> 12 | B24: MT-01古铜不锈钢线条（展开面为69mm） | C24: 1、1.2mm厚 MT-01古铜不锈钢线条（展开面为69mm），结构胶固定 2、9厘玻镁板基层 3、包含完成该项内容所有工作及费用并满足设计图纸、规范等要求 | D24: m | E24: 0.96 | I24: =(F24+G24+H24)*$I$3 -> 0 | J24: =ROUND(SUM(F24:I24),2) -> 0 | K24: =ROUND(J24*E24,2) -> 0 | M24: 1
A25: =1+N(A24) -> 13 | B25: MT-01古铜不锈钢线条（展开面为114mm） | C25: 1、1.2mm厚 MT-01古铜不锈钢线条（展开面为114mm），结构胶固定 2、9厘玻镁板基层 3、包含完成该项内容所有工作及费用并满足设计图纸、规范等要求 | D25: m | E25: 24.41 | I25: =(F25+G25+H25)*$I$3 -> 0 | J25: =ROUND(SUM(F25:I25),2) -> 0 | K25: =ROUND(J25*E25,2) -> 0 | M25: 1
A26: =1+N(A25) -> 14 | B26: MT-01古铜不锈钢顶部收口条（展开面为41mm） | C26: 1、1.2mm厚 MT-01古铜不锈钢顶部收口条（展开面为41mm），结构胶固定 2、9厘玻镁板基层 3、包含完成该项内容所有工作及费用并满足设计图纸、规范等要求 | D26: m | E26: 25.71 | I26: =(F26+G26+H26)*$I$3 -> 0 | J26: =ROUND(SUM(F26:I26),2) -> 0 | K26: =ROUND(J26*E26,2) -> 0 | M26: 1
B27: 天花工程
A28: =1+N(A27) -> 1 | B28: 造型石膏板吊顶 | C28: 1.60系列轻钢主龙骨@900，60系列轻钢副龙骨@400，60系列横撑龙骨@600，08螺纹吊杆@900不上人天花吊顶（投影面计算） 2.玻镁板、双层9.5厚石膏板基层，含开孔、检修口、10*10凹槽等费用； 3.含除灯槽外的侧面高差及其连接件、吊件； 4.包含完成该项内容所有工作及费用并满足设计图纸、规范等要求； | D28: m2 | E28: 31.77 | I28: =(F28+G28+H28)*$I$3 -> 0 | J28: =ROUND(SUM(F28:I28),2) -> 0 | K28: =ROUND(J28*E28,2) -> 0 | M28: 1
A29: =1+N(A28) -> 2 | B29: 灯槽（100mm*200mm） | C29: 1.灯槽（100mm*200mm）； 2.双层板：9mm玻镁板、9.5厚石膏板； 3.包含完成该项内容所有工作及费用并满足设计图纸、规范等要求； | D29: m | E29: 12.73 | I29: =(F29+G29+H29)*$I$3 -> 0 | J29: =ROUND(SUM(F29:I29),2) -> 0 | K29: =ROUND(J29*E29,2) -> 0 | M29: 1
A30: =1+N(A29) -> 3 | B30: 成品石膏线条 | C30: 1.成品石膏线条（50mm*50mm）； 2.按图纸造型； 3.包含完成该项内容所有工作及费用并满足设计图纸、规范等要求； | D30: m | E30: 12.73 | I30: =(F30+G30+H30)*$I$3 -> 0 | J30: =ROUND(SUM(F30:I30),2) -> 0 | K30: =ROUND(J30*E30,2) -> 0 | M30: 1
A31: =1+N(A30) -> 4 | B31: 条形空调风口（150mm） | C31: 1.条形空调风口（150mm）； 2.风口周边阻燃板封边加固处理； 3.包含完成该项内容所有工作及费用并满足设计图纸、规范等要求； | D31: m | E31: =1.2*2*1 -> 2.4 | I31: =(F31+G31+H31)*$I$3 -> 0 | J31: =ROUND(SUM(F31:I31),2) -> 0 | K31: =ROUND(J31*E31,2) -> 0 | M31: 1
A32: =1+N(A31) -> 5 | B32: 天花肌理无机涂料PT-01 | C32: 1.天花肌理无机涂料PT-01； 2.刮腻子二遍磨平； 3.底漆1遍，面漆2遍； 4.包含完成该项内容所有工作及费用并满足设计图纸、规范等要求； | D32: m2 | E32: =31.77+12.73*0.3 -> 35.589 | I32: =(F32+G32+H32)*$I$3 -> 0 | J32: =ROUND(SUM(F32:I32),2) -> 0 | K32: =ROUND(J32*E32,2) -> 0 | M32: 1
B33: 门窗、家具工程
A34: =1+N(A33) -> 1 | B34: 设备间暗门(不含面层) | C34: 1、40x40x5mm热镀锌方管骨架、背封铝塑板 2、含天地轴、门吸等五金配件 3、包含完成该项内容所有工作及费用并满足设计图纸、规范等要求 | D34: m2 | E34: =0.96*3 -> 2.88 | I34: =(F34+G34+H34)*$I$3 -> 0 | J34: =ROUND(SUM(F34:I34),2) -> 0 | K34: =ROUND(J34*E34,2) -> 0 | M34: 1
A35: =1+N(A34) -> 2 | B35: 电梯厅门（参DR01） | C35: 1、门扇：1.2mm厚 MT-01古铜不锈钢饰面、GL-01超白钢化玻璃、ST-08石材、L40*40*4镀锌角钢骨架 2、门套：1.2mm厚 MT-01古铜不锈钢饰面 3、定制成品套装门制安 4、含电机、暗铰链、地弹簧等五金配件 5、包含完成该项内容所有工作及费用并满足设计图纸、规范等要求 | D35: m2 | E35: =1.84*3 -> 5.52 | I35: =(F35+G35+H35)*$I$3 -> 0 | J35: =ROUND(SUM(F35:I35),2) -> 0 | K35: =ROUND(J35*E35,2) -> 0 | M35: 1
A36: =1+N(A35) -> 3 | B36: 固定玻璃隔断 | C36: 1、GL-01超白钢化玻璃饰面 2、1.2mm厚 MT-01古铜不锈钢饰面边框 3、包含完成该项内容所有工作及费用并满足设计图纸、规范等要求 | D36: m2 | E36: =1.71*3 -> 5.13 | I36: =(F36+G36+H36)*$I$3 -> 0 | J36: =ROUND(SUM(F36:I36),2) -> 0 | K36: =ROUND(J36*E36,2) -> 0 | M36: 1
A37: 二 | B37: 一层入户大堂、前室（上） | O37: =_xlfn.DISPIMG("ID_EC83A7CF2DCE420D98B785E34F0891B0",1) -> =DISPIMG("ID_EC83A7CF2DCE420D98B785E34F0891B0",1)
B38: 地面工程
A39: =1+N(A38) -> 1 | B39: 地面铺贴大理石ST-01 | C39: 1.地面20mm大理石ST-01、铺贴、厚度及样式按物料书为准； 2.10mm厚石材专用粘结剂； 3.70mm厚DS-M15干混砂浆找平； 4.基层清理、石材六面防护、背面刷胶封闭,同色云石胶补缝； 5.含开槽、磨边、倒角、拼接等处理； 6.包含完成该项内容所有工作及费用并满足设计图纸、规范等要求； | D39: m2 | E39: 30.5 | I39: =(F39+G39+H39)*$I$3 -> 0 | J39: =ROUND(SUM(F39:I39),2) -> 0 | K39: =ROUND(J39*E39,2) -> 0 | M39: 1 | O39: 29.2
A40: =1+N(A39) -> 2 | B40: 地面铺贴大理石ST-01.03拼花 | C40: 1.地面20mm大理石拼花、参考3F-DF-01样式、ST-01、ST-03按物料书为准； 2.10mm厚石材专用粘结剂； 3.70mm厚DS-M15干混砂浆找平； 4.基层清理、石材六面防护、背面刷胶封闭,同色云石胶补缝； 5.含开槽、磨边、倒角、拼接等处理； 6.包含完成该项内容所有工作及费用并满足设计图纸、规范等要求； | D40: m2 | E40: 41.2 | I40: =(F40+G40+H40)*$I$3 -> 0 | J40: =ROUND(SUM(F40:I40),2) -> 0 | K40: =ROUND(J40*E40,2) -> 0 | M40: 1
...

Sheet 电梯轿厢装修工程
A1: 珠海海德公馆会所项目-工程量清单
A2: 序号 | B2: 项目名称 | C2: 项目特征 | D2: 单位 | E2: 工程量 | F2: 人工 | G2: 主材 | H2: 辅材及机械费 | I2: 管理及利润取费 | J2: 综合单价 （不含税） | K2: 合价 （不含税） | L2: 备注
A4: A | B4: 电梯轿厢 | K4: =SUM(K5:K23) -> 0
B5: 地面工程
A6: =1+N(A5) -> 1 | B6: 地面铺贴大理石ST-01 | C6: 1.地面20mm大理石ST-01、铺贴、厚度及样式按物料书为准； 2.10mm厚石材专用粘结剂； 3.70mm厚DS-M15干混砂浆找平； 4.基层清理、石材六面防护、背面刷胶封闭,同色云石胶补缝； 5.含开槽、磨边、倒角、拼接等处理； 6.包含完成该项内容所有工作及费用并满足设计图纸、规范等要求； | D6: m2 | E6: 2.337 | I6: =(F6+G6+H6)*$I$3 -> 0 | J6: =ROUND(SUM(F6:I6),2) -> 0 | K6: =ROUND(J6*E6,2) -> 0
A7: =1+N(A6) -> 2 | B7: 地面石材晶面处理 | C7: 1.石材结晶处理(结晶水及石材保养剂,中性清洁剂)； 2.包含完成该项内容所有工作及费用并满足设计图纸、规范等要求； | D7: m2 | E7: 2.337 | I7: =(F7+G7+H7)*$I$3 -> 0 | J7: =ROUND(SUM(F7:I7),2) -> 0 | K7: =ROUND(J7*E7,2) -> 0
B8: 墙面工程
A9: =1+N(A8) -> 1 | B9: 墙面湿贴石材ST-04 | C9: 1、墙面湿贴石材ST-04 2、8mm厚石材专用胶粘剂WC粘结层 3、界面剂拉毛处理 4、石材的开槽、磨边、倒角、粘接、形成所需之凹坑、抛光、六面防污防渗等一切处理费用均在主材费中考虑，不再另行计取 5、包含完成该项内容所有工作及费用并满足设计图纸、规范等要求 | D9: m2 | E9: 2.738 | I9: =(F9+G9+H9)*$I$3 -> 0 | J9: =ROUND(SUM(F9:I9),2) -> 0 | K9: =ROUND(J9*E9,2) -> 0
A10: =1+N(A9) -> 2 | B10: MT-01古铜不锈钢饰面 | C10: 1、1.2mm厚 MT-01古铜不锈钢饰面(结构胶固定) 2、9厘玻镁板基层 3、包含完成该项内容所有工作及费用并满足设计图纸、规范等要求 | D10: m2 | E10: =2.415+(0.217*1.05+0.037*1.47+0.054*1.05)*2 -> 3.09288 | I10: =(F10+G10+H10)*$I$3 -> 0 | J10: =ROUND(SUM(F10:I10),2) -> 0 | K10: =ROUND(J10*E10,2) -> 0
A11: =1+N(A10) -> 3 | B11: 墙面WD-09摩素板 | C11: 1、墙面WD-09摩素板(结构胶固定) 2、12厘玻镁板基层 3、膨胀螺栓、轻钢龙骨(钢结构)基层找平 4、包含完成该项内容所有工作及费用并满足设计图纸、规范等要求 | D11: m2 | E11: 8.025 | I11: =(F11+G11+H11)*$I$3 -> 0 | J11: =ROUND(SUM(F11:I11),2) -> 0 | K11: =ROUND(J11*E11,2) -> 0
A12: =1+N(A11) -> 4 | B12: MT-01古铜不锈钢踢脚线（高50mm） | C12: 1、1.2mm厚 MT-01古铜不锈钢踢脚线（高50mm，展开面为67mm），结构胶固定 2、9厘玻镁板基层 3、包含完成该项内容所有工作及费用并满足设计图纸、规范等要求 | D12: m | E12: 4.47 | I12: =(F12+G12+H12)*$I$3 -> 0 | J12: =ROUND(SUM(F12:I12),2) -> 0 | K12: =ROUND(J12*E12,2) -> 0
A13: =1+N(A12) -> 5 | B13: MT-01古铜不锈钢线条（展开面为67mm） | C13: 1、1.2mm厚 MT-01古铜不锈钢线条（展开面为67mm），结构胶固定 2、9厘玻镁板基层 3、包含完成该项内容所有工作及费用并满足设计图纸、规范等要求 | D13: m | E13: 5.17 | I13: =(F13+G13+H13)*$I$3 -> 0 | J13: =ROUND(SUM(F13:I13),2) -> 0 | K13: =ROUND(J13*E13,2) -> 0
A14: =1+N(A13) -> 6 | B14: MT-01古铜不锈钢线条（展开面为37mm） | C14: 1、1.2mm厚 MT-01古铜不锈钢线条（展开面为37mm），结构胶固定 2、9厘玻镁板基层 3、包含完成该项内容所有工作及费用并满足设计图纸、规范等要求 | D14: m | E14: 5.17 | I14: =(F14+G14+H14)*$I$3 -> 0 | J14: =ROUND(SUM(F14:I14),2) -> 0 | K14: =ROUND(J14*E14,2) -> 0
A15: =1+N(A14) -> 7 | B15: MT-01古铜不锈钢收口条（展开面为26mm） | C15: 1、1.2mm厚 MT-01古铜不锈钢收口条（展开面为26mm），结构胶固定 2、9厘玻镁板基层 3、包含完成该项内容所有工作及费用并满足设计图纸、规范等要求 | D15: m | E15: =6.78+3.394+10.06+2.585*2 -> 25.404 | I15: =(F15+G15+H15)*$I$3 -> 0 | J15: =ROUND(SUM(F15:I15),2) -> 0 | K15: =ROUND(J15*E15,2) -> 0
B16: 天花工程
A17: =1+N(A16) -> 1 | B17: 古铜不锈钢吊顶 | C17: 1.60系列轻钢主龙骨@900，60系列轻钢副龙骨@400，60系列横撑龙骨@600，08螺纹吊杆@900不上人天花吊顶（投影面计算） 2.玻镁板、古铜不锈钢MT-01，含开孔、检修口等费用； 3.含除灯槽外的侧面高差及其连接件、吊件； 4.包含完成该项内容所有工作及费用并满足设计图纸、规范等要求； | D17: m2 | E17: 2.096 | I17: =(F17+G17+H17)*$I$3 -> 0 | J17: =ROUND(SUM(F17:I17),2) -> 0 | K17: =ROUND(J17*E17,2) -> 0
A18: =1+N(A17) -> 2 | B18: 灯槽（135mm*100mm） | C18: 1.灯槽（135mm*100mm）； 2.双层板：9mm玻镁板、9.5厚石膏板； 3.包含完成该项内容所有工作及费用并满足设计图纸、规范等要求； | D18: m | E18: 5.26 | I18: =(F18+G18+H18)*$I$3 -> 0 | J18: =ROUND(SUM(F18:I18),2) -> 0 | K18: =ROUND(J18*E18,2) -> 0
A19: =1+N(A18) -> 3 | B19: 条形空调风口（80mm） | C19: 1.条形空调风口（80mm）； 2.风口周边阻燃板封边加固处理； 3.包含完成该项内容所有工作及费用并满足设计图纸、规范等要求； | D19: m | E19: =1.25*2 -> 2.5 | I19: =(F19+G19+H19)*$I$3 -> 0 | J19: =ROUND(SUM(F19:I19),2) -> 0 | K19: =ROUND(J19*E19,2) -> 0
A20: =1+N(A19) -> 4 | B20: 天花肌理无机涂料PT-01 | C20: 1.天花肌理无机涂料PT-01； 2.刮腻子二遍磨平； 3.底漆1遍，面漆2遍； 4.包含完成该项内容所有工作及费用并满足设计图纸、规范等要求； | D20: m2 | E20: 1.146 | I20: =(F20+G20+H20)*$I$3 -> 0 | J20: =ROUND(SUM(F20:I20),2) -> 0 | K20: =ROUND(J20*E20,2) -> 0
A21: =1+N(A20) -> 5 | B21: MT-06深色不锈钢线条 | C21: 1、MT-06深色不锈钢线条（宽为40mm），结构胶固定 2、9厘玻镁板基层 3、包含完成该项内容所有工作及费用并满足设计图纸、规范等要求 | D21: m | E21: 2.46 | I21: =(F21+G21+H21)*$I$3 -> 0 | J21: =ROUND(SUM(F21:I21),2) -> 0 | K21: =ROUND(J21*E21,2) -> 0
B22: 门窗、家具工程
A23: =1+N(A22) -> 1 | B23: 电梯扶手 | C23: 1、ST-04石材、古铜不锈钢、UP-01皮革 2、定制成品扶手制安 3、包含完成该项内容所有工作及费用并满足设计图纸、规范等要求 | D23: m | E23: =1.04*2 -> 2.08 | I23: =(F23+G23+H23)*$I$3 -> 0 | J23: =ROUND(SUM(F23:I23),2) -> 0 | K23: =ROUND(J23*E23,2) -> 0
A24: B | B24: 无障碍电梯轿厢 | K24: =SUM(K25:K43) -> 0
B25: 地面工程
A26: =1+N(A25) -> 1 | B26: 地面铺贴大理石ST-01 | C26: 1.地面20mm大理石ST-01、铺贴、厚度及样式按物料书为准； 2.10mm厚石材专用粘结剂； 3.70mm厚DS-M15干混砂浆找平； 4.基层清理、石材六面防护、背面刷胶封闭,同色云石胶补缝； 5.含开槽、磨边、倒角、拼接等处理； 6.包含完成该项内容所有工作及费用并满足设计图纸、规范等要求； | D26: m2 | E26: 2.337 | I26: =(F26+G26+H26)*$I$3 -> 0 | J26: =ROUND(SUM(F26:I26),2) -> 0 | K26: =ROUND(J26*E26,2) -> 0
A27: =1+N(A26) -> 2 | B27: 地面石材晶面处理 | C27: 1.石材结晶处理(结晶水及石材保养剂,中性清洁剂)； 2.包含完成该项内容所有工作及费用并满足设计图纸、规范等要求； | D27: m2 | E27: 2.337 | I27: =(F27+G27+H27)*$I$3 -> 0 | J27: =ROUND(SUM(F27:I27),2) -> 0 | K27: =ROUND(J27*E27,2) -> 0
B28: 墙面工程
A29: =1+N(A28) -> 1 | B29: 墙面湿贴石材ST-04 | C29: 1、墙面湿贴石材ST-04 2、8mm厚石材专用胶粘剂WC粘结层 3、界面剂拉毛处理 4、石材的开槽、磨边、倒角、粘接、形成所需之凹坑、抛光、六面防污防渗等一切处理费用均在主材费中考虑，不再另行计取 5、包含完成该项内容所有工作及费用并满足设计图纸、规范等要求 | D29: m2 | E29: 2.738 | I29: =(F29+G29+H29)*$I$3 -> 0 | J29: =ROUND(SUM(F29:I29),2) -> 0 | K29: =ROUND(J29*E29,2) -> 0
A30: =1+N(A29) -> 2 | B30: MT-01古铜不锈钢饰面 | C30: 1、1.2mm厚 MT-01古铜不锈钢饰面(结构胶固定) 2、9厘玻镁板基层 3、包含完成该项内容所有工作及费用并满足设计图纸、规范等要求 | D30: m2 | E30: =2.415+(0.547*1.05+0.037*2.13+0.054*1.05)*2 -> 3.83472 | I30: =(F30+G30+H30)*$I$3 -> 0 | J30: =ROUND(SUM(F30:I30),2) -> 0 | K30: =ROUND(J30*E30,2) -> 0
A31: =1+N(A30) -> 3 | B31: 墙面WD-09摩素板 | C31: 1、墙面WD-09摩素板(结构胶固定) 2、12厘玻镁板基层 3、膨胀螺栓、轻钢龙骨(钢结构)基层找平 4、包含完成该项内容所有工作及费用并满足设计图纸、规范等要求 | D31: m2 | E31: 7.332 | I31: =(F31+G31+H31)*$I$3 -> 0 | J31: =ROUND(SUM(F31:I31),2) -> 0 | K31: =ROUND(J31*E31,2) -> 0
A32: =1+N(A31) -> 4 | B32: MT-01古铜不锈钢踢脚线（高50mm） | C32: 1、1.2mm厚 MT-01古铜不锈钢踢脚线（高50mm，展开面为67mm），结构胶固定 2、9厘玻镁板基层 3、包含完成该项内容所有工作及费用并满足设计图纸、规范等要求 | D32: m | E32: 4.47 | I32: =(F32+G32+H32)*$I$3 -> 0 | J32: =ROUND(SUM(F32:I32),2) -> 0 | K32: =ROUND(J32*E32,2) -> 0
A33: =1+N(A32) -> 5 | B33: MT-01古铜不锈钢线条（展开面为67mm） | C33: 1、1.2mm厚 MT-01古铜不锈钢线条（展开面为67mm），结构胶固定 2、9厘玻镁板基层 3、包含完成该项内容所有工作及费用并满足设计图纸、规范等要求 | D33: m | E33: 5.17 | I33: =(F33+G33+H33)*$I$3 -> 0 | J33: =ROUND(SUM(F33:I33),2) -> 0 | K33: =ROUND(J33*E33,2) -> 0
A34: =1+N(A33) -> 6 | B34: MT-01古铜不锈钢线条（展开面为37mm） | C34: 1、1.2mm厚 MT-01古铜不锈钢线条（展开面为37mm），结构胶固定 2、9厘玻镁板基层 3、包含完成该项内容所有工作及费用并满足设计图纸、规范等要求 | D34: m | E34: 5.17 | I34: =(F34+G34+H34)*$I$3 -> 0 | J34: =ROUND(SUM(F34:I34),2) -> 0 | K34: =ROUND(J34*E34,2) -> 0
A35: =1+N(A34) -> 7 | B35: MT-01古铜不锈钢收口条（展开面为26mm） | C35: 1、1.2mm厚 MT-01古铜不锈钢收口条（展开面为26mm），结构胶固定 2、9厘玻镁板基层 3、包含完成该项内容所有工作及费用并满足设计图纸、规范等要求 | D35: m | E35: =6.78+3.394+10.06+2.585*2 -> 25.404 | I35: =(F35+G35+H35)*$I$3 -> 0 | J35: =ROUND(SUM(F35:I35),2) -> 0 | K35: =ROUND(J35*E35,2) -> 0
B36: 天花工程
A37: =1+N(A36) -> 1 | B37: 古铜不锈钢吊顶 | C37: 1.60系列轻钢主龙骨@900，60系列轻钢副龙骨@400，60系列横撑龙骨@600，08螺纹吊杆@900不上人天花吊顶（投影面计算） 2.玻镁板、古铜不锈钢MT-01，含开孔、检修口等费用； 3.含除灯槽外的侧面高差及其连接件、吊件； 4.包含完成该项内容所有工作及费用并满足设计图纸、规范等要求； | D37: m2 | E37: 2.096 | I37: =(F37+G37+H37)*$I$3 -> 0 | J37: =ROUND(SUM(F37:I37),2) -> 0 | K37: =ROUND(J37*E37,2) -> 0
A38: =1+N(A37) -> 2 | B38: 灯槽（135mm*100mm） | C38: 1.灯槽（135mm*100mm）； 2.双层板：9mm玻镁板、9.5厚石膏板； 3.包含完成该项内容所有工作及费用并满足设计图纸、规范等要求； | D38: m | E38: 5.26 | I38: =(F38+G38+H38)*$I$3 -> 0 | J38: =ROUND(SUM(F38:I38),2) -> 0 | K38: =ROUND(J38*E38,2) -> 0
A39: =1+N(A38) -> 3 | B39: 条形空调风口（80mm） | C39: 1.条形空调风口（80mm）； 2.风口周边阻燃板封边加固处理； 3.包含完成该项内容所有工作及费用并满足设计图纸、规范等要求； | D39: m | E39: =1.25*2 -> 2.5 | I39: =(F39+G39+H39)*$I$3 -> 0 | J39: =ROUND(SUM(F39:I39),2) -> 0 | K39: =ROUND(J39*E39,2) -> 0
A40: =1+N(A39) -> 4 | B40: 天花肌理无机涂料PT-01 | C40: 1.天花肌理无机涂料PT-01； 2.刮腻子二遍磨平； 3.底漆1遍，面漆2遍； 4.包含完成该项内容所有工作及费用并满足设计图纸、规范等要求； | D40: m2 | E40: 1.146 | I40: =(F40+G40+H40)*$I$3 -> 0 | J40: =ROUND(SUM(F40:I40),2) -> 0 | K40: =ROUND(J40*E40,2) -> 0
A41: =1+N(A40) -> 5 | B41: MT-06深色不锈钢线条 | C41: 1、MT-06深色不锈钢线条（宽为40mm），结构胶固定 2、9厘玻镁板基层 3、包含完成该项内容所有工作及费用并满足设计图纸、规范等要求 | D41: m | E41: 2.46 | I41: =(F41+G41+H41)*$I$3 -> 0 | J41: =ROUND(SUM(F41:I41),2) -> 0 | K41: =ROUND(J41*E41,2) -> 0
...

Sheet 地下室装修工程
A1: 珠海海德公馆会所项目-工程量清单
A2: 序号 | B2: 项目名称 | C2: 项目特征 | D2: 单位 | E2: 工程量 | F2: 人工 | G2: 主材 | H2: 辅材及机械费 | I2: 管理及利润取费 | J2: 综合单价 （不含税） | K2: 合价 （不含税） | L2: 备注
A4: A | B4: 负一层 | K4: =SUM(K5:K104) -> 0
A5: 一 | B5: 一单元合用前室
B6: 地面工程
A7: =1+N(A6) -> 1 | B7: 地面铺贴大理石ST-01 | C7: 1.地面20mm大理石ST-01、铺贴、厚度及样式按物料书为准； 2.10mm厚石材专用粘结剂； 3.70mm厚DS-M15干混砂浆找平； 4.基层清理、石材六面防护、背面刷胶封闭,同色云石胶补缝； 5.含开槽、磨边、倒角、拼接等处理； 6.包含完成该项内容所有工作及费用并满足设计图纸、规范等要求； | D7: m2 | E7: 10.765 | I7: =(F7+G7+H7)*$I$3 -> 0 | J7: =ROUND(SUM(F7:I7),2) -> 0 | K7: =ROUND(J7*E7,2) -> 0 | P7: 1
A8: =1+N(A7) -> 2 | B8: 地面铺贴大理石ST-01.02拼花 | C8: 1.地面20mm大理石拼花、参考3F-DF-01样式、ST-01、ST-02按物料书为准； 2.10mm厚石材专用粘结剂； 3.70mm厚DS-M15干混砂浆找平； 4.基层清理、石材六面防护、背面刷胶封闭,同色云石胶补缝； 5.含开槽、磨边、倒角、拼接等处理； 6.包含完成该项内容所有工作及费用并满足设计图纸、规范等要求； | D8: m2 | E8: 16.519 | I8: =(F8+G8+H8)*$I$3 -> 0 | J8: =ROUND(SUM(F8:I8),2) -> 0 | K8: =ROUND(J8*E8,2) -> 0 | P8: 1
A9: =1+N(A8) -> 3 | B9: 实心铜条5mm宽 | C9: 1.实心铜条5mm宽； 2.包含完成该项内容所有工作及费用并满足设计图纸、规范等要求； | D9: m | E9: 17.264 | I9: =(F9+G9+H9)*$I$3 -> 0 | J9: =ROUND(SUM(F9:I9),2) -> 0 | K9: =ROUND(J9*E9,2) -> 0
A10: =1+N(A9) -> 4 | B10: 地面石材晶面处理 | C10: 1.石材结晶处理(结晶水及石材保养剂,中性清洁剂)； 2.包含完成该项内容所有工作及费用并满足设计图纸、规范等要求； | D10: m2 | E10: =+E7+E8 -> 27.284 | I10: =(F10+G10+H10)*$I$3 -> 0 | J10: =ROUND(SUM(F10:I10),2) -> 0 | K10: =ROUND(J10*E10,2) -> 0
B11: 墙面工程
A12: =1+N(A11) -> 1 | B12: 墙面湿贴石材ST-05 | C12: 1、墙面湿贴石材ST-05 2、8mm厚石材专用胶粘剂WC粘结层 3、界面剂拉毛处理 4、石材的开槽、磨边、倒角、粘接、形成所需之凹坑、抛光、六面防污防渗等一切处理费用均在主材费中考虑，不再另行计取 5、包含完成该项内容所有工作及费用并满足设计图纸、规范等要求 | D12: m2 | E12: 6.099 | I12: =(F12+G12+H12)*$I$3 -> 0 | J12: =ROUND(SUM(F12:I12),2) -> 0 | K12: =ROUND(J12*E12,2) -> 0
A13: =1+N(A12) -> 2 | B13: 墙面干挂ST-05石材 | C13: 1、墙面干挂ST-05石材 2、不锈钢背栓挂件安装，云石胶+AB胶固定 3、镀锌角钢钢架(高度超4m、完成面超150mm采用槽钢基层加固)，钢架防锈处理 4、膨胀螺栓固定预埋铁件(轻质砖墙体需要穿墙螺栓固定) 5、石材的开槽、磨边、倒角、粘接、形成所需之凹坑、抛光、六面防污防渗等一切处理费用均在主材费中考虑，不再另行计取 6、包含完成该项内容所有工作及费用并满足设计图纸、规范等要求 | D13: m2 | E13: 27.664 | I13: =(F13+G13+H13)*$I$3 -> 0 | J13: =ROUND(SUM(F13:I13),2) -> 0 | K13: =ROUND(J13*E13,2) -> 0
A14: =1+N(A13) -> 3 | B14: WD-07摩素板 | C14: 1、墙面WD-08摩素板(结构胶固定) 2、12厘玻镁板基层 3、膨胀螺栓、轻钢龙骨(钢结构)基层找平 4、包含完成该项内容所有工作及费用并满足设计图纸、规范等要求 | D14: m2 | E14: 5.421 | I14: =(F14+G14+H14)*$I$3 -> 0 | J14: =ROUND(SUM(F14:I14),2) -> 0 | K14: =ROUND(J14*E14,2) -> 0
A15: =1+N(A14) -> 4 | B15: 墙面PT-01肌理无机涂料 | C15: 1、墙面PT-01肌理无机涂料(底漆1遍，面漆2遍) 2、刮白胶腻子找平二遍，打磨 3、阴、阳角护角收边 4、双层9.5mm纸面石膏板 5、轻钢龙骨基层找平 6、包含完成该项内容所有工作及费用并满足设计图纸、规范等要求 | D15: m2 | E15: 29.816 | I15: =(F15+G15+H15)*$I$3 -> 0 | J15: =ROUND(SUM(F15:I15),2) -> 0 | K15: =ROUND(J15*E15,2) -> 0
A16: =1+N(A15) -> 5 | B16: 不锈钢门套 | C16: 1、1.2mm厚 MT-01古铜不锈钢门套，结构胶固定 2、9厘玻镁板基层 3、工程量以展开面积计算 4、包含完成该项内容所有工作及费用并满足设计图纸、规范等要求 | D16: m2 | E16: =0.21*2.2*2+0.15*1.11 -> 1.0905 | I16: =(F16+G16+H16)*$I$3 -> 0 | J16: =ROUND(SUM(F16:I16),2) -> 0 | K16: =ROUND(J16*E16,2) -> 0
A17: =1+N(A16) -> 6 | B17: 电梯不锈钢门套 | C17: 1、1.2mm厚 MT-01古铜不锈钢门套，结构胶固定 2、9厘玻镁板基层 3、工程量以展开面积计算 4、包含完成该项内容所有工作及费用并满足设计图纸、规范等要求 | D17: m2 | E17: =0.34*2.75*2*2 -> 3.74 | I17: =(F17+G17+H17)*$I$3 -> 0 | J17: =ROUND(SUM(F17:I17),2) -> 0 | K17: =ROUND(J17*E17,2) -> 0
A18: =1+N(A17) -> 7 | B18: 电梯不锈钢门头 | C18: 1、1.2mm厚 MT-01古铜不锈钢门头，结构胶固定 2、12mm阻燃板，轻钢副龙骨@400 3、电梯门顶内置亚克力，内部面层刮白处理 4、工程量以展开面积计算 5、包含完成该项内容所有工作及费用并满足设计图纸、规范等要求 | D18: m2 | E18: =+(0.061+0.475+0.114+0.074)*0.95*2 -> 1.3756 | I18: =(F18+G18+H18)*$I$3 -> 0 | J18: =ROUND(SUM(F18:I18),2) -> 0 | K18: =ROUND(J18*E18,2) -> 0
A19: =1+N(A18) -> 8 | B19: MT-01古铜不锈钢饰面（电梯按钮处） | C19: 1、1.2mm厚 MT-01古铜不锈钢饰面 2、12mm阻燃板基层，轻钢副龙骨@400 3、工程量以展开面积计算 4、包含完成该项内容所有工作及费用并满足设计图纸、规范等要求 | D19: m2 | E19: 0.253 | I19: =(F19+G19+H19)*$I$3 -> 0 | J19: =ROUND(SUM(F19:I19),2) -> 0 | K19: =ROUND(J19*E19,2) -> 0
A20: =1+N(A19) -> 9 | B20: MT-01古铜不锈钢踢脚线（高20mm） | C20: 1、1.2mm厚 MT-01古铜不锈钢踢脚线（高20mm，展开面为46mm），结构胶固定 2、9厘玻镁板基层 3、包含完成该项内容所有工作及费用并满足设计图纸、规范等要求 | D20: m | E20: 24.611 | I20: =(F20+G20+H20)*$I$3 -> 0 | J20: =ROUND(SUM(F20:I20),2) -> 0 | K20: =ROUND(J20*E20,2) -> 0
A21: =1+N(A20) -> 10 | B21: MT-01古铜不锈钢线条（展开面为51mm） | C21: 1、1.2mm厚 MT-01古铜不锈钢线条（展开面为51mm），结构胶固定 2、9厘玻镁板基层 3、包含完成该项内容所有工作及费用并满足设计图纸、规范等要求 | D21: m | E21: 10.065 | I21: =(F21+G21+H21)*$I$3 -> 0 | J21: =ROUND(SUM(F21:I21),2) -> 0 | K21: =ROUND(J21*E21,2) -> 0
A22: =1+N(A21) -> 11 | B22: MT-01古铜不锈钢线条（展开面为114mm） | C22: 1、1.2mm厚 MT-01古铜不锈钢线条（展开面为114mm），结构胶固定 2、9厘玻镁板基层 3、包含完成该项内容所有工作及费用并满足设计图纸、规范等要求 | D22: m | E22: 10.795 | I22: =(F22+G22+H22)*$I$3 -> 0 | J22: =ROUND(SUM(F22:I22),2) -> 0 | K22: =ROUND(J22*E22,2) -> 0
A23: =1+N(A22) -> 12 | B23: MT-01古铜不锈钢顶部收口条（展开面为41mm） | C23: 1、1.2mm厚 MT-01古铜不锈钢顶部收口条（展开面为41mm），结构胶固定 2、9厘玻镁板基层 3、包含完成该项内容所有工作及费用并满足设计图纸、规范等要求 | D23: m | E23: 25.474 | I23: =(F23+G23+H23)*$I$3 -> 0 | J23: =ROUND(SUM(F23:I23),2) -> 0 | K23: =ROUND(J23*E23,2) -> 0
B24: 天花工程
A25: =1+N(A24) -> 1 | B25: 石膏板吊顶 | C25: 1.60系列轻钢主龙骨@900，60系列轻钢副龙骨@400，60系列横撑龙骨@600，08螺纹吊杆@900不上人天花吊顶（投影面计算） 2.玻镁板、双层9.5厚石膏板基层，含开孔、检修口、10*10凹槽等费用； 3.含除灯槽外的侧面高差及其连接件、吊件； 4.包含完成该项内容所有工作及费用并满足设计图纸、规范等要求； | D25: m2 | E25: 27.946 | I25: =(F25+G25+H25)*$I$3 -> 0 | J25: =ROUND(SUM(F25:I25),2) -> 0 | K25: =ROUND(J25*E25,2) -> 0
A26: =1+N(A25) -> 2 | B26: 灯槽（100mm*250mm） | C26: 1.灯槽（100mm*250mm）； 2.双层板：9mm玻镁板、9.5厚石膏板； 3.包含完成该项内容所有工作及费用并满足设计图纸、规范等要求； | D26: m | E26: 17.282 | I26: =(F26+G26+H26)*$I$3 -> 0 | J26: =ROUND(SUM(F26:I26),2) -> 0 | K26: =ROUND(J26*E26,2) -> 0
A27: =1+N(A26) -> 3 | B27: 成品石膏线条 | C27: 1.成品石膏线条（50mm*50mm）； 2.按图纸造型； 3.包含完成该项内容所有工作及费用并满足设计图纸、规范等要求； | D27: m | E27: 17.282 | I27: =(F27+G27+H27)*$I$3 -> 0 | J27: =ROUND(SUM(F27:I27),2) -> 0 | K27: =ROUND(J27*E27,2) -> 0
A28: =1+N(A27) -> 4 | B28: 条形空调风口（150mm） | C28: 1.条形空调风口（150mm）； 2.风口周边阻燃板封边加固处理； 3.包含完成该项内容所有工作及费用并满足设计图纸、规范等要求； | D28: m | E28: =5.12*2 -> 10.24 | I28: =(F28+G28+H28)*$I$3 -> 0 | J28: =ROUND(SUM(F28:I28),2) -> 0 | K28: =ROUND(J28*E28,2) -> 0
A29: =1+N(A28) -> 5 | B29: 天花肌理无机涂料PT-01 | C29: 1.天花肌理无机涂料PT-01； 2.刮腻子二遍磨平； 3.底漆1遍，面漆2遍； 4.包含完成该项内容所有工作及费用并满足设计图纸、规范等要求； | D29: m2 | E29: 34.76 | I29: =(F29+G29+H29)*$I$3 -> 0 | J29: =ROUND(SUM(F29:I29),2) -> 0 | K29: =ROUND(J29*E29,2) -> 0
B30: 门窗、家具工程
A31: 二 | B31: 二单元合用前室
B32: 地面工程
A33: =1+N(A32) -> 1 | B33: 地面铺贴大理石ST-01 | C33: 1.地面20mm大理石ST-01、铺贴、厚度及样式按物料书为准； 2.10mm厚石材专用粘结剂； 3.70mm厚DS-M15干混砂浆找平； 4.基层清理、石材六面防护、背面刷胶封闭,同色云石胶补缝； 5.含开槽、磨边、倒角、拼接等处理； 6.包含完成该项内容所有工作及费用并满足设计图纸、规范等要求； | D33: m2 | E33: 11.09 | I33: =(F33+G33+H33)*$I$3 -> 0 | J33: =ROUND(SUM(F33:I33),2) -> 0 | K33: =ROUND(J33*E33,2) -> 0 | P33: 1
A34: =1+N(A33) -> 2 | B34: 地面铺贴大理石ST-01.02拼花 | C34: 1.地面20mm大理石拼花、参考3F-DF-01样式、ST-01、ST-02按物料书为准； 2.10mm厚石材专用粘结剂； 3.70mm厚DS-M15干混砂浆找平； 4.基层清理、石材六面防护、背面刷胶封闭,同色云石胶补缝； 5.含开槽、磨边、倒角、拼接等处理； 6.包含完成该项内容所有工作及费用并满足设计图纸、规范等要求； | D34: m2 | E34: 19.448 | I34: =(F34+G34+H34)*$I$3 -> 0 | J34: =ROUND(SUM(F34:I34),2) -> 0 | K34: =ROUND(J34*E34,2) -> 0 | P34: 1
A35: =1+N(A34) -> 3 | B35: 实心铜条5mm宽 | C35: 1.实心铜条5mm宽； 2.包含完成该项内容所有工作及费用并满足设计图纸、规范等要求； | D35: m | E35: 19.526 | I35: =(F35+G35+H35)*$I$3 -> 0 | J35: =ROUND(SUM(F35:I35),2) -> 0 | K35: =ROUND(J35*E35,2) -> 0
A36: =1+N(A35) -> 4 | B36: 地面石材晶面处理 | C36: 1.石材结晶处理(结晶水及石材保养剂,中性清洁剂)； 2.包含完成该项内容所有工作及费用并满足设计图纸、规范等要求； | D36: m2 | E36: =+E33+E34 -> 30.538 | I36: =(F36+G36+H36)*$I$3 -> 0 | J36: =ROUND(SUM(F36:I36),2) -> 0 | K36: =ROUND(J36*E36,2) -> 0
B37: 墙面工程
A38: =1+N(A37) -> 1 | B38: 墙面湿贴石材ST-05 | C38: 1、墙面湿贴石材ST-05 2、8mm厚石材专用胶粘剂WC粘结层 3、界面剂拉毛处理 4、石材的开槽、磨边、倒角、粘接、形成所需之凹坑、抛光、六面防污防渗等一切处理费用均在主材费中考虑，不再另行计取 5、包含完成该项内容所有工作及费用并满足设计图纸、规范等要求 | D38: m2 | E38: 8.311 | I38: =(F38+G38+H38)*$I$3 -> 0 | J38: =ROUND(SUM(F38:I38),2) -> 0 | K38: =ROUND(J38*E38,2) -> 0
A39: =1+N(A38) -> 2 | B39: 墙面干挂ST-05石材 | C39: 1、墙面干挂ST-05石材 2、不锈钢背栓挂件安装，云石胶+AB胶固定 3、镀锌角钢钢架(高度超4m、完成面超150mm采用槽钢基层加固)，钢架防锈处理 4、膨胀螺栓固定预埋铁件(轻质砖墙体需要穿墙螺栓固定) 5、石材的开槽、磨边、倒角、粘接、形成所需之凹坑、抛光、六面防污防渗等一切处理费用均在主材费中考虑，不再另行计取 6、包含完成该项内容所有工作及费用并满足设计图纸、规范等要求 | D39: m2 | E39: 37.242 | I39: =(F39+G39+H39)*$I$3 -> 0 | J39: =ROUND(SUM(F39:I39),2) -> 0 | K39: =ROUND(J39*E39,2) -> 0
A40: =1+N(A39) -> 3 | B40: 墙面PT-01肌理无机涂料 | C40: 1、墙面PT-01肌理无机涂料(底漆1遍，面漆2遍) 2、刮白胶腻子找平二遍，打磨 3、阴、阳角护角收边 4、双层9.5mm纸面石膏板 5、轻钢龙骨基层找平 6、包含完成该项内容所有工作及费用并满足设计图纸、规范等要求 | D40: m2 | E40: 24.247 | I40: =(F40+G40+H40)*$I$3 -> 0 | J40: =ROUND(SUM(F40:I40),2) -> 0 | K40: =ROUND(J40*E40,2) -> 0
A41: =1+N(A40) -> 4 | B41: 不锈钢门套 | C41: 1、1.2mm厚 MT-01古铜不锈钢门套，结构胶固定 2、9厘玻镁板基层 3、工程量以展开面积计算 4、包含完成该项内容所有工作及费用并满足设计图纸、规范等要求 | D41: m2 | E41: =0.38*2.2*2+0.29*1.2 -> 2.02 | I41: =(F41+G41+H41)*$I$3 -> 0 | J41: =ROUND(SUM(F41:I41),2) -> 0 | K41: =ROUND(J41*E41,2) -> 0
...

Sheet 会所安装工程量清单
A1: 工程清单与计价表
A2: 序号 | B2: 项目名称 | C2: 项目特征描述 | D2: 计量 单位 | E2: 工程量 | F2: 人工 | G2: 主材 | H2: 辅材及机械费 | I2: 管理费、利润及规费 | J2: 不含税综合单价 （元） | K2: 不含税合价（元） | L2: 备注
B4: 电气工程 | K4: =+K5+K75+K79+K83 -> 0
B5: （1）会所 | K5: =SUM(K6:K74) -> 0
A6: =A5+1 -> 1 | B6: D13m 可调深藏射灯 | C6: 1.名称:D13m 可调深藏射灯 2.规格：功率：9W、流明量：756lm；63lm/W、色温：3500K、光速角：24° 3.其他:包含完成该项内容所有工作及费用并满足设计图纸、规范等要求 | D6: 套 | E6: 17 | I6: =(F6+G6+H6)*$I$3 -> 0 | J6: =F6+G6+H6+I6 -> 0 | K6: =ROUND(E6*J6,2) -> 0
A7: =A6+1 -> 2 | B7: D13f 可调深藏射灯 | C7: 1.名称:D13f 可调深藏射灯 2.规格：功率：9W、流明量：594lm；63lm/W、色温：3500K、光速角：36° 3.其他:包含完成该项内容所有工作及费用并满足设计图纸、规范等要求 | D7: 套 | E7: 124 | I7: =(F7+G7+H7)*$I$3 -> 0 | J7: =F7+G7+H7+I7 -> 0 | K7: =ROUND(E7*J7,2) -> 0
A8: =A7+1 -> 3 | B8: D14m 可调深藏射灯 | C8: 1.名称:D14m 可调深藏射灯 2.规格：功率：12W、流明量：756lm；63lm/W、色温：3500K、光速角：24° 3.其他:包含完成该项内容所有工作及费用并满足设计图纸、规范等要求 | D8: 套 | E8: 26 | I8: =(F8+G8+H8)*$I$3 -> 0 | J8: =F8+G8+H8+I8 -> 0 | K8: =ROUND(E8*J8,2) -> 0
A9: =A8+1 -> 4 | B9: D14f 可调深藏射灯 | C9: 1.名称:D14f 可调深藏射灯 2.规格：功率：12W、流明量：792lm；66lm/W、色温：3500K、光速角：36° 3.其他:包含完成该项内容所有工作及费用并满足设计图纸、规范等要求 | D9: 套 | E9: 104 | I9: =(F9+G9+H9)*$I$3 -> 0 | J9: =F9+G9+H9+I9 -> 0 | K9: =ROUND(E9*J9,2) -> 0
A10: =A9+1 -> 5 | B10: D15m 可调深藏射灯 | C10: 1.名称:D15m 可调深藏射灯 2.规格：功率：15W、流明量：951lm；65lm/W、色温：3500K、光速角：24° 3.其他:包含完成该项内容所有工作及费用并满足设计图纸、规范等要求 | D10: 套 | E10: 9 | I10: =(F10+G10+H10)*$I$3 -> 0 | J10: =F10+G10+H10+I10 -> 0 | K10: =ROUND(E10*J10,2) -> 0
A11: =A10+1 -> 6 | B11: D15f 可调深藏射灯 | C11: 1.名称:D15f 可调深藏射灯 2.规格：功率：15W、流明量：970lm；67lm/W、色温：3500K、光速角：36° 3.其他:包含完成该项内容所有工作及费用并满足设计图纸、规范等要求 | D11: 套 | E11: 96 | I11: =(F11+G11+H11)*$I$3 -> 0 | J11: =F11+G11+H11+I11 -> 0 | K11: =ROUND(E11*J11,2) -> 0
A12: =A11+1 -> 7 | B12: D17m 可调深藏射灯 | C12: 1.名称:D17m 可调深藏射灯 2.规格：功率：24W、流明量：1802lm；77lm/W、色温：3500K、光速角：24° 3.其他:包含完成该项内容所有工作及费用并满足设计图纸、规范等要求 | D12: 套 | E12: 24 | I12: =(F12+G12+H12)*$I$3 -> 0 | J12: =F12+G12+H12+I12 -> 0 | K12: =ROUND(E12*J12,2) -> 0
A13: =A12+1 -> 8 | B13: Gs15f 方形下照深藏射灯 | C13: 1.名称:Gs15f 方形下照深藏射灯 2.规格：功率：9W、流明量：603lm；67lm/W、色温：3500K、光速角：36° 3.其他:包含完成该项内容所有工作及费用并满足设计图纸、规范等要求 | D13: 套 | E13: 12 | I13: =(F13+G13+H13)*$I$3 -> 0 | J13: =F13+G13+H13+I13 -> 0 | K13: =ROUND(E13*J13,2) -> 0
A14: =A13+1 -> 9 | B14: Mr15n 下照迷你格栅灯 | C14: 1.名称:Mr15n 下照迷你格栅灯 2.规格：功率：10*2W、流明量：1400lm；70lm/W、色温：3500K、光速角：15° 3.其他:包含完成该项内容所有工作及费用并满足设计图纸、规范等要求 | D14: 套 | E14: 6 | I14: =(F14+G14+H14)*$I$3 -> 0 | J14: =F14+G14+H14+I14 -> 0 | K14: =ROUND(E14*J14,2) -> 0
A15: =A14+1 -> 10 | B15: Mr15m 下照迷你格栅灯 | C15: 1.名称:Mr15m 下照迷你格栅灯 2.规格：功率：10*2W、流明量：1360lm；68lm/W、色温：3500K、光速角：24° 3.其他:包含完成该项内容所有工作及费用并满足设计图纸、规范等要求 | D15: 套 | E15: 8 | I15: =(F15+G15+H15)*$I$3 -> 0 | J15: =F15+G15+H15+I15 -> 0 | K15: =ROUND(E15*J15,2) -> 0
A16: =A15+1 -> 11 | B16: Mr15f 下照迷你格栅灯 | C16: 1.名称:Mr15f 下照迷你格栅灯 2.规格：功率：10*2W、流明量：1360lm；68lm/W、色温：3500K、光速角：36° 3.其他:包含完成该项内容所有工作及费用并满足设计图纸、规范等要求 | D16: 套 | E16: 6 | I16: =(F16+G16+H16)*$I$3 -> 0 | J16: =F16+G16+H16+I16 -> 0 | K16: =ROUND(E16*J16,2) -> 0
A17: =A16+1 -> 12 | B17: Md15m 可调迷你格栅灯 | C17: 1.名称:Md15m 可调迷你格栅灯 2.规格：功率：10*2W、流明量：1360lm；68lm/W、色温：3500K、光速角：36° 3.其他:包含完成该项内容所有工作及费用并满足设计图纸、规范等要求 | D17: 套 | E17: 25 | I17: =(F17+G17+H17)*$I$3 -> 0 | J17: =F17+G17+H17+I17 -> 0 | K17: =ROUND(E17*J17,2) -> 0
... A74: =A73+1 -> 69 | B74: 自助售卖机 | C74: 1.名称：自助售卖机 2.规格：750*780*1830 3.包含完成该项内容所有工作及费用并满足设计图纸、规范等要求 | D74: 个 | E74: 2 | I74: =(F74+G74+H74)*$I$3 -> 0 | J74: =F74+G74+H74+I74 -> 0 | K74: =ROUND(E74*J74,2) -> 0
B75: （2）标准层电梯厅 | K75: =SUM(K76:K78) -> 0
A76: =A75+1 -> 1 | B76: D13f 可调深藏射灯 | C76: 1.名称:D13f 可调深藏射灯 2.规格：功率：9W、流明量：594lm；63lm/W、色温：3500K、光速角：36° 3.其他:包含完成该项内容所有工作及费用并满足设计图纸、规范等要求 | D76: 套 | E76: 21 | I76: =(F76+G76+H76)*$I$3 -> 0 | J76: =F76+G76+H76+I76 -> 0 | K76: =ROUND(E76*J76,2) -> 0
A77: =A76+1 -> 2 | B77: Rm10 LED透光模组灯 | C77: 1.名称:Rm10 LED透光模组灯 2.规格：功率：80W、流明量：5500lm；80lm/W、色温：3500K、光速角：170° 3.含外置电源驱动 4.其他:包含完成该项内容所有工作及费用并满足设计图纸、规范等要求 | D77: m | E77: 13.6 | I77: =(F77+G77+H77)*$I$3 -> 0 | J77: =F77+G77+H77+I77 -> 0 | K77: =ROUND(E77*J77,2) -> 0
A78: =A77+1 -> 3 | B78: Lc12-LED侧弯灯带 | C78: 1.名称:Lc12-LED侧弯灯带 2.规格：功率：14W/M、流明量：1260lm/M；90lm/W、色温：3500K、光速角：120° 3.含外置电源驱动 4.其他:包含完成该项内容所有工作及费用并满足设计图纸、规范等要求 | D78: m | E78: 36.295 | I78: =(F78+G78+H78)*$I$3 -> 0 | J78: =F78+G78+H78+I78 -> 0 | K78: =ROUND(E78*J78,2) -> 0
B79: （3）地下室大堂 | K79: =SUM(K80:K82) -> 0
A80: =A79+1 -> 1 | B80: D13f 可调深藏射灯 | C80: 1.名称:D13f 可调深藏射灯 2.规格：功率：9W、流明量：594lm；63lm/W、色温：3500K、光速角：36° 3.其他:包含完成该项内容所有工作及费用并满足设计图纸、规范等要求 | D80: 套 | E80: 78 | I80: =(F80+G80+H80)*$I$3 -> 0 | J80: =F80+G80+H80+I80 -> 0 | K80: =ROUND(E80*J80,2) -> 0
A81: =A80+1 -> 2 | B81: Rm10 LED透光模组灯 | C81: 1.名称:Rm10 LED透光模组灯 2.规格：功率：80W、流明量：5500lm；80lm/W、色温：3500K、光速角：170° 3.含外置电源驱动 4.其他:包含完成该项内容所有工作及费用并满足设计图纸、规范等要求 | D81: m | E81: 40.8 | I81: =(F81+G81+H81)*$I$3 -> 0 | J81: =F81+G81+H81+I81 -> 0 | K81: =ROUND(E81*J81,2) -> 0
A82: =A81+1 -> 3 | B82: Lc12-LED侧弯灯带 | C82: 1.名称:Lc12-LED侧弯灯带 2.规格：功率：14W/M、流明量：1260lm/M；90lm/W、色温：3500K、光速角：120° 3.含外置电源驱动 4.其他:包含完成该项内容所有工作及费用并满足设计图纸、规范等要求 | D82: m | E82: 184.32 | I82: =(F82+G82+H82)*$I$3 -> 0 | J82: =F82+G82+H82+I82 -> 0 | K82: =ROUND(E82*J82,2) -> 0
B83: （4）电梯轿厢 | K83: =SUM(K84:K86) -> 0
A84: =A83+1 -> 1 | B84: Mr15m 下照迷你格栅灯 | C84: 1.名称:Mr15m 下照迷你格栅灯 2.规格：功率：10*2W、流明量：1360lm；68lm/W、色温：3500K、光速角：24° 3.其他:包含完成该项内容所有工作及费用并满足设计图纸、规范等要求 | D84: 套 | E84: 2 | I84: =(F84+G84+H84)*$I$3 -> 0 | J84: =F84+G84+H84+I84 -> 0 | K84: =ROUND(E84*J84,2) -> 0
A85: =A84+1 -> 2 | B85: Ls12-LED硬灯条 | C85: 1.名称:Ls12-LED硬灯条 2.规格：功率：14W/M、流明量：1260lm/M；90lm/W、色温：3500K、光速角：120° 3.含外置电源驱动 4.其他:包含完成该项内容所有工作及费用并满足设计图纸、规范等要求 | D85: m | E85: 6.98 | I85: =(F85+G85+H85)*$I$3 -> 0 | J85: =F85+G85+H85+I85 -> 0 | K85: =ROUND(E85*J85,2) -> 0
A86: =A85+1 -> 3 | B86: Lc12-LED侧弯灯带 | C86: 1.名称:Lc12-LED侧弯灯带 2.规格：功率：14W/M、流明量：1260lm/M；90lm/W、色温：3500K、光速角：120° 3.含外置电源驱动 4.其他:包含完成该项内容所有工作及费用并满足设计图纸、规范等要求 | D86: m | E86: 4.78 | I86: =(F86+G86+H86)*$I$3 -> 0 | J86: =F86+G86+H86+I86 -> 0 | K86: =ROUND(E86*J86,2) -> 0
B87: 给排水工程 | K87: =SUM(K88:K111) -> 0
A88: 1 | B88: 厨用单盆水槽 | C88: 1.名称：厨用单盆水槽 2.水槽安装 3.包含完成该项内容所有工作及费用并满足设计图纸、规范等要求 | D88: 个 | E88: 3 | I88: =(F88+G88+H88)*$I$3 -> 0 | J88: =F88+G88+H88+I88 -> 0 | K88: =ROUND(E88*J88,2) -> 0
A89: =A88+1 -> 2 | B89: 厨用龙头 | C89: 1.名称：厨用龙头 2.龙头安装，包括角阀、不锈钢软管、下水管等所需材料 3.包含完成该项内容所有工作及费用并满足设计图纸、规范等要求 | D89: 个 | E89: 3 | I89: =(F89+G89+H89)*$I$3 -> 0 | J89: =F89+G89+H89+I89 -> 0 | K89: =ROUND(E89*J89,2) -> 0
A90: =A89+1 -> 3 | B90: 台下盆 | C90: 1.名称：台下盆 2.台盆安装 3.包含完成该项内容所有工作及费用并满足设计图纸、规范等要求 | D90: 个 | E90: 2 | I90: =(F90+G90+H90)*$I$3 -> 0 | J90: =F90+G90+H90+I90 -> 0 | K90: =ROUND(E90*J90,2) -> 0 | M90: 1
A91: =A90+1 -> 4 | B91: 台盆龙头 | C91: 1.名称：台盆龙头 2.台盆龙头安装，包括角阀、不锈钢软管、下水管等所需材料 3.包含完成该项内容所有工作及费用并满足设计图纸、规范等要求 | D91: 个 | E91: =+E90+E99 -> 6 | I91: =(F91+G91+H91)*$I$3 -> 0 | J91: =F91+G91+H91+I91 -> 0 | K91: =ROUND(E91*J91,2) -> 0
A92: =A91+1 -> 5 | B92: 智能马桶 | C92: 1.名称：智能马桶 2.智能马桶安装，包括角阀、不锈钢软管、马桶橡胶圈等所需材料 3.包含完成该项内容所有工作及费用并满足设计图纸、规范等要求 | D92: 个 | E92: 7 | I92: =(F92+G92+H92)*$I$3 -> 0 | J92: =F92+G92+H92+I92 -> 0 | K92: =ROUND(E92*J92,2) -> 0
A93: =A92+1 -> 6 | B93: 连体蹲便器 | C93: 1.名称：连体蹲便器 2.蹲便器、水箱安装，包括角阀、不锈钢软管、等所需材料 3.包含完成该项内容所有工作及费用并满足设计图纸、规范等要求 | D93: 个 | E93: 1 | I93: =(F93+G93+H93)*$I$3 -> 0 | J93: =F93+G93+H93+I93 -> 0 | K93: =ROUND(E93*J93,2) -> 0
A94: =A93+1 -> 7 | B94: 感应一体挂式小便器 | C94: 1.名称：感应一体挂式小便器 2.小便器、感应开关安装及其他一切等所需材料 3.包含完成该项内容所有工作及费用并满足设计图纸、规范等要求 | D94: 个 | E94: 4 | I94: =(F94+G94+H94)*$I$3 -> 0 | J94: =F94+G94+H94+I94 -> 0 | K94: =ROUND(E94*J94,2) -> 0
A95: =A94+1 -> 8 | B95: 拖把池 | C95: 1.名称：拖把池 2.拖把池安装 3.包含完成该项内容所有工作及费用并满足设计图纸、规范等要求 | D95: 个 | E95: 1 | I95: =(F95+G95+H95)*$I$3 -> 0 | J95: =F95+G95+H95+I95 -> 0 | K95: =ROUND(E95*J95,2) -> 0
A96: =A95+1 -> 9 | B96: 用水咀龙头 | C96: 1.名称：用水咀龙头 2.拖把池安装 3.包含完成该项内容所有工作及费用并满足设计图纸、规范等要求 | D96: 个 | E96: 2 | I96: =(F96+G96+H96)*$I$3 -> 0 | J96: =F96+G96+H96+I96 -> 0 | K96: =ROUND(E96*J96,2) -> 0
A97: =A96+1 -> 10 | B97: 淋浴器 | C97: 1.名称：淋浴器 2.淋浴器安装 3.包含完成该项内容所有工作及费用并满足设计图纸、规范等要求 | D97: 套 | E97: 4 | I97: =(F97+G97+H97)*$I$3 -> 0 | J97: =F97+G97+H97+I97 -> 0 | K97: =ROUND(E97*J97,2) -> 0
...

Sheet 措施费
A1: 丹田海德公馆公区装修工程-工程量清单
A2: 序号 | B2: 项目名称 | C2: 项目特征 | D2: 单位 | E2: 工程量 | F2: 人工 | G2: 主材 | H2: 辅材及机械费 | I2: 管理及利润取费 | J2: 综合单价 （不含税） | K2: 合价 （不含税） | L2: 备注
A4: 一 | B4: 措施费 | K4: =SUM(K5:K6) -> 0
A5: 1 | B5: 垃圾清理及卫生清洁 | C5: 卫生清理、含粗清洁、精清洁（按地面投影面积计算） | D5: m2 | E5: =汇总表!C13 -> 3700.17 | I5: =(F5+G5+H5)*$I$3 -> 0 | J5: =ROUND(SUM(F5:I5),2) -> 0 | K5: =ROUND(J5*E5,2) -> 0
A6: 2 | B6: 脚手架费用 | C6: 脚手架费用、包括活动式、满堂式、综合式、单排式（按地面投影面积计算） | D6: m2 | E6: =E5 -> 3700.17 | I6: =(F6+G6+H6)*$I$3 -> 0 | J6: =ROUND(SUM(F6:I6),2) -> 0 | K6: =ROUND(J6*E6,2) -> 0
A7: 二 | B7: 合计 | K7: =SUM(K4:K6)/2 -> 0
