Workbook

Sheet 2-报价汇总
H4: 安措 | I4: 管理 | J4: 利润
H5: 0.01 | I5: 0 | J5: 0

Sheet 2.1-装饰工程
A1: 理想汽车中心店装修工程量清单
A2: 注意：此报价清单每项不得随意更改、删减，如有任何增加项请务必在每大项最后“补充项“中列举，补充项及说明字体颜色均采用蓝色；且所有项目都需要填写。
A3: 序号 | B3: 项目名称 | C3: 项目特征 | D3: 适用范围 | E3: 工程量计算规则 | F3: 单位 | G3: 24/25年暂估工程量 | H3: 综合单价 | I3: 人工费 | J3: 材料费 | K3: 机械费 | L3: 安措费 | M3: 管理费 | N3: 利润 | O3: 24/25年暂估总价 | P3: 备注
B4: 2.1装饰工程
A5: 2.1.1 | B5: 拆除工程
A6: 2.1.1.01 | B6: 原有石膏板天花拆除 | C6: 1.拆除原有天花 2.龙骨、吊筋拆除 | D6: 室内、室外装饰装修及安装工程项目 | E6: 按拆除面积计算。垃圾清理折算系数：0.05 | F6: m2 | G6: 1123021.8 | H6: =SUM(I6:N6) -> 10.493506 | I6: 10.14961 | J6: 0 | K6: 0.24 | L6: =(I6+J6+K6)*'2-报价汇总'!$H$5 -> 0.1038961 | M6: =(I6+J6+K6+L6)*'2-报价汇总'!$I$5 -> 0 | N6: =(M6+L6+K6+J6+I6)*'2-报价汇总'!$J$5 -> 0 | O6: =G6*H6 -> 11784437
A7: 2.1.1.02 | B7: 原有矿棉板/铝扣板天花拆除 | C7: 1.拆除原有天花 2.龙骨、吊筋拆除 | D7: 室内、室外装饰装修及安装工程项目 | E7: 按拆除面积计算。垃圾清理折算系数：0.05 | F7: m2 | G7: 355016.51 | H7: =SUM(I7:N7) -> 8.7445887 | I7: 8.4580087 | J7: 0 | K7: 0.2 | L7: =(I7+J7+K7)*'2-报价汇总'!$H$5 -> 0.086580087 | M7: =(I7+J7+K7+L7)*'2-报价汇总'!$I$5 -> 0 | N7: =(M7+L7+K7+J7+I7)*'2-报价汇总'!$J$5 -> 0 | O7: =G7*H7 -> 3104473.4
A8: 2.1.1.03 | B8: 原有地砖或石材地面拆除 *拆除至不改变地面标高 | C8: 1.拆除原有地面石材&地砖 2.粘结层拆除至满足图纸地面面层做法高度 | D8: 室内、室外装饰装修及安装工程项目 | E8: 按拆除面积计算。垃圾清理折算系数：0.05 | F8: m2 | G8: 1080551.6 | H8: =SUM(I8:N8) -> 27.982684 | I8: 27.005628 | J8: 0 | K8: 0.7 | L8: =(I8+J8+K8)*'2-报价汇总'!$H$5 -> 0.27705628 | M8: =(I8+J8+K8+L8)*'2-报价汇总'!$I$5 -> 0 | N8: =(M8+L8+K8+J8+I8)*'2-报价汇总'!$J$5 -> 0 | O8: =G8*H8 -> 30236735
A9: 2.1.1.04 | B9: 混凝土地面拆除 | C9: 1.拆除原有混凝土地面，≤100mm厚 2.＞100mm厚按此项目比例折算 | D9: 室内、室外装饰装修及安装工程项目 | E9: 按拆除面积计算。垃圾清理折算系数：0.05 | F9: m2 | G9: 350000 | H9: =SUM(I9:N9) -> 52.467532 | I9: 50.978052 | J9: 0 | K9: 0.97 | L9: =(I9+J9+K9)*'2-报价汇总'!$H$5 -> 0.51948052 | M9: =(I9+J9+K9+L9)*'2-报价汇总'!$I$5 -> 0 | N9: =(M9+L9+K9+J9+I9)*'2-报价汇总'!$J$5 -> 0 | O9: =G9*H9 -> 18363636
A10: 2.1.1.05 | B10: 原有环氧树脂地面拆除（刨铣） *拆除至不改变地面标高 | C10: 1.拆除原有环氧树脂自流平 2.地面打磨平整并不改变地面标高 | D10: 室内、室外装饰装修及安装工程项目 | E10: 按拆除面积计算。垃圾清理折算系数：0.005 | F10: m2 | G10: 300000 | H10: =SUM(I10:N10) -> 10.493506 | I10: 9.8096104 | J10: 0 | K10: 0.58 | L10: =(I10+J10+K10)*'2-报价汇总'!$H$5 -> 0.1038961 | M10: =(I10+J10+K10+L10)*'2-报价汇总'!$I$5 -> 0 | N10: =(M10+L10+K10+J10+I10)*'2-报价汇总'!$J$5 -> 0 | O10: =G10*H10 -> 3148051.9
A11: 2.1.1.06 | B11: 原有地毯或胶地板地面拆除 | C11: 1.拆除原有地面地毯、胶地板、木地板 | D11: 室内、室外装饰装修及安装工程项目 | E11: 按拆除面积计算。垃圾清理折算系数：0.01 | F11: m2 | G11: 50000 | H11: =SUM(I11:N11) -> 5.2467532 | I11: 4.9748052 | J11: 0 | K11: 0.22 | L11: =(I11+J11+K11)*'2-报价汇总'!$H$5 -> 0.051948052 | M11: =(I11+J11+K11+L11)*'2-报价汇总'!$I$5 -> 0 | N11: =(M11+L11+K11+J11+I11)*'2-报价汇总'!$J$5 -> 0 | O11: =G11*H11 -> 262337.66
A12: 2.1.1.07 | B12: 原有砌筑墙体（连门）拆除 | C12: 1.拆除原有砌体墙连墙体内砼柱破碎 2.装袋清理 | D12: 室内、室外装饰装修及安装工程项目 | E12: 以 m3计量，按拆除的体积计算。垃圾清理折算系数：1 | F12: m3 | G12: 283578.53 | H12: =SUM(I12:N12) -> 174.89177 | I12: 171.02017 | J12: 0 | K12: 2.14 | L12: =(I12+J12+K12)*'2-报价汇总'!$H$5 -> 1.7316017 | M12: =(I12+J12+K12+L12)*'2-报价汇总'!$I$5 -> 0 | N12: =(M12+L12+K12+J12+I12)*'2-报价汇总'!$J$5 -> 0 | O12: =G12*H12 -> 49595553
A13: 2.1.1.08 | B13: 原有玻璃隔墙（连门）拆除 | C13: 1.拆除原有玻璃隔断及框 2.装袋清理 | D13: 室内、室外装饰装修及安装工程项目 | E13: 按拆除的面积计算。垃圾清理折算系数：0.05 | F13: m2 | G13: 145436.63 | H13: =SUM(I13:N13) -> 17.489177 | I13: 17.116017 | J13: 0 | K13: 0.2 | L13: =(I13+J13+K13)*'2-报价汇总'!$H$5 -> 0.17316017 | M13: =(I13+J13+K13+L13)*'2-报价汇总'!$I$5 -> 0 | N13: =(M13+L13+K13+J13+I13)*'2-报价汇总'!$J$5 -> 0 | O13: =G13*H13 -> 2543567.1
A14: 2.1.1.09 | B14: 原有石膏板/水泥压力板隔墙（连门）拆除 | C14: 1.拆除原有龙骨式隔墙 2.装袋清理 | D14: 室内、室外装饰装修及安装工程项目 | E14: 按拆除面积计算。垃圾清理折算系数：0.15 | F14: m2 | G14: 494719.99 | H14: =SUM(I14:N14) -> 19.233898 | I14: 18.083463 | J14: 0 | K14: 0.96 | L14: =(I14+J14+K14)*'2-报价汇总'!$H$5 -> 0.19043463 | M14: =(I14+J14+K14+L14)*'2-报价汇总'!$I$5 -> 0 | N14: =(M14+L14+K14+J14+I14)*'2-报价汇总'!$J$5 -> 0 | O14: =G14*H14 -> 9515393.8
A15: 2.1.1.10 | B15: 拆除墙面石材、墙砖 | C15: 1.拆除原有墙面石材&瓷砖 2.粘结层拆除至满足图纸墙面面层做法厚度 | D15: 室内、室外装饰装修及安装工程项目 | E15: 按拆除面积计算。垃圾清理折算系数：0.05 | F15: m2 | G15: 45876.504 | H15: =SUM(I15:N15) -> 27.982684 | I15: 26.925628 | J15: 0 | K15: 0.78 | L15: =(I15+J15+K15)*'2-报价汇总'!$H$5 -> 0.27705628 | M15: =(I15+J15+K15+L15)*'2-报价汇总'!$I$5 -> 0 | N15: =(M15+L15+K15+J15+I15)*'2-报价汇总'!$J$5 -> 0 | O15: =G15*H15 -> 1283747.7
A16: 2.1.1.11 | B16: 乳胶漆铲除 | C16: 1.铲除原有墙面/顶面乳胶漆及腻子 | D16: 室内、室外装饰装修及安装工程项目 | E16: 按拆除部位的面积计算。垃圾清理折算系数：0.001 | F16: m2 | G16: 2000 | H16: =SUM(I16:N16) -> 4.3722944 | I16: 4.2690043 | J16: 0 | K16: 0.06 | L16: =(I16+J16+K16)*'2-报价汇总'!$H$5 -> 0.043290043 | M16: =(I16+J16+K16+L16)*'2-报价汇总'!$I$5 -> 0 | N16: =(M16+L16+K16+J16+I16)*'2-报价汇总'!$J$5 -> 0 | O16: =G16*H16 -> 8744.5887
A17: 2.1.1.12 | B17: 拆除外窗 | C17: 1.拆除原有外窗 2.装袋清理 | D17: 室内、室外装饰装修及安装工程项目 | E17: 按拆除部位的面积计算。垃圾清理折算系数：0.02 | F17: m2 | G17: 64681.04 | H17: =SUM(I17:N17) -> 11.367965 | I17: 10.535411 | J17: 0 | K17: 0.72 | L17: =(I17+J17+K17)*'2-报价汇总'!$H$5 -> 0.11255411 | M17: =(I17+J17+K17+L17)*'2-报价汇总'!$I$5 -> 0 | N17: =(M17+L17+K17+J17+I17)*'2-报价汇总'!$J$5 -> 0 | O17: =G17*H17 -> 735291.82
... A38: 2.1.1.33 | B38: 幕墙钢框保护利旧及拆除幕墙玻璃 | C38: 1.原有幕墙玻璃拆除 2.原幕墙结构保护 3.垃圾清理及垃圾外运 | D38: 室内、室外装饰装修及安装工程项目 | E38: 按拆除面积计算 | F38: m2 | G38: 5000 | H38: =SUM(I38:N38) -> 43.719971 | I38: 42.2871 | J38: 0 | K38: 1 | L38: =(I38+J38+K38)*'2-报价汇总'!$H$5 -> 0.432871 | M38: =(I38+J38+K38+L38)*'2-报价汇总'!$I$5 -> 0 | N38: =(M38+L38+K38+J38+I38)*'2-报价汇总'!$J$5 -> 0 | O38: =G38*H38 -> 218599.85
A39: 2.1.1.34 | B39: 拆除垃圾清理、清运（规格：5立方） | D39: 室内、室外装饰装修及安装工程项目 | E39: 分项工程垃圾清理折算系数*面积之和/5 | F39: 车 | G39: 30000 | H39: =SUM(I39:N39) -> 546.5368 | I39: 181.12554 | J39: 0 | K39: 360 | L39: =(I39+J39+K39)*'2-报价汇总'!$H$5 -> 5.4112554 | M39: =(I39+J39+K39+L39)*'2-报价汇总'!$I$5 -> 0 | N39: =(M39+L39+K39+J39+I39)*'2-报价汇总'!$J$5 -> 0 | O39: =G39*H39 -> 16396104
A40: 2.1.1.35 | B40: 拆除垃圾清理、清运（规格：7立方） | D40: 室内、室外装饰装修及安装工程项目 | E40: 分项工程垃圾清理折算系数*面积之和/7 | F40: 车 | G40: 35655.67 | H40: =SUM(I40:N40) -> 765.15152 | I40: 257.57576 | J40: 0 | K40: 500 | L40: =(I40+J40+K40)*'2-报价汇总'!$H$5 -> 7.5757576 | M40: =(I40+J40+K40+L40)*'2-报价汇总'!$I$5 -> 0 | N40: =(M40+L40+K40+J40+I40)*'2-报价汇总'!$J$5 -> 0 | O40: =G40*H40 -> 27281990
B41: 补充项
B42: 小 计
A43: 2.1.2 | B43: 隔断工程
A44: 2.1.2.01 | B44: 120mm厚双面双层石膏板隔墙 | C44: 1.75轻钢龙骨 间距400 2.双面双层9厘石膏板 防锈螺钉固定 3.内填50mm隔音岩棉，容重65kg/m3 | D44: 室内、室外装饰装修项目 | E44: 按设计图示尺寸以面积计算 | F44: m2 | G44: 139029.87 | H44: =SUM(I44:N44) -> 197.455 | I44: 94.3 | J44: 100 | K44: 1.2 | L44: =(I44+J44+K44)*'2-报价汇总'!$H$5 -> 1.955 | M44: =(I44+J44+K44+L44)*'2-报价汇总'!$I$5 -> 0 | N44: =(M44+L44+K44+J44+I44)*'2-报价汇总'!$J$5 -> 0 | O44: =G44*H44 -> 27452143
A45: 2.1.2.02 | B45: 120mm厚双面双层防水石膏板隔墙 | C45: 1.75轻钢龙骨 间距400 2.双面双层9厘防水石膏板 防锈螺钉固定 3.内填50mm隔音岩棉，容重65kg/m3 | D45: 室内、室外装饰装修项目 | E45: 按设计图示尺寸面积计算 | F45: m2 | G45: 80000 | H45: =SUM(I45:N45) -> 217.655 | I45: 94.3 | J45: 120 | K45: 1.2 | L45: =(I45+J45+K45)*'2-报价汇总'!$H$5 -> 2.155 | M45: =(I45+J45+K45+L45)*'2-报价汇总'!$I$5 -> 0 | N45: =(M45+L45+K45+J45+I45)*'2-报价汇总'!$J$5 -> 0 | O45: =G45*H45 -> 17412400
A46: 2.1.2.03 | B46: 100mm厚单面双层石膏板隔墙包管道或墙体，假天花标高：（管道、消防栓） | C46: 1.75轻钢龙骨 间距400 2单面双层9厘石膏板 防锈螺钉固定 3.内填50mm隔音岩棉，容重65kg/m3 | D46: 室内、室外装饰装修项目 | E46: 按设计图示尺寸面积计算 | F46: m2 | G46: 499161.28 | H46: =SUM(I46:N46) -> 144.632 | I46: 62 | J46: 80 | K46: 1.2 | L46: =(I46+J46+K46)*'2-报价汇总'!$H$5 -> 1.432 | M46: =(I46+J46+K46+L46)*'2-报价汇总'!$I$5 -> 0 | N46: =(M46+L46+K46+J46+I46)*'2-报价汇总'!$J$5 -> 0 | O46: =G46*H46 -> 72194694
A47: 2.1.2.04 | B47: 100mm厚单面双层防水石膏板隔墙包管道或墙体，假天花标高：（管道、消防栓） | C47: 1.75轻钢龙骨 间距400 2单面双层9厘防水石膏板 防锈螺钉固定 3.内填50mm隔音岩棉，容重65kg/m3 | D47: 室内、室外装饰装修项目 | E47: 按设计图示尺寸面积计算 | F47: m2 | G47: 499161.28 | H47: =SUM(I47:N47) -> 154.732 | I47: 62 | J47: 90 | K47: 1.2 | L47: =(I47+J47+K47)*'2-报价汇总'!$H$5 -> 1.532 | M47: =(I47+J47+K47+L47)*'2-报价汇总'!$I$5 -> 0 | N47: =(M47+L47+K47+J47+I47)*'2-报价汇总'!$J$5 -> 0 | O47: =G47*H47 -> 77236223
A48: 2.1.2.05 | B48: 100mm厚双面单层水泥压力板隔墙 | C48: 1.75轻钢龙骨 间距400 2.双面单层12厘水泥压力板 防锈螺钉固定 3.内填50mm隔音岩棉，容重65kg/m3 | D48: 室内、室外装饰装修项目 | E48: 按设计图示尺寸面积计算 | F48: m2 | G48: 69708.456 | H48: =SUM(I48:N48) -> 156.752 | I48: 62 | J48: 92 | K48: 1.2 | L48: =(I48+J48+K48)*'2-报价汇总'!$H$5 -> 1.552 | M48: =(I48+J48+K48+L48)*'2-报价汇总'!$I$5 -> 0 | N48: =(M48+L48+K48+J48+I48)*'2-报价汇总'!$J$5 -> 0 | O48: =G48*H48 -> 10926940
A49: 2.1.2.06 | B49: 100mm厚单面单层水泥压力板板隔墙包管道或墙体，假天花标高：（管道、消防栓） | C49: 1.75轻钢龙骨 间距400 2.单面单层12厘水泥压力板 防锈螺钉固定 3.内填50mm隔音岩棉，容重65kg/m3 | D49: 室内、室外装饰装修项目 | E49: 按设计图示尺寸面积计算 | F49: m2 | G49: 69708.456 | H49: =SUM(I49:N49) -> 133.32 | I49: 56 | J49: 75 | K49: 1 | L49: =(I49+J49+K49)*'2-报价汇总'!$H$5 -> 1.32 | M49: =(I49+J49+K49+L49)*'2-报价汇总'!$I$5 -> 0 | N49: =(M49+L49+K49+J49+I49)*'2-报价汇总'!$J$5 -> 0 | O49: =G49*H49 -> 9293531.3
A50: 2.1.2.07 | B50: 120mm厚单面双层石膏板+单面双层水泥板隔墙 | C50: 1.75轻钢龙骨 间距400 2.单面双层9厘石膏板+单面双层9厘水泥板 防锈螺钉固定 3.内填50mm隔音岩棉，容重65kg/m3 | D50: 室内、室外装饰装修项目（无特殊原因不采用此项目，砌块墙优先选择） | E50: 按设计图示尺寸面积计算 | F50: m2 | G50: 10000 | H50: =SUM(I50:N50) -> 248.2681 | I50: 120 | J50: 120 | K50: 5.81 | L50: =(I50+J50+K50)*'2-报价汇总'!$H$5 -> 2.4581 | M50: =(I50+J50+K50+L50)*'2-报价汇总'!$I$5 -> 0 | N50: =(M50+L50+K50+J50+I50)*'2-报价汇总'!$J$5 -> 0 | O50: =G50*H50 -> 2482681
A51: 2.1.2.08 | B51: 120mm厚双面双层水泥压力板隔墙 | C51: 1.75轻钢龙骨 间距400 2.双面双层9厘水泥压力板 防锈螺钉固定 3.内填50mm隔音岩棉，容重65kg/m3 | D51: 室内、室外装饰装修项目（无特殊原因不采用此项目，砌块墙优先选择） | E51: 按设计图示尺寸面积计算 | F51: m2 | G51: 10000 | H51: =SUM(I51:N51) -> 183.63636 | I51: 45.838182 | J51: 130 | K51: 5.98 | L51: =(I51+J51+K51)*'2-报价汇总'!$H$5 -> 1.8181818 | M51: =(I51+J51+K51+L51)*'2-报价汇总'!$I$5 -> 0 | N51: =(M51+L51+K51+J51+I51)*'2-报价汇总'!$J$5 -> 0 | O51: =G51*H51 -> 1836363.6
A52: 2.1.2.09 | B52: 100mm厚单面双层水泥压力板板隔墙包管道或墙体（管道、消防栓） | C52: 1.75轻钢龙骨 间距400 2.单面双层9厘水泥压力板 防锈螺钉固定 3.内填50mm隔音岩棉，容重65kg/m3 | D52: 室内、室外装饰装修项目（无特殊原因不采用此项目，砌块墙优先选择） | E52: 按设计图示尺寸面积计算 | F52: m2 | G52: 10000 | H52: =SUM(I52:N52) -> 139.91342 | I52: 64.958139 | J52: 70 | K52: 3.57 | L52: =(I52+J52+K52)*'2-报价汇总'!$H$5 -> 1.3852814 | M52: =(I52+J52+K52+L52)*'2-报价汇总'!$I$5 -> 0 | N52: =(M52+L52+K52+J52+I52)*'2-报价汇总'!$J$5 -> 0 | O52: =G52*H52 -> 1399134.2
A53: 2.1.2.10 | B53: 在原有墙面 贴2层纸面石膏板 单面双层9mm厚石膏板 防锈螺钉固定 | C53: 1.原墙面修补双层纸面石膏板 2.防锈螺钉固定 | D53: 室内、室外装饰装修项目 | E53: 按设计图示尺寸面积计算 | F53: m2 | G53: 10000 | H53: =SUM(I53:N53) -> 56.839827 | I53: 25.647056 | J53: 30 | K53: 0.63 | L53: =(I53+J53+K53)*'2-报价汇总'!$H$5 -> 0.56277056 | M53: =(I53+J53+K53+L53)*'2-报价汇总'!$I$5 -> 0 | N53: =(M53+L53+K53+J53+I53)*'2-报价汇总'!$J$5 -> 0 | O53: =G53*H53 -> 568398.27
A54: 2.1.2.11 | B54: 20*40方钢管双层防水纸面石膏板 | C54: 1.20*40方钢龙骨 2.双面双层9厘防水石膏板，防锈螺钉固定 3.内填50mm隔音岩棉，容重65kg/m3 | D54: 室内、室外装饰装修项目 | E54: 按设计图示尺寸面积计算 | F54: m2 | G54: 10000 | H54: =SUM(I54:N54) -> 214.24242 | I54: 65.931212 | J54: 140 | K54: 6.19 | L54: =(I54+J54+K54)*'2-报价汇总'!$H$5 -> 2.1212121 | M54: =(I54+J54+K54+L54)*'2-报价汇总'!$I$5 -> 0 | N54: =(M54+L54+K54+J54+I54)*'2-报价汇总'!$J$5 -> 0 | O54: =G54*H54 -> 2142424.2
A55: 2.1.2.12 | B55: 在原有墙面 贴2层水泥板 单面双层12mm厚水泥压力板 防锈螺钉固定 | C55: 1.原墙面修补双层水泥压力板 2.防锈螺钉固定 | D55: 室内、室外装饰装修项目 | E55: 按设计图示尺寸面积计算 | F55: m2 | G55: 35540.846 | H55: =SUM(I55:N55) -> 65.584416 | I55: 24.135065 | J55: 40 | K55: 0.8 | L55: =(I55+J55+K55)*'2-报价汇总'!$H$5 -> 0.64935065 | M55: =(I55+J55+K55+L55)*'2-报价汇总'!$I$5 -> 0 | N55: =(M55+L55+K55+J55+I55)*'2-报价汇总'!$J$5 -> 0 | O55: =G55*H55 -> 2330925.6
... A74: 2.1.2.31 | B74: 单面单层阻燃板隔墙 | C74: 1.75轻钢龙骨 2.单层15厘阻燃板 防锈螺钉固定 3.内填50mm隔音岩棉，容重65kg/m3 | D74: 室内装饰装修项目 | E74: 按设计图示尺寸以以面积计算 | F74: m2 | G74: 5000 | H74: =SUM(I74:N74) -> 149.682 | I74: 45 | J74: 102 | K74: 1.2 | L74: =(I74+J74+K74)*'2-报价汇总'!$H$5 -> 1.482 | M74: =(I74+J74+K74+L74)*'2-报价汇总'!$I$5 -> 0 | N74: =(M74+L74+K74+J74+I74)*'2-报价汇总'!$J$5 -> 0 | O74: =G74*H74 -> 748410
A75: 2.1.2.32 | B75: 100mm厚单面单层石膏板隔墙 | C75: 1.75轻钢龙骨间距400 2.单面单层9厘石膏板 防锈螺钉固定 3.内填50mm隔音岩棉，容重65kg/m3 | D75: 室内、室外装饰装修项目 | E75: 按设计图示尺寸以面积计算 | F75: m2 | G75: 5000 | H75: =SUM(I75:N75) -> 118.877 | I75: 45 | J75: =100-9.5*3 -> 71.5 | K75: 1.2 | L75: =(I75+J75+K75)*'2-报价汇总'!$H$5 -> 1.177 | M75: =(I75+J75+K75+L75)*'2-报价汇总'!$I$5 -> 0 | N75: =(M75+L75+K75+J75+I75)*'2-报价汇总'!$J$5 -> 0 | O75: =G75*H75 -> 594385
A76: 2.1.2.33 | B76: 隔墙圆弧角加工制作（阴角弧长785mm） | C76: 1.75轻钢龙骨 间距400 2.双面双层9厘石膏板 防锈螺钉固定 3.内填50mm隔音岩棉，容重65kg/m3 | E76: 按设计图示尺寸以长度计算（从地面算至天花） | F76: m | G76: 14401.923 | H76: =SUM(I76:N76) -> 44.036 | I76: 12 | J76: =7.6*4 -> 30.4 | K76: 1.2 | L76: =(I76+J76+K76)*'2-报价汇总'!$H$5 -> 0.436 | M76: =(I76+J76+K76+L76)*'2-报价汇总'!$I$5 -> 0 | N76: =(M76+L76+K76+J76+I76)*'2-报价汇总'!$J$5 -> 0 | O76: =G76*H76 -> 634203.07
A77: 2.1.2.34 | B77: 隔墙圆弧角加工制作（阳角弧长314mm） | C77: 1.75轻钢龙骨 间距400 2.双面双层9厘石膏板 防锈螺钉固定 3.内填50mm隔音岩棉，容重65kg/m3 | E77: 按设计图示尺寸以长度计算（从地面算至天花） | F77: m | G77: 5469.0846 | H77: =SUM(I77:N77) -> 22.018 | I77: 6 | J77: =J76/2 -> 15.2 | K77: 0.6 | L77: =(I77+J77+K77)*'2-报价汇总'!$H$5 -> 0.218 | M77: =(I77+J77+K77+L77)*'2-报价汇总'!$I$5 -> 0 | N77: =(M77+L77+K77+J77+I77)*'2-报价汇总'!$J$5 -> 0 | O77: =G77*H77 -> 120418.3 | P77: =SUM(#REF!) -> #REF!
B78: 补充项
...

Sheet 2.2-电气工程
A1: 理想汽车中心店电气工程量清单
A2: ='2.1-装饰工程'!A2 -> 注意：此报价清单每项不得随意更改、删减，如有任何增加项请务必在每大项最后“补充项“中列举，补充项及说明字体颜色均采用蓝色；且所有项目都需要填写。
A3: 序号 | B3: 名 称 | C3: 项目特征 | D3: 适用范围 | E3: 工程量计算规则 | F3: 单位 | G3: 24/25年暂估工程量 | H3: 综合单价 | I3: 人工费 | J3: 材料费 | K3: 机械费 | L3: 安措费 | M3: 管理费 | N3: 利润 | O3: 24/25年暂估总价 | P3: 备注
B4: 2.2电气工程
A5: 2.2.1 | B5: 配电部分
B6: 新增配电箱（除空开外一切配套附件）
A7: 2.2.1.01 | B7: 移位配电箱 | C7: 1.拆除原有配电箱 2.安装利旧原有配电箱 3.元配电箱元器件检测 | D7: 室内、室外装饰装修项目 | E7: 按设计图示数量计算 | F7: 个 | G7: 100 | H7: =SUM(I7:N7) -> 507.18615 | I7: 408.2645 | J7: 88.89 | K7: 5.01 | L7: =(I7+J7+K7)*'2-报价汇总'!$H$5 -> 5.021645 | M7: =(I7+J7+K7+L7)*'2-报价汇总'!$I$5 -> 0 | N7: =(M7+L7+K7+J7+I7)*'2-报价汇总'!$J$5 -> 0 | O7: =G7*H7 -> 50718.615
A8: 2.2.1.02 | B8: 总配电箱箱体 | C8: 1000*1200以上规格 | D8: 室内、室外装饰装修项目 | E8: 按设计图示数量计算 包含配套铜排及落地安装基础、接地等 | F8: 个 | G8: 800 | H8: =SUM(I8:N8) -> 2273.5931 | I8: 598.35498 | J8: 1600 | K8: 52.727273 | L8: =(I8+J8+K8)*'2-报价汇总'!$H$5 -> 22.510823 | M8: =(I8+J8+K8+L8)*'2-报价汇总'!$I$5 -> 0 | N8: =(M8+L8+K8+J8+I8)*'2-报价汇总'!$J$5 -> 0 | O8: =G8*H8 -> 1818874.5
A9: 2.2.1.03 | B9: 一级配电箱 | C9: 800*1000以上规格 | D9: 室内、室外装饰装修项目 | F9: 个 | G9: 1823.0282 | H9: =SUM(I9:N9) -> 1748.9177 | I9: 525.10173 | J9: 1200 | K9: 6.5 | L9: =(I9+J9+K9)*'2-报价汇总'!$H$5 -> 17.316017 | M9: =(I9+J9+K9+L9)*'2-报价汇总'!$I$5 -> 0 | N9: =(M9+L9+K9+J9+I9)*'2-报价汇总'!$J$5 -> 0 | O9: =G9*H9 -> 3188326.4
A10: 2.2.1.04 | B10: 二级配电箱 | D10: 室内、室外装饰装修项目 | E10: 按设计图示数量计算 | F10: 个 | G10: 4557.5705 | H10: =SUM(I10:N10) -> 664.58874 | I10: 193.14866 | J10: 461.08 | K10: 3.78 | L10: =(I10+J10+K10)*'2-报价汇总'!$H$5 -> 6.5800866 | M10: =(I10+J10+K10+L10)*'2-报价汇总'!$I$5 -> 0 | N10: =(M10+L10+K10+J10+I10)*'2-报价汇总'!$J$5 -> 0 | O10: =G10*H10 -> 3028910
A11: 2.2.1.05 | B11: 设备终端箱 | D11: 室内、室外装饰装修项目 | E11: 按设计图示数量计算 | F11: 个 | G11: 20053.31 | H11: =SUM(I11:N11) -> 524.67532 | I11: 56.950519 | J11: 459.19 | K11: 3.34 | L11: =(I11+J11+K11)*'2-报价汇总'!$H$5 -> 5.1948052 | M11: =(I11+J11+K11+L11)*'2-报价汇总'!$I$5 -> 0 | N11: =(M11+L11+K11+J11+I11)*'2-报价汇总'!$J$5 -> 0 | O11: =G11*H11 -> 10521477
A12: 2.2.1.06 | B12: 供应及安装成套配电箱，包括开箱检查、本体安装固定、箱内辅材、连接线缆、接地、调试等，一切如图纸及规范所述。 | D12: 室内、室外装饰装修项目 | E12: 按设计图示数量计算 | F12: 个 | G12: 27345.423 | H12: =SUM(I12:N12) -> 206.98442 | I12: 204.93506 | L12: =(I12+J12+K12)*'2-报价汇总'!$H$5 -> 2.0493506 | M12: =(I12+J12+K12+L12)*'2-报价汇总'!$I$5 -> 0 | N12: =(M12+L12+K12+J12+I12)*'2-报价汇总'!$J$5 -> 0 | O12: =G12*H12 -> 5660076.4
A13: 2.2.1.07 | B13: NB3-63 C16/1P | C13: 1.电气元器件及附件供应安装 2.接线、调试 | D13: 配电箱内 | E13: 按设计图示数量计算 | F13: 个 | G13: 41929.648 | H13: =SUM(I13:N13) -> 14.603463 | I13: 2.7588745 | J13: 11.37 | K13: 0.33 | L13: =(I13+J13+K13)*'2-报价汇总'!$H$5 -> 0.14458874 | M13: =(I13+J13+K13+L13)*'2-报价汇总'!$I$5 -> 0 | N13: =(M13+L13+K13+J13+I13)*'2-报价汇总'!$J$5 -> 0 | O13: =G13*H13 -> 612318.08
A14: 2.2.1.08 | B14: NB3-63 C16/2P | C14: 1.电气元器件及附件供应安装 2.接线、调试 | D14: 配电箱内 | E14: 按设计图示数量计算 | F14: 个 | G14: 76567.184 | H14: =SUM(I14:N14) -> 25.709091 | I14: 11.464545 | J14: 13.55 | K14: 0.44 | L14: =(I14+J14+K14)*'2-报价汇总'!$H$5 -> 0.25454545 | M14: =(I14+J14+K14+L14)*'2-报价汇总'!$I$5 -> 0 | N14: =(M14+L14+K14+J14+I14)*'2-报价汇总'!$J$5 -> 0 | O14: =G14*H14 -> 1968472.7
A15: 2.2.1.09 | B15: NB3-63 C16/3P | C15: 1.电气元器件及附件供应安装 2.接线、调试 | D15: 配电箱内 | E15: 按设计图示数量计算 | F15: 个 | G15: 15000 | H15: =SUM(I15:N15) -> 33.404329 | I15: 12.573593 | J15: 20.06 | K15: 0.44 | L15: =(I15+J15+K15)*'2-报价汇总'!$H$5 -> 0.33073593 | M15: =(I15+J15+K15+L15)*'2-报价汇总'!$I$5 -> 0 | N15: =(M15+L15+K15+J15+I15)*'2-报价汇总'!$J$5 -> 0 | O15: =G15*H15 -> 501064.94
A16: 2.2.1.10 | B16: NXB-63 D16/1P | C16: 1.电气元器件及附件供应安装 2.接线、调试 | D16: 配电箱内 | E16: 按设计图示数量计算 | F16: 个 | G16: 500 | H16: =SUM(I16:N16) -> 10.7471 | I16: 3.9406926 | J16: 6.37 | K16: 0.33 | L16: =(I16+J16+K16)*'2-报价汇总'!$H$5 -> 0.10640693 | M16: =(I16+J16+K16+L16)*'2-报价汇总'!$I$5 -> 0 | N16: =(M16+L16+K16+J16+I16)*'2-报价汇总'!$J$5 -> 0 | O16: =G16*H16 -> 5373.5498
A17: 2.2.1.11 | B17: NXB-63 D16/2P | C17: 1.电气元器件及附件供应安装 2.接线、调试 | D17: 配电箱内 | E17: 按设计图示数量计算 | F17: 个 | G17: 2000 | H17: =SUM(I17:N17) -> 24.047619 | I17: 9.8195238 | J17: 13.55 | K17: 0.44 | L17: =(I17+J17+K17)*'2-报价汇总'!$H$5 -> 0.23809524 | M17: =(I17+J17+K17+L17)*'2-报价汇总'!$I$5 -> 0 | N17: =(M17+L17+K17+J17+I17)*'2-报价汇总'!$J$5 -> 0 | O17: =G17*H17 -> 48095.238
A18: 2.2.1.12 | B18: NXB-63 D16/3P | C18: 1.电气元器件及附件供应安装 2.接线、调试 | D18: 配电箱内 | E18: 按设计图示数量计算 | F18: 个 | G18: 2000 | H18: =SUM(I18:N18) -> 33.404329 | I18: 12.573593 | J18: 20.06 | K18: 0.44 | L18: =(I18+J18+K18)*'2-报价汇总'!$H$5 -> 0.33073593 | M18: =(I18+J18+K18+L18)*'2-报价汇总'!$I$5 -> 0 | N18: =(M18+L18+K18+J18+I18)*'2-报价汇总'!$J$5 -> 0 | O18: =G18*H18 -> 66808.658
A19: 2.2.1.13 | B19: NXBLE-32 D16/4P(30mA) | C19: 1.电气元器件及附件供应安装 2.接线、调试 | D19: 配电箱内 | E19: 按设计图示数量计算 | F19: 个 | G19: 2000 | H19: =SUM(I19:N19) -> 84.997403 | I19: 35.215844 | J19: 48.5 | K19: 0.44 | L19: =(I19+J19+K19)*'2-报价汇总'!$H$5 -> 0.84155844 | M19: =(I19+J19+K19+L19)*'2-报价汇总'!$I$5 -> 0 | N19: =(M19+L19+K19+J19+I19)*'2-报价汇总'!$J$5 -> 0 | O19: =G19*H19 -> 169994.81
A20: 2.2.1.14 | B20: NB3-63 C20/1P | C20: 1.电气元器件及附件供应安装 2.接线、调试 | D20: 配电箱内 | E20: 按设计图示数量计算 | F20: 个 | G20: 2000 | H20: =SUM(I20:N20) -> 14.603463 | I20: 6.2188745 | J20: 7.8 | K20: 0.44 | L20: =(I20+J20+K20)*'2-报价汇总'!$H$5 -> 0.14458874 | M20: =(I20+J20+K20+L20)*'2-报价汇总'!$I$5 -> 0 | N20: =(M20+L20+K20+J20+I20)*'2-报价汇总'!$J$5 -> 0 | O20: =G20*H20 -> 29206.926
A21: 2.2.1.15 | B21: NB3-63 C20/2P | C21: 1.电气元器件及附件供应安装 2.接线、调试 | D21: 配电箱内 | E21: 按设计图示数量计算 | F21: 个 | G21: 4500 | H21: =SUM(I21:N21) -> 25.709091 | I21: 11.464545 | J21: 13.55 | K21: 0.44 | L21: =(I21+J21+K21)*'2-报价汇总'!$H$5 -> 0.25454545 | M21: =(I21+J21+K21+L21)*'2-报价汇总'!$I$5 -> 0 | N21: =(M21+L21+K21+J21+I21)*'2-报价汇总'!$J$5 -> 0 | O21: =G21*H21 -> 115690.91
A22: 2.2.1.16 | B22: NB3-63 C20/3P | C22: 1.电气元器件及附件供应安装 2.接线、调试 | D22: 配电箱内 | E22: 按设计图示数量计算 | F22: 个 | G22: 4500 | H22: =SUM(I22:N22) -> 33.780346 | I22: 16.505887 | J22: 16.5 | K22: 0.44 | L22: =(I22+J22+K22)*'2-报价汇总'!$H$5 -> 0.33445887 | M22: =(I22+J22+K22+L22)*'2-报价汇总'!$I$5 -> 0 | N22: =(M22+L22+K22+J22+I22)*'2-报价汇总'!$J$5 -> 0 | O22: =G22*H22 -> 152011.56
A23: 2.2.1.17 | B23: NXBLE-63 C20/2P（30mA） | C23: 1.电气元器件及附件供应安装 2.接线、调试 | D23: 配电箱内 | E23: 按设计图示数量计算 | F23: 个 | G23: 4500 | H23: =SUM(I23:N23) -> 54.741126 | I23: 11.929134 | J23: 41.83 | K23: 0.44 | L23: =(I23+J23+K23)*'2-报价汇总'!$H$5 -> 0.54199134 | M23: =(I23+J23+K23+L23)*'2-报价汇总'!$I$5 -> 0 | N23: =(M23+L23+K23+J23+I23)*'2-报价汇总'!$J$5 -> 0 | O23: =G23*H23 -> 246335.06
A24: 2.2.1.18 | B24: NXB-63 D20/1P | C24: 1.电气元器件及附件供应安装 2.接线、调试 | D24: 配电箱内 | E24: 按设计图示数量计算 | F24: 个 | G24: 4500 | H24: =SUM(I24:N24) -> 12.478528 | I24: 4.3149784 | J24: 7.6 | K24: 0.44 | L24: =(I24+J24+K24)*'2-报价汇总'!$H$5 -> 0.12354978 | M24: =(I24+J24+K24+L24)*'2-报价汇总'!$I$5 -> 0 | N24: =(M24+L24+K24+J24+I24)*'2-报价汇总'!$J$5 -> 0 | O24: =G24*H24 -> 56153.377
... A62: 2.2.1.56 | B62: NB6LE-63 C40/3P（30mA） | C62: 1.电气元器件及附件供应安装 2.接线、调试 | D62: 配电箱内 | E62: 按设计图示数量计算 | F62: 个 | G62: 300 | H62: =SUM(I62:N62) -> 89.3042 | I62: 15.49 | J62: 71.92 | K62: 1.01 | L62: =(I62+J62+K62)*'2-报价汇总'!$H$5 -> 0.8842 | M62: =(I62+J62+K62+L62)*'2-报价汇总'!$I$5 -> 0 | N62: =(M62+L62+K62+J62+I62)*'2-报价汇总'!$J$5 -> 0 | O62: =G62*H62 -> 26791.26
A63: 2.2.1.57 | B63: NXB-63/C25/4P、NXM-63/25A/4P | C63: 1.电气元器件及附件供应安装 2.接线、调试 | D63: 配电箱内 | E63: 按设计图示数量计算 | F63: 个 | G63: 6000 | H63: =SUM(I63:N63) -> 36.0873 | I63: 11.89 | J63: 23.4 | K63: 0.44 | L63: =(I63+J63+K63)*'2-报价汇总'!$H$5 -> 0.3573 | M63: =(I63+J63+K63+L63)*'2-报价汇总'!$I$5 -> 0 | N63: =(M63+L63+K63+J63+I63)*'2-报价汇总'!$J$5 -> 0 | O63: =G63*H63 -> 216523.8 | P63: 41.68
A64: 2.2.1.58 | B64: NXB-63/D20/4P | C64: 1.电气元器件及附件供应安装 2.接线、调试 | D64: 配电箱内 | E64: 按设计图示数量计算 | F64: 个 | G64: 6000 | H64: =SUM(I64:N64) -> 42.9452 | I64: 12.08 | J64: 30 | K64: 0.44 | L64: =(I64+J64+K64)*'2-报价汇总'!$H$5 -> 0.4252 | M64: =(I64+J64+K64+L64)*'2-报价汇总'!$I$5 -> 0 | N64: =(M64+L64+K64+J64+I64)*'2-报价汇总'!$J$5 -> 0 | O64: =G64*H64 -> 257671.2 | P64: 49.6
A65: 2.2.1.59 | B65: NXMLE-125/D63/3P（30mA） | C65: 1.电气元器件及附件供应安装 2.接线、调试 | D65: 配电箱内 | E65: 按设计图示数量计算 | F65: 个 | G65: 6000 | H65: =SUM(I65:N65) -> 135.5117 | I65: 26.71 | J65: 106.45 | K65: 1.01 | L65: =(I65+J65+K65)*'2-报价汇总'!$H$5 -> 1.3417 | M65: =(I65+J65+K65+L65)*'2-报价汇总'!$I$5 -> 0 | N65: =(M65+L65+K65+J65+I65)*'2-报价汇总'!$J$5 -> 0 | O65: =G65*H65 -> 813070.2 | P65: 156.52
A66: 2.2.1.60 | B66: ESC227P | C66: 1.电气元器件及附件供应安装 2.接线、调试 | D66: 配电箱内 | E66: 按设计图示数量计算 | F66: 个 | G66: 6000 | H66: =SUM(I66:N66) -> 301.1921 | I66: 128.58 | J66: 169.19 | K66: 0.44 | L66: =(I66+J66+K66)*'2-报价汇总'!$H$5 -> 2.9821 | M66: =(I66+J66+K66+L66)*'2-报价汇总'!$I$5 -> 0 | N66: =(M66+L66+K66+J66+I66)*'2-报价汇总'!$J$5 -> 0 | O66: =G66*H66 -> 1807152.6 | P66: 347.88
A67: 2.2.1.61 | B67: NXMLE-400/3P 250A（30mA） | C67: 1.电气元器件及附件供应安装 2.接线、调试 | D67: 配电箱内 | E67: 按设计图示数量计算 | F67: 个 | G67: 6000 | H67: =SUM(I67:N67) -> 378.0738 | I67: 100.32 | J67: 272.9105 | K67: 1.1 | L67: =(I67+J67+K67)*'2-报价汇总'!$H$5 -> 3.743305 | M67: =(I67+J67+K67+L67)*'2-报价汇总'!$I$5 -> 0 | N67: =(M67+L67+K67+J67+I67)*'2-报价汇总'!$J$5 -> 0 | O67: =G67*H67 -> 2268442.8 | P67: 436.68
A68: 2.2.1.62 | B68: NXBLE-63/C25 3P（30mA） | C68: 1.电气元器件及附件供应安装 2.接线、调试 | D68: 配电箱内 | E68: 按设计图示数量计算 | F68: 个 | G68: 6000 | H68: =SUM(I68:N68) -> 120.5839 | I68: 14.69 | J68: 103.6 | K68: 1.1 | L68: =(I68+J68+K68)*'2-报价汇总'!$H$5 -> 1.1939 | M68: =(I68+J68+K68+L68)*'2-报价汇总'!$I$5 -> 0 | N68: =(M68+L68+K68+J68+I68)*'2-报价汇总'!$J$5 -> 0 | O68: =G68*H68 -> 723503.4 | P68: 139.27
A69: 2.2.1.63 | B69: NM1-6300S/4300 630A 4极 | C69: 1.电气元器件及附件供应安装 2.接线、调试 | D69: 配电箱内 | E69: 按设计图示数量计算 | F69: 个 | G69: 6000 | H69: =SUM(I69:N69) -> 904.3237 | I69: 162.63 | J69: 731.73 | K69: 1.01 | L69: =(I69+J69+K69)*'2-报价汇总'!$H$5 -> 8.9537 | M69: =(I69+J69+K69+L69)*'2-报价汇总'!$I$5 -> 0 | N69: =(M69+L69+K69+J69+I69)*'2-报价汇总'!$J$5 -> 0 | O69: =G69*H69 -> 5425942.2 | P69: 1044.49
A70: 2.2.1.64 | B70: NM1-1250S/3300 1250A | C70: 1.电气元器件及附件供应安装 2.接线、调试 | D70: 配电箱内 | E70: 按设计图示数量计算 | F70: 个 | G70: 6000 | H70: =SUM(I70:N70) -> 2205.4158 | I70: 300.17 | J70: 1882.4 | K70: 1.01 | L70: =(I70+J70+K70)*'2-报价汇总'!$H$5 -> 21.8358 | M70: =(I70+J70+K70+L70)*'2-报价汇总'!$I$5 -> 0 | N70: =(M70+L70+K70+J70+I70)*'2-报价汇总'!$J$5 -> 0 | O70: =G70*H70 -> 13232495 | P70: 2547.26
A71: 2.2.1.65 | B71: NM1-630S/3300 500A | C71: 1.电气元器件及附件供应安装 2.接线、调试 | D71: 配电箱内 | E71: 按设计图示数量计算 | F71: 个 | G71: 6000 | H71: =SUM(I71:N71) -> 791.9309 | I71: 297.02 | J71: 486.06 | K71: 1.01 | L71: =(I71+J71+K71)*'2-报价汇总'!$H$5 -> 7.8409 | M71: =(I71+J71+K71+L71)*'2-报价汇总'!$I$5 -> 0 | N71: =(M71+L71+K71+J71+I71)*'2-报价汇总'!$J$5 -> 0 | O71: =G71*H71 -> 4751585.4 | P71: 914.68
A72: 2.2.1.66 | B72: NM1LE-400S/3300 315A 4极（30mA） | C72: 1.电气元器件及附件供应安装 2.接线、调试 | D72: 配电箱内 | E72: 按设计图示数量计算 | F72: 个 | G72: 6000 | H72: =SUM(I72:N72) -> 588.74415 | I72: 168.63 | J72: 413.275 | K72: 1.01 | L72: =(I72+J72+K72)*'2-报价汇总'!$H$5 -> 5.82915 | M72: =(I72+J72+K72+L72)*'2-报价汇总'!$I$5 -> 0 | N72: =(M72+L72+K72+J72+I72)*'2-报价汇总'!$J$5 -> 0 | O72: =G72*H72 -> 3532464.9 | P72: 680
A73: 2.2.1.67 | B73: ARD-80/4P/Ⅰ级 | C73: 1.电气元器件及附件供应安装 2.接线、调试 | D73: 配电箱内 | E73: 按设计图示数量计算 | F73: 个 | G73: 5000 | H73: =SUM(I73:N73) -> 744.5922 | I73: 145.67 | J73: 590.54 | K73: 1.01 | L73: =(I73+J73+K73)*'2-报价汇总'!$H$5 -> 7.3722 | M73: =(I73+J73+K73+L73)*'2-报价汇总'!$I$5 -> 0 | N73: =(M73+L73+K73+J73+I73)*'2-报价汇总'!$J$5 -> 0 | O73: =G73*H73 -> 3722961 | P73: 860
A74: 2.2.1.68 | B74: NM1-100S/3300 100A（30mA） | C74: 1.电气元器件及附件供应安装 2.接线、调试 | D74: 配电箱内 | E74: 按设计图示数量计算 | F74: 个 | G74: 5000 | H74: =SUM(I74:N74) -> 242.4202 | I74: 69 | J74: 170.01 | K74: 1.01 | L74: =(I74+J74+K74)*'2-报价汇总'!$H$5 -> 2.4002 | M74: =(I74+J74+K74+L74)*'2-报价汇总'!$I$5 -> 0 | N74: =(M74+L74+K74+J74+I74)*'2-报价汇总'!$J$5 -> 0 | O74: =G74*H74 -> 1212101 | P74: 280
... A81: 2.2.1.75 | B81: NXBLE-63 3P C16（30mA） | C81: 1.电气元器件及附件供应安装 2.接线、调试 | D81: 配电箱内 | E81: 按设计图示数量计算 | F81: 个 | G81: 5000 | H81: =SUM(I81:N81) -> 135.14305 | I81: 16.025 | J81: 117.34 | K81: 0.44 | L81: =(I81+J81+K81)*'2-报价汇总'!$H$5 -> 1.33805 | M81: =(I81+J81+K81+L81)*'2-报价汇总'!$I$5 -> 0 | N81: =(M81+L81+K81+J81+I81)*'2-报价汇总'!$J$5 -> 0 | O81: =G81*H81 -> 675715.25 | P81: 156.09
A82: 2.2.1.76 | B82: 定式控制器 NKG1 | C82: 1.电气元器件及附件供应安装 2.接线、调试 | D82: 配电箱内 | E82: 按设计图示数量计算 | F82: 个 | G82: 300 | H82: =SUM(I82:N82) -> 68.347706 | I82: 28.810996 | J82: 37.87 | K82: 0.99 | L82: =(I82+J82+K82)*'2-报价汇总'!$H$5 -> 0.67670996 | M82: =(I82+J82+K82+L82)*'2-报价汇总'!$I$5 -> 0 | N82: =(M82+L82+K82+J82+I82)*'2-报价汇总'!$J$5 -> 0 | O82: =G82*H82 -> 20504.312
A83: 2.2.1.77 | B83: 交流接触器 CJX2-1210 | C83: 1.电气元器件及附件供应安装 2.接线、调试 | D83: 配电箱内 | E83: 按设计图示数量计算 | F83: 个 | G83: 3646.0564 | H83: =SUM(I83:N83) -> 51.35697 | I83: 14.548485 | J83: 35.86 | K83: 0.44 | L83: =(I83+J83+K83)*'2-报价汇总'!$H$5 -> 0.50848485 | M83: =(I83+J83+K83+L83)*'2-报价汇总'!$I$5 -> 0 | N83: =(M83+L83+K83+J83+I83)*'2-报价汇总'!$J$5 -> 0 | O83: =G83*H83 -> 187250.41
...

Sheet 2.3-给排水工程
A1: 理想汽车中心店给排水工程量清单
A2: ='2.1-装饰工程'!A2 -> 注意：此报价清单每项不得随意更改、删减，如有任何增加项请务必在每大项最后“补充项“中列举，补充项及说明字体颜色均采用蓝色；且所有项目都需要填写。
A3: 序号 | B3: 项目名称 | C3: 项目特征 | D3: 适用范围 | E3: 工程量计算规则 | F3: 单位 | G3: 24/25年暂估工程量 | H3: 综合单价 | I3: 人工费 | J3: 材料费 | K3: 机械费 | L3: 安措费 | M3: 管理费 | N3: 利润 | O3: 24/25年暂估总价 | P3: 备注
B4: 2.3给排水工程
A5: 2.3.1 | B5: 卫生间工程
A6: 2.3.1.01 | B6: 坐便器采购及安装 | C6: 1.本体及辅料（软管、阀门等）安装 | D6: 卫生间、淋浴间、清扫间 | E6: 按设计图示数量计算 | F6: 套 | G6: 15495.74 | H6: =SUM(I6:N6) -> 2271.7728 | I6: 205 | J6: 2042.36 | K6: 1.92 | L6: =(I6+J6+K6)*'2-报价汇总'!$H$5 -> 22.4928 | M6: =(I6+J6+K6+L6)*'2-报价汇总'!$I$5 -> 0 | N6: =(M6+L6+K6+J6+I6)*'2-报价汇总'!$J$5 -> 0 | O6: =G6*H6 -> 35202800 | S6: 15495.74
A7: 2.3.1.02 | B7: 小便斗及感应器采购及安装 | C7: 1.本体及辅料（软管、阀门等）安装 | D7: 卫生间、淋浴间、清扫间 | E7: 按设计图示数量计算 | F7: 套 | G7: 7292.1128 | H7: =SUM(I7:N7) -> 2152.714 | I7: 150 | J7: 1980.64 | K7: 0.76 | L7: =(I7+J7+K7)*'2-报价汇总'!$H$5 -> 21.314 | M7: =(I7+J7+K7+L7)*'2-报价汇总'!$I$5 -> 0 | N7: =(M7+L7+K7+J7+I7)*'2-报价汇总'!$J$5 -> 0 | O7: =G7*H7 -> 15697833 | S7: 7292.1128
A8: 2.3.1.03 | B8: 洗手盆及龙头采购及安装 | C8: 1.本体及辅料（软管、阀门等）安装 | D8: 卫生间、淋浴间、清扫间 | E8: 按设计图示数量计算 | F8: 套 | G8: 5000 | H8: =SUM(I8:N8) -> 1914.6883 | I8: 143.88095 | J8: 1750.77 | K8: 1.08 | L8: =(I8+J8+K8)*'2-报价汇总'!$H$5 -> 18.95731 | M8: =(I8+J8+K8+L8)*'2-报价汇总'!$I$5 -> 0 | N8: =(M8+L8+K8+J8+I8)*'2-报价汇总'!$J$5 -> 0 | O8: =G8*H8 -> 9573441.3 | S8: 10938.169
A9: 2.3.1.04 | B9: 坐便器采购及安装（箭牌AB1287-400） | C9: 1.本体及辅料（软管、阀门等）安装 | D9: 员工区 | E9: 按设计图示数量计算 | F9: 套 | G9: 5000 | H9: =SUM(I9:N9) -> 1049.3506 | I9: 258.37104 | J9: 778.67 | K9: 1.92 | L9: =(I9+J9+K9)*'2-报价汇总'!$H$5 -> 10.38961 | M9: =(I9+J9+K9+L9)*'2-报价汇总'!$I$5 -> 0 | N9: =(M9+L9+K9+J9+I9)*'2-报价汇总'!$J$5 -> 0 | O9: =G9*H9 -> 5246753.2 | S9: 0
A10: 2.3.1.05 | B10: 小便斗及感应器采购及安装（箭牌AN633+感应器AGY108-3A（交流）） | C10: 1.本体及辅料（软管、阀门等）安装 | D10: 员工区 | E10: 按设计图示数量计算 | F10: 套 | G10: 5000 | H10: =SUM(I10:N10) -> 1281.0823 | I10: 223.39827 | J10: 1044.24 | K10: 0.76 | L10: =(I10+J10+K10)*'2-报价汇总'!$H$5 -> 12.683983 | M10: =(I10+J10+K10+L10)*'2-报价汇总'!$I$5 -> 0 | N10: =(M10+L10+K10+J10+I10)*'2-报价汇总'!$J$5 -> 0 | O10: =G10*H10 -> 6405411.3 | S10: 0
A11: 2.3.1.06 | B11: 工位不锈钢洗手盆及龙头采购及安装 | C11: 1.本体及辅料（软管、阀门等）安装 | D11: 卫生间、淋浴间、清扫间 | E11: 按设计图示数量计算 | F11: 套 | G11: 500 | H11: =SUM(I11:N11) -> 699.5671 | I11: 135.82069 | J11: 555.39 | K11: 1.43 | L11: =(I11+J11+K11)*'2-报价汇总'!$H$5 -> 6.9264069 | M11: =(I11+J11+K11+L11)*'2-报价汇总'!$I$5 -> 0 | N11: =(M11+L11+K11+J11+I11)*'2-报价汇总'!$J$5 -> 0 | O11: =G11*H11 -> 349783.55 | S11: 0
A12: 2.3.1.07 | B12: 皂液器采购及安装 | C12: 1.本体及配件辅料安装 | D12: 卫生间、淋浴间、清扫间 | E12: 按设计图示数量计算 | F12: 套 | G12: 500 | H12: =SUM(I12:N12) -> 131.16883 | I12: 31.68013 | J12: 97.9 | K12: 0.29 | L12: =(I12+J12+K12)*'2-报价汇总'!$H$5 -> 1.2987013 | M12: =(I12+J12+K12+L12)*'2-报价汇总'!$I$5 -> 0 | N12: =(M12+L12+K12+J12+I12)*'2-报价汇总'!$J$5 -> 0 | O12: =G12*H12 -> 65584.416 | S12: 0
A13: 2.3.1.08 | B13: 手纸盒（小）采购及安装，卫生间隔间内 | C13: 1.本体及配件辅料安装 | D13: 卫生间、淋浴间、清扫间 | E13: 按设计图示数量计算 | F13: 套 | G13: 500 | H13: =SUM(I13:N13) -> 306.06061 | I13: 136.0303 | J13: 166.67 | K13: 0.33 | L13: =(I13+J13+K13)*'2-报价汇总'!$H$5 -> 3.030303 | M13: =(I13+J13+K13+L13)*'2-报价汇总'!$I$5 -> 0 | N13: =(M13+L13+K13+J13+I13)*'2-报价汇总'!$J$5 -> 0 | O13: =G13*H13 -> 153030.3 | S13: 15495.74
A14: 2.3.1.09 | B14: 洗手池：抽纸不锈钢纸盒采购及安装 | C14: 1.本体及配件辅料安装 | D14: 卫生间、淋浴间、清扫间 | E14: 按设计图示数量计算 | F14: 套 | G14: 500 | H14: =SUM(I14:N14) -> 104.93506 | I14: 36.896104 | J14: 66.67 | K14: 0.33 | L14: =(I14+J14+K14)*'2-报价汇总'!$H$5 -> 1.038961 | M14: =(I14+J14+K14+L14)*'2-报价汇总'!$I$5 -> 0 | N14: =(M14+L14+K14+J14+I14)*'2-报价汇总'!$J$5 -> 0 | O14: =G14*H14 -> 52467.532 | S14: 6380.5987
A15: 2.3.1.10 | B15: 厕板纸纸盒采购及安装，卫生间隔间内 | C15: 1.本体及配件辅料安装 | D15: 卫生间、淋浴间、清扫间 | E15: 按设计图示数量计算 | F15: 套 | G15: 500 | H15: =SUM(I15:N15) -> 113.67965 | I15: 45.554113 | J15: 66.67 | K15: 0.33 | L15: =(I15+J15+K15)*'2-报价汇总'!$H$5 -> 1.1255411 | M15: =(I15+J15+K15+L15)*'2-报价汇总'!$I$5 -> 0 | N15: =(M15+L15+K15+J15+I15)*'2-报价汇总'!$J$5 -> 0 | O15: =G15*H15 -> 56839.827 | S15: 15495.74
A16: 2.3.1.11 | B16: 墩布池及龙头采购及安装 | C16: 1.本体及辅料（软管、阀门等）安装 | D16: 卫生间、淋浴间、清扫间 | E16: 按设计图示数量计算 | F16: 套 | G16: 500 | H16: =SUM(I16:N16) -> 1049.3506 | I16: 325.17104 | J16: 713.03 | K16: 0.76 | L16: =(I16+J16+K16)*'2-报价汇总'!$H$5 -> 10.38961 | M16: =(I16+J16+K16+L16)*'2-报价汇总'!$I$5 -> 0 | N16: =(M16+L16+K16+J16+I16)*'2-报价汇总'!$J$5 -> 0 | O16: =G16*H16 -> 524675.32 | S16: 1823.0282
A17: 2.3.1.12 | B17: 花洒采购及安装 | C17: 1.本体及辅料（软管、阀门等）安装 | D17: 卫生间、淋浴间、清扫间 | E17: 按设计图示数量计算 | F17: 套 | G17: 500 | H17: =SUM(I17:N17) -> 1168.4185 | I17: 50 | J17: 1104 | K17: 2.85 | L17: =(I17+J17+K17)*'2-报价汇总'!$H$5 -> 11.5685 | M17: =(I17+J17+K17+L17)*'2-报价汇总'!$I$5 -> 0 | N17: =(M17+L17+K17+J17+I17)*'2-报价汇总'!$J$5 -> 0 | O17: =G17*H17 -> 584209.25 | S17: 0
... A46: 2.3.1.41 | B46: 电热水器 60L 采购及安装 | C46: 1.设备供应安装 2.包含墙面加固、安装支架等其他辅助工作 3.设备调试 | D46: 卫生间、淋浴间、清扫间 | E46: 按设计图示数量计算 | F46: 套 | G46: 1000 | H46: =SUM(I46:N46) -> 1661.4719 | I46: 126.29165 | J46: 1504.2 | K46: 14.53 | L46: =(I46+J46+K46)*'2-报价汇总'!$H$5 -> 16.450216 | M46: =(I46+J46+K46+L46)*'2-报价汇总'!$I$5 -> 0 | N46: =(M46+L46+K46+J46+I46)*'2-报价汇总'!$J$5 -> 0 | O46: =G46*H46 -> 1661471.9 | S46: 0
A47: 2.3.1.42 | B47: 工业太阳能热水器 | C47: 1.管件及接线供应安装，清华紫光，容积：4立方 2.本体及附件，配线及管道等安装工作 3.含控制柜及水泵等安装工作 | D47: 卫生间、淋浴间、清扫间 | E47: 按设计图示数量计算 | F47: 项 | G47: 1000 | H47: =SUM(I47:N47) -> 45471.861 | I47: 32521.645 | J47: 12500 | L47: =(I47+J47+K47)*'2-报价汇总'!$H$5 -> 450.21645 | M47: =(I47+J47+K47+L47)*'2-报价汇总'!$I$5 -> 0 | N47: =(M47+L47+K47+J47+I47)*'2-报价汇总'!$J$5 -> 0 | O47: =G47*H47 -> 45471861 | S47: 0
A48: 2.3.1.43 | B48: 主给水管改造，增加控制阀门、水表 | C48: 1.原管道拆除调整 2.相关管件安装 3.阀门、水表提供及安装 | D48: 室内、室外装饰装修及安装工程项目 | E48: 按设计图示数量计算 | F48: 处 | G48: 1823.0282 | H48: =SUM(I48:N48) -> 437.22944 | I48: 432.90043 | L48: =(I48+J48+K48)*'2-报价汇总'!$H$5 -> 4.3290043 | M48: =(I48+J48+K48+L48)*'2-报价汇总'!$I$5 -> 0 | N48: =(M48+L48+K48+J48+I48)*'2-报价汇总'!$J$5 -> 0 | O48: =G48*H48 -> 797081.59 | S48: 1823.0282
A49: 2.3.1.44 | B49: 室外给水主管道增压泵 | C49: 1.1.5kw，扬程20m，口径50mm，不锈钢离心泵 2.品牌：利欧、人民 | D49: 室内、室外装饰装修及安装工程项目 | E49: 按设计图示数量计算 | F49: 套 | G49: 1000 | H49: =SUM(I49:N49) -> 1923.8095 | I49: 435.2719 | J49: 1433.67 | K49: 35.82 | L49: =(I49+J49+K49)*'2-报价汇总'!$H$5 -> 19.047619 | M49: =(I49+J49+K49+L49)*'2-报价汇总'!$I$5 -> 0 | N49: =(M49+L49+K49+J49+I49)*'2-报价汇总'!$J$5 -> 0 | O49: =G49*H49 -> 1923809.5 | S49: 0
A50: 2.3.1.45 | B50: 不锈钢拖把池 | C50: 1.成品不锈钢拖把池 2.规格1200*410*550 | E50: 按设计图示数量计算 | F50: 套 | G50: 1000 | H50: =SUM(I50:N50) -> 743.29004 | I50: 22.320736 | J50: 712.85 | K50: 0.76 | L50: =(I50+J50+K50)*'2-报价汇总'!$H$5 -> 7.3593074 | M50: =(I50+J50+K50+L50)*'2-报价汇总'!$I$5 -> 0 | N50: =(M50+L50+K50+J50+I50)*'2-报价汇总'!$J$5 -> 0 | O50: =G50*H50 -> 743290.04 | S50: 0
A51: 2.3.1.46 | B51: 混凝土地面开挖排水管槽及修补 1.测位、划线、刨沟、垃圾清理、填补 | F51: m | G51: 1000 | H51: =SUM(I51:N51) -> 157.4026 | I51: 153.84416 | K51: 2 | L51: =(I51+J51+K51)*'2-报价汇总'!$H$5 -> 1.5584416 | M51: =(I51+J51+K51+L51)*'2-报价汇总'!$I$5 -> 0 | N51: =(M51+L51+K51+J51+I51)*'2-报价汇总'!$J$5 -> 0 | O51: =G51*H51 -> 157402.6 | S51: 0
A52: 2.3.1.47 | B52: 提供及安装排水管UPVC200 | F52: m | G52: 1000 | H52: =SUM(I52:N52) -> 69.2658 | I52: 9.06 | J52: 57.76 | K52: 1.76 | L52: =(I52+J52+K52)*'2-报价汇总'!$H$5 -> 0.6858 | M52: =(I52+J52+K52+L52)*'2-报价汇总'!$I$5 -> 0 | N52: =(M52+L52+K52+J52+I52)*'2-报价汇总'!$J$5 -> 0
B53: 补充项
B54: 给排水工程合计： | O54: =SUM(O6:O51) -> 1.6278697e+08

Sheet 2.4-外立面工程
A1: 理想汽车中心店外立面工程量清单
A2: ='2.1-装饰工程'!A2 -> 注意：此报价清单每项不得随意更改、删减，如有任何增加项请务必在每大项最后“补充项“中列举，补充项及说明字体颜色均采用蓝色；且所有项目都需要填写。
A3: 序号 | B3: 项目名称 | C3: 项目特征 | D3: 适用范围 | E3: 工程量计算规则 | F3: 单位 | G3: 24/25年暂估工程量 | H3: 综合单价 | I3: 人工费 | J3: 材料费 | K3: 机械费 | L3: 安措费 | M3: 管理费 | N3: 利润 | O3: 24/25年暂估总价 | P3: 备注
B4: 2.4外立面工程
A5: 2.4.1 | B5: 外幕墙准备工作
A6: 2.4.1.01 | B6: 外幕墙拆除（玻璃、石材、外墙砖、铝板等） *包括原幕墙固定结构拆除 | C6: 1.拆除原有外幕墙 2.包括玻璃、石材、外墙砖、铝板等幕墙 3.幕墙固定结构拆除 | D6: 室外装饰装修及安装工程项目 | E6: 按设计图示尺寸面积计算 垃圾清运折算系数0.05 | F6: m2 | G6: 50000 | H6: =SUM(I6:N6) -> 34.978355 | I6: 33.672035 | J6: 0 | K6: 0.96 | L6: =(I6+J6+K6)*'2-报价汇总'!$H$5 -> 0.34632035 | M6: =(I6+J6+K6+L6)*'2-报价汇总'!$I$5 -> 0 | N6: =(M6+L6+K6+J6+I6)*'2-报价汇总'!$J$5 -> 0 | O6: =G6*H6 -> 1748917.7
A7: 2.4.1.02 | B7: 外墙涂料拆除 | C7: 1.外墙涂料拆除 2.垃圾清理 | D7: 室外装饰装修及安装工程项目 | E7: 按设计图示尺寸面积计算 垃圾清运折算系数0.001 | F7: m2 | G7: 50000 | H7: =SUM(I7:N7) -> 4.3722944 | I7: 4.2690043 | J7: 0 | K7: 0.06 | L7: =(I7+J7+K7)*'2-报价汇总'!$H$5 -> 0.043290043 | M7: =(I7+J7+K7+L7)*'2-报价汇总'!$I$5 -> 0 | N7: =(M7+L7+K7+J7+I7)*'2-报价汇总'!$J$5 -> 0 | O7: =G7*H7 -> 218614.72
A8: 2.4.1.03 | B8: 外墙开洞及修补 | C8: 1.外墙涂料拆除 2.垃圾清理 | D8: 室外装饰装修及安装工程项目 | E8: 按设计图示尺寸面积计算 | F8: m2 | G8: 6316.7927 | H8: =SUM(I8:N8) -> 122.42424 | I8: 16.212121 | J8: 5 | K8: 100 | L8: =(I8+J8+K8)*'2-报价汇总'!$H$5 -> 1.2121212 | M8: =(I8+J8+K8+L8)*'2-报价汇总'!$I$5 -> 0 | N8: =(M8+L8+K8+J8+I8)*'2-报价汇总'!$J$5 -> 0 | O8: =G8*H8 -> 773328.56
A9: 2.4.1.04 | B9: 拆除垃圾清理、清运（7立方） | E9: 分项工程垃圾清理折算系数*面积之和/7 | F9: 车 | G9: 911.51409 | H9: =SUM(I9:N9) -> 765.15152 | I9: 257.57576 | J9: 0 | K9: 500 | L9: =(I9+J9+K9)*'2-报价汇总'!$H$5 -> 7.5757576 | M9: =(I9+J9+K9+L9)*'2-报价汇总'!$I$5 -> 0 | N9: =(M9+L9+K9+J9+I9)*'2-报价汇总'!$J$5 -> 0 | O9: =G9*H9 -> 697446.39
A10: 2.4.1.05 | B10: 室外搭建围挡2m高 | C10: (材质：蓝色金属板含金属骨架) | D10: 室内、室外各个功能区域 | E10: 正投影面积计算 | F10: ㎡ | G10: 95565.349 | H10: =SUM(I10:N10) -> 112.5544 | I10: 49.9 | J10: 55.94 | K10: 5.6 | L10: =(I10+J10+K10)*'2-报价汇总'!$H$5 -> 1.1144 | M10: =(I10+J10+K10+L10)*'2-报价汇总'!$I$5 -> 0 | N10: =(M10+L10+K10+J10+I10)*'2-报价汇总'!$J$5 -> 0 | O10: =G10*H10 -> 10756300
A11: 2.4.1.06 | B11: 室外搭建围挡2m高 | C11: 龙骨：方钢龙骨 饰面：彩条布或宝丽布 | D11: 室内、室外各个功能区域 | E11: 正投影面积计算 | F11: ㎡ | G11: 95565.349 | H11: =SUM(I11:N11) -> 51.9443 | I11: 23.03 | J11: 25 | K11: 3.4 | L11: =(I11+J11+K11)*'2-报价汇总'!$H$5 -> 0.5143 | M11: =(I11+J11+K11+L11)*'2-报价汇总'!$I$5 -> 0 | N11: =(M11+L11+K11+J11+I11)*'2-报价汇总'!$J$5 -> 0 | O11: =G11*H11 -> 4964075.1
A12: 2.4.1.07 | B12: 室外墙面脚手架 | C12: 租赁、搭拆脚手架费用及相关运输费用 | D12: 室外结构标高超过4.5m计取此部分费用 | E12: 墙面投影面积 | F12: m2 | G12: 2033697.3 | H12: =SUM(I12:N12) -> 21.6443 | I12: 10.39 | J12: 10 | K12: 1.04 | L12: =(I12+J12+K12)*'2-报价汇总'!$H$5 -> 0.2143 | M12: =(I12+J12+K12+L12)*'2-报价汇总'!$I$5 -> 0 | N12: =(M12+L12+K12+J12+I12)*'2-报价汇总'!$J$5 -> 0 | O12: =G12*H12 -> 44017955
B13: 补充项
B14: 小计
A15: 2.4.2 | B15: 外墙涂料
A16: 2.4.2.01 | B16: 外墙涂料，基层处理（平涂） | C16: 1.基层清理 2.外墙防水腻子2遍，打磨 3.外墙涂料2遍底漆3遍面漆（平涂） | D16: 室外装饰装修及安装工程项目 | E16: 按设计图示尺寸面积计算 | F16: m2 | G16: 5000 | H16: =SUM(I16:N16) -> 54.21645 | I16: 23.409654 | J16: 29.93 | K16: 0.34 | L16: =(I16+J16+K16)*'2-报价汇总'!$H$5 -> 0.53679654 | M16: =(I16+J16+K16+L16)*'2-报价汇总'!$I$5 -> 0 | N16: =(M16+L16+K16+J16+I16)*'2-报价汇总'!$J$5 -> 0 | O16: =G16*H16 -> 271082.25
A17: 2.4.2.02 | B17: 外墙涂料，基层处理（弹涂） | C17: 1.基层清理 2.外墙防水腻子2遍，打磨 3.外墙涂料2遍底漆3遍面漆（弹涂） 4.弹涂：真石漆、肌理漆、水包水等 | D17: 室外装饰装修及安装工程项目 | E17: 按设计图示尺寸面积计算 | F17: m2 | G17: 5000 | H17: =SUM(I17:N17) -> 74.329004 | I17: 36.203074 | J17: 37 | K17: 0.39 | L17: =(I17+J17+K17)*'2-报价汇总'!$H$5 -> 0.73593074 | M17: =(I17+J17+K17+L17)*'2-报价汇总'!$I$5 -> 0 | N17: =(M17+L17+K17+J17+I17)*'2-报价汇总'!$J$5 -> 0 | O17: =G17*H17 -> 371645.02
A18: 2.4.2.03 | B18: 外墙氟碳漆，基层处理 | C18: 1.基层清理 2.外墙防水腻子2遍，打磨 3.氟碳喷涂 | D18: 室外装饰装修及安装工程项目 | E18: 按设计图示尺寸面积计算 | F18: m2 | G18: 5000 | H18: =SUM(I18:N18) -> 100.56277 | I18: 29.1571 | J18: 70 | K18: 0.41 | L18: =(I18+J18+K18)*'2-报价汇总'!$H$5 -> 0.995671 | M18: =(I18+J18+K18+L18)*'2-报价汇总'!$I$5 -> 0 | N18: =(M18+L18+K18+J18+I18)*'2-报价汇总'!$J$5 -> 0 | O18: =G18*H18 -> 502813.85
A19: 2.4.2.04 | B19: 外墙面国产花岗岩石材 | C19: 1.基层清理 2.钢龙骨自作安装 3.石材六面防护 4.干挂石材供应安装 | D19: 室外装饰装修及安装工程项目 | E19: 按设计图示尺寸面积计算 | F19: m2 | G19: 5000 | H19: =SUM(I19:N19) -> 480.95238 | I19: 186.89048 | J19: 280 | K19: 9.3 | L19: =(I19+J19+K19)*'2-报价汇总'!$H$5 -> 4.7619048 | M19: =(I19+J19+K19+L19)*'2-报价汇总'!$I$5 -> 0 | N19: =(M19+L19+K19+J19+I19)*'2-报价汇总'!$J$5 -> 0 | O19: =G19*H19 -> 2404761.9
B20: 补充项
B21: 小计
A22: 2.4.3 | B22: 外幕墙玻璃
A23: 2.4.3.01 | B23: 外玻璃幕墙 | C23: 1.钢结构骨架自作安装及相关结构改造施工 2.8+6+8mm中空钢化玻璃（普白） 3.氟碳喷涂铝框 | D23: 适用于外立面＞3米高外玻璃幕墙，≤3米高幕墙套用装饰内项目 | E23: 按图示尺寸以投影面积计算 | F23: m2 | G23: 5000 | H23: =SUM(I23:N23) -> 1202.381 | I23: 262.33619 | J23: 900 | K23: 28.14 | L23: =(I23+J23+K23)*'2-报价汇总'!$H$5 -> 11.904762 | M23: =(I23+J23+K23+L23)*'2-报价汇总'!$I$5 -> 0 | N23: =(M23+L23+K23+J23+I23)*'2-报价汇总'!$J$5 -> 0 | O23: =G23*H23 -> 6011904.8
A24: 2.4.3.02 | B24: 主入口玻璃门 | C24: 1.8+6+8mm钢化玻璃 2.氟碳喷涂门拉手，配套五金 3.金属边框氟碳喷涂 *多玛重力地弹簧、上夹、下夹、锁夹 | D24: 室外装饰装修及安装工程项目 | E24: 按图示尺寸以投影面积计算 | F24: m2 | G24: 5000 | H24: =SUM(I24:N24) -> 1049.3506 | I24: 233.96104 | J24: 800 | K24: 5 | L24: =(I24+J24+K24)*'2-报价汇总'!$H$5 -> 10.38961 | M24: =(I24+J24+K24+L24)*'2-报价汇总'!$I$5 -> 0 | N24: =(M24+L24+K24+J24+I24)*'2-报价汇总'!$J$5 -> 0 | O24: =G24*H24 -> 5246753.2
A25: 2.4.3.03 | B25: 外玻璃幕墙，15mm超白钢化玻璃 | C25: 1.钢结构骨架自作安装及相关结构改造施工 2.15mm钢化玻璃（超白） 3.氟碳喷涂铝框 | D25: 适用于外立面＞3米高外玻璃幕墙，≤3米高幕墙套用装饰内项目 | E25: 按图示尺寸以投影面积计算 | F25: m2 | G25: 5000 | H25: =SUM(I25:N25) -> 839.48052 | I25: 253.02883 | J25: 550 | K25: 28.14 | L25: =(I25+J25+K25)*'2-报价汇总'!$H$5 -> 8.3116883 | M25: =(I25+J25+K25+L25)*'2-报价汇总'!$I$5 -> 0 | N25: =(M25+L25+K25+J25+I25)*'2-报价汇总'!$J$5 -> 0 | O25: =G25*H25 -> 4197402.6
A26: 2.4.3.04 | B26: 外玻璃幕墙（明框或隐框） | C26: 1.钢结构骨架自作安装及相关结构改造施工 2.8+8夹胶玻璃钢化玻璃（普白） 3.氟碳喷涂铝框 | D26: 适用于外立面＞3米高外玻璃幕墙，≤3米高幕墙套用装饰内项目 | E26: 按图示尺寸以投影面积计算 | F26: m2 | G26: 5000 | H26: =SUM(I26:N26) -> 1202.381 | I26: 211.47619 | J26: 950 | K26: 29 | L26: =(I26+J26+K26)*'2-报价汇总'!$H$5 -> 11.904762 | M26: =(I26+J26+K26+L26)*'2-报价汇总'!$I$5 -> 0 | N26: =(M26+L26+K26+J26+I26)*'2-报价汇总'!$J$5 -> 0 | O26: =G26*H26 -> 6011904.8
A27: 2.4.3.05 | B27: 新做消防排烟平开窗（含电动装置） | C27: 1.成品电动排烟窗 2.电机、控制器、控制主板 3.设备调试安装 | D27: 室外装饰装修及安装工程项目 | E27: 按图示尺寸以投影面积计算 | F27: m2 | G27: 500 | H27: =SUM(I27:N27) -> 1311.6883 | I27: 263.7013 | J27: 1000 | K27: 35 | L27: =(I27+J27+K27)*'2-报价汇总'!$H$5 -> 12.987013 | M27: =(I27+J27+K27+L27)*'2-报价汇总'!$I$5 -> 0 | N27: =(M27+L27+K27+J27+I27)*'2-报价汇总'!$J$5 -> 0 | O27: =G27*H27 -> 655844.16
A28: 2.4.3.06 | B28: 双扇玻璃门： 1500*2200 | C28: 1.15钢化玻璃 2.氟碳喷涂门拉手，配套五金 3.金属边框氟碳喷涂 *多玛重力地弹簧、上夹、下夹、锁夹 | D28: 室外装饰装修及安装工程项目 | E28: 按图示尺寸以投影面积计算 | F28: 樘 | G28: 400 | H28: =SUM(I28:N28) -> 5211.7749 | I28: 944.30316 | J28: 4200 | K28: 15.87 | L28: =(I28+J28+K28)*'2-报价汇总'!$H$5 -> 51.601732 | M28: =(I28+J28+K28+L28)*'2-报价汇总'!$I$5 -> 0 | N28: =(M28+L28+K28+J28+I28)*'2-报价汇总'!$J$5 -> 0 | O28: =G28*H28 -> 2084710
A29: 2.4.3.07 | B29: 双扇玻璃门： L2500*H2400 | C29: 1.15mm钢化玻璃 2.氟碳喷涂门拉手，配套五金 3.金属边框氟碳喷涂 *多玛重力地弹簧、上夹、下夹、锁夹 | D29: 室外装饰装修及安装工程项目 | E29: 按设计图示数量计算 | F29: 樘 | G29: 400 | H29: =SUM(I29:N29) -> 6392.2944 | I29: 1100.1443 | J29: 5200 | K29: 28.86 | L29: =(I29+J29+K29)*'2-报价汇总'!$H$5 -> 63.290043 | M29: =(I29+J29+K29+L29)*'2-报价汇总'!$I$5 -> 0 | N29: =(M29+L29+K29+J29+I29)*'2-报价汇总'!$J$5 -> 0 | O29: =G29*H29 -> 2556917.7
A30: 2.4.3.08 | B30: 外窗、外墙彩钢板孔洞修补 | C30: 1.修补外窗玻璃&彩钢板 2.龙骨加固 | D30: 室外装饰装修及安装工程项目 | E30: 按设计图示数量计算 | F30: m2 | G30: 500 | H30: =SUM(I30:N30) -> 174.89177 | I30: 92.060173 | J30: 80 | K30: 1.1 | L30: =(I30+J30+K30)*'2-报价汇总'!$H$5 -> 1.7316017 | M30: =(I30+J30+K30+L30)*'2-报价汇总'!$I$5 -> 0 | N30: =(M30+L30+K30+J30+I30)*'2-报价汇总'!$J$5 -> 0 | O30: =G30*H30 -> 87445.887
B31: 补充项
B32: 小计
A33: 2.4.4 | B33: 雨棚
A34: 2.4.4.01 | B34: 外幕墙铝塑板雨棚 | C34: 1.铝塑板面层 2.铝方型材龙骨，用于固定铝板 3.方钢龙骨，固定于墙面 | D34: 室外装饰装修及安装工程项目 | E34: 1、按展开面积计算 2、雨棚跨度＞3.5米，雨棚所用型钢骨架及饰面材料骨架套用钢结构项目以吨计量，饰面材料单独计算。 | F34: m2 | G34: 43548.263 | H34: =SUM(I34:N34) -> 345.58615 | I34: 116.7945 | J34: 220 | K34: 5.37 | L34: =(I34+J34+K34)*'2-报价汇总'!$H$5 -> 3.421645 | M34: =(I34+J34+K34+L34)*'2-报价汇总'!$I$5 -> 0 | N34: =(M34+L34+K34+J34+I34)*'2-报价汇总'!$J$5 -> 0 | O34: =G34*H34 -> 15049676
A35: 2.4.4.02 | B35: 外幕墙钢化夹胶玻璃雨棚 | C35: 1.6+1.2+6钢化夹胶玻璃 2.镀锌方管龙骨，含结构链接 3.氟碳漆 | D35: 室外装饰装修及安装工程项目 | E35: 按水平投影面积计算 | F35: m2 | G35: 43548.263 | H35: =SUM(I35:N35) -> 559.65368 | I35: 95.972554 | J35: 450 | K35: 8.14 | L35: =(I35+J35+K35)*'2-报价汇总'!$H$5 -> 5.5411255 | M35: =(I35+J35+K35+L35)*'2-报价汇总'!$I$5 -> 0 | N35: =(M35+L35+K35+J35+I35)*'2-报价汇总'!$J$5 -> 0 | O35: =G35*H35 -> 24371946
B36: 补充项
B37: 小计
A38: 2.4.5 | B38: 门头
A39: 2.4.5.01 | B39: 外墙铝塑板，含基层处理 | C39: 1.铝塑板面层 2.镀锌方钢龙骨，用于固定铝塑板 3.含结构胶勾缝 | D39: 室外装饰装修及安装工程项目 | E39: 按设计图示尺寸面积计算 | F39: m2 | G39: 690830.51 | H39: =SUM(I39:N39) -> 402.25108 | I39: 138.2684 | J39: 240 | K39: 20 | L39: =(I39+J39+K39)*'2-报价汇总'!$H$5 -> 3.982684 | M39: =(I39+J39+K39+L39)*'2-报价汇总'!$I$5 -> 0 | N39: =(M39+L39+K39+J39+I39)*'2-报价汇总'!$J$5 -> 0 | O39: =G39*H39 -> 2.7788732e+08
A40: 2.4.5.02 | B40: 外墙LOGO安装位置角钢加固 | C40: 1.外墙龙骨加密 | D40: 室外装饰装修及安装工程项目 | E40: 按设计图示数量计算 | F40: 项 | G40: 911.51409 | H40: =SUM(I40:N40) -> 743.29004 | I40: 130.93074 | J40: 590 | K40: 15 | L40: =(I40+J40+K40)*'2-报价汇总'!$H$5 -> 7.3593074 | M40: =(I40+J40+K40+L40)*'2-报价汇总'!$I$5 -> 0 | N40: =(M40+L40+K40+J40+I40)*'2-报价汇总'!$J$5 -> 0 | O40: =G40*H40 -> 677519.35
...

Sheet 2.5-室外工程
A1: 理想汽车中心店室外工程量清单
A2: ='2.1-装饰工程'!A2 -> 注意：此报价清单每项不得随意更改、删减，如有任何增加项请务必在每大项最后“补充项“中列举，补充项及说明字体颜色均采用蓝色；且所有项目都需要填写。
A3: 序号 | B3: 项目名称 | C3: 项目特征 | D3: 适用范围 | E3: 工程量计算规则 | F3: 单位 | G3: 24/25年暂估工程量 | H3: 综合单价 | I3: 人工费 | J3: 材料费 | K3: 机械费 | L3: 安措费 | M3: 管理费 | N3: 利润 | O3: 24/25年暂估总价 | P3: 备注
B4: 2.5室外工程
A5: 2.5.1 | B5: 沥青地面，含场地平整
A6: 2.5.1.1 | B6: 30mm厚细沥青混凝土 | C6: 1.地面清理、平整 2.30mm后沥青混凝土 3.面层压平 | D6: 室外装饰装修及安装工程项目 | E6: 按设计图示尺寸面积计算 | F6: m2 | G6: 1025476.1 | H6: =SUM(I6:N6) -> 45.471861 | I6: 2.511645 | J6: 34.54 | K6: 7.97 | L6: =(I6+J6+K6)*'2-报价汇总'!$H$5 -> 0.45021645 | M6: =(I6+J6+K6+L6)*'2-报价汇总'!$I$5 -> 0 | N6: =(M6+L6+K6+J6+I6)*'2-报价汇总'!$J$5 -> 0 | O6: =G6*H6 -> 46630308
A7: 2.5.1.2 | B7: 50mm厚粗沥青混凝土 | C7: 1.地面清理、平整 2.50mm后沥青混凝土 3.面层压平 | D7: 室外装饰装修及安装工程项目 | E7: 按设计图示尺寸面积计算 | F7: m2 | G7: 725476.13 | H7: =SUM(I7:N7) -> 64.709957 | I7: 2.1992641 | J7: 53.8 | K7: 8.07 | L7: =(I7+J7+K7)*'2-报价汇总'!$H$5 -> 0.64069264 | M7: =(I7+J7+K7+L7)*'2-报价汇总'!$I$5 -> 0 | N7: =(M7+L7+K7+J7+I7)*'2-报价汇总'!$J$5 -> 0 | O7: =G7*H7 -> 46945529
A8: 2.5.1.3 | B8: 拆除原有沥青路面 | C8: 1.拆除原有沥青地面 2.垃圾清理及垃圾外运 | D8: 室外装饰装修及安装工程项目 | E8: 按设计图示尺寸面积计算 | F8: m2 | G8: 2000 | H8: =SUM(I8:N8) -> 27.982684 | I8: 27.225628 | J8: 0 | K8: 0.48 | L8: =(I8+J8+K8)*'2-报价汇总'!$H$5 -> 0.27705628 | M8: =(I8+J8+K8+L8)*'2-报价汇总'!$I$5 -> 0 | N8: =(M8+L8+K8+J8+I8)*'2-报价汇总'!$J$5 -> 0 | O8: =G8*H8 -> 55965.368
A9: 2.5.1.4 | B9: 150mm素混凝土基层 | C9: 1.地面清理、平整 2.150mm素混凝土基层 3.面层压光 4.防滑处理 | D9: 室外装饰装修及安装工程项目 | E9: 按设计图示尺寸面积计算 | F9: m2 | G9: 73406.441 | H9: =SUM(I9:N9) -> 83.073593 | I9: 5.2810823 | J9: 76.83 | K9: 0.14 | L9: =(I9+J9+K9)*'2-报价汇总'!$H$5 -> 0.82251082 | M9: =(I9+J9+K9+L9)*'2-报价汇总'!$I$5 -> 0 | N9: =(M9+L9+K9+J9+I9)*'2-报价汇总'!$J$5 -> 0 | O9: =G9*H9 -> 6098136.8
A10: 2.5.1.5 | B10: 150mm碎石垫层基层 | C10: 1.地面清理、平整 2.150mm碎石垫层基层 | D10: 室外装饰装修及安装工程项目 | E10: 按设计图示尺寸面积计算 | F10: m2 | G10: 73406.441 | H10: =SUM(I10:N10) -> 40.225108 | I10: 10.28684 | J10: 26 | K10: 3.54 | L10: =(I10+J10+K10)*'2-报价汇总'!$H$5 -> 0.3982684 | M10: =(I10+J10+K10+L10)*'2-报价汇总'!$I$5 -> 0 | N10: =(M10+L10+K10+J10+I10)*'2-报价汇总'!$J$5 -> 0 | O10: =G10*H10 -> 2952782
A11: 2.5.1.6 | B11: 厚100mm混凝土地面 | C11: 1.地面清理、场地平整 2.100mm混凝土地面 3.满铺钢筋网片 4.面层压光，防滑处理 | D11: 室外装饰装修及安装工程项目 | E11: 按设计图示尺寸面积计算 | F11: m2 | G11: 73406.441 | H11: =SUM(I11:N11) -> 94.441558 | I11: 28.396494 | J11: 63.2 | K11: 1.91 | L11: =(I11+J11+K11)*'2-报价汇总'!$H$5 -> 0.93506494 | M11: =(I11+J11+K11+L11)*'2-报价汇总'!$I$5 -> 0 | N11: =(M11+L11+K11+J11+I11)*'2-报价汇总'!$J$5 -> 0 | O11: =G11*H11 -> 6932618.7
A12: 2.5.1.7 | B12: 厚100mm混凝土地面 | C12: 1.地面清理、场地平整 2.100mm混凝土地面 3.面层压光，防滑处理 | D12: 室外装饰装修及安装工程项目 | E12: 按设计图示尺寸面积计算 | F12: m2 | G12: 73406.441 | H12: =SUM(I12:N12) -> 52.467532 | I12: 4.8480519 | J12: 46.41 | K12: 0.69 | L12: =(I12+J12+K12)*'2-报价汇总'!$H$5 -> 0.51948052 | M12: =(I12+J12+K12+L12)*'2-报价汇总'!$I$5 -> 0 | N12: =(M12+L12+K12+J12+I12)*'2-报价汇总'!$J$5 -> 0 | O12: =G12*H12 -> 3851454.8
A13: 2.5.1.8 | B13: 草坪砖地面供应及安装 | C13: 1.地面清理、场地平整 2.草坪砖地面供应及安装 | D13: 室外装饰装修及安装工程项目 | E13: 按设计图示尺寸面积计算 | F13: m2 | G13: 5000 | H13: =SUM(I13:N13) -> 78.701299 | I13: 27.162078 | J13: 50 | K13: 0.76 | L13: =(I13+J13+K13)*'2-报价汇总'!$H$5 -> 0.77922078 | M13: =(I13+J13+K13+L13)*'2-报价汇总'!$I$5 -> 0 | N13: =(M13+L13+K13+J13+I13)*'2-报价汇总'!$J$5 -> 0 | O13: =G13*H13 -> 393506.49
A14: 2.5.1.9 | B14: 广场砖地面供应及安装 | C14: 1.地面清理、场地平整 2.广场砖地面供应及安装 | D14: 室外装饰装修及安装工程项目 | E14: 按设计图示尺寸面积计算 | F14: m2 | G14: 5000 | H14: =SUM(I14:N14) -> 78.701299 | I14: 31.862078 | J14: 45 | K14: 1.06 | L14: =(I14+J14+K14)*'2-报价汇总'!$H$5 -> 0.77922078 | M14: =(I14+J14+K14+L14)*'2-报价汇总'!$I$5 -> 0 | N14: =(M14+L14+K14+J14+I14)*'2-报价汇总'!$J$5 -> 0 | O14: =G14*H14 -> 393506.49
A15: 2.5.1.10 | B15: 道牙新做 | C15: 1.地面清理、场地平整 2.地面开挖、回填 3.道牙石供应及安装 | D15: 室外装饰装修及安装工程项目 | F15: m | G15: 97349.705 | H15: =SUM(I15:N15) -> 48.095238 | I15: 12.109048 | J15: 35 | K15: 0.51 | L15: =(I15+J15+K15)*'2-报价汇总'!$H$5 -> 0.47619048 | M15: =(I15+J15+K15+L15)*'2-报价汇总'!$I$5 -> 0 | N15: =(M15+L15+K15+J15+I15)*'2-报价汇总'!$J$5 -> 0 | O15: =G15*H15 -> 4682057.3
A16: 2.5.1.11 | B16: 新做方钢栏杆 | C16: 1.方钢栏杆（1800mm高）含地面基础 2.表面防锈处理 3.满刷油漆面层 | D16: 室外装饰装修及安装工程项目 | F16: m | G16: 3000 | H16: =SUM(I16:N16) -> 218.61472 | I16: 92.540216 | J16: 120 | K16: 3.91 | L16: =(I16+J16+K16)*'2-报价汇总'!$H$5 -> 2.1645022 | M16: =(I16+J16+K16+L16)*'2-报价汇总'!$I$5 -> 0 | N16: =(M16+L16+K16+J16+I16)*'2-报价汇总'!$J$5 -> 0 | O16: =G16*H16 -> 655844.16
A17: 2.5.1.12 | B17: 钢塑围栏，高度:1500mm高 | C17: 1.成品钢塑围栏 2.高度1500mm高 3.含地面基础制作 | D17: 室外装饰装修及安装工程项目 | F17: m | G17: 2000 | H17: =SUM(I17:N17) -> 262.33766 | I17: 27.10026 | J17: 230 | K17: 2.64 | L17: =(I17+J17+K17)*'2-报价汇总'!$H$5 -> 2.5974026 | M17: =(I17+J17+K17+L17)*'2-报价汇总'!$I$5 -> 0 | N17: =(M17+L17+K17+J17+I17)*'2-报价汇总'!$J$5 -> 0 | O17: =G17*H17 -> 524675.32
A18: 2.5.1.13 | B18: 金属小围栏，含铁链 | C18: 1.成品金属小围栏，含铁链（1800mm高）含地面基础 | D18: 室外装饰装修及安装工程项目 | E18: 按设计图示数量计算 | F18: 根 | G18: 1000 | H18: =SUM(I18:N18) -> 87.445887 | I18: 5.9800866 | J18: 80 | K18: 0.6 | L18: =(I18+J18+K18)*'2-报价汇总'!$H$5 -> 0.86580087 | M18: =(I18+J18+K18+L18)*'2-报价汇总'!$I$5 -> 0 | N18: =(M18+L18+K18+J18+I18)*'2-报价汇总'!$J$5 -> 0 | O18: =G18*H18 -> 87445.887
A19: 2.5.1.14 | B19: 外围墙围栏翻新处理 | C19: 1.面层打磨 2.表面防锈处理 3.满刷油漆面层 | D19: 室外装饰装修及安装工程项目 | F19: m | G19: 1000 | H19: =SUM(I19:N19) -> 76.952381 | I19: 57.830476 | J19: 17 | K19: 1.36 | L19: =(I19+J19+K19)*'2-报价汇总'!$H$5 -> 0.76190476 | M19: =(I19+J19+K19+L19)*'2-报价汇总'!$I$5 -> 0 | N19: =(M19+L19+K19+J19+I19)*'2-报价汇总'!$J$5 -> 0 | O19: =G19*H19 -> 76952.381
A20: 2.5.1.15 | B20: 室外停车场划线、喷字 | C20: 1.基层清理 2.150mm宽白色热融漆划线； 3.含白色数字编号、标识等，按公司规范字体； | D20: 室外装饰装修及安装工程项目 | E20: 按设计图示数量计算 | F20: 车位 | G20: 37372.078 | H20: =SUM(I20:N20) -> 139.91342 | I20: 36.528139 | J20: 100 | K20: 2 | L20: =(I20+J20+K20)*'2-报价汇总'!$H$5 -> 1.3852814 | M20: =(I20+J20+K20+L20)*'2-报价汇总'!$I$5 -> 0 | N20: =(M20+L20+K20+J20+I20)*'2-报价汇总'!$J$5 -> 0 | O20: =G20*H20 -> 5228855.2
A21: 2.5.1.16 | B21: 室外停车位车档供应及安装 | C21: 1.成品车档制作安装 | D21: 室外装饰装修及安装工程项目 | E21: 按设计图示数量计算 | F21: 对 | G21: 51956.303 | H21: =SUM(I21:N21) -> 139.91342 | I21: 27.028139 | J21: 110 | K21: 1.5 | L21: =(I21+J21+K21)*'2-报价汇总'!$H$5 -> 1.3852814 | M21: =(I21+J21+K21+L21)*'2-报价汇总'!$I$5 -> 0 | N21: =(M21+L21+K21+J21+I21)*'2-报价汇总'!$J$5 -> 0 | O21: =G21*H21 -> 7269384.1
A22: 2.5.1.17 | B22: 室外原围墙间结构柱刷外墙涂料，含基层处理 | C22: 1.基层清理 2.外墙防水腻子2遍，打磨 3.外墙涂料2遍底漆3遍面漆（平涂） | D22: 室外装饰装修及安装工程项目 | E22: 按设计图示尺寸面积计算 | F22: m2 | G22: 1000 | H22: =SUM(I22:N22) -> 50.718615 | I22: 13.79645 | J22: 36 | K22: 0.42 | L22: =(I22+J22+K22)*'2-报价汇总'!$H$5 -> 0.5021645 | M22: =(I22+J22+K22+L22)*'2-报价汇总'!$I$5 -> 0 | N22: =(M22+L22+K22+J22+I22)*'2-报价汇总'!$J$5 -> 0 | O22: =G22*H22 -> 50718.615
A23: 2.5.1.18 | B23: 室外成品岗亭提供及安装，含地面基础 | C23: 1.室外成品岗亭 | D23: 室外装饰装修及安装工程项目 | F23: 项 | G23: 300 | H23: =SUM(I23:N23) -> 14865.801 | I23: 2518.6147 | J23: 12000 | K23: 200 | L23: =(I23+J23+K23)*'2-报价汇总'!$H$5 -> 147.18615 | M23: =(I23+J23+K23+L23)*'2-报价汇总'!$I$5 -> 0 | N23: =(M23+L23+K23+J23+I23)*'2-报价汇总'!$J$5 -> 0 | O23: =G23*H23 -> 4459740.3
A24: 2.5.1.19 | B24: 提供及安装立招基础、立招电源 | C24: 1.室外地面开挖 2.混凝土基础（含模板、钢筋等） 3.预留室外电源 | D24: 室外装饰装修及安装工程项目 | F24: 项 | G24: 300 | H24: =SUM(I24:N24) -> 11805.195 | I24: 1638.3117 | J24: 10000 | K24: 50 | L24: =(I24+J24+K24)*'2-报价汇总'!$H$5 -> 116.88312 | M24: =(I24+J24+K24+L24)*'2-报价汇总'!$I$5 -> 0 | N24: =(M24+L24+K24+J24+I24)*'2-报价汇总'!$J$5 -> 0 | O24: =G24*H24 -> 3541558.4
A25: 2.5.1.20 | B25: 厂区大门新做 (1)铁艺大门新做，含轨道 | C25: 1.大门地面轨道制作 2.定制厂区大门提供及安装 | D25: 室外装饰装修及安装工程项目 | E25: 按设计图示尺寸面积计算 | F25: m2 | G25: 50 | H25: =SUM(I25:N25) -> 830.73593 | I25: 21.880823 | J25: 800 | K25: 0.63 | L25: =(I25+J25+K25)*'2-报价汇总'!$H$5 -> 8.2251082 | M25: =(I25+J25+K25+L25)*'2-报价汇总'!$I$5 -> 0 | N25: =(M25+L25+K25+J25+I25)*'2-报价汇总'!$J$5 -> 0 | O25: =G25*H25 -> 41536.797
A26: 2.5.1.21 | B26: 电动伸缩门，含轨道 | C26: 1.本体、配管配线、安装 | D26: 室外装饰装修及安装工程项目 | E26: 按设计图示数量计算 | F26: 套 | G26: 50 | H26: =SUM(I26:N26) -> 4022.5108 | I26: 469.68398 | J26: 3500 | K26: 13 | L26: =(I26+J26+K26)*'2-报价汇总'!$H$5 -> 39.82684 | M26: =(I26+J26+K26+L26)*'2-报价汇总'!$I$5 -> 0 | N26: =(M26+L26+K26+J26+I26)*'2-报价汇总'!$J$5 -> 0 | O26: =G26*H26 -> 201125.54
A27: 2.5.1.22 | B27: 遥控挡车杆 | C27: 2.本体、配管配线、安装 | D27: 室外装饰装修及安装工程项目 | E27: 按设计图示数量计算 | F27: 套 | G27: 1823.0282 | H27: =SUM(I27:N27) -> 2098.7013 | I27: 262.92208 | J27: 1800 | K27: 15 | L27: =(I27+J27+K27)*'2-报价汇总'!$H$5 -> 20.779221 | M27: =(I27+J27+K27+L27)*'2-报价汇总'!$I$5 -> 0 | N27: =(M27+L27+K27+J27+I27)*'2-报价汇总'!$J$5 -> 0 | O27: =G27*H27 -> 3825991.6
A28: 2.5.1.23 | B28: 承重井盖（能承重车） | C28: 1.球墨铸铁承重井盖 | D28: 室外装饰装修及安装工程项目 | E28: 按设计图示数量计算 | F28: 个 | G28: 5469.0846 | H28: =SUM(I28:N28) -> 466.08658 | I28: 106.47186 | J28: 350 | K28: 5 | L28: =(I28+J28+K28)*'2-报价汇总'!$H$5 -> 4.6147186 | M28: =(I28+J28+K28+L28)*'2-报价汇总'!$I$5 -> 0 | N28: =(M28+L28+K28+J28+I28)*'2-报价汇总'!$J$5 -> 0 | O28: =G28*H28 -> 2549066.9
A29: 2.5.1.24 | B29: 室外路灯，含相关电路 | C29: 1.本体及配管配线等工作 2.挖土、回填、基础制作等工作 | D29: 室外装饰装修及安装工程项目 | E29: 按设计图示数量计算 | F29: 个 | G29: 500 | H29: =SUM(I29:N29) -> 1224.2424 | I29: 192.12121 | J29: 1000 | K29: 20 | L29: =(I29+J29+K29)*'2-报价汇总'!$H$5 -> 12.121212 | M29: =(I29+J29+K29+L29)*'2-报价汇总'!$I$5 -> 0 | N29: =(M29+L29+K29+J29+I29)*'2-报价汇总'!$J$5 -> 0 | O29: =G29*H29 -> 612121.21
A30: 2.5.1.25 | B30: 室外高光灯，含相关电路 | C30: 1.本体及配管配线等工作 3.挖土、回填、基础制作等工作 | D30: 室外装饰装修及安装工程项目 | E30: 按设计图示数量计算 | F30: 个 | G30: 500 | H30: =SUM(I30:N30) -> 699.5671 | I30: 172.64069 | J30: 500 | K30: 20 | L30: =(I30+J30+K30)*'2-报价汇总'!$H$5 -> 6.9264069 | M30: =(I30+J30+K30+L30)*'2-报价汇总'!$I$5 -> 0 | N30: =(M30+L30+K30+J30+I30)*'2-报价汇总'!$J$5 -> 0 | O30: =G30*H30 -> 349783.55
A31: 2.5.1.26 | B31: 室外金属篦子 | C31: 1.球墨铸铁金属篦子 | D31: 室外装饰装修及安装工程项目 | E31: 按设计图示数量计算 | F31: 个 | G31: 500 | H31: =SUM(I31:N31) -> 87.445887 | I31: 4.5800866 | J31: 80 | K31: 2 | L31: =(I31+J31+K31)*'2-报价汇总'!$H$5 -> 0.86580087 | M31: =(I31+J31+K31+L31)*'2-报价汇总'!$I$5 -> 0 | N31: =(M31+L31+K31+J31+I31)*'2-报价汇总'!$J$5 -> 0 | O31: =G31*H31 -> 43722.944
A32: 2.5.1.27 | B32: 给排水接入市政管线DN100 | C32: 1.PE管道及管件供应安装 2.管沟开挖、回填 | D32: 室外装饰装修及安装工程项目 | F32: m | G32: 500 | H32: =SUM(I32:N32) -> 121.2 | I32: 29.5 | J32: 90 | K32: 0.5 | L32: =(I32+J32+K32)*'2-报价汇总'!$H$5 -> 1.2 | M32: =(I32+J32+K32+L32)*'2-报价汇总'!$I$5 -> 0 | N32: =(M32+L32+K32+J32+I32)*'2-报价汇总'!$J$5 -> 0 | O32: =G32*H32 -> 60600
A33: 2.5.1.28 | B33: 给排水接入市政管线DN150 | C33: 1.PE管道及管件供应安装 2.管沟开挖、回填 | D33: 室外装饰装修及安装工程项目 | F33: m | G33: 500 | H33: =SUM(I33:N33) -> 154.60433 | I33: 52.573593 | J33: 100 | K33: 0.5 | L33: =(I33+J33+K33)*'2-报价汇总'!$H$5 -> 1.5307359 | M33: =(I33+J33+K33+L33)*'2-报价汇总'!$I$5 -> 0 | N33: =(M33+L33+K33+J33+I33)*'2-报价汇总'!$J$5 -> 0 | O33: =G33*H33 -> 77302.165
A34: 2.5.1.29 | B34: 给排水接入市政管线DN200 | C34: 1.PE管道及管件供应安装 2.管沟开挖、回填 | D34: 室外装饰装修及安装工程项目 | F34: m | G34: 500 | H34: =SUM(I34:N34) -> 168.24589 | I34: 56.080087 | J34: 110 | K34: 0.5 | L34: =(I34+J34+K34)*'2-报价汇总'!$H$5 -> 1.6658009 | M34: =(I34+J34+K34+L34)*'2-报价汇总'!$I$5 -> 0 | N34: =(M34+L34+K34+J34+I34)*'2-报价汇总'!$J$5 -> 0 | O34: =G34*H34 -> 84122.944
A35: 2.5.1.30 | B35: 空调室外机基座 | C35: 1.挖土、回填等工作 2.混凝土基础 | D35: 室外装饰装修及安装工程项目 | E35: 按设计图示数量计算 | F35: 个 | G35: 500 | H35: =SUM(I35:N35) -> 874.45887 | I35: 265.42087 | J35: 600 | K35: 0.38 | L35: =(I35+J35+K35)*'2-报价汇总'!$H$5 -> 8.6580087 | M35: =(I35+J35+K35+L35)*'2-报价汇总'!$I$5 -> 0 | N35: =(M35+L35+K35+J35+I35)*'2-报价汇总'!$J$5 -> 0 | O35: =G35*H35 -> 437229.44
A36: 2.5.1.31 | B36: 化粪池 | C36: 1.地面开挖及回填等工作 2.钢筋混凝土化粪池制作（含模板） 3.内外防水处理 | D36: 室外装饰装修及安装工程项目 | E36: 按设计图示尺寸以混凝土体积计算 | F36: m3 | G36: 1000 | H36: =SUM(I36:N36) -> 3935.0649 | I36: 661.1039 | J36: 3200 | K36: 35 | L36: =(I36+J36+K36)*'2-报价汇总'!$H$5 -> 38.961039 | M36: =(I36+J36+K36+L36)*'2-报价汇总'!$I$5 -> 0 | N36: =(M36+L36+K36+J36+I36)*'2-报价汇总'!$J$5 -> 0 | O36: =G36*H36 -> 3935064.9
A37: 2.5.1.32 | B37: 雨水井 | C37: 1.地面开挖及回填等工作 2.预制混凝土井道及井圈 3.球磨铸铁承重井盖 | D37: 室外装饰装修及安装工程项目 | E37: 按设计图示数量计算 | F37: 个 | G37: 200 | H37: =SUM(I37:N37) -> 3397.2727 | I37: 513.63636 | J37: 2800 | K37: 50 | L37: =(I37+J37+K37)*'2-报价汇总'!$H$5 -> 33.636364 | M37: =(I37+J37+K37+L37)*'2-报价汇总'!$I$5 -> 0 | N37: =(M37+L37+K37+J37+I37)*'2-报价汇总'!$J$5 -> 0 | O37: =G37*H37 -> 679454.55
A38: 2.5.1.33 | B38: 200mm厚混凝土地面 | C38: 1.地面清理、场地平整 2.200mmC20混凝土地面 3.满铺钢筋网片φ6，横纵向间距200mm 4.面层压光，防滑处理 | D38: 室外装饰装修及安装工程项目 | E38: 按设计图示尺寸面积计算 | F38: m2 | G38: 500 | H38: =SUM(I38:N38) -> 166.14719 | I38: 114.50216 | J38: 40 | K38: 10 | L38: =(I38+J38+K38)*'2-报价汇总'!$H$5 -> 1.6450216 | M38: =(I38+J38+K38+L38)*'2-报价汇总'!$I$5 -> 0 | N38: =(M38+L38+K38+J38+I38)*'2-报价汇总'!$J$5 -> 0 | O38: =G38*H38 -> 83073.593
A39: 2.5.1.34 | B39: 排水管道土方开挖 | C39: 1.土方开挖 | D39: 室外装饰装修及安装工程项目 | E39: 按设计图示尺寸体积计算 | F39: m3 | G39: 500 | H39: =SUM(I39:N39) -> 69.95671 | I39: 62.794069 | J39: 3.8 | K39: 2.67 | L39: =(I39+J39+K39)*'2-报价汇总'!$H$5 -> 0.69264069 | M39: =(I39+J39+K39+L39)*'2-报价汇总'!$I$5 -> 0 | N39: =(M39+L39+K39+J39+I39)*'2-报价汇总'!$J$5 -> 0 | O39: =G39*H39 -> 34978.355
A40: 2.5.1.35 | B40: 排水管道土方回填 | C40: 1.土方回填 2.余土清理 | D40: 室内、室外装饰装修及安装工程项目 | E40: 按设计图示尺寸体积计算 | F40: m3 | G40: 500 | H40: =SUM(I40:N40) -> 87.445887 | I40: 77.240087 | J40: 7 | K40: 2.34 | L40: =(I40+J40+K40)*'2-报价汇总'!$H$5 -> 0.86580087 | M40: =(I40+J40+K40+L40)*'2-报价汇总'!$I$5 -> 0 | N40: =(M40+L40+K40+J40+I40)*'2-报价汇总'!$J$5 -> 0 | O40: =G40*H40 -> 43722.944
...

Sheet 2.6-消防工程
A1: 理想汽车中心店消防工程量清单
A2: ='2.1-装饰工程'!A2 -> 注意：此报价清单每项不得随意更改、删减，如有任何增加项请务必在每大项最后“补充项“中列举，补充项及说明字体颜色均采用蓝色；且所有项目都需要填写。
A3: 序号 | B3: 名 称 | C3: 型号及规格 | D3: 单位 | E3: 24/25年暂估工程量 | F3: 综合单价 | G3: 人工费 | H3: 材料费 | I3: 机械费 | J3: 安措费 | K3: 管理费 | L3: 利润 | M3: 24/25年暂估总价 | N3: 备注
B4: 2.6消防工程
A5: 2.6.1 | B5: 消防电系统
A6: 2.6.1.01 | B6: 新增烟感 1.含本体、管线、安装 2.底盒安装 | C6: 含管、线及辅料 | D6: 个 | F6: =SUM(G6:L6) -> 279.82684 | G6: 114.50628 | H6: 155.19 | I6: 7.36 | J6: =(G6+H6+I6)*'2-报价汇总'!$H$5 -> 2.7705628 | K6: =(G6+H6+I6+J6)*'2-报价汇总'!$I$5 -> 0 | L6: =(K6+J6+I6+H6+G6)*'2-报价汇总'!$J$5 -> 0 | M6: =E6*F6 -> 0
A7: 2.6.1.02 | B7: 移位及安装烟感 1.含拆除、移位、管线、重新安装 2.底盒安装 | C7: 含管、线及辅料 | D7: 个 | E7: 0 | F7: =SUM(G7:L7) -> 227.35931 | G7: 225.10823 | J7: =(G7+H7+I7)*'2-报价汇总'!$H$5 -> 2.2510823 | K7: =(G7+H7+I7+J7)*'2-报价汇总'!$I$5 -> 0 | L7: =(K7+J7+I7+H7+G7)*'2-报价汇总'!$J$5 -> 0 | M7: =E7*F7 -> 0
A8: 2.6.1.03 | B8: 新增火灾声光警报器 1.含本体、管线、安装 2.底盒安装 | C8: 含管、线及辅料 | D8: 个 | E8: 0 | F8: =SUM(G8:L8) -> 507.18615 | G8: 146.2445 | H8: 355.17 | I8: 0.75 | J8: =(G8+H8+I8)*'2-报价汇总'!$H$5 -> 5.021645 | K8: =(G8+H8+I8+J8)*'2-报价汇总'!$I$5 -> 0 | L8: =(K8+J8+I8+H8+G8)*'2-报价汇总'!$J$5 -> 0 | M8: =E8*F8 -> 0
A9: 2.6.1.04 | B9: 新增手动火灾警报装置 1.含本体、管线、安装 2.底盒安装 | C9: 含管、线及辅料 | D9: 个 | E9: 0 | F9: =SUM(G9:L9) -> 148.65801 | G9: 73.856147 | H9: 71.61 | I9: 1.72 | J9: =(G9+H9+I9)*'2-报价汇总'!$H$5 -> 1.4718615 | K9: =(G9+H9+I9+J9)*'2-报价汇总'!$I$5 -> 0 | L9: =(K9+J9+I9+H9+G9)*'2-报价汇总'!$J$5 -> 0 | M9: =E9*F9 -> 0
A10: 2.6.1.05 | B10: 新增消火栓起泵按钮 1.含本体、管线、安装 2.底盒安装 | C10: 含管、线及辅料 | D10: 个 | E10: 0 | F10: =SUM(G10:L10) -> 96.190476 | G10: 89.418095 | H10: 4.94 | I10: 0.88 | J10: =(G10+H10+I10)*'2-报价汇总'!$H$5 -> 0.95238095 | K10: =(G10+H10+I10+J10)*'2-报价汇总'!$I$5 -> 0 | L10: =(K10+J10+I10+H10+G10)*'2-报价汇总'!$J$5 -> 0 | M10: =E10*F10 -> 0
A11: 2.6.1.06 | B11: 移动及安装带电话插孔的手动报警按钮 1.含本体、管线、安装 2.底盒安装 | C11: 含管、线及辅料 | D11: 个 | E11: 0 | F11: =SUM(G11:L11) -> 183.63636 | G11: 45.828182 | H11: 134.43 | I11: 1.56 | J11: =(G11+H11+I11)*'2-报价汇总'!$H$5 -> 1.8181818 | K11: =(G11+H11+I11+J11)*'2-报价汇总'!$I$5 -> 0 | L11: =(K11+J11+I11+H11+G11)*'2-报价汇总'!$J$5 -> 0 | M11: =E11*F11 -> 0
A12: 2.6.1.07 | B12: 提供及安装短路隔离器 1.含本体、管线、安装 2.底盒安装 | C12: 含管、线及辅料 | D12: 个 | E12: 0 | F12: =SUM(G12:L12) -> 253.59307 | G12: 27.692251 | H12: 222.19 | I12: 1.2 | J12: =(G12+H12+I12)*'2-报价汇总'!$H$5 -> 2.5108225 | K12: =(G12+H12+I12+J12)*'2-报价汇总'!$I$5 -> 0 | L12: =(K12+J12+I12+H12+G12)*'2-报价汇总'!$J$5 -> 0 | M12: =E12*F12 -> 0
A13: 2.6.1.08 | B13: 新增消防广播 1.含本体、管线、安装 2.底盒安装 | C13: 含管、线及辅料 | D13: 个 | E13: 0 | F13: =SUM(G13:L13) -> 338.41558 | G13: 86.684935 | H13: 247.2 | I13: 1.18 | J13: =(G13+H13+I13)*'2-报价汇总'!$H$5 -> 3.3506494 | K13: =(G13+H13+I13+J13)*'2-报价汇总'!$I$5 -> 0 | L13: =(K13+J13+I13+H13+G13)*'2-报价汇总'!$J$5 -> 0 | M13: =E13*F13 -> 0
A14: 2.6.1.09 | B14: 移位消防广播 1.含本体、管线、安装 2.底盒安装 | C14: 含管、线及辅料 | D14: 个 | E14: 0 | F14: =SUM(G14:L14) -> 244.84848 | G14: 173.36987 | H14: 67.874372 | I14: 1.18 | J14: =(G14+H14+I14)*'2-报价汇总'!$H$5 -> 2.4242424 | K14: =(G14+H14+I14+J14)*'2-报价汇总'!$I$5 -> 0 | L14: =(K14+J14+I14+H14+G14)*'2-报价汇总'!$J$5 -> 0 | M14: =E14*F14 -> 0
A15: 2.6.1.10 | B15: 系统的调试 | D15: m2 | E15: 0 | F15: =SUM(G15:L15) -> 2.6233766 | G15: 2.5974026 | J15: =(G15+H15+I15)*'2-报价汇总'!$H$5 -> 0.025974026 | K15: =(G15+H15+I15+J15)*'2-报价汇总'!$I$5 -> 0 | L15: =(K15+J15+I15+H15+G15)*'2-报价汇总'!$J$5 -> 0 | M15: =E15*F15 -> 0
B16: 补充项 | E16: 0 | G16: 0 | J16: =(G16+H16+I16)*'2-报价汇总'!$H$5 -> 0 | K16: =(G16+H16+I16+J16)*'2-报价汇总'!$I$5 -> 0 | L16: =(K16+J16+I16+H16+G16)*'2-报价汇总'!$J$5 -> 0 | M16: =E16*F16 -> 0
B17: 小计 | E17: 0 | G17: 0 | J17: =(G17+H17+I17)*'2-报价汇总'!$H$5 -> 0 | K17: =(G17+H17+I17+J17)*'2-报价汇总'!$I$5 -> 0 | L17: =(K17+J17+I17+H17+G17)*'2-报价汇总'!$J$5 -> 0 | M17: =E17*F17 -> 0
A18: 2.6.2 | B18: 消防水系统 | E18: 0 | G18: 0 | J18: =(G18+H18+I18)*'2-报价汇总'!$H$5 -> 0 | K18: =(G18+H18+I18+J18)*'2-报价汇总'!$I$5 -> 0 | L18: =(K18+J18+I18+H18+G18)*'2-报价汇总'!$J$5 -> 0 | M18: =E18*F18 -> 0
A19: 2.6.2.01 | B19: 提供及安装明装喷淋 1.含本体、管道、构件、阀门等安装 2.支、吊架制作安装 | C19: 含管路及辅料 | D19: 个 | E19: 0 | F19: =SUM(G19:L19) -> 104.93506 | G19: 15.006104 | H19: 88.24 | I19: 0.65 | J19: =(G19+H19+I19)*'2-报价汇总'!$H$5 -> 1.038961 | K19: =(G19+H19+I19+J19)*'2-报价汇总'!$I$5 -> 0 | L19: =(K19+J19+I19+H19+G19)*'2-报价汇总'!$J$5 -> 0 | M19: =E19*F19 -> 0
A20: 2.6.2.02 | B20: 提供及安装暗装喷淋 1.含本体、管道、构件、阀门等安装 2.支、吊架制作安装 | C20: 含管路及辅料 | D20: 个 | E20: 0 | F20: =SUM(G20:L20) -> 104.93506 | G20: 15.006104 | H20: 88.24 | I20: 0.65 | J20: =(G20+H20+I20)*'2-报价汇总'!$H$5 -> 1.038961 | K20: =(G20+H20+I20+J20)*'2-报价汇总'!$I$5 -> 0 | L20: =(K20+J20+I20+H20+G20)*'2-报价汇总'!$J$5 -> 0 | M20: =E20*F20 -> 0
A21: 2.6.2.03 | B21: 移动原有喷淋 1.含拆除本体、管道、构件、阀门等重新安装 2.支、吊架制作安装 | C21: 含管路及辅料 | D21: 个 | E21: 0 | F21: =SUM(G21:L21) -> 69.95671 | G21: 69.264069 | J21: =(G21+H21+I21)*'2-报价汇总'!$H$5 -> 0.69264069 | K21: =(G21+H21+I21+J21)*'2-报价汇总'!$I$5 -> 0 | L21: =(K21+J21+I21+H21+G21)*'2-报价汇总'!$J$5 -> 0 | M21: =E21*F21 -> 0
