Workbook

Sheet 表03单项工程招标控制价汇总表
A1: 单项工程招标控制价汇总表
A2: 工程名称:装修工程（B2户型）
A3: 序号 | B3: 单位工程名称 | C3: 装修面积 | D3: 单户金额(元) | E3: 备注
A4: 1 | B4: 装修工程（B2户型） | D4: =装修工程!H53 -> 88900.898
A5: 2 | B5: 安装工程（B2户型） | D5: =安装工程!H17 -> 11569.4
A6: 3 | B6: 电器工程（B2户型） | D6: =电器工程!H11 -> 16034
A7: 4 | B7: 措施费 | D7: =(D4+D5+D6)*0.08 -> 9320.3438
A8: 5 | B8: 单户小计 | D8: =SUM(D4:D7) -> 125824.64 | F8: 92.85 | G8: =D8/F8 -> 1355.1388
A9: 6 | B9: 户数 | D9: 128
B10: 合计 | D10: =D8*D9 -> 16105554

Sheet 装修工程
A1: 分部分项工程量清单与计价表 | K1: 1
A2: 工程名称:装修工程（B2户型）
A3: 序号 | B3: 项目编码 | C3: 项目名称 | D3: 项目特征描述 | E3: 计量 单位 | F3: 工程量 | G3: 金额(元) | K3: 成本单价分析
G4: 综合 单价 | H4: 合价 | I4: 备注 | K4: 成本单价 | L4: 主材 | M4: 损耗率 | N4: 人工 | O4: 辅材 | P4: 机械 | Q4: 合价
C5: 交付标准
C6: 地面工程
A7: 1 | B7: 011102003008 | C7: 块料楼地面（阳台） | D7: 1.结合层:素水泥砂浆10mm厚，1：3干硬性水泥砂浆20mm厚，水泥膏10mm厚_x000D_ 2.面层:400*400防滑瓷砖_x000D_ 3.满足设计图纸、相关规范及招标文件的要求 | E7: m2 | F7: 8.96 | G7: =K7*$K$1 -> 112.375 | H7: =F7*G7 -> 1006.88 | J7: =((0.4*0.4*60)-8.96)/8.96 -> 0.071428571 | K7: =L7+L7*M7+N7+O7+P7 -> 112.375 | L7: 45 | M7: 0.075 | N7: 48 | O7: 14 | P7: 2 | Q7: =K7*F7 -> 1006.88
A8: 2 | B8: 011102003011 | C8: 块料楼地面（客厅、厨房） | D8: 1.结合层:素水泥砂浆10mm厚，1:3干硬性水泥砂浆20mm厚，水泥膏10mm厚_x000D_ 2.面层:1500*750mm瓷砖_x000D_ 3.满足设计图纸、相关规范及招标文件的要求 | E8: m2 | F8: 31.93 | G8: =K8*$K$1 -> 149 | H8: =F8*G8 -> 4757.57 | K8: =L8+L8*M8+N8+O8+P8 -> 149 | L8: 85 | M8: 0 | N8: 48 | O8: 14 | P8: 2 | Q8: =K8*F8 -> 4757.57
A9: 3 | B9: 011102003001 | C9: 块料楼地面（卫生间） | D9: 1.结合层:素水泥砂浆10mm厚，1:3干硬性水泥砂浆20mm厚，水泥膏10mm厚_x000D_ 2.面层:1200*600mm瓷砖_x000D_ 3.满足设计图纸、相关规范及招标文件的要求 | E9: m2 | F9: 8.28 | G9: =K9*$K$1 -> 119 | H9: =F9*G9 -> 985.32 | K9: =L9+L9*M9+N9+O9+P9 -> 119 | L9: 55 | M9: 0 | N9: 48 | O9: 14 | P9: 2 | Q9: =K9*F9 -> 985.32
A10: 4 | B10: 010904002004 | C10: 卫生间防水（第二道防水） | D10: 1.防水膜品种:JS-II防水涂层_x000D_ 2.涂膜厚度、遍数:1.0mm_x000D_ 3.满足设计图纸、相关规范及招标文件的要求 | E10: m2 | F10: 12.9 | G10: =K10*$K$1 -> 56.7 | H10: =F10*G10 -> 731.43 | K10: =L10+L10*M10+N10+O10+P10 -> 56.7 | L10: 26.5 | M10: 0 | N10: 18 | O10: 12 | P10: 0.2 | Q10: =K10*F10 -> 731.43
A11: 5 | B11: 011101003002 | C11: 卫生间地面-细石混凝土保护层 | D11: 1.保护层:50mm厚C20细石混凝土_x000D_ 2.满足设计图纸、相关规范及招标文件的要求 | E11: m2 | F11: 8.28 | G11: =K11*$K$1 -> 45 | H11: =F11*G11 -> 372.6 | K11: =L11+L11*M11+N11+O11+P11 -> 45 | L11: 0 | M11: 0 | N11: 22 | O11: =420*0.05 -> 21 | P11: 2 | Q11: =K11*F11 -> 372.6
A12: 6 | B12: 010103001003 | C12: 卫生间回填 | D12: 1.卫生间回填陶粒混凝土_x000D_ 2.满足设计图纸、相关规范及招标文件的要求 | E12: m3 | F12: 2.48 | G12: =K12*$K$1 -> 482 | H12: =F12*G12 -> 1195.36 | K12: =L12+L12*M12+N12+O12+P12 -> 482 | L12: =385 -> 385 | M12: 0 | N12: 85 | O12: 12 | P12: 0 | Q12: =K12*F12 -> 1195.36
A13: 7 | B13: 011104002004 | C13: 竹、木(复合)地板 | D13: 1.30mm厚1:3干硬性水泥砂浆，表面撒素水泥_x000D_ 2.1.5mm地板专用防潮垫_x000D_ 3.面层材料:WF01强化复合地板_x000D_ 4.满足设计图纸、相关规范及招标文件的要求 | E13: m2 | F13: 34.59 | G13: =K13*$K$1 -> 101 | H13: =F13*G13 -> 3493.59 | K13: =L13+L13*M13+N13+O13+P13 -> 101 | L13: 60 | M13: 0.05 | N13: 20 | O13: 17.5 | P13: 0.5 | Q13: =K13*F13 -> 3493.59
A14: 8 | B14: 010809004001 | C14: 窗台(岩板) | D14: 1.窗台板材质:岩板_x000D_ 2.胶粘剂_x000D_ 3.满足设计图纸、相关规范及招标文件的要求 | E14: m2 | F14: 7.66 | G14: =K14*$K$1 -> 320.3 | H14: =F14*G14 -> 2453.498 | K14: =L14+L14*M14+N14+O14+P14 -> 320.3 | L14: 193 | M14: 0 | N14: 110 | O14: =16.8 -> 16.8 | P14: 0.5 | Q14: =K14*F14 -> 2453.498
A15: 9 | B15: 011102001001 | C15: 石材楼地面（门槛石ST-02大理石） | D15: 1.面层材料品种、规格、颜色:门槛石ST-02大理石（正、背面及四周边满涂防碱背涂剂）_x000D_ 2.结合层厚度、砂浆配合比:水泥砂浆粘结层_x000D_ 3.满足设计图纸、相关规范及招标文件的要求 | E15: m2 | F15: 1.43 | G15: =K15*$K$1 -> 291.55 | H15: =F15*G15 -> 416.9165 | K15: =L15+L15*M15+N15+O15+P15 -> 291.55 | L15: 135 | M15: 0.03 | N15: 140 | O15: 12 | P15: 0.5 | Q15: =K15*F15 -> 416.9165
A16: 10 | B16: 010904002005 | C16: 卫生间门槛石防水（第一道防水） | D16: 1.防水膜品种:JS-II防水涂层_x000D_ 2.涂膜厚度、遍数:1.0mm_x000D_ 3.满足设计图纸、相关规范及招标文件的要求 | E16: m2 | F16: 0.32 | G16: =$G$10 -> 56.7 | H16: =F16*G16 -> 18.144 | K16: =L16+L16*M16+N16+O16+P16 -> 0 | Q16: =K16*F16 -> 0
A17: 11 | B17: 030701007002 | C17: 卫生间挡水条（ST-01） | D17: 1.名称:卫生间挡水条（ST-01）_x000D_ 2.挡水条底部用1:2:5的水泥砂浆固定_x000D_ 3.挡水石嵌入挡水条后,底部用防水砂浆进行收口处理_x000D_ 4.内嵌止水钢板_x000D_ 5.满足设计图纸、相关规范及招标文件的要求 | E17: m | F17: 2.28 | G17: =K17*$K$1 -> 172.9 | H17: =F17*G17 -> 394.212 | K17: =L17+L17*M17+N17+O17+P17 -> 172.9 | L17: 130 | M17: 0.03 | N17: 35 | O17: 3.5 | P17: 0.5 | Q17: =K17*F17 -> 394.212
C18: 天棚工程
A19: 12 | B19: 011302001026 | C19: 吊顶天棚 | D19: 1.龙骨材料:轻钢龙骨,双向吊点,900~1200_x000D_ 2.基层材料:9MM阻燃夹板基层_x000D_ 3.面层材料:9.5mm石膏板_x000D_ 4.孔眼用腻子填平(防锈),阴、阳角及板接缝处分别贴专用封缝带刮内墙布耐水腻子找平2~3遍_x000D_ 5.刷白色乳胶漆三遍_x000D_ 6.满足设计图纸、相关规范及招标文件的要求 | E19: m2 | F19: 11.82 | G19: =K19*$K$1 -> 177.562 | H19: =F19*G19 -> 2098.7828 | K19: =L19+L19*M19+N19+O19+P19 -> 177.562 | L19: 5.5 | M19: 0.02 | N19: =19.5+75 -> 94.5 | O19: =(3.3*3.7+1.1*4.7+1.5+6*0.23+1*0.75+1*0.13+80*0.04+1*2.8)*1.05+10.5*1.45+25*1.05+5.98 -> 75.952 | P19: 1.5 | Q19: =K19*F19 -> 2098.7828
A20: 13 | B20: 011302001029 | C20: 吊顶天棚 | D20: 1.龙骨材料:轻钢龙骨_x000D_ 2.面层材料:300x600mm铝扣板_x000D_ 3.满足设计图纸、相关规范及招标文件的要求 | E20: m2 | F20: 11.76 | G20: =K20*$K$1 -> 112.48 | H20: =F20*G20 -> 1322.7648 | K20: =L20+L20*M20+N20+O20+P20 -> 112.48 | L20: 48 | M20: 0.01 | N20: 45 | O20: =18.5 -> 18.5 | P20: 0.5 | Q20: =K20*F20 -> 1322.7648
A21: 14 | B21: 011301001003 | C21: 天棚抹灰(平梁、原顶) | D21: 1.刮白胶腻子二遍、刷白色乳胶漆三遍_x000D_ 2.满足设计图纸、相关规范及招标文件的要求 | E21: m2 | F21: 57.19 | G21: =K21*$K$1 -> 63.115 | H21: =F21*G21 -> 3609.5469 | K21: =L21+L21*M21+N21+O21+P21 -> 63.115 | L21: 5.5 | M21: 0.01 | N21: =20+19.5 -> 39.5 | O21: =12+5.86 -> 17.86 | P21: 0.2 | Q21: =K21*F21 -> 3609.5469
A22: 15 | B22: 011304001010 | C22: 灯带(槽) | D22: 1.规格:70*50mm_x000D_ 2.基层:9MM阻燃夹板_x000D_ 3.面层:9.5mm石膏板_x000D_ 4.油漆:刮白胶腻子与白色乳胶漆各二遍_x000D_ 5.详见:028/01~02_x000D_ 6.满足设计图纸、相关规范及招标文件的要求 | E22: m | F22: 3.5 | G22: =K22*$K$1 -> 49.699 | H22: =F22*G22 -> 173.9465 | K22: =L22+L22*M22+N22+O22+P22 -> 49.699 | L22: =(25*2+10.5+5.5)*0.15 -> 9.9 | M22: 0.01 | N22: 38 | O22: 1.5 | P22: 0.2 | Q22: =K22*F22 -> 173.9465
A23: 16 | B23: 011207001001 | C23: 天棚装饰板 | D23: 1.基层材料:双层9.5mm厘轻质不燃板_x000D_ 2.面层材料:刮白胶腻子二遍、刷白色乳胶漆三遍_x000D_ 3.满足设计图纸、相关规范及招标文件的要求 | E23: m2 | F23: 11.94 | G23: =K23*$K$1 -> 108.415 | H23: =F23*G23 -> 1294.4751 | K23: =L23+L23*M23+N23+O23+P23 -> 108.415 | L23: 5.5 | M23: 0.01 | N23: =20+18+19.5 -> 57.5 | O23: =28.5+10.5+5.86 -> 44.86 | P23: 0.5 | Q23: =K23*F23 -> 1294.4751
C24: 墙、柱面装饰工程
A25: 17 | B25: 011105005001 | C25: 金属踢脚线 | D25: 1.铝合金踢脚线_x000D_ 2.高度:45mm_x000D_ 3.满足设计图纸、相关规范及招标文件的要求 | E25: m | F25: 66.14 | G25: =K25*$K$1 -> 32.705 | H25: =F25*G25 -> 2163.1087 | K25: =L25+L25*M25+N25+O25+P25 -> 32.705 | L25: 13.5 | M25: 0.03 | N25: 15 | O25: 3.5 | P25: 0.3 | Q25: =K25*F25 -> 2163.1087
A26: 18 | B26: 011502001017 | C26: 金属装饰线 | D26: 1.名称:MT02黑色铝条_x000D_ 2.满足设计图纸、相关规范及招标文件的要求 | E26: m | F26: 6.31 | G26: =K26*$K$1 -> 41.54 | H26: =F26*G26 -> 262.1174 | K26: =L26+L26*M26+N26+O26+P26 -> 41.54 | L26: =38-10 -> 28 | M26: 0.03 | N26: 10 | O26: 2.5 | P26: 0.2 | Q26: =K26*F26 -> 262.1174
A27: 19 | B27: 011204003004 | C27: 块料墙面 | D27: 1.1.5MM厚防水层至天花吊顶底1:3水泥石灰浆打底_x000D_ 2.1：1水泥石灰浆(加107胶)粘结层_x000D_ 3.陶瓷 1200mm×600mm_x000D_ 4.满足设计图纸、相关规范及招标文件的要求 | E27: m2 | F27: 63.74 | G27: =K27*$K$1 -> 180.6 | H27: =F27*G27 -> 11511.444 | K27: =L27+L27*M27+N27+O27+P27 -> 180.6 | L27: 55 | M27: 0.16 | N27: =48+20 -> 68 | O27: =30+16.8 -> 46.8 | P27: 2 | Q27: =K27*F27 -> 11511.444
A28: 20 | B28: 011204003001 | C28: 块料墙面 | D28: 1.基层材料:9mm厚B1级阻燃多层板_x000D_ 2.岩板_x000D_ 3.满足设计图纸、相关规范及招标文件的要求 | E28: m2 | F28: 4.73 | G28: =K28*$K$1 -> 311.45 | H28: =F28*G28 -> 1473.1585 | K28: =L28+L28*M28+N28+O28+P28 -> 311.45 | L28: 193 | M28: 0.05 | N28: 90 | O28: 16.8 | P28: 2 | Q28: =K28*F28 -> 1473.1585
A29: 21 | B29: 011201001003 | C29: 墙面乳胶漆 | D29: 1.0.3:3水泥石灰沙浆打底_x000D_ 2.0.3:2.5水泥石灰沙浆抹面_x000D_ 3.刮白胶腻子找平二遍_x000D_ 4.刷乳胶漆三遍(一底、二面漆)PT-01、PT-03_x000D_ 5.满足设计图纸、相关规范及招标文件的要求 | E29: m2 | F29: 172.05 | G29: =K29*$K$1 -> 31.89 | H29: =F29*G29 -> 5486.6745 | K29: =L29+L29*M29+N29+O29+P29 -> 31.89 | L29: 5.5 | M29: 0.02 | N29: 19.5 | O29: 5.98 | P29: 0.8 | Q29: =K29*F29 -> 5486.6745
A30: 22 | B30: 011207001025 | C30: 墙面装饰板 | D30: 1.基层材料:18厘夹板_x000D_ 2.刮白胶腻子找平二遍_x000D_ 3.刷乳胶漆三遍(一底、二面漆)_x000D_ 4.满足设计图纸、相关规范及招标文件的要求 | E30: m2 | F30: 15.68 | G30: =K30*$K$1 -> 126.625 | H30: =F30*G30 -> 1985.48 | K30: =L30+L30*M30+N30+O30+P30 -> 126.625 | L30: 5.5 | M30: 0.03 | N30: =19.5+20+15 -> 54.5 | O30: =15+42.5+5.89 -> 63.39 | P30: 3.07 | Q30: =K30*F30 -> 1985.48
A31: 23 | B31: 011207001028 | C31: 深色格栅面板 | D31: 1.基层材料:9mm厚B1级阻燃多层板 2.深色格栅面板 3.满足设计图纸、相关规范及招标文件的要求 | E31: m2 | F31: 1.15 | G31: =K31*$K$1 -> 518.45 | H31: =F31*G31 -> 596.2175 | J31: =_xlfn.DISPIMG("ID_65234C535EA54FD9BAC834617EFFCCF9",1) -> =DISPIMG("ID_65234C535EA54FD9BAC834617EFFCCF9",1) | K31: =L31+L31*M31+N31+O31+P31 -> 518.45 | L31: 365 | M31: 0.03 | N31: =15+20+55 -> 90 | O31: =15+35 -> 50 | P31: 2.5 | Q31: =K31*F31 -> 596.2175
A32: 24 | B32: 011210003005 | C32: 玻璃隔断 | D32: 1.玻璃品种:12厘钢化玻璃隔断_x000D_ 2.满足设计图纸、相关规范及招标文件的要求 | E32: m2 | F32: 5.64 | G32: =K32*$K$1 -> 204 | H32: =F32*G32 -> 1150.56 | K32: =L32+L32*M32+N32+O32+P32 -> 204 | L32: 100 | M32: 0.01 | N32: 85 | O32: 15 | P32: 3 | Q32: =K32*F32 -> 1150.56
A33: 25 | B33: 011207001028 | C33: 墙面硬包 | D33: 1.基层材料:9mm厚B1级阻燃多层板_x000D_ 2.墙面硬包_x000D_ 3.满足设计图纸、相关规范及招标文件的要求 | E33: m2 | F33: 7.93 | G33: =K33*$K$1 -> 331.4 | H33: =F33*G33 -> 2628.002 | K33: =L33+L33*M33+N33+O33+P33 -> 331.4 | L33: 230 | M33: 0.03 | N33: =20+15 -> 35 | O33: =15+42.5 -> 57.5 | P33: 2 | Q33: =K33*F33 -> 2628.002
C34: 其他
A35: 26 | B35: 011501005001 | C35: 入户柜 | D35: 1.成品入户柜_x000D_ 2.面层:木饰面_x000D_ 3.计算规则:按图示墙面投影面积计算_x000D_ 4.具体规格做法详见招标图纸，满足图纸及施工规范要求。 | E35: ㎡ | F35: 5.85 | G35: =K35*$K$1 -> 918 | H35: =F35*G35 -> 5370.3 | K35: =L35+L35*M35+N35+O35+P35 -> 918 | L35: 850 | M35: 0 | N35: 30 | O35: 35 | P35: 3 | Q35: =K35*F35 -> 5370.3
A36: 27 | B36: 030701002002 | C36: 厨房门（双包） | D36: 1.名称:2200mm*840mm定制成品铝合金门_x000D_ 2.满足设计图纸、相关规范及招标文件的要求 | E36: m2 | F36: 1.85 | G36: =K36*$K$1 -> 1050 | H36: =F36*G36 -> 1942.5 | K36: =L36+L36*M36+N36+O36+P36 -> 1050 | L36: 860 | M36: 0 | N36: 150 | O36: 35 | P36: 5 | Q36: =K36*F36 -> 1942.5
A37: 28 | B37: 030701002003 | C37: 卫生间门 | D37: 1.名称:2200mm*920mm定制成品木门_x000D_ 2.满足设计图纸、相关规范及招标文件的要求 | E37: 樘 | F37: 2 | G37: =K37*$K$1 -> 1766.5 | H37: =F37*G37 -> 3533 | K37: =L37+L37*M37+N37+O37+P37 -> 1766.5 | L37: 1500 | M37: 0 | N37: 250 | O37: 15 | P37: 1.5 | Q37: =K37*F37 -> 3533
A38: 29 | B38: 030701002004 | C38: 房间木门 | D38: 1.名称:2200mm*920mm定制成品木门_x000D_ 2.满足设计图纸、相关规范及招标文件的要求 | E38: 樘 | F38: 4 | G38: =K38*$K$1 -> 1766.5 | H38: =F38*G38 -> 7066 | K38: =L38+L38*M38+N38+O38+P38 -> 1766.5 | L38: 1500 | M38: 0 | N38: 250 | O38: 15 | P38: 1.5 | Q38: =K38*F38 -> 7066
A39: 30 | B39: 011501B002001 | C39: 浴室柜 | D39: 1.柜规格:800*585*400mm_x000D_ 2.材料种类、规格:定制浴室柜_x000D_ 3.其他详设计图纸、招标文件 | E39: 个 | F39: 2 | G39: =K39*$K$1 -> 1236.5 | H39: =F39*G39 -> 2473 | K39: =L39+L39*M39+N39+O39+P39 -> 1236.5 | L39: 1050 | M39: 0 | N39: 150 | O39: 35 | P39: 1.5 | Q39: =K39*F39 -> 2473
A40: 31 | B40: 011505011001 | C40: 定制镜箱 | D40: 1.镜箱尺寸:800*650mm_x000D_ 2.镜箱材质:定制镜箱_x000D_ 3.其他详设计图纸、招标文件 | E40: 个 | F40: 2 | G40: =K40*$K$1 -> 981.5 | H40: =F40*G40 -> 1963 | K40: =L40+L40*M40+N40+O40+P40 -> 981.5 | L40: 850 | M40: 0 | N40: 95 | O40: 35 | P40: 1.5 | Q40: =K40*F40 -> 1963
...

Sheet 安装工程
A1: 分部分项工程量清单与计价表 | K1: =装修工程!$K$1 -> 1
A2: 工程名称:安装工程(B2户型)
A3: 序号 | B3: 项目编码 | C3: 项目名称 | D3: 项目特征描述 | E3: 计量 单位 | F3: 工程量 | G3: 金额(元) | K3: 成本单价分析
G4: 综合 单价 | H4: 合价 | I4: 备注 | K4: 成本单价 | L4: 主材 | M4: 损耗率 | N4: 人工 | O4: 辅材 | P4: 机械 | Q4: 合价
C5: B2户型
C6: 给排水
A7: 1 | B7: 031004003002 | C7: 洗脸盆 | D7: (1)名称:洗脸盆_x000D_ (2)规格、类型:_x000D_ (3)附件名称、数量:龙头 | E7: 组 | F7: 2 | G7: =K7*$K$1 -> 419.8 | H7: =F7*G7 -> 839.6 | K7: =L7+L7*M7+N7+O7+P7 -> 419.8 | L7: 320 | M7: 0 | N7: 55 | O7: =22*2 -> 44 | P7: 0.8 | Q7: =K7*F7 -> 839.6
A8: 2 | B8: 031004004002 | C8: 洗涤盆 | D8: (1)名称:洗菜盆_x000D_ (2)附件名称、数量:水龙头 | E8: 组 | F8: 1 | G8: =K8*$K$1 -> 729.8 | H8: =F8*G8 -> 729.8 | K8: =L8+L8*M8+N8+O8+P8 -> 729.8 | L8: 630 | M8: 0 | N8: 55 | O8: =22*2 -> 44 | P8: 0.8 | Q8: =K8*F8 -> 729.8
A9: 3 | B9: 031004006002 | C9: 大便器 | D9: (1)名称:坐便器_x000D_ (2)规格、类型: | E9: 组 | F9: 2 | G9: =K9*$K$1 -> 2415.8 | H9: =F9*G9 -> 4831.6 | K9: =L9+L9*M9+N9+O9+P9 -> 2415.8 | L9: 2300 | M9: 0 | N9: 100 | O9: 15 | P9: 0.8 | Q9: =K9*F9 -> 4831.6
A10: 4 | B10: 031004010001 | C10: 淋浴器 | D10: (1)名称:花洒 | E10: 套 | F10: 2 | G10: =K10*$K$1 -> 1410.8 | H10: =F10*G10 -> 2821.6 | K10: =L10+L10*M10+N10+O10+P10 -> 1410.8 | L10: 1300 | M10: 0 | N10: 85 | O10: 25 | P10: 0.8 | Q10: =K10*F10 -> 2821.6
A11: 5 | B11: 031004008002 | C11: 地漏 | D11: (1)材质:不锈钢_x000D_ (2)其他满足图纸、规范及招标文件要求 | E11: 组 | F11: 6 | G11: =K11*$K$1 -> 81.7 | H11: =F11*G11 -> 490.2 | K11: =L11+L11*M11+N11+O11+P11 -> 81.7 | L11: 55 | M11: 0 | N11: 25 | O11: 1.5 | P11: 0.2 | Q11: =K11*F11 -> 490.2
C12: 强电
A13: 6 | B13: 030412004006 | C13: 装饰灯 | D13: (1)名称:吸顶灯_x000D_ (2)规格:11-15W/4000K | E13: 套 | F13: 7 | G13: =K13*$K$1 -> 74.7 | H13: =F13*G13 -> 522.9 | K13: =L13+L13*M13+N13+O13+P13 -> 74.7 | L13: 55 | M13: 0 | N13: 18 | O13: 1.5 | P13: 0.2 | Q13: =K13*F13 -> 522.9
A14: 7 | B14: 030412004001 | C14: 装饰灯 | D14: (1)名称:300*300平板灯_x000D_ (2)安装形式:嵌入 | E14: 套 | F14: 1 | G14: =K14*$K$1 -> 61.7 | H14: =F14*G14 -> 61.7 | K14: =L14+L14*M14+N14+O14+P14 -> 61.7 | L14: 42 | M14: 0 | N14: 18 | O14: 1.5 | P14: 0.2 | Q14: =K14*F14 -> 61.7
A15: 8 | B15: 030412001001 | C15: 普通灯具 | D15: (1)名称:射灯_x000D_ (2)规格:5W/3000K_x000D_ (3)类型:嵌入 | E15: 套 | F15: 8 | G15: =K15*$K$1 -> 67.7 | H15: =F15*G15 -> 541.6 | K15: =L15+L15*M15+N15+O15+P15 -> 67.7 | L15: 48 | M15: 0 | N15: 18 | O15: 1.5 | P15: 0.2 | Q15: =K15*F15 -> 541.6
A16: 9 | B16: 030412004002 | C16: 装饰灯 | D16: (1)名称:三合一浴霸 | E16: 套 | F16: 2 | G16: =K16*$K$1 -> 365.2 | H16: =F16*G16 -> 730.4 | K16: =L16+L16*M16+N16+O16+P16 -> 365.2 | L16: 320 | M16: 0 | N16: 40 | O16: 5 | P16: 0.2 | Q16: =K16*F16 -> 730.4
C17: 合计 | H17: =SUM(H7:H16) -> 11569.4

Sheet 电器工程
A1: 分部分项工程量清单与计价表 | K1: =装修工程!$K$1 -> 1
A2: 工程名称:电器工程（B2）
A3: 序号 | B3: 项目编码 | C3: 项目名称 | D3: 项目特征描述 | E3: 计量 单位 | F3: 工程量 | G3: 金额(元) | K3: 成本单价分析
G4: 综合 单价 | H4: 合价 | I4: 备注 | K4: 成本单价 | L4: 主材 | M4: 损耗率 | N4: 人工 | O4: 辅材 | P4: 机械 | Q4: 合价
C5: 分部工程
A6: 1 | B6: 030701003001 | C6: 空调 | D6: (1)名称:客厅风管机 | E6: 台 | F6: 1 | G6: =K6*$K$1 -> 5845 | H6: =F6*G6 -> 5845 | K6: =L6+L6*M6+N6+O6+P6 -> 5845 | L6: 3600 | M6: 0 | N6: 1000 | O6: 1200 | P6: 45 | Q6: =K6*F6 -> 5845
A7: 2 | B7: 031007004001 | C7: 燃气热水器 | D7: (1)类型:热水器 | E7: 台 | F7: 1 | G7: =K7*$K$1 -> 3233.5 | H7: =F7*G7 -> 3233.5 | K7: =L7+L7*M7+N7+O7+P7 -> 3233.5 | L7: 3000 | M7: 0 | N7: 180 | O7: 45 | P7: 8.5 | Q7: =K7*F7 -> 3233.5
A8: 3 | B8: 031007004002 | C8: 油烟机 | D8: (1)类型:油烟机 | E8: 台 | F8: 1 | G8: =K8*$K$1 -> 1193.5 | H8: =F8*G8 -> 1193.5 | K8: =L8+L8*M8+N8+O8+P8 -> 1193.5 | L8: 900 | M8: 0 | N8: 250 | O8: 35 | P8: 8.5 | Q8: =K8*F8 -> 1193.5
A9: 4 | B9: 031007004003 | C9: 燃气灶 | D9: (1)类型:燃气灶 | E9: 台 | F9: 1 | G9: =K9*$K$1 -> 1268.5 | H9: =F9*G9 -> 1268.5 | K9: =L9+L9*M9+N9+O9+P9 -> 1268.5 | L9: 1150 | M9: 0 | N9: 85 | O9: 25 | P9: 8.5 | Q9: =K9*F9 -> 1268.5
A10: 5 | B10: 031007004004 | C10: 洗碗机 | D10: (1)类型:洗碗机 | E10: 台 | F10: 1 | G10: =K10*$K$1 -> 4493.5 | H10: =F10*G10 -> 4493.5 | K10: =L10+L10*M10+N10+O10+P10 -> 4493.5 | L10: 4200 | M10: 0 | N10: 250 | O10: 35 | P10: 8.5 | Q10: =K10*F10 -> 4493.5
B11: 合计 | H11: =SUM(H6:H10) -> 16034
