Workbook
Name _: [1]PUR资料库!$B$5:$F$2503
Name ______________ys1: #REF!
Name ______________ys2: #REF!
Name ______________ys3: #REF!
Name _____________ys1: #REF!
Name _____________ys2: #REF!
Name _____________ys3: #REF!
Name ____________W200: '[2]21'!$B$1:$B$802
Name ____________x1: #REF!
Name ____________ys1: #REF!
Name ____________ys2: #REF!
Name ____________ys3: #REF!
Name ___________W200: '[2]21'!$B$1:$B$802
Name ___________x1: #REF!
Name ___________ys1: #REF!
Name ___________ys2: #REF!
Name ___________ys3: #REF!
Name __________W200: '[2]21'!$B$1:$B$802
Name __________x1: #REF!
Name __________ys1: #REF!
Name __________ys2: #REF!
Name __________ys3: #REF!
Name _________W200: '[2]21'!$B$1:$B$802
Name _________x1: #REF!
Name _________ys1: #REF!
Name _________ys2: #REF!
Name _________ys3: #REF!
Name ________W200: '[2]21'!$B$1:$B$802
Name ________x1: #REF!
Name ________ys1: #REF!
Name ________ys2: #REF!
Name ________ys3: #REF!
Name _______W200: '[2]21'!$B$1:$B$802
Name _______x1: #REF!
Name _______ys1: #REF!
Name _______ys2: #REF!
Name _______ys3: #REF!
Name ______W200: '[2]21'!$B$1:$B$802
Name ______x1: #REF!
Name ______ys1: #REF!
Name ______ys2: #REF!
Name ______ys3: #REF!
Name _____W200: '[2]21'!$B$1:$B$802
Name _____x1: #REF!
Name _____ys1: #REF!
Name _____ys2: #REF!
Name _____ys3: #REF!
Name ____W200: '[2]21'!$B$1:$B$802
Name ____x1: #REF!
Name ____ys1: #REF!
Name ____ys2: #REF!
Name ____ys3: #REF!
Name ___W200: '[2]21'!$B$1:$B$802
Name ___x1: #REF!
Name ___ys1: #REF!
Name ___ys2: #REF!
Name ___ys3: #REF!
Name __1W200_: '[2]21'!$B$1:$B$802
Name __W200: '[2]21'!$B$1:$B$802
Name __x1: #REF!

Sheet 封面
A2: 投 标 总 价
A4: 招 标 人： | B4: 深圳市九亿通航电子设备科技有限公司
A5: 工程名称： | B5: 广东省深圳市龙华区龙华数字智造中心(建泰城市更新项目)项目1栋 11层 01号/装修施工工程
A6: 投标总价（小写）： | B6: =报价汇总!C11 -> 2073870.3
A7: 投标总价（大写）： | B7: =IF(B6<0,"负","")&SUBSTITUTE(SUBSTITUTE(TEXT(TRUNC(FIXED(ABS(B6))),"[>0][dbnum2];;")&TEXT(RIGHT(FIXED(B6),2),"元[dbnum2]0角0分;;"&IF(ABS(B6)>1%,"元整",)),"零角",IF(ABS(B6)<1,,"零")),"零分","整") -> 贰佰零柒万叁仟捌佰柒拾元叁角壹分
A8: 投标人： | B8: 深圳市广湾建设科技有限公司
B9: （单位盖章）
A10: 法定代表人 或其授权人： | B10: 叶利威
B11: （签字或盖章）
A12: 编制人： | B12: 黄维师
B13: （造价人员签字盖专用章）
A15: 编制时间： | B15: 2026 年 3 月 13 日

Sheet 报价说明
B1: 报价说明
A2: 工程名称：广东省深圳市龙华区龙华数字智造中心(建泰城市更新项目)项目1栋 11层 01号/装修施工工程
A3: 一、编制范围： 1、内装修编制范围（即内装修界面范围）： （1）室内的面层装修：墙地面瓷砖、地毯、强化地板，顶棚墙面腻子涂料、顶棚石膏板吊顶、灯膜，轻钢龙骨隔墙、普通钢化玻璃中空隔断，墙面木饰面、不锈钢、阳极氧化铝板、烤漆玻璃、软包、毛毡、亚光板、洞洞板、海鲜板、软木板装饰，房间门、隔断玻璃门，大堂前台、卡座，清单项目所列范围内项目，不含招牌logo、门牌标识、艺术壁灯、装饰画、家具。 2、安装工程编制范围（即装修配套的二次安装界面范围）： （2.1）强电工程：包含二次配电箱及下口出线开始至末端设备（电线、线管、开关、插座、灯具）清单项目所列范围内项目，不含预埋在建筑主体柱梁板基础混凝土内的预埋管、套管及封堵，含二次配电箱至机房的桥架、线缆； （2.2）弱电工程：不在本次范围； （2.3）消防报警工程：包含应急照明电线、线管、安全指示灯，火灾报警电线、线管、烟感探测器、吸顶式扬声器、手动报警器、防火阀、总线隔离模块、报警按钮、控制模块、输入模块、探测模块、非消防电源切除、声光报警器、气体灭火紧急启停按钮、气体灭火放气警告灯、非贮存悬挂式超细干粉灭火装置电控联动； （2.4）消防水工程：包含消防喷淋管、喷头、消防栓； （2.5）空调工程：含电源线、线管，不含空调开关、按钮、设备、阀门、百叶风口、冷凝管、冷媒管等；

Sheet 报价汇总
A1: 汇总表
A2: 工程名称：广东省深圳市龙华区龙华数字智造中心(建泰城市更新项目)项目1栋 11层 01号/装修施工工程
A3: 序号 | B3: 名称 | C3: 金额（元） | D3: 面积（㎡） | E3: 单方价格（元/㎡） | F3: 备注
A4: 一 | B4: 装饰工程 | C4: =装修工程清单!G4 -> 1241384.2
A5: 二 | B5: 安装工程 | C5: =装修工程清单!G361 -> 423293.57
A6: 三 | B6: 措施费 | C6: =装修工程清单!G399 -> 51350
A7: 四 | B7: 消防工程 | C7: =消防工程!G52 -> 131189
A8: 五 | B8: 小计：一+二+三+四 | C8: =C4+C5+C6+C7 -> 1847216.8
A9: 六 | B9: 管理费3% | C9: =装修工程清单!G406+消防工程!G53 -> 55416.504
A10: 七 | B10: 税金9% | C10: =装修工程清单!G407+消防工程!G54 -> 171237
A11: 八 | B11: 合计=五+六+七 | C11: =C8+C9+C10 -> 2073870.3

Sheet 装修工程清单
A1: 分部分项工程量清单计价表 | Q1: 1.12 | S1: =$Q$1 -> 1.12 | T1: =$Q$1 -> 1.12 | U1: =$Q$1 -> 1.12
A2: 工程名称：广东省深圳市龙华区龙华数字智造中心(建泰城市更新项目)项目1栋 11层 01号/装修施工工程-装修工程
A3: 序号 | B3: 项目名称 | C3: 项目特征 | D3: 单位 | E3: 工程量 | F3: 综合单价（不含税） | G3: 合价 | H3: 备注 | I3: 综合单价（不含税） | J3: 主材费 | K3: 主材损耗率 | L3: 人工费 | M3: 辅材费 | N3: 机械费 | O3: 合计 | P3: 成本单价 | Q3: 主材费 | R3: 主材损耗率 | S3: 人工费 | T3: 辅材费 | U3: 机械费
A4: 一 | B4: 装饰工程 | G4: =SUBTOTAL(9,G5:G360) -> 1241384.2
A5: （一） | B5: 隔墙工程
A6: 1 | B6: 轻钢龙骨隔墙（100mm） | C6: 单层双面轻钢龙骨隔墙 1、墙厚100mm; 2、75mm轻钢龙骨； 3、50mm厚，48kg/m3的吸音棉； 4、12mm厚石膏板 | D6: ㎡ | E6: =4.33*(2.9+2.4+0.5+2.2+1.4+0.4+0.4+2.1+0.3+3+0.9+0.4+2+1.6+0.4+6.05+3.35+0.45+4.1+2.8+0.7+2.25+0.6+4.9+4.65+2.15+0.3+2.4+3.1+8.85+5.05*2+1.5+3.6+4.9+2.15+5.05+0.5+0.2+0.1+4.05+7.5+0.5+1.15+1.5+0.6+1.95*2+2.2+6.85+2.2+4.95*3+0.3+4.77+1.93+0.3+9.1+0.7*2+5.74+9.17*2)-1*2.8-1.4*2.8-1.45*2.8+5.7*0.75+(4.33-2.8)*(1+1.4+1*11+1.6) -> 808.0989 | F6: =I6 -> 146.5632 | G6: =F6*E6 -> 118437.56 | I6: =J6+J6*K6+L6+M6+N6 -> 146.5632 | J6: =Q6*$Q$1 -> 23.52 | K6: =R6 -> 0.01 | L6: =S6*$S$1 -> 78.4 | M6: =T6*$T$1 -> 42.728 | N6: =U6*$U$1 -> 1.68 | O6: =E6*I6 -> 118437.56 | P6: =Q6*(1+R6)+S6+T6+U6 -> 130.86 | Q6: 21 | R6: 0.01 | S6: 70 | T6: =26.5+11.65 -> 38.15 | U6: 1.5
A7: 2 | B7: 轻钢龙骨隔墙（100mm弧形） | C7: 单层双面轻钢龙骨隔墙 1、墙厚100mm; 2、75mm轻钢龙骨； 3、50mm厚，48kg/m3的吸音棉； 4、12mm厚石膏板 | D7: ㎡ | E7: =4.33*(1.2+0.7+0.63+7.28) -> 42.4773 | F7: =I7 -> 169.4336 | G7: =F7*E7 -> 7197.0819 | I7: =J7+J7*K7+L7+M7+N7 -> 169.4336 | J7: =Q7*$Q$1 -> 23.52 | K7: =R7 -> 0.03 | L7: =S7*$S$1 -> 100.8 | M7: =T7*$T$1 -> 42.728 | N7: =U7*$U$1 -> 1.68 | O7: =E7*I7 -> 7197.0819 | P7: =Q7*(1+R7)+S7+T7+U7 -> 151.28 | Q7: 21 | R7: 0.03 | S7: 90 | T7: =26.5+11.65 -> 38.15 | U7: 1.5
A8: 3 | B8: 轻钢龙骨隔墙（200mm） | C8: 单层双面轻钢龙骨隔墙 1、墙厚200mm; 2、75mm轻钢龙骨； 3、50mm厚，48kg/m3的吸音棉； 4、12mm厚石膏板 | D8: ㎡ | E8: =4.33*(0.8+0.7+5.15+5.8+2.75+1.45+3.9+2.4+1+1.55+1.49+1.3+4+3.25+0.3+5.6+5.8+2.75+1.45+12.1-0.9+2.37+1.3)+(4.33-2.8)*(2+1+1+2) -> 296.3023 | F8: =I8 -> 199.7632 | G8: =F8*E8 -> 59190.296 | I8: =J8+J8*K8+L8+M8+N8 -> 199.7632 | J8: =Q8*$Q$1 -> 23.52 | K8: =R8 -> 0.01 | L8: =S8*$S$1 -> 101.92 | M8: =T8*$T$1 -> 72.408 | N8: =U8*$U$1 -> 1.68 | O8: =E8*I8 -> 59190.296 | P8: =Q8*(1+R8)+S8+T8+U8 -> 178.36 | Q8: 21 | R8: 0.01 | S8: =70*1.3 -> 91 | T8: =26.5*2+11.65 -> 64.65 | U8: 1.5
A9: 4 | B9: 轻钢龙骨隔墙（200mm弧形） | C9: 单层双面轻钢龙骨隔墙 1、墙厚200mm; 2、75mm轻钢龙骨； 3、50mm厚，48kg/m3的吸音棉； 4、12mm厚石膏板 | D9: ㎡ | E9: =4.33*(0.79+2.86+1.4+6.5+0.5+3.93+1.26) -> 74.6492 | F9: =I9 -> 221.5136 | G9: =F9*E9 -> 16535.813 | I9: =J9+J9*K9+L9+M9+N9 -> 221.5136 | J9: =Q9*$Q$1 -> 23.52 | K9: =R9 -> 0.03 | L9: =S9*$S$1 -> 123.2 | M9: =T9*$T$1 -> 72.408 | N9: =U9*$U$1 -> 1.68 | O9: =E9*I9 -> 16535.813 | P9: =Q9*(1+R9)+S9+T9+U9 -> 197.78 | Q9: 21 | R9: 0.03 | S9: 110 | T9: =26.5*2+11.65 -> 64.65 | U9: 1.5
A10: 5 | B10: GL-02 钢化普通玻璃中空隔断 | C10: 1、GL-01 6+6mm钢化普通玻璃; 2、铝框包边 | D10: ㎡ | E10: =2.8*(3.3+4.7+5.45+2.2+4.15+3.3+3.4+13.3+4.05+7.8) -> 144.62 | F10: =I10 -> 407.512 | G10: =F10*E10 -> 58934.385 | I10: =J10+J10*K10+L10+M10+N10 -> 407.512 | J10: =Q10*$Q$1 -> 375.2 | K10: =R10 -> 0.01 | L10: =S10*$S$1 -> 16.8 | M10: =T10*$T$1 -> 11.76 | N10: =U10*$U$1 -> 0 | O10: =E10*I10 -> 58934.385 | P10: =Q10*(1+R10)+S10+T10+U10 -> 363.85 | Q10: =415-80 -> 335 | R10: 0.01 | S10: 15 | T10: 10.5
A11: 6 | B11: GL-02 钢化普通玻璃中空隔断（弧形） | C11: 1、GL-01 6+6mm钢化普通玻璃; 2、铝框包边 | D11: ㎡ | E11: =2.8*(1.57*3) -> 13.188 | F11: =I11 -> 786.464 | G11: =F11*E11 -> 10371.887 | I11: =J11+J11*K11+L11+M11+N11 -> 786.464 | J11: =Q11*$Q$1 -> 750.4 | K11: =R11 -> 0.01 | L11: =S11*$S$1 -> 16.8 | M11: =T11*$T$1 -> 11.76 | N11: =U11*$U$1 -> 0 | O11: =E11*I11 -> 10371.887 | P11: =Q11*(1+R11)+S11+T11+U11 -> 702.2 | Q11: =750-80 -> 670 | R11: 0.01 | S11: 15 | T11: 10.5
A12: 7 | B12: 玻璃隔断上方封板 | C12: 双层双面钢结构龙骨隔墙 1、墙厚100mm; 2、钢结构龙骨； 3、50mm厚，48kg/m3的吸音棉； 4、12mm厚石膏板 | D12: ㎡ | E12: =(4.33-2.8)*(3.3+4.7+5.45+2.2+4.15+3.3+3.4+13.3+4.05+7.8+1.57*3) -> 86.2308 | F12: =I12 -> 144.8832 | G12: =F12*E12 -> 12493.394 | I12: =J12+J12*K12+L12+M12+N12 -> 144.8832 | J12: =Q12*$Q$1 -> 23.52 | K12: =R12 -> 0.01 | L12: =S12*$S$1 -> 78.4 | M12: =T12*$T$1 -> 42.728 | N12: =U12*$U$1 -> 0 | O12: =E12*I12 -> 12493.394 | P12: =Q12*(1+R12)+S12+T12+U12 -> 129.36 | Q12: 21 | R12: 0.01 | S12: 70 | T12: =26.5+11.65 -> 38.15
A13: （二） | B13: 财务室、财务经理室
B14: 地面工程
A15: 1 | B15: 浅色水磨石砖 | C15: 1、CT-01浅色水磨石砖 2、瓷砖规格：800*800 3、水泥砂浆结合层，厚度包干，后期不因厚度调整价格； 4、白水泥擦缝 | D15: ㎡ | E15: 36.32 | F15: =I15 -> 148.568 | G15: =F15*E15 -> 5395.9898 | I15: =J15+J15*K15+L15+M15+N15 -> 148.568 | J15: =Q15*$Q$1 -> 72.8 | K15: =R15 -> 0.01 | L15: =S15*$S$1 -> 61.6 | M15: =T15*$T$1 -> 13.44 | N15: =U15*$U$1 -> 0 | O15: =E15*I15 -> 5395.9898 | P15: =Q15*(1+R15)+S15+T15+U15 -> 132.65 | Q15: 65 | R15: 0.01 | S15: 55 | T15: 12 | U15: 0
A16: 2 | B16: 水泥砂浆找平 | C16: 1、水泥砂浆找平 2、厚度≤100mm | D16: ㎡ | E16: =$E$15 -> 36.32 | F16: =I16 -> 89.6 | G16: =F16*E16 -> 3254.272 | I16: =J16+J16*K16+L16+M16+N16 -> 89.6 | J16: =Q16*$Q$1 -> 0 | K16: =R16 -> 0.025 | L16: =S16*$S$1 -> 42.56 | M16: =T16*$T$1 -> 47.04 | N16: =U16*$U$1 -> 0 | O16: =E16*I16 -> 3254.272 | P16: =Q16*(1+R16)+S16+T16+U16 -> 80 | Q16: 0 | R16: 0.025 | S16: =38 -> 38 | T16: 42 | U16: 0
B17: 天棚工程
A18: 3 | B18: 石膏板天花吊顶 | C18: 1、吊顶形式：平级+跌级吊顶 2、基层：轻钢龙骨+双层9.5mm厚石膏板 | D18: ㎡ | E18: =15.22+18.41 -> 33.63 | F18: =I18 -> 121.772 | G18: =F18*E18 -> 4095.1924 | I18: =J18+J18*K18+L18+M18+N18 -> 121.772 | J18: =Q18*$Q$1 -> 25.2 | K18: =R18 -> 0.01 | L18: =S18*$S$1 -> 67.2 | M18: =T18*$T$1 -> 29.12 | N18: =U18*$U$1 -> 0 | O18: =E18*I18 -> 4095.1924 | P18: =Q18*(1+R18)+S18+T18+U18 -> 108.725 | Q18: 22.5 | R18: 0.01 | S18: 60 | T18: 26
A19: 4 | B19: 天花板缝贴纸带刮平整 | C19: 1、螺丝钉刷防锈漆 2、缝贴纸带刮平整 | D19: ㎡ | E19: =$E$21 -> 46.7115 | F19: =I19 -> 9.52 | G19: =F19*E19 -> 444.69348 | I19: =J19+J19*K19+L19+M19+N19 -> 9.52 | J19: =Q19*$Q$1 -> 3.92 | K19: =R19 -> 0 | L19: =S19*$S$1 -> 5.6 | M19: =T19*$T$1 -> 0 | N19: =U19*$U$1 -> 0 | O19: =E19*I19 -> 444.69348 | P19: =Q19*(1+R19)+S19+T19+U19 -> 8.5 | Q19: 3.5 | R19: 0 | S19: 5 | T19: 0 | U19: 0
A20: 5 | B20: 天花挂耐水腻子 | C20: 1、耐水腻子2道，含打磨、修补 | D20: ㎡ | E20: =$E$21 -> 46.7115 | F20: =I20 -> 19.04 | G20: =F20*E20 -> 889.38696 | I20: =J20+J20*K20+L20+M20+N20 -> 19.04 | J20: =Q20*$Q$1 -> 3.92 | K20: =R20 -> 0 | L20: =S20*$S$1 -> 15.12 | M20: =T20*$T$1 -> 0 | N20: =U20*$U$1 -> 0 | O20: =E20*I20 -> 889.38696 | P20: =Q20*(1+R20)+S20+T20+U20 -> 17 | Q20: 3.5 | R20: 0 | S20: 13.5 | T20: 0 | U20: 0
A21: 6 | B21: 天棚乳胶漆 | C21: 1、面层：PT-01白色无机涂料一底二面 | D21: ㎡ | E21: =E18+E22*0.85 -> 46.7115 | F21: =I21 -> 14.56 | G21: =F21*E21 -> 680.11944 | I21: =J21+J21*K21+L21+M21+N21 -> 14.56 | J21: =Q21*$Q$1 -> 3.36 | K21: =R21 -> 0 | L21: =S21*$S$1 -> 11.2 | M21: =T21*$T$1 -> 0 | N21: =U21*$U$1 -> 0 | O21: =E21*I21 -> 680.11944 | P21: =Q21*(1+R21)+S21+T21+U21 -> 13 | Q21: 3 | R21: 0 | S21: 10 | T21: 0 | U21: 0
A22: 7 | B22: 窗帘盒 | C22: 1、规格尺寸：200*200*650mm 2、基层：钢结构龙骨+阻燃板基层 3、面层：9.5mm厚石膏板 | D22: m | E22: =2.6+7.84+4.95 -> 15.39 | F22: =I22 -> 195.076 | G22: =F22*E22 -> 3002.2196 | I22: =J22+J22*K22+L22+M22+N22 -> 195.076 | J22: =Q22*$Q$1 -> 98.196 | K22: =R22 -> 0 | L22: =S22*$S$1 -> 95.2 | M22: =T22*$T$1 -> 1.68 | N22: =U22*$U$1 -> 0 | O22: =E22*I22 -> 3002.2196 | P22: =Q22*(1+R22)+S22+T22+U22 -> 174.175 | Q22: 87.675 | S22: 85 | T22: 1.5
A23: 8 | B23: 窗帘 | C23: 1、成品窗帘 | D23: ㎡ | E23: =E22*2.05 -> 31.5495 | F23: =I23 -> 84 | G23: =F23*E23 -> 2650.158 | I23: =J23+J23*K23+L23+M23+N23 -> 84 | J23: =Q23*$Q$1 -> 76.16 | K23: =R23 -> 0 | L23: =S23*$S$1 -> 5.6 | M23: =T23*$T$1 -> 1.68 | N23: =U23*$U$1 -> 0.56 | O23: =E23*I23 -> 2650.158 | P23: =Q23*(1+R23)+S23+T23+U23 -> 75 | Q23: 68 | S23: 5 | T23: 1.5 | U23: 0.5
A24: 9 | B24: 空调风口 | C24: 1、成品风口 | D24: ㎡ | E24: =0.3+0.44+0.24*2 -> 1.22 | F24: =I24 -> 617.98295 | G24: =F24*E24 -> 753.9392 | I24: =J24+J24*K24+L24+M24+N24 -> 617.98295 | J24: =Q24*$Q$1 -> 476 | K24: =R24 -> 0 | L24: =S24*$S$1 -> 67.2 | M24: =T24*$T$1 -> 74.222951 | N24: =U24*$U$1 -> 0.56 | O24: =E24*I24 -> 753.9392 | P24: =Q24*(1+R24)+S24+T24+U24 -> 551.77049 | Q24: 425 | S24: 60 | T24: =5.5*(4.3+4.8+2.8*2)/1.22 -> 66.270492 | U24: 0.5
B25: 墙面工程
A26: 10 | B26: 墙面缝贴纸带刮平整 | C26: 1、螺丝钉刷防锈漆 2、缝贴纸带刮平整 | D26: ㎡ | E26: =$E$28 -> 56.105 | F26: =I26 -> 9.52 | G26: =F26*E26 -> 534.1196 | I26: =J26+J26*K26+L26+M26+N26 -> 9.52 | J26: =Q26*$Q$1 -> 3.92 | K26: =R26 -> 0 | L26: =S26*$S$1 -> 5.6 | M26: =T26*$T$1 -> 0 | N26: =U26*$U$1 -> 0 | O26: =E26*I26 -> 534.1196 | P26: =Q26*(1+R26)+S26+T26+U26 -> 8.5 | Q26: 3.5 | R26: =R19 -> 0 | S26: =S19 -> 5 | T26: =T19 -> 0 | U26: 0
A27: 11 | B27: 墙面挂耐水腻子 | C27: 耐水腻子2道，含打磨、修补 | D27: ㎡ | E27: =$E$28 -> 56.105 | F27: =I27 -> 19.04 | G27: =F27*E27 -> 1068.2392 | I27: =J27+J27*K27+L27+M27+N27 -> 19.04 | J27: =Q27*$Q$1 -> 3.92 | K27: =R27 -> 0 | L27: =S27*$S$1 -> 15.12 | M27: =T27*$T$1 -> 0 | N27: =U27*$U$1 -> 0 | O27: =E27*I27 -> 1068.2392 | P27: =Q27*(1+R27)+S27+T27+U27 -> 17 | Q27: 3.5 | R27: =R20 -> 0 | S27: =S20 -> 13.5 | T27: =T20 -> 0 | U27: 0
A28: 12 | B28: 墙面乳胶漆PT-01 | C28: 1、面层：PT-01白色无机涂料一底二面 | D28: ㎡ | E28: =(2.8-0.02)*(2.06+5.2+9.05-1)+(2.6+7.84+4.95)*0.88 -> 56.105 | F28: =I28 -> 14.56 | G28: =F28*E28 -> 816.8888 | I28: =J28+J28*K28+L28+M28+N28 -> 14.56 | J28: =Q28*$Q$1 -> 3.36 | K28: =R28 -> 0 | L28: =S28*$S$1 -> 11.2 | M28: =T28*$T$1 -> 0 | N28: =U28*$U$1 -> 0 | O28: =E28*I28 -> 816.8888 | P28: =Q28*(1+R28)+S28+T28+U28 -> 13 | Q28: 3 | R28: =R21 -> 0 | S28: =S21 -> 10 | T28: =T21 -> 0 | U28: 0
A29: 13 | B29: AL-03 黑色型材踢脚线 | C29: 1、规格尺寸：20mm高 2、面层：MT-01 黑色型材踢脚线 3、基层：轻钢龙骨+12mm厚阻燃夹板 | D29: m | E29: =2.06+5.2+9.05-1+2.6+7.84+4.95 -> 30.7 | F29: =I29 -> 32.34224 | G29: =F29*E29 -> 992.90677 | I29: =J29+J29*K29+L29+M29+N29 -> 32.34224 | J29: =Q29*$Q$1 -> 17.808 | K29: =R29 -> 0.03 | L29: =S29*$S$1 -> 13.44 | M29: =T29*$T$1 -> 0.56 | N29: =U29*$U$1 -> 0 | O29: =E29*I29 -> 992.90677 | P29: =Q29*(1+R29)+S29+T29+U29 -> 28.877 | Q29: 15.9 | R29: 0.03 | S29: 12 | T29: 0.5
A30: 14 | B30: 石材窗台板-宽度50+75mm | C30: 1.面层石材铺贴，同色填缝； 2.石材见光侧面加厚，阳角边磨边抛光/阳角处2*2倒边磨边抛光 3.砂浆或粘贴剂粘贴层结合层； | D30: m | E30: =2.6+7.84+4.95 -> 15.39 | F30: =I30 -> 84.28 | G30: =F30*E30 -> 1297.0692 | I30: =J30+J30*K30+L30+M30+N30 -> 84.28 | J30: =Q30*$Q$1 -> 62.44 | K30: =R30 -> 0 | L30: =S30*$S$1 -> 20.16 | M30: =T30*$T$1 -> 1.68 | N30: =U30*$U$1 -> 0 | O30: =E30*I30 -> 1297.0692 | P30: =Q30*(1+R30)+S30+T30+U30 -> 75.25 | Q30: 55.75 | R30: 0 | S30: 18 | T30: 1.5 | U30: 0
B31: 柜子、门窗工程
A32: 15 | B32: 隔断玻璃单开门 | C32: 1、隔断玻璃单开门安装 2、门洞尺寸：1000*2800mm 3、包含门锁、拉手、合页、企口胶条、门吸等五金 | D32: 樘 | E32: 1 | F32: =I32 -> 1299.2 | G32: =F32*E32 -> 1299.2 | I32: =J32+J32*K32+L32+M32+N32 -> 1299.2 | J32: =Q32*$Q$1 -> 1097.6 | K32: =R32 -> 0 | L32: =S32*$S$1 -> 201.6 | M32: =T32*$T$1 -> 0 | N32: =U32*$U$1 -> 0 | O32: =E32*I32 -> 1299.2 | P32: =Q32*(1+R32)+S32+T32+U32 -> 1160 | Q32: 980 | S32: 180 | V32: =(325+125*2.8+75*2+150)/2.8 -> 348.21429
A33: 16 | B33: 房间门-免漆板单开门 | C33: 1、免漆板单开门安装 2、门洞尺寸：1000*2800mm 3、包含门锁、拉手、合页、企口胶条、门吸等五金 | D33: 樘 | E33: 1 | F33: =I33 -> 1926.4 | G33: =F33*E33 -> 1926.4 | I33: =J33+J33*K33+L33+M33+N33 -> 1926.4 | J33: =Q33*$Q$1 -> 1724.8 | K33: =R33 -> 0 | L33: =S33*$S$1 -> 201.6 | M33: =T33*$T$1 -> 0 | N33: =U33*$U$1 -> 0 | O33: =E33*I33 -> 1926.4 | P33: =Q33*(1+R33)+S33+T33+U33 -> 1720 | Q33: 1540 | S33: 180
A34: （三） | B34: 总经理办公室
B35: 地面工程
A36: 1 | B36: 强化地板 | C36: 1、强化地板WA-01 2、规格尺寸： 3、防潮垫层 4、水泥砂浆找平 | D36: ㎡ | E36: 75.88 | F36: =I36 -> 180.46 | G36: =F36*E36 -> 13693.305 | I36: =J36+J36*K36+L36+M36+N36 -> 180.46 | J36: =Q36*$Q$1 -> 140 | K36: =R36 -> 0.025 | L36: =S36*$S$1 -> 31.36 | M36: =T36*$T$1 -> 5.6 | N36: =U36*$U$1 -> 0 | O36: =E36*I36 -> 13693.305 | P36: =Q36*(1+R36)+S36+T36+U36 -> 161.125 | Q36: 125 | R36: 0.025 | S36: 28 | T36: 5 | U36: 0
A37: 2 | B37: 水泥砂浆找平 | C37: 1、水泥砂浆找平 2、厚度≤100mm | D37: ㎡ | E37: =E36 -> 75.88 | F37: =$F$16 -> 89.6 | G37: =F37*E37 -> 6798.848 | I37: =J37+J37*K37+L37+M37+N37 -> 0 | J37: =Q37*$Q$1 -> 0 | K37: =R37 -> 0 | L37: =S37*$S$1 -> 0 | M37: =T37*$T$1 -> 0 | N37: =U37*$U$1 -> 0 | O37: =E37*I37 -> 0
B38: 天棚工程
A39: 3 | B39: 石膏板天花吊顶 | C39: 1、吊顶形式：平级+跌级吊顶 2、基层：轻钢龙骨+双层9.5mm厚石膏板 | D39: ㎡ | E39: 75.88 | F39: =$F$18 -> 121.772 | G39: =F39*E39 -> 9240.0594 | I39: =J39+J39*K39+L39+M39+N39 -> 0 | J39: =Q39*$Q$1 -> 0 | K39: =R39 -> 0 | L39: =S39*$S$1 -> 0 | M39: =T39*$T$1 -> 0 | N39: =U39*$U$1 -> 0 | O39: =E39*I39 -> 0
A40: 4 | B40: 天花板缝贴纸带刮平整 | C40: 1、螺丝钉刷防锈漆 2、缝贴纸带刮平整 | D40: ㎡ | E40: =E42 -> 89.368 | F40: =$F$19 -> 9.52 | G40: =F40*E40 -> 850.78336 | I40: =J40+J40*K40+L40+M40+N40 -> 0 | J40: =Q40*$Q$1 -> 0 | K40: =R40 -> 0 | L40: =S40*$S$1 -> 0 | M40: =T40*$T$1 -> 0 | N40: =U40*$U$1 -> 0 | O40: =E40*I40 -> 0
...

Sheet 消防工程
A1: 分部分项工程量清单计价表
A2: 项目名称：广东省深圳市龙华区龙华数字智造中心(建泰城市更新项目)项目1栋 11层 01号/装修施工工程-消防工程
A3: 序号 | B3: 项目名称 | C3: 项目特征 | D3: 单位 | E3: 工程量 | F3: 综合单价（不含税） | G3: 合计 | H3: 备注
A4: 一 | B4: 喷淋消火栓系统改造
A5: 1 | B5: 水喷淋(雾)喷头 | C5: 1.名称:吊顶型洒水喷头新增 2.材质、型号、规格:DN25(K=80 喷头动作温度 68℃) 3.综合考虑超高与非超高部分 4.需满足图纸、行业规范及招标文件要求 | D5: 个 | E5: 192 | F5: 155 | G5: =E5*F5 -> 29760
A6: 2 | B6: 水喷淋(雾)喷头 | C6: 1.名称:直立型洒水喷头移位 2.材质、型号、规格:DN25(K=80 喷头动作温度 68℃) 3.综合考虑超高与非超高部分 4.需满足图纸、行业规范及招标文件要求 | D6: 个 | E6: 25 | F6: 130 | G6: =E6*F6 -> 3250
A7: 3 | B7: 消防箱 | C7: 1.名称:室内单口消火栓 2.规格尺寸:箱800X650X240 3.其他参数:箱内设DN65消火栓, DN65麻质衬胶水龙带,长25米,水枪 喷嘴φ19,以及指示灯一个.带消防软管卷盘 4.综合考虑超高与非超高部分 5.需满足图纸、行业规范及招标文件要求 | D7: 个 | E7: 6 | F7: 1500 | G7: =E7*F7 -> 9000
A8: 4 | B8: 水喷淋钢管DN25新增及拆除 | C8: 1.名称:内外热镀锌钢管 2.规格及型号:DN25(含管件制作、安装) 3.连接形式:螺纹连接 4.压力试验及设计要求:管道冲洗、消毒，管道水压试验 5.综合考虑超高与非超高部分 6.其他:满足设计图纸、相关规范、招标文件及其技术要求 | D8: 米 | E8: 230 | F8: 18 | G8: =E8*F8 -> 4140
A9: 5 | B9: 水喷淋钢管DN65新增及拆除 | C9: 1.名称:内外热镀锌钢管 2.规格及型号:DN32(含管件制作、安装) 3.连接形式:螺纹连接 4.压力试验及设计要求:管道冲洗、消毒，管道水压试验 5.综合考虑超高与非超高部分 6.其他:满足设计图纸、相关规范、招标文件及其技术要求 | D9: 米 | E9: 48 | F9: 35 | G9: =E9*F9 -> 1680
A10: 6 | B10: 水喷淋钢管DN150新增 | C10: 1.名称:内外热镀锌钢管 2.规格及型号:DN25/32/65(含管件制作、安装) 3.连接形式:螺纹连接 4.压力试验及设计要求:管道冲洗、消毒，管道水压试验 5.综合考虑超高与非超高部分 6.其他:满足设计图纸、相关规范、招标文件及其技术要求 | D10: 米 | E10: 25 | F10: 45 | G10: =E10*F10 -> 1125
A11: 7 | B11: 管道刷漆 | C11: 1.名称:管道刷油 2.刷樟丹二道,红色调和漆二道,且加红色环圈标志,宽度不小于20mm 3.综合考虑超高与非超高部分 4.其他:满足设计图纸、相关规范、招标文件及其技术要求 | D11: 平方 | E11: 70 | F11: 13 | G11: =E11*F11 -> 910
A12: 8 | B12: 角铁支架 | C12: 1.名称:管道支架 2含管道支架制作及安装,支吊架外表经除锈后,刷樟丹二道,银灰漆二道 3.综合考虑超高与非超高部分 4.其他:满足设计图纸、相关规范、招标文件及其技术要求 | D12: KG | E12: 60 | F12: 13 | G12: =E12*F12 -> 780
A13: 9 | B13: 水灭火控制装置调试 | C13: 1.名称:自动喷水灭火系统调试 2.名称:消火栓系统调试 3.其他:满足设计图纸、相关规范、招标文件及其技术要求 | D13: 点 | E13: 6 | F13: 100 | G13: =E13*F13 -> 600
B14: 小计 | G14: =SUM(G5:G13) -> 51245
A15: 二 | B15: 自动报警系统改造
A16: 1 | B16: 智能光电烟感探测器 | C16: 1.名称:智能烟感探测器新增 2.规格及型号:原有系统设备型号 3.综合考虑超高与非超高部分 4.其他:满足设计图纸、相关规范、招标文件及其技术要求 | D16: 个 | E16: 60 | F16: 120 | G16: =F16*E16 -> 7200
A17: 2 | B17: 智能光电烟感探测器 | C17: 1.名称:智能烟感探测器（原设备保护性拆除，移位安装） 2.规格及型号:原有系统设备型号 3.综合考虑超高与非超高部分 4.其他:满足设计图纸、相关规范、招标文件及其技术要求 | D17: 个 | E17: 20 | F17: 80 | G17: =F17*E17 -> 1600
A18: 3 | B18: 智能手动报警按钮 | C18: 1.名称:智能手动报警按钮 2.规格及型号:原有系统设备型号 3.综合考虑超高与非超高部分 4.其他:满足设计图纸、相关规范、招标文件及其技术要求 | D18: 个 | E18: 9 | F18: 110 | G18: =F18*E18 -> 990
A19: 4 | B19: 移位声光报警器 | C19: 1.名称:智能声光警报器 2.规格及型号:原有系统设备型号 3.综合考虑超高与非超高部分 4.其他:满足设计图纸、相关规范、招标文件及其技术要求 | D19: 个 | E19: 9 | F19: 110 | G19: =F19*E19 -> 990
A20: 5 | B20: 消火栓启泵按钮 | C20: 1.名称:消火栓按钮 2.规格及型号:原有系统设备型号 3.综合考虑超高与非超高部分 4.其他:满足设计图纸、相关规范、招标文件及其技术要求 | D20: 个 | E20: 6 | F20: 110 | G20: =F20*E20 -> 660
A21: 6 | B21: 消防广播 | C21: 1.名称:消防广播 2.规格及型号:原有系统设备型号 3.综合考虑超高与非超高部分 4.其他:满足设计图纸、相关规范、招标文件及其技术要求 | D21: 个 | E21: 6 | F21: 110 | G21: =F21*E21 -> 660
A22: 7 | B22: 新增短路隔离器 | C22: 1.名称:隔离模块新增 2.规格及型号:原设备型号 3.综合考虑超高与非超高部分 4.其他:满足设计图纸、相关规范、招标文件及其技术要求 | D22: 个 | E22: 4 | F22: 130 | G22: =F22*E22 -> 520
A23: 8 | B23: 配线 | C23: 1.名称:信号线 2.规格及型号:ZR-RVS 2*1.5 3.综合考虑超高与非超高部分 4.其他:满足设计图纸、相关规范、招标文件及其技术要求 | D23: 米 | E23: 700 | F23: 5 | G23: =F23*E23 -> 3500
A24: 9 | B24: 配线 | C24: 1.名称:电源线 2.规格及型号:ZR-BVR 2.5 3.综合考虑超高与非超高部分 4.其他:满足设计图纸、相关规范、招标文件及其技术要求 | D24: 米 | E24: 400 | F24: 5 | G24: =F24*E24 -> 2000
A25: 10 | B25: 配线 | C25: 1.名称:电话线 2.规格及型号:BVVP2*1.0 3.综合考虑超高与非超高部分 4.其他:满足设计图纸、相关规范、招标文件及其技术要求 | D25: 米 | E25: 200 | F25: 4 | G25: =F25*E25 -> 800
A26: 11 | B26: 配管 | C26: 1.名称:电气配管 2.规格:JDG20 3.敷设方式:综合考虑 4.综合考虑超高与非超高部分 5.其他:满足设计图纸、相关规范、招标文件及其技术要求 | D26: 米 | E26: 200 | F26: 4.5 | G26: =F26*E26 -> 900
A27: 12 | B27: 配管 | C27: 1.名称:金属软管 2.规格:DN15 3.敷设方式:综合考虑 4.综合考虑超高与非超高部分 5.其他:满足设计图纸、相关规范、招标文件及其技术要求 | D27: 米 | E27: 200 | F27: 5.5 | G27: =F27*E27 -> 1100
A28: 13 | B28: 自动报警系统调试 | C28: 1.名称:火灾自动报警系统调试（1000点以内） 2.其他:满足设计图纸、相关规范、招标文件及其技术要求 | D28: 系统 | E28: 1 | F28: 1000 | G28: =F28*E28 -> 1000
B29: 小计 | G29: =SUM(G16:G28) -> 21920
A30: 三 | B30: 防排烟系统改造
A31: 1 | B31: 通风管道绝热 | C31: 1.名称:风管防火包裹，不燃A级离心玻璃棉绝 2.形状:矩形 3.规格:0.5小时 4.板材厚度:50mm，含辅材 5.需满足图纸、行业规范及招标文件要求 6.综合考虑超高与非超高部分 7.其他:满足设计图纸、相关规范、招标文件及其技术要求 | D31: M² | E31: 170 | F31: 58 | G31: =F31*E31 -> 9860
A32: 2 | B32: 碳钢通风管道 | C32: 1.名称：镀锌钢板风管拆除。拆除后的废品由本公司处理，其费用用以抵充垃圾处理费。 | D32: M² | E32: 30 | F32: 33 | G32: =F32*E32 -> 990
A33: 3 | B33: 碳钢通风管道 | C33: 1.名称:镀锌钢板风管 2.形状:矩形 3.规格:1500<b≤2000 4.板材厚度:1.50mm 5.管件.法兰等附件及支架设计要求:风管管件、法兰、加固框、吊托支架制作安装及除锈刷油 6.综合考虑超高与非超高部分 7.其他:满足设计图纸、相关规范、招标文件及其技术要求 | D33: M² | E33: 170 | F33: 130 | G33: =F33*E33 -> 22100
A34: 4 | B34: 铝及铝合金风口 | C34: 1.名称:单层百叶风口，带调节阀 2.规格:600*600 3.综合考虑超高与非超高部分 4.其他:满足设计图纸、相关规范、招标文件及其技术要求 | D34: 个 | E34: 12 | F34: 162 | G34: =F34*E34 -> 1944
A35: 5 | B35: 控制模块 | C35: 1.名称:输入输出模块 2.规格及型号:原有系统设备型号 3.综合考虑超高与非超高部分 4.其他:满足设计图纸、相关规范、招标文件及其技术要求 | D35: 套 | E35: 3 | F35: 140 | G35: =F35*E35 -> 420
A36: 6 | B36: 执行机构 | C36: 1.名称:排烟阀执行机构 2.规格及型号:原有系统设备型号 3.综合考虑超高与非超高部分 4.其他:满足设计图纸、相关规范、招标文件及其技术要求 | D36: 个 | E36: 6 | F36: 520 | G36: =F36*E36 -> 3120
A37: 7 | B37: 排烟防火阀 | C37: 1.名称:280℃排烟防火阀 2.型号:2000*320 3.综合考虑超高与非超高部分 4.其他:满足设计图纸、相关规范、招标文件及其技术要求 | D37: 个 | E37: 6 | F37: 500 | G37: =F37*E37 -> 3000
A38: 8 | B38: 通风工程检测、调试 | C38: (1)名称:排烟工程检测、调试 (2)包括风管漏光试验、漏风试验 | D38: 系统 | E38: 1 | F38: 1000 | G38: =F38*E38 -> 1000
B39: 小计 | G39: =SUM(G31:G38) -> 42434
A40: 四 | B40: 应急疏散系统改造
...

Sheet 材料设备参考品牌
A1: 材料设备参考品牌
A2: 序号 | B2: 专业 | C2: 材料编号 | D2: 材料名称 | E2: 品牌 | F2: 备注
A3: 一 | B3: 涂料
A4: 1 | B4: 装饰 | C4: PT-01 | D4: 白色无机涂料 | E4: 立邦、多乐士、美巢
A5: 2 | B5: 装饰 | C5: PT-02 | D5: 黑色无机涂料 | E5: 立邦、多乐士、美巢
A6: 3 | B6: 装饰 | C6: PT-03 | D6: 红色无机涂料 | E6: 立邦、多乐士、美巢
A7: 4 | B7: 装饰 | C7: PT-04 | D7: 蓝色无机涂料 | E7: 立邦、多乐士、美巢
A8: 5 | B8: 装饰 | C8: PT-05 | D8: 橙色无机涂料 | E8: 立邦、多乐士、美巢
A9: 6 | B9: 装饰 | C9: PT-06 | D9: 蓝绿色无机涂料 | E9: 立邦、多乐士、美巢
A10: 7 | B10: 装饰 | C10: PT-07 | D10: 绿色无机涂料 | E10: 立邦、多乐士、美巢
A11: 8 | B11: 装饰 | C11: PT-08 | D11: 浅绿色无机涂料 | E11: 立邦、多乐士、美巢
A12: 9 | B12: 装饰 | C12: PT-09 | D12: 紫色无机涂料 | E12: 立邦、多乐士、美巢
A13: 二 | B13: 玻璃
A14: 1 | B14: 装饰 | C14: GL-01 | D14: 白色烤漆玻璃 | E14: 信义、南玻、台玻
A15: 2 | B15: 装饰 | C15: GL-02 | D15: 6+6mm玻璃隔断 | E15: 信义、南玻、台玻
A16: 三 | B16: 金属
A17: 1 | B17: 装饰 | C17: MT-01 | D17: 黑色不锈钢 | E17: 国产优质
A18: 2 | B18: 装饰 | C18: MT-02 | D18: 白色不锈钢 | E18: 国产优质
A19: 3 | B19: 装饰 | C19: AL-01 | D19: 阳极氧化铝板 | E19: 国产优质
A20: 4 | B20: 装饰 | C20: AL-02 | D20: 黑色型材踢脚线 | E20: 国产优质
A21: 四 | B21: 地毯
A22: 1 | B22: 装饰 | C22: CA-01 | D22: 浅色地毯 | E22: 国产优质
A23: 2 | B23: 装饰 | C23: CA-02 | D23: 蓝色地毯 | E23: 国产优质
A24: 五 | B24: 布艺/皮革
A25: 1 | B25: 装饰 | C25: UP-01 | D25: 蓝色软包 | E25: 国产优质
A26: 2 | B26: 装饰 | C26: UP-02 | D26: 浅蓝色软包 | E26: 国产优质
A27: 六 | B27: 石材
A28: 1 | B28: 装饰 | C28: ST-01 | D28: 白色人造石 | E28: 国产优质
A29: 七 | B29: 瓷砖
A30: 1 | B30: 装饰 | C30: CT-01 | D30: 浅色水磨石砖 | E30: 东鹏
A31: 2 | B31: 装饰 | C31: CT-02 | D31: 深色水磨石砖 | E31: 东鹏
A32: 3 | B32: 装饰 | C32: CT-03 | D32: 仿木纹砖 | E32: 东鹏
A33: 4 | B33: 装饰 | C33: CT-04 | D33: 红色定制面包砖 | E33: 东鹏
A34: 八 | B34: 毛毯
A35: 1 | B35: 装饰 | C35: CP-01 | D35: 浅灰色毛毡 | E35: 国产优质
A36: 2 | B36: 装饰 | C36: CP-02 | D36: 红色毛毡 | E36: 国产优质
A37: 3 | B37: 装饰 | C37: CP-03 | D37: 浅红色毛毡 | E37: 国产优质
A38: 4 | B38: 装饰 | C38: CP-04 | D38: 蓝色毛毡 | E38: 国产优质
A39: 5 | B39: 装饰 | C39: CP-05 | D39: 浅蓝色毛毡 | E39: 国产优质
A40: 6 | B40: 装饰 | C40: CP-06 | D40: 绿色毛毡 | E40: 国产优质
...
