Workbook
Name _04房1300_1500浴缸: #REF!
Name _1500×1000浴缸及龙头花洒: #REF!

Sheet 南川一标段
A1: 重庆站房2标装饰装修一标段南川北站一标分包工程招标控制价审核表
A2: 项目名称：中铁建工集团有限公司重庆至黔江铁路站房工程2标项目经理部 | M2: 单位：元 | N2: 成本分析
A3: 序号 | B3: 项目名称 | C3: 项目特征 | D3: 工作内容 | E3: 单位 | F3: 工程量 | G3: 控制价 | I3: 上报金额 | K3: 工程量计算规则 | L3: 费用组成 | M3: 备注 | N3: 主材 | O3: 辅材 | P3: 人工 | Q3: 单价 | R3: 取费
G4: 不含税单价（元） | H4: 不含税合价（元） | I4: 不含税单价（元） | J4: 不含税合价（元） | R4: 1.2
A5: 一 | B5: 南川北站
A6: （一） | B6: 站房区域 | O6: =400*1.6*1.05*0.05 -> 33.6
A7: 1 | B7: 花岗石地面 | C7: 1、铺25厚磨光花岗石板(六面涂刷石材保护剂),同色稀水泥浆擦 2、50厚1:3干硬性水泥粘结层,撒素水泥粉 3、水泥浆一道(内掺建筑胶) 4、嵌缝材料种类：按甲方要求嵌缝、打胶； 5、防护层材料：防护剂六面处理，满足设计和相关规范要求； 6、酸洗、打蜡要求：满足设计和相关规范要求； 7、楼地面伸缩缝、变形缝的处理； 8、其他：该项包含本项工作所有工作内容含垂直运输机械等，未详尽列举特征，详见施工图纸、设计规范、施工方案事项均包含在综合单价中。(石材规格800*800) | D7: 1、基层清理、打磨；2、砂浆的制作、运输、找平、压实；3、面层的铺贴；4、水泥砂浆擦缝；5、局部部位花岗石切割、打磨，未详尽列举的图纸、方案事项均包含在综合单价中；6.该项包含本项工作所有工作内容含垂直运输机械等，未详尽列举特征，详见施工图纸、设计规范、施工方案事项均包含在综合单价中。 | E7: m2 | F7: =3735.87-F8 -> 3695.99 | G7: 85 | H7: =ROUND(F7*G7,2) -> 314159.15 | I7: =R7 -> 118.32 | J7: =F7*I7 -> 437309.54 | K7: 按设计图示尺寸以面积计算 | L7: 1、除甲供材外全费用综合单价； 2、甲供材：石材 | N7: 0 | O7: =400*1.6*1.05*0.05 -> 33.6 | P7: 65 | Q7: =N7+O7+P7 -> 98.6 | R7: =Q7*$R$4 -> 118.32 | T7: 118.32 | U7: =T7-I7 -> 0
A8: 2 | B8: 花岗石梯面 | C8: 1、铺25厚磨光花岗石板(六面涂刷石材保护剂),同色稀水泥浆擦 2、50厚1:3干硬性水泥粘结层,撒素水泥粉 3、水泥浆一道(内掺建筑胶) 4、嵌缝材料种类：按甲方要求嵌缝、打胶，挡水条制作； 5、防护层材料：防护剂六面处理，满足设计和相关规范要求； 6、酸洗、打蜡要求：满足设计和相关规范要求； 7、楼地面伸缩缝、变形缝的处理； 8、其他：该项包含本项工作所有工作内容含垂直运输机械等，未详尽列举特征，详见施工图纸、设计规范、施工方案事项均包含在综合单价中。 (石材规格800*800) | D8: 1、基层清理、打磨；2、砂浆的制作、运输、找平、压实；3、面层的铺贴，挡水条制作；4、水泥砂浆擦缝；5、局部部位花岗石切割、打磨，未详尽列举的图纸、方案事项均包含在综合单价中；6.该项包含本项工作所有工作内容含垂直运输机械等，未详尽列举特征，详见施工图纸、设计规范、施工方案事项均包含在综合单价中。 | E8: m2 | F8: 39.88 | G8: 110 | H8: =ROUND(F8*G8,2) -> 4386.8 | I8: =R8 -> 160.32 | J8: =F8*I8 -> 6393.56 | K8: 按设计图示尺寸以展开面积计算 | L8: 1、除甲供材外全费用综合单价； 2、甲供材：石材 | N8: 0 | O8: =400*1.6*1.05*0.05 -> 33.6 | P8: 100 | Q8: =N8+O8+P8 -> 133.6 | R8: =Q8*$R$4 -> 160.32 | T8: 160.32 | U8: =T8-I8 -> 0
A9: 3 | B9: 地砖地面 | C9: 1、面层：10厚玻化砖(防滑),同色水泥浆擦缝 2、30厚1:3干硬性水泥砂浆,表面撒水泥粉 3、嵌缝材料种类：按甲方要求嵌缝、打胶； 4、防护层材料：满足设计和相关规范要求； 5、酸洗、打蜡要求：满足设计和相关规范要求； 6、楼地面伸缩缝、变形缝的处理； 7、其他：该项包含本项工作所有工作内容含垂直运输机械等，未详尽列举特征，详见施工图纸、设计规范、施工方案事项均包含在综合单价中。 (地砖规格600*600) | D9: 1、基层清理、打磨；2、砂浆的制作、运输、找平、压实；3、面层的铺贴；4、水泥砂浆擦缝；5、局部部位防滑地砖切割、打磨，未详尽列举的图纸、方案事项均包含在综合单价中；6.该项包含本项工作所有工作内容含垂直运输机械等，未详尽列举特征，详见施工图纸、设计规范、施工方案事项均包含在综合单价中。 | E9: m2 | F9: 403.66 | G9: 120 | H9: =ROUND(F9*G9,2) -> 48439.2 | I9: =R9 -> 165.22 | J9: =F9*I9 -> 66692.71 | K9: 按设计图示尺寸以面积计算 | L9: 全费用综合单价 | N9: =主材表!L5 -> 57.52 | O9: =400*1.6*1.05*0.03 -> 20.16 | P9: 60 | Q9: =N9+O9+P9 -> 137.68 | R9: =Q9*$R$4 -> 165.22 | T9: 165.22 | U9: =T9-I9 -> 0
A10: 4 | B10: 防滑地砖地面(防水) | C10: 1、面层：10厚玻化砖(防滑),同色水泥浆擦缝 2、30厚1:3干硬性水泥砂浆,表面撒水泥粉 3、嵌缝材料种类：按甲方要求嵌缝、打胶； 4、防护层材料：满足设计和相关规范要求； 5、酸洗、打蜡要求：满足设计和相关规范要求； 6、楼地面伸缩缝、变形缝的处理； 7、其他：该项包含本项工作所有工作内容含垂直运输机械等，未详尽列举特征，详见施工图纸、设计规范、施工方案事项均包含在综合单价中。 (地砖规格600*600) | D10: 1、基层清理、打磨；2、砂浆的制作、运输、找平、压实；3、面层的铺贴；4、水泥砂浆擦缝；5、局部部位防滑地砖切割、打磨，未详尽列举的图纸、方案事项均包含在综合单价中 | E10: m2 | F10: 619.6 | G10: 120 | H10: =ROUND(F10*G10,2) -> 74352 | I10: =R10 -> 165.22 | J10: =F10*I10 -> 102370.31 | K10: 按设计图示尺寸以面积计算 | L10: 全费用综合单价 | N10: =主材表!$L$6 -> 57.52 | O10: =400*1.6*1.05*0.03 -> 20.16 | P10: =$P$9 -> 60 | Q10: =N10+O10+P10 -> 137.68 | R10: =Q10*$R$4 -> 165.22 | T10: 165.22 | U10: =T10-I10 -> 0
A11: 5 | B11: 地砖梯面 | C11: 1、面层：10厚玻化砖(防滑),同色水泥浆擦缝 2、30厚1:3干硬性水泥砂浆,表面撒水泥粉 3、嵌缝材料种类：按甲方要求嵌缝、打胶； 4、防护层材料：满足设计和相关规范要求； 5、酸洗、打蜡要求：满足设计和相关规范要求； 6、楼地面伸缩缝、变形缝的处理； 7、其他：该项包含本项工作所有工作内容含垂直运输机械等，未详尽列举特征，详见施工图纸、设计规范、施工方案事项均包含在综合单价中。 (地砖规格600*600) | D11: 1、基层清理、打磨；2、砂浆的制作、运输、找平、压实；3、面层的铺贴，挡水条制作；4、水泥砂浆擦缝；5、局部部位防滑地砖切割、打磨，未详尽列举的图纸、方案事项均包含在综合单价中；6.该项包含本项工作所有工作内容含垂直运输机械等，未详尽列举特征，详见施工图纸、设计规范、施工方案事项均包含在综合单价中。 | E11: m2 | F11: 1090.99 | G11: 135 | H11: =ROUND(F11*G11,2) -> 147283.65 | I11: =R11 -> 175.84 | J11: =F11*I11 -> 191839.68 | K11: 按设计图示尺寸以展开面积计算 | L11: 全费用综合单价 | N11: =主材表!L7 -> 66.37 | O11: =400*1.6*1.05*0.03 -> 20.16 | P11: =$P$9 -> 60 | Q11: =N11+O11+P11 -> 146.53 | R11: =Q11*$R$4 -> 175.84 | T11: 175.84 | U11: =T11-I11 -> 0
A12: 6 | B12: 地砖楼面 | C12: 1、面层：10厚玻化砖(防滑),同色水泥浆擦缝 2、30厚1:3干硬性水泥砂浆,表面撒水泥粉 3、嵌缝材料种类：按甲方要求嵌缝、打胶； 4、防护层材料：满足设计和相关规范要求； 5、酸洗、打蜡要求：满足设计和相关规范要求； 6、楼地面伸缩缝、变形缝的处理； 7、其他：该项包含本项工作所有工作内容含垂直运输机械等，未详尽列举特征，详见施工图纸、设计规范、施工方案事项均包含在综合单价中。 (地砖规格600*600) | D12: 1、基层清理、打磨；2、砂浆的制作、运输、找平、压实；3、面层的铺贴；4、水泥砂浆擦缝；5、局部部位防滑地砖切割、打磨，未详尽列举的图纸、方案事项均包含在综合单价中；6.该项包含本项工作所有工作内容含垂直运输机械等，未详尽列举特征，详见施工图纸、设计规范、施工方案事项均包含在综合单价中。 | E12: m2 | F12: 1090.99 | G12: 120 | H12: =ROUND(F12*G12,2) -> 130918.8 | I12: =R12 -> 165.22 | J12: =F12*I12 -> 180253.37 | K12: 按设计图示尺寸以面积计算 | L12: 全费用综合单价 | N12: =主材表!L8 -> 57.52 | O12: =400*1.6*1.05*0.03 -> 20.16 | P12: =$P$9 -> 60 | Q12: =N12+O12+P12 -> 137.68 | R12: =Q12*$R$4 -> 165.22 | T12: 165.22 | U12: =T12-I12 -> 0
A13: 7 | B13: 水泥自流平防水地面 | C13: 1、5厚水泥基自流平面层 2、涂刷自流平界面剂 3、其他：该项包含本项工作所有工作内容含垂直运输机械等，未详尽列举特征，详见施工图纸、设计规范、施工方案事项均包含在综合单价中。 | D13: 1.基层处理；2.涂界面剂；3.拌合自流平浆料；4.铺自流平面层；5、未详尽列举的图纸、方案事项均包含在综合单价中；6.该项包含本项工作所有工作内容含垂直运输机械等，未详尽列举特征，详见施工图纸、设计规范、施工方案事项均包含在综合单价中。 | E13: m2 | F13: 277.7 | G13: 47.92 | H13: =ROUND(F13*G13,2) -> 13307.38 | I13: =R13 -> 28.8 | J13: =F13*I13 -> 7997.76 | K13: 按设计图示尺寸以面积计算 | L13: 全费用综合单价 | M13: 图纸未找到 | N13: 12 | P13: 12 | Q13: =N13+O13+P13 -> 24 | R13: =Q13*$R$4 -> 28.8 | T13: 28.8 | U13: =T13-I13 -> 0
A14: 8 | B14: 防静电架空地面 | C14: 1、10厚玻化砖,同色水泥浆擦缝 2、30厚1:3干硬性水泥砂浆,表面撒水泥粉 3、水泥浆一道(内掺建筑胶) 4、其他：该项包含本项工作所有工作内容含垂直运输机械等，未详尽列举特征，详见施工图纸、设计规范、施工方案事项均包含在综合单价中。 | D14: 1、基层清理、打磨；2、水泥浆一道，内掺建筑胶；3、砂浆的制作、运输、找平、压实；4、面砖的铺贴；5、成套支架安装；6、安装陶瓷防静电架空地板；6、该项包含防静电架空地板的所有工作内容，含垂直运输机械等，未详尽列举的图纸、方案事项均包含在综合单价中 | E14: m2 | F14: 77.79 | G14: 316.06 | H14: =ROUND(F14*G14,2) -> 24586.31 | I14: =R14 -> 391.2 | J14: =F14*I14 -> 30431.45 | K14: 按设计图示尺寸以面积计算 | L14: 全费用综合单价 | M14: 图纸未找到 | N14: 225 | O14: 26 | P14: 75 | Q14: =N14+O14+P14 -> 326 | R14: =Q14*$R$4 -> 391.2 | T14: 391.2 | U14: =T14-I14 -> 0
A15: 9 | B15: 防静电活动楼面 | C15: 1、10厚玻化砖,同色水泥浆擦缝 2、30厚1:3干硬性水泥砂浆,表面撒水泥粉 3、水泥浆一道(内掺建筑胶) 4、其他：该项包含本项工作所有工作内容含垂直运输机械等，未详尽列举特征，详见施工图纸、设计规范、施工方案事项均包含在综合单价中。 | D15: 1、基层清理、打磨；2、水泥浆一道，内掺建筑胶；3、砂浆的制作、运输、找平、压实；4、面砖的铺贴；5、成套支架安装；6、安装陶瓷防静电架空地板；6、该项包含防静电架空地板的所有工作内容，含垂直运输机械等，未详尽列举的图纸、方案事项均包含在综合单价中 | E15: m2 | F15: 147.29 | G15: 316.06 | H15: =ROUND(F15*G15,2) -> 46552.48 | I15: =I14 -> 391.2 | J15: =F15*I15 -> 57619.85 | K15: 按设计图示尺寸以面积计算 | L15: 全费用综合单价 | M15: 图纸未找到 | T15: 391.2 | U15: =T15-I15 -> 0
A16: 10 | B16: 25MM 厚深灰麻过门石 | C16: 1、铺25厚磨光花岗石板(六面涂刷石材保护剂),同色稀水泥浆擦 2、50厚1:3干硬性水泥粘结层,撒素水泥粉 3、水泥浆一道(内掺建筑胶) 4、嵌缝材料种类：按甲方要求嵌缝、打胶； 5、防护层材料：防护剂六面处理，满足设计和相关规范要求； 6、酸洗、打蜡要求：满足设计和相关规范要求； 7、楼地面伸缩缝、变形缝的处理； 8、其他：该项包含本项工作所有工作内容含垂直运输机械等，未详尽列举特征，详见施工图纸、设计规范、施工方案事项均包含在综合单价中。 (石材规格800*800) | D16: 1、基层清理、打磨；2、砂浆的制作、运输、找平、压实；3、面层的铺贴；4、水泥砂浆擦缝；5、局部部位过门石切割、打磨，未详尽列举的图纸、方案事项均包含在综合单价中；5该项包含本项工作所有工作内容含垂直运输机械等，未详尽列举特征，详见施工图纸、设计规范、施工方案事项均包含在综合单价中。 | E16: m2 | F16: 31.88 | G16: 80 | H16: =ROUND(F16*G16,2) -> 2550.4 | I16: =R16 -> 156 | J16: =F16*I16 -> 4973.28 | K16: 按设计图示尺寸以面积计算 | L16: 1、除甲供材外全费用综合单价； 2、甲供材：石材 | N16: 0 | O16: 20 | P16: 110 | Q16: =N16+O16+P16 -> 130 | R16: =Q16*$R$4 -> 156 | T16: 156 | U16: =T16-I16 -> 0
A17: 11 | B17: 水泥踢脚 | C17: 1、6厚1:2.5水泥砂浆抹面压实赶光 2、刷素水泥浆一道 3、7厚1:1:6水泥石灰膏砂浆打底骚猫或划出纹道 4、3厚外加剂专用砂浆抹基底刮糙(抹前用水喷湿墙面) | D17: 1、清理基层，抹灰，材料制备，成品保护等，2、其他详见设计图纸未详尽列举的图纸、方案事项均包含在综合单价中；3.该项包含本项工作所有工作内容含垂直运输机械等，未详尽列举特征，详见施工图纸、设计规范、施工方案事项均包含在综合单价中。 | E17: m2 | F17: 42.11 | G17: 35 | H17: =ROUND(F17*G17,2) -> 1473.85 | I17: =R17 -> 174.1 | J17: =F17*I17 -> 7331.35 | K17: 以平方米计量，按设计图示长度乘高度以面积计算 | L17: 全费用综合单价 | O17: =400*1.6*1.05*0.015+15 -> 25.08 | P17: =12*10 -> 120 | Q17: =N17+O17+P17 -> 145.08 | R17: =Q17*$R$4 -> 174.1 | T17: 174.1 | U17: =T17-I17 -> 0
A18: 12 | B18: 地砖踢脚 | C18: 1、粘贴10厚地砖,专用勾缝剂勾缝 2、9厚1:2水泥砂浆(内掺3%超密聚合物防水剂)粘结层 3、素水泥浆一道(内掺建筑胶) | D18: 1、清理基层、面层铺贴、成品保护及半成品保护，材料运输，养护抛光等。2、部位：水磨石楼地面含水磨石踢脚3、其它:该项包含本项工作所有工作内容含垂直运输机械等，未详尽列举特征，详见施工图纸、设计规范、施工方案事项均包含在综合单价中。 | E18: m2 | F18: 150.88 | G18: 130 | H18: =ROUND(F18*G18,2) -> 19614.4 | I18: =R18 -> 233.83 | J18: =F18*I18 -> 35280.27 | K18: 以平方米计量，按设计图示长度乘高度以面积计算 | L18: 全费用综合单价 | N18: =主材表!L9 -> 68.14 | O18: =400*1.6*1.05*0.01 -> 6.72 | P18: =12*10 -> 120 | Q18: =N18+O18+P18 -> 194.86 | R18: =Q18*$R$4 -> 233.83 | T18: 233.83 | U18: =T18-I18 -> 0
A19: 13 | B19: 金属踢脚(高100) | C19: 1、1.0厚不锈钢金属踢脚板,下端用水泥钉钉入地面垫层,中距300 2、10厚1:3水泥砂浆压实抹平 3、素水泥浆一道(内掺建筑胶)(用于混凝土空心砌块墙);3厚外加剂专用砂浆抹基底刮糙(抹灰前用水喷湿墙面)(用于蒸 压加气混凝土砌块墙) 4、水泥钉固定踢脚上端,中距300 | D19: 1.粘贴层厚度、材料种类:铝合金踢脚卡，水泥钉固定在墙内防腐耐火砖上； 2.面层材料品种、规格、颜色:详见设计图纸 3.其它:该项包含本项工作所有工作内容含垂直运输机械等，未详尽列举特征，详见施工图纸、设计规范、施工方案事项均包含在综合单价中。 | E19: m2 | F19: 99.99 | G19: 272.98 | H19: =ROUND(F19*G19,2) -> 27295.27 | I19: =R19 -> 519.74 | J19: =F19*I19 -> 51968.8 | K19: 以平方米计量，按设计图示长度乘高度以面积计算 | L19: 全费用综合单价 | N19: =主材表!L25 -> 301.62 | O19: =8+3.5 -> 11.5 | P19: =20+100 -> 120 | Q19: =N19+O19+P19 -> 433.12 | R19: =Q19*$R$4 -> 519.74 | T19: 519.74 | U19: =T19-I19 -> 0
A20: 14 | B20: 无机涂料墙面 | C20: 1、喷(刷、辊)无机内墙薄涂涂料2道 2、满刮2厚腻子砂磨平 3、其他：该项包含本项工作所有工作内容含垂直运输机械等，未详尽列举特征，详见施工图纸、设计规范、施工方案事项均包含在综合单价中。 | D20: 1、墙体基层处理；2、刮腻子；3、涂料的制作、运输；4、喷面浆或涂料；5、该项包含涂料墙面的所有工作内容，含垂直运输机械等，未详尽列举特征，详见施工图纸、设计规范、施工方案事项均包含在综合单价中。 | E20: m2 | F20: 4198.38 | G20: 27 | H20: =ROUND(F20*G20,2) -> 113356.26 | I20: =R20 -> 44.4 | J20: =F20*I20 -> 186408.07 | K20: 按设计图示尺寸以面积计算（有吊顶房间算至吊顶底，无吊顶房间算至梁底或者板底） | L20: 全费用综合单价 | N20: 7.5 | O20: 4.5 | P20: 25 | Q20: =N20+O20+P20 -> 37 | R20: =Q20*$R$4 -> 44.4 | T20: 44.4 | U20: =T20-I20 -> 0
A21: 15 | B21: 防水面砖墙面 | C21: 1、同色水泥擦缝 2、8-10厚墙面砖(粘贴前墙砖充分浸湿) 3、8厚1:2水泥砂浆粘结层(内掺建筑胶) 4、缝宽、嵌缝材料：按甲方要求嵌缝、打胶； 5、酸洗、打蜡要求：满足设计和相关规范要求； 6、墙面伸缩缝、变形缝的处理； 7、根据安装需要开孔 8、其他：该项包含本项工作所有工作内容含垂直运输机械等，未详尽列举特征，详见施工图纸、设计规范、施工方案事项均包含在综合单价中。； | D21: 1、墙体基层处理；2、水泥砂浆的制作、运输；3、粘贴墙面砖；4、局部部位面砖切割、打磨；5、水泥擦缝；6、该项包含玻化砖墙面的所有工作内容，含垂直运输机械等，未详尽列举特征，详见施工图纸、设计规范、施工方案事项均包含在综合单价中。 | E21: m2 | F21: 1750.02 | G21: 120 | H21: =ROUND(F21*G21,2) -> 210002.4 | I21: =R21 -> 153.02 | J21: =F21*I21 -> 267788.06 | K21: 按设计图示尺寸以面积计算（有吊顶房间算至吊顶底） | L21: 全费用综合单价 | N21: =主材表!L10 -> 57.52 | O21: 10 | P21: 60 | Q21: =N21+O21+P21 -> 127.52 | R21: =Q21*$R$4 -> 153.02 | T21: 153.02 | U21: =T21-I21 -> 0
A22: 16 | B22: 干挂铝板墙面（含消防暗门） | C22: 1、2.5厚铝合金饰面面层,接缝处密缝(或10*10MM凹槽);(3 米以下加肋,衬6mm厚硅酸钙板)。 2、金属板材用抽芯铆钉或自攻螺钉固定于铝方型材纵横方向龙骨上,板材带折边采用搭接式,带挂耳采用对接式; 3、60X40X4铝方型材龙骨,横向间距同金属板材宽度,纵向间距同金属板材长度,用螺栓与角钢连接。 4、8#槽钢竖向龙骨连接件螺栓连接, 5、连接件与预埋板焊接 6、预埋件 7、墙面伸缩缝、变形缝； 其他：该项包含本项工作所有工作内容含垂直运输机械等，未详尽列举特征，详见施工图纸、设计规范、施工方案事项均包含在综合单价中。； | D22: 1、铝板下料；2、铝单板干挂；3、铝单板上铝格栅粘贴；4、与石材楼面接缝的处理；5、该项包含本项工作所有工作内容含垂直运输机械等，未详尽列举特征，详见施工图纸、设计规范、施工方案事项均包含在综合单价中。 | E22: m2 | F22: 5752.72 | G22: 120 | H22: =ROUND(F22*G22,2) -> 690326.4 | I22: =R22 -> 177 | J22: =F22*I22 -> 1018231.4 | K22: 按设计图示尺寸以面积计算 | L22: 1、除型钢龙骨及甲供材外全费用综合单价； 2、甲供材：铝板 | M22: 甲供材料：铝板 | N22: 0 | O22: =22+5.5 -> 27.5 | P22: 120 | Q22: =N22+O22+P22 -> 147.5 | R22: =Q22*$R$4 -> 177 | S22: =(5.45*1.3+8.045*0.55)/(1.2*0.55) -> 17.44 | T22: 177 | U22: =T22-I22 -> 0
A23: 17 | B23: 耐擦洗涂料墙面 | C23: 1、防火型无机耐擦洗涂料两道饰面(白色) 2、满刮2厚耐水腻子找平 3、其他：该项包含本项工作所有工作内容含垂直运输机械等，未详尽列举特征，详见施工图纸、设计规范、施工方案事项均包含在综合单价中。； | D23: 1、墙体基层处理；2、刮腻子；3、涂料的制作、运输；4、喷面浆或涂料；5、该项包含涂料墙面的所有工作内容，含垂直运输机械等，未详尽列举特征，详见施工图纸、设计规范、施工方案事项均包含在综合单价中。 | E23: m2 | F23: 1745.67 | G23: 30 | H23: =ROUND(F23*G23,2) -> 52370.1 | I23: =R23 -> 44.4 | J23: =F23*I23 -> 77507.75 | K23: 按设计图示尺寸以面积计算（有吊顶房间算至吊顶底，无吊顶房间算至梁底或者板底） | L23: 全费用综合单价 | N23: =$N$20 -> 7.5 | O23: 4.5 | P23: =$P$20 -> 25 | Q23: =N23+O23+P23 -> 37 | R23: =Q23*$R$4 -> 44.4 | T23: 44.4 | U23: =T23-I23 -> 0
A24: 18 | B24: 穿孔吸声板墙面 | C24: 1、10厚穿孔板用螺钉固定于龙骨上 2、玻璃布一层绷紧固定于龙骨表面 3、40厚岩棉(或玻璃棉)毡,建筑胶粘济粘贴于龙骨档内 4、75X50X0.7轻钢龙骨用膨胀螺栓宇墙面固定,中距按板规格设计 5、1.5厚聚合物水泥防水涂膜 6、在混凝土梁、柱或现浇混凝土条带、砌块上钻孔打入M6X75膨胀螺栓,中距按穿孔板规格设计 7、6~9厚DP-HR砂浆修补墙面抹平 8、3厚外加剂专用砂浆抹基底,抹前喷湿墙面(用于加气混凝土砌块墙) 9、墙面伸缩缝、变形缝； 其他：该项包含本项工作所有工作内容含垂直运输机械等，未详尽列举特征，详见施工图纸、设计规范、施工方案事项均包含在综合单价中。 | D24: 1、天棚基层处理；2、后置件、骨架的制作、运输、安装；3、硅酸钙板安装；4、表面涂刷乳胶漆，压条安装；5、该项包含硅酸钙板吊顶的所有工作内容，含垂直运输机械等，未详尽列举特征，详见施工图纸、设计规范、施工方案事项均包含在综合单价中。 | E24: m2 | F24: 386.43 | G24: 136.53 | H24: =ROUND(F24*G24,2) -> 52759.29 | I24: =R24 -> 294.36 | J24: =F24*I24 -> 113749.53 | K24: 按设计图示尺寸以硅酸钙板吊顶水平投影面积计算 | L24: 全费用综合单价 | N24: =主材表!L27 -> 70.8 | O24: =16+28+18+5.5 -> 67.5 | P24: =6+30+6+65 -> 107 | Q24: =N24+O24+P24 -> 245.3 | R24: =Q24*$R$4 -> 294.36 | T24: 294.36 | U24: =T24-I24 -> 0
A25: 19 | B25: 穿孔山水纹样铝单板墙面（含消防暗门） | C25: 1、穿孔山水纹样铝单板 2、金属板材用抽芯铆钉或自攻螺钉固定于铝方型材纵横方向龙骨上,板材带折边采用搭接式,带挂耳采用对接式; 3、60X40X4铝方型材龙骨,横向间距同金属板材宽度,纵向间距同金属板材长度,用螺栓与角钢连接。 4、8#槽钢竖向龙骨连接件螺栓连接, 5、连接件与预埋板焊接 6、预埋件 7、墙面伸缩缝、变形缝； 其他：该项包含本项工作所有工作内容含垂直运输机械等，未详尽列举特征，详见施工图纸、设计规范、施工方案事项均包含在综合单价中。； | D25: 1、后置件、骨架的制作、运输、安装；2、铝板下料；3、铝单板干挂；4、铝单板上铝格栅粘贴；5、与石材楼面接缝的处理；6、该项包含本项工作所有工作内容含垂直运输机械等，未详尽列举特征，详见施工图纸、设计规范、施工方案事项均包含在综合单价中。 | E25: m2 | F25: 457.25 | G25: 120 | H25: =ROUND(F25*G25,2) -> 54870 | I25: =R25 -> 181.8 | J25: =F25*I25 -> 83128.05 | K25: 按设计图示尺寸以室外可视铝板面积计算，其中：铝板梁面和铝单板吊顶分界线为最内侧的垂直方向的铝单板边线 | L25: 1、除型钢龙骨及甲供材外全费用综合单价； 2、甲供材：铝板 | O25: =26+5.5 -> 31.5 | P25: =$P$22 -> 120 | Q25: =N25+O25+P25 -> 151.5 | R25: =Q25*$R$4 -> 181.8 | S25: =_xlfn.DISPIMG("ID_4771296B097B4BBBA094ED4C648C6B3B",1) -> =DISPIMG("ID_4771296B097B4BBBA094ED4C648C6B3B",1) | T25: 181.8 | U25: =T25-I25 -> 0
A26: 20 | B26: 鱼骨纹木色铝板墙面（含消防暗门） | C26: 1、鱼骨纹木色铝板 2、金属板材用抽芯铆钉或自攻螺钉固定于铝方型材纵横方向龙骨上,板材带折边采用搭接式,带挂耳采用对接式; 3、60X40X4铝方型材龙骨,横向间距同金属板材宽度,纵向间距同金属板材长度,用螺栓与角钢连接。 4、8#槽钢竖向龙骨连接件螺栓连接, 5、连接件与预埋板焊接 6、预埋件 7、墙面伸缩缝、变形缝； 其他：该项包含本项工作所有工作内容含垂直运输机械等，未详尽列举特征，详见施工图纸、设计规范、施工方案事项均包含在综合单价中。； | D26: 1、后置件、骨架的制作、运输、安装；2、铝板下料；3、铝单板干挂；4、铝单板上铝格栅粘贴；5、与石材楼面接缝的处理；6、该项包含本项工作所有工作内容含垂直运输机械等，未详尽列举特征，详见施工图纸、设计规范、施工方案事项均包含在综合单价中。 | E26: m2 | F26: 28.16 | G26: 120 | H26: =ROUND(F26*G26,2) -> 3379.2 | I26: =$I$22 -> 177 | J26: =F26*I26 -> 4984.32 | K26: 按设计图示尺寸以室外可视铝板面积计算，其中：铝板梁面和铝单板吊顶分界线为最内侧的垂直方向的铝单板边线 | L26: 1、除型钢龙骨及甲供材外全费用综合单价； 2、甲供材：铝板 | S26: =_xlfn.DISPIMG("ID_8AFDA53BCB7C4881B934B1C0D89D3540",1) -> =DISPIMG("ID_8AFDA53BCB7C4881B934B1C0D89D3540",1) | T26: 177 | U26: =T26-I26 -> 0
A27: 21 | B27: 无机涂料吸音顶棚 | C27: 1、无机涂料 2、20厚矿物纤维吸声涂层 3、其他：该项包含本项工作所有工作内容含垂直运输机械等，未详尽列举特征，详见施工图纸、设计规范、施工方案事项均包含在综合单价中。 | D27: 1、墙体基层处理；2、刮腻子；3、涂料的制作、运输；4、矿物纤维吸声喷涂、喷面浆或涂料；5、该项包含涂料墙面的所有工作内容，含垂直运输机械等，未详尽列举特征，详见施工图纸、设计规范、施工方案事项均包含在综合单价中。 | E27: m2 | F27: 457.93 | G27: 32 | H27: =ROUND(F27*G27,2) -> 14653.76 | I27: =R27 -> 44.4 | J27: =F27*I27 -> 20332.09 | K27: 按设计图示尺寸以水平投影面积计算 | L27: 全费用综合单价 | N27: =$N$20 -> 7.5 | O27: 4.5 | P27: =$P$20 -> 25 | Q27: =N27+O27+P27 -> 37 | R27: =Q27*$R$4 -> 44.4 | T27: 44.4 | U27: =T27-I27 -> 0
A28: 22 | B28: 无机涂料顶棚 | C28: 1、防火型无机耐擦洗涂料两道饰面(白色) 2、2厚面层耐水腻子刮平 3、其他：该项包含本项工作所有工作内容含垂直运输机械等，未详尽列举特征，详见施工图纸、设计规范、施工方案事项均包含在综合单价中。 | D28: 1、墙体基层处理；2、刮腻子；3、涂料的制作、运输；4、喷面浆或涂料；5、该项包含涂料墙面的所有工作内容，含垂直运输机械等，未详尽列举特征，详见施工图纸、设计规范、施工方案事项均包含在综合单价中。 | E28: m2 | F28: 705.44 | G28: 32 | H28: =ROUND(F28*G28,2) -> 22574.08 | I28: =$I$27 -> 44.4 | J28: =F28*I28 -> 31321.54 | K28: 按设计图示尺寸以水平投影面积计算 | L28: 全费用综合单价 | T28: 44.4 | U28: =T28-I28 -> 0
A29: 23 | B29: 铝合金扣板顶棚 | C29: 1、600*600*1.0铝合金扣板(折边20) 2、与铝合金扣板配套的专用暗架龙骨,间距≤300,通过十字连扣连接件与承载龙骨连接 3、D38承载龙骨,间距≤1200,用吊杆与钢筋吊杆联结后找平 4、10厚镀锌低碳钢丝(或%%C8钢筋)吊杆,双向中距≤1200,吊杆上部与板底(或钢结构)预留吊环(勾)固定 5、结构层预埋%%C10(或钢结构预留)钢筋吊环(勾),双向中距≤1200 6、天棚伸缩缝、变形缝； 其他：该项包含本项工作所有工作内容含垂直运输机械等，未详尽列举特征，详见施工图纸、设计规范、施工方案事项均包含在综合单价中。 | D29: 1、吊杆的制作、运输、安装；2、铝板下料； 3、铝扣板安装以及与墙柱面接缝处理； 4、未详尽列举的图纸、方案事项均包含在综合单价中 5.该项包含本项工作所有工作内容含垂直运输机械等，未详尽列举特征，详见施工图纸、设计规范、施工方案事项均包含在综合单价中。 | E29: m2 | F29: 602.16 | G29: 136.14 | H29: =ROUND(F29*G29,2) -> 81978.06 | I29: =R29 -> 160.04 | J29: =F29*I29 -> 96369.69 | K29: 按设计图示尺寸以投影面积计算 | L29: 除型钢龙骨、转换层外的全费用综合单价 | N29: =主材表!L29 -> 66.37 | O29: 22 | P29: 45 | Q29: =N29+O29+P29 -> 133.37 | R29: =Q29*$R$4 -> 160.04 | T29: 160.04 | U29: =T29-I29 -> 0
A30: 24 | B30: 硅酸钙板面层板吊顶 | C30: 1、喷(刷、辊)涂料面层两遍(每道间隔2小时) 2、封底漆一道(干燥后再做面层) 3、满刮2厚面层耐水腻子找平,板面接缝处贴嵌缝带,刮腻子抹平 4、错缝粘贴第二层9.5厚耐水耐火纸面石膏板 5、双层6mm厚硅酸钙板用自攻螺丝与龙骨固定,中距≤200,螺丝距板长边≥10,短边≥15 6、U型轻钢覆面横撑龙骨CB60x27,间距1200,用挂插件与次龙骨联结 7、U型轻钢覆面次龙骨CB60x27,间距400,用挂件与承接龙骨联结 8、U型轻钢承接龙骨CS50x15,间距≤1200,用吊杆与钢筋吊杆联结后找平 9、%%C8钢筋吊杆并加反支撑,双向中距≤1200,吊杆上部与预留钢筋吊环固定 10、现浇钢筋混凝土板底预埋%%C10钢筋吊环(勾),双向中距≤1200(转换层另列） 11、天棚伸缩缝、变形缝； 其他：该项包含本项工作所有工作内容含垂直运输机械等，未详尽列举特征，详见施工图纸、设计规范、施工方案事项均包含在综合单价中。 | D30: 1、天棚基层处理；2、后置件、骨架的制作、运输、安装；3、硅酸钙板安装；4、表面涂刷乳胶漆，压条安装；5、该项包含硅酸钙板吊顶的所有工作内容，含垂直运输机械等，未详尽列举特征，详见施工图纸、设计规范、施工方案事项均包含在综合单价中。 | E30: m2 | F30: 1343.7 | G30: 185.86 | H30: =ROUND(F30*G30,2) -> 249740.08 | I30: =R30 -> 348 | J30: =F30*I30 -> 467607.6 | K30: 按设计图示尺寸以硅酸钙板吊顶水平投影面积计算 | L30: 全费用综合单价 | N30: 7.5 | O30: =65+28+26+10+4.5 -> 133.5 | P30: =55+30+20+18+26 -> 149 | Q30: =N30+O30+P30 -> 290 | R30: =Q30*$R$4 -> 348 | T30: 348 | U30: =T30-I30 -> 0
A31: 25 | B31: 铝合金单板(穿孔铝板2.5厚)装饰吊顶（候车大厅） | C31: 1、2.5厚铝合金单板与配套专用龙骨固定 2、与铝合金单板配套的专用下层副龙骨联结,间距≤600 3、与安装型式配套的专用上层主龙骨,间距≤1200,用吊件与钢筋吊杆联结后找平 4、10号镀锌低碳钢丝(或%%C8钢筋)吊杆,双向中距≤1200,吊杆上部与板底预留吊环固定 5、现浇钢筋混凝土板底预留%%C10钢筋吊环,双向中距≤1200 6、天棚伸缩缝、变形缝； 其他：该项包含本项工作所有工作内容含垂直运输机械等，未详尽列举特征，详见施工图纸、设计规范、施工方案事项均包含在综合单价中。 | D31: 1、钢结构转换层制作、安装；2、安装龙骨；3、铝单板片面层安装；4、该项包含本项工作所有工作内容含垂直运输机械等，未详尽列举特征，详见施工图纸、设计规范、施工方案事项均包含在综合单价中。 | E31: m2 | F31: 1195.5 | G31: 135 | H31: =ROUND(F31*G31,2) -> 161392.5 | I31: =R31 -> 182.4 | J31: =F31*I31 -> 218059.2 | K31: 按铝单板吊顶的水平投影面积计算 | L31: 1、除型钢龙骨及甲供材外全费用综合单价； 2、甲供材：铝板 | N31: 0 | O31: 22 | P31: 130 | Q31: =N31+O31+P31 -> 152 | R31: =Q31*$R$4 -> 182.4 | T31: 182.4 | U31: =T31-I31 -> 0
A32: 26 | B32: 铝合金单板(穿孔铝板3厚)装饰吊顶（候车大厅） | C32: 1、3厚铝合金单板与配套专用龙骨固定 2、与铝合金单板配套的专用下层副龙骨联结,间距≤600 3、与安装型式配套的专用上层主龙骨,间距≤1200,用吊件与钢筋吊杆联结后找平 4、10号镀锌低碳钢丝(或%%C8钢筋)吊杆,双向中距≤1200,吊杆上部与板底预留吊环固定 5、现浇钢筋混凝土板底预留%%C10钢筋吊环,双向中距≤1200 6、天棚伸缩缝、变形缝； 其他：该项包含本项工作所有工作内容含垂直运输机械等，未详尽列举特征，详见施工图纸、设计规范、施工方案事项均包含在综合单价中。 | D32: 1、钢结构转换层制作、安装；2、安装龙骨；3、铝单板片面层安装；4、该项包含本项工作所有工作内容含垂直运输机械等，未详尽列举特征，详见施工图纸、设计规范、施工方案事项均包含在综合单价中。 | E32: m2 | F32: 2722.94 | G32: 135 | H32: =ROUND(F32*G32,2) -> 367596.9 | I32: =$I$31 -> 182.4 | J32: =F32*I32 -> 496664.26 | K32: 按铝单板吊顶的水平投影面积计算 | L32: 1、除型钢龙骨及甲供材外全费用综合单价； 2、甲供材：铝板 | T32: 182.4 | U32: =T32-I32 -> 0
A33: 27 | B33: 铝合金条板(锤片)吊顶（候车大厅） | C33: 1、铝合金条板与配套专用龙骨固定(宽150mm,缝75mm,厚1mm) 2、与铝合金方通配套的专用龙骨,间距≤1200,用吊件与钢筋吊杆连接后找平 3、10号镀锌低碳钢丝(或%%C6钢筋)吊杆,双向中距≤1200,吊杆上部与板底预留吊环(勾)固定 4、现浇钢筋混凝土板底预留%%C10钢筋吊环(勾),双向中距≤1200(吊杆长度超过1.5米后需要做反支撑,吊杆长度超过2.5米需做转换层,做法详见二次结构施工安装详图)(转换层另列） 5、天棚伸缩缝、变形缝； 其他：该项包含本项工作所有工作内容含垂直运输机械等，未详尽列举特征，详见施工图纸、设计规范、施工方案事项均包含在综合单价中。； | D33: 基层清理；吊杆制作；吊杆、龙骨安装；面板固定、安装；洞口、检查孔、灯槽等留置、处理及收边收口，按照图纸要求吊顶四周设置圆形收边条、顶棚喷黑处理；材料场内运输；脚手架搭拆，成品保护等。该项包含本项工作所有工作内容含垂直运输机械等，未详尽列举特征，详见施工图纸、设计规范、施工方案事项均包含在综合单价中。 | E33: m2 | F33: 27.2 | G33: 125 | H33: =ROUND(F33*G33,2) -> 3400 | I33: =R33 -> 182.4 | J33: =F33*I33 -> 4961.28 | K33: 按设计图示尺寸以水平投影面积计算 | L33: 1、除型钢龙骨及甲供材外全费用综合单价； 2、甲供材：铝合金条板 | N33: 0 | O33: 22 | P33: 130 | Q33: =N33+O33+P33 -> 152 | R33: =Q33*$R$4 -> 182.4 | T33: 182.4 | U33: =T33-I33 -> 0
A34: 28 | B34: 天棚喷刷深灰色涂料 | C34: 1、基层类型：砼天棚；2、深灰A级无机涂料喷涂，厚度、装饰效果满足设计要求3、超高增加的措施费用 | D34: [工作内容] 1.基层清理 2.刮腻子 3.刷、喷涂料 | E34: m2 | F34: 922.73 | G34: 12.89 | H34: =ROUND(F34*G34,2) -> 11893.99 | I34: =R34 -> 24.6 | J34: =F34*I34 -> 22699.16 | K34: 按GB 50854-2013工程量计算规范计算 | L34: 此项工作的全费用综合单价 | N34: 8.5 | P34: 12 | Q34: =N34+O34+P34 -> 20.5 | R34: =Q34*$R$4 -> 24.6 | T34: 24.6 | U34: =T34-I34 -> 0
A35: 29 | B35: 洗漱台 | C35: 1、部位：具体详设计图纸要求； 2、石材规格：综合详见图纸； 3、2.5mm铝单板挡板 4、台面、挡水 5、其它：满足设计规范及图纸要求。 | D35: 1.洗漱台面层石材制作、运输、铺贴 2.铝板安装、收边收口 3.材料的运输、摆放、清运及场内多次搬运； 4.对已施工完成的成品及其他专业已完成的成品进行保护工作，无论是否由该单位导致的损坏，该单位都应履行修复处理责任； 5.对施工需要拆除或移动的材料，待施工完毕后，恢复原状； 6.完成工作区域的安全文明施工,清理施工遗留下的垃圾； 7、该项包含本项工作所有工作内容含垂直运输机械等，未详尽列举特征，详见施工图纸、设计规范、施工方案事项均包含在综合单价中。 | E35: m | F35: 41.85 | G35: 420.78 | H35: =ROUND(F35*G35,2) -> 17609.64 | I35: =R35 -> 639.9 | J35: =F35*I35 -> 26779.82 | K35: 按设计图示以米计算 | L35: 除基层龙骨外，此项工作的全费用综合单价 | N35: =350*0.64+主材表!L26*0.55 -> 343.25 | O35: =10 -> 10 | P35: 180 | Q35: =N35+O35+P35 -> 533.25 | R35: =Q35*$R$4 -> 639.9 | S35: =_xlfn.DISPIMG("ID_D9027A23E9374EC3A029BBD590E7A70F",1) -> =DISPIMG("ID_D9027A23E9374EC3A029BBD590E7A70F",1) | T35: 639.9 | U35: =T35-I35 -> 0
A36: 30 | B36: 镜面玻璃 | C36: 1.30*30mm方管龙骨（刷防火、防腐） 2.6mm厚双层硅酸钙板基层（涂刷防腐） 3.5mm厚银镜及安装。 4.顶部及底部LED贴片灯带、灯槽制作安装 5.不锈钢边框包边；6.完成该项工作所需的全部工作内容 | D36: [工作内容] 1.基层安装 2.玻璃及框制作、运输、安装 3.该项包含本项工作所有工作内容含垂直运输机械等，未详尽列举特征，详见施工图纸、设计规范、施工方案事项均包含在综合单价中。 | E36: m2 | F36: 54.84 | G36: 220 | H36: =ROUND(F36*G36,2) -> 12064.8 | I36: =R36 -> 526.8 | J36: =F36*I36 -> 28889.71 | K36: 按设计图示尺寸以面积计算 | L36: 除基层龙骨外，此项工作的全费用综合单价 | N36: =5.5*35+75 -> 267.5 | O36: =30+26+5.5 -> 61.5 | P36: =35+20+55 -> 110 | Q36: =N36+O36+P36 -> 439 | R36: =Q36*$R$4 -> 526.8 | S36: =(1.2*2+1.3*2)/1.2*1.3 -> 5.42 | T36: 526.8 | U36: =T36-I36 -> 0
A37: 31 | B37: 蹲位隔断 | C37: 1.50*4不锈钢角码固定隔板，膨胀螺丝与墙面固定 2.20mm厚金属复合板制作安装，含不锈钢挂衣钩固定安装； 3.复合板面不锈钢把手、不锈钢锁（红绿）隔门不锈钢合页安装； 4.隔板交接处50*4不锈钢角码纵向安装，专用平头螺丝固定，隔板与地面交接位置装100mm高不锈钢踢脚，防水胶嵌缝，2mm厚不锈钢U形抵扣封边； 5.未尽部分详见图纸； 6.完成该项工作所需的全部工作内容，完成工作区域的安全文明施工,清理施工遗留下的垃圾。 | D37: [工作内容] 1.隔断运输、安装 2.嵌缝、塞口 3.该项包含本项工作所有工作内容含垂直运输机械等，未详尽列举特征，详见施工图纸、设计规范、施工方案事项均包含在综合单价中。 | E37: 间 | F37: 66 | G37: 1250 | H37: =ROUND(F37*G37,2) -> 82500 | I37: =R37 -> 3490.32 | J37: =F37*I37 -> 230361.12 | K37: 以间计量，按设计间的数量计算。 | L37: 除基层龙骨外，此项工作的全费用综合单价 | M37: 市场不含税成本单价385元一平米，平均每个蹲位7.46㎡， | N37: =主材表!L19*7.46 -> 2872.1 | O37: 1.5 | P37: 35 | Q37: =N37+O37+P37 -> 2908.6 | R37: =Q37*$R$4 -> 3490.32 | S37: =2.8*3 -> 8.4 | T37: 3490.32 | U37: =T37-I37 -> 0
A38: 32 | B38: 小便斗隔板 | C38: 1.50*4不锈钢角码固定隔板，膨胀螺丝与墙面固定 2.20mm厚金属复合板制作安装 3.完成该项工作所需的全部工作内容，完成工作区域的安全文明施工,清理施工遗留下的垃圾。 | D38: [工作内容] 1.隔断运输、安装 2.嵌缝、塞口 3.该项包含本项工作所有工作内容含垂直运输机械等，未详尽列举特征，详见施工图纸、设计规范、施工方案事项均包含在综合单价中。 | E38: 间 | F38: 26 | G38: 265 | H38: =ROUND(F38*G38,2) -> 6890 | I38: =R38 -> 254.09 | J38: =F38*I38 -> 6606.34 | K38: 以间计量，按设计间的数量计算。 | L38: 全费用综合单价 | N38: =385*1.06*0.4 -> 163.24 | O38: 3.5 | P38: 45 | Q38: =N38+O38+P38 -> 211.74 | R38: =Q38*$R$4 -> 254.09 | T38: 254.09 | U38: =T38-I38 -> 0
A39: 33 | B39: 卫生纸盒 | C39: 1、成品304#不锈钢嵌入纸巾盒（抽纸盒垃圾箱一体）2、完成该项工作所需的全部工作内容，完成工作区域的安全文明施工,清理施工遗留下的垃圾。 | D39: [工作内容] 1.台面及支架制作、运输、安装 2.杆、环、盒、螺栓等配件安装 3.刷油漆 4.该项包含本项工作所有工作内容含垂直运输机械等，未详尽列举特征，详见施工图纸、设计规范、施工方案事项均包含在综合单价中。 | E39: 个 | F39: 59 | G39: 12.6 | H39: =ROUND(F39*G39,2) -> 743.4 | I39: =R39 -> 72.6 | J39: =F39*I39 -> 4283.4 | K39: 按设计图示个数以个计算 | L39: 全费用综合单价 | N39: 42 | O39: 0.5 | P39: 18 | Q39: =N39+O39+P39 -> 60.5 | R39: =Q39*$R$4 -> 72.6 | T39: 72.6 | U39: =T39-I39 -> 0
A40: 34 | B40: 烘手器 | C40: 1、成品烘手器安装；2.完成该项工作所需的全部工作内容，完成工作区域的安全文明施工,清理施工遗留下的垃圾。 | D40: [工作内容] 1.台面及支架制作、运输、安装 2.杆、环、盒、配件安装 3.刷油漆 4.该项包含本项工作所有工作内容含垂直运输机械等，未详尽列举特征，详见施工图纸、设计规范、施工方案事项均包含在综合单价中。 | E40: 副 | F40: 16 | G40: 417.6 | H40: =ROUND(F40*G40,2) -> 6681.6 | I40: =R40 -> 369 | J40: =F40*I40 -> 5904 | K40: 按设计图示以数量计算 | L40: 全费用综合单价 | N40: 288 | O40: 1.5 | P40: 18 | Q40: =N40+O40+P40 -> 307.5 | R40: =Q40*$R$4 -> 369 | T40: 369 | U40: =T40-I40 -> 0
...

Sheet 彭水二标段
A1: 彭水二标
A2: 项目名称：中铁建工集团有限公司重庆至黔江铁路站房工程2标项目经理部 | M2: 单位：元
A3: 序号 | B3: 项目名称 | C3: 项目特征 | D3: 工作内容 | E3: 单位 | F3: 工程量 | G3: 控制价 | I3: 上报金额 | K3: 工程量计算规则 | L3: 费用组成 | M3: 备注 | N3: 主材 | O3: 辅材 | P3: 人工 | Q3: 单价 | R3: 取费
G4: 不含税单价（元） | H4: 不含税合价（元） | I4: 不含税单价（元） | J4: 不含税合价（元） | R4: =南川一标段!$R$4 -> 1.2
A5: （一） | B5: 彭水南站
A6: （一） | B6: 站房区域
A7: 1 | B7: 花岗石地面 | C7: 1、铺25厚磨光花岗石板(六面涂刷石材保护剂),同色稀水泥浆擦 2、50厚1:3干硬性水泥粘结层,撒素水泥粉 3、水泥浆一道(内掺建筑胶) 4、嵌缝材料种类：按甲方要求嵌缝、打胶； 5、防护层材料：防护剂六面处理，满足设计和相关规范要求； 6、酸洗、打蜡要求：满足设计和相关规范要求； 7、楼地面伸缩缝、变形缝的处理； 8、其他：该项包含本项工作所有工作内容含垂直运输机械等，未详尽列举特征，详见施工图纸、设计规范、施工方案事项均包含在综合单价中。 (石材规格800*800) | D7: 1、基层清理、打磨；2、砂浆的制作、运输、找平、压实；3、面层的铺贴；4、水泥砂浆擦缝；5、局部部位花岗石切割、打磨，所有工作内容含垂直运输机械等，未详尽列举特征，详见施工图纸、设计规范、施工方案事项均包含在综合单价中 | E7: m2 | F7: 6650.56 | G7: 85 | H7: =F7*G7 -> 565297.6 | I7: =南川一标段!$I$7 -> 118.32 | J7: =F7*I7 -> 786894.26 | K7: 按设计图示尺寸以面积计算 | L7: 1、除甲供材外全费用综合单价； 2、甲供材：花岗石 | Q7: =N7+O7+P7 -> 0 | R7: =Q7*$R$4 -> 0 | S7: =_xlfn.DISPIMG("ID_7371E3C92DDC4979A83E0D9C73E49416",1) -> =DISPIMG("ID_7371E3C92DDC4979A83E0D9C73E49416",1)
A8: 2 | B8: 25MM厚深灰麻过门石 | C8: 1、铺25厚磨光花岗石板(六面涂刷石材保护剂),同色稀水泥浆擦 2、50厚1:3干硬性水泥粘结层,撒素水泥粉 3、水泥浆一道(内掺建筑胶) 4、嵌缝材料种类：按甲方要求嵌缝、打胶； 5、防护层材料：防护剂六面处理，满足设计和相关规范要求； 6、酸洗、打蜡要求：满足设计和相关规范要求； 7、楼地面伸缩缝、变形缝的处理； 8、其他：该项包含本项工作所有工作内容含垂直运输机械等，未详尽列举特征，详见施工图纸、设计规范、施工方案事项均包含在综合单价中。 (石材规格800*800) | D8: 1、基层清理、打磨；2、砂浆的制作、运输、找平、压实；3、面层的铺贴；4、水泥砂浆擦缝；5、局部部位过门石切割、打磨，所有工作内容含垂直运输机械等，未详尽列举特征，详见施工图纸、设计规范、施工方案事项均包含在综合单价中 | E8: m2 | F8: 20.58 | G8: 80 | H8: =F8*G8 -> 1646.4 | I8: =南川一标段!$I$16 -> 156 | J8: =F8*I8 -> 3210.48 | K8: 按设计图示尺寸以面积计算 | L8: 1、除甲供材外全费用综合单价； 2、甲供材：深灰麻过门石 | Q8: =N8+O8+P8 -> 0 | R8: =Q8*$R$4 -> 0
A9: 3 | B9: 防滑地砖地面(防水)架空 | C9: 1、面层：10厚玻化砖(防滑),同色水泥浆擦缝 2、30厚1:3干硬性水泥砂浆,表面撒水泥粉 3、嵌缝材料种类：按甲方要求嵌缝、打胶； 4、防护层材料：满足设计和相关规范要求； 5、酸洗、打蜡要求：满足设计和相关规范要求； 6、楼地面伸缩缝、变形缝的处理； 7、其他：该项包含本项工作所有工作内容含垂直运输机械等，未详尽列举特征，详见施工图纸、设计规范、施工方案事项均包含在综合单价中。 (地砖规格600*600) | D9: 1、基层清理、打磨；2、砂浆的制作、运输、找平、压实；3、面层的铺贴；4、水泥砂浆擦缝；5、局部部位防滑地砖切割、打磨，所有工作内容含垂直运输机械等，未详尽列举特征，详见施工图纸、设计规范、施工方案事项均包含在综合单价中 | E9: m2 | F9: 772.33 | G9: 120 | H9: =F9*G9 -> 92679.6 | I9: =南川一标段!$I$10 -> 165.22 | J9: =F9*I9 -> 127604.36 | K9: 按设计图示尺寸以面积计算 | L9: 全费用综合单价 | Q9: =N9+O9+P9 -> 0 | R9: =Q9*$R$4 -> 0
A10: 4 | B10: 水泥自流平楼面（非架空） | C10: 1、10-12厚水泥基自流平面层 2、涂刷自流平界面剂两道 3、40厚C20细石混凝土,随打随抹平,表面打磨或喷砂处理 4.水泥浆水灰比0.4~0.5结合层一道 | D10: 1.基层处理；2.涂界面剂；3.拌合自流平浆料；4.铺自流平面层；5、该项包含本项工作所有工作内容含垂直运输机械等，未详尽列举特征，详见施工图纸、设计规范、施工方案事项均包含在综合单价中 | E10: m2 | F10: 19.44 | G10: 47.92 | H10: =F10*G10 -> 931.56 | I10: =南川一标段!$I$13 -> 28.8 | J10: =F10*I10 -> 559.87 | K10: 按设计图示尺寸以面积计算 | L10: 全费用综合单价 | Q10: =N10+O10+P10 -> 0 | R10: =Q10*$R$4 -> 0
A11: 5 | B11: 防静电架空地面 | C11: 1、250高防静电活动地板,耐压强度10kN/㎡,配成套支架 2、10厚地砖(色另定) 3、20厚1:3干硬性砂浆,表面撒水泥粉 4、20厚1:3水泥砂浆 5、水泥浆一道(内掺建筑胶) 6、楼地面伸缩缝、变形缝的处理； | D11: 1、基层清理、打磨；2、水泥浆一道，内掺建筑胶；3、砂浆的制作、运输、找平、压实；4、面砖的铺贴；5、成套支架安装；6、安装陶瓷防静电架空地板；6、该项包含防静电架空地板的所有工作内容，所有工作内容含垂直运输机械等，未详尽列举特征，详见施工图纸、设计规范、施工方案事项均包含在综合单价中 | E11: m2 | F11: 266.08 | G11: 316.06 | H11: =F11*G11 -> 84097.24 | I11: =南川一标段!$I$14 -> 391.2 | J11: =F11*I11 -> 104090.5 | K11: 按设计图示尺寸以面积计算 | L11: 全费用综合单价 | Q11: =N11+O11+P11 -> 0 | R11: =Q11*$R$4 -> 0
A12: 6 | B12: 地砖地面（架空） | C12: 1、15防滑地砖，干水泥擦缝 2、30厚1:3干硬性水泥砂浆结合层，表面撒水泥粉 3、水泥砂浆一道（内掺建筑胶） 4、楼地面伸缩缝、变形缝的处理； | D12: 1、基层清理、打磨；2、砂浆的制作、运输、找平、压实；3、面层的铺贴；4、水泥砂浆擦缝；5、局部部位防滑地砖切割、打磨，所有工作内容含垂直运输机械等，未详尽列举特征，详见施工图纸、设计规范、施工方案事项均包含在综合单价中 | E12: m2 | F12: 1145.38 | G12: 120 | H12: =F12*G12 -> 137445.6 | I12: =南川一标段!$I$9 -> 165.22 | J12: =F12*I12 -> 189239.68 | K12: 按设计图示尺寸以面积计算 | L12: 全费用综合单价 | Q12: =N12+O12+P12 -> 0 | R12: =Q12*$R$4 -> 0
A13: 7 | B13: 防滑地砖地面(防水)架空 | C13: 1、面层：10厚玻化砖(防滑),同色水泥浆擦缝 2、30厚1:3干硬性水泥砂浆,表面撒水泥粉 3、嵌缝材料种类：按甲方要求嵌缝、打胶； 4、防护层材料：满足设计和相关规范要求； 5、酸洗、打蜡要求：满足设计和相关规范要求； 6、楼地面伸缩缝、变形缝的处理； 7、其他：该项包含本项工作所有工作内容含垂直运输机械等，未详尽列举特征，详见施工图纸、设计规范、施工方案事项均包含在综合单价中。 (地砖规格600*600) | D13: 1、基层清理、打磨；2、砂浆的制作、运输、找平、压实；3、面层的铺贴；4、水泥砂浆擦缝；5、局部部位防滑地砖切割、打磨，所有工作内容含垂直运输机械等，未详尽列举特征，详见施工图纸、设计规范、施工方案事项均包含在综合单价中 | E13: m2 | F13: 76.55 | G13: 120 | H13: =F13*G13 -> 9186 | I13: =南川一标段!$I$10 -> 165.22 | J13: =F13*I13 -> 12647.59 | K13: 按设计图示尺寸以面积计算 | L13: 全费用综合单价 | Q13: =N13+O13+P13 -> 0 | R13: =Q13*$R$4 -> 0
A14: 8 | B14: 防滑玻化砖梯面 | C14: 1、面层：10厚玻化砖(防滑),同色水泥浆擦缝 2、30厚1:3干硬性水泥砂浆,表面撒水泥粉 3、嵌缝材料种类：按甲方要求嵌缝、打胶，挡水条制作； 4、防护层材料：满足设计和相关规范要求； 5、酸洗、打蜡要求：满足设计和相关规范要求； 6、楼地面伸缩缝、变形缝的处理； 7、其他：该项包含本项工作所有工作内容含垂直运输机械等，未详尽列举特征，详见施工图纸、设计规范、施工方案事项均包含在综合单价中。 (地砖规格600*600) | D14: 1.基层清理、找平、打磨、甩浆、弹线、定位； 2.结合层施工； 3.防滑地砖铺贴，干水泥擦缝，挡水条制作； 4.材料的运输、堆码、清运及场内多次搬运； 5.单价已包括送样的材料费用、检验、试验等工作，还包括地砖铺贴前排版图设计工作; 6.配合安装队伍进行多次预留预埋及相关开槽、开洞的修补工作； 7.对已施工完成的成品及其他专业已完成的成品进行保护工作，无论是否由该单位导致的损坏，该单位都应履行修复处理责任； 8.对施工需要拆除或移动的材料，待施工完毕后，恢复原状； 9.完成工作区域的安全文明施工,清理施工遗留下的垃圾； 10.该项包含本项工作所有工作内容含垂直运输机械等，未详尽列举特征，详见施工图纸、设计规范、施工方案事项均包含在综合单价中。 | E14: m2 | F14: 105.08 | G14: 135 | H14: =F14*G14 -> 14185.8 | I14: =南川一标段!$I$11 -> 175.84 | J14: =F14*I14 -> 18477.27 | K14: 按设计图示尺寸以展开面积计算 | L14: 全费用综合单价 | Q14: =N14+O14+P14 -> 0 | R14: =Q14*$R$4 -> 0
A15: 9 | B15: 不锈钢踢脚 | C15: 1、板缝处理 2、1.0厚不锈钢板与卡件安装 3、金属踢脚卡件固定,间距500mm 4、基层墙面 | D15: 1、墙体基层处理；2、砂浆的制作、运输、安装；3、金属踢脚卡件固定及不锈钢板面的安装；4、该项包含不锈钢踢脚的所有工作内容，所有工作内容含垂直运输机械等，未详尽列举特征，详见施工图纸、设计规范、施工方案事项均包含在综合单价中 | E15: m2 | F15: 1.47 | G15: 272.98 | H15: =F15*G15 -> 401.28 | I15: =南川一标段!$I$71 -> 519.74 | J15: =F15*I15 -> 764.02 | K15: 按设计图示尺寸以面积计算 | L15: 全费用综合单价 | Q15: =N15+O15+P15 -> 0 | R15: =Q15*$R$4 -> 0
A16: 10 | B16: 干挂铝板墙面（含消防暗门） | C16: 1、2.5厚铝合金饰面面层,接缝处密缝(或10*10MM凹槽);(3 米以下加肋,衬6mm厚硅酸钙板)。 2、金属板材用抽芯铆钉或自攻螺钉固定于铝方型材纵横方向龙骨上,板材带折边采用搭接式,带挂耳采用对接式; 3、60X40X4铝方型材龙骨,横向间距同金属板材宽度,纵向间距同金属板材长度,用螺栓与角钢连接。 4、8#槽钢竖向龙骨连接件螺栓连接, 5、连接件与预埋板焊接 6、预埋件 7、墙面伸缩缝、变形缝； 其他：该项包含本项工作所有工作内容含垂直运输机械等，未详尽列举特征，详见施工图纸、设计规范、施工方案事项均包含在综合单价中。； | D16: 1、铝板下料；2、铝单板干挂；3、铝单板上铝格栅粘贴；4、与石材楼面接缝的处理；5、所有工作内容含垂直运输机械等，未详尽列举特征，详见施工图纸、设计规范、施工方案事项均包含在综合单价中 | E16: m2 | F16: 760.71 | G16: 120 | H16: =F16*G16 -> 91285.2 | I16: =南川一标段!$I$22 -> 177 | J16: =F16*I16 -> 134645.67 | K16: 按设计图示尺寸以面积计算 | L16: 1、除型钢龙骨及甲供材外全费用综合单价； 2、甲供材：铝板 | Q16: =N16+O16+P16 -> 0 | R16: =Q16*$R$4 -> 0
A17: 11 | B17: 柱面CA07木纹色铝单板 | C17: 1、2.5厚铝合金饰面面层,接缝处密缝(或10*10MM凹槽);(3 米以下加肋,衬6mm厚硅酸钙板)。 2、金属板材用抽芯铆钉或自攻螺钉固定于铝方型材纵横方向龙骨上,板材带折边采用搭接式,带挂耳采用对接式; 3、60X40X4铝方型材龙骨,横向间距同金属板材宽度,纵向间距同金属板材长度,用螺栓与角钢连接。 4、8#槽钢竖向龙骨连接件螺栓连接, 5、连接件与预埋板焊接 6、预埋件 7、墙面伸缩缝、变形缝； 其他：该项包含本项工作所有工作内容含垂直运输机械等，未详尽列举特征，详见施工图纸、设计规范、施工方案事项均包含在综合单价中。； | D17: 1、铝板下料；2、铝单板干挂；3、铝单板上铝格栅粘贴；4、与石材楼面接缝的处理；5、所有工作内容含垂直运输机械等，未详尽列举特征，详见施工图纸、设计规范、施工方案事项均包含在综合单价中 | E17: m2 | F17: 49.41 | G17: 120 | H17: =F17*G17 -> 5929.2 | I17: =南川一标段!$I$22 -> 177 | J17: =F17*I17 -> 8745.57 | K17: 按设计图示尺寸以面积计算 | L17: 1、除型钢龙骨及甲供材外全费用综合单价； 2、甲供材：铝板 | Q17: =N17+O17+P17 -> 0 | R17: =Q17*$R$4 -> 0
A18: 12 | B18: 候车厅方通背景墙 | C18: 候车厅铝方通背景墙 | D18: 1.基层材料种类、规格：12mm厚多层阻燃板基层+隔音棉 2.面层材料品种、规格、颜色：成品白色皮纹板块（12mm中纤板基层+胶粘+真空吸附+翻边钉扣），设计选样， 3.压条材料种类、规格：综合 4.成品保护、压条、嵌缝、各种螺栓、螺钉、射钉、固定配件等费用包含在综合单价中 5.其他：满足设计、施工验收规范及招标技术要求 6.所有工作内容含垂直运输机械等，未详尽列举特征，详见施工图纸、设计规范、施工方案事项均包含在综合单价中 | E18: m2 | F18: 516.8 | G18: 403.26 | H18: =F18*G18 -> 208404.77 | I18: =R18 -> 658.78 | J18: =F18*I18 -> 340457.5 | K18: 按设计图示尺寸以面积计算 | L18: 全费用综合单价 | N18: =主材表!L37 -> 353.98 | O18: 65 | P18: 130 | Q18: =N18+O18+P18 -> 548.98 | R18: =Q18*$R$4 -> 658.78 | S18: =_xlfn.DISPIMG("ID_4B889F83850B41C88BEAC61337EDA281",1) -> =DISPIMG("ID_4B889F83850B41C88BEAC61337EDA281",1)
A19: 13 | B19: 商务ME06印花不锈钢 | C19: 1、1.2mm印花不锈钢 2、双层18mm阻燃版基层板 | D19: 1.龙骨材料种类、规格、中距：轻钢龙骨，规格间距综合 2.防护材料种类：以型材及型材间需要焊接位置都镀锌处理满足防锈及防火要求为止3.基层材料品种、规格：双层18mm阻燃版基层板 4.面层材料品种、规格、颜色：不锈钢面层 5.压条材料种类、规格：综合 6.成品保护、压条、嵌缝、各种螺栓、螺钉、射钉、固定配件及面层开孔（开孔符合安装要求）等费用包含在综合单价中 7.其他：所有工作内容含垂直运输机械等，未详尽列举特征，详见施工图纸、设计规范、施工方案事项均包含在综合单价中 | E19: m2 | F19: 75.35 | G19: 412.27 | H19: =F19*G19 -> 31064.54 | I19: =R19 -> 978.6 | J19: =F19*I19 -> 73737.51 | K19: 按设计图示尺寸以面积计算 | L19: 全费用综合单价 | N19: =主材表!O36 -> 580 | O19: =30+35*2+5.5 -> 105.5 | P19: 130 | Q19: =N19+O19+P19 -> 815.5 | R19: =Q19*$R$4 -> 978.6 | S19: =_xlfn.DISPIMG("ID_872B2FD62EDA4309BD1AE6E0417C0DF4",1) -> =DISPIMG("ID_872B2FD62EDA4309BD1AE6E0417C0DF4",1)
A20: 14 | B20: 干挂花岗岩墙面（含消防暗门） | C20: 1、干挂25mm厚石材墙面（含消防暗门） 2、石材背栓挂件,L50*5角钢连接件与横向龙骨(L50*5角钢)螺栓连接 3、L50*5角钢横向龙骨,与竖向槽钢(8#槽钢)焊接 4、8#槽钢,与连接件焊接, 5、连接件,与预埋件M3焊接 6、预埋件M3 7、墙面伸缩缝、变形缝的处理； 8、根据安装需要开孔 9、其他：该项包含本项工作所有工作内容含垂直运输机械等，未详尽列举特征，详见施工图纸、设计规范、施工方案事项均包含在综合单价中。； | D20: 2.安装方式：干挂 3.面层材料品种、规格、颜色：干挂花岗石石材,表面作晶面处理 4.龙骨材料：竖向主龙骨贯通,固定在墙体上下端(梁或楼板),龙骨截面尺寸根据墙体高度确定,次龙骨在主龙骨之间,龙骨间距依据面材分格尺寸,龙骨刷黑漆 5、所有工作内容含垂直运输机械等，未详尽列举特征，详见施工图纸、设计规范、施工方案事项均包含在综合单价中 | E20: m2 | F20: 2193.59 | G20: 150 | H20: =F20*G20 -> 329038.5 | I20: =南川一标段!$I$103 -> 255.6 | J20: =F20*I20 -> 560681.6 | K20: 按设计图示尺寸以面积计算（有吊顶房间算至吊顶底，无吊顶房间算至梁底或者板底） | L20: 1、除型钢龙骨及甲供材外全费用综合单价； 2、甲供材：花岗石 | Q20: =N20+O20+P20 -> 0 | R20: =Q20*$R$4 -> 0
A21: 15 | B21: 白色无机涂料墙面(A级) | C21: 1、喷(刷、辊)无机内墙薄涂涂料2道 2、满刮2厚腻子砂磨平 3、其他：该项包含本项工作所有工作内容含垂直运输机械等，未详尽列举特征，详见施工图纸、设计规范、施工方案事项均包含在综合单价中。 | D21: 1、墙体基层处理；2、刮腻子；3、涂料的制作、运输；4、喷面浆或涂料；5、该项包含涂料墙面的所有工作内容，所有工作内容含垂直运输机械等，未详尽列举特征，详见施工图纸、设计规范、施工方案事项均包含在综合单价中 | E21: m2 | F21: 4422.81 | G21: 27 | H21: =F21*G21 -> 119415.87 | I21: =南川一标段!$I$20 -> 44.4 | J21: =F21*I21 -> 196372.76 | K21: 按设计图示尺寸以面积计算（有吊顶房间算至吊顶底，无吊顶房间算至梁底或者板底） | L21: 全费用综合单价 | Q21: =N21+O21+P21 -> 0 | R21: =Q21*$R$4 -> 0
A22: 16 | B22: 白色无机涂料吸音墙面(A级) | C22: 1.无机涂料 2.20厚矿物纤维吸声喷涂层 3.6厚1:3水泥砂浆找平 4.7厚1:3水泥砂浆打底扫毛（内掺建筑胶） 5.基层清理 | D22: 1、墙体基层处理；2、刮腻子；3、涂料的制作、运输；4、矿物纤维吸声喷涂、喷面浆或涂料；5、该项包含涂料墙面的所有工作内容，所有工作内容含垂直运输机械等，未详尽列举特征，详见施工图纸、设计规范、施工方案事项均包含在综合单价中 | E22: m2 | F22: 3113.59 | G22: 32 | H22: =F22*G22 -> 99634.88 | I22: =南川一标段!$I$27 -> 44.4 | J22: =F22*I22 -> 138243.4 | K22: 按设计图示尺寸以面积计算（有吊顶房间算至吊顶底，无吊顶房间算至梁底或者板底） | L22: 全费用综合单价 | Q22: =N22+O22+P22 -> 0 | R22: =Q22*$R$4 -> 0
A23: 17 | B23: 防水面砖墙面 | C23: 1、同色水泥擦缝 2、8-10厚墙面砖(粘贴前墙砖充分浸湿) 3、8厚1:2水泥砂浆粘结层(内掺建筑胶) 4、缝宽、嵌缝材料：按甲方要求嵌缝、打胶； 5、酸洗、打蜡要求：满足设计和相关规范要求； 6、墙面伸缩缝、变形缝的处理； 7、根据安装需要开孔 8、其他：该项包含本项工作所有工作内容含垂直运输机械等，未详尽列举特征，详见施工图纸、设计规范、施工方案事项均包含在综合单价中。 (600×300墙砖) | D23: 1、墙体基层处理；2、水泥砂浆的制作、运输；3、粘贴墙面砖；4、局部部位面砖切割、打磨；5、水泥擦缝；6、该项包含玻化砖墙面的所有工作内容，所有工作内容含垂直运输机械等，未详尽列举特征，详见施工图纸、设计规范、施工方案事项均包含在综合单价中 | E23: m2 | F23: 2340.9 | G23: 120 | H23: =F23*G23 -> 280908 | I23: =南川一标段!$I$21 -> 153.02 | J23: =F23*I23 -> 358204.52 | K23: 按设计图示尺寸以面积计算（有吊顶房间算至吊顶底） | L23: 全费用综合单价 | Q23: =N23+O23+P23 -> 0 | R23: =Q23*$R$4 -> 0
A24: 18 | B24: 防火玻璃隔断（旅客服务房间） | C24: 1、施工部位：旅客服务室外围隔断； 2、面层材料：8HS+1.52PVB+8HS（low-e）+12Ar+27mm全超白中空夹胶防火玻璃（A类，1小时防火），具体施工要求与细部分格等详见图纸及方案，包含通长支座、副框、扣盖、压板、压块、垫块、连接件等，不同规格的钢板等； 3、底部塞防火岩棉、外包1.5mm厚镀锌钢板； 4、底部及顶部采用通长钢U槽连接； 5、接缝、嵌缝及塞口材料：泡沫棒、结构密封胶、耐候密封胶、EPDM胶条、防火胶条等详图纸及方案要求； 6、所有保温防火封堵、不锈钢自攻钉、不锈钢销钉、不锈钢螺栓、断热条、防脱螺钉、硬质玻璃垫块、钢托板、φ12压力间隔套等其他所有辅材需满足图纸及方案要求，其施工费及材料费等均已含在综合单价中； 7、与其他装饰面收口打胶； | D24: 1、防火岩棉及镀锌钢板的制作、运输、安装；2、型材的制作、运输、安装；3、玻璃安装；4、嵌缝、塞口；5、清洗；6、施工区域的安全文明施工；7、该项包含本项工作所有工作内容，未详尽列举的图纸、方案事项均包含在综合单价中 | E24: m2 | F24: 153.68 | G24: 1429.33 | H24: =F24*G24 -> 219659.43 | I24: =南川一标段!$I$45 -> 1243.27 | J24: =F24*I24 -> 191065.73 | K24: 按设计图示尺寸以面积计算 | L24: 全费用综合单价 | Q24: =N24+O24+P24 -> 0 | R24: =Q24*$R$4 -> 0
A25: 19 | B25: 铝合金条板(锤片)吊顶（候车大厅） | C25: 1、铝合金条板与配套专用龙骨固定(宽150mm,缝90mm,厚1.5mm) 2、与铝合金方通配套的专用龙骨,间距≤1200,用吊件与钢筋吊杆连接后找平 3、10号镀锌低碳钢丝(或%%C6钢筋)吊杆,双向中距≤1200,吊杆上部与板底预留吊环(勾)固定 4、现浇钢筋混凝土板底预留%%C10钢筋吊环(勾),双向中距≤1200(吊杆长度超过1.5米后需要做反支撑,吊杆长度超过2.5米需做转换层,做法详见二次结构施工安装详图)(转换层另列） 5、天棚伸缩缝、变形缝； 其他：该项包含本项工作所有工作内容含垂直运输机械等，未详尽列举特征，详见施工图纸、设计规范、施工方案事项均包含在综合单价中。； | D25: 1、钢结构转换层制作、安装；2、安装龙骨；3、铝条板面层安装；4、所有工作内容含垂直运输机械等，未详尽列举特征，详见施工图纸、设计规范、施工方案事项均包含在综合单价中 | E25: m2 | F25: 3810.7 | G25: 125 | H25: =F25*G25 -> 476337.5 | I25: =南川一标段!$I$33 -> 182.4 | J25: =F25*I25 -> 695071.68 | K25: 按设计图示尺寸以铝条板吊顶水平投影面积计算，其中筒灯所在的位置的宽度对应的面积不计算 | L25: 1、除型钢龙骨及甲供材外全费用综合单价； 2、甲供材：铝板 | Q25: =N25+O25+P25 -> 0 | R25: =Q25*$R$4 -> 0
A26: 20 | B26: 铝合金单板装饰吊顶（候车大厅） | C26: 1、2.5厚铝合金单板与配套专用龙骨固定 2、与铝合金单板配套的专用下层副龙骨联结,间距≤600 3、与安装型式配套的专用上层主龙骨,间距≤1200,用吊件与钢筋吊杆联结后找平 4、10号镀锌低碳钢丝(或%%C8钢筋)吊杆,双向中距≤1200,吊杆上部与板底预留吊环固定 5、现浇钢筋混凝土板底预留%%C10钢筋吊环,双向中距≤1200 6、天棚伸缩缝、变形缝； 其他：该项包含本项工作所有工作内容含垂直运输机械等，未详尽列举特征，详见施工图纸、设计规范、施工方案事项均包含在综合单价中。 | D26: 1、钢结构转换层制作、安装；2、安装龙骨；3、铝单板片面层安装；4、所有工作内容含垂直运输机械等，未详尽列举特征，详见施工图纸、设计规范、施工方案事项均包含在综合单价中 | E26: m2 | F26: 5230.12 | G26: 135 | H26: =F26*G26 -> 706066.2 | I26: =南川一标段!$I$31 -> 182.4 | J26: =F26*I26 -> 953973.89 | K26: 按铝单板吊顶的水平投影面积计算 | L26: 1、除型钢龙骨及甲供材外全费用综合单价； 2、甲供材：铝板 | Q26: =N26+O26+P26 -> 0 | R26: =Q26*$R$4 -> 0
A27: 21 | B27: CA02铝单板（印花）吊顶 | C27: 1、2.5厚铝单板印花与配套专用龙骨固定 2、与铝合金单板配套的专用下层副龙骨联结,间距≤600 3、与安装型式配套的专用上层主龙骨,间距≤1200,用吊件与钢筋吊杆联结后找平 4、10号镀锌低碳钢丝(或%%C8钢筋)吊杆,双向中距≤1200,吊杆上部与板底预留吊环固定 5、现浇钢筋混凝土板底预留%%C10钢筋吊环,双向中距≤1200 6、天棚伸缩缝、变形缝； 其他：该项包含本项工作所有工作内容含垂直运输机械等，未详尽列举特征，详见施工图纸、设计规范、施工方案事项均包含在综合单价中。 | D27: 1、后置件、骨架的制作、运输、安装；2、铝板下料；3、铝单板干挂；4、铝单板上铝格栅粘贴；5、与石材楼面接缝的处理；6、所有工作内容含垂直运输机械等，未详尽列举特征，详见施工图纸、设计规范、施工方案事项均包含在综合单价中 | E27: m2 | F27: 125.08 | G27: 135 | H27: =F27*G27 -> 16885.8 | I27: =南川一标段!$I$31 -> 182.4 | J27: =F27*I27 -> 22814.59 | K27: 按设计图示尺寸以室外可视铝板面积计算，其中：铝板梁面和铝单板吊顶分界线为最内侧的垂直方向的铝单板边线 | L27: 1、除型钢龙骨及甲供材外全费用综合单价； 2、甲供材：铝板 | Q27: =N27+O27+P27 -> 0 | R27: =Q27*$R$4 -> 0
A28: 22 | B28: 铝合金扣板顶棚 | C28: 1、600*600*1.0铝合金扣板(折边20) 2、与铝合金扣板配套的专用暗架龙骨,间距≤300,通过十字连扣连接件与承载龙骨连接 3、D38承载龙骨,间距≤1200,用吊杆与钢筋吊杆联结后找平 4、10厚镀锌低碳钢丝(或%%C8钢筋)吊杆,双向中距≤1200,吊杆上部与板底(或钢结构)预留吊环(勾)固定 5、结构层预埋%%C10(或钢结构预留)钢筋吊环(勾),双向中距≤1200 6、天棚伸缩缝、变形缝； 其他：该项包含本项工作所有工作内容含垂直运输机械等，未详尽列举特征，详见施工图纸、设计规范、施工方案事项均包含在综合单价中。 | D28: 1、吊杆的制作、运输、安装；2、铝板下料； 3、铝扣板安装以及与墙柱面接缝处理； 4、所有工作内容含垂直运输机械等，未详尽列举特征，详见施工图纸、设计规范、施工方案事项均包含在综合单价中 | E28: m2 | F28: 693.33 | G28: 136.14 | H28: =F28*G28 -> 94389.95 | I28: =南川一标段!$I$29 -> 160.04 | J28: =F28*I28 -> 110960.53 | K28: 按设计图示尺寸以面积计算 | L28: 除型钢龙骨外的全费用综合单价 | Q28: =N28+O28+P28 -> 0 | R28: =Q28*$R$4 -> 0
A29: 23 | B29: 9.5mm双层石膏板轻钢龙骨涂料跌级 | C29: 1、9.5mm厚双层石膏面层板面层,规格592x592 2、T型次龙骨TB24x30,间距600,与主龙骨插接 3、T型主龙骨TB24X30,间距600,通过D-T挂件与承载龙骨连接 4、D38承载龙骨,间距1200,用吊件与钢筋吊杆联结后找平 5、%C8螺纹吊杆,双向中距≤1200,吊杆上部与吊顶转换层固定 7、50*5镀锌角钢吊顶转换层,井字型网格间距≤2400*1200(转换层另列） 8、天棚伸缩缝、变形缝； 其他：该项包含本项工作所有工作内容含垂直运输机械等，未详尽列举特征，详见施工图纸、设计规范、施工方案事项均包含在综合单价中。 | D29: 1.吊顶形式、吊杆规格、高度：跌级，Φ8吊杆楼板固定，间距综合 2.龙骨材料种类、规格、中距：主次轻钢龙骨，间距综合；横撑轻钢龙骨，间距综合 3.面层材料品种、规格：双层9.5mm厚纸面石膏板，固定方式综合 4.防护材料种类：需要焊接位置都镀锌处理满足防锈及防火要求 5.压条、嵌缝、防护、收边线、灯槽、配套螺栓、螺钉、紧固件、弹线、窗帘盒，根据安装专业要求所开洞口（喷淋孔、灯孔、检修口、通风口）等费用均包含在综合单价中 6.清单工程量按面层水平投影面积计算,造型，石膏板立面等增加的工料包含在综合单价中考虑 7.其他：所有工作内容含垂直运输机械等，未详尽列举特征，详见施工图纸、设计规范、施工方案事项均包含在综合单价中 | E29: m2 | F29: 298.89 | G29: 166.94 | H29: =F29*G29 -> 49896.7 | I29: =R29 -> 177.6 | J29: =F29*I29 -> 53082.86 | K29: 按设计图示以水平投影面积计算 | L29: 全费用综合单价 | N29: =4.5 -> 4.5 | O29: =26+10*2+4.5 -> 50.5 | P29: =35+18*2+22 -> 93 | Q29: =N29+O29+P29 -> 148 | R29: =Q29*$R$4 -> 177.6
A30: 24 | B30: 石膏线100*100 | C30: 石膏装饰线条 100*100mm | D30: [工作内容] 1.基层清理 2.刮腻子 3.刷防护材料、油漆 | E30: m | F30: 143.06 | G30: 15 | H30: =F30*G30 -> 2145.9 | I30: =R30 -> 43.2 | J30: =F30*I30 -> 6180.19 | K30: 按设计图示尺寸以长度计算 | L30: 全费用综合单价 | N30: 12.5 | O30: 3.5 | P30: 20 | Q30: =N30+O30+P30 -> 36 | R30: =Q30*$R$4 -> 43.2
A31: 25 | B31: 硅酸钙板(防潮石膏板)涂料顶棚(防水) | C31: 1、喷(刷、辊)涂料面层两遍(每道间隔2小时) 2、封底漆一道(干燥后再做面层) 3、满刮2厚面层耐水腻子找平,板面接缝处贴嵌缝带,刮腻子抹平 4、错缝粘贴第二层9.5厚耐水耐火纸面石膏板 5、9.5厚耐水耐火纸面石膏板用自攻螺丝与龙骨固定,中距≤200,螺丝距板长边≥10,短边≥15 6、U型轻钢覆面横撑龙骨CB60x27,间距1200,用挂插件与次龙骨联结 7、U型轻钢覆面次龙骨CB60x27,间距400,用挂件与承接龙骨联结 8、U型轻钢承接龙骨CS50x15,间距≤1200,用吊杆与钢筋吊杆联结后找平 9、%%C8钢筋吊杆并加反支撑,双向中距≤1200,吊杆上部与预留钢筋吊环固定 10、现浇钢筋混凝土板底预埋%%C10钢筋吊环(勾),双向中距≤1200 11、天棚伸缩缝、变形缝； 其他：该项包含本项工作所有工作内容含垂直运输机械等，未详尽列举特征，详见施工图纸、设计规范、施工方案事项均包含在综合单价中。 | D31: 1、天棚基层处理；2、后置件、骨架的制作、运输、安装；3、硅酸钙板安装；4、表面涂刷乳胶漆，压条安装；5、该项包含硅酸钙板吊顶的所有工作内容，所有工作内容含垂直运输机械等，未详尽列举特征，详见施工图纸、设计规范、施工方案事项均包含在综合单价中 | E31: m2 | F31: 90.63 | G31: 166.94 | H31: =F31*G31 -> 15129.77 | I31: =$I$29 -> 177.6 | J31: =F31*I31 -> 16095.89 | K31: 按设计图示尺寸以硅酸钙板吊顶水平投影面积计算 | L31: 全费用综合单价 | Q31: =N31+O31+P31 -> 0 | R31: =Q31*$R$4 -> 0
A32: 26 | B32: 石膏板吊顶(轻钢龙骨)(A级)[办公用房、走道 | C32: 1、12厚石膏面层板面层,规格592x592 2、T型次龙骨TB24x30,间距600,与主龙骨插接 3、T型主龙骨TB24X30,间距600,通过D-T挂件与承载龙骨连接 4、D38承载龙骨,间距1200,用吊件与钢筋吊杆联结后找平 5、%%C8螺纹吊杆,双向中距≤1200,吊杆上部与吊顶转换层固定 7、50*5镀锌角钢吊顶转换层,井字型网格间距≤2400*1200(转换层另列） | D32: 1、天棚基层处理；2、后置件、骨架的制作、运输、安装；3、轻钢龙骨石膏板安装；4、该项包含轻钢龙骨石膏板吊顶的所有工作内容，所有工作内容含垂直运输机械等，未详尽列举特征，详见施工图纸、设计规范、施工方案事项均包含在综合单价中 | E32: m2 | F32: 1251.43 | G32: 108.1 | H32: =F32*G32 -> 135279.58 | I32: =R32 -> 108.6 | J32: =F32*I32 -> 135905.3 | K32: 按设计图示尺寸以轻钢龙骨石膏板吊顶水平投影面积计算 | L32: 全费用综合单价 | O32: =11.5+26 -> 37.5 | P32: =35+18 -> 53 | Q32: =N32+O32+P32 -> 90.5 | R32: =Q32*$R$4 -> 108.6
A33: 27 | B33: 白色无机涂料顶棚(A级） | C33: 1、防火型无机耐擦洗涂料两道饰面(白色) 2、2厚面层耐水腻子刮平 3、其他：该项包含本项工作所有工作内容含垂直运输机械等，未详尽列举特征，详见施工图纸、设计规范、施工方案事项均包含在综合单价中。 | D33: 1、天棚基层处理；2、满刮腻子一遍，砂抹平；3、涂料的制作、运输、喷涂；4、该项包含无机涂料天棚的所有工作内容，所有工作内容含垂直运输机械等，未详尽列举特征，详见施工图纸、设计规范、施工方案事项均包含在综合单价中 | E33: m2 | F33: 428.03 | G33: 32 | H33: =F33*G33 -> 13696.96 | I33: =南川一标段!$I$28 -> 44.4 | J33: =F33*I33 -> 19004.53 | K33: 按设计图示尺寸以面积计算（梁侧并入此项计算） | L33: 全费用综合单价 | Q33: =N33+O33+P33 -> 0 | R33: =Q33*$R$4 -> 0
A34: 28 | B34: 白色无机涂料吸音顶棚(A级) | C34: 1、白色无机涂料 2、20厚矿物纤维吸声喷涂层 3、其他：该项包含本项工作所有工作内容含垂直运输机械等，未详尽列举特征，详见施工图纸、设计规范、施工方案事项均包含在综合单价中。 | D34: 1、天棚基层处理；2、满刮腻子一遍，砂抹平；3、矿物纤维吸声喷涂、涂料的制作、运输、喷涂；4、该项包含无机涂料天棚的所有工作内容，所有工作内容含垂直运输机械等，未详尽列举特征，详见施工图纸、设计规范、施工方案事项均包含在综合单价中 | E34: m2 | F34: 79.5 | G34: 32 | H34: =F34*G34 -> 2544 | I34: =南川一标段!$I$27 -> 44.4 | J34: =F34*I34 -> 3529.8 | K34: 按设计图示尺寸以面积计算（梁侧并入此项计算） | L34: 全费用综合单价 | Q34: =N34+O34+P34 -> 0 | R34: =Q34*$R$4 -> 0
A35: 29 | B35: 吊顶转换层 | C35: 主次龙骨50*50*5镀锌方管、埋板等 | D35: 1、包含完成本项目所需要的材料费，转换层钢龙骨/铝板龙骨制作安装、材料运输、装卸、场内外多次倒运、试验检测等所有费用 2、包工作面清理、成品保护、负责工作区域的安全文明施工,施工遗留垃圾的清理及外运等； 3、含材料费管理费、措施费、夜间施工费、赶工措施费、安全文明施工费、规费、税金、临近既有线施工费用以及可能出现的人员窝工及机械停滞费用等施工所发生的一切费用 所有工作内容含垂直运输机械等，未详尽列举特征，详见施工图纸、设计规范、施工方案事项均包含在综合单价中 | E35: t | F35: 122 | G35: 8726.4 | H35: =F35*G35 -> 1064620.8 | I35: =南川一标段!$I$47 -> 10536 | J35: =F35*I35 -> 1285392 | K35: 按照设计图示尺寸以重量进行计算 | L35: 全费用综合单价 | Q35: =N35+O35+P35 -> 0 | R35: =Q35*$R$4 -> 0
A36: 30 | B36: 干挂型钢龙骨 | C36: 1、石材、铝板墙面龙骨、埋板等； 2、骨架种类、规格：具体规格、尺寸、连接方式详见图纸； | D36: 1.镀锌型钢龙骨转换层、骨架的制作、运输、安装、刷漆 2.该项包含本项工作所有工作内容，所有工作内容含垂直运输机械等，所有工作内容含垂直运输机械等，未详尽列举特征，详见施工图纸、设计规范、施工方案事项均包含在综合单价中。 | E36: t | F36: 70.9 | G36: 8726.4 | H36: =F36*G36 -> 618701.76 | I36: =南川一标段!$I$48 -> 10536 | J36: =F36*I36 -> 747002.4 | K36: 按设计图示尺寸以实际安装根数以重量计算 | L36: 此项工作的全费用综合单价 | Q36: =N36+O36+P36 -> 0 | R36: =Q36*$R$4 -> 0
A37: 31 | B37: 天棚喷刷深灰色涂料 | C37: 1、基层类型：砼天棚；2、深灰A级无机涂料喷涂，厚度、装饰效果满足设计要求3、超高增加的措施费用 | D37: [工作内容] 1.基层清理 2.刮腻子 3.刷、喷涂料 | E37: m2 | F37: 3900 | G37: 12.89 | H37: =F37*G37 -> 50271 | I37: =南川一标段!$I$34 -> 24.6 | J37: =F37*I37 -> 95940 | K37: 按设计图示尺寸以面积计算（梁侧并入此项计算） | L37: 全费用综合单价 | Q37: =N37+O37+P37 -> 0 | R37: =Q37*$R$4 -> 0
A38: 32 | B38: 洗漱台 | C38: 1、石材面台 2、石材挡水 3、2.5MM铝单板挡板 | D38: 1.材料品种、规格、品牌、颜色：详设计图纸 2.基层：阻燃板基层厚度综合 3.支架、配件品种、规格、品牌：热镀锌矩管，规格间距综合 5.其他：所有工作内容含垂直运输机械等，未详尽列举特征，详见施工图纸、设计规范、施工方案事项均包含在综合单价中 | E38: m | F38: 24.79 | G38: 420.78 | H38: =F38*G38 -> 10431.14 | I38: =南川一标段!$I$35 -> 639.9 | J38: =F38*I38 -> 15863.12 | K38: 按设计图示尺寸长度以“米”计量。 | L38: 除基层龙骨外，此项工作的全费用综合单价 | Q38: =N38+O38+P38 -> 0 | R38: =Q38*$R$4 -> 0
A39: 33 | B39: 母婴设施 | C39: 成品母婴设备安装，完成该项工作所需的全部工作内容，完成工作区域的安全文明施工,清理施工遗留下的垃圾。 | D39: [工作内容] 1.台面及支架运输、安装 2.杆、环、盒、配件安装 3.刷油漆 | E39: 副 | F39: 1 | G39: 16920 | H39: =ROUND(F39*G39,2) -> 16920 | I39: =南川一标段!$I$51 -> 20304 | J39: =F39*I39 -> 20304 | K39: 按设计图示个数以套计算 | L39: 此项工作的全费用综合单价 | Q39: =N39+O39+P39 -> 0 | R39: =Q39*$R$4 -> 0
A40: 34 | B40: 镜面玻璃 | C40: 1.30*30mm方管龙骨（刷防火、防腐） 2.6mm厚双层硅酸钙板基层（涂刷防腐） 3.5mm厚银镜及安装。 4.顶部及底部LED贴片灯带、灯槽制作安装 5.不锈钢边框包边；6.完成该项工作所需的全部工作内容 | D40: [工作内容] 1.基层安装 2.玻璃及框制作、运输、安装 3.该项包含本项工作所有工作内容，所有工作内容含垂直运输机械等，所有工作内容含垂直运输机械等，未详尽列举特征，详见施工图纸、设计规范、施工方案事项均包含在综合单价中。 | E40: m2 | F40: 27 | G40: 220 | H40: =F40*G40 -> 5940 | I40: =南川一标段!$I$36 -> 526.8 | J40: =F40*I40 -> 14223.6 | K40: 按设计图示尺寸以面积计算 | L40: 除基层龙骨外，此项工作的全费用综合单价 | Q40: =N40+O40+P40 -> 0 | R40: =Q40*$R$4 -> 0
...

Sheet 巴南三标段
A1: 重庆站房2标装饰装修三标段巴南站分包工程招标控制价审核表
A2: 项目名称：中铁建工集团有限公司重庆至黔江铁路站房工程2标项目经理部 | N2: 单位：元
A3: 序号 | B3: 项目名称 | C3: 项目特征 | D3: 工作内容 | E3: 单位 | F3: 工程量 | G3: 控制价 | I3: 上报金额 | K3: 单价差额 | L3: 工程量计算规则 | M3: 费用组成 | N3: 备注 | O3: 主材 | P3: 辅材 | Q3: 人工 | R3: 单价 | S3: 取费
G4: 不含税单价（元） | H4: 不含税合价（元） | I4: 不含税单价（元） | J4: 不含税合价（元） | S4: =南川一标段!$R$4 -> 1.2
A5: 一 | B5: 巴南站
A6: （一） | B6: 站房非公共区
A7: 1 | B7: 花岗石地面 | C7: 1、铺25厚磨光花岗石板(六面涂刷石材保护剂),同色稀水泥浆擦 2、50厚1:3干硬性水泥粘结层,撒素水泥粉 3、水泥浆一道(内掺建筑胶) 4、嵌缝材料种类：按甲方要求嵌缝、打胶； 5、防护层材料：防护剂六面处理，满足设计和相关规范要求； 6、酸洗、打蜡要求：满足设计和相关规范要求； 7、楼地面伸缩缝、变形缝的处理； 8、其它：该项包含本项工作所有工作内容含垂直运输机械等，未详尽列举特征，详见施工图纸、设计规范、施工方案事项均包含在综合单价中。 (石材规格800*800) | D7: 1.清理基层，试排弹线，锯板磨边，调铺砂浆；铺板、灌缝擦缝、清理净面等全部操作过程； 2.找平层、结合层施工； 3.石材刷防护液、铺贴、水泥浆勾缝； 4.材料的运输、堆码、清运及场内多次搬运； 5.综合单价包含切角、倒角、磨边、加厚、弧形加工、嵌缝、拉槽、排版损耗、晶面处理等费用，送样的材料费用、检验、试验等工作费用，还包括地砖铺贴前排版图设计工作; 6.配合安装队伍进行多次预留预埋及相关开槽、开洞的修补工作； 7.对已施工完成的成品及其他专业已完成的成品进行保护工作，无论是否由该单位导致的损坏，该单位都应履行修复处理责任； 8.对施工需要拆除或移动的材料，待施工完毕后，恢复原状； 9.完成工作区域的安全文明施工,清理施工遗留下的垃圾； 10.该项包含本项工作所有工作内容含垂直运输机械等，未详尽列举特征，详见施工图纸、设计规范、施工方案事项均包含在综合单价中。 | E7: m2 | F7: 365.77 | G7: 85 | H7: =F7*G7 -> 31090.45 | I7: =南川一标段!$I$7 -> 118.32 | J7: =F7*I7 -> 43277.91 | K7: =G7-I7 -> -33.32 | L7: 按设计图示尺寸以面积计算。 | M7: 除甲供外，此项工作的全费用综合单价 | N7: 甲供材料：石材 | R7: =O7+P7+Q7 -> 0 | S7: =R7*$S$4 -> 0
A8: 2 | B8: 防滑地砖地面 | C8: 1、面层：10厚玻化砖(防滑),同色水泥浆擦缝 2、30厚1:3干硬性水泥砂浆,表面撒水泥粉 3、嵌缝材料种类：按甲方要求嵌缝、打胶； 4、防护层材料：满足设计和相关规范要求； 5、酸洗、打蜡要求：满足设计和相关规范要求； 6、楼地面伸缩缝、变形缝的处理； 7、其它：该项包含本项工作所有工作内容含垂直运输机械等，未详尽列举特征，详见施工图纸、设计规范、施工方案事项均包含在综合单价中。 (地砖规格600*600) | D8: 1.基层清理、找平、打磨、甩浆、弹线、定位； 2.结合层施工； 3.防滑地砖铺贴，干水泥擦缝； 4.材料的运输、堆码、清运及场内多次搬运； 5.单价已包括送样的材料费用、检验、试验等工作，还包括地砖铺贴前排版图设计工作; 6.配合安装队伍进行多次预留预埋及相关开槽、开洞的修补工作； 7.对已施工完成的成品及其他专业已完成的成品进行保护工作，无论是否由该单位导致的损坏，该单位都应履行修复处理责任； 8.对施工需要拆除或移动的材料，待施工完毕后，恢复原状； 9.完成工作区域的安全文明施工,清理施工遗留下的垃圾； 10.该项包含本项工作所有工作内容含垂直运输机械等，未详尽列举特征，详见施工图纸、设计规范、施工方案事项均包含在综合单价中。 | E8: m2 | F8: 664.72 | G8: 120 | H8: =F8*G8 -> 79766.4 | I8: =南川一标段!$I$10 -> 165.22 | J8: =F8*I8 -> 109825.04 | K8: =G8-I8 -> -45.22 | L8: 按设计图示尺寸以面积计算。 | M8: 此项工作的全费用综合单价 | R8: =O8+P8+Q8 -> 0 | S8: =R8*$S$4 -> 0
A9: 3 | B9: 防静电架空地面 | C9: 1、300高防静电活动地板,耐压强度10kN/㎡,配成套支架 2、10厚地砖(色另定) 3、20厚1:3干硬性砂浆,表面撒水泥粉 4、其它：该项包含本项工作所有工作内容含垂直运输机械等，未详尽列举特征，详见施工图纸、设计规范、施工方案事项均包含在综合单价中。 | D9: 1.基层清理、找平、打磨、甩浆、弹线、定位； 2.水泥砂浆找平； 3.安装固定支柱、横梁，防静电活动地板铺装； 4.材料的运输、堆码、清运及场内多次搬运； 5.单价已包括送样的材料费用、检验、试验等工作; 6.配合安装队伍进行多次预留预埋及相关开槽、开洞的修补工作； 7.对已施工完成的成品及其他专业已完成的成品进行保护工作，无论是否由该单位导致的损坏，该单位都应履行修复处理责任； 8.对施工需要拆除或移动的材料，待施工完毕后，恢复原状； 9.完成工作区域的安全文明施工,清理施工遗留下的垃圾。 10.该项包含本项工作所有工作内容含垂直运输机械等，未详尽列举特征，详见施工图纸、设计规范、施工方案事项均包含在综合单价中 | E9: m2 | F9: 199.77 | G9: 316.06 | H9: =F9*G9 -> 63139.31 | I9: =南川一标段!$I$14 -> 391.2 | J9: =F9*I9 -> 78150.02 | K9: =G9-I9 -> -75.14 | L9: 按设计图示尺寸以面积计算。 | M9: 此项工作的全费用综合单价 | R9: =O9+P9+Q9 -> 0 | S9: =R9*$S$4 -> 0
A10: 4 | B10: 水泥基自流平地面 | C10: 1、5厚水泥基自流平面层 2、涂刷自流平界面剂 3、其他：该项包含本项工作所有工作内容含垂直运输机械等，未详尽列举特征，详见施工图纸、设计规范、施工方案事项均包含在综合单价中。 | D10: 1.基层清理、找平、打磨、甩浆、定位、弹线； 2.刷界面剂一道； 3.自流平水泥施工、刮平、分格、养护、填塞分格缝、打磨面层； 4.材料的运输、堆码、清运及场内多次搬运； 5.单价已包括送样的材料费用、检验、试验等工作; 6.配合安装队伍进行多次预留预埋及相关开槽、开洞的修补工作； 7.对已施工完成的成品及其他专业已完成的成品进行保护工作，无论是否由该单位导致的损坏，该单位都应履行修复处理责任； 8.对施工需要拆除或移动的材料，待施工完毕后，恢复原状； 9.完成工作区域的安全文明施工,清理施工遗留下的垃圾； 10.该项包含本项工作所有工作内容含垂直运输机械等，未详尽列举特征，详见施工图纸、设计规范、施工方案事项均包含在综合单价中。 | E10: m2 | F10: 235.52 | G10: 47.92 | H10: =F10*G10 -> 11286.12 | I10: =南川一标段!$I$13 -> 28.8 | J10: =F10*I10 -> 6782.98 | K10: =G10-I10 -> 19.12 | L10: 按设计图示尺寸以面积计算。 | M10: 此项工作的全费用综合单价 | R10: =O10+P10+Q10 -> 0 | S10: =R10*$S$4 -> 0
A11: 5 | B11: 防滑地砖梯面 | C11: 1、面层：10厚玻化砖(防滑),同色水泥浆擦缝 2、30厚1:3干硬性水泥砂浆,表面撒水泥粉 3、嵌缝材料种类：按甲方要求嵌缝、打胶，挡水条制作； 4、防护层材料：满足设计和相关规范要求； 5、酸洗、打蜡要求：满足设计和相关规范要求； 6、楼地面伸缩缝、变形缝的处理； 7、其他：该项包含本项工作所有工作内容含垂直运输机械等，未详尽列举特征，详见施工图纸、设计规范、施工方案事项均包含在综合单价中。 (地砖规格600*600) | D11: 1.基层清理、找平、打磨、甩浆、弹线、定位； 2.结合层施工； 3.防滑地砖铺贴，干水泥擦缝，挡水条制作； 4.材料的运输、堆码、清运及场内多次搬运； 5.单价已包括送样的材料费用、检验、试验等工作，还包括地砖铺贴前排版图设计工作; 6.配合安装队伍进行多次预留预埋及相关开槽、开洞的修补工作； 7.对已施工完成的成品及其他专业已完成的成品进行保护工作，无论是否由该单位导致的损坏，该单位都应履行修复处理责任； 8.对施工需要拆除或移动的材料，待施工完毕后，恢复原状； 9.完成工作区域的安全文明施工,清理施工遗留下的垃圾； 10.该项包含本项工作所有工作内容含垂直运输机械等，未详尽列举特征，详见施工图纸、设计规范、施工方案事项均包含在综合单价中。 | E11: m2 | F11: 119.87 | G11: 135 | H11: =F11*G11 -> 16182.45 | I11: =南川一标段!$I$11 -> 175.84 | J11: =F11*I11 -> 21077.94 | K11: =G11-I11 -> -40.84 | L11: 按设计图示尺寸以展开面积计算。 | M11: 此项工作的全费用综合单价 | R11: =O11+P11+Q11 -> 0 | S11: =R11*$S$4 -> 0
A12: 6 | B12: 防滑地砖楼面 | C12: 1、面层：10厚玻化砖(防滑),同色水泥浆擦缝 2、30厚1:3干硬性水泥砂浆,表面撒水泥粉 3、嵌缝材料种类：按甲方要求嵌缝、打胶； 4、防护层材料：满足设计和相关规范要求； 5、酸洗、打蜡要求：满足设计和相关规范要求； 6、楼地面伸缩缝、变形缝的处理； 7、其他：该项包含本项工作所有工作内容含垂直运输机械等，未详尽列举特征，详见施工图纸、设计规范、施工方案事项均包含在综合单价中。 (地砖规格600*600) | D12: 1.基层清理、找平、打磨、甩浆、弹线、定位； 2.结合层施工； 3.防滑地砖铺贴，干水泥擦缝； 4.材料的运输、堆码、清运及场内多次搬运； 5.单价已包括送样的材料费用、检验、试验等工作，还包括地砖铺贴前排版图设计工作; 6.配合安装队伍进行多次预留预埋及相关开槽、开洞的修补工作； 7.对已施工完成的成品及其他专业已完成的成品进行保护工作，无论是否由该单位导致的损坏，该单位都应履行修复处理责任； 8.对施工需要拆除或移动的材料，待施工完毕后，恢复原状； 9.完成工作区域的安全文明施工,清理施工遗留下的垃圾； 10.该项包含本项工作所有工作内容含垂直运输机械等，未详尽列举特征，详见施工图纸、设计规范、施工方案事项均包含在综合单价中。 | E12: m2 | F12: 257.7 | G12: 120 | H12: =F12*G12 -> 30924 | I12: =南川一标段!$I$12 -> 165.22 | J12: =F12*I12 -> 42577.19 | K12: =G12-I12 -> -45.22 | L12: 按设计图示尺寸以面积计算。 | M12: 此项工作的全费用综合单价 | R12: =O12+P12+Q12 -> 0 | S12: =R12*$S$4 -> 0
A13: 7 | B13: 水泥踢脚 | C13: 1、6厚1:2.5水泥砂浆抹面压实赶光 2、刷素水泥浆一道 3、7厚1:1:6水泥石灰膏砂浆打底骚猫或划出纹道 4、3厚外加剂专用砂浆抹基底刮糙(抹前用水喷湿墙面) 5、其他：该项包含本项工作所有工作内容含垂直运输机械等，未详尽列举特征，详见施工图纸、设计规范、施工方案事项均包含在综合单价中。 | D13: 1.墙体基层处理、找平抹灰、压实； 2.踢脚线制作、运输、安装，抹面压实赶光； 3.材料的运输、堆码、清运及场内多次搬运； 4.单价已包括送样的材料费用、检验、试验等工作; 5.配合安装队伍进行多次预留预埋及相关开槽、开洞的修补工作； 6.对已施工完成的成品及其他专业已完成的成品进行保护工作，无论是否由该单位导致的损坏，该单位都应履行修复处理责任； 7.对施工需要拆除或移动的材料，待施工完毕后，恢复原状； 8.完成工作区域的安全文明施工,清理施工遗留下的垃圾； 9.该项包含本项工作所有工作内容含垂直运输机械等，未详尽列举特征，详见施工图纸、设计规范、施工方案事项均包含在综合单价中。 | E13: m2 | F13: 20.46 | G13: 35 | H13: =F13*G13 -> 716.1 | I13: =南川一标段!$I$17 -> 174.1 | J13: =F13*I13 -> 3562.09 | K13: =G13-I13 -> -139.1 | L13: 以平方米计量，按设计图示长度乘高度以面积计算。 | M13: 此项工作的全费用综合单价 | R13: =O13+P13+Q13 -> 0 | S13: =R13*$S$4 -> 0
A14: 8 | B14: 地砖踢脚 | C14: 1、粘贴10厚地砖,专用勾缝剂勾缝 2、9厚1:2水泥砂浆(内掺3%超密聚合物防水剂)粘结层 3、素水泥浆一道(内掺建筑胶) 4、其他：该项包含本项工作所有工作内容含垂直运输机械等，未详尽列举特征，详见施工图纸、设计规范、施工方案事项均包含在综合单价中。 | D14: 1.墙体基层处理、找平抹灰、压实； 2.踢脚线制作、运输、安装，面砖背面涂专用粘接剂，用专用勾缝剂勾缝； 3.材料的运输、堆码、清运及场内多次搬运； 4.单价已包括送样的材料费用、检验、试验等工作; 5.配合安装队伍进行多次预留预埋及相关开槽、开洞的修补工作； 6.对已施工完成的成品及其他专业已完成的成品进行保护工作，无论是否由该单位导致的损坏，该单位都应履行修复处理责任； 7.对施工需要拆除或移动的材料，待施工完毕后，恢复原状； 8.完成工作区域的安全文明施工,清理施工遗留下的垃圾； 9.该项包含本项工作所有工作内容含垂直运输机械等，未详尽列举特征，详见施工图纸、设计规范、施工方案事项均包含在综合单价中。 | E14: m2 | F14: 59.69 | G14: 130 | H14: =F14*G14 -> 7759.7 | I14: =南川一标段!$I$18 -> 233.83 | J14: =F14*I14 -> 13957.31 | K14: =G14-I14 -> -103.83 | L14: 以平方米计量，按设计图示长度乘高度以面积计算。 | M14: 此项工作的全费用综合单价 | R14: =O14+P14+Q14 -> 0 | S14: =R14*$S$4 -> 0
A15: 9 | B15: 不锈钢踢脚 | C15: 1、1.0厚不锈钢金属踢脚板,下端用水泥钉钉入地面垫层,中距300 2、10厚1:3水泥砂浆压实抹平 3、素水泥浆一道(内掺建筑胶)(用于混凝土空心砌块墙);3厚外加剂专用砂浆抹基底刮糙(抹灰前用水喷湿墙面)(用于蒸 压加气混凝土砌块墙) 4、水泥钉固定踢脚上端,中距300 5、其他：该项包含本项工作所有工作内容含垂直运输机械等，未详尽列举特征，详见施工图纸、设计规范、施工方案事项均包含在综合单价中。 | D15: 1.墙体基层处理； 2.粘贴、固定不锈钢踢脚线； 3.材料的运输、堆码、清运及场内多次搬运； 4.单价已包括送样的材料费用、检验、试验等工作; 5.配合安装队伍进行多次预留预埋及相关开槽、开洞的修补工作； 6.对已施工完成的成品及其他专业已完成的成品进行保护工作，无论是否由该单位导致的损坏，该单位都应履行修复处理责任； 7.对施工需要拆除或移动的材料，待施工完毕后，恢复原状； 8.完成工作区域的安全文明施工,清理施工遗留下的垃圾； 9.该项包含本项工作所有工作内容含垂直运输机械等，未详尽列举特征，详见施工图纸、设计规范、施工方案事项均包含在综合单价中。 | E15: m2 | F15: 9.23 | G15: 272.98 | H15: =F15*G15 -> 2519.61 | I15: =南川一标段!$I$19 -> 519.74 | J15: =F15*I15 -> 4797.2 | K15: =G15-I15 -> -246.76 | L15: 以平方米计量，按设计图示长度乘高度以面积计算。 | M15: 此项工作的全费用综合单价 | R15: =O15+P15+Q15 -> 0 | S15: =R15*$S$4 -> 0
A16: 10 | B16: 穿孔吸声板墙面 | C16: 1、10厚穿孔板用螺钉固定于龙骨上 2、玻璃布一层绷紧固定于龙骨表面 3、40厚岩棉(或玻璃棉)毡,建筑胶粘济粘贴于龙骨档内 4、75X50X0.7轻钢龙骨用膨胀螺栓宇墙面固定,中距按板规格设计 6、在混凝土梁、柱或现浇混凝土条带、砌块上钻孔打入M6X75膨胀螺栓,中距按穿孔板规格设计 7、6~9厚DP-HR砂浆修补墙面抹平 8、3厚外加剂专用砂浆抹基底,抹前喷湿墙面(用于加气混凝土砌块墙) 9、其他：该项包含本项工作所有工作内容含垂直运输机械等，未详尽列举特征，详见施工图纸、设计规范、施工方案事项均包含在综合单价中。 | D16: 1.基层处理; 2.龙骨安装； 3.填充40厚岩棉(或玻璃棉)毡,； 4.穿孔板用螺钉固定于龙骨上； 5.材料的运输、堆码、清运及场内多次搬运； 6.单价已包括送样的材料费用、检验、试验等工作; 7.配合安装队伍进行多次预留预埋及相关开槽、开洞的修补工作； 8.对已施工完成的成品及其他专业已完成的成品进行保护工作，无论是否由该单位导致的损坏，该单位都应履行修复处理责任； 9.对施工需要拆除或移动的材料，待施工完毕后，恢复原状； 10.完成工作区域的安全文明施工,清理施工遗留下的垃圾； 11.该项包含本项工作所有工作内容含垂直运输机械等，未详尽列举特征，详见施工图纸、设计规范、施工方案事项均包含在综合单价中。 | E16: m2 | F16: 272.11 | G16: 136.53 | H16: =F16*G16 -> 37151.18 | I16: =南川一标段!$I$24 -> 294.36 | J16: =F16*I16 -> 80098.3 | K16: =G16-I16 -> -157.83 | L16: 按设计图示尺寸以硅酸钙板吊顶水平投影面积计算 | M16: 此项工作的全费用综合单价 | R16: =O16+P16+Q16 -> 0 | S16: =R16*$S$4 -> 0
A17: 11 | B17: 无机涂料墙面 | C17: 1、喷(刷、辊)无机内墙薄涂涂料2道 2、满刮2厚腻子砂磨平 3、其他：该项包含本项工作所有工作内容含垂直运输机械等，未详尽列举特征，详见施工图纸、设计规范、施工方案事项均包含在综合单价中。 | D17: 1.内墙基层处理； 2.水泥砂浆找平打底扫毛，内掺建筑胶； 3.水泥砂浆找平层、水泥砂浆罩面压光施工； 4.满刮腻子两遍，找平磨光； 5.喷（刷）无机涂料2道； 6.材料的运输、堆码、清运及场内多次搬运； 7.单价已包括送样的材料费用、检验、试验等工作; 8.配合安装队伍进行多次预留预埋及相关开槽、开洞的修补工作； 9.对已施工完成的成品及其他专业已完成的成品进行保护工作，无论是否由该单位导致的损坏，该单位都应履行修复处理责任； 10.对施工需要拆除或移动的材料，待施工完毕后，恢复原状； 11.完成工作区域的安全文明施工,清理施工遗留下的垃圾。 12.该项包含本项工作所有工作内容含垂直运输机械等，未详尽列举特征，详见施工图纸、设计规范、施工方案事项均包含在综合单价中。 | E17: m2 | F17: 4386.41 | G17: 27 | H17: =F17*G17 -> 118433.07 | I17: =南川一标段!$I$20 -> 44.4 | J17: =F17*I17 -> 194756.6 | K17: =G17-I17 -> -17.4 | L17: 按设计图示尺寸以面积计算（有吊顶房间算至吊顶底，无吊顶房间算至梁底或者板底） | M17: 此项工作的全费用综合单价 | R17: =O17+P17+Q17 -> 0 | S17: =R17*$S$4 -> 0
A18: 12 | B18: 防水面砖墙面 | C18: 1、同色水泥擦缝 2、8-10厚墙面砖(粘贴前墙砖充分浸湿) 3、8厚1:2水泥砂浆粘结层(内掺建筑胶) 4、缝宽、嵌缝材料：按甲方要求嵌缝、打胶； 5、酸洗、打蜡要求：满足设计和相关规范要求； 6、墙面伸缩缝、变形缝的处理； 7、根据安装需要开孔 8、其他：该项包含本项工作所有工作内容含垂直运输机械等，未详尽列举特征，详见施工图纸、设计规范、施工方案事项均包含在综合单价中。 (600×300墙砖) | D18: 1.内墙基层处理； 2.水泥砂浆粘结层，内掺建筑胶； 3.墙面面砖运输、制作、铺贴、擦缝 4.材料的运输、堆码、清运及场内多次搬运； 5.综合单价包含切角、倒角、磨边、加厚、弧形加工、嵌缝、拉槽、排版损耗、晶面处理等费用，送样的材料费用、检验、试验等工作费用，还包括地砖铺贴前排版图设计工作; 6.配合安装队伍进行多次预留预埋及相关开槽、开洞的修补工作； 7.对已施工完成的成品及其他专业已完成的成品进行保护工作，无论是否由该单位导致的损坏，该单位都应履行修复处理责任； 8.对施工需要拆除或移动的材料，待施工完毕后，恢复原状； 9.完成工作区域的安全文明施工,清理施工遗留下的垃圾。 10.该项包含本项工作所有工作内容含垂直运输机械等，未详尽列举特征，详见施工图纸、设计规范、施工方案事项均包含在综合单价中。 | E18: m2 | F18: 958.65 | G18: 120 | H18: =F18*G18 -> 115038 | I18: =南川一标段!$I$21 -> 153.02 | J18: =F18*I18 -> 146692.62 | K18: =G18-I18 -> -33.02 | L18: 按设计图示尺寸以面积计算（有吊顶房间算至吊顶底） | M18: 全费用综合单价 | R18: =O18+P18+Q18 -> 0 | S18: =R18*$S$4 -> 0
A19: 13 | B19: 耐擦洗涂料墙面 | C19: 1、防火型无机耐擦洗涂料两道饰面(白色) 2、满刮2厚耐水腻子找平 3、其他：该项包含本项工作所有工作内容含垂直运输机械等，未详尽列举特征，详见施工图纸、设计规范、施工方案事项均包含在综合单价中。 | D19: 1.内墙基层处理； 2.外加剂专用砂浆打底刮糙或专用界面剂一道甩毛； 3.石灰膏砂浆分层抹平； 4.满刮腻子两遍，找平磨光； 5.防火型无机耐擦洗涂料两道饰面； 6.材料的运输、堆码、清运及场内多次搬运； 7.单价已包括送样的材料费用、检验、试验等工作; 8.配合安装队伍进行多次预留预埋及相关开槽、开洞的修补工作； 9.对已施工完成的成品及其他专业已完成的成品进行保护工作，无论是否由该单位导致的损坏，该单位都应履行修复处理责任； 10.对施工需要拆除或移动的材料，待施工完毕后，恢复原状； 11.完成工作区域的安全文明施工,清理施工遗留下的垃圾。 12.该项包含本项工作所有工作内容含垂直运输机械等，未详尽列举特征，详见施工图纸、设计规范、施工方案事项均包含在综合单价中。 | E19: m2 | F19: 342.79 | G19: 30 | H19: =F19*G19 -> 10283.7 | I19: =南川一标段!$I$100 -> 44.4 | J19: =F19*I19 -> 15219.88 | K19: =G19-I19 -> -14.4 | L19: 按设计图示尺寸以面积计算（有吊顶房间算至吊顶底，无吊顶房间算至梁底或者板底） | M19: 此项工作的全费用综合单价 | R19: =O19+P19+Q19 -> 0 | S19: =R19*$S$4 -> 0
A20: 14 | B20: 白色仿铝板金属漆 | C20: 1、涂刷罩面清漆 2、涂饰第二遍面层涂料(透明) 3、涂饰面层涂料(透明) 4、喷主层涂料 5、辊、刷或喷底层涂料 10、其他：该项包含本项工作所有工作内容含垂直运输机械等，未详尽列举特征，详见施工图纸、设计规范、施工方案事项均包含在综合单价中。 | D20: 1.刷底层涂料、主层涂料、面层涂料； 2.涂刷罩面清漆； 3.材料的运输、堆码、清运及场内多次搬运； 4.单价已包括送样的材料费用、检验、试验等工作; 5.配合安装队伍进行多次预留预埋及相关开槽、开洞的修补工作； 6.对已施工完成的成品及其他专业已完成的成品进行保护工作，无论是否由该单位导致的损坏，该单位都应履行修复处理责任； 7.对施工需要拆除或移动的材料，待施工完毕后，恢复原状； 8.完成工作区域的安全文明施工,清理施工遗留下的垃圾。 9.该项包含本项工作所有工作内容含垂直运输机械等，未详尽列举特征，详见施工图纸、设计规范、施工方案事项均包含在综合单价中。 | E20: m2 | F20: 420.7 | G20: 85.06 | H20: =F20*G20 -> 35784.74 | I20: =S20 -> 117 | J20: =F20*I20 -> 49221.9 | K20: =G20-I20 -> -31.94 | L20: 按设计图示尺寸以面积计算。 | M20: 除甲供材外，此项工作的全费用综合单价 | O20: 65 | P20: 4.5 | Q20: 28 | R20: =O20+P20+Q20 -> 97.5 | S20: =R20*$S$4 -> 117
A21: 15 | B21: 铝合金扣板顶棚 | C21: 1、600*600*1.0铝合金扣板(折边20) 2、与铝合金扣板配套的专用暗架龙骨,间距≤300,通过十字连扣连接件与承载龙骨连接 3、D38承载龙骨,间距≤1200,用吊杆与钢筋吊杆联结后找平 4、10厚镀锌低碳钢丝(或%%C8钢筋)吊杆,双向中距≤1200,吊杆上部与板底(或钢结构)预留吊环(勾)固定 5、结构层预埋%%C10(或钢结构预留)钢筋吊环(勾),双向中距≤1200 6、顶棚伸缩缝、变形缝； 6、其他：该项包含本项工作所有工作内容含垂直运输机械等，未详尽列举特征，详见施工图纸、设计规范、施工方案事项均包含在综合单价中。 | D21: 1.基层处理 2.轻钢龙骨、吊杆安装； 3.铝扣板安装、收边线； 4.材料的运输、堆码、清运及场内多次搬运； 5.单价已包括送样的材料费用、检验、试验等工作; 6.配合安装队伍进行多次预留预埋及相关开槽、开洞的修补工作； 7.对已施工完成的成品及其他专业已完成的成品进行保护工作，无论是否由该单位导致的损坏，该单位都应履行修复处理责任； 8.对施工需要拆除或移动的材料，待施工完毕后，恢复原状； 9.完成工作区域的安全文明施工,清理施工遗留下的垃圾； 10.该项包含本项工作所有工作内容含垂直运输机械等，未详尽列举特征，详见施工图纸、设计规范、施工方案事项均包含在综合单价中。 | E21: m2 | F21: 262.6 | G21: 136.14 | H21: =F21*G21 -> 35750.36 | I21: =南川一标段!$I$29 -> 160.04 | J21: =F21*I21 -> 42026.5 | K21: =G21-I21 -> -23.9 | L21: 按设计图示尺寸以水平投影面积计算。 | M21: 除型钢龙骨外的全费用综合单价 | R21: =O21+P21+Q21 -> 0 | S21: =R21*$S$4 -> 0
A22: 16 | B22: 硅酸钙板面层吊顶 | C22: 1、喷(刷、辊)涂料面层两遍(每道间隔2小时) 2、封底漆一道(干燥后再做面层) 3、满刮2厚面层耐水腻子找平,板面接缝处贴嵌缝带,刮腻子抹平 4、错缝粘贴第二层9.5厚耐水耐火纸面石膏板 5、双层6mm厚硅酸钙板用自攻螺丝与龙骨固定,中距≤200,螺丝距板长边≥10,短边≥15 6、U型轻钢覆面横撑龙骨CB60x27,间距1200,用挂插件与次龙骨联结 7、U型轻钢覆面次龙骨CB60x27,间距400,用挂件与承接龙骨联结 8、U型轻钢承接龙骨CS50x15,间距≤1200,用吊杆与钢筋吊杆联结后找平 9、%%C8钢筋吊杆并加反支撑,双向中距≤1200,吊杆上部与预留钢筋吊环固定 10、现浇钢筋混凝土板底预埋%%C10钢筋吊环(勾),双向中距≤1200(转换层另列） 11.其他：该项包含本项工作所有工作内容含垂直运输机械等，未详尽列举特征，详见施工图纸、设计规范、施工方案事项均包含在综合单价中。 | D22: 1.基层处理； 2.龙骨、吊杆安装； 3.耐水耐火纸面石膏板安装、收边收口； 4.满刮腻子找平、贴嵌缝，刷底漆、面层涂料； 5.材料的运输、堆码、清运及场内多次搬运； 6.单价已包括送样的材料费用、检验、试验等工作; 7.配合安装队伍进行多次预留预埋及相关开槽、开洞的修补工作； 8.对已施工完成的成品及其他专业已完成的成品进行保护工作，无论是否由该单位导致的损坏，该单位都应履行修复处理责任； 9.对施工需要拆除或移动的材料，待施工完毕后，恢复原状； 10.完成工作区域的安全文明施工,清理施工遗留下的垃圾。 11.该项包含本项工作所有工作内容含垂直运输机械等，未详尽列举特征，详见施工图纸、设计规范、施工方案事项均包含在综合单价中。 | E22: m2 | F22: 9.71 | G22: 185.86 | H22: =F22*G22 -> 1804.7 | I22: =南川一标段!$I$30 -> 348 | J22: =F22*I22 -> 3379.08 | K22: =G22-I22 -> -162.14 | L22: 按设计图示尺寸以水平投影面积计算。 | M22: 除甲供材外，此项工作的全费用综合单价 | R22: =O22+P22+Q22 -> 0 | S22: =R22*$S$4 -> 0
A23: 17 | B23: 石膏面层板吊顶 | C23: 1、12厚石膏面层板面层,规格592x592 2、T型次龙骨TB24x30,间距600,与主龙骨插接 3、T型主龙骨TB24X30,间距600,通过D-T挂件与承载龙骨连接 4、D38承载龙骨,间距1200,用吊件与钢筋吊杆联结后找平 5、%%C8螺纹吊杆,双向中距≤1200,吊杆上部与吊顶转换层固定 7、50*5镀锌角钢吊顶转换层,井字型网格间距≤2400*1200(转换层另列） 8、顶棚伸缩缝、变形缝； 9、其他：该项包含本项工作所有工作内容含垂直运输机械等，未详尽列举特征，详见施工图纸、设计规范、施工方案事项均包含在综合单价中。 | D23: 1.基层处理； 2.主、次龙骨、角钢、吊杆安装； 3.纸面石膏板面层安装，收边收口； 4.材料的运输、堆码、清运及场内多次搬运； 5.单价已包括送样的材料费用、检验、试验等工作; 6.配合安装队伍进行多次预留预埋及相关开槽、开洞的修补工作； 7.对已施工完成的成品及其他专业已完成的成品进行保护工作，无论是否由该单位导致的损坏，该单位都应履行修复处理责任； 8.对施工需要拆除或移动的材料，待施工完毕后，恢复原状； 9.完成工作区域的安全文明施工,清理施工遗留下的垃圾； 10.该项包含本项工作所有工作内容含垂直运输机械等，未详尽列举特征，详见施工图纸、设计规范、施工方案事项均包含在综合单价中。 | E23: m2 | F23: 1071.2 | G23: 98.94 | H23: =F23*G23 -> 105984.53 | I23: =彭水二标段!$I$32 -> 108.6 | J23: =F23*I23 -> 116332.32 | K23: =G23-I23 -> -9.66 | L23: 按设计图示尺寸以水平投影面积计算。 | M23: 此项工作的全费用综合单价 | R23: =O23+P23+Q23 -> 0 | S23: =R23*$S$4 -> 0
A24: 18 | B24: 轻钢龙骨整体石膏板吊顶 | C24: 1、整体石膏板 2、配套龙骨及吊杆 3、其他：该项包含本项工作所有工作内容含垂直运输机械等，未详尽列举特征，详见施工图纸、设计规范、施工方案事项均包含在综合单价中。 | D24: 1.基层处理； 2.龙骨、吊杆安装； 3.石膏板面层安装，收边收口； 4.材料的运输、堆码、清运及场内多次搬运； 5.单价已包括送样的材料费用、检验、试验等工作; 6.配合安装队伍进行多次预留预埋及相关开槽、开洞的修补工作； 7.对已施工完成的成品及其他专业已完成的成品进行保护工作，无论是否由该单位导致的损坏，该单位都应履行修复处理责任； 8.对施工需要拆除或移动的材料，待施工完毕后，恢复原状； 9.完成工作区域的安全文明施工,清理施工遗留下的垃圾； 10.该项包含本项工作所有工作内容含垂直运输机械等，未详尽列举特征，详见施工图纸、设计规范、施工方案事项均包含在综合单价中。 | E24: m2 | F24: 34.55 | G24: 98.94 | H24: =F24*G24 -> 3418.38 | I24: =$I$23 -> 108.6 | J24: =F24*I24 -> 3752.13 | K24: =G24-I24 -> -9.66 | L24: 按设计图示尺寸以水平投影面积计算。 | M24: 此项工作的全费用综合单价 | R24: =O24+P24+Q24 -> 0 | S24: =R24*$S$4 -> 0
A25: 19 | B25: 无机涂料顶棚 | C25: 1、防火型无机耐擦洗涂料两道饰面(白色) 2、2厚面层耐水腻子刮平 3、顶棚伸缩缝、变形缝； 其他：该项包含本项工作所有工作内容含垂直运输机械等，未详尽列举特征，详见施工图纸、设计规范、施工方案事项均包含在综合单价中。 | D25: 1.基层处理、甩浆； 2.水泥砂浆打底找平； 2.满刮腻子找平、磨光； 4.防火型无机耐擦洗涂料两道饰面(； 5.材料的运输、堆码、清运及场内多次搬运； 6.单价已包括送样的材料费用、检验、试验等工作; 7.配合安装队伍进行多次预留预埋及相关开槽、开洞的修补工作； 8.对已施工完成的成品及其他专业已完成的成品进行保护工作，无论是否由该单位导致的损坏，该单位都应履行修复处理责任； 9.对施工需要拆除或移动的材料，待施工完毕后，恢复原状； 10.完成工作区域的安全文明施工,清理施工遗留下的垃圾。 11.该项包含本项工作所有工作内容含垂直运输机械等，未详尽列举特征，详见施工图纸、设计规范、施工方案事项均包含在综合单价中。 | E25: m2 | F25: 625.79 | G25: 32 | H25: =F25*G25 -> 20025.28 | I25: =南川一标段!$I$28 -> 44.4 | J25: =F25*I25 -> 27785.08 | K25: =G25-I25 -> -12.4 | L25: 按设计图示尺寸以水平投影面积计算。 | M25: 此项工作的全费用综合单价 | R25: =O25+P25+Q25 -> 0 | S25: =R25*$S$4 -> 0
A26: 20 | B26: 吸顶玻璃棉毡铝板网吸声吊顶 | C26: 1、1.5厚穿孔铝合金饰面板 2、50厚超细玻璃丝棉吸声层,玻璃丝布袋装填于龙骨间 3、T型轻钢横撑龙骨TB24X28,间距600,与主龙骨插接 4、T型轻钢主龙骨TB24X38,间距≤1200,用吸顶吊件联结 5、龙骨吸顶吊件,中距横向≤1200,纵向600,用膨胀螺栓与钢筋砼板固定 6、顶棚伸缩缝、变形缝； 其他：该项包含本项工作所有工作内容含垂直运输机械等，未详尽列举特征，详见施工图纸、设计规范、施工方案事项均包含在综合单价中。 | D26: 1.基层处理; 2.吊杆及预埋件焊接或后置紧固件连接； 3.龙骨安装； 4.填充50mm厚超细玻璃丝棉吸声层； 5.穿孔铝合金饰面板安装； 6.材料的运输、堆码、清运及场内多次搬运； 7.单价已包括送样的材料费用、检验、试验等工作; 8.配合安装队伍进行多次预留预埋及相关开槽、开洞的修补工作； 9.对已施工完成的成品及其他专业已完成的成品进行保护工作，无论是否由该单位导致的损坏，该单位都应履行修复处理责任； 10.对施工需要拆除或移动的材料，待施工完毕后，恢复原状； 11.完成工作区域的安全文明施工,清理施工遗留下的垃圾； 12.该项包含本项工作所有工作内容含垂直运输机械等，未详尽列举特征，详见施工图纸、设计规范、施工方案事项均包含在综合单价中。 | E26: m2 | F26: 144.68 | G26: 121.02 | H26: =F26*G26 -> 17509.17 | I26: =S26 -> 201.6 | J26: =F26*I26 -> 29167.49 | K26: =G26-I26 -> -80.58 | L26: 按设计图示尺寸以水平投影面积计算。 | M26: 除甲供材外，此项工作的全费用综合单价 | N26: 甲供材料：1.5厚穿孔铝合金饰面板 | O26: 0 | P26: =16+22 -> 38 | Q26: 130 | R26: =O26+P26+Q26 -> 168 | S26: =R26*$S$4 -> 201.6
A27: 21 | B27: 吊顶转换层--网架转换层 | C27: 网架转换层龙骨 | D27: 1.镀锌型钢龙骨转换层、骨架的制作、运输、安装、刷漆 2.该项包含本项工作所有工作内容含垂直运输机械等，未详尽列举特征，详见施工图纸、设计规范、施工方案事项均包含在综合单价中。 | E27: t | F27: 37.51 | G27: 8726.4 | H27: =F27*G27 -> 327327.26 | I27: =南川一标段!$I$47 -> 10536 | J27: =F27*I27 -> 395205.36 | K27: =G27-I27 -> -1809.6 | L27: 按设计图示尺寸以实际安装根数以重量计算 | M27: 此项工作的全费用综合单价 | R27: =O27+P27+Q27 -> 0 | S27: =R27*$S$4 -> 0
A28: 22 | B28: 镀锌方管转换层 | C28: 主次龙骨50*50*5镀锌方管、埋板等 | D28: 1.镀锌型钢龙骨转换层、骨架的制作、运输、安装、刷漆 2.该项包含本项工作所有工作内容含垂直运输机械等，未详尽列举特征，详见施工图纸、设计规范、施工方案事项均包含在综合单价中。 | E28: t | F28: 55.317 | G28: 8726.4 | H28: =F28*G28 -> 482718.27 | I28: =南川一标段!$I$47 -> 10536 | J28: =F28*I28 -> 582819.91 | K28: =G28-I28 -> -1809.6 | L28: 按设计图示尺寸以实际安装根数以重量计算 | M28: 此项工作的全费用综合单价 | R28: =O28+P28+Q28 -> 0 | S28: =R28*$S$4 -> 0
A29: 23 | B29: 干挂型钢龙骨 | C29: 1、石材、铝板墙面龙骨、埋板等； 2、骨架种类、规格：具体规格、尺寸、连接方式详见图纸； | D29: 1.镀锌型钢龙骨转换层、骨架的制作、运输、安装、刷漆 2.该项包含本项工作所有工作内容含垂直运输机械等，未详尽列举特征，详见施工图纸、设计规范、施工方案事项均包含在综合单价中。 | E29: t | F29: 96.34 | G29: 8726.4 | H29: =F29*G29 -> 840701.38 | I29: =南川一标段!$I$48 -> 10536 | J29: =F29*I29 -> 1015038.2 | K29: =G29-I29 -> -1809.6 | L29: 按设计图示尺寸以实际安装根数以重量计算 | M29: 此项工作的全费用综合单价 | R29: =O29+P29+Q29 -> 0 | S29: =R29*$S$4 -> 0
A30: 24 | B30: 洗漱台 | C30: 1、部位：具体详设计图纸要求； 2、石材规格：综合详见图纸； 3、2.5mm铝单板挡板 4、台面、挡水 5、其它：满足设计规范及图纸要求。 | D30: 1.洗漱台面层石材制作、运输、铺贴 2.铝板安装、收边收口 3.材料的运输、摆放、清运及场内多次搬运； 4.对已施工完成的成品及其他专业已完成的成品进行保护工作，无论是否由该单位导致的损坏，该单位都应履行修复处理责任； 5.对施工需要拆除或移动的材料，待施工完毕后，恢复原状； 6.完成工作区域的安全文明施工,清理施工遗留下的垃圾； 7、该项包含本项工作所有工作内容含垂直运输机械等，未详尽列举特征，详见施工图纸、设计规范、施工方案事项均包含在综合单价中。 | E30: m | F30: 27.93 | G30: 420.78 | H30: =F30*G30 -> 11752.39 | I30: =南川一标段!$I$35 -> 639.9 | J30: =F30*I30 -> 17872.41 | K30: =G30-I30 -> -219.12 | L30: 按设计图示尺寸以米计算 | M30: 除基层龙骨外，此项工作的全费用综合单价 | R30: =O30+P30+Q30 -> 0 | S30: =R30*$S$4 -> 0
A31: 25 | B31: 镜面玻璃 | C31: 1.30*30mm方管龙骨（刷防火、防腐） 2.6mm厚双层硅酸钙板基层（涂刷防腐） 3.5mm厚银镜及安装。 4.顶部及底部LED贴片灯带、灯槽制作安装 5.不锈钢边框包边；6.完成该项工作所需的全部工作内容 | D31: [工作内容] 1.基层安装 2.玻璃及框制作、运输、安装 3.该项包含本项工作所有工作内容含垂直运输机械等，未详尽列举特征，详见施工图纸、设计规范、施工方案事项均包含在综合单价中。 | E31: m2 | F31: 36.31 | G31: 220 | H31: =F31*G31 -> 7988.2 | I31: =南川一标段!$I$36 -> 526.8 | J31: =F31*I31 -> 19128.11 | K31: =G31-I31 -> -306.8 | L31: 按设计图示尺寸以面积计算 | M31: 除基层龙骨外，此项工作的全费用综合单价 | R31: =O31+P31+Q31 -> 0 | S31: =R31*$S$4 -> 0
