Workbook

Sheet 1-清单及价格说明
A1: 编制说明
A2: 一 | B2: 工程量清单编制依据：
A3: 1 | B3: 长城智选设计、施工一体化项目工程图纸、效果图（1.0、2.0版本）
A4: 2 | B4: 《建设工程工程量清单计价规范 GB 50500-2013》
A5: 3 | B5: 《建筑工程建筑面积计算规范》GB 55031-2022
A6: 二 | B6: 工程量清单及控制价注意事项说明:
A7: 1 | B7: 本工程采用设计施工一体化，包工包料的全费用固定综合单价组价。固定综合单价包括现场人工费、材料费、机械费、管理费、措施费、规费、利润、税金、合同备案费、水电费、工程当地所要求必须缴纳的费用以及采用固定价格的工程所测算的风险金、相关的材料试验费、检测费（包括但不限于空气、材料、结构等第三方检测、鉴定等费用）及各系统施工完成后系统调试费、资料整理归档等一切费用。
A8: 2 | B8: 措施费用包含在固定综合单价中，不单独体现。措施费费用包括但不限于安全文明施工费用（应满足项目所在地的政府及物业要求的安全文明施工标准）、临时设施（办公住宿临设、临水临电、临时道路等）、夜间施工、非夜间施工照明、二次搬运、冬雨季施工、已完工程及设备成品保护等与项目相关的措施费用。
A9: 3 | B9: 本项目中涉及脚手架、垂直运输、超高增加费、垃圾清运费、垃圾消纳费含在固定综合单价中，不再单独体现。
A10: 4 | B10: 消防设备复检、玻璃幕墙、石材幕墙的检测以及当地政府要求的检测相关费用包含在固定综合单价中，不再单独体现。消防验收在招标范围内，消防的备案、验收、办证，单独组价。其它相关建设手续费（含物业及政府相关备案、开工、建设、验收等所有手续相关费用）含在固定综合单价中，不再单独体现。
A11: 5 | B11: 强弱电、给排水、消防、暖通等专业开洞、封堵、套管等，包含在对应专业的管道固定综合单价中，不再单独列清单。
A12: 6 | B12: 方案图纸设计费（包括但不限于涉及本项目的各专业工程（建筑、装饰、结构、幕墙、消防、电气、照明、给排水、暖通等）图纸深化、报审、审图、现场施工指导配合、竣工图编制等所有图纸相关费用），按照平方米进行计价，未使用区域、室内、外停车位不计算，部分店面涉及室外院落、隔离墙、道路规划，不计量，不单独计价。
A13: 7 | B13: 需进行政府竣工验收的费用，及因验收产生的检测费用均含在综合单价内。
A14: 8 | B14: 投标单位在投标前应踏勘现场，充分考虑现场、方案设计等实际情况(如:运输条件、施工场地、地质条件、施工时间区段等)；综合考虑现场实际地面找平厚度与清单、方案设计不一致时，价格不进行调整，投标单位也应深入理解技术要求和验收要求,所有在招标时提供的文件均认为已完整无误包含在报价之中；
A15: 9 | B15: 无节点做法，可自行深化，经甲方确认后实施，费用包含在综合单价相关子目中。
A16: 10 | B16: 对于新增项目或签证、设计变更产生的工程项目造价的调整按以下顺序执行：
A17: 10.1 | B17: 工程量清单表中有相同工程内容的项目，按相同项目综合单价执行，根据工程量增减进行总价调整；同标段或是同期其他分包合同有相同项目或类似项目单价，按照该单价计取。
A18: 10.2 | B18: 工程量清单表中有类似工程内容的项目，如某项清单发包人要求主要材料更换，则原综合单价不变，只调整主材价差，土建材料价差=（双方确定含税材料价格-本合同清单表内注明的主材价格）× (1+税金)。
... A20: 11 | B20: 本页不得删除,将作为合同清单的有效组成部分。

Sheet 2-报价汇总
A1: 工程报价汇总表 | F1: 其他 综合费率 | G1: 0.207
A2: 公司名称：深圳市广湾建设科技有限公司 | D2: 单位：元
A3: 序号 | B3: 单 位 工 程 名 称 | C3: 报价汇总 | D3: 备注
A4: 1 | B4: 装饰工程 | C4: ='2.1装饰工程'!M370 -> 4086904.2 | E4: 4126563.6 | F4: =C4-E4 -> -39659.318
A5: 2 | B5: 强电工程 | C5: ='2.2强电工程'!M211 -> 466528.86 | E5: 467688.42 | F5: =C5-E5 -> -1159.5581
A6: 3 | B6: 弱电工程 | C6: ='2.3弱电工程'!M98 -> 334909.49 | E6: 335741.91 | F6: =C6-E6 -> -832.41796
A7: 4 | B7: 给排水工程 | C7: ='2.4给排水工程'!M113 -> 36186.655 | E7: 36276.597 | F7: =C7-E7 -> -89.941975
A8: 5 | B8: 消防工程 | C8: ='2.5消防工程'!M265 -> 344458.75 | E8: 345692.79 | F8: =C8-E8 -> -1234.0357
A9: 6 | B9: 暖通工程 | C9: ='2.6暖通工程'!M145 -> 694220.44 | E9: 695945.92 | F9: =C9-E9 -> -1725.4858
A10: 7 | B10: 合计 | C10: =SUM(C4:C9) -> 5963208.4 | E10: 6007909.2 | F10: =C10-E10 -> -44700.757

Sheet 2.1装饰工程
A1: 长城智选中心店装修项目装饰工程
A2: 序号 | B2: 分部分项名称 | C2: 项目特征 | D2: 计量规则 | E2: 单位 | F2: 工程量 | G2: 综合单价 | H2: 人工 | I2: 主材 | J2: 辅材 | K2: 机械 | L2: 其他 综合费率 | M2: 合计 | N2: 备注
A3: 一 | B3: 方案设计费
A4: 1 | B4: 方案图纸设计费 | C4: 1.包含建筑及装饰、结构、电气、暖通、给排水、消防、幕墙等专业，前期需现场踏勘，出具平面图、效果图等 2.包括但不限于图纸深化、报审、审图、竣工图编制等图纸相关费用 | D4: 以设计图纸尺寸按室内空间净面积计量（含不与墙面交集的柱面积），未使用区域、室内、外停车位不计算 | E4: m2 | F4: 2900 | G4: =(H4+I4+J4+K4)*(1+L4) -> 48.28 | H4: =VLOOKUP(B4,'[1]2.1装饰工程'!$B$4:$H$354,7,0) -> 40 | I4: =VLOOKUP(B4,'[1]2.1装饰工程'!$B$4:$I$354,8,0) -> 0 | J4: =VLOOKUP(B4,'[1]2.1装饰工程'!$B$4:$J$354,9,0) -> 0 | K4: =VLOOKUP(B4,'[1]2.1装饰工程'!$B$4:$K$354,10,0) -> 0 | L4: ='2-报价汇总'!$G$1 -> 0.207 | M4: =F4*G4 -> 140012
A5: 二 | B5: 拆除工程
A6: 1 | B6: 素混凝土拆除 | C6: 1.素混凝土构件拆除（含平面、立面、基础等） 2.包括：墙体内的管线、开关、插座等，达到不妨碍后期装修的程度，拆除后的所有材料施工单位自行处理 3.其他：满足施工要求 | D6: 工程量按拆除构件的混凝土体积计算 | E6: m3 | G6: =(H6+I6+J6+K6)*(1+L6) -> 411.56286 | H6: =VLOOKUP(B6,'[1]2.1装饰工程'!$B$4:$H$354,7,0) -> 250.88 | I6: =VLOOKUP(B6,'[1]2.1装饰工程'!$B$4:$I$354,8,0) -> 0 | J6: =VLOOKUP(B6,'[1]2.1装饰工程'!$B$4:$J$354,9,0) -> 7.47 | K6: =VLOOKUP(B6,'[1]2.1装饰工程'!$B$4:$K$354,10,0) -> 82.63 | L6: =$L$4 -> 0.207 | M6: =F6*G6 -> 0
A7: 2 | B7: 钢筋混凝土构件拆除 | C7: 1.钢筋混凝土构件拆除（含平面、立面、基础等） 2.包括：墙体内的管线、开关、插座等，达到不妨碍后期装修的程度，拆除后的所有材料施工单位自行处理 3.其他：满足施工要求 | D7: 工程量按拆除构件的混凝土体积计算 | E7: m3 | F7: 3.09 | G7: =(H7+I7+J7+K7)*(1+L7) -> 569.18499 | H7: =VLOOKUP(B7,'[1]2.1装饰工程'!$B$4:$H$354,7,0) -> 339 | I7: =VLOOKUP(B7,'[1]2.1装饰工程'!$B$4:$I$354,8,0) -> 0 | J7: =VLOOKUP(B7,'[1]2.1装饰工程'!$B$4:$J$354,9,0) -> 9.2 | K7: =VLOOKUP(B7,'[1]2.1装饰工程'!$B$4:$K$354,10,0) -> 123.37 | L7: =$L$4 -> 0.207 | M7: =F7*G7 -> 1758.7816
A8: 3 | B8: 金属构件拆除 | C8: 1.金属构件拆除（综合考虑钢构件规格尺寸） 2.包括：其中的管线、开关、插座等，达到不妨碍后期装修的程度，拆除后的所有材料施工单位自行处理 3.其他：满足施工要求 | D8: 工程量按拆除构件的质量计算 | E8: t | G8: =(H8+I8+J8+K8)*(1+L8) -> 830.09011 | H8: =VLOOKUP(B8,'[1]2.1装饰工程'!$B$4:$H$354,7,0) -> 674.73 | I8: =VLOOKUP(B8,'[1]2.1装饰工程'!$B$4:$I$354,8,0) -> 0 | J8: =VLOOKUP(B8,'[1]2.1装饰工程'!$B$4:$J$354,9,0) -> 0 | K8: =VLOOKUP(B8,'[1]2.1装饰工程'!$B$4:$K$354,10,0) -> 13 | L8: =$L$4 -> 0.207 | M8: =F8*G8 -> 0
A9: 4 | B9: 砌体墙拆除 | C9: 1.砌筑墙体拆除，连墙体内砼柱破碎后装袋 2.包括：砌体墙及附属的基层面层，墙体内的管线、开关、插座等，达到不妨碍装修的程度，拆除后的所有材料施工单位自行处理 3.其他：满足施工要求 | D9: 工程量按拆除部位的体积计算 | E9: m3 | F9: 310 | G9: =(H9+I9+J9+K9)*(1+L9) -> 243.66916 | H9: =VLOOKUP(B9,'[1]2.1装饰工程'!$B$4:$H$354,7,0) -> 136.88 | I9: =VLOOKUP(B9,'[1]2.1装饰工程'!$B$4:$I$354,8,0) -> 0 | J9: =VLOOKUP(B9,'[1]2.1装饰工程'!$B$4:$J$354,9,0) -> 0 | K9: =VLOOKUP(B9,'[1]2.1装饰工程'!$B$4:$K$354,10,0) -> 65 | L9: =$L$4 -> 0.207 | M9: =F9*G9 -> 75537.44
A10: 5 | B10: 玻璃隔墙拆除 | C10: 1.玻璃隔墙拆除 2.包括：玻璃隔墙及附属的基层面层，墙体内的管线、开关、插座等，达到不妨碍装修的程度，拆除后的所有材料施工单位自行处理 3.墙体厚度：综合考虑 4.其他：满足施工要求 | D10: 工程量按拆除部位的面积计算 | E10: m2 | G10: =(H10+I10+J10+K10)*(1+L10) -> 28.85937 | H10: =VLOOKUP(B10,'[1]2.1装饰工程'!$B$4:$H$354,7,0) -> 10.91 | I10: =VLOOKUP(B10,'[1]2.1装饰工程'!$B$4:$I$354,8,0) -> 0 | J10: =VLOOKUP(B10,'[1]2.1装饰工程'!$B$4:$J$354,9,0) -> 0 | K10: =VLOOKUP(B10,'[1]2.1装饰工程'!$B$4:$K$354,10,0) -> 13 | L10: =$L$4 -> 0.207 | M10: =F10*G10 -> 0
A11: 6 | B11: 石膏板隔墙拆除 | C11: 1.石膏板隔墙拆除 2.包括：石膏板隔墙及附属的基层面层，墙体内的管线、开关、插座等，达到不妨碍装修的程度，拆除后的所有材料施工单位自行处理 3.墙体厚度：综合考虑， 4.其他：满足施工要求 | D11: 工程量按拆除部位的面积计算 | E11: m2 | G11: =(H11+I11+J11+K11)*(1+L11) -> 30.06637 | H11: =VLOOKUP(B11,'[1]2.1装饰工程'!$B$4:$H$354,7,0) -> 14.91 | I11: =VLOOKUP(B11,'[1]2.1装饰工程'!$B$4:$I$354,8,0) -> 0 | J11: =VLOOKUP(B11,'[1]2.1装饰工程'!$B$4:$J$354,9,0) -> 0 | K11: =VLOOKUP(B11,'[1]2.1装饰工程'!$B$4:$K$354,10,0) -> 10 | L11: =$L$4 -> 0.207 | M11: =F11*G11 -> 0
A12: 7 | B12: 砌体墙开门洞（含修补） | C12: 1.砌体墙开门洞（含修补） 2.包括：砌体墙隔墙及附属的基层面层，墙体内的管线、开关、插座等，达到不妨碍装修的程度，拆除后的所有材料施工单位自行处理 3.墙体厚度：综合考虑，包含开门洞的修补工作 4.其他：满足施工要求 | D12: 工程量按拆除部位的面积计算 | E12: m2 | G12: =(H12+I12+J12+K12)*(1+L12) -> 99.27575 | H12: =VLOOKUP(B12,'[1]2.1装饰工程'!$B$4:$H$354,7,0) -> 66.66 | I12: =VLOOKUP(B12,'[1]2.1装饰工程'!$B$4:$I$354,8,0) -> 0 | J12: =VLOOKUP(B12,'[1]2.1装饰工程'!$B$4:$J$354,9,0) -> 2.59 | K12: =VLOOKUP(B12,'[1]2.1装饰工程'!$B$4:$K$354,10,0) -> 13 | L12: =$L$4 -> 0.207 | M12: =F12*G12 -> 0
A13: 8 | B13: 门窗拆除（包括门框、门套） | C13: 1.门窗拆除 2.包括：门框、门套，不区分门窗材质，达到不妨碍装修的程度，拆除后的所有材料施工单位自行处理 3.其他：满足施工要求 | D13: 工程量按拆除面积计算 | E13: m2 | F13: 25.2 | G13: =(H13+I13+J13+K13)*(1+L13) -> 34.59262 | H13: =VLOOKUP(B13,'[1]2.1装饰工程'!$B$4:$H$354,7,0) -> 15.66 | I13: =VLOOKUP(B13,'[1]2.1装饰工程'!$B$4:$I$354,8,0) -> 0 | J13: =VLOOKUP(B13,'[1]2.1装饰工程'!$B$4:$J$354,9,0) -> 0 | K13: =VLOOKUP(B13,'[1]2.1装饰工程'!$B$4:$K$354,10,0) -> 13 | L13: =$L$4 -> 0.207 | M13: =F13*G13 -> 871.73402
A14: 9 | B14: 楼地面装饰物拆除 | C14: 1.楼地面装饰物拆除（包括但不限于地砖、地板、地毯、玻璃、PVC、环氧地坪等材质） 2.包括：装饰地面面层及基层，地面内的管线、开关、插座等，达到不妨碍后期地面装修的程度，拆除后的所有材料施工单位自行处理 3.其他：满足施工要求 | D14: 工程量按拆除面积计算 | E14: m2 | F14: 80 | G14: =(H14+I14+J14+K14)*(1+L14) -> 39.40855 | H14: =VLOOKUP(B14,'[1]2.1装饰工程'!$B$4:$H$354,7,0) -> 26.15 | I14: =VLOOKUP(B14,'[1]2.1装饰工程'!$B$4:$I$354,8,0) -> 0 | J14: =VLOOKUP(B14,'[1]2.1装饰工程'!$B$4:$J$354,9,0) -> 0 | K14: =VLOOKUP(B14,'[1]2.1装饰工程'!$B$4:$K$354,10,0) -> 6.5 | L14: =$L$4 -> 0.207 | M14: =F14*G14 -> 3152.684
A15: 10 | B15: 楼地面地毯拆除 | C15: 1.楼地面地毯拆除 2.包括：装饰地面面层及基层，地面内的管线、开关、插座等，达到不妨碍后期地面装修的程度，拆除后的所有材料施工单位自行处理 3.其他：满足施工要求 | D15: 工程量按拆除面积计算 | E15: m2 | G15: =(H15+I15+J15+K15)*(1+L15) -> 6.3304799 | H15: 4.9748052 | I15: 0 | J15: 0.05 | K15: 0.22 | L15: =$L$4 -> 0.207 | M15: =F15*G15 -> 0
A16: 11 | B16: 楼地面地砖拆除 | C16: 1.楼地面地砖拆除 2.包括：装饰地面面层及基层，地面内的管线、开关、插座等，达到不妨碍后期地面装修的程度，拆除后的所有材料施工单位自行处理 4.其他：满足施工要求 | D16: 工程量按拆除面积计算 | E16: m2 | G16: =(H16+I16+J16+K16)*(1+L16) -> 33.7751 | H16: 27.005628 | I16: 0 | J16: 0.27705628 | K16: 0.7 | L16: =$L$4 -> 0.207 | M16: =F16*G16 -> 0
A17: 12 | B17: 楼地面地板拆除 | C17: 1.楼地面地板拆除 2.包括：装饰地面面层及基层，地面内的管线、开关、插座等，达到不妨碍后期地面装修的程度，拆除后的所有材料施工单位自行处理 5.其他：满足施工要求 | D17: 工程量按拆除面积计算 | E17: m2 | G17: =(H17+I17+J17+K17)*(1+L17) -> 6.3304799 | H17: =H15 -> 4.9748052 | I17: =I15 -> 0 | J17: =J15 -> 0.05 | K17: =K15 -> 0.22 | L17: =$L$4 -> 0.207 | M17: =F17*G17 -> 0
A18: 13 | B18: 墙面、柱（梁）面装饰物拆除（含龙骨） | C18: 1.墙面装饰物拆除，含龙骨及基层板（包括但不限于石材、铝板、金属、木饰面、石膏板等材质） 2.包括：拆除装饰墙面龙骨、基层板及面层，地面内的管线、开关、插座等，达到不妨碍后期墙面装修的程度，拆除后的所有材料施工单位自行处理 3.其他：满足施工要求 | D18: 工程量按拆除面积计算 | E18: m2 | G18: =(H18+I18+J18+K18)*(1+L18) -> 34.18224 | H18: =VLOOKUP(B18,'[1]2.1装饰工程'!$B$4:$H$354,7,0) -> 21.82 | I18: =VLOOKUP(B18,'[1]2.1装饰工程'!$B$4:$I$354,8,0) -> 0 | J18: =VLOOKUP(B18,'[1]2.1装饰工程'!$B$4:$J$354,9,0) -> 0 | K18: =VLOOKUP(B18,'[1]2.1装饰工程'!$B$4:$K$354,10,0) -> 6.5 | L18: =$L$4 -> 0.207 | M18: =F18*G18 -> 0
A19: 14 | B19: 墙面、柱（梁）面装饰物拆除（不含龙骨） | C19: 1.墙面装饰物拆除，不含龙骨（包括但不限于石材、铝板、金属、木饰面等材质） 2.包括：拆除装饰墙面基层及面层，地面内的管线、开关、插座等，达到不妨碍后期墙面装修的程度，拆除后的所有材料施工单位自行处理 3.其他：满足施工要求 | D19: 工程量按拆除面积计算 | E19: m2 | G19: =(H19+I19+J19+K19)*(1+L19) -> 27.04887 | H19: =VLOOKUP(B19,'[1]2.1装饰工程'!$B$4:$H$354,7,0) -> 15.91 | I19: =VLOOKUP(B19,'[1]2.1装饰工程'!$B$4:$I$354,8,0) -> 0 | J19: =VLOOKUP(B19,'[1]2.1装饰工程'!$B$4:$J$354,9,0) -> 0 | K19: =VLOOKUP(B19,'[1]2.1装饰工程'!$B$4:$K$354,10,0) -> 6.5 | L19: =$L$4 -> 0.207 | M19: =F19*G19 -> 0
A20: 15 | B20: 铲除涂料、裱糊面 | C20: 1.铲除涂料、裱糊面（综合考虑铲除部位） 2.包括：拆除装饰墙面涂料、腻子，地面内的管线、开关、插座等，达到不妨碍后期装修的程度，拆除后的所有材料施工单位自行处理 3.其他：满足施工要求 | D20: 工程量按拆除面积计算 | E20: m2 | G20: =(H20+I20+J20+K20)*(1+L20) -> 9.02836 | H20: 4.23 | K20: 3.25 | L20: =$L$4 -> 0.207 | M20: =F20*G20 -> 0
A21: 16 | B21: 钢结构表面油漆铲除 | C21: 1.钢结构表面油漆铲除 2.包括：表面油漆铲除及钢结构表面清理，达到不妨碍后期装修的程度，拆除后的所有材料施工单位自行处理 3.其他：满足施工要求 | D21: 工程量按拆除面积计算 | E21: m2 | G21: =(H21+I21+J21+K21)*(1+L21) -> 16.59625 | H21: 8.5 | K21: 5.25 | L21: =$L$4 -> 0.207 | M21: =F21*G21 -> 0
A22: 17 | B22: 玻璃贴膜拆除 | C22: 1.玻璃贴膜拆除 2.包括：清除玻璃贴膜，达到不妨碍装修的程度，拆除后的所有材料施工单位自行处理 3.其他：满足施工要求 | D22: 工程量按拆除面积计算 | E22: m2 | G22: =(H22+I22+J22+K22)*(1+L22) -> 9.57151 | H22: =VLOOKUP(B22,'[1]2.1装饰工程'!$B$4:$H$354,7,0) -> 4.68 | I22: =VLOOKUP(B22,'[1]2.1装饰工程'!$B$4:$I$354,8,0) -> 0 | J22: =VLOOKUP(B22,'[1]2.1装饰工程'!$B$4:$J$354,9,0) -> 0 | K22: =VLOOKUP(B22,'[1]2.1装饰工程'!$B$4:$K$354,10,0) -> 3.25 | L22: =$L$4 -> 0.207 | M22: =F22*G22 -> 0
A23: 18 | B23: 吊顶拆除 | C23: 1.吊顶拆除（包括但不限于石膏板、铝扣板、矿棉板等材质） 2.包括：转换层、龙骨、基层、面层及配套的风口、灯具、线管、吊顶上水管风管等所有材料，达到不妨碍吊顶装修的程度，拆除后的所有材料施工单位自行处理 3.其他：满足施工要求 | D23: 工程量按拆除面积计算 | E23: m2 | F23: 79 | G23: =(H23+I23+J23+K23)*(1+L23) -> 22.86058 | H23: =VLOOKUP(B23,'[1]2.1装饰工程'!$B$4:$H$354,7,0) -> 12.44 | I23: =VLOOKUP(B23,'[1]2.1装饰工程'!$B$4:$I$354,8,0) -> 0 | J23: =VLOOKUP(B23,'[1]2.1装饰工程'!$B$4:$J$354,9,0) -> 0 | K23: =VLOOKUP(B23,'[1]2.1装饰工程'!$B$4:$K$354,10,0) -> 6.5 | L23: =$L$4 -> 0.207 | M23: =F23*G23 -> 1805.9858
A24: 19 | B24: 玻璃幕墙拆除 | C24: 1.玻璃幕墙拆除 2.包括：幕墙、基层板、龙骨及辅材（包含破碎后装袋），达到不妨碍装修的程度，拆除后的所有材料施工单位自行处理 3.其他：满足施工要求 | D24: 工程量按拆除面积计算 | E24: m2 | G24: =(H24+I24+J24+K24)*(1+L24) -> 51.44234 | H24: 36.12 | I24: 0 | J24: 0 | K24: 6.5 | L24: =$L$4 -> 0.207 | M24: =F24*G24 -> 0
A25: 20 | B25: 金属幕墙拆除 | C25: 1.金属幕墙拆除 2.包括：幕墙、基层板、龙骨及辅材（包含破碎后装袋），达到不妨碍装修的程度，拆除后的所有材料施工单位自行处理 3.其他：满足施工要求 | D25: 工程量按拆除面积计算 | E25: m2 | G25: =(H25+I25+J25+K25)*(1+L25) -> 51.44234 | H25: 36.12 | I25: 0 | J25: 0 | K25: 6.5 | L25: =$L$4 -> 0.207 | M25: =F25*G25 -> 0
A26: 21 | B26: 外幕墙拆除 | C26: 1.外幕墙拆除（包括石材、铝塑板等材质） 2.包括：幕墙、基层板、龙骨及辅材（包含破碎后装袋），达到不妨碍装修的程度，拆除后的所有材料施工单位自行处理 3.其他：满足施工要求 | D26: 工程量按拆除面积计算 | E26: m2 | G26: =(H26+I26+J26+K26)*(1+L26) -> 51.44234 | H26: =VLOOKUP(B26,'[1]2.1装饰工程'!$B$4:$H$354,7,0) -> 36.12 | I26: =VLOOKUP(B26,'[1]2.1装饰工程'!$B$4:$I$354,8,0) -> 0 | J26: =VLOOKUP(B26,'[1]2.1装饰工程'!$B$4:$J$354,9,0) -> 0 | K26: =VLOOKUP(B26,'[1]2.1装饰工程'!$B$4:$K$354,10,0) -> 6.5 | L26: =$L$4 -> 0.207 | M26: =F26*G26 -> 0
A27: 22 | B27: 栏杆、栏板拆除 | C27: 1.栏杆、栏板拆除（综合考虑栏杆、栏板的材质及高度） 2.包括：达到不妨碍装修的程度，拆除后的所有材料施工单位自行处理 3.其他：满足施工要求 | D27: 工程量按拆除长度计算 | E27: m | G27: =(H27+I27+J27+K27)*(1+L27) -> 20.80868 | H27: =VLOOKUP(B27,'[1]2.1装饰工程'!$B$4:$H$354,7,0) -> 10.74 | I27: =VLOOKUP(B27,'[1]2.1装饰工程'!$B$4:$I$354,8,0) -> 0 | J27: =VLOOKUP(B27,'[1]2.1装饰工程'!$B$4:$J$354,9,0) -> 0 | K27: =VLOOKUP(B27,'[1]2.1装饰工程'!$B$4:$K$354,10,0) -> 6.5 | L27: =$L$4 -> 0.207 | M27: =F27*G27 -> 0
A28: 23 | B28: 电气、暖通等拆除费用 | C28: 1.电气、暖通等拆除费用（裸顶） 2.包括：达到不妨碍装修的程度，拆除后的所有材料施工单位自行处理 3.其他：满足施工要求 | D28: 工程量按拆除裸顶天棚水平投影面积计算 | E28: m2 | G28: =(H28+I28+J28+K28)*(1+L28) -> 17.19975 | H28: =VLOOKUP(B28,'[1]2.1装饰工程'!$B$4:$H$354,7,0) -> 11 | I28: =VLOOKUP(B28,'[1]2.1装饰工程'!$B$4:$I$354,8,0) -> 0 | J28: =VLOOKUP(B28,'[1]2.1装饰工程'!$B$4:$J$354,9,0) -> 0 | K28: =VLOOKUP(B28,'[1]2.1装饰工程'!$B$4:$K$354,10,0) -> 3.25 | L28: =$L$4 -> 0.207 | M28: =F28*G28 -> 0
A29: 24 | B29: 卷帘拆除 | C29: 1.卷帘及配置等拆除 2.拆除后的所有材料施工单位自行处理 3.其他：满足施工要求 | D29: 工程量按拆除面积计算 | E29: m2 | G29: =(H29+I29+J29+K29)*(1+L29) -> 15.854076 | H29: 12.435108 | I29: 0 | J29: 0.15 | K29: 0.55 | L29: =$L$4 -> 0.207 | M29: =F29*G29 -> 0
A30: 25 | B30: 保洁费 | C30: 1.保洁费 2.包括：精保洁，满足开业条件 3.其他:详见SI手册、品牌表及标准节点等，满足施工要求及国家规范 | D30: 工程量按装修店面装修面积计算 | E30: m2 | F30: 2900 | G30: =(H30+I30+J30+K30)*(1+L30) -> 16.898 | H30: =VLOOKUP(B30,'[1]2.1装饰工程'!$B$4:$H$354,7,0) -> 14 | I30: =VLOOKUP(B30,'[1]2.1装饰工程'!$B$4:$I$354,8,0) -> 0 | J30: =VLOOKUP(B30,'[1]2.1装饰工程'!$B$4:$J$354,9,0) -> 0 | K30: =VLOOKUP(B30,'[1]2.1装饰工程'!$B$4:$K$354,10,0) -> 0 | L30: =$L$4 -> 0.207 | M30: =F30*G30 -> 49004.2
A31: 三 | B31: 结构及结构加固工程
A32: 1 | B32: 构造柱/抱框柱 | C32: 1.混凝土种类:商品砼（含钢筋及模板） 2.混凝土强度等级:C25 3.构造柱带马牙槎 4.工作内容:混凝土制作、运输、浇筑、振捣、养护 5.其他:详见SI手册、品牌表及标准节点等，满足施工要求及国家规范 | D32: 按设计图示尺寸以体积计算 | E32: m3 | F32: 12 | G32: =(H32+I32+J32+K32)*(1+L32) -> 1818.1765 | H32: =VLOOKUP(B32,'[1]2.1装饰工程'!$B$4:$H$354,7,0) -> 375.87 | I32: =VLOOKUP(B32,'[1]2.1装饰工程'!$B$4:$I$354,8,0) -> 1010.57 | J32: =VLOOKUP(B32,'[1]2.1装饰工程'!$B$4:$J$354,9,0) -> 0 | K32: =VLOOKUP(B32,'[1]2.1装饰工程'!$B$4:$K$354,10,0) -> 119.92 | L32: =$L$4 -> 0.207 | M32: =F32*G32 -> 21818.118
A33: 2 | B33: 圈梁/水平系梁/导墙 | C33: 1.混凝土种类:商品砼（含钢筋及模板） 2.混凝土强度等级:C25 3.工作内容:混凝土制作、运输、浇筑、振捣、养护 4.其他:详见SI手册、品牌表及标准节点等，满足施工要求及国家规范 | D33: 按设计图示尺寸以体积计算 | E33: m3 | G33: =(H33+I33+J33+K33)*(1+L33) -> 1737.6093 | H33: =VLOOKUP(B33,'[1]2.1装饰工程'!$B$4:$H$354,7,0) -> 375.87 | I33: =VLOOKUP(B33,'[1]2.1装饰工程'!$B$4:$I$354,8,0) -> 1044.42 | J33: =VLOOKUP(B33,'[1]2.1装饰工程'!$B$4:$J$354,9,0) -> 0 | K33: =VLOOKUP(B33,'[1]2.1装饰工程'!$B$4:$K$354,10,0) -> 19.32 | L33: =$L$4 -> 0.207 | M33: =F33*G33 -> 0
A34: 3 | B34: 过梁 | C34: 1.混凝土种类:商品砼（含钢筋及模板） 2.混凝土强度等级:C25 3.工作内容:混凝土制作、运输、浇筑、振捣、养护 4.其他:详见SI手册、品牌表及标准节点等，满足施工要求及国家规范 | D34: 按设计图示尺寸以体积计算 | E34: m3 | G34: =(H34+I34+J34+K34)*(1+L34) -> 1764.2478 | H34: =VLOOKUP(B34,'[1]2.1装饰工程'!$B$4:$H$354,7,0) -> 375.87 | I34: =VLOOKUP(B34,'[1]2.1装饰工程'!$B$4:$I$354,8,0) -> 957.89 | J34: =VLOOKUP(B34,'[1]2.1装饰工程'!$B$4:$J$354,9,0) -> 0 | K34: =VLOOKUP(B34,'[1]2.1装饰工程'!$B$4:$K$354,10,0) -> 127.92 | L34: =$L$4 -> 0.207 | M34: =F34*G34 -> 0
A35: 4 | B35: 化粪池 | C35: 1.成品玻璃钢化粪池 2.包含地面破碎开挖回填夯实及余土外运、成品化粪池制作运输及安装、套管等所有内容 3.按有效容积计算 4.其他:详见SI手册、品牌表及标准节点等，满足施工要求及国家规范 | D35: 按设计图示尺寸以体积计算 | E35: m3 | G35: =(H35+I35+J35+K35)*(1+L35) -> 783.60854 | H35: 87.12 | I35: 550 | J35: 6.3 | K35: 5.8 | L35: =$L$4 -> 0.207 | M35: =F35*G35 -> 0
A36: 5 | B36: 加气砌块砌筑墙 | C36: 1.加气砌块砌筑墙 2.墙体类型:综合考虑 3.砂浆强度等级:综合考虑 4.工作内容:砂浆制作、运输；砌砖、砌块；勾缝；材料运输 5.其他:详见SI手册、品牌表及标准节点等，满足施工要求及国家规范 | D36: 按设计图示尺寸以体积计算 | E36: m3 | F36: 150 | G36: =(H36+I36+J36+K36)*(1+L36) -> 934.22001 | H36: 216.03 | I36: 528.18 | J36: =4.5*(1/0.24) -> 18.75 | K36: =2.65*(1/0.24) -> 11.041667 | L36: =$L$4 -> 0.207 | M36: =F36*G36 -> 140133
A37: 6 | B37: 砖砌筑墙 | C37: 1.砖砌墙 2.墙体类型:综合考虑 3.砂浆强度等级:综合考虑 4.工作内容:砂浆制作、运输；砌砖、砌块；勾缝；材料运输 6.其他:详见SI手册、品牌表及标准节点等，满足施工要求及国家规范 | D37: 按设计图示尺寸以体积计算 | E37: m3 | F37: 150 | G37: =(H37+I37+J37+K37)*(1+L37) -> 1173.556 | H37: =55*(1/0.24) -> 229.16667 | I37: =200*(1/0.24)-120 -> 713.33333 | J37: =4.5*(1/0.24) -> 18.75 | K37: =2.65*(1/0.24) -> 11.041667 | L37: =$L$4 -> 0.207 | M37: =F37*G37 -> 176033.41
A38: 7 | B38: 预埋铁件 | C38: 1.钢材种类:钢板、锚筋等 2.规格:综合考虑 3.工作内容:铁件制作、运输、安装 4.其他:详见SI手册、品牌表及标准节点等，满足施工要求及国家规范 | D38: 按设计图示尺寸以质量计算，不扣除孔眼的质量，焊条、铆钉、螺栓等不另增加质量 | E38: t | F38: 0.5 | G38: =(H38+I38+J38+K38)*(1+L38) -> 10314.612 | H38: =VLOOKUP(B38,'[1]2.1装饰工程'!$B$4:$H$354,7,0) -> 2047.71 | I38: =VLOOKUP(B38,'[1]2.1装饰工程'!$B$4:$I$354,8,0) -> 6045.67 | J38: =VLOOKUP(B38,'[1]2.1装饰工程'!$B$4:$J$354,9,0) -> 0 | K38: =VLOOKUP(B38,'[1]2.1装饰工程'!$B$4:$K$354,10,0) -> 452.28 | L38: =$L$4 -> 0.207 | M38: =F38*G38 -> 5157.3058
A39: 8 | B39: 钢构件 | C39: 1.构件名称:综合考虑 2.钢材品种、规格:综合考虑 3.工作内容:构件场内外驳运、构件制作、安装 4.其他:详见SI手册、品牌表及标准节点等，满足施工要求及国家规范 | D39: 按设计图示尺寸以质量计算，不扣除孔眼的质量，焊条、铆钉、螺栓等不另增加质量 | E39: t | F39: 0.5 | G39: =(H39+I39+J39+K39)*(1+L39) -> 9875.5774 | H39: =VLOOKUP(B39,'[1]2.1装饰工程'!$B$4:$H$354,7,0) -> 2047.71 | I39: =VLOOKUP(B39,'[1]2.1装饰工程'!$B$4:$I$354,8,0) -> 5921.58 | J39: =VLOOKUP(B39,'[1]2.1装饰工程'!$B$4:$J$354,9,0) -> 0 | K39: =VLOOKUP(B39,'[1]2.1装饰工程'!$B$4:$K$354,10,0) -> 212.63 | L39: =$L$4 -> 0.207 | M39: =F39*G39 -> 4937.7887
A40: 9 | B40: 新做钢梯 | C40: 1.钢材品种、规格:综合考虑 2.钢梯形式:踏步式 3.螺栓种类:普通螺栓含在单价内，高强螺栓另行计取 4.包括:钢梯柱、钢梯梁、踏步板、休息平台、连接板等 5.其他:详见SI手册、品牌表及标准节点等，满足施工要求及国家规范 | D40: 按设计图示尺寸以质量计算，不扣除孔眼的质量，焊条、铆钉、螺栓等不另增加质量 | E40: t | F40: 2 | G40: =(H40+I40+J40+K40)*(1+L40) -> 11166.416 | H40: =VLOOKUP(B40,'[1]2.1装饰工程'!$B$4:$H$354,7,0) -> 918.01 | I40: =VLOOKUP(B40,'[1]2.1装饰工程'!$B$4:$I$354,8,0) -> 8020.14 | J40: =VLOOKUP(B40,'[1]2.1装饰工程'!$B$4:$J$354,9,0) -> 0 | K40: =VLOOKUP(B40,'[1]2.1装饰工程'!$B$4:$K$354,10,0) -> 313.23 | L40: =$L$4 -> 0.207 | M40: =F40*G40 -> 22332.831
...

Sheet 2.2强电工程
A1: 长城智选中心店装修项目装饰工程
A2: 序号 | B2: 分部分项名称 | C2: 项目特征 | D2: 计量规则 | E2: 单位 | F2: 工程量 | G2: 综合单价 | H2: 人工 | I2: 主材 | J2: 辅材 | K2: 机械 | L2: 其他综合费率 | M2: 合计 | N2: 备注
A3: 一 | B3: 配电系统
A4: 1 | B4: 落地式配电箱 | C4: 1.名称:落地式配电箱 2.基础形式、材质、规格:10#基础槽钢 3.接线端子材质、规格:按设计及规范要求 4.端子板外部接线材质、规格:按设计及规范要求 5.安装方式:落地式 6.其他:含智能电表、时控开关、电气元器件及配套附件成套费用 | D4: 按设计图示数量计算 | E4: 台 | F4: 2 | G4: =(H4+I4+J4+K4)*(1+L4) -> 9919.126 | H4: =VLOOKUP(B4,'[1]2.2强电工程'!$B$4:$H$254,7,0) -> 524.73 | I4: =VLOOKUP(B4,'[1]2.2强电工程'!$B$4:$I$254,8,0) -> 7637.4 | J4: =VLOOKUP(B4,'[1]2.2强电工程'!$B$4:$J$254,9,0) -> 36.96 | K4: =VLOOKUP(B4,'[1]2.2强电工程'!$B$4:$K$254,10,0) -> 18.91 | L4: ='2.1装饰工程'!$L$4 -> 0.207 | M4: =F4*G4 -> 19838.252
A5: 2 | B5: 落地式配电箱（IP65防水型） | C5: 1.名称:落地式配电箱（IP65防水型） 2.基础形式、材质、规格:10#基础槽钢 3.接线端子材质、规格:按设计及规范要求 4.端子板外部接线材质、规格:按设计及规范要求 5.安装方式:落地式 6.其他:含智能电表、时控开关、电气元器件及配套附件成套费用 | D5: 按设计图示数量计算 | E5: 台 | F5: 2 | G5: =(H5+I5+J5+K5)*(1+L5) -> 10239.572 | H5: =VLOOKUP(B5,'[1]2.2强电工程'!$B$4:$H$254,7,0) -> 524.73 | I5: =VLOOKUP(B5,'[1]2.2强电工程'!$B$4:$I$254,8,0) -> 7902.89 | J5: =VLOOKUP(B5,'[1]2.2强电工程'!$B$4:$J$254,9,0) -> 36.96 | K5: =VLOOKUP(B5,'[1]2.2强电工程'!$B$4:$K$254,10,0) -> 18.91 | L5: =$L$4 -> 0.207 | M5: =F5*G5 -> 20479.145
A6: 3 | B6: 配电箱 | C6: 1.名称::配电箱（嵌入/悬挂） 2.规格:半周长2.5m 3.接线端子材质、规格:按设计及规范要求 4.端子板外部接线材质、规格:按设计及规范要求 5.安装方式:悬挂式 6.其他:含智能电表、时控开关、电气元器件及配套附件成套费用 | D6: 按设计图示数量计算 | E6: 台 | F6: 2 | G6: =(H6+I6+J6+K6)*(1+L6) -> 4683.7876 | H6: 448.4 | I6: 3407.08 | J6: 21.43 | K6: 3.61 | L6: =$L$4 -> 0.207 | M6: =F6*G6 -> 9367.5753
A7: 4 | B7: 配电箱 | C7: 1.名称::配电箱（嵌入/悬挂） 2.规格:半周长1.5m 3.接线端子材质、规格:按设计及规范要求 4.端子板外部接线材质、规格:按设计及规范要求 5.安装方式:悬挂式 6.其他:含智能电表、时控开关、电气元器件及配套附件成套费用 | D7: 按设计图示数量计算 | E7: 台 | F7: 3 | G7: =(H7+I7+J7+K7)*(1+L7) -> 2698.9003 | H7: 373.78 | I7: 1840.71 | J7: 17.94 | K7: 3.61 | L7: =$L$4 -> 0.207 | M7: =F7*G7 -> 8096.7008
A8: 5 | B8: 配电箱 | C8: 1.名称::配电箱（嵌入/悬挂） 2.规格:半周长1.0m 3.接线端子材质、规格:按设计及规范要求 4.端子板外部接线材质、规格:按设计及规范要求 5.安装方式:悬挂式 6.其他:含智能电表、时控开关、电气元器件及配套附件成套费用 | D8: 按设计图示数量计算 | E8: 台 | F8: 3 | G8: =(H8+I8+J8+K8)*(1+L8) -> 1447.5551 | H8: 249.11 | I8: 929.2 | J8: 17.38 | K8: 3.61 | L8: =$L$4 -> 0.207 | M8: =F8*G8 -> 4342.6653
A9: 6 | B9: 配电箱 | C9: 1.名称::配电箱（嵌入/悬挂） 2.规格:半周长0.5m 3.接线端子材质、规格:按设计及规范要求 4.端子板外部接线材质、规格:按设计及规范要求 5.安装方式:悬挂式 6.其他:含智能电表、时控开关、电气元器件及配套附件成套费用 | D9: 按设计图示数量计算 | E9: 台 | F9: 3 | G9: =(H9+I9+J9+K9)*(1+L9) -> 844.86379 | H9: 166.08 | I9: 513.27 | J9: 17.01 | K9: 3.61 | L9: =$L$4 -> 0.207 | M9: =F9*G9 -> 2534.5914
A10: 7 | B10: 应急照明配电箱 | C10: 1.名称:应急照明配电箱 2.接线端子材质、规格:按设计及规范要求 3.端子板外部接线材质、规格:按设计及规范要求 4.其他:含元器件及配套附件成套费用 | D10: 按设计图示数量计算 | E10: 台 | F10: 1 | G10: =(H10+I10+J10+K10)*(1+L10) -> 3570.5836 | H10: =VLOOKUP(B10,'[1]2.2强电工程'!$B$4:$H$254,7,0) -> 398.21 | I10: =VLOOKUP(B10,'[1]2.2强电工程'!$B$4:$I$254,8,0) -> 2500 | J10: =VLOOKUP(B10,'[1]2.2强电工程'!$B$4:$J$254,9,0) -> 41.11 | K10: =VLOOKUP(B10,'[1]2.2强电工程'!$B$4:$K$254,10,0) -> 18.91 | L10: =$L$4 -> 0.207 | M10: =F10*G10 -> 3570.5836
A11: 8 | B11: 电缆WDZA-YJV-3*240+2*120 | C11: 1.名称:电力电缆 2.型号:WDZA-YJV 3.规格:3*240+2*120 4.材质:铜芯 5.敷设方式、部位:桥架内及配管内敷设 6.电压等级(kV):1.0KV | D11: 按设计图示尺寸以长度计算（含预留长度及附加长度） | E11: m | G11: =(H11+I11+J11+K11)*(1+L11) -> 856.16131 | H11: =VLOOKUP(B11,'[1]2.2强电工程'!$B$4:$H$254,7,0) -> 28.73 | I11: =VLOOKUP(B11,'[1]2.2强电工程'!$B$4:$I$254,8,0) -> 676.29 | J11: =VLOOKUP(B11,'[1]2.2强电工程'!$B$4:$J$254,9,0) -> 1.99 | K11: =VLOOKUP(B11,'[1]2.2强电工程'!$B$4:$K$254,10,0) -> 2.32 | L11: =$L$4 -> 0.207 | M11: =F11*G11 -> 0
A12: 9 | B12: 电缆WDZA-YJV-3*185+2*95 | C12: 1.名称:电力电缆 2.型号:WDZA-YJV 3.规格:3*185+2*95 4.材质:铜芯 5.敷设方式、部位:桥架内及配管内敷设 6.电压等级(kV):1.0KV | D12: 按设计图示尺寸以长度计算（含预留长度及附加长度） | E12: m | F12: 162.21 | G12: =(H12+I12+J12+K12)*(1+L12) -> 670.39194 | H12: =VLOOKUP(B12,'[1]2.2强电工程'!$B$4:$H$254,7,0) -> 28.73 | I12: =VLOOKUP(B12,'[1]2.2强电工程'!$B$4:$I$254,8,0) -> 522.38 | J12: =VLOOKUP(B12,'[1]2.2强电工程'!$B$4:$J$254,9,0) -> 1.99 | K12: =VLOOKUP(B12,'[1]2.2强电工程'!$B$4:$K$254,10,0) -> 2.32 | L12: =$L$4 -> 0.207 | M12: =F12*G12 -> 108744.28
A13: 10 | B13: 电缆WDZA-YJV-3*150+2*70 | C13: 1.名称:电力电缆 2.型号:WDZA-YJV 3.规格:3*150+2*70 4.材质:铜芯 5.敷设方式、部位:桥架内及配管内敷设 6.电压等级(kV):1.0KV | D13: 按设计图示尺寸以长度计算（含预留长度及附加长度） | E13: m | G13: =(H13+I13+J13+K13)*(1+L13) -> 532.84222 | H13: =VLOOKUP(B13,'[1]2.2强电工程'!$B$4:$H$254,7,0) -> 28.73 | I13: =VLOOKUP(B13,'[1]2.2强电工程'!$B$4:$I$254,8,0) -> 408.42 | J13: =VLOOKUP(B13,'[1]2.2强电工程'!$B$4:$J$254,9,0) -> 1.99 | K13: =VLOOKUP(B13,'[1]2.2强电工程'!$B$4:$K$254,10,0) -> 2.32 | L13: =$L$4 -> 0.207 | M13: =F13*G13 -> 0
A14: 11 | B14: 电缆WDZA-YJV-3*120+2*70 | C14: 1.名称:电力电缆 2.型号:WDZA-YJV 3.规格:3*120+2*70 4.材质:铜芯 5.敷设方式、部位:桥架内及配管内敷设 6.电压等级(kV):1.0KV | D14: 按设计图示尺寸以长度计算（含预留长度及附加长度） | E14: m | F14: 20 | G14: =(H14+I14+J14+K14)*(1+L14) -> 451.06797 | H14: =VLOOKUP(B14,'[1]2.2强电工程'!$B$4:$H$254,7,0) -> 20.72 | I14: =VLOOKUP(B14,'[1]2.2强电工程'!$B$4:$I$254,8,0) -> 350.6 | J14: =VLOOKUP(B14,'[1]2.2强电工程'!$B$4:$J$254,9,0) -> 1.25 | K14: =VLOOKUP(B14,'[1]2.2强电工程'!$B$4:$K$254,10,0) -> 1.14 | L14: =$L$4 -> 0.207 | M14: =F14*G14 -> 9021.3594
A15: 12 | B15: 电缆WDZA-YJV-3*95+2*50 | C15: 1.名称:电力电缆 2.型号:WDZA-YJV 3.规格:3*95+2*50 4.材质:铜芯 5.敷设方式、部位:桥架内及配管内敷设 6.电压等级(kV):1.0KV | D15: 按设计图示尺寸以长度计算（含预留长度及附加长度） | E15: m | G15: =(H15+I15+J15+K15)*(1+L15) -> 353.13199 | H15: =VLOOKUP(B15,'[1]2.2强电工程'!$B$4:$H$254,7,0) -> 20.72 | I15: =VLOOKUP(B15,'[1]2.2强电工程'!$B$4:$I$254,8,0) -> 269.46 | J15: =VLOOKUP(B15,'[1]2.2强电工程'!$B$4:$J$254,9,0) -> 1.25 | K15: =VLOOKUP(B15,'[1]2.2强电工程'!$B$4:$K$254,10,0) -> 1.14 | L15: =$L$4 -> 0.207 | M15: =F15*G15 -> 0
A16: 13 | B16: 电缆WDZA-YJV-3*70+2*35 | C16: 1.名称:电力电缆 2.型号:WDZA-YJV 3.规格:3*70+2*35 4.材质:铜芯 5.敷设方式、部位:桥架内及配管内敷设 6.电压等级(kV):1.0KV | D16: 按设计图示尺寸以长度计算（含预留长度及附加长度） | E16: m | G16: =(H16+I16+J16+K16)*(1+L16) -> 261.15859 | H16: =VLOOKUP(B16,'[1]2.2强电工程'!$B$4:$H$254,7,0) -> 17.42 | I16: =VLOOKUP(B16,'[1]2.2强电工程'!$B$4:$I$254,8,0) -> 196.8 | J16: =VLOOKUP(B16,'[1]2.2强电工程'!$B$4:$J$254,9,0) -> 1.01 | K16: =VLOOKUP(B16,'[1]2.2强电工程'!$B$4:$K$254,10,0) -> 1.14 | L16: =$L$4 -> 0.207 | M16: =F16*G16 -> 0
A17: 14 | B17: 电缆WDZA-YJV-3*50+2*25 | C17: 1.名称:电力电缆 2.型号:WDZA-YJV 3.规格:3*50+2*25 4.材质:铜芯 5.敷设方式、部位:桥架内及配管内敷设 6.电压等级(kV):1.0KV | D17: 按设计图示尺寸以长度计算（含预留长度及附加长度） | E17: m | G17: =(H17+I17+J17+K17)*(1+L17) -> 191.50262 | H17: =VLOOKUP(B17,'[1]2.2强电工程'!$B$4:$H$254,7,0) -> 17.42 | I17: =VLOOKUP(B17,'[1]2.2强电工程'!$B$4:$I$254,8,0) -> 139.09 | J17: =VLOOKUP(B17,'[1]2.2强电工程'!$B$4:$J$254,9,0) -> 1.01 | K17: =VLOOKUP(B17,'[1]2.2强电工程'!$B$4:$K$254,10,0) -> 1.14 | L17: =$L$4 -> 0.207 | M17: =F17*G17 -> 0
A18: 15 | B18: 电缆WDZA-YJV-3*35+2*16 | C18: 1.名称:电力电缆 2.型号:WDZA-YJV 3.规格:3*35+2*16 4.材质:铜芯 5.敷设方式、部位:桥架内及配管内敷设 6.电压等级(kV):1.0KV | D18: 按设计图示尺寸以长度计算（含预留长度及附加长度） | E18: m | G18: =(H18+I18+J18+K18)*(1+L18) -> 134.84604 | H18: =VLOOKUP(B18,'[1]2.2强电工程'!$B$4:$H$254,7,0) -> 11.07 | I18: =VLOOKUP(B18,'[1]2.2强电工程'!$B$4:$I$254,8,0) -> 99.38 | J18: =VLOOKUP(B18,'[1]2.2强电工程'!$B$4:$J$254,9,0) -> 1.11 | K18: =VLOOKUP(B18,'[1]2.2强电工程'!$B$4:$K$254,10,0) -> 0.16 | L18: =$L$4 -> 0.207 | M18: =F18*G18 -> 0
A19: 16 | B19: 电缆WDZA-YJV-3*25+2*16 | C19: 1.名称:电力电缆 2.型号:WDZA-YJV 3.规格:3*25+2*16 4.材质:铜芯 5.敷设方式、部位:桥架内及配管内敷设 6.电压等级(kV):1.0KV | D19: 按设计图示尺寸以长度计算（含预留长度及附加长度） | E19: m | G19: =(H19+I19+J19+K19)*(1+L19) -> 112.16651 | H19: =VLOOKUP(B19,'[1]2.2强电工程'!$B$4:$H$254,7,0) -> 11.07 | I19: =VLOOKUP(B19,'[1]2.2强电工程'!$B$4:$I$254,8,0) -> 80.59 | J19: =VLOOKUP(B19,'[1]2.2强电工程'!$B$4:$J$254,9,0) -> 1.11 | K19: =VLOOKUP(B19,'[1]2.2强电工程'!$B$4:$K$254,10,0) -> 0.16 | L19: =$L$4 -> 0.207 | M19: =F19*G19 -> 0
A20: 17 | B20: 电缆WDZA-YJV-4*185+1*95 | C20: 1.名称:电力电缆 2.型号:WDZA-YJV 3.规格:4*185+1*95 4.材质:铜芯 5.敷设方式、部位:桥架内及配管内敷设 6.电压等级(kV):1.0KV | D20: 按设计图示尺寸以长度计算（含预留长度及附加长度） | E20: m | G20: =(H20+I20+J20+K20)*(1+L20) -> 745.47941 | H20: =VLOOKUP(B20,'[1]2.2强电工程'!$B$4:$H$254,7,0) -> 28.73 | I20: =VLOOKUP(B20,'[1]2.2强电工程'!$B$4:$I$254,8,0) -> 584.59 | J20: =VLOOKUP(B20,'[1]2.2强电工程'!$B$4:$J$254,9,0) -> 1.99 | K20: =VLOOKUP(B20,'[1]2.2强电工程'!$B$4:$K$254,10,0) -> 2.32 | L20: =$L$4 -> 0.207 | M20: =F20*G20 -> 0
A21: 18 | B21: 电缆WDZA-YJV-4*150+1*70 | C21: 1.名称:电力电缆 2.型号:WDZA-YJV 3.规格:4*150+1*70 4.材质:铜芯 5.敷设方式、部位:桥架内及配管内敷设 6.电压等级(kV):1.0KV | D21: 按设计图示尺寸以长度计算（含预留长度及附加长度） | E21: m | G21: =(H21+I21+J21+K21)*(1+L21) -> 599.09445 | H21: =VLOOKUP(B21,'[1]2.2强电工程'!$B$4:$H$254,7,0) -> 28.73 | I21: =VLOOKUP(B21,'[1]2.2强电工程'!$B$4:$I$254,8,0) -> 463.31 | J21: =VLOOKUP(B21,'[1]2.2强电工程'!$B$4:$J$254,9,0) -> 1.99 | K21: =VLOOKUP(B21,'[1]2.2强电工程'!$B$4:$K$254,10,0) -> 2.32 | L21: =$L$4 -> 0.207 | M21: =F21*G21 -> 0
A22: 19 | B22: 电缆WDZA-YJV-4*120+1*70 | C22: 1.名称:电力电缆 2.型号:WDZA-YJV 3.规格:4*120+1*70 4.材质:铜芯 5.敷设方式、部位:桥架内及配管内敷设 6.电压等级(kV):1.0KV | D22: 按设计图示尺寸以长度计算（含预留长度及附加长度） | E22: m | G22: =(H22+I22+J22+K22)*(1+L22) -> 493.72335 | H22: =VLOOKUP(B22,'[1]2.2强电工程'!$B$4:$H$254,7,0) -> 20.72 | I22: =VLOOKUP(B22,'[1]2.2强电工程'!$B$4:$I$254,8,0) -> 385.94 | J22: =VLOOKUP(B22,'[1]2.2强电工程'!$B$4:$J$254,9,0) -> 1.25 | K22: =VLOOKUP(B22,'[1]2.2强电工程'!$B$4:$K$254,10,0) -> 1.14 | L22: =$L$4 -> 0.207 | M22: =F22*G22 -> 0
A23: 20 | B23: 电缆WDZA-YJV-4*95+1*50 | C23: 1.名称:电力电缆 2.型号:WDZA-YJV 3.规格:4*95+1*50 4.材质:铜芯 5.敷设方式、部位:桥架内及配管内敷设 6.电压等级(kV):1.0KV | D23: 按设计图示尺寸以长度计算（含预留长度及附加长度） | E23: m | G23: =(H23+I23+J23+K23)*(1+L23) -> 392.74573 | H23: =VLOOKUP(B23,'[1]2.2强电工程'!$B$4:$H$254,7,0) -> 20.72 | I23: =VLOOKUP(B23,'[1]2.2强电工程'!$B$4:$I$254,8,0) -> 302.28 | J23: =VLOOKUP(B23,'[1]2.2强电工程'!$B$4:$J$254,9,0) -> 1.25 | K23: =VLOOKUP(B23,'[1]2.2强电工程'!$B$4:$K$254,10,0) -> 1.14 | L23: =$L$4 -> 0.207 | M23: =F23*G23 -> 0
A24: 21 | B24: 电缆WDZA-YJV-4*70+1*35 | C24: 1.名称:电力电缆 2.型号:WDZA-YJV 3.规格:4*70+1*35 4.材质:铜芯 5.敷设方式、部位:桥架内及配管内敷设 6.电压等级(kV):1.0KV | D24: 按设计图示尺寸以长度计算（含预留长度及附加长度） | E24: m | G24: =(H24+I24+J24+K24)*(1+L24) -> 289.53516 | H24: =VLOOKUP(B24,'[1]2.2强电工程'!$B$4:$H$254,7,0) -> 17.42 | I24: =VLOOKUP(B24,'[1]2.2强电工程'!$B$4:$I$254,8,0) -> 220.31 | J24: =VLOOKUP(B24,'[1]2.2强电工程'!$B$4:$J$254,9,0) -> 1.01 | K24: =VLOOKUP(B24,'[1]2.2强电工程'!$B$4:$K$254,10,0) -> 1.14 | L24: =$L$4 -> 0.207 | M24: =F24*G24 -> 0
A25: 22 | B25: 电缆WDZA-YJV-4*50+1*25 | C25: 1.名称:电力电缆 2.型号:WDZA-YJV 3.规格:4*50+1*25 4.材质:铜芯 5.敷设方式、部位:桥架内及配管内敷设 6.电压等级(kV):1.0KV | D25: 按设计图示尺寸以长度计算（含预留长度及附加长度） | E25: m | G25: =(H25+I25+J25+K25)*(1+L25) -> 209.64383 | H25: =VLOOKUP(B25,'[1]2.2强电工程'!$B$4:$H$254,7,0) -> 17.42 | I25: =VLOOKUP(B25,'[1]2.2强电工程'!$B$4:$I$254,8,0) -> 154.12 | J25: =VLOOKUP(B25,'[1]2.2强电工程'!$B$4:$J$254,9,0) -> 1.01 | K25: =VLOOKUP(B25,'[1]2.2强电工程'!$B$4:$K$254,10,0) -> 1.14 | L25: =$L$4 -> 0.207 | M25: =F25*G25 -> 0
A26: 23 | B26: 电缆WDZA-YJV-4*35+1*16 | C26: 1.名称:电力电缆 2.型号:WDZA-YJV 3.规格:4*35+1*16 4.材质:铜芯 5.敷设方式、部位:桥架内及配管内敷设 6.电压等级(kV):1.0KV | D26: 按设计图示尺寸以长度计算（含预留长度及附加长度） | E26: m | G26: =(H26+I26+J26+K26)*(1+L26) -> 150.33185 | H26: =VLOOKUP(B26,'[1]2.2强电工程'!$B$4:$H$254,7,0) -> 11.07 | I26: =VLOOKUP(B26,'[1]2.2强电工程'!$B$4:$I$254,8,0) -> 112.21 | J26: =VLOOKUP(B26,'[1]2.2强电工程'!$B$4:$J$254,9,0) -> 1.11 | K26: =VLOOKUP(B26,'[1]2.2强电工程'!$B$4:$K$254,10,0) -> 0.16 | L26: =$L$4 -> 0.207 | M26: =F26*G26 -> 0
A27: 24 | B27: 电缆WDZA-YJV-4*25+1*16 | C27: 1.名称:电力电缆 2.型号:WDZA-YJV 3.规格:4*25+1*16 4.材质:铜芯 5.敷设方式、部位:桥架内及配管内敷设 6.电压等级(kV):1.0KV | D27: 按设计图示尺寸以长度计算（含预留长度及附加长度） | E27: m | G27: =(H27+I27+J27+K27)*(1+L27) -> 119.6137 | H27: =VLOOKUP(B27,'[1]2.2强电工程'!$B$4:$H$254,7,0) -> 11.07 | I27: =VLOOKUP(B27,'[1]2.2强电工程'!$B$4:$I$254,8,0) -> 86.76 | J27: =VLOOKUP(B27,'[1]2.2强电工程'!$B$4:$J$254,9,0) -> 1.11 | K27: =VLOOKUP(B27,'[1]2.2强电工程'!$B$4:$K$254,10,0) -> 0.16 | L27: =$L$4 -> 0.207 | M27: =F27*G27 -> 0
A28: 25 | B28: 电缆WDZA-YJV-5*16 | C28: 1.名称:电力电缆 2.型号:WDZA-YJV 3.规格:5*16 4.材质:铜芯 5.敷设方式、部位:桥架内及配管内敷设 6.电压等级(kV):1.0KV | D28: 按设计图示尺寸以长度计算（含预留长度及附加长度） | E28: m | F28: 65.01 | G28: =(H28+I28+J28+K28)*(1+L28) -> 89.46284 | H28: =VLOOKUP(B28,'[1]2.2强电工程'!$B$4:$H$254,7,0) -> 11.07 | I28: =VLOOKUP(B28,'[1]2.2强电工程'!$B$4:$I$254,8,0) -> 61.78 | J28: =VLOOKUP(B28,'[1]2.2强电工程'!$B$4:$J$254,9,0) -> 1.11 | K28: =VLOOKUP(B28,'[1]2.2强电工程'!$B$4:$K$254,10,0) -> 0.16 | L28: =$L$4 -> 0.207 | M28: =F28*G28 -> 5815.9792
A29: 26 | B29: 电缆WDZA-YJV-5*10 | C29: 1.名称:电力电缆 2.型号:WDZA-YJV 3.规格:5*10 4.材质:铜芯 5.敷设方式、部位:桥架内及配管内敷设 6.电压等级(kV):1.0KV | D29: 按设计图示尺寸以长度计算（含预留长度及附加长度） | E29: m | G29: =(H29+I29+J29+K29)*(1+L29) -> 57.51355 | H29: =VLOOKUP(B29,'[1]2.2强电工程'!$B$4:$H$254,7,0) -> 6.12 | I29: =VLOOKUP(B29,'[1]2.2强电工程'!$B$4:$I$254,8,0) -> 40.53 | J29: =VLOOKUP(B29,'[1]2.2强电工程'!$B$4:$J$254,9,0) -> 1 | K29: =VLOOKUP(B29,'[1]2.2强电工程'!$B$4:$K$254,10,0) -> 0 | L29: =$L$4 -> 0.207 | M29: =F29*G29 -> 0
A30: 27 | B30: 电缆WDZA-YJV-5*6 | C30: 1.名称:电力电缆 2.型号:WDZA-YJV 3.规格:5*6 4.材质:铜芯 5.敷设方式、部位:桥架内及配管内敷设 6.电压等级(kV):1.0KV | D30: 按设计图示尺寸以长度计算（含预留长度及附加长度） | E30: m | F30: 450.46 | G30: =(H30+I30+J30+K30)*(1+L30) -> 57.86358 | H30: =VLOOKUP(B30,'[1]2.2强电工程'!$B$4:$H$254,7,0) -> 11.07 | I30: 35.6 | J30: =VLOOKUP(B30,'[1]2.2强电工程'!$B$4:$J$254,9,0) -> 1.11 | K30: =VLOOKUP(B30,'[1]2.2强电工程'!$B$4:$K$254,10,0) -> 0.16 | L30: =$L$4 -> 0.207 | M30: =F30*G30 -> 26065.228
A31: 28 | B31: 电缆WDZA-YJV-5*4 | C31: 1.名称:电力电缆 2.型号:WDZA-YJV 3.规格:5*4 4.材质:铜芯 5.敷设方式、部位:桥架内及配管内敷设 6.电压等级(kV):1.0KV | D31: 按设计图示尺寸以长度计算（含预留长度及附加长度） | E31: m | F31: 14.3 | G31: =(H31+I31+J31+K31)*(1+L31) -> 30.44054 | H31: =VLOOKUP(B31,'[1]2.2强电工程'!$B$4:$H$254,7,0) -> 4.57 | I31: =VLOOKUP(B31,'[1]2.2强电工程'!$B$4:$I$254,8,0) -> 19.57 | J31: =VLOOKUP(B31,'[1]2.2强电工程'!$B$4:$J$254,9,0) -> 1.08 | K31: =VLOOKUP(B31,'[1]2.2强电工程'!$B$4:$K$254,10,0) -> 0 | L31: =$L$4 -> 0.207 | M31: =F31*G31 -> 435.29972
A32: 29 | B32: 电缆WDZA-YJV-3*6 | C32: 1.名称:电力电缆 2.型号:WDZA-YJV 3.规格:3*6 4.材质:铜芯 5.敷设方式、部位:桥架内及配管内敷设 6.电压等级(kV):1.0KV | D32: 按设计图示尺寸以长度计算（含预留长度及附加长度） | E32: m | G32: =(H32+I32+J32+K32)*(1+L32) -> 50.50088 | H32: =VLOOKUP(B32,'[1]2.2强电工程'!$B$4:$H$254,7,0) -> 11.07 | I32: 29.5 | J32: =VLOOKUP(B32,'[1]2.2强电工程'!$B$4:$J$254,9,0) -> 1.11 | K32: =VLOOKUP(B32,'[1]2.2强电工程'!$B$4:$K$254,10,0) -> 0.16 | L32: =$L$4 -> 0.207 | M32: =F32*G32 -> 0
A33: 30 | B33: 电缆WDZA-YJV-3*10 | C33: 1.名称:电力电缆 2.型号:WDZA-YJV 3.规格:3*10 4.材质:铜芯 5.敷设方式、部位:桥架内及配管内敷设 6.电压等级(kV):1.0KV | D33: 按设计图示尺寸以长度计算（含预留长度及附加长度） | E33: m | G33: =(H33+I33+J33+K33)*(1+L33) -> 38.841365 | H33: 4.5614719 | I33: 27.17 | J33: 0.13 | K33: 0.31861472 | L33: =$L$4 -> 0.207 | M33: =F33*G33 -> 0
A34: 31 | B34: 电缆WDZB-YJV-3*240+2*120 | C34: 1.名称:电力电缆 2.型号:WDZB-YJV 3.规格:3*240+2*120 4.材质:铜芯 5.敷设方式、部位:桥架内及配管内敷设 6.电压等级(kV):1.0KV | D34: 按设计图示尺寸以长度计算（含预留长度及附加长度） | E34: m | G34: =(H34+I34+J34+K34)*(1+L34) -> 848.21925 | H34: =VLOOKUP(B34,'[1]2.2强电工程'!$B$4:$H$254,7,0) -> 28.73 | I34: =VLOOKUP(B34,'[1]2.2强电工程'!$B$4:$I$254,8,0) -> 669.71 | J34: =VLOOKUP(B34,'[1]2.2强电工程'!$B$4:$J$254,9,0) -> 1.99 | K34: =VLOOKUP(B34,'[1]2.2强电工程'!$B$4:$K$254,10,0) -> 2.32 | L34: =$L$4 -> 0.207 | M34: =F34*G34 -> 0
A35: 32 | B35: 电缆WDZB-YJV-3*185+2*95 | C35: 1.名称:电力电缆 2.型号:WDZB-YJV 3.规格:3*185+2*95 4.材质:铜芯 5.敷设方式、部位:桥架内及配管内敷设 6.电压等级(kV):1.0KV | D35: 按设计图示尺寸以长度计算（含预留长度及附加长度） | E35: m | G35: =(H35+I35+J35+K35)*(1+L35) -> 663.7293 | H35: =VLOOKUP(B35,'[1]2.2强电工程'!$B$4:$H$254,7,0) -> 28.73 | I35: =VLOOKUP(B35,'[1]2.2强电工程'!$B$4:$I$254,8,0) -> 516.86 | J35: =VLOOKUP(B35,'[1]2.2强电工程'!$B$4:$J$254,9,0) -> 1.99 | K35: =VLOOKUP(B35,'[1]2.2强电工程'!$B$4:$K$254,10,0) -> 2.32 | L35: =$L$4 -> 0.207 | M35: =F35*G35 -> 0
A36: 33 | B36: 电缆WDZB-YJV-3*150+2*70 | C36: 1.名称:电力电缆 2.型号:WDZB-YJV 3.规格:3*150+2*70 4.材质:铜芯 5.敷设方式、部位:桥架内及配管内敷设 6.电压等级(kV):1.0KV | D36: 按设计图示尺寸以长度计算（含预留长度及附加长度） | E36: m | G36: =(H36+I36+J36+K36)*(1+L36) -> 527.27795 | H36: =VLOOKUP(B36,'[1]2.2强电工程'!$B$4:$H$254,7,0) -> 28.73 | I36: =VLOOKUP(B36,'[1]2.2强电工程'!$B$4:$I$254,8,0) -> 403.81 | J36: =VLOOKUP(B36,'[1]2.2强电工程'!$B$4:$J$254,9,0) -> 1.99 | K36: =VLOOKUP(B36,'[1]2.2强电工程'!$B$4:$K$254,10,0) -> 2.32 | L36: =$L$4 -> 0.207 | M36: =F36*G36 -> 0
A37: 34 | B37: 电缆WDZB-YJV-3*120+2*70 | C37: 1.名称:电力电缆 2.型号:WDZB-YJV 3.规格:3*120+2*70 4.材质:铜芯 5.敷设方式、部位:桥架内及配管内敷设 6.电压等级(kV):1.0KV | D37: 按设计图示尺寸以长度计算（含预留长度及附加长度） | E37: m | G37: =(H37+I37+J37+K37)*(1+L37) -> 446.14341 | H37: =VLOOKUP(B37,'[1]2.2强电工程'!$B$4:$H$254,7,0) -> 20.72 | I37: =VLOOKUP(B37,'[1]2.2强电工程'!$B$4:$I$254,8,0) -> 346.52 | J37: =VLOOKUP(B37,'[1]2.2强电工程'!$B$4:$J$254,9,0) -> 1.25 | K37: =VLOOKUP(B37,'[1]2.2强电工程'!$B$4:$K$254,10,0) -> 1.14 | L37: =$L$4 -> 0.207 | M37: =F37*G37 -> 0
A38: 35 | B38: 电缆WDZB-YJV-3*95+2*50 | C38: 1.名称:电力电缆 2.型号:WDZB-YJV 3.规格:3*95+2*50 4.材质:铜芯 5.敷设方式、部位:桥架内及配管内敷设 6.电压等级(kV):1.0KV | D38: 按设计图示尺寸以长度计算（含预留长度及附加长度） | E38: m | F38: 124.67 | G38: =(H38+I38+J38+K38)*(1+L38) -> 348.96784 | H38: =VLOOKUP(B38,'[1]2.2强电工程'!$B$4:$H$254,7,0) -> 20.72 | I38: =VLOOKUP(B38,'[1]2.2强电工程'!$B$4:$I$254,8,0) -> 266.01 | J38: =VLOOKUP(B38,'[1]2.2强电工程'!$B$4:$J$254,9,0) -> 1.25 | K38: =VLOOKUP(B38,'[1]2.2强电工程'!$B$4:$K$254,10,0) -> 1.14 | L38: =$L$4 -> 0.207 | M38: =F38*G38 -> 43505.821
A39: 36 | B39: 电缆WDZB-YJV-3*70+2*35 | C39: 1.名称:电力电缆 2.型号:WDZB-YJV 3.规格:3*70+2*35 4.材质:铜芯 5.敷设方式、部位:桥架内及配管内敷设 6.电压等级(kV):1.0KV | D39: 按设计图示尺寸以长度计算（含预留长度及附加长度） | E39: m | G39: =(H39+I39+J39+K39)*(1+L39) -> 257.48931 | H39: =VLOOKUP(B39,'[1]2.2强电工程'!$B$4:$H$254,7,0) -> 17.42 | I39: =VLOOKUP(B39,'[1]2.2强电工程'!$B$4:$I$254,8,0) -> 193.76 | J39: =VLOOKUP(B39,'[1]2.2强电工程'!$B$4:$J$254,9,0) -> 1.01 | K39: =VLOOKUP(B39,'[1]2.2强电工程'!$B$4:$K$254,10,0) -> 1.14 | L39: =$L$4 -> 0.207 | M39: =F39*G39 -> 0
A40: 37 | B40: 电缆WDZB-YJV-3*50+2*25 | C40: 1.名称:电力电缆 2.型号:WDZB-YJV 3.规格:3*50+2*25 4.材质:铜芯 5.敷设方式、部位:桥架内及配管内敷设 6.电压等级(kV):1.0KV | D40: 按设计图示尺寸以长度计算（含预留长度及附加长度） | E40: m | G40: =(H40+I40+J40+K40)*(1+L40) -> 188.59375 | H40: =VLOOKUP(B40,'[1]2.2强电工程'!$B$4:$H$254,7,0) -> 17.42 | I40: =VLOOKUP(B40,'[1]2.2强电工程'!$B$4:$I$254,8,0) -> 136.68 | J40: =VLOOKUP(B40,'[1]2.2强电工程'!$B$4:$J$254,9,0) -> 1.01 | K40: =VLOOKUP(B40,'[1]2.2强电工程'!$B$4:$K$254,10,0) -> 1.14 | L40: =$L$4 -> 0.207 | M40: =F40*G40 -> 0
...

Sheet 2.3弱电工程
A1: 长城智选中心店装修项目装饰工程
A2: 序号 | B2: 分部分项名称 | C2: 项目特征 | D2: 计量规则 | E2: 单位 | F2: 工程量 | G2: 综合单价 | H2: 人工 | I2: 主材 | J2: 辅材 | K2: 机械 | L2: 其他综合费率 | M2: 合计 | N2: 备注
A3: 一 | B3: 综合布线
A4: 1 | B4: 弱电机柜12U | C4: 1.名称:弱电机柜12U 2.规格:包含PDU插排，用于放置交换机、路由器等设备，留有冗余空间 3.安装方式:落地 | D4: 按设计图示数量计算 | E4: 台 | G4: =(H4+I4+J4+K4)*(1+L4) -> 799.91511 | H4: =VLOOKUP(B4,'[1]2.3弱电工程'!$B$4:$H$195,7,0) -> 270.73 | I4: =VLOOKUP(B4,'[1]2.3弱电工程'!$B$4:$I$195,8,0) -> 380.53 | J4: =VLOOKUP(B4,'[1]2.3弱电工程'!$B$4:$J$195,9,0) -> 10.49 | K4: =VLOOKUP(B4,'[1]2.3弱电工程'!$B$4:$K$195,10,0) -> 0.98 | L4: ='2.1装饰工程'!$L$4 -> 0.207 | M4: =F4*G4 -> 0
A5: 2 | B5: 弱电机柜24U | C5: 1.名称:弱电机柜24U 2.规格:包含PDU插排，用于放置交换机、路由器等设备，留有冗余空间 3.安装方式:落地 | D5: 按设计图示数量计算 | E5: 台 | G5: =(H5+I5+J5+K5)*(1+L5) -> 1152.4074 | H5: =VLOOKUP(B5,'[1]2.3弱电工程'!$B$4:$H$195,7,0) -> 270.73 | I5: =VLOOKUP(B5,'[1]2.3弱电工程'!$B$4:$I$195,8,0) -> 672.57 | J5: =VLOOKUP(B5,'[1]2.3弱电工程'!$B$4:$J$195,9,0) -> 10.49 | K5: =VLOOKUP(B5,'[1]2.3弱电工程'!$B$4:$K$195,10,0) -> 0.98 | L5: =$L$4 -> 0.207 | M5: =F5*G5 -> 0
A6: 3 | B6: 弱电机柜27U | C6: 1.名称:弱电机柜27U 2.规格:包含PDU插排，用于放置交换机、路由器等设备，留有冗余空间 3.安装方式:落地 | D6: 按设计图示数量计算 | E6: 台 | F6: 2 | G6: =(H6+I6+J6+K6)*(1+L6) -> 1227.169 | H6: =VLOOKUP(B6,'[1]2.3弱电工程'!$B$4:$H$195,7,0) -> 270.73 | I6: =VLOOKUP(B6,'[1]2.3弱电工程'!$B$4:$I$195,8,0) -> 734.51 | J6: =VLOOKUP(B6,'[1]2.3弱电工程'!$B$4:$J$195,9,0) -> 10.49 | K6: =VLOOKUP(B6,'[1]2.3弱电工程'!$B$4:$K$195,10,0) -> 0.98 | L6: =$L$4 -> 0.207 | M6: =F6*G6 -> 2454.3379
A7: 4 | B7: 弱电机柜42U | C7: 1.名称:弱电机柜42U 2.规格:包含PDU插排，用于放置交换机、路由器等设备，留有冗余空间 3.安装方式:落地 | D7: 按设计图示数量计算 | E7: 台 | G7: =(H7+I7+J7+K7)*(1+L7) -> 1686.4687 | H7: =VLOOKUP(B7,'[1]2.3弱电工程'!$B$4:$H$195,7,0) -> 270.73 | I7: =VLOOKUP(B7,'[1]2.3弱电工程'!$B$4:$I$195,8,0) -> 1115.04 | J7: =VLOOKUP(B7,'[1]2.3弱电工程'!$B$4:$J$195,9,0) -> 10.49 | K7: =VLOOKUP(B7,'[1]2.3弱电工程'!$B$4:$K$195,10,0) -> 0.98 | L7: =$L$4 -> 0.207 | M7: =F7*G7 -> 0
A8: 5 | B8: USP不间断电源 | C8: 1.名称:USP不间断电源 2.型号:参考英威腾HT1103CL，内置电池，后备时间＞30分钟 | D8: 按设计图示数量计算 | E8: 个 | F8: 2 | G8: =(H8+I8+J8+K8)*(1+L8) -> 5482.9303 | H8: =VLOOKUP(B8,'[1]2.3弱电工程'!$B$4:$H$195,7,0) -> 860.41 | I8: =VLOOKUP(B8,'[1]2.3弱电工程'!$B$4:$I$195,8,0) -> 700.6 | J8: =VLOOKUP(B8,'[1]2.3弱电工程'!$B$4:$J$195,9,0) -> 2981.6 | K8: =VLOOKUP(B8,'[1]2.3弱电工程'!$B$4:$K$195,10,0) -> 0 | L8: =$L$4 -> 0.207 | M8: =F8*G8 -> 10965.861
A9: 6 | B9: 24口配线架 | C9: 1.名称:24口配线架 2.规格:1U,24口，含同品牌非屏蔽模块，模块满配 | D9: 按设计图示数量计算 | E9: 个 | G9: =(H9+I9+J9+K9)*(1+L9) -> 434.8821 | H9: =VLOOKUP(B9,'[1]2.3弱电工程'!$B$4:$H$195,7,0) -> 216.23 | I9: =VLOOKUP(B9,'[1]2.3弱电工程'!$B$4:$I$195,8,0) -> 144.07 | J9: =VLOOKUP(B9,'[1]2.3弱电工程'!$B$4:$J$195,9,0) -> 0 | K9: =VLOOKUP(B9,'[1]2.3弱电工程'!$B$4:$K$195,10,0) -> 0 | L9: =$L$4 -> 0.207 | M9: =F9*G9 -> 0
A10: 7 | B10: 48口配线架 | C10: 1.名称:48口配线架 2.规格:48口，含同品牌非屏蔽模块，模块满配 | D10: 按设计图示数量计算 | E10: 个 | G10: =(H10+I10+J10+K10)*(1+L10) -> 665.35875 | H10: =VLOOKUP(B10,'[1]2.3弱电工程'!$B$4:$H$195,7,0) -> 235.65 | I10: =VLOOKUP(B10,'[1]2.3弱电工程'!$B$4:$I$195,8,0) -> 315.6 | J10: =VLOOKUP(B10,'[1]2.3弱电工程'!$B$4:$J$195,9,0) -> 0 | K10: =VLOOKUP(B10,'[1]2.3弱电工程'!$B$4:$K$195,10,0) -> 0 | L10: =$L$4 -> 0.207 | M10: =F10*G10 -> 0
A11: 8 | B11: 24口理线架 | C11: 1.名称:24口理线架 2.规格:1U,金属材质 | D11: 按设计图示数量计算 | E11: 个 | F11: 35 | G11: =(H11+I11+J11+K11)*(1+L11) -> 64.84004 | H11: =VLOOKUP(B11,'[1]2.3弱电工程'!$B$4:$H$195,7,0) -> 22.75 | I11: =VLOOKUP(B11,'[1]2.3弱电工程'!$B$4:$I$195,8,0) -> 30.97 | J11: =VLOOKUP(B11,'[1]2.3弱电工程'!$B$4:$J$195,9,0) -> 0 | K11: =VLOOKUP(B11,'[1]2.3弱电工程'!$B$4:$K$195,10,0) -> 0 | L11: =$L$4 -> 0.207 | M11: =F11*G11 -> 2269.4014
A12: 9 | B12: 48口理线架 | C12: 1.名称:48口理线架 2.规格:金属材质 | D12: 按设计图示数量计算 | E12: 个 | G12: =(H12+I12+J12+K12)*(1+L12) -> 70.18705 | H12: =VLOOKUP(B12,'[1]2.3弱电工程'!$B$4:$H$195,7,0) -> 22.75 | I12: =VLOOKUP(B12,'[1]2.3弱电工程'!$B$4:$I$195,8,0) -> 35.4 | J12: =VLOOKUP(B12,'[1]2.3弱电工程'!$B$4:$J$195,9,0) -> 0 | K12: =VLOOKUP(B12,'[1]2.3弱电工程'!$B$4:$K$195,10,0) -> 0 | L12: =$L$4 -> 0.207 | M12: =F12*G12 -> 0
A13: 10 | B13: 24口交换机 | C13: 1.名称:24口交换机 2.功能:可网管、不低于24口，POE供电，参考TP-LINK | D13: 按设计图示数量计算 | E13: 台 | G13: =(H13+I13+J13+K13)*(1+L13) -> 2012.0569 | H13: =VLOOKUP(B13,'[1]2.3弱电工程'!$B$4:$H$195,7,0) -> 614.25 | I13: =VLOOKUP(B13,'[1]2.3弱电工程'!$B$4:$I$195,8,0) -> 1031.86 | J13: =VLOOKUP(B13,'[1]2.3弱电工程'!$B$4:$J$195,9,0) -> 10.49 | K13: =VLOOKUP(B13,'[1]2.3弱电工程'!$B$4:$K$195,10,0) -> 10.39 | L13: =$L$4 -> 0.207 | M13: =F13*G13 -> 0
A14: 11 | B14: 48口交换机 | C14: 1.名称:48口交换机 2.功能:可网管、不低于48口，POE供电，参考TP-LINK：TL-SG3452P | D14: 按设计图示数量计算 | E14: 台 | G14: =(H14+I14+J14+K14)*(1+L14) -> 5148.7723 | H14: =VLOOKUP(B14,'[1]2.3弱电工程'!$B$4:$H$195,7,0) -> 1023.75 | I14: =VLOOKUP(B14,'[1]2.3弱电工程'!$B$4:$I$195,8,0) -> 3215.93 | J14: =VLOOKUP(B14,'[1]2.3弱电工程'!$B$4:$J$195,9,0) -> 10.49 | K14: =VLOOKUP(B14,'[1]2.3弱电工程'!$B$4:$K$195,10,0) -> 15.59 | L14: =$L$4 -> 0.207 | M14: =F14*G14 -> 0
A15: 12 | B15: 千兆可网管交换机 | C15: 1.名称：交换机 2.规格型号：TP-LINK：TL-SG2226P，可网管、不低于24口，POE供电 3.包括为满足设计、验收规范规定施工所需的一切工序 | D15: 按设计图示数量计算 | E15: 台 | F15: 2 | G15: =(H15+I15+J15+K15)*(1+L15) -> 1530.3191 | H15: =VLOOKUP(B15,'[1]2.3弱电工程'!$B$4:$H$195,7,0) -> 614.25 | I15: =VLOOKUP(B15,'[1]2.3弱电工程'!$B$4:$I$195,8,0) -> 632.74 | J15: =VLOOKUP(B15,'[1]2.3弱电工程'!$B$4:$J$195,9,0) -> 10.49 | K15: =VLOOKUP(B15,'[1]2.3弱电工程'!$B$4:$K$195,10,0) -> 10.39 | L15: =$L$4 -> 0.207 | M15: =F15*G15 -> 3060.6382
A16: 13 | B16: 工业级以太网交换机 | C16: 1.名称:工业级以太网交换机 2.功能:不低于4个千兆电口+2千兆SFP光口插槽，含光模块、含电源适配器 | D16: 按设计图示数量计算 | E16: 台 | G16: =(H16+I16+J16+K16)*(1+L16) -> 1270.2347 | H16: =VLOOKUP(B16,'[1]2.3弱电工程'!$B$4:$H$195,7,0) -> 614.25 | I16: =VLOOKUP(B16,'[1]2.3弱电工程'!$B$4:$I$195,8,0) -> 417.26 | J16: =VLOOKUP(B16,'[1]2.3弱电工程'!$B$4:$J$195,9,0) -> 10.49 | K16: =VLOOKUP(B16,'[1]2.3弱电工程'!$B$4:$K$195,10,0) -> 10.39 | L16: =$L$4 -> 0.207 | M16: =F16*G16 -> 0
A17: 14 | B17: 路由器 | C17: 1.名称：路由器 2.规格型号：TP-LINK：TL-ER3200G千兆企业级， 3.包括为满足设计、验收规范规定施工所需的一切工序 | D17: 按设计图示数量计算 | E17: 台 | F17: 4 | G17: =(H17+I17+J17+K17)*(1+L17) -> 744.67072 | H17: =VLOOKUP(B17,'[1]2.3弱电工程'!$B$4:$H$195,7,0) -> 182 | I17: =VLOOKUP(B17,'[1]2.3弱电工程'!$B$4:$I$195,8,0) -> 420.31 | J17: =VLOOKUP(B17,'[1]2.3弱电工程'!$B$4:$J$195,9,0) -> 10.49 | K17: =VLOOKUP(B17,'[1]2.3弱电工程'!$B$4:$K$195,10,0) -> 4.16 | L17: =$L$4 -> 0.207 | M17: =F17*G17 -> 2978.6829
A18: 15 | B18: 显示器 | C18: 1.名称:显示器 2.规格:尺寸23.8英寸，分辨率：1920*1080像素，接口：DP、HDMI，附带一根3米HDMI线、键盘1个、鼠标1个 | D18: 按设计图示数量计算 | E18: 台 | F18: 4 | G18: =(H18+I18+J18+K18)*(1+L18) -> 606.38473 | H18: =VLOOKUP(B18,'[1]2.3弱电工程'!$B$4:$H$195,7,0) -> 54.6 | I18: =VLOOKUP(B18,'[1]2.3弱电工程'!$B$4:$I$195,8,0) -> 447.79 | J18: =VLOOKUP(B18,'[1]2.3弱电工程'!$B$4:$J$195,9,0) -> 0 | K18: =VLOOKUP(B18,'[1]2.3弱电工程'!$B$4:$K$195,10,0) -> 0 | L18: =$L$4 -> 0.207 | M18: =F18*G18 -> 2425.5389
A19: 16 | B19: 100寸电视(包括电视伸缩支架的采购、安装) | C19: 1.名称:100寸电视 2.类别:(包括电视支架的采购、安装) 3.规格:100寸，选用酷开创维 | D19: 按设计图示数量计算 | E19: 台 | F19: 1 | G19: =(H19+I19+J19+K19)*(1+L19) -> 11828.503 | H19: =VLOOKUP(B19,'[1]2.3弱电工程'!$B$4:$H$195,7,0) -> 63.7 | I19: =VLOOKUP(B19,'[1]2.3弱电工程'!$B$4:$I$195,8,0) -> 9734.51 | J19: =VLOOKUP(B19,'[1]2.3弱电工程'!$B$4:$J$195,9,0) -> 1.71 | K19: =VLOOKUP(B19,'[1]2.3弱电工程'!$B$4:$K$195,10,0) -> 0 | L19: =$L$4 -> 0.207 | M19: =F19*G19 -> 11828.503
A20: 17 | B20: 75寸电视(包括伸缩支架的采购、安装) | C20: 1.名称:75寸电视 2.类别:(包括电视支架的采购、安装) 3.规格:75寸，选用酷开创维 | D20: 按设计图示数量计算 | E20: 台 | F20: 1 | G20: =(H20+I20+J20+K20)*(1+L20) -> 4609.4244 | H20: 63.7 | I20: 3750 | J20: 1.71 | K20: 3.5 | L20: =$L$4 -> 0.207 | M20: =F20*G20 -> 4609.4244
A21: 18 | B21: 65寸电视(包括伸缩支架的采购、安装) | C21: 1.名称:65寸电视 2.类别:(包括电视支架的采购、安装) 3.规格:65寸，选用酷开创维 | D21: 按设计图示数量计算 | E21: 台 | F21: 1 | G21: =(H21+I21+J21+K21)*(1+L21) -> 3523.1244 | H21: 63.7 | I21: 2850 | J21: 1.71 | K21: 3.5 | L21: =$L$4 -> 0.207 | M21: =F21*G21 -> 3523.1244
A22: 19 | B22: 智能电表 | C22: 1.名称:智能电表 2.规格:采用4G无线联网，赠送至少8年流量，无需采集器，赠送平台，可查看用电量情况 | D22: 按设计图示数量计算 | E22: 台 | F22: 4 | G22: =(H22+I22+J22+K22)*(1+L22) -> 444.51396 | H22: =VLOOKUP(B22,'[1]2.3弱电工程'!$B$4:$H$195,7,0) -> 250.25 | I22: =VLOOKUP(B22,'[1]2.3弱电工程'!$B$4:$I$195,8,0) -> 116.81 | J22: =VLOOKUP(B22,'[1]2.3弱电工程'!$B$4:$J$195,9,0) -> 1.22 | K22: =VLOOKUP(B22,'[1]2.3弱电工程'!$B$4:$K$195,10,0) -> 0 | L22: =$L$4 -> 0.207 | M22: =F22*G22 -> 1778.0558
A23: 20 | B23: 桌面型防火墙 | C23: 1.名称：桌面型防火墙 2.规格型号：TP-LINK：TL-FW5600，支持配置安全策略、审计策略、带宽策略，包含2年病毒库免费升级服务 3.包括为满足设计、验收规范规定施工所需的一切工序 | D23: 按设计图示数量计算 | E23: 台 | F23: 21 | G23: =(H23+I23+J23+K23)*(1+L23) -> 2450.2221 | H23: =VLOOKUP(B23,'[1]2.3弱电工程'!$B$4:$H$195,7,0) -> 364 | I23: =VLOOKUP(B23,'[1]2.3弱电工程'!$B$4:$I$195,8,0) -> 1645.13 | J23: =VLOOKUP(B23,'[1]2.3弱电工程'!$B$4:$J$195,9,0) -> 10.49 | K23: =VLOOKUP(B23,'[1]2.3弱电工程'!$B$4:$K$195,10,0) -> 10.39 | L23: =$L$4 -> 0.207 | M23: =F23*G23 -> 51454.663
A24: 21 | B24: 无线AP | C24: 1.名称：无线AP 2.规格型号：TP-LINK：TL-XAP1506GC-PoE/DC易展版、千兆、802.11ax、双频WIFI，参考 3.包括为满足设计、验收规范规定施工所需的一切工序 | D24: 按设计图示数量计算 | E24: 台 | F24: 11 | G24: =(H24+I24+J24+K24)*(1+L24) -> 434.87003 | H24: =VLOOKUP(B24,'[1]2.3弱电工程'!$B$4:$H$195,7,0) -> 68.25 | I24: =VLOOKUP(B24,'[1]2.3弱电工程'!$B$4:$I$195,8,0) -> 292.04 | J24: =VLOOKUP(B24,'[1]2.3弱电工程'!$B$4:$J$195,9,0) -> 0 | K24: =VLOOKUP(B24,'[1]2.3弱电工程'!$B$4:$K$195,10,0) -> 0 | L24: =$L$4 -> 0.207 | M24: =F24*G24 -> 4783.5703
A25: 22 | B25: 单口信息插座 | C25: 1.名称:单口信息插座 2.规格:白色，含同等品牌六类非屏蔽模块 3.安装方式:暗装 | D25: 按设计图示数量计算 | E25: 个 | F25: 26 | G25: =(H25+I25+J25+K25)*(1+L25) -> 38.84126 | H25: =VLOOKUP(B25,'[1]2.3弱电工程'!$B$4:$H$195,7,0) -> 11.38 | I25: =VLOOKUP(B25,'[1]2.3弱电工程'!$B$4:$I$195,8,0) -> 20.8 | J25: =VLOOKUP(B25,'[1]2.3弱电工程'!$B$4:$J$195,9,0) -> 0 | K25: =VLOOKUP(B25,'[1]2.3弱电工程'!$B$4:$K$195,10,0) -> 0 | L25: =$L$4 -> 0.207 | M25: =F25*G25 -> 1009.8728
A26: 23 | B26: 双口信息插座 | C26: 1.名称:双口信息插座 2.规格:白色，含同等品牌六类非屏蔽模块 3.安装方式:暗装 | D26: 按设计图示数量计算 | E26: 个 | G26: =(H26+I26+J26+K26)*(1+L26) -> 51.35785 | H26: =VLOOKUP(B26,'[1]2.3弱电工程'!$B$4:$H$195,7,0) -> 13.65 | I26: =VLOOKUP(B26,'[1]2.3弱电工程'!$B$4:$I$195,8,0) -> 28.9 | J26: =VLOOKUP(B26,'[1]2.3弱电工程'!$B$4:$J$195,9,0) -> 0 | K26: =VLOOKUP(B26,'[1]2.3弱电工程'!$B$4:$K$195,10,0) -> 0 | L26: =$L$4 -> 0.207 | M26: =F26*G26 -> 0
A27: 24 | B27: 六类非屏蔽网线 | C27: 1.名称:六类非屏蔽网线 2.敷设方式:综合考虑 | D27: 按设计图示尺寸以长度计算 | E27: m | F27: 3569.5 | G27: =(H27+I27+J27+K27)*(1+L27) -> 5.05733 | H27: =VLOOKUP(B27,'[1]2.3弱电工程'!$B$4:$H$195,7,0) -> 1.57 | I27: =VLOOKUP(B27,'[1]2.3弱电工程'!$B$4:$I$195,8,0) -> 2.61 | J27: =VLOOKUP(B27,'[1]2.3弱电工程'!$B$4:$J$195,9,0) -> 0.01 | K27: =VLOOKUP(B27,'[1]2.3弱电工程'!$B$4:$K$195,10,0) -> 0 | L27: =$L$4 -> 0.207 | M27: =F27*G27 -> 18052.139
A28: 25 | B28: RVV-2*1.0 | C28: 1.名称:RVV-2*1.0 2.敷设方式:综合考虑 | D28: 按设计图示尺寸以长度计算 | E28: m | F28: 125 | G28: =(H28+I28+J28+K28)*(1+L28) -> 5.82981 | H28: =VLOOKUP(B28,'[1]2.3弱电工程'!$B$4:$H$195,7,0) -> 1.73 | I28: =VLOOKUP(B28,'[1]2.3弱电工程'!$B$4:$I$195,8,0) -> 2.92 | J28: =VLOOKUP(B28,'[1]2.3弱电工程'!$B$4:$J$195,9,0) -> 0.18 | K28: =VLOOKUP(B28,'[1]2.3弱电工程'!$B$4:$K$195,10,0) -> 0 | L28: =$L$4 -> 0.207 | M28: =F28*G28 -> 728.72625
A29: 26 | B29: RVV-2*2.5 | C29: 1.名称:RVV-2*2.5 2.敷设方式:综合考虑 | D29: 按设计图示尺寸以长度计算 | E29: m | F29: 1113.3 | G29: =(H29+I29+J29+K29)*(1+L29) -> 9.2939 | H29: =VLOOKUP(B29,'[1]2.3弱电工程'!$B$4:$H$195,7,0) -> 1.73 | I29: =VLOOKUP(B29,'[1]2.3弱电工程'!$B$4:$I$195,8,0) -> 5.79 | J29: =VLOOKUP(B29,'[1]2.3弱电工程'!$B$4:$J$195,9,0) -> 0.18 | K29: =VLOOKUP(B29,'[1]2.3弱电工程'!$B$4:$K$195,10,0) -> 0 | L29: =$L$4 -> 0.207 | M29: =F29*G29 -> 10346.899
A30: 27 | B30: 六类非屏蔽成品跳线 | C30: 1.名称:六类非屏蔽成品跳线 | D30: 按设计图示数量计算 | E30: 条 | F30: 1 | G30: =(H30+I30+J30+K30)*(1+L30) -> 25.16595 | H30: 4.55 | I30: 15.6 | J30: 0.5 | K30: 0.2 | L30: =$L$4 -> 0.207 | M30: =F30*G30 -> 25.16595
A31: 28 | B31: 双光纤跳线 | C31: 1.名称:双光纤跳线 2.类别:单模，双芯，2M，支持FC/SC/ST/LC互转 | D31: 按设计图示数量计算 | E31: 条 | G31: =(H31+I31+J31+K31)*(1+L31) -> 33.36148 | H31: 4.55 | I31: 22.39 | J31: 0.5 | K31: 0.2 | L31: =$L$4 -> 0.207 | M31: =F31*G31 -> 0
A32: 29 | B32: 尾纤2m | C32: 1.名称:尾纤2m | D32: 按设计图示数量计算 | E32: 根 | G32: =(H32+I32+J32+K32)*(1+L32) -> 28.15931 | H32: =VLOOKUP(B32,'[1]2.3弱电工程'!$B$4:$H$195,7,0) -> 18.13 | I32: =VLOOKUP(B32,'[1]2.3弱电工程'!$B$4:$I$195,8,0) -> 3.1 | J32: =VLOOKUP(B32,'[1]2.3弱电工程'!$B$4:$J$195,9,0) -> 0 | K32: =VLOOKUP(B32,'[1]2.3弱电工程'!$B$4:$K$195,10,0) -> 2.1 | L32: =$L$4 -> 0.207 | M32: =F32*G32 -> 0
A33: 30 | B33: 配管JDG20 | C33: 1.名称:配管JDG20 2.材质:镀锌薄钢管 3.规格:Φ20 4.配置形式:明配 5.接地要求:按规范要求 6.其他:含支、吊架制作安装 | D33: 按设计图示尺寸以长度计算 | E33: m | F33: 258.5 | G33: =(H33+I33+J33+K33)*(1+L33) -> 20.53107 | H33: 10.09 | I33: 4.84 | J33: 1.58 | K33: 0.5 | L33: =$L$4 -> 0.207 | M33: =F33*G33 -> 5307.2816
A34: 31 | B34: 配管JDG20 | C34: 1.名称:配管JDG20 2.材质:镀锌薄钢管 3.规格Φ20 4.配置形式:暗配 5.接地要求:按规范要求 | D34: 按设计图示尺寸以长度计算 | E34: m | G34: =(H34+I34+J34+K34)*(1+L34) -> 19.93964 | H34: 10.74 | I34: 4.84 | J34: 0.44 | K34: 0.5 | L34: =$L$4 -> 0.207 | M34: =F34*G34 -> 0
A35: 32 | B35: 配管JDG25 | C35: 1.名称:配管JDG25 2.材质:镀锌薄钢管 3.规格:Φ25 4.配置形式:明配 5.接地要求:按规范要求 6.其他:含支、吊架制作安装 | D35: 按设计图示尺寸以长度计算 | E35: m | G35: =(H35+I35+J35+K35)*(1+L35) -> 22.80023 | H35: 11.59 | I35: 5.65 | J35: 1.15 | K35: 0.5 | L35: =$L$4 -> 0.207 | M35: =F35*G35 -> 0
A36: 33 | B36: 配管JDG25 | C36: 1.名称:配管JDG25 2.材质:镀锌薄钢管 3.规格Φ25 4.配置形式:暗配 5.接地要求:按规范要求 | D36: 按设计图示尺寸以长度计算 | E36: m | G36: =(H36+I36+J36+K36)*(1+L36) -> 20.42244 | H36: 10.33 | I36: 5.65 | J36: 0.44 | K36: 0.5 | L36: =$L$4 -> 0.207 | M36: =F36*G36 -> 0
A37: 34 | B37: 配管JDG32 | C37: 1.名称:配管JDG32 2.材质:镀锌薄钢管 3.规格:Φ32 4.配置形式:明配 5.接地要求:按规范要求 6.其他:含支、吊架制作安装 | D37: 按设计图示尺寸以长度计算 | E37: m | G37: =(H37+I37+J37+K37)*(1+L37) -> 29.05249 | H37: 13.56 | I37: 8.32 | J37: 1.69 | K37: 0.5 | L37: =$L$4 -> 0.207 | M37: =F37*G37 -> 0
A38: 35 | B38: 配管JDG32 | C38: 1.名称:配管JDG32 2.材质:镀锌薄钢管 3.规格Φ32 4.配置形式:暗配 5.接地要求:按规范要求 | D38: 按设计图示尺寸以长度计算 | E38: m | G38: =(H38+I38+J38+K38)*(1+L38) -> 25.92636 | H38: 11.78 | I38: 8.32 | J38: 0.88 | K38: 0.5 | L38: =$L$4 -> 0.207 | M38: =F38*G38 -> 0
A39: 36 | B39: 配管PCDN20 | C39: 1.名称:配管PCDN20 2.材质:PC 3.规格:DN20mm 4.配置形式:明配 5.接地要求:按规范要求 | D39: 按设计图示尺寸以长度计算 | E39: m | G39: =(H39+I39+J39+K39)*(1+L39) -> 14.42365 | H39: =VLOOKUP(B39,'[1]2.3弱电工程'!$B$4:$H$195,7,0) -> 9.21 | I39: =VLOOKUP(B39,'[1]2.3弱电工程'!$B$4:$I$195,8,0) -> 1.67 | J39: =VLOOKUP(B39,'[1]2.3弱电工程'!$B$4:$J$195,9,0) -> 1.07 | K39: =VLOOKUP(B39,'[1]2.3弱电工程'!$B$4:$K$195,10,0) -> 0 | L39: =$L$4 -> 0.207 | M39: =F39*G39 -> 0
A40: 37 | B40: 配管PCDN20 | C40: 1.名称:配管PCDN20 2.材质:PC 3.规格:DN20mm 4.配置形式:暗配 5.接地要求:按规范要求 | D40: 按设计图示尺寸以长度计算 | E40: m | G40: =(H40+I40+J40+K40)*(1+L40) -> 14.42365 | H40: =VLOOKUP(B40,'[1]2.3弱电工程'!$B$4:$H$195,7,0) -> 9.21 | I40: =VLOOKUP(B40,'[1]2.3弱电工程'!$B$4:$I$195,8,0) -> 1.67 | J40: =VLOOKUP(B40,'[1]2.3弱电工程'!$B$4:$J$195,9,0) -> 1.07 | K40: =VLOOKUP(B40,'[1]2.3弱电工程'!$B$4:$K$195,10,0) -> 0 | L40: =$L$4 -> 0.207 | M40: =F40*G40 -> 0
...

Sheet 2.4给排水工程
A1: 长城智选中心店装修项目装饰工程
A2: 序号 | B2: 分部分项名称 | C2: 项目特征 | D2: 计量规则 | E2: 单位 | F2: 工程量 | G2: 综合单价 | H2: 人工 | I2: 主材 | J2: 辅材 | K2: 机械 | L2: 其他综合费率 | M2: 合计 | N2: 备注
A3: 1 | B3: 钢塑复合管DN150 | C3: 1.安装部位:室内 2.介质:水 3.连接形式:按设计及规范要求 4.压力试验及吹、洗设计要求:按设计及规范要求 5.管道穿内墙、楼板、吊顶开洞及封堵套管:按设计及规范要求 6.管道支架及抗震支架：按设计及规范要求 7.其他:按设计及规范要求 | D3: 按设计图示管道中心线以长度计算 | E3: m | G3: =(H3+I3+J3+K3)*(1+L3) -> 251.27326 | H3: =VLOOKUP(B3,'[1]2.4给排水工程'!$B$3:$H$113,7,0) -> 89.38 | I3: =VLOOKUP(B3,'[1]2.4给排水工程'!$B$3:$I$113,8,0) -> 93 | J3: =VLOOKUP(B3,'[1]2.4给排水工程'!$B$3:$J$113,9,0) -> 0.99 | K3: =VLOOKUP(B3,'[1]2.4给排水工程'!$B$3:$K$113,10,0) -> 24.81 | L3: ='2.1装饰工程'!$L$4 -> 0.207 | M3: =F3*G3 -> 0
A4: 2 | B4: 钢塑复合管DN100 | C4: 1.安装部位:室内 2.介质:水 3.连接形式:按设计及规范要求 4.压力试验及吹、洗设计要求:按设计及规范要求 5.管道穿内墙、楼板、吊顶开洞及封堵套管:按设计及规范要求 6.管道支架及抗震支架：按设计及规范要求 7.其他:按设计及规范要求 | D4: 按设计图示管道中心线以长度计算 | E4: m | G4: =(H4+I4+J4+K4)*(1+L4) -> 169.68006 | H4: =VLOOKUP(B4,'[1]2.4给排水工程'!$B$3:$H$113,7,0) -> 82.38 | I4: =VLOOKUP(B4,'[1]2.4给排水工程'!$B$3:$I$113,8,0) -> 40.3 | J4: =VLOOKUP(B4,'[1]2.4给排水工程'!$B$3:$J$113,9,0) -> 0.97 | K4: =VLOOKUP(B4,'[1]2.4给排水工程'!$B$3:$K$113,10,0) -> 16.93 | L4: =$L$3 -> 0.207 | M4: =F4*G4 -> 0
A5: 3 | B5: 钢塑复合管DN80 | C5: 1.安装部位:室内 2.介质:水 3.连接形式:按设计及规范要求 4.压力试验及吹、洗设计要求:按设计及规范要求 5.管道穿内墙、楼板、吊顶开洞及封堵套管:按设计及规范要求 6.管道支架及抗震支架：按设计及规范要求 7.其他:按设计及规范要求 | D5: 按设计图示管道中心线以长度计算 | E5: m | G5: =(H5+I5+J5+K5)*(1+L5) -> 137.61007 | H5: =VLOOKUP(B5,'[1]2.4给排水工程'!$B$3:$H$113,7,0) -> 72.69 | I5: =VLOOKUP(B5,'[1]2.4给排水工程'!$B$3:$I$113,8,0) -> 37.06 | J5: =VLOOKUP(B5,'[1]2.4给排水工程'!$B$3:$J$113,9,0) -> 0.9 | K5: =VLOOKUP(B5,'[1]2.4给排水工程'!$B$3:$K$113,10,0) -> 3.36 | L5: =$L$3 -> 0.207 | M5: =F5*G5 -> 0
A6: 4 | B6: 钢塑复合管DN65 | C6: 1.安装部位:室内 2.介质:水 3.连接形式:按设计及规范要求 4.压力试验及吹、洗设计要求:按设计及规范要求 5.管道穿内墙、楼板、吊顶开洞及封堵套管:按设计及规范要求 6.管道支架及抗震支架：按设计及规范要求 7.其他:按设计及规范要求 | D6: 按设计图示管道中心线以长度计算 | E6: m | G6: =(H6+I6+J6+K6)*(1+L6) -> 115.23229 | H6: =VLOOKUP(B6,'[1]2.4给排水工程'!$B$3:$H$113,7,0) -> 66.88 | I6: =VLOOKUP(B6,'[1]2.4给排水工程'!$B$3:$I$113,8,0) -> 25.1 | J6: =VLOOKUP(B6,'[1]2.4给排水工程'!$B$3:$J$113,9,0) -> 0.83 | K6: =VLOOKUP(B6,'[1]2.4给排水工程'!$B$3:$K$113,10,0) -> 2.66 | L6: =$L$3 -> 0.207 | M6: =F6*G6 -> 0
A7: 5 | B7: 钢塑复合管DN50 | C7: 1.安装部位:室内 2.介质:水 3.连接形式:按设计及规范要求 4.压力试验及吹、洗设计要求:按设计及规范要求 5.管道穿内墙、楼板、吊顶开洞及封堵套管:按设计及规范要求 6.管道支架及抗震支架：按设计及规范要求 7.其他:按设计及规范要求 | D7: 按设计图示管道中心线以长度计算 | E7: m | G7: =(H7+I7+J7+K7)*(1+L7) -> 96.01685 | H7: =VLOOKUP(B7,'[1]2.4给排水工程'!$B$3:$H$113,7,0) -> 64.31 | I7: =VLOOKUP(B7,'[1]2.4给排水工程'!$B$3:$I$113,8,0) -> 12.19 | J7: =VLOOKUP(B7,'[1]2.4给排水工程'!$B$3:$J$113,9,0) -> 0.81 | K7: =VLOOKUP(B7,'[1]2.4给排水工程'!$B$3:$K$113,10,0) -> 2.24 | L7: =$L$3 -> 0.207 | M7: =F7*G7 -> 0
A8: 6 | B8: 钢塑复合管DN40 | C8: 1.安装部位:室内 2.介质:水 3.连接形式:按设计及规范要求 4.压力试验及吹、洗设计要求:按设计及规范要求 5.管道穿内墙、楼板、吊顶开洞及封堵套管:按设计及规范要求 6.管道支架及抗震支架：按设计及规范要求 7.其他:按设计及规范要求 | D8: 按设计图示管道中心线以长度计算 | E8: m | G8: =(H8+I8+J8+K8)*(1+L8) -> 80.57932 | H8: =VLOOKUP(B8,'[1]2.4给排水工程'!$B$3:$H$113,7,0) -> 53.19 | I8: =VLOOKUP(B8,'[1]2.4给排水工程'!$B$3:$I$113,8,0) -> 11.1 | J8: =VLOOKUP(B8,'[1]2.4给排水工程'!$B$3:$J$113,9,0) -> 0.77 | K8: =VLOOKUP(B8,'[1]2.4给排水工程'!$B$3:$K$113,10,0) -> 1.7 | L8: =$L$3 -> 0.207 | M8: =F8*G8 -> 0
A9: 7 | B9: 钢塑复合管DN32 | C9: 1.安装部位:室内 2.介质:水 3.连接形式:按设计及规范要求 4.压力试验及吹、洗设计要求:按设计及规范要求 5.管道穿内墙、楼板、吊顶开洞及封堵套管:按设计及规范要求 6.管道支架及抗震支架：按设计及规范要求 7.其他:按设计及规范要求 | D9: 按设计图示管道中心线以长度计算 | E9: m | G9: =(H9+I9+J9+K9)*(1+L9) -> 72.77003 | H9: =VLOOKUP(B9,'[1]2.4给排水工程'!$B$3:$H$113,7,0) -> 52.6 | I9: =VLOOKUP(B9,'[1]2.4给排水工程'!$B$3:$I$113,8,0) -> 5.5 | J9: =VLOOKUP(B9,'[1]2.4给排水工程'!$B$3:$J$113,9,0) -> 0.75 | K9: =VLOOKUP(B9,'[1]2.4给排水工程'!$B$3:$K$113,10,0) -> 1.44 | L9: =$L$3 -> 0.207 | M9: =F9*G9 -> 0
A10: 8 | B10: 钢塑复合管DN25 | C10: 1.安装部位:室内 2.介质:水 3.连接形式:按设计及规范要求 4.压力试验及吹、洗设计要求:按设计及规范要求 5.管道穿内墙、楼板、吊顶开洞及封堵套管:按设计及规范要求 6.管道支架及抗震支架：按设计及规范要求 7.其他:按设计及规范要求 | D10: 按设计图示管道中心线以长度计算 | E10: m | G10: =(H10+I10+J10+K10)*(1+L10) -> 61.72598 | H10: =VLOOKUP(B10,'[1]2.4给排水工程'!$B$3:$H$113,7,0) -> 46.2 | I10: =VLOOKUP(B10,'[1]2.4给排水工程'!$B$3:$I$113,8,0) -> 3.2 | J10: =VLOOKUP(B10,'[1]2.4给排水工程'!$B$3:$J$113,9,0) -> 0.65 | K10: =VLOOKUP(B10,'[1]2.4给排水工程'!$B$3:$K$113,10,0) -> 1.09 | L10: =$L$3 -> 0.207 | M10: =F10*G10 -> 0
A11: 9 | B11: 钢塑复合管DN20 | C11: 1.安装部位:室内 2.介质:水 3.连接形式:按设计及规范要求 4.压力试验及吹、洗设计要求:按设计及规范要求 5.管道穿内墙、楼板、吊顶开洞及封堵套管:按设计及规范要求 6.管道支架及抗震支架：按设计及规范要求 7.其他:按设计及规范要求 | D11: 按设计图示管道中心线以长度计算 | E11: m | G11: =(H11+I11+J11+K11)*(1+L11) -> 56.01687 | H11: =VLOOKUP(B11,'[1]2.4给排水工程'!$B$3:$H$113,7,0) -> 42.1 | I11: =VLOOKUP(B11,'[1]2.4给排水工程'!$B$3:$I$113,8,0) -> 3.2 | J11: =VLOOKUP(B11,'[1]2.4给排水工程'!$B$3:$J$113,9,0) -> 0.5 | K11: =VLOOKUP(B11,'[1]2.4给排水工程'!$B$3:$K$113,10,0) -> 0.61 | L11: =$L$3 -> 0.207 | M11: =F11*G11 -> 0
A12: 10 | B12: 球磨铸铁管DN150 | C12: 1.安装部位:室内 2.介质:水 3.连接形式:按设计及规范要求 4.压力试验及吹、洗设计要求:按设计及规范要求 5.管道穿内墙、楼板、吊顶开洞及封堵套管:按设计及规范要求 6.管道支架及抗震支架：按设计及规范要求 7.其他:按设计及规范要求 | D12: 按设计图示管道中心线以长度计算 | E12: m | G12: =(H12+I12+J12+K12)*(1+L12) -> 258.32214 | H12: =VLOOKUP(B12,'[1]2.4给排水工程'!$B$3:$H$113,7,0) -> 54.87 | I12: =VLOOKUP(B12,'[1]2.4给排水工程'!$B$3:$I$113,8,0) -> 132.1 | J12: =VLOOKUP(B12,'[1]2.4给排水工程'!$B$3:$J$113,9,0) -> 2.64 | K12: =VLOOKUP(B12,'[1]2.4给排水工程'!$B$3:$K$113,10,0) -> 24.41 | L12: =$L$3 -> 0.207 | M12: =F12*G12 -> 0
A13: 11 | B13: 球磨铸铁管DN100 | C13: 1.安装部位:室内 2.介质:水 3.连接形式:按设计及规范要求 4.压力试验及吹、洗设计要求:按设计及规范要求 5.管道穿内墙、楼板、吊顶开洞及封堵套管:按设计及规范要求 6.管道支架及抗震支架：按设计及规范要求 7.其他:按设计及规范要求 | D13: 按设计图示管道中心线以长度计算 | E13: m | G13: =(H13+I13+J13+K13)*(1+L13) -> 209.14896 | H13: =VLOOKUP(B13,'[1]2.4给排水工程'!$B$3:$H$113,7,0) -> 45.82 | I13: =VLOOKUP(B13,'[1]2.4给排水工程'!$B$3:$I$113,8,0) -> 107.5 | J13: =VLOOKUP(B13,'[1]2.4给排水工程'!$B$3:$J$113,9,0) -> 1.84 | K13: =VLOOKUP(B13,'[1]2.4给排水工程'!$B$3:$K$113,10,0) -> 18.12 | L13: =$L$3 -> 0.207 | M13: =F13*G13 -> 0
A14: 12 | B14: 球磨铸铁管DN80 | C14: 1.安装部位:室内 2.介质:水 3.连接形式:按设计及规范要求 4.压力试验及吹、洗设计要求:按设计及规范要求 5.管道穿内墙、楼板、吊顶开洞及封堵套管:按设计及规范要求 6.管道支架及抗震支架：按设计及规范要求 7.其他:按设计及规范要求 | D14: 按设计图示管道中心线以长度计算 | E14: m | G14: =(H14+I14+J14+K14)*(1+L14) -> 180.15682 | H14: =VLOOKUP(B14,'[1]2.4给排水工程'!$B$3:$H$113,7,0) -> 29.83 | I14: =VLOOKUP(B14,'[1]2.4给排水工程'!$B$3:$I$113,8,0) -> 115.26 | J14: =VLOOKUP(B14,'[1]2.4给排水工程'!$B$3:$J$113,9,0) -> 1.26 | K14: =VLOOKUP(B14,'[1]2.4给排水工程'!$B$3:$K$113,10,0) -> 2.91 | L14: =$L$3 -> 0.207 | M14: =F14*G14 -> 0
A15: 13 | B15: 球磨铸铁管DN65 | C15: 1.安装部位:室内 2.介质:水 3.连接形式:按设计及规范要求 4.压力试验及吹、洗设计要求:按设计及规范要求 5.管道穿内墙、楼板、吊顶开洞及封堵套管:按设计及规范要求 6.管道支架及抗震支架：按设计及规范要求 7.其他:按设计及规范要求 | D15: 按设计图示管道中心线以长度计算 | E15: m | G15: =(H15+I15+J15+K15)*(1+L15) -> 154.55635 | H15: =VLOOKUP(B15,'[1]2.4给排水工程'!$B$3:$H$113,7,0) -> 29.83 | I15: =VLOOKUP(B15,'[1]2.4给排水工程'!$B$3:$I$113,8,0) -> 94.05 | J15: =VLOOKUP(B15,'[1]2.4给排水工程'!$B$3:$J$113,9,0) -> 1.26 | K15: =VLOOKUP(B15,'[1]2.4给排水工程'!$B$3:$K$113,10,0) -> 2.91 | L15: =$L$3 -> 0.207 | M15: =F15*G15 -> 0
... A20: 18 | B20: PPR给水管De63 | C20: 1.安装部位:室内 2.介质:水 3.连接形式:热熔连接 4.阻火圈设计要求:设计及规范要求 5.压力试验及吹、洗设计要求:按规范要求 6.管道穿内墙、楼板、吊顶开洞及封堵套管:按设计及规范要求 7.管道支架及抗震支架：按设计及规范要求 8.其他:按设计及规范要求 | D20: 按设计图示管道中心线以长度计算 | E20: m | G20: =(H20+I20+J20+K20)*(1+L20) -> 78.15325 | H20: =VLOOKUP(B20,'[1]2.4给排水工程'!$B$3:$H$113,7,0) -> 23.68 | I20: =VLOOKUP(B20,'[1]2.4给排水工程'!$B$3:$I$113,8,0) -> 40.6 | J20: =VLOOKUP(B20,'[1]2.4给排水工程'!$B$3:$J$113,9,0) -> 0.42 | K20: =VLOOKUP(B20,'[1]2.4给排水工程'!$B$3:$K$113,10,0) -> 0.05 | L20: =$L$3 -> 0.207 | M20: =F20*G20 -> 0
A21: 19 | B21: PPR给水管De50 | C21: 1.安装部位:室内 2.介质:水 3.连接形式:热熔连接 4.阻火圈设计要求:设计及规范要求 5.压力试验及吹、洗设计要求:按规范要求 6.管道穿内墙、楼板、吊顶开洞及封堵套管:按设计及规范要求 7.管道支架及抗震支架：按设计及规范要求 8.其他:按设计及规范要求 | D21: 按设计图示管道中心线以长度计算 | E21: m | F21: 18.54 | G21: =(H21+I21+J21+K21)*(1+L21) -> 63.17438 | H21: =VLOOKUP(B21,'[1]2.4给排水工程'!$B$3:$H$113,7,0) -> 23.68 | I21: =VLOOKUP(B21,'[1]2.4给排水工程'!$B$3:$I$113,8,0) -> 28.24 | J21: =VLOOKUP(B21,'[1]2.4给排水工程'!$B$3:$J$113,9,0) -> 0.37 | K21: =VLOOKUP(B21,'[1]2.4给排水工程'!$B$3:$K$113,10,0) -> 0.05 | L21: =$L$3 -> 0.207 | M21: =F21*G21 -> 1171.253
A22: 20 | B22: PPR给水管De40 | C22: 1.安装部位:室内 2.介质:水 3.连接形式:热熔连接 4.阻火圈设计要求:设计及规范要求 5.压力试验及吹、洗设计要求:按规范要求 6.管道穿内墙、楼板、吊顶开洞及封堵套管:按设计及规范要求 7.管道支架及抗震支架：按设计及规范要求 8.其他:按设计及规范要求 | D22: 按设计图示管道中心线以长度计算 | E22: m | G22: =(H22+I22+J22+K22)*(1+L22) -> 50.76642 | H22: =VLOOKUP(B22,'[1]2.4给排水工程'!$B$3:$H$113,7,0) -> 23.68 | I22: =VLOOKUP(B22,'[1]2.4给排水工程'!$B$3:$I$113,8,0) -> 18 | J22: =VLOOKUP(B22,'[1]2.4给排水工程'!$B$3:$J$113,9,0) -> 0.35 | K22: =VLOOKUP(B22,'[1]2.4给排水工程'!$B$3:$K$113,10,0) -> 0.03 | L22: =$L$3 -> 0.207 | M22: =F22*G22 -> 0
A23: 21 | B23: PPR给水管De32 | C23: 1.安装部位:室内 2.介质:水 3.连接形式:热熔连接 4.阻火圈设计要求:设计及规范要求 5.压力试验及吹、洗设计要求:按规范要求 6.管道穿内墙、楼板、吊顶开洞及封堵套管:按设计及规范要求 7.管道支架及抗震支架：按设计及规范要求 8.其他:按设计及规范要求 | D23: 按设计图示管道中心线以长度计算 | E23: m | F23: 21.69 | G23: =(H23+I23+J23+K23)*(1+L23) -> 41.6415 | H23: =VLOOKUP(B23,'[1]2.4给排水工程'!$B$3:$H$113,7,0) -> 23.68 | I23: =VLOOKUP(B23,'[1]2.4给排水工程'!$B$3:$I$113,8,0) -> 10.5 | J23: =VLOOKUP(B23,'[1]2.4给排水工程'!$B$3:$J$113,9,0) -> 0.29 | K23: =VLOOKUP(B23,'[1]2.4给排水工程'!$B$3:$K$113,10,0) -> 0.03 | L23: =$L$3 -> 0.207 | M23: =F23*G23 -> 903.20413
A24: 22 | B24: PPR给水管De25 | C24: 1.安装部位:室内 2.介质:水 3.连接形式:热熔连接 4.阻火圈设计要求:设计及规范要求 5.压力试验及吹、洗设计要求:按规范要求 6.管道穿内墙、楼板、吊顶开洞及封堵套管:按设计及规范要求 7.管道支架及抗震支架：按设计及规范要求 8.其他:按设计及规范要求 | D24: 按设计图示管道中心线以长度计算 | E24: m | F24: 13.25 | G24: =(H24+I24+J24+K24)*(1+L24) -> 33.27699 | H24: =VLOOKUP(B24,'[1]2.4给排水工程'!$B$3:$H$113,7,0) -> 23.68 | I24: =VLOOKUP(B24,'[1]2.4给排水工程'!$B$3:$I$113,8,0) -> 3.6 | J24: =VLOOKUP(B24,'[1]2.4给排水工程'!$B$3:$J$113,9,0) -> 0.26 | K24: =VLOOKUP(B24,'[1]2.4给排水工程'!$B$3:$K$113,10,0) -> 0.03 | L24: =$L$3 -> 0.207 | M24: =F24*G24 -> 440.92012
A25: 23 | B25: PPR给水管De20 | C25: 1.安装部位:室内 2.介质:水 3.连接形式:热熔连接 4.阻火圈设计要求:设计及规范要求 5.压力试验及吹、洗设计要求:按规范要求 6.管道穿内墙、楼板、吊顶开洞及封堵套管:按设计及规范要求 7.管道支架及抗震支架：按设计及规范要求 8.其他:按设计及规范要求 | D25: 按设计图示管道中心线以长度计算 | E25: m | F25: 9.64 | G25: =(H25+I25+J25+K25)*(1+L25) -> 27.08508 | H25: =VLOOKUP(B25,'[1]2.4给排水工程'!$B$3:$H$113,7,0) -> 20.68 | I25: =VLOOKUP(B25,'[1]2.4给排水工程'!$B$3:$I$113,8,0) -> 1.49 | J25: =VLOOKUP(B25,'[1]2.4给排水工程'!$B$3:$J$113,9,0) -> 0.24 | K25: =VLOOKUP(B25,'[1]2.4给排水工程'!$B$3:$K$113,10,0) -> 0.03 | L25: =$L$3 -> 0.207 | M25: =F25*G25 -> 261.10017
A26: 24 | B26: PPR热给水管De90 | C26: 1.安装部位:室内 2.介质:水 3.连接形式:热熔连接 4.阻火圈设计要求:设计及规范要求 5.压力试验及吹、洗设计要求:按规范要求 6.管道穿内墙、楼板、吊顶开洞及封堵套管:按设计及规范要求 7.管道支架及抗震支架：按设计及规范要求 8.其他:按设计及规范要求 | D26: 按设计图示管道中心线以长度计算 | E26: m | G26: =(H26+I26+J26+K26)*(1+L26) -> 125.72112 | H26: =VLOOKUP(B26,'[1]2.4给排水工程'!$B$3:$H$113,7,0) -> 23.68 | I26: =VLOOKUP(B26,'[1]2.4给排水工程'!$B$3:$I$113,8,0) -> 79.88 | J26: =VLOOKUP(B26,'[1]2.4给排水工程'!$B$3:$J$113,9,0) -> 0.55 | K26: =VLOOKUP(B26,'[1]2.4给排水工程'!$B$3:$K$113,10,0) -> 0.05 | L26: =$L$3 -> 0.207 | M26: =F26*G26 -> 0
