Workbook

Sheet 1-清单及价格说明
A1: 编制说明
A3: 一 | B3: 工程量清单编制依据：
A4: 1 | B4: 长城智选设计、施工一体化项目工程图纸、效果图（1.0、2.0版本）
A5: 2 | B5: 《建设工程工程量清单计价规范 GB 50500-2013》
A6: 3 | B6: 《建筑工程建筑面积计算规范》GB 55031-2022
A7: 二 | B7: 工程量清单及控制价注意事项说明:
A8: 1 | B8: 本工程采用设计施工一体化，包工包料的全费用固定综合单价组价。固定综合单价包括现场人工费、材料费、机械费、管理费、措施费、规费、利润、税金、合同备案费、水电费、工程当地所要求必须缴纳的费用以及采用固定价格的工程所测算的风险金、相关的材料试验费、检测费（包括但不限于空气、材料、结构等第三方检测、鉴定等费用）及各系统施工完成后系统调试费、资料整理归档等一切费用。
A9: 2 | B9: 措施费用包含在固定综合单价中，不单独体现。措施费费用包括但不限于安全文明施工费用（应满足项目所在地的政府及物业要求的安全文明施工标准）、临时设施（办公住宿临设、临水临电、临时道路等）、夜间施工、非夜间施工照明、二次搬运、冬雨季施工、已完工程及设备成品保护等与项目相关的措施费用。
A10: 3 | B10: 本项目中涉及脚手架、垂直运输、超高增加费、垃圾清运费、垃圾消纳费含在固定综合单价中，不再单独体现。
A11: 4 | B11: 消防设备复检、玻璃幕墙、石材幕墙的检测以及当地政府要求的检测相关费用包含在固定综合单价中，不再单独体现。消防验收在招标范围内，消防的备案、验收、办证，单独组价。其它相关建设手续费（含物业及政府相关备案、开工、建设、验收等所有手续相关费用）含在固定综合单价中，不再单独体现。
A12: 5 | B12: 强弱电、给排水、消防、暖通等专业开洞、封堵、套管等，包含在对应专业的管道固定综合单价中，不再单独列清单。
A13: 6 | B13: 方案图纸设计费（包括但不限于涉及本项目的各专业工程（建筑、装饰、结构、幕墙、消防、电气、照明、给排水、暖通等）图纸深化、报审、审图、现场施工指导配合、竣工图编制等所有图纸相关费用），按照平方米进行计价，未使用区域、室内、外停车位不计算，部分店面涉及室外院落、隔离墙、道路规划，不计量，不单独计价。
A14: 7 | B14: 需进行政府竣工验收的费用，及因验收产生的检测费用均含在综合单价内。
A15: 8 | B15: 投标单位在投标前应踏勘现场，充分考虑现场、方案设计等实际情况(如:运输条件、施工场地、地质条件、施工时间区段等)；综合考虑现场实际地面找平厚度与清单、方案设计不一致时，价格不进行调整，投标单位也应深入理解技术要求和验收要求,所有在招标时提供的文件均认为已完整无误包含在报价之中；
A16: 9 | B16: 无节点做法，可自行深化，经甲方确认后实施，费用包含在综合单价相关子目中。
A17: 10 | B17: 对于新增项目或签证、设计变更产生的工程项目造价的调整按以下顺序执行：
A18: 10.1 | B18: 工程量清单表中有相同工程内容的项目，按相同项目综合单价执行，根据工程量增减进行总价调整；同标段或是同期其他分包合同有相同项目或类似项目单价，按照该单价计取。
A19: 10.2 | B19: 工程量清单表中有类似工程内容的项目，如某项清单发包人要求主要材料更换，则原综合单价不变，只调整主材价差，土建材料价差=（双方确定含税材料价格-本合同清单表内注明的主材价格）× (1+税金)。
... A21: 11 | B21: 本页不得删除,将作为合同清单的有效组成部分。

Sheet 2-报价汇总
A1: 工程报价汇总表
A2: 公司名称：深圳市广湾建设科技有限公司 | D2: 单位：元
A3: 序号 | B3: 单 位 工 程 名 称 | C3: 报价汇总 | D3: 备注
A4: 1 | B4: 装饰工程 | C4: ='2.1装饰工程'!M230 -> 640705.34 | E4: 642437.17 | F4: =C4-E4 -> -1731.8326
A5: 2 | B5: 强电工程 | C5: ='2.2强电工程'!M143 -> 80496.588 | E5: 80696.663 | F5: =C5-E5 -> -200.07437
A6: 3 | B6: 弱电工程 | C6: ='2.3弱电工程'!M83 -> 93628.43 | E6: 93861.144 | F6: =C6-E6 -> -232.71358
A7: 4 | B7: 消防工程 | C7: ='2.4消防工程 '!M15 -> 399026.96 | E7: 400018.74 | F7: =C7-E7 -> -991.782
A8: 5 | B8: 暖通工程 | C8: ='2.5暖通工程'!M90 -> 97546.873 | E8: 97789.326 | F8: =C8-E8 -> -242.45287
A9: 6 | B9: 合计 | C9: =SUM(C4:C8) -> 1311404.2 | E9: 1314803 | F9: =C9-E9 -> -3398.8555

Sheet 2.1装饰工程
A1: 长城智选商超店装修项目装饰工程
A2: 序号 | B2: 分部分项名称 | C2: 项目特征 | D2: 计量规则 | E2: 单位 | F2: 工程量 | G2: 综合单价 | H2: 人工 | I2: 主材 | J2: 辅材 | K2: 机械 | L2: 其他综合费率 | M2: 合计 | N2: 备注
A3: 一 | B3: 方案设计费
A4: 1 | B4: 方案图纸设计费 | C4: 1.包含建筑及装饰、结构、电气、暖通、给排水、消防、幕墙等专业，前期需现场踏勘，出具平面图、效果图等 2.包括但不限于图纸深化、报审、审图、竣工图编制等图纸相关费用 | D4: 1.使用面积<300平方米 2.以设计图纸尺寸按室内空间净面积计量（含不与墙面交集的柱面积），未使用区域、室内、外停车位不计算 | E4: m2 | F4: 300 | G4: =(H4+I4+J4+K4)*(1+L4) -> 108.63 | H4: =VLOOKUP(B4,'[1]2.1装饰工程'!$B$4:$H$231,7,0) -> 90 | I4: =VLOOKUP(B4,'[1]2.1装饰工程'!$B$4:$I$231,8,0) -> 0 | J4: =VLOOKUP(B4,'[1]2.1装饰工程'!$B$4:$J$231,9,0) -> 0 | K4: =VLOOKUP(B4,'[1]2.1装饰工程'!$B$4:$K$231,10,0) -> 0 | L4: ='[2]2-报价汇总'!$G$1 -> 0.207 | M4: =F4*G4 -> 32589
A5: 2 | B5: 方案图纸设计费 | C5: 1.包含建筑及装饰、结构、电气、暖通、给排水、消防、幕墙等专业，前期需现场踏勘，出具平面图、效果图等 2.包括但不限于图纸深化、报审、审图、竣工图编制等图纸相关费用 | D5: 1.使用面积≥300平方米 2.以设计图纸尺寸按室内空间净面积计量（含不与墙面交集的柱面积），未使用区域、室内、外停车位不计算 | E5: m2 | G5: =(H5+I5+J5+K5)*(1+L5) -> 96.56 | H5: 80 | I5: 0 | J5: 0 | K5: 0 | L5: =$L$4 -> 0.207 | M5: =F5*G5 -> 0
A6: 二 | B6: 拆除工程
A7: 1 | B7: 素混凝土拆除 | C7: 1.素混凝土构件拆除（含平面、立面、基础等） 2.包括：墙体内的管线、开关、插座等，达到不妨碍后期装修的程度，拆除后的所有材料施工单位自行处理 3.其他：满足施工要求 | D7: 工程量按拆除构件的混凝土体积计算 | E7: m3 | G7: =(H7+I7+J7+K7)*(1+L7) -> 483.98286 | H7: =VLOOKUP(B7,'[1]2.1装饰工程'!$B$4:$H$231,7,0) -> 280.88 | I7: =VLOOKUP(B7,'[1]2.1装饰工程'!$B$4:$I$231,8,0) -> 0 | J7: =VLOOKUP(B7,'[1]2.1装饰工程'!$B$4:$J$231,9,0) -> 7.47 | K7: =VLOOKUP(B7,'[1]2.1装饰工程'!$B$4:$K$231,10,0) -> 112.63 | L7: =$L$4 -> 0.207 | M7: =F7*G7 -> 0
A8: 2 | B8: 钢筋混凝土构件拆除 | C8: 1.钢筋混凝土构件拆除（含平面、立面、基础等） 2.包括：墙体内的管线、开关、插座等，达到不妨碍后期装修的程度，拆除后的所有材料施工单位自行处理 3.其他：满足施工要求 | D8: 工程量按拆除构件的混凝土体积计算 | E8: m3 | G8: =(H8+I8+J8+K8)*(1+L8) -> 617.46499 | H8: =VLOOKUP(B8,'[1]2.1装饰工程'!$B$4:$H$231,7,0) -> 359 | I8: =VLOOKUP(B8,'[1]2.1装饰工程'!$B$4:$I$231,8,0) -> 0 | J8: =VLOOKUP(B8,'[1]2.1装饰工程'!$B$4:$J$231,9,0) -> 9.2 | K8: =VLOOKUP(B8,'[1]2.1装饰工程'!$B$4:$K$231,10,0) -> 143.37 | L8: =$L$4 -> 0.207 | M8: =F8*G8 -> 0
A9: 3 | B9: 砌体墙拆除 | C9: 1.砌筑墙体拆除，连墙体内砼柱破碎后装袋 2.包括：砌体墙及附属的基层面层，墙体内的管线、开关、插座、等，达到不妨碍装修的程度，拆除后的所有材料施工单位自行处理 3.其他：满足施工要求 | D9: 工程量按拆除部位的体积计算 | E9: m3 | G9: =(H9+I9+J9+K9)*(1+L9) -> 231.59916 | H9: =VLOOKUP(B9,'[1]2.1装饰工程'!$B$4:$H$231,7,0) -> 126.88 | I9: =VLOOKUP(B9,'[1]2.1装饰工程'!$B$4:$I$231,8,0) -> 0 | J9: =VLOOKUP(B9,'[1]2.1装饰工程'!$B$4:$J$231,9,0) -> 0 | K9: =VLOOKUP(B9,'[1]2.1装饰工程'!$B$4:$K$231,10,0) -> 65 | L9: =$L$4 -> 0.207 | M9: =F9*G9 -> 0
A10: 4 | B10: 玻璃隔墙拆除 | C10: 1.玻璃隔墙拆除 2.包括：玻璃隔墙及附属的基层面层，墙体内的管线、开关、插座等，达到不妨碍装修的程度，拆除后的所有材料施工单位自行处理 3.墙体厚度：综合考虑 4.其他：满足施工要求 | D10: 工程量按拆除部位的面积计算 | E10: m2 | G10: =(H10+I10+J10+K10)*(1+L10) -> 32.48037 | H10: =VLOOKUP(B10,'[1]2.1装饰工程'!$B$4:$H$231,7,0) -> 13.91 | I10: =VLOOKUP(B10,'[1]2.1装饰工程'!$B$4:$I$231,8,0) -> 0 | J10: =VLOOKUP(B10,'[1]2.1装饰工程'!$B$4:$J$231,9,0) -> 0 | K10: =VLOOKUP(B10,'[1]2.1装饰工程'!$B$4:$K$231,10,0) -> 13 | L10: =$L$4 -> 0.207 | M10: =F10*G10 -> 0
A11: 5 | B11: 石膏板隔墙拆除 | C11: 1.石膏板隔墙拆除 2.包括：石膏板隔墙及附属的基层面层，墙体内的管线、开关、插座等，达到不妨碍装修的程度，拆除后的所有材料施工单位自行处理 3.墙体厚度：综合考虑， 4.其他：满足施工要求 | D11: 工程量按拆除部位的面积计算 | E11: m2 | G11: =(H11+I11+J11+K11)*(1+L11) -> 33.68737 | H11: =VLOOKUP(B11,'[1]2.1装饰工程'!$B$4:$H$231,7,0) -> 14.91 | I11: =VLOOKUP(B11,'[1]2.1装饰工程'!$B$4:$I$231,8,0) -> 0 | J11: =VLOOKUP(B11,'[1]2.1装饰工程'!$B$4:$J$231,9,0) -> 0 | K11: =VLOOKUP(B11,'[1]2.1装饰工程'!$B$4:$K$231,10,0) -> 13 | L11: =$L$4 -> 0.207 | M11: =F11*G11 -> 0
A12: 6 | B12: 砌体墙开门洞（含修补） | C12: 1.砌体墙开门洞（含修补） 2.包括：砌体墙隔墙及附属的基层面层，墙体内的管线、开关、插座等，达到不妨碍装修的程度，拆除后的所有材料施工单位自行处理 3.墙体厚度：综合考虑，包含开门洞的修补工作 4.其他：满足施工要求 | D12: 工程量按拆除部位的面积计算 | E12: m2 | G12: =(H12+I12+J12+K12)*(1+L12) -> 87.20575 | H12: =VLOOKUP(B12,'[1]2.1装饰工程'!$B$4:$H$231,7,0) -> 56.66 | I12: =VLOOKUP(B12,'[1]2.1装饰工程'!$B$4:$I$231,8,0) -> 0 | J12: =VLOOKUP(B12,'[1]2.1装饰工程'!$B$4:$J$231,9,0) -> 2.59 | K12: =VLOOKUP(B12,'[1]2.1装饰工程'!$B$4:$K$231,10,0) -> 13 | L12: =$L$4 -> 0.207 | M12: =F12*G12 -> 0
A13: 7 | B13: 门窗拆除（包括门框、门套） | C13: 1.门窗拆除 2.包括：门框、门套，不区分门窗材质，达到不妨碍装修的程度，拆除后的所有材料施工单位自行处理 3.其他：满足施工要求 | D13: 工程量按拆除面积计算 | E13: m2 | G13: =(H13+I13+J13+K13)*(1+L13) -> 34.59262 | H13: =VLOOKUP(B13,'[1]2.1装饰工程'!$B$4:$H$231,7,0) -> 15.66 | I13: =VLOOKUP(B13,'[1]2.1装饰工程'!$B$4:$I$231,8,0) -> 0 | J13: =VLOOKUP(B13,'[1]2.1装饰工程'!$B$4:$J$231,9,0) -> 0 | K13: =VLOOKUP(B13,'[1]2.1装饰工程'!$B$4:$K$231,10,0) -> 13 | L13: =$L$4 -> 0.207 | M13: =F13*G13 -> 0
A14: 8 | B14: 楼地面装饰物拆除 | C14: 1.楼地面装饰物拆除（包括但不限于玻璃、PVC、环氧地坪等材质） 2.包括：装饰地面面层及基层，地面内的管线、开关、插座等，达到不妨碍后期地面装修的程度，拆除后的所有材料施工单位自行处理 3.其他：满足施工要求 | D14: 工程量按拆除面积计算 | E14: m2 | G14: =(H14+I14+J14+K14)*(1+L14) -> 41.82255 | H14: =VLOOKUP(B14,'[1]2.1装饰工程'!$B$4:$H$231,7,0) -> 28.15 | I14: =VLOOKUP(B14,'[1]2.1装饰工程'!$B$4:$I$231,8,0) -> 0 | J14: =VLOOKUP(B14,'[1]2.1装饰工程'!$B$4:$J$231,9,0) -> 0 | K14: =VLOOKUP(B14,'[1]2.1装饰工程'!$B$4:$K$231,10,0) -> 6.5 | L14: =$L$4 -> 0.207 | M14: =F14*G14 -> 0
A15: 9 | B15: 楼地面地毯拆除 | C15: 1.楼地面地毯拆除 2.包括：地面面层及基层，地面内的管线、开关、插座等，达到不妨碍后期地面装修的程度，拆除后的所有材料施工单位自行处理 3.其他：满足施工要求 | D15: 工程量按拆除面积计算 | E15: m2 | G15: =(H15+I15+J15+K15)*(1+L15) -> 7.2244985 | H15: =4.97*1.15 -> 5.7155 | I15: 0 | J15: 0.05 | K15: 0.22 | L15: =$L$4 -> 0.207 | M15: =F15*G15 -> 0
A16: 10 | B16: 楼地面地砖拆除 | C16: 1.楼地面地砖拆除 2.包括：地面面层及基层，地面内的管线、开关、插座等，达到不妨碍后期地面装修的程度，拆除后的所有材料施工单位自行处理 3.其他：满足施工要求 | D16: 工程量按拆除面积计算 | E16: m2 | G16: =(H16+I16+J16+K16)*(1+L16) -> 38.656657 | H16: =27*1.15 -> 31.05 | I16: 0 | J16: 0.27705628 | K16: 0.7 | L16: =$L$4 -> 0.207 | M16: =F16*G16 -> 0
A17: 11 | B17: 楼地面地板拆除 | C17: 1.楼地面地板拆除 2.包括：地面面层及基层，地面内的管线、开关、插座等，达到不妨碍后期地面装修的程度，拆除后的所有材料施工单位自行处理 3.其他：满足施工要求 | D17: 工程量按拆除面积计算 | E17: m2 | G17: =(H17+I17+J17+K17)*(1+L17) -> 7.2244985 | H17: =4.97*1.15 -> 5.7155 | I17: 0 | J17: 0.05 | K17: 0.22 | L17: =$L$4 -> 0.207 | M17: =F17*G17 -> 0
A18: 12 | B18: 墙面、柱（梁）面装饰物拆除（含龙骨） | C18: 1.墙面装饰物拆除，含龙骨及基层板（包括但不限于石材、铝板、金属、木饰面、石膏板等材质） 2.包括：拆除装饰墙面龙骨、基层板及面层，地面内的管线、开关、插座等，达到不妨碍后期墙面装修的程度，拆除后的所有材料施工单位自行处理 3.其他：满足施工要求 | D18: 工程量按拆除面积计算 | E18: m2 | G18: =(H18+I18+J18+K18)*(1+L18) -> 36.59624 | H18: =VLOOKUP(B18,'[1]2.1装饰工程'!$B$4:$H$231,7,0) -> 23.82 | I18: =VLOOKUP(B18,'[1]2.1装饰工程'!$B$4:$I$231,8,0) -> 0 | J18: =VLOOKUP(B18,'[1]2.1装饰工程'!$B$4:$J$231,9,0) -> 0 | K18: =VLOOKUP(B18,'[1]2.1装饰工程'!$B$4:$K$231,10,0) -> 6.5 | L18: =$L$4 -> 0.207 | M18: =F18*G18 -> 0
A19: 13 | B19: 墙面、柱（梁）面装饰物拆除（不含龙骨） | C19: 1.墙面装饰物拆除，不含龙骨（包括但不限于石材、铝板、金属、木饰面等材质） 2.包括：拆除装饰墙面基层及面层，地面内的管线、开关、插座等，达到不妨碍后期墙面装修的程度，拆除后的所有材料施工单位自行处理 3.其他：满足施工要求 | D19: 工程量按拆除面积计算 | E19: m2 | G19: =(H19+I19+J19+K19)*(1+L19) -> 30.18707 | H19: =VLOOKUP(B19,'[1]2.1装饰工程'!$B$4:$H$231,7,0) -> 18.51 | I19: =VLOOKUP(B19,'[1]2.1装饰工程'!$B$4:$I$231,8,0) -> 0 | J19: =VLOOKUP(B19,'[1]2.1装饰工程'!$B$4:$J$231,9,0) -> 0 | K19: =VLOOKUP(B19,'[1]2.1装饰工程'!$B$4:$K$231,10,0) -> 6.5 | L19: =$L$4 -> 0.207 | M19: =F19*G19 -> 0
A20: 14 | B20: 铲除墙面涂料、裱糊面 | C20: 1.铲除涂料、裱糊面（综合考虑铲除部位） 2.包括：拆除装饰墙面涂料、腻子及砂浆找平层，地面内的管线、开关、插座等，达到不妨碍后期装修的程度，拆除后的所有材料施工单位自行处理 3.其他：满足施工要求 | D20: 工程量按拆除面积计算 | E20: m2 | G20: =(H20+I20+J20+K20)*(1+L20) -> 10.382614 | H20: =1.15*4.23 -> 4.8645 | K20: =1.15*3.25 -> 3.7375 | L20: =$L$4 -> 0.207 | M20: =F20*G20 -> 0
A21: 15 | B21: 铲除钢结构面油漆 | C21: 1.铲除油漆（综合考虑铲除部位） 2.包括：拆除钢结构面层涂料 3.其他：满足施工要求 | D21: 工程量按拆除面积计算 | E21: m2 | G21: =(H21+I21+J21+K21)*(1+L21) -> 19.085687 | H21: =1.15*8.5 -> 9.775 | K21: =1.15*5.25 -> 6.0375 | L21: =$L$4 -> 0.207 | M21: =F21*G21 -> 0
A22: 16 | B22: 玻璃贴膜拆除 | C22: 1.玻璃贴膜拆除 2.包括：清除玻璃贴膜，达到不妨碍装修的程度，拆除后的所有材料施工单位自行处理 3.其他：满足施工要求 | D22: 工程量按拆除面积计算 | E22: m2 | G22: =(H22+I22+J22+K22)*(1+L22) -> 11.62341 | H22: =VLOOKUP(B22,'[1]2.1装饰工程'!$B$4:$H$231,7,0) -> 6.38 | I22: =VLOOKUP(B22,'[1]2.1装饰工程'!$B$4:$I$231,8,0) -> 0 | J22: =VLOOKUP(B22,'[1]2.1装饰工程'!$B$4:$J$231,9,0) -> 0 | K22: =VLOOKUP(B22,'[1]2.1装饰工程'!$B$4:$K$231,10,0) -> 3.25 | L22: =$L$4 -> 0.207 | M22: =F22*G22 -> 0
A23: 17 | B23: 吊顶拆除 | C23: 1.吊顶拆除（包括但不限于石膏板、铝扣板、矿棉板等材质） 2.包括：转换层、龙骨、基层、面层及配套的风口、灯具、线管、吊顶上水管风管等所有材料，达到不妨碍吊顶装修的程度，拆除后的所有材料施工单位自行处理 3.其他：满足施工要求 | D23: 工程量按拆除面积计算 | E23: m2 | G23: =(H23+I23+J23+K23)*(1+L23) -> 27.08508 | H23: =VLOOKUP(B23,'[1]2.1装饰工程'!$B$4:$H$231,7,0) -> 15.94 | I23: =VLOOKUP(B23,'[1]2.1装饰工程'!$B$4:$I$231,8,0) -> 0 | J23: =VLOOKUP(B23,'[1]2.1装饰工程'!$B$4:$J$231,9,0) -> 0 | K23: =VLOOKUP(B23,'[1]2.1装饰工程'!$B$4:$K$231,10,0) -> 6.5 | L23: =$L$4 -> 0.207 | M23: =F23*G23 -> 0
A24: 18 | B24: 电气、暖通等拆除费用 | C24: 1.电气、暖通等拆除费用（裸顶） 2.包括：达到不妨碍装修的程度，拆除后的所有材料施工单位自行处理 3.其他：满足施工要求 | D24: 工程量按拆除裸顶天棚水平投影面积计算 | E24: m2 | G24: =(H24+I24+J24+K24)*(1+L24) -> 21.42425 | H24: =VLOOKUP(B24,'[1]2.1装饰工程'!$B$4:$H$231,7,0) -> 14.5 | I24: =VLOOKUP(B24,'[1]2.1装饰工程'!$B$4:$I$231,8,0) -> 0 | J24: =VLOOKUP(B24,'[1]2.1装饰工程'!$B$4:$J$231,9,0) -> 0 | K24: =VLOOKUP(B24,'[1]2.1装饰工程'!$B$4:$K$231,10,0) -> 3.25 | L24: =$L$4 -> 0.207 | M24: =F24*G24 -> 0
A25: 19 | B25: 外幕墙拆除 | C25: 1.外幕墙拆除（包括但不限于石材等材质） 2.包括：幕墙、基层板、龙骨及辅材（包含破碎后装袋），达到不妨碍装修的程度，拆除后的所有材料施工单位自行处理 3.其他：满足施工要求 | D25: 工程量按拆除面积计算 | E25: m2 | G25: =(H25+I25+J25+K25)*(1+L25) -> 56.27034 | H25: =VLOOKUP(B25,'[1]2.1装饰工程'!$B$4:$H$231,7,0) -> 40.12 | I25: =VLOOKUP(B25,'[1]2.1装饰工程'!$B$4:$I$231,8,0) -> 0 | J25: =VLOOKUP(B25,'[1]2.1装饰工程'!$B$4:$J$231,9,0) -> 0 | K25: =VLOOKUP(B25,'[1]2.1装饰工程'!$B$4:$K$231,10,0) -> 6.5 | L25: =$L$4 -> 0.207 | M25: =F25*G25 -> 0
A26: 20 | B26: 外幕墙金属拆除 | C26: 1.外幕墙金属面拆除 2.包括：幕墙、基层板、龙骨及辅材（包含破碎后装袋），达到不妨碍装修的程度，拆除后的所有材料施工单位自行处理 3.其他：满足施工要求 | D26: 工程量按拆除面积计算 | E26: m2 | G26: =(H26+I26+J26+K26)*(1+L26) -> 59.158691 | H26: =1.15*36.12 -> 41.538 | I26: 0 | J26: 0 | K26: =1.15*6.5 -> 7.475 | L26: =$L$4 -> 0.207 | M26: =F26*G26 -> 0
A27: 21 | B27: 外幕墙玻璃拆除 | C27: 1.外幕墙玻璃拆除 2.包括：幕墙、辅材（包含破碎后装袋），达到不妨碍装修的程度，拆除后的所有材料施工单位自行处理 3.其他：满足施工要求 | D27: 工程量按拆除面积计算 | E27: m2 | G27: =(H27+I27+J27+K27)*(1+L27) -> 59.158691 | H27: =1.15*36.12 -> 41.538 | I27: 0 | J27: 0 | K27: =1.15*6.5 -> 7.475 | L27: =$L$4 -> 0.207 | M27: =F27*G27 -> 0
A28: 22 | B28: 栏杆、栏板拆除 | C28: 1.栏杆、栏板拆除（综合考虑栏杆、栏板的材质及高度） 2.包括：达到不妨碍装修的程度，拆除后的所有材料施工单位自行处理 3.其他：满足施工要求 | D28: 工程量按拆除长度计算 | E28: m | G28: =(H28+I28+J28+K28)*(1+L28) -> 19.60168 | H28: =VLOOKUP(B28,'[1]2.1装饰工程'!$B$4:$H$231,7,0) -> 9.74 | I28: =VLOOKUP(B28,'[1]2.1装饰工程'!$B$4:$I$231,8,0) -> 0 | J28: =VLOOKUP(B28,'[1]2.1装饰工程'!$B$4:$J$231,9,0) -> 0 | K28: =VLOOKUP(B28,'[1]2.1装饰工程'!$B$4:$K$231,10,0) -> 6.5 | L28: =$L$4 -> 0.207 | M28: =F28*G28 -> 0
A29: 23 | B29: 店铺吊挂logo拆除 | C29: 1.店铺吊挂logo拆除，墙面logo不计（logo尺寸综合考虑） 2.包括：达到不妨碍装修的程度，拆除后的所有材料施工单位自行处理 3.其他：满足施工要求 | D29: 工程量按个计算 | E29: 个 | G29: =(H29+I29+J29+K29)*(1+L29) -> 65.93841 | H29: =VLOOKUP(B29,'[1]2.1装饰工程'!$B$4:$H$231,7,0) -> 48.13 | I29: =VLOOKUP(B29,'[1]2.1装饰工程'!$B$4:$I$231,8,0) -> 0 | J29: =VLOOKUP(B29,'[1]2.1装饰工程'!$B$4:$J$231,9,0) -> 0 | K29: =VLOOKUP(B29,'[1]2.1装饰工程'!$B$4:$K$231,10,0) -> 6.5 | L29: =$L$4 -> 0.207 | M29: =F29*G29 -> 0
A30: 24 | B30: 墙面logo拆除 | C30: 1.店铺墙面logo拆除（logo尺寸综合考虑） 2.包括：达到不妨碍装修的程度，拆除后的所有材料施工单位自行处理 3.其他：满足施工要求 | D30: 工程量按个计算 | E30: 个 | G30: =(H30+I30+J30+K30)*(1+L30) -> 90.07841 | H30: =VLOOKUP(B30,'[1]2.1装饰工程'!$B$4:$H$231,7,0) -> 68.13 | I30: =VLOOKUP(B30,'[1]2.1装饰工程'!$B$4:$I$231,8,0) -> 0 | J30: =VLOOKUP(B30,'[1]2.1装饰工程'!$B$4:$J$231,9,0) -> 0 | K30: =VLOOKUP(B30,'[1]2.1装饰工程'!$B$4:$K$231,10,0) -> 6.5 | L30: =$L$4 -> 0.207 | M30: =F30*G30 -> 0
A31: 25 | B31: 保洁费 | C31: 1.保洁费 2.包括：精保洁，满足开业条件 3.其他详见SI手册、品牌表及标准节点等，满足施工要求及国家规范 | D31: 工程量按装修店面占地面积计算 | E31: m2 | F31: 300 | G31: =(H31+I31+J31+K31)*(1+L31) -> 18.105 | H31: =VLOOKUP(B31,'[1]2.1装饰工程'!$B$4:$H$231,7,0) -> 15 | I31: =VLOOKUP(B31,'[1]2.1装饰工程'!$B$4:$I$231,8,0) -> 0 | J31: =VLOOKUP(B31,'[1]2.1装饰工程'!$B$4:$J$231,9,0) -> 0 | K31: =VLOOKUP(B31,'[1]2.1装饰工程'!$B$4:$K$231,10,0) -> 0 | L31: =$L$4 -> 0.207 | M31: =F31*G31 -> 5431.5
A32: 三 | B32: 装饰地面工程
A33: 1 | B33: 原地面做拉毛处理 | C33: 1.原始地面拉毛 2.其他详见SI手册、品牌表及标准节点等，满足施工要求及国家规范 | D33: 工程量按设计图示尺寸以面积计算 | E33: m2 | G33: =(H33+I33+J33+K33)*(1+L33) -> 14.13397 | H33: =VLOOKUP(B33,'[1]2.1装饰工程'!$B$4:$H$231,7,0) -> 11.71 | I33: =VLOOKUP(B33,'[1]2.1装饰工程'!$B$4:$I$231,8,0) -> 0 | J33: =VLOOKUP(B33,'[1]2.1装饰工程'!$B$4:$J$231,9,0) -> 0 | K33: =VLOOKUP(B33,'[1]2.1装饰工程'!$B$4:$K$231,10,0) -> 0 | L33: =$L$4 -> 0.207 | M33: =F33*G33 -> 0
A34: 2 | B34: 5mm水泥自流平基层 | C34: 1.5mm水泥自流平 2.其他详见SI手册、品牌表及标准节点等，满足施工要求及国家规范 | D34: 工程量按设计图示尺寸以面积计算 | E34: m2 | G34: =(H34+I34+J34+K34)*(1+L34) -> 46.11947 | H34: =VLOOKUP(B34,'[1]2.1装饰工程'!$B$4:$H$231,7,0) -> 26.26 | I34: =VLOOKUP(B34,'[1]2.1装饰工程'!$B$4:$I$231,8,0) -> 11.95 | J34: =VLOOKUP(B34,'[1]2.1装饰工程'!$B$4:$J$231,9,0) -> 0 | K34: =VLOOKUP(B34,'[1]2.1装饰工程'!$B$4:$K$231,10,0) -> 0 | L34: =$L$4 -> 0.207 | M34: =F34*G34 -> 0
A35: 3 | B35: 水泥自流平基层厚度每增减1mm | C35: 1.水泥自流平厚度每增减1mm 2.其他详见SI手册、品牌表及标准节点等，满足施工要求及国家规范 | D35: 工程量按设计图示尺寸以面积计算 | E35: m2 | G35: =(H35+I35+J35+K35)*(1+L35) -> 8.12311 | H35: =VLOOKUP(B35,'[1]2.1装饰工程'!$B$4:$H$231,7,0) -> 3.54 | I35: =VLOOKUP(B35,'[1]2.1装饰工程'!$B$4:$I$231,8,0) -> 3.19 | J35: =VLOOKUP(B35,'[1]2.1装饰工程'!$B$4:$J$231,9,0) -> 0 | K35: =VLOOKUP(B35,'[1]2.1装饰工程'!$B$4:$K$231,10,0) -> 0 | L35: =$L$4 -> 0.207 | M35: =F35*G35 -> 0
A36: 4 | B36: 20mm地面水泥砂浆 | C36: 1.20厚水泥砂浆 2.其他详见SI手册、品牌表及标准节点等，满足施工要求及国家规范 | D36: 工程量按设计图示尺寸以面积计算 | E36: m2 | F36: 60 | G36: =(H36+I36+J36+K36)*(1+L36) -> 33.45804 | H36: =VLOOKUP(B36,'[1]2.1装饰工程'!$B$4:$H$231,7,0) -> 11.6 | I36: =VLOOKUP(B36,'[1]2.1装饰工程'!$B$4:$I$231,8,0) -> 16.12 | J36: =VLOOKUP(B36,'[1]2.1装饰工程'!$B$4:$J$231,9,0) -> 0 | K36: =VLOOKUP(B36,'[1]2.1装饰工程'!$B$4:$K$231,10,0) -> 0 | L36: =$L$4 -> 0.207 | M36: =F36*G36 -> 2007.4824
A37: 5 | B37: 地面水泥砂浆厚度每增减10mm | C37: 1.地面水泥砂浆厚度每增减10mm 2.其他详见SI手册、品牌表及标准节点等，满足施工要求及国家规范 | D37: 工程量按设计图示尺寸以面积计算 | E37: m2 | F37: 60 | G37: =(H37+I37+J37+K37)*(1+L37) -> 11.49064 | H37: =VLOOKUP(B37,'[1]2.1装饰工程'!$B$4:$H$231,7,0) -> 3.66 | I37: =VLOOKUP(B37,'[1]2.1装饰工程'!$B$4:$I$231,8,0) -> 5.86 | J37: =VLOOKUP(B37,'[1]2.1装饰工程'!$B$4:$J$231,9,0) -> 0 | K37: =VLOOKUP(B37,'[1]2.1装饰工程'!$B$4:$K$231,10,0) -> 0 | L37: =$L$4 -> 0.207 | M37: =F37*G37 -> 689.4384
A38: 6 | B38: 20mm厚C15细石混凝土找平 | C38: 1.20厚15细石混凝土找平+素水泥浆一道 2.包含止水坎综合考虑，其他详见SI手册、品牌表及标准节点等，满足施工要求及国家规范 | D38: 工程量按设计图示尺寸以面积计算，有厚度变化进行则算 | E38: m2 | G38: =(H38+I38+J38+K38)*(1+L38) -> 41.891349 | H38: =1.15*7.62 -> 8.763 | I38: =1.15*22.5 -> 25.875 | K38: =1.15*0.06 -> 0.069 | L38: =$L$4 -> 0.207 | M38: =F38*G38 -> 0
A39: 7 | B39: 20mm厚C25细石混凝土找平 | C39: 1.20厚C25细石混凝土找平+素水泥浆一道 2.包含止水坎综合考虑，其他详见SI手册、品牌表及标准节点等，满足施工要求及国家规范 | D39: 工程量按设计图示尺寸以面积计算，有厚度变化进行则算 | E39: m2 | F39: 60 | G39: =(H39+I39+J39+K39)*(1+L39) -> 45.541921 | H39: =1.15*7.62 -> 8.763 | I39: =1.15*25.13 -> 28.8995 | K39: =1.15*0.06 -> 0.069 | L39: =$L$4 -> 0.207 | M39: =F39*G39 -> 2732.5152
A40: 8 | B40: 20mm厚C30细石混凝土找平 | C40: 1.20厚C30细石混凝土找平+素水泥浆一道 2.包含止水坎综合考虑，其他详见SI手册、品牌表及标准节点等，满足施工要求及国家规范 | D40: 工程量按设计图示尺寸以面积计算，有厚度变化进行则算 | E40: m2 | G40: =(H40+I40+J40+K40)*(1+L40) -> 47.027134 | H40: =1.15*7.62 -> 8.763 | I40: =1.15*26.2 -> 30.13 | K40: =1.15*0.06 -> 0.069 | L40: =$L$4 -> 0.207 | M40: =F40*G40 -> 0
...

Sheet 2.2强电工程
A1: 长城智选商超店装修项目装饰工程
A2: 序号 | B2: 分部分项名称 | C2: 项目特征 | D2: 计量规则 | E2: 单位 | F2: 工程量 | G2: 综合单价 | H2: 人工 | I2: 主材 | J2: 辅材 | K2: 机械 | L2: 其他综合费率 | M2: 合计 | N2: 备注
A3: 一 | B3: 配电系统
A4: 1 | B4: 落地式配电箱 | C4: 1.名称:落地式配电箱 2.基础形式、材质、规格:10#基础槽钢 3.接线端子材质、规格:按设计及规范要求 4.端子板外部接线材质、规格:按设计及规范要求 5.安装方式:落地式 6.其他:含智能电表、时控开关、电气元器件及配套附件成套费用 | D4: 按设计图示数量计算 | E4: 台 | F4: 1 | G4: =(H4+I4+J4+K4)*(1+L4) -> 11126.126 | H4: =VLOOKUP(B4,'[1]2.2强电工程'!$B$4:$H$254,7,0) -> 524.73 | I4: =VLOOKUP(B4,'[1]2.2强电工程'!$B$4:$I$254,8,0) -> 8637.4 | J4: =VLOOKUP(B4,'[1]2.2强电工程'!$B$4:$J$254,9,0) -> 36.96 | K4: =VLOOKUP(B4,'[1]2.2强电工程'!$B$4:$K$254,10,0) -> 18.91 | L4: ='2.1装饰工程'!$L$4 -> 0.207 | M4: =F4*G4 -> 11126.126
A5: 2 | B5: 落地式配电箱（IP65防水型） | C5: 1.名称:落地式配电箱（IP65防水型） 2.基础形式、材质、规格:10#基础槽钢 3.接线端子材质、规格:按设计及规范要求 4.端子板外部接线材质、规格:按设计及规范要求 5.安装方式:落地式 6.其他:含智能电表、时控开关、电气元器件及配套附件成套费用 | D5: 按设计图示数量计算 | E5: 台 | G5: =(H5+I5+J5+K5)*(1+L5) -> 11446.572 | H5: =VLOOKUP(B5,'[1]2.2强电工程'!$B$4:$H$254,7,0) -> 524.73 | I5: =VLOOKUP(B5,'[1]2.2强电工程'!$B$4:$I$254,8,0) -> 8902.89 | J5: =VLOOKUP(B5,'[1]2.2强电工程'!$B$4:$J$254,9,0) -> 36.96 | K5: =VLOOKUP(B5,'[1]2.2强电工程'!$B$4:$K$254,10,0) -> 18.91 | L5: =$L$4 -> 0.207 | M5: =F5*G5 -> 0
A6: 3 | B6: 配电箱 | C6: 1.名称:配电箱（嵌入/悬挂） 2.规格:半周长2.5m 3.接线端子材质、规格:按设计及规范要求 4.端子板外部接线材质、规格:按设计及规范要求 5.安装方式:悬挂式 6.其他:含智能电表、时控开关、电气元器件及配套附件成套费用 | D6: 按设计图示数量计算 | E6: 台 | G6: =(H6+I6+J6+K6)*(1+L6) -> 7821.9876 | H6: 448.4 | I6: 6007.08 | J6: 21.43 | K6: 3.61 | L6: =$L$4 -> 0.207 | M6: =F6*G6 -> 0
A7: 4 | B7: 配电箱 | C7: 1.名称:配电箱（嵌入/悬挂） 2.规格:半周长1.5m 3.接线端子材质、规格:按设计及规范要求 4.端子板外部接线材质、规格:按设计及规范要求 5.安装方式:悬挂式 6.其他:含智能电表、时控开关、电气元器件及配套附件成套费用 | D7: 按设计图示数量计算 | E7: 台 | F7: 1 | G7: =(H7+I7+J7+K7)*(1+L7) -> 4871.5003 | H7: 373.78 | I7: 3640.71 | J7: 17.94 | K7: 3.61 | L7: =$L$4 -> 0.207 | M7: =F7*G7 -> 4871.5003
A8: 5 | B8: 配电箱 | C8: 1.名称:配电箱（嵌入/悬挂） 2.规格:半周长1.0m 3.接线端子材质、规格:按设计及规范要求 4.端子板外部接线材质、规格:按设计及规范要求 5.安装方式:悬挂式 6.其他:含智能电表、时控开关、电气元器件及配套附件成套费用 | D8: 按设计图示数量计算 | E8: 台 | G8: =(H8+I8+J8+K8)*(1+L8) -> 3437.7653 | H8: 298 | I8: 2529.2 | J8: 17.38 | K8: 3.61 | L8: =$L$4 -> 0.207 | M8: =F8*G8 -> 0
A9: 6 | B9: 配电箱 | C9: 1.名称:配电箱（嵌入/悬挂） 2.规格:半周长0.5m 3.接线端子材质、规格:按设计及规范要求 4.端子板外部接线材质、规格:按设计及规范要求 5.安装方式:悬挂式 6.其他:含智能电表、时控开关、电气元器件及配套附件成套费用 | D9: 按设计图示数量计算 | E9: 台 | G9: =(H9+I9+J9+K9)*(1+L9) -> 1670.6811 | H9: 250.27 | I9: 1113.27 | J9: 17.01 | K9: 3.61 | L9: =$L$4 -> 0.207 | M9: =F9*G9 -> 0
A10: 7 | B10: 应急照明配电箱 | C10: 1.名称:应急照明配电箱 2.接线端子材质、规格:按设计及规范要求 3.端子板外部接线材质、规格:按设计及规范要求 4.其他:含元器件及配套附件成套费用 | D10: 按设计图示数量计算 | E10: 台 | G10: =(H10+I10+J10+K10)*(1+L10) -> 3651.0302 | H10: =VLOOKUP(B10,'[1]2.2强电工程'!$B$4:$H$254,7,0) -> 464.21 | I10: =VLOOKUP(B10,'[1]2.2强电工程'!$B$4:$I$254,8,0) -> 2500.65 | J10: =VLOOKUP(B10,'[1]2.2强电工程'!$B$4:$J$254,9,0) -> 41.11 | K10: =VLOOKUP(B10,'[1]2.2强电工程'!$B$4:$K$254,10,0) -> 18.91 | L10: =$L$4 -> 0.207 | M10: =F10*G10 -> 0
A11: 8 | B11: 电缆WDZB-YJV-3*240+2*120 | C11: 1.名称:电力电缆 2.型号:WDZB-YJV 3.规格:3*240+2*120 4.材质:铜芯 5.敷设方式、部位:桥架内及配管内敷设 6.电压等级(kV):1.0KV | D11: 按设计图示尺寸以长度计算（含预留长度及附加长度） | E11: m | G11: =(H11+I11+J11+K11)*(1+L11) -> 1089.6192 | H11: =VLOOKUP(B11,'[1]2.2强电工程'!$B$4:$H$254,7,0) -> 28.73 | I11: =VLOOKUP(B11,'[1]2.2强电工程'!$B$4:$I$254,8,0) -> 869.71 | J11: =VLOOKUP(B11,'[1]2.2强电工程'!$B$4:$J$254,9,0) -> 1.99 | K11: =VLOOKUP(B11,'[1]2.2强电工程'!$B$4:$K$254,10,0) -> 2.32 | L11: =$L$4 -> 0.207 | M11: =F11*G11 -> 0
A12: 9 | B12: 电缆WDZB-YJV-3*185+2*95 | C12: 1.名称:电力电缆 2.型号:WDZB-YJV 3.规格:3*185+2*95 4.材质:铜芯 5.敷设方式、部位:桥架内及配管内敷设 6.电压等级(kV):1.0KV | D12: 按设计图示尺寸以长度计算（含预留长度及附加长度） | E12: m | G12: =(H12+I12+J12+K12)*(1+L12) -> 784.4293 | H12: =VLOOKUP(B12,'[1]2.2强电工程'!$B$4:$H$254,7,0) -> 28.73 | I12: =VLOOKUP(B12,'[1]2.2强电工程'!$B$4:$I$254,8,0) -> 616.86 | J12: =VLOOKUP(B12,'[1]2.2强电工程'!$B$4:$J$254,9,0) -> 1.99 | K12: =VLOOKUP(B12,'[1]2.2强电工程'!$B$4:$K$254,10,0) -> 2.32 | L12: =$L$4 -> 0.207 | M12: =F12*G12 -> 0
A13: 10 | B13: 电缆WDZB-YJV-3*150+2*70 | C13: 1.名称:电力电缆 2.型号:WDZB-YJV 3.规格:3*150+2*70 4.材质:铜芯 5.敷设方式、部位:桥架内及配管内敷设 6.电压等级(kV):1.0KV | D13: 按设计图示尺寸以长度计算（含预留长度及附加长度） | E13: m | G13: =(H13+I13+J13+K13)*(1+L13) -> 720.39795 | H13: =VLOOKUP(B13,'[1]2.2强电工程'!$B$4:$H$254,7,0) -> 28.73 | I13: =VLOOKUP(B13,'[1]2.2强电工程'!$B$4:$I$254,8,0) -> 563.81 | J13: =VLOOKUP(B13,'[1]2.2强电工程'!$B$4:$J$254,9,0) -> 1.99 | K13: =VLOOKUP(B13,'[1]2.2强电工程'!$B$4:$K$254,10,0) -> 2.32 | L13: =$L$4 -> 0.207 | M13: =F13*G13 -> 0
A14: 11 | B14: 电缆WDZB-YJV-3*120+2*70 | C14: 1.名称:电力电缆 2.型号:WDZB-YJV 3.规格:3*120+2*70 4.材质:铜芯 5.敷设方式、部位:桥架内及配管内敷设 6.电压等级(kV):1.0KV | D14: 按设计图示尺寸以长度计算（含预留长度及附加长度） | E14: m | G14: =(H14+I14+J14+K14)*(1+L14) -> 566.84341 | H14: =VLOOKUP(B14,'[1]2.2强电工程'!$B$4:$H$254,7,0) -> 20.72 | I14: =VLOOKUP(B14,'[1]2.2强电工程'!$B$4:$I$254,8,0) -> 446.52 | J14: =VLOOKUP(B14,'[1]2.2强电工程'!$B$4:$J$254,9,0) -> 1.25 | K14: =VLOOKUP(B14,'[1]2.2强电工程'!$B$4:$K$254,10,0) -> 1.14 | L14: =$L$4 -> 0.207 | M14: =F14*G14 -> 0
A15: 12 | B15: 电缆WDZB-YJV-3*95+2*50 | C15: 1.名称:电力电缆 2.型号:WDZB-YJV 3.规格:3*95+2*50 4.材质:铜芯 5.敷设方式、部位:桥架内及配管内敷设 6.电压等级(kV):1.0KV | D15: 按设计图示尺寸以长度计算（含预留长度及附加长度） | E15: m | G15: =(H15+I15+J15+K15)*(1+L15) -> 385.17784 | H15: =VLOOKUP(B15,'[1]2.2强电工程'!$B$4:$H$254,7,0) -> 20.72 | I15: =VLOOKUP(B15,'[1]2.2强电工程'!$B$4:$I$254,8,0) -> 296.01 | J15: =VLOOKUP(B15,'[1]2.2强电工程'!$B$4:$J$254,9,0) -> 1.25 | K15: =VLOOKUP(B15,'[1]2.2强电工程'!$B$4:$K$254,10,0) -> 1.14 | L15: =$L$4 -> 0.207 | M15: =F15*G15 -> 0
A16: 13 | B16: 电缆WDZB-YJV-3*70+2*35 | C16: 1.名称:电力电缆 2.型号:WDZB-YJV 3.规格:3*70+2*35 4.材质:铜芯 5.敷设方式、部位:桥架内及配管内敷设 6.电压等级(kV):1.0KV | D16: 按设计图示尺寸以长度计算（含预留长度及附加长度） | E16: m | G16: =(H16+I16+J16+K16)*(1+L16) -> 317.83931 | H16: =VLOOKUP(B16,'[1]2.2强电工程'!$B$4:$H$254,7,0) -> 17.42 | I16: =VLOOKUP(B16,'[1]2.2强电工程'!$B$4:$I$254,8,0) -> 243.76 | J16: =VLOOKUP(B16,'[1]2.2强电工程'!$B$4:$J$254,9,0) -> 1.01 | K16: =VLOOKUP(B16,'[1]2.2强电工程'!$B$4:$K$254,10,0) -> 1.14 | L16: =$L$4 -> 0.207 | M16: =F16*G16 -> 0
A17: 14 | B17: 电缆WDZB-YJV-3*50+2*25 | C17: 1.名称:电力电缆 2.型号:WDZB-YJV 3.规格:3*50+2*25 4.材质:铜芯 5.敷设方式、部位:桥架内及配管内敷设 6.电压等级(kV):1.0KV | D17: 按设计图示尺寸以长度计算（含预留长度及附加长度） | E17: m | G17: =(H17+I17+J17+K17)*(1+L17) -> 236.87375 | H17: =VLOOKUP(B17,'[1]2.2强电工程'!$B$4:$H$254,7,0) -> 17.42 | I17: =VLOOKUP(B17,'[1]2.2强电工程'!$B$4:$I$254,8,0) -> 176.68 | J17: =VLOOKUP(B17,'[1]2.2强电工程'!$B$4:$J$254,9,0) -> 1.01 | K17: =VLOOKUP(B17,'[1]2.2强电工程'!$B$4:$K$254,10,0) -> 1.14 | L17: =$L$4 -> 0.207 | M17: =F17*G17 -> 0
A18: 15 | B18: 电缆WDZB-YJV-3*35+2*16 | C18: 1.名称:电力电缆 2.型号:WDZB-YJV 3.规格:3*35+2*16 4.材质:铜芯 5.敷设方式、部位:桥架内及配管内敷设 6.电压等级(kV):1.0KV | D18: 按设计图示尺寸以长度计算（含预留长度及附加长度） | E18: m | G18: =(H18+I18+J18+K18)*(1+L18) -> 181.8949 | H18: =VLOOKUP(B18,'[1]2.2强电工程'!$B$4:$H$254,7,0) -> 11.07 | I18: =VLOOKUP(B18,'[1]2.2强电工程'!$B$4:$I$254,8,0) -> 138.36 | J18: =VLOOKUP(B18,'[1]2.2强电工程'!$B$4:$J$254,9,0) -> 1.11 | K18: =VLOOKUP(B18,'[1]2.2强电工程'!$B$4:$K$254,10,0) -> 0.16 | L18: =$L$4 -> 0.207 | M18: =F18*G18 -> 0
A19: 16 | B19: 电缆WDZB-YJV-3*25+2*16 | C19: 1.名称:电力电缆 2.型号:WDZB-YJV 3.规格:3*25+2*16 4.材质:铜芯 5.敷设方式、部位:桥架内及配管内敷设 6.电压等级(kV):1.0KV | D19: 按设计图示尺寸以长度计算（含预留长度及附加长度） | E19: m | G19: =(H19+I19+J19+K19)*(1+L19) -> 134.47187 | H19: =VLOOKUP(B19,'[1]2.2强电工程'!$B$4:$H$254,7,0) -> 11.07 | I19: =VLOOKUP(B19,'[1]2.2强电工程'!$B$4:$I$254,8,0) -> 99.07 | J19: =VLOOKUP(B19,'[1]2.2强电工程'!$B$4:$J$254,9,0) -> 1.11 | K19: =VLOOKUP(B19,'[1]2.2强电工程'!$B$4:$K$254,10,0) -> 0.16 | L19: =$L$4 -> 0.207 | M19: =F19*G19 -> 0
A20: 17 | B20: 电缆WDZB-YJV-4*185+1*95 | C20: 1.名称:电力电缆 2.型号:WDZB-YJV 3.规格:4*185+1*95 4.材质:铜芯 5.敷设方式、部位:桥架内及配管内敷设 6.电压等级(kV):1.0KV | D20: 按设计图示尺寸以长度计算（含预留长度及附加长度） | E20: m | G20: =(H20+I20+J20+K20)*(1+L20) -> 883.12569 | H20: =VLOOKUP(B20,'[1]2.2强电工程'!$B$4:$H$254,7,0) -> 28.73 | I20: =VLOOKUP(B20,'[1]2.2强电工程'!$B$4:$I$254,8,0) -> 698.63 | J20: =VLOOKUP(B20,'[1]2.2强电工程'!$B$4:$J$254,9,0) -> 1.99 | K20: =VLOOKUP(B20,'[1]2.2强电工程'!$B$4:$K$254,10,0) -> 2.32 | L20: =$L$4 -> 0.207 | M20: =F20*G20 -> 0
A21: 18 | B21: 电缆WDZB-YJV-4*150+1*70 | C21: 1.名称:电力电缆 2.型号:WDZB-YJV 3.规格:4*150+1*70 4.材质:铜芯 5.敷设方式、部位:桥架内及配管内敷设 6.电压等级(kV):1.0KV | D21: 按设计图示尺寸以长度计算（含预留长度及附加长度） | E21: m | G21: =(H21+I21+J21+K21)*(1+L21) -> 761.89461 | H21: =VLOOKUP(B21,'[1]2.2强电工程'!$B$4:$H$254,7,0) -> 28.73 | I21: =VLOOKUP(B21,'[1]2.2强电工程'!$B$4:$I$254,8,0) -> 598.19 | J21: =VLOOKUP(B21,'[1]2.2强电工程'!$B$4:$J$254,9,0) -> 1.99 | K21: =VLOOKUP(B21,'[1]2.2强电工程'!$B$4:$K$254,10,0) -> 2.32 | L21: =$L$4 -> 0.207 | M21: =F21*G21 -> 0
... A29: 26 | B29: 电缆WDZB-YJV-5*10 | C29: 1.名称:电力电缆 2.型号:WDZB-YJV 3.规格:5*10 4.材质:铜芯 5.敷设方式、部位:桥架内及配管内敷设 6.电压等级(kV):1.0KV | D29: 按设计图示尺寸以长度计算（含预留长度及附加长度） | E29: m | G29: =(H29+I29+J29+K29)*(1+L29) -> 68.36448 | H29: =VLOOKUP(B29,'[1]2.2强电工程'!$B$4:$H$254,7,0) -> 6.12 | I29: =VLOOKUP(B29,'[1]2.2强电工程'!$B$4:$I$254,8,0) -> 49.52 | J29: =VLOOKUP(B29,'[1]2.2强电工程'!$B$4:$J$254,9,0) -> 1 | K29: =VLOOKUP(B29,'[1]2.2强电工程'!$B$4:$K$254,10,0) -> 0 | L29: =$L$4 -> 0.207 | M29: =F29*G29 -> 0
A30: 27 | B30: 电缆WDZB-YJV-5*6 | C30: 1.名称:电力电缆 2.型号:WDZB-YJV 3.规格:5*6 4.材质:铜芯 5.敷设方式、部位:桥架内及配管内敷设 6.电压等级(kV):1.0KV | D30: 按设计图示尺寸以长度计算（含预留长度及附加长度） | E30: m | G30: =(H30+I30+J30+K30)*(1+L30) -> 98.899166 | H30: =VLOOKUP(B30,'[1]2.2强电工程'!$B$4:$H$254,7,0) -> 11.07 | I30: 69.598 | J30: =VLOOKUP(B30,'[1]2.2强电工程'!$B$4:$J$254,9,0) -> 1.11 | K30: =VLOOKUP(B30,'[1]2.2强电工程'!$B$4:$K$254,10,0) -> 0.16 | L30: =$L$4 -> 0.207 | M30: =F30*G30 -> 0
A31: 28 | B31: 电缆WDZB-YJV-5*4 | C31: 1.名称:电力电缆 2.型号:WDZB-YJV 3.规格:5*4 4.材质:铜芯 5.敷设方式、部位:桥架内及配管内敷设 6.电压等级(kV):1.0KV | D31: 按设计图示尺寸以长度计算（含预留长度及附加长度） | E31: m | G31: =(H31+I31+J31+K31)*(1+L31) -> 35.66685 | H31: =VLOOKUP(B31,'[1]2.2强电工程'!$B$4:$H$254,7,0) -> 4.57 | I31: =VLOOKUP(B31,'[1]2.2强电工程'!$B$4:$I$254,8,0) -> 23.9 | J31: =VLOOKUP(B31,'[1]2.2强电工程'!$B$4:$J$254,9,0) -> 1.08 | K31: =VLOOKUP(B31,'[1]2.2强电工程'!$B$4:$K$254,10,0) -> 0 | L31: =$L$4 -> 0.207 | M31: =F31*G31 -> 0
A32: 29 | B32: 电缆WDZB-YJV-3*6 | C32: 1.名称:电力电缆 2.型号:WDZB-YJV 3.规格:3*6 4.材质:铜芯 5.敷设方式、部位:桥架内及配管内敷设 6.电压等级(kV):1.0KV | D32: 按设计图示尺寸以长度计算（含预留长度及附加长度） | E32: m | G32: =(H32+I32+J32+K32)*(1+L32) -> 66.25223 | H32: =VLOOKUP(B32,'[1]2.2强电工程'!$B$4:$H$254,7,0) -> 11.07 | I32: 42.55 | J32: =VLOOKUP(B32,'[1]2.2强电工程'!$B$4:$J$254,9,0) -> 1.11 | K32: =VLOOKUP(B32,'[1]2.2强电工程'!$B$4:$K$254,10,0) -> 0.16 | L32: =$L$4 -> 0.207 | M32: =F32*G32 -> 0
A33: 30 | B33: 电缆WDZB-YJV-3*10 | C33: 1.名称:电力电缆 2.型号:WDZB-YJV 3.规格:3*10 4.材质:铜芯 5.敷设方式、部位:桥架内及配管内敷设 6.电压等级(kV):1.0KV | D33: 按设计图示尺寸以长度计算（含预留长度及附加长度） | E33: m | G33: =(H33+I33+J33+K33)*(1+L33) -> 47.915486 | H33: =1.15*4.6 -> 5.29 | I33: =1.15*29.47 -> 33.8905 | J33: =1.15*0.13 -> 0.1495 | K33: =1.15*0.32 -> 0.368 | L33: =$L$4 -> 0.207 | M33: =F33*G33 -> 0
A34: 31 | B34: 电缆ZR-YJV-3*240+2*120 | C34: 1.名称:电力电缆 2.型号:ZR-YJV 3.规格:3*240+2*120 4.材质:铜芯 5.敷设方式、部位:桥架内及配管内敷设 6.电压等级(kV):1.0KV | D34: 按设计图示尺寸以长度计算（含预留长度及附加长度） | E34: m | G34: =(H34+I34+J34+K34)*(1+L34) -> 967.98986 | H34: =VLOOKUP(B34,'[1]2.2强电工程'!$B$4:$H$254,7,0) -> 28.73 | I34: =VLOOKUP(B34,'[1]2.2强电工程'!$B$4:$I$254,8,0) -> 768.94 | J34: =VLOOKUP(B34,'[1]2.2强电工程'!$B$4:$J$254,9,0) -> 1.99 | K34: =VLOOKUP(B34,'[1]2.2强电工程'!$B$4:$K$254,10,0) -> 2.32 | L34: =$L$4 -> 0.207 | M34: =F34*G34 -> 0
A35: 32 | B35: 电缆ZR-YJV-3*185+2*95 | C35: 1.名称:电力电缆 2.型号:ZR-YJV 3.规格:3*185+2*95 4.材质:铜芯 5.敷设方式、部位:桥架内及配管内敷设 6.电压等级(kV):1.0KV | D35: 按设计图示尺寸以长度计算（含预留长度及附加长度） | E35: m | G35: =(H35+I35+J35+K35)*(1+L35) -> 785.91391 | H35: =VLOOKUP(B35,'[1]2.2强电工程'!$B$4:$H$254,7,0) -> 28.73 | I35: =VLOOKUP(B35,'[1]2.2强电工程'!$B$4:$I$254,8,0) -> 618.09 | J35: =VLOOKUP(B35,'[1]2.2强电工程'!$B$4:$J$254,9,0) -> 1.99 | K35: =VLOOKUP(B35,'[1]2.2强电工程'!$B$4:$K$254,10,0) -> 2.32 | L35: =$L$4 -> 0.207 | M35: =F35*G35 -> 0
A36: 33 | B36: 电缆ZR-YJV-3*150+2*70 | C36: 1.名称:电力电缆 2.型号:ZR-YJV 3.规格:3*150+2*70 4.材质:铜芯 5.敷设方式、部位:桥架内及配管内敷设 6.电压等级(kV):1.0KV | D36: 按设计图示尺寸以长度计算（含预留长度及附加长度） | E36: m | G36: =(H36+I36+J36+K36)*(1+L36) -> 648.89527 | H36: =VLOOKUP(B36,'[1]2.2强电工程'!$B$4:$H$254,7,0) -> 28.73 | I36: =VLOOKUP(B36,'[1]2.2强电工程'!$B$4:$I$254,8,0) -> 504.57 | J36: =VLOOKUP(B36,'[1]2.2强电工程'!$B$4:$J$254,9,0) -> 1.99 | K36: =VLOOKUP(B36,'[1]2.2强电工程'!$B$4:$K$254,10,0) -> 2.32 | L36: =$L$4 -> 0.207 | M36: =F36*G36 -> 0
A37: 34 | B37: 电缆ZR-YJV-3*120+2*70 | C37: 1.名称:电力电缆 2.型号:ZR-YJV 3.规格:3*120+2*70 4.材质:铜芯 5.敷设方式、部位:桥架内及配管内敷设 6.电压等级(kV):1.0KV | D37: 按设计图示尺寸以长度计算（含预留长度及附加长度） | E37: m | G37: =(H37+I37+J37+K37)*(1+L37) -> 567.60382 | H37: =VLOOKUP(B37,'[1]2.2强电工程'!$B$4:$H$254,7,0) -> 20.72 | I37: =VLOOKUP(B37,'[1]2.2强电工程'!$B$4:$I$254,8,0) -> 447.15 | J37: =VLOOKUP(B37,'[1]2.2强电工程'!$B$4:$J$254,9,0) -> 1.25 | K37: =VLOOKUP(B37,'[1]2.2强电工程'!$B$4:$K$254,10,0) -> 1.14 | L37: =$L$4 -> 0.207 | M37: =F37*G37 -> 0
A38: 35 | B38: 电缆ZR-YJV-3*95+2*50 | C38: 1.名称:电力电缆 2.型号:ZR-YJV 3.规格:3*95+2*50 4.材质:铜芯 5.敷设方式、部位:桥架内及配管内敷设 6.电压等级(kV):1.0KV | D38: 按设计图示尺寸以长度计算（含预留长度及附加长度） | E38: m | G38: =(H38+I38+J38+K38)*(1+L38) -> 422.34137 | H38: =VLOOKUP(B38,'[1]2.2强电工程'!$B$4:$H$254,7,0) -> 20.72 | I38: =VLOOKUP(B38,'[1]2.2强电工程'!$B$4:$I$254,8,0) -> 326.8 | J38: =VLOOKUP(B38,'[1]2.2强电工程'!$B$4:$J$254,9,0) -> 1.25 | K38: =VLOOKUP(B38,'[1]2.2强电工程'!$B$4:$K$254,10,0) -> 1.14 | L38: =$L$4 -> 0.207 | M38: =F38*G38 -> 0
A39: 36 | B39: 电缆ZR-YJV-3*70+2*35 | C39: 1.名称:电力电缆 2.型号:ZR-YJV 3.规格:3*70+2*35 4.材质:铜芯 5.敷设方式、部位:桥架内及配管内敷设 6.电压等级(kV):1.0KV | D39: 按设计图示尺寸以长度计算（含预留长度及附加长度） | E39: m | G39: =(H39+I39+J39+K39)*(1+L39) -> 293.61482 | H39: =VLOOKUP(B39,'[1]2.2强电工程'!$B$4:$H$254,7,0) -> 17.42 | I39: =VLOOKUP(B39,'[1]2.2强电工程'!$B$4:$I$254,8,0) -> 223.69 | J39: =VLOOKUP(B39,'[1]2.2强电工程'!$B$4:$J$254,9,0) -> 1.01 | K39: =VLOOKUP(B39,'[1]2.2强电工程'!$B$4:$K$254,10,0) -> 1.14 | L39: =$L$4 -> 0.207 | M39: =F39*G39 -> 0
A40: 37 | B40: 电缆ZR-YJV-3*50+2*25 | C40: 1.名称:电力电缆 2.型号:ZR-YJV 3.规格:3*50+2*25 4.材质:铜芯 5.敷设方式、部位:桥架内及配管内敷设 6.电压等级(kV):1.0KV | D40: 按设计图示尺寸以长度计算（含预留长度及附加长度） | E40: m | G40: =(H40+I40+J40+K40)*(1+L40) -> 212.34751 | H40: =VLOOKUP(B40,'[1]2.2强电工程'!$B$4:$H$254,7,0) -> 17.42 | I40: =VLOOKUP(B40,'[1]2.2强电工程'!$B$4:$I$254,8,0) -> 156.36 | J40: =VLOOKUP(B40,'[1]2.2强电工程'!$B$4:$J$254,9,0) -> 1.01 | K40: =VLOOKUP(B40,'[1]2.2强电工程'!$B$4:$K$254,10,0) -> 1.14 | L40: =$L$4 -> 0.207 | M40: =F40*G40 -> 0
A41: 38 | B41: 电缆ZR-YJV-3*35+2*16 | C41: 1.名称:电力电缆 2.型号:ZR-YJV 3.规格:3*35+2*16 4.材质:铜芯 5.敷设方式、部位:桥架内及配管内敷设 6.电压等级(kV):1.0KV | D41: 按设计图示尺寸以长度计算（含预留长度及附加长度） | E41: m | G41: =(H41+I41+J41+K41)*(1+L41) -> 169.07656 | H41: =VLOOKUP(B41,'[1]2.2强电工程'!$B$4:$H$254,7,0) -> 11.07 | I41: =VLOOKUP(B41,'[1]2.2强电工程'!$B$4:$I$254,8,0) -> 127.74 | J41: =VLOOKUP(B41,'[1]2.2强电工程'!$B$4:$J$254,9,0) -> 1.11 | K41: =VLOOKUP(B41,'[1]2.2强电工程'!$B$4:$K$254,10,0) -> 0.16 | L41: =$L$4 -> 0.207 | M41: =F41*G41 -> 0
A42: 39 | B42: 电缆ZR-YJV-3*25+2*16 | C42: 1.名称:电力电缆 2.型号:ZR-YJV 3.规格:3*25+2*16 4.材质:铜芯 5.敷设方式、部位:桥架内及配管内敷设 6.电压等级(kV):1.0KV | D42: 按设计图示尺寸以长度计算（含预留长度及附加长度） | E42: m | G42: =(H42+I42+J42+K42)*(1+L42) -> 109.31799 | H42: =VLOOKUP(B42,'[1]2.2强电工程'!$B$4:$H$254,7,0) -> 11.07 | I42: =VLOOKUP(B42,'[1]2.2强电工程'!$B$4:$I$254,8,0) -> 78.23 | J42: =VLOOKUP(B42,'[1]2.2强电工程'!$B$4:$J$254,9,0) -> 1.11 | K42: =VLOOKUP(B42,'[1]2.2强电工程'!$B$4:$K$254,10,0) -> 0.16 | L42: =$L$4 -> 0.207 | M42: =F42*G42 -> 0
A43: 40 | B43: 电缆ZR-YJV-4*240+1*120 | C43: 1.名称:电力电缆 2.型号:ZR-YJV 3.规格:4*240+1*120 4.材质:铜芯 5.敷设方式、部位:桥架内及配管内敷设 6.电压等级(kV):1.0KV | D43: 按设计图示尺寸以长度计算（含预留长度及附加长度） | E43: m | G43: =(H43+I43+J43+K43)*(1+L43) -> 947.89331 | H43: =VLOOKUP(B43,'[1]2.2强电工程'!$B$4:$H$254,7,0) -> 28.73 | I43: =VLOOKUP(B43,'[1]2.2强电工程'!$B$4:$I$254,8,0) -> 752.29 | J43: =VLOOKUP(B43,'[1]2.2强电工程'!$B$4:$J$254,9,0) -> 1.99 | K43: =VLOOKUP(B43,'[1]2.2强电工程'!$B$4:$K$254,10,0) -> 2.32 | L43: =$L$4 -> 0.207 | M43: =F43*G43 -> 0
A44: 41 | B44: 电缆ZR-YJV-4*185+1*95 | C44: 1.名称:电力电缆 2.型号:ZR-YJV 3.规格:4*185+1*95 4.材质:铜芯 5.敷设方式、部位:桥架内及配管内敷设 6.电压等级(kV):1.0KV | D44: 按设计图示尺寸以长度计算（含预留长度及附加长度） | E44: m | G44: =(H44+I44+J44+K44)*(1+L44) -> 739.83065 | H44: =VLOOKUP(B44,'[1]2.2强电工程'!$B$4:$H$254,7,0) -> 28.73 | I44: =VLOOKUP(B44,'[1]2.2强电工程'!$B$4:$I$254,8,0) -> 579.91 | J44: =VLOOKUP(B44,'[1]2.2强电工程'!$B$4:$J$254,9,0) -> 1.99 | K44: =VLOOKUP(B44,'[1]2.2强电工程'!$B$4:$K$254,10,0) -> 2.32 | L44: =$L$4 -> 0.207 | M44: =F44*G44 -> 0
A45: 42 | B45: 电缆ZR-YJV-4*150+1*70 | C45: 1.名称:电力电缆 2.型号:ZR-YJV 3.规格:4*150+1*70 4.材质:铜芯 5.敷设方式、部位:桥架内及配管内敷设 6.电压等级(kV):1.0KV | D45: 按设计图示尺寸以长度计算（含预留长度及附加长度） | E45: m | G45: =(H45+I45+J45+K45)*(1+L45) -> 594.2061 | H45: =VLOOKUP(B45,'[1]2.2强电工程'!$B$4:$H$254,7,0) -> 28.73 | I45: =VLOOKUP(B45,'[1]2.2强电工程'!$B$4:$I$254,8,0) -> 459.26 | J45: =VLOOKUP(B45,'[1]2.2强电工程'!$B$4:$J$254,9,0) -> 1.99 | K45: =VLOOKUP(B45,'[1]2.2强电工程'!$B$4:$K$254,10,0) -> 2.32 | L45: =$L$4 -> 0.207 | M45: =F45*G45 -> 0
... A51: 48 | B51: 电缆ZR-YJV-4*25+1*16 | C51: 1.名称:电力电缆 2.型号:ZR-YJV 3.规格:4*25+1*16 4.材质:铜芯 5.敷设方式、部位:桥架内及配管内敷设 6.电压等级(kV):1.0KV | D51: 按设计图示尺寸以长度计算（含预留长度及附加长度） | E51: m | G51: =(H51+I51+J51+K51)*(1+L51) -> 116.76518 | H51: =VLOOKUP(B51,'[1]2.2强电工程'!$B$4:$H$254,7,0) -> 11.07 | I51: =VLOOKUP(B51,'[1]2.2强电工程'!$B$4:$I$254,8,0) -> 84.4 | J51: =VLOOKUP(B51,'[1]2.2强电工程'!$B$4:$J$254,9,0) -> 1.11 | K51: =VLOOKUP(B51,'[1]2.2强电工程'!$B$4:$K$254,10,0) -> 0.16 | L51: =$L$4 -> 0.207 | M51: =F51*G51 -> 0
A52: 49 | B52: 电缆ZR-YJV-4*16+1*10 | C52: 1.名称:电力电缆 2.型号:ZR-YJV 3.规格:4*16+1*10 4.材质:铜芯 5.敷设方式、部位:桥架内及配管内敷设 6.电压等级(kV):1.0KV | D52: 按设计图示尺寸以长度计算（含预留长度及附加长度） | E52: m | G52: =(H52+I52+J52+K52)*(1+L52) -> 98.884682 | H52: =1.15*11.07 -> 12.7305 | I52: =1.15*58.9 -> 67.735 | J52: =1.15*1.11 -> 1.2765 | K52: =1.15*0.16 -> 0.184 | L52: =$L$4 -> 0.207 | M52: =F52*G52 -> 0
...

Sheet 2.3弱电工程
A1: 长城智选商超店装修项目装饰工程
A2: 序号 | B2: 分部分项名称 | C2: 项目特征 | D2: 计量规则 | E2: 单位 | F2: 工程量 | G2: 综合单价 | H2: 人工 | I2: 主材 | J2: 辅材 | K2: 机械 | L2: 其他综合费率 | M2: 合计 | N2: 备注
A3: 一 | B3: 综合布线
A4: 1 | B4: 弱电机柜12U | C4: 1.名称:弱电机柜12U 2.规格:包含PDU插排，用于放置交换机、路由器等设备，留有冗余空间 3.安装方式:落地 | D4: 按设计图示数量计算 | E4: 台 | G4: =(H4+I4+J4+K4)*(1+L4) -> 920.61511 | H4: =VLOOKUP(B4,'[1]2.3弱电工程'!$B$4:$H$195,7,0) -> 270.73 | I4: =VLOOKUP(B4,'[1]2.3弱电工程'!$B$4:$I$195,8,0) -> 480.53 | J4: =VLOOKUP(B4,'[1]2.3弱电工程'!$B$4:$J$195,9,0) -> 10.49 | K4: =VLOOKUP(B4,'[1]2.3弱电工程'!$B$4:$K$195,10,0) -> 0.98 | L4: ='2.1装饰工程'!$L$4 -> 0.207 | M4: =F4*G4 -> 0
A5: 2 | B5: 弱电机柜24U | C5: 1.名称:弱电机柜24U 2.规格:包含PDU插排，用于放置交换机、路由器等设备，留有冗余空间 3.安装方式:落地 | D5: 按设计图示数量计算 | E5: 台 | G5: =(H5+I5+J5+K5)*(1+L5) -> 1755.9074 | H5: =VLOOKUP(B5,'[1]2.3弱电工程'!$B$4:$H$195,7,0) -> 270.73 | I5: =VLOOKUP(B5,'[1]2.3弱电工程'!$B$4:$I$195,8,0) -> 1172.57 | J5: =VLOOKUP(B5,'[1]2.3弱电工程'!$B$4:$J$195,9,0) -> 10.49 | K5: =VLOOKUP(B5,'[1]2.3弱电工程'!$B$4:$K$195,10,0) -> 0.98 | L5: =$L$4 -> 0.207 | M5: =F5*G5 -> 0
A6: 3 | B6: 弱电机柜27U | C6: 1.名称:弱电机柜27U 2.规格:包含PDU插排，用于放置交换机、路由器等设备，留有冗余空间 3.安装方式:落地 | D6: 按设计图示数量计算 | E6: 台 | F6: 1 | G6: =(H6+I6+J6+K6)*(1+L6) -> 2072.069 | H6: =VLOOKUP(B6,'[1]2.3弱电工程'!$B$4:$H$195,7,0) -> 270.73 | I6: =VLOOKUP(B6,'[1]2.3弱电工程'!$B$4:$I$195,8,0) -> 1434.51 | J6: =VLOOKUP(B6,'[1]2.3弱电工程'!$B$4:$J$195,9,0) -> 10.49 | K6: =VLOOKUP(B6,'[1]2.3弱电工程'!$B$4:$K$195,10,0) -> 0.98 | L6: =$L$4 -> 0.207 | M6: =F6*G6 -> 2072.069
A7: 4 | B7: 弱电机柜42U | C7: 1.名称:弱电机柜42U 2.规格:包含PDU插排，用于放置交换机、路由器等设备，留有冗余空间 3.安装方式:落地 | D7: 按设计图示数量计算 | E7: 台 | G7: =(H7+I7+J7+K7)*(1+L7) -> 3134.8687 | H7: =VLOOKUP(B7,'[1]2.3弱电工程'!$B$4:$H$195,7,0) -> 270.73 | I7: =VLOOKUP(B7,'[1]2.3弱电工程'!$B$4:$I$195,8,0) -> 2315.04 | J7: =VLOOKUP(B7,'[1]2.3弱电工程'!$B$4:$J$195,9,0) -> 10.49 | K7: =VLOOKUP(B7,'[1]2.3弱电工程'!$B$4:$K$195,10,0) -> 0.98 | L7: =$L$4 -> 0.207 | M7: =F7*G7 -> 0
A8: 5 | B8: USP不间断电源 | C8: 1.名称:USP不间断电源 2.型号:参考英威腾HT1103CL，内置电池，后备时间＞30分钟 | D8: 按设计图示数量计算 | E8: 个 | G8: =(H8+I8+J8+K8)*(1+L8) -> 5603.6303 | H8: =VLOOKUP(B8,'[1]2.3弱电工程'!$B$4:$H$195,7,0) -> 960.41 | I8: =VLOOKUP(B8,'[1]2.3弱电工程'!$B$4:$I$195,8,0) -> 2981.6 | J8: =VLOOKUP(B8,'[1]2.3弱电工程'!$B$4:$J$195,9,0) -> 700.6 | K8: =VLOOKUP(B8,'[1]2.3弱电工程'!$B$4:$K$195,10,0) -> 0 | L8: =$L$4 -> 0.207 | M8: =F8*G8 -> 0
A9: 6 | B9: 24口配线架 | C9: 1.名称:24口配线架 2.规格:1U,24口，含同品牌非屏蔽模块，模块满配 | D9: 按设计图示数量计算 | E9: 个 | G9: =(H9+I9+J9+K9)*(1+L9) -> 434.8821 | H9: =VLOOKUP(B9,'[1]2.3弱电工程'!$B$4:$H$195,7,0) -> 216.23 | I9: =VLOOKUP(B9,'[1]2.3弱电工程'!$B$4:$I$195,8,0) -> 144.07 | J9: =VLOOKUP(B9,'[1]2.3弱电工程'!$B$4:$J$195,9,0) -> 0 | K9: =VLOOKUP(B9,'[1]2.3弱电工程'!$B$4:$K$195,10,0) -> 0 | L9: =$L$4 -> 0.207 | M9: =F9*G9 -> 0
A10: 7 | B10: 48口配线架 | C10: 1.名称:48口配线架 2.规格:48口，含同品牌非屏蔽模块，模块满配 | D10: 按设计图示数量计算 | E10: 个 | G10: =(H10+I10+J10+K10)*(1+L10) -> 665.35875 | H10: =VLOOKUP(B10,'[1]2.3弱电工程'!$B$4:$H$195,7,0) -> 235.65 | I10: =VLOOKUP(B10,'[1]2.3弱电工程'!$B$4:$I$195,8,0) -> 315.6 | J10: =VLOOKUP(B10,'[1]2.3弱电工程'!$B$4:$J$195,9,0) -> 0 | K10: =VLOOKUP(B10,'[1]2.3弱电工程'!$B$4:$K$195,10,0) -> 0 | L10: =$L$4 -> 0.207 | M10: =F10*G10 -> 0
A11: 8 | B11: 24口理线架 | C11: 1.名称:24口理线架 2.规格:1U,金属材质 | D11: 按设计图示数量计算 | E11: 个 | F11: 1 | G11: =(H11+I11+J11+K11)*(1+L11) -> 107.08504 | H11: =VLOOKUP(B11,'[1]2.3弱电工程'!$B$4:$H$195,7,0) -> 22.75 | I11: =VLOOKUP(B11,'[1]2.3弱电工程'!$B$4:$I$195,8,0) -> 65.97 | J11: =VLOOKUP(B11,'[1]2.3弱电工程'!$B$4:$J$195,9,0) -> 0 | K11: =VLOOKUP(B11,'[1]2.3弱电工程'!$B$4:$K$195,10,0) -> 0 | L11: =$L$4 -> 0.207 | M11: =F11*G11 -> 107.08504
A12: 9 | B12: 48口理线架 | C12: 1.名称:48口理线架 2.规格:金属材质 | D12: 按设计图示数量计算 | E12: 个 | G12: =(H12+I12+J12+K12)*(1+L12) -> 142.60705 | H12: =VLOOKUP(B12,'[1]2.3弱电工程'!$B$4:$H$195,7,0) -> 22.75 | I12: =VLOOKUP(B12,'[1]2.3弱电工程'!$B$4:$I$195,8,0) -> 95.4 | J12: =VLOOKUP(B12,'[1]2.3弱电工程'!$B$4:$J$195,9,0) -> 0 | K12: =VLOOKUP(B12,'[1]2.3弱电工程'!$B$4:$K$195,10,0) -> 0 | L12: =$L$4 -> 0.207 | M12: =F12*G12 -> 0
A13: 10 | B13: 24口交换机 | C13: 1.名称:24口交换机 2.功能:可网管、不低于24口，POE供电，参考TP-LINK | D13: 按设计图示数量计算 | E13: 台 | G13: =(H13+I13+J13+K13)*(1+L13) -> 2977.6569 | H13: =VLOOKUP(B13,'[1]2.3弱电工程'!$B$4:$H$195,7,0) -> 614.25 | I13: =VLOOKUP(B13,'[1]2.3弱电工程'!$B$4:$I$195,8,0) -> 1831.86 | J13: =VLOOKUP(B13,'[1]2.3弱电工程'!$B$4:$J$195,9,0) -> 10.49 | K13: =VLOOKUP(B13,'[1]2.3弱电工程'!$B$4:$K$195,10,0) -> 10.39 | L13: =$L$4 -> 0.207 | M13: =F13*G13 -> 0
A14: 11 | B14: 48口交换机 | C14: 1.名称:48口交换机 2.功能:可网管、不低于48口，POE供电，参考TP-LINK：TL-SG3452P | D14: 按设计图示数量计算 | E14: 台 | G14: =(H14+I14+J14+K14)*(1+L14) -> 5148.7723 | H14: =VLOOKUP(B14,'[1]2.3弱电工程'!$B$4:$H$195,7,0) -> 1023.75 | I14: =VLOOKUP(B14,'[1]2.3弱电工程'!$B$4:$I$195,8,0) -> 3215.93 | J14: =VLOOKUP(B14,'[1]2.3弱电工程'!$B$4:$J$195,9,0) -> 10.49 | K14: =VLOOKUP(B14,'[1]2.3弱电工程'!$B$4:$K$195,10,0) -> 15.59 | L14: =$L$4 -> 0.207 | M14: =F14*G14 -> 0
A15: 12 | B15: 千兆可网管交换机 | C15: 1.名称：交换机 2.规格型号：TP-LINK：TL-SG2226P，可网管、不低于24口，POE供电 3.包括为满足设计、验收规范规定施工所需的一切工序 | D15: 按设计图示数量计算 | E15: 台 | F15: 1 | G15: =(H15+I15+J15+K15)*(1+L15) -> 2737.3191 | H15: =VLOOKUP(B15,'[1]2.3弱电工程'!$B$4:$H$195,7,0) -> 614.25 | I15: =VLOOKUP(B15,'[1]2.3弱电工程'!$B$4:$I$195,8,0) -> 1632.74 | J15: =VLOOKUP(B15,'[1]2.3弱电工程'!$B$4:$J$195,9,0) -> 10.49 | K15: =VLOOKUP(B15,'[1]2.3弱电工程'!$B$4:$K$195,10,0) -> 10.39 | L15: =$L$4 -> 0.207 | M15: =F15*G15 -> 2737.3191
A16: 13 | B16: 工业级以太网交换机 | C16: 1.名称:工业级以太网交换机 2.功能:不低于4个千兆电口+2千兆SFP光口插槽，含光模块、含电源适配器 | D16: 按设计图示数量计算 | E16: 台 | G16: =(H16+I16+J16+K16)*(1+L16) -> 3201.4347 | H16: =VLOOKUP(B16,'[1]2.3弱电工程'!$B$4:$H$195,7,0) -> 614.25 | I16: =VLOOKUP(B16,'[1]2.3弱电工程'!$B$4:$I$195,8,0) -> 2017.26 | J16: =VLOOKUP(B16,'[1]2.3弱电工程'!$B$4:$J$195,9,0) -> 10.49 | K16: =VLOOKUP(B16,'[1]2.3弱电工程'!$B$4:$K$195,10,0) -> 10.39 | L16: =$L$4 -> 0.207 | M16: =F16*G16 -> 0
A17: 14 | B17: 路由器 | C17: 1.名称：路由器 2.规格型号：TP-LINK：TL-ER3200G千兆企业级， 3.包括为满足设计、验收规范规定施工所需的一切工序 | D17: 按设计图示数量计算 | E17: 台 | F17: 1 | G17: =(H17+I17+J17+K17)*(1+L17) -> 986.07072 | H17: =VLOOKUP(B17,'[1]2.3弱电工程'!$B$4:$H$195,7,0) -> 182 | I17: =VLOOKUP(B17,'[1]2.3弱电工程'!$B$4:$I$195,8,0) -> 620.31 | J17: =VLOOKUP(B17,'[1]2.3弱电工程'!$B$4:$J$195,9,0) -> 10.49 | K17: =VLOOKUP(B17,'[1]2.3弱电工程'!$B$4:$K$195,10,0) -> 4.16 | L17: =$L$4 -> 0.207 | M17: =F17*G17 -> 986.07072
A18: 15 | B18: 显示器 | C18: 1.名称:显示器 2.规格:尺寸23.8英寸，分辨率：1920*1080像素，接口：DP、HDMI，附带一根3米HDMI线、键盘1个、鼠标1个 | D18: 按设计图示数量计算 | E18: 台 | F18: 1 | G18: =(H18+I18+J18+K18)*(1+L18) -> 1330.5847 | H18: =VLOOKUP(B18,'[1]2.3弱电工程'!$B$4:$H$195,7,0) -> 54.6 | I18: =VLOOKUP(B18,'[1]2.3弱电工程'!$B$4:$I$195,8,0) -> 1047.79 | J18: =VLOOKUP(B18,'[1]2.3弱电工程'!$B$4:$J$195,9,0) -> 0 | K18: =VLOOKUP(B18,'[1]2.3弱电工程'!$B$4:$K$195,10,0) -> 0 | L18: =$L$4 -> 0.207 | M18: =F18*G18 -> 1330.5847
A19: 16 | B19: 100寸电视(包括电视伸缩支架的采购、安装) | C19: 1.名称:100寸电视 2.类别:(包括电视支架的采购、安装) 3.规格:100寸，选用酷开创维 | D19: 按设计图示数量计算 | E19: 台 | F19: 1 | G19: =(H19+I19+J19+K19)*(1+L19) -> 15449.503 | H19: =VLOOKUP(B19,'[1]2.3弱电工程'!$B$4:$H$195,7,0) -> 63.7 | I19: =VLOOKUP(B19,'[1]2.3弱电工程'!$B$4:$I$195,8,0) -> 12734.51 | J19: =VLOOKUP(B19,'[1]2.3弱电工程'!$B$4:$J$195,9,0) -> 1.71 | K19: =VLOOKUP(B19,'[1]2.3弱电工程'!$B$4:$K$195,10,0) -> 0 | L19: =$L$4 -> 0.207 | M19: =F19*G19 -> 15449.503
A20: 17 | B20: 75寸电视(包括伸缩支架的采购、安装) | C20: 1.名称:75寸电视 2.类别:(包括电视支架的采购、安装) 3.规格:75寸，选用酷开创维 | D20: 按设计图示数量计算 | E20: 台 | F20: 1 | G20: =(H20+I20+J20+K20)*(1+L20) -> 5300.838 | H20: =1.15*63.7 -> 73.255 | I20: 4312.5 | J20: =1.15*1.71 -> 1.9665 | K20: =1.15*3.5 -> 4.025 | L20: =$L$4 -> 0.207 | M20: =F20*G20 -> 5300.838
A21: 18 | B21: 65寸电视(包括伸缩支架的采购、安装) | C21: 1.名称:65寸电视 2.类别:(包括电视支架的采购、安装) 3.规格:65寸，选用酷开创维 | D21: 按设计图示数量计算 | E21: 台 | F21: 1 | G21: =(H21+I21+J21+K21)*(1+L21) -> 4051.593 | H21: =1.15*63.7 -> 73.255 | I21: 3277.5 | J21: =1.15*1.71 -> 1.9665 | K21: =1.15*3.5 -> 4.025 | L21: =$L$4 -> 0.207 | M21: =F21*G21 -> 4051.593
A22: 19 | B22: 智能电表 | C22: 1.名称:智能电表 2.规格:采用4G无线联网，赠送至少8年流量，无需采集器，赠送平台，可查看用电量情况 | D22: 按设计图示数量计算 | E22: 台 | F22: 1 | G22: =(H22+I22+J22+K22)*(1+L22) -> 1168.714 | H22: =VLOOKUP(B22,'[1]2.3弱电工程'!$B$4:$H$195,7,0) -> 250.25 | I22: =VLOOKUP(B22,'[1]2.3弱电工程'!$B$4:$I$195,8,0) -> 716.81 | J22: =VLOOKUP(B22,'[1]2.3弱电工程'!$B$4:$J$195,9,0) -> 1.22 | K22: =VLOOKUP(B22,'[1]2.3弱电工程'!$B$4:$K$195,10,0) -> 0 | L22: =$L$4 -> 0.207 | M22: =F22*G22 -> 1168.714
A23: 20 | B23: 桌面型防火墙 | C23: 1.名称：桌面型防火墙 2.规格型号：TP-LINK：TL-FW5600，支持配置安全策略、审计策略、带宽策略，包含2年病毒库免费升级服务 3.包括为满足设计、验收规范规定施工所需的一切工序 | D23: 按设计图示数量计算 | E23: 台 | F23: 1 | G23: =(H23+I23+J23+K23)*(1+L23) -> 2691.6221 | H23: =VLOOKUP(B23,'[1]2.3弱电工程'!$B$4:$H$195,7,0) -> 364 | I23: =VLOOKUP(B23,'[1]2.3弱电工程'!$B$4:$I$195,8,0) -> 1845.13 | J23: =VLOOKUP(B23,'[1]2.3弱电工程'!$B$4:$J$195,9,0) -> 10.49 | K23: =VLOOKUP(B23,'[1]2.3弱电工程'!$B$4:$K$195,10,0) -> 10.39 | L23: =$L$4 -> 0.207 | M23: =F23*G23 -> 2691.6221
A24: 21 | B24: 无线AP | C24: 1.名称：无线AP 2.规格型号：TP-LINK：TL-XAP1506GC-PoE/DC易展版、千兆、802.11ax、双频WIFI，参考 3.包括为满足设计、验收规范规定施工所需的一切工序 | D24: 按设计图示数量计算 | E24: 台 | F24: 2 | G24: =(H24+I24+J24+K24)*(1+L24) -> 603.85003 | H24: =VLOOKUP(B24,'[1]2.3弱电工程'!$B$4:$H$195,7,0) -> 68.25 | I24: =VLOOKUP(B24,'[1]2.3弱电工程'!$B$4:$I$195,8,0) -> 432.04 | J24: =VLOOKUP(B24,'[1]2.3弱电工程'!$B$4:$J$195,9,0) -> 0 | K24: =VLOOKUP(B24,'[1]2.3弱电工程'!$B$4:$K$195,10,0) -> 0 | L24: =$L$4 -> 0.207 | M24: =F24*G24 -> 1207.7001
A25: 22 | B25: 单口信息插座 | C25: 1.名称:单口信息插座 2.规格:白色，含同等品牌六类非屏蔽模块 3.安装方式:暗装 | D25: 按设计图示数量计算 | E25: 个 | F25: 6 | G25: =(H25+I25+J25+K25)*(1+L25) -> 38.84126 | H25: =VLOOKUP(B25,'[1]2.3弱电工程'!$B$4:$H$195,7,0) -> 11.38 | I25: =VLOOKUP(B25,'[1]2.3弱电工程'!$B$4:$I$195,8,0) -> 20.8 | J25: =VLOOKUP(B25,'[1]2.3弱电工程'!$B$4:$J$195,9,0) -> 0 | K25: =VLOOKUP(B25,'[1]2.3弱电工程'!$B$4:$K$195,10,0) -> 0 | L25: =$L$4 -> 0.207 | M25: =F25*G25 -> 233.04756
A26: 23 | B26: 双口信息插座 | C26: 1.名称:双口信息插座 2.规格:白色，含同等品牌六类非屏蔽模块 3.安装方式:暗装 | D26: 按设计图示数量计算 | E26: 个 | F26: 4 | G26: =(H26+I26+J26+K26)*(1+L26) -> 51.35785 | H26: =VLOOKUP(B26,'[1]2.3弱电工程'!$B$4:$H$195,7,0) -> 13.65 | I26: =VLOOKUP(B26,'[1]2.3弱电工程'!$B$4:$I$195,8,0) -> 28.9 | J26: =VLOOKUP(B26,'[1]2.3弱电工程'!$B$4:$J$195,9,0) -> 0 | K26: =VLOOKUP(B26,'[1]2.3弱电工程'!$B$4:$K$195,10,0) -> 0 | L26: =$L$4 -> 0.207 | M26: =F26*G26 -> 205.4314
A27: 24 | B27: 六类非屏蔽网线 | C27: 1.名称:六类非屏蔽网线 2.敷设方式:综合考虑 | D27: 按设计图示尺寸以长度计算 | E27: m | F27: 480 | G27: =(H27+I27+J27+K27)*(1+L27) -> 5.05733 | H27: =VLOOKUP(B27,'[1]2.3弱电工程'!$B$4:$H$195,7,0) -> 1.57 | I27: =VLOOKUP(B27,'[1]2.3弱电工程'!$B$4:$I$195,8,0) -> 2.61 | J27: =VLOOKUP(B27,'[1]2.3弱电工程'!$B$4:$J$195,9,0) -> 0.01 | K27: =VLOOKUP(B27,'[1]2.3弱电工程'!$B$4:$K$195,10,0) -> 0 | L27: =$L$4 -> 0.207 | M27: =F27*G27 -> 2427.5184
A28: 25 | B28: 六类非屏蔽成品跳线 | C28: 1.名称:六类非屏蔽成品跳线 | D28: 按设计图示数量计算 | E28: 条 | G28: =(H28+I28+J28+K28)*(1+L28) -> 28.940842 | H28: =1.15*4.55 -> 5.2325 | I28: =1.15*15.6 -> 17.94 | J28: =1.15*0.5 -> 0.575 | K28: =1.15*0.2 -> 0.23 | L28: =$L$4 -> 0.207 | M28: =F28*G28 -> 0
A29: 26 | B29: RVV-2*1.0 | C29: 1.名称:RVV-2*1.0 2.敷设方式:综合考虑 | D29: 按设计图示尺寸以长度计算 | E29: m | F29: 35 | G29: =(H29+I29+J29+K29)*(1+L29) -> 5.82981 | H29: =VLOOKUP(B29,'[1]2.3弱电工程'!$B$4:$H$195,7,0) -> 1.73 | I29: =VLOOKUP(B29,'[1]2.3弱电工程'!$B$4:$I$195,8,0) -> 2.92 | J29: =VLOOKUP(B29,'[1]2.3弱电工程'!$B$4:$J$195,9,0) -> 0.18 | K29: =VLOOKUP(B29,'[1]2.3弱电工程'!$B$4:$K$195,10,0) -> 0 | L29: =$L$4 -> 0.207 | M29: =F29*G29 -> 204.04335
A30: 27 | B30: RVV-2*2.5 | C30: 1.名称:RVV-2*2.5 2.敷设方式:综合考虑 | D30: 按设计图示尺寸以长度计算 | E30: m | G30: =(H30+I30+J30+K30)*(1+L30) -> 9.75256 | H30: =VLOOKUP(B30,'[1]2.3弱电工程'!$B$4:$H$195,7,0) -> 1.73 | I30: =VLOOKUP(B30,'[1]2.3弱电工程'!$B$4:$I$195,8,0) -> 6.17 | J30: =VLOOKUP(B30,'[1]2.3弱电工程'!$B$4:$J$195,9,0) -> 0.18 | K30: =VLOOKUP(B30,'[1]2.3弱电工程'!$B$4:$K$195,10,0) -> 0 | L30: =$L$4 -> 0.207 | M30: =F30*G30 -> 0
A31: 28 | B31: 双光纤跳线 | C31: 1.名称:双光纤跳线 2.类别:单模，双芯，2M，支持FC/SC/ST/LC互转 | D31: 按设计图示数量计算 | E31: 条 | G31: =(H31+I31+J31+K31)*(1+L31) -> 38.365702 | H31: =1.15*4.55 -> 5.2325 | I31: =1.15*22.39 -> 25.7485 | J31: =1.15*0.5 -> 0.575 | K31: =1.15*0.2 -> 0.23 | L31: =$L$4 -> 0.207 | M31: =F31*G31 -> 0
A32: 29 | B32: 尾纤2m | C32: 1.名称:尾纤2m | D32: 按设计图示数量计算 | E32: 根 | G32: =(H32+I32+J32+K32)*(1+L32) -> 28.15931 | H32: =VLOOKUP(B32,'[1]2.3弱电工程'!$B$4:$H$195,7,0) -> 18.13 | I32: =VLOOKUP(B32,'[1]2.3弱电工程'!$B$4:$I$195,8,0) -> 3.1 | J32: =VLOOKUP(B32,'[1]2.3弱电工程'!$B$4:$J$195,9,0) -> 0 | K32: =VLOOKUP(B32,'[1]2.3弱电工程'!$B$4:$K$195,10,0) -> 2.1 | L32: =$L$4 -> 0.207 | M32: =F32*G32 -> 0
A33: 30 | B33: 配管JDG20 | C33: 1.名称:配管JDG20 2.材质:镀锌薄钢管 3.规格:Φ20 4.配置形式:明配 5.接地要求:按规范要求 6.其他:含支、吊架制作安装 | D33: 按设计图示尺寸以长度计算 | E33: m | F33: 190 | G33: =(H33+I33+J33+K33)*(1+L33) -> 23.61073 | H33: =1.15*10.09 -> 11.6035 | I33: =1.15*4.84 -> 5.566 | J33: =1.15*1.58 -> 1.817 | K33: =1.15*0.5 -> 0.575 | L33: =$L$4 -> 0.207 | M33: =F33*G33 -> 4486.0388
A34: 31 | B34: 配管JDG20 | C34: 1.名称:配管JDG20 2.材质:镀锌薄钢管 3.规格Φ20 4.配置形式:暗配 5.接地要求:按规范要求 | D34: 按设计图示尺寸以长度计算 | E34: m | G34: =(H34+I34+J34+K34)*(1+L34) -> 22.930586 | H34: =1.15*10.74 -> 12.351 | I34: =1.15*4.84 -> 5.566 | J34: =1.15*0.44 -> 0.506 | K34: =1.15*0.5 -> 0.575 | L34: =$L$4 -> 0.207 | M34: =F34*G34 -> 0
A35: 32 | B35: 配管JDG25 | C35: 1.名称:配管JDG25 2.材质:镀锌薄钢管 3.规格:Φ25 4.配置形式:明配 5.接地要求:按规范要求 6.其他:含支、吊架制作安装 | D35: 按设计图示尺寸以长度计算 | E35: m | G35: =(H35+I35+J35+K35)*(1+L35) -> 26.220264 | H35: =1.15*11.59 -> 13.3285 | I35: =1.15*5.65 -> 6.4975 | J35: =1.15*1.15 -> 1.3225 | K35: =1.15*0.5 -> 0.575 | L35: =$L$4 -> 0.207 | M35: =F35*G35 -> 0
A36: 33 | B36: 配管JDG25 | C36: 1.名称:配管JDG25 2.材质:镀锌薄钢管 3.规格Φ25 4.配置形式:暗配 5.接地要求:按规范要求 | D36: 按设计图示尺寸以长度计算 | E36: m | G36: =(H36+I36+J36+K36)*(1+L36) -> 23.485806 | H36: =1.15*10.33 -> 11.8795 | I36: =1.15*5.65 -> 6.4975 | J36: =1.15*0.44 -> 0.506 | K36: =1.15*0.5 -> 0.575 | L36: =$L$4 -> 0.207 | M36: =F36*G36 -> 0
A37: 34 | B37: 配管JDG32 | C37: 1.名称:配管JDG32 2.材质:镀锌薄钢管 3.规格:Φ32 4.配置形式:明配 5.接地要求:按规范要求 6.其他:含支、吊架制作安装 | D37: 按设计图示尺寸以长度计算 | E37: m | G37: =(H37+I37+J37+K37)*(1+L37) -> 33.410364 | H37: =1.15*13.56 -> 15.594 | I37: =1.15*8.32 -> 9.568 | J37: =1.15*1.69 -> 1.9435 | K37: =1.15*0.5 -> 0.575 | L37: =$L$4 -> 0.207 | M37: =F37*G37 -> 0
A38: 35 | B38: 配管JDG32 | C38: 1.名称:配管JDG32 2.材质:镀锌薄钢管 3.规格Φ32 4.配置形式:暗配 5.接地要求:按规范要求 | D38: 按设计图示尺寸以长度计算 | E38: m | G38: =(H38+I38+J38+K38)*(1+L38) -> 29.815314 | H38: =1.15*11.78 -> 13.547 | I38: =1.15*8.32 -> 9.568 | J38: =1.15*0.88 -> 1.012 | K38: =1.15*0.5 -> 0.575 | L38: =$L$4 -> 0.207 | M38: =F38*G38 -> 0
A39: 36 | B39: 配管PCDN20 | C39: 1.名称:配管PCDN20 2.材质:PC 3.规格:DN20mm 4.配置形式:明配 5.接地要求:按规范要求 | D39: 按设计图示尺寸以长度计算 | E39: m | G39: =(H39+I39+J39+K39)*(1+L39) -> 14.42365 | H39: =VLOOKUP(B39,'[1]2.3弱电工程'!$B$4:$H$195,7,0) -> 9.21 | I39: =VLOOKUP(B39,'[1]2.3弱电工程'!$B$4:$I$195,8,0) -> 1.67 | J39: =VLOOKUP(B39,'[1]2.3弱电工程'!$B$4:$J$195,9,0) -> 1.07 | K39: =VLOOKUP(B39,'[1]2.3弱电工程'!$B$4:$K$195,10,0) -> 0 | L39: =$L$4 -> 0.207 | M39: =F39*G39 -> 0
A40: 37 | B40: 配管PCDN20 | C40: 1.名称:配管PCDN20 2.材质:PC 3.规格:DN20mm 4.配置形式:暗配 5.接地要求:按规范要求 | D40: 按设计图示尺寸以长度计算 | E40: m | G40: =(H40+I40+J40+K40)*(1+L40) -> 14.42365 | H40: =VLOOKUP(B40,'[1]2.3弱电工程'!$B$4:$H$195,7,0) -> 9.21 | I40: =VLOOKUP(B40,'[1]2.3弱电工程'!$B$4:$I$195,8,0) -> 1.67 | J40: =VLOOKUP(B40,'[1]2.3弱电工程'!$B$4:$J$195,9,0) -> 1.07 | K40: =VLOOKUP(B40,'[1]2.3弱电工程'!$B$4:$K$195,10,0) -> 0 | L40: =$L$4 -> 0.207 | M40: =F40*G40 -> 0
...

Sheet 2.4消防工程 
A1: 长城智选商超店装修项目装饰工程
A2: 序号 | B2: 分部分项名称 | C2: 项目特征 | D2: 计量规则 | E2: 单位 | F2: 工程量 | G2: 综合单价 | H2: 人工 | I2: 主材 | J2: 辅材 | K2: 机械 | L2: 其他综合费率 | M2: 合计 | N2: 备注
A3: 1 | B3: 消防工程 | C3: 消防工程审图、消防工程施工、检测、验收、系统接入、放水、店面内灭火器、开业检等一切消防相关费用 | D3: 按消防工程施工部分面积计算 一类城市：北京 | E3: m2 | F3: 300 | G3: =(H3+I3+J3+K3)*(1+L3) -> 482.8 | H3: 400 | I3: 0 | J3: 0 | K3: 0 | L3: ='2.1装饰工程'!$L$4 -> 0.207 | M3: =F3*G3 -> 144840
A4: 2 | B4: 消防工程 | C4: 消防工程审图、消防工程施工、检测、验收、系统接入、放水、店面内灭火器、开业检等一切消防相关费用 | D4: 按消防工程施工部分面积计算 二类城市： 直辖市、省会城市 | E4: m2 | F4: 300 | G4: =(H4+I4+J4+K4)*(1+L4) -> 458.66 | H4: 380 | I4: 0 | J4: 0 | K4: 0 | L4: =$L$3 -> 0.207 | M4: =F4*G4 -> 137598
A5: 3 | B5: 消防工程 | C5: 消防工程审图、消防工程施工、检测、验收、系统接入、放水、店面内灭火器、开业检等一切消防相关费用 | D5: 按消防工程施工部分面积计算 三类城市： 除一、二类以外城市 | E5: m2 | F5: 300 | G5: =(H5+I5+J5+K5)*(1+L5) -> 362.1 | H5: 300 | I5: 0 | J5: 0 | K5: 0 | L5: =$L$3 -> 0.207 | M5: =F5*G5 -> 108630
A6: 4 | B6: 灭火毯 | C6: 1.形式:灭火毯（停车位） 2.其他:按设计及规范要求 | D6: 依据设计要求按m2计算 | E6: m2 | F6: 3 | G6: =(H6+I6+J6+K6)*(1+L6) -> 72.42 | H6: =VLOOKUP(B6,'[1]2.4消防工程 '!$B$3:$H$10,7,0) -> 0 | I6: =VLOOKUP(B6,'[1]2.4消防工程 '!$B$3:$I$10,8,0) -> 60 | J6: =VLOOKUP(B6,'[1]2.4消防工程 '!$B$3:$J$10,9,0) -> 0 | K6: =VLOOKUP(B6,'[1]2.4消防工程 '!$B$3:$K$10,10,0) -> 0 | L6: =$L$3 -> 0.207 | M6: =F6*G6 -> 217.26
A7: 5 | B7: 灭火器箱 | C7: 1.形式:灭火器箱（停车位） 2.其他:按设计及规范要求 | D7: 按设计图示数量计算 | E7: 个 | F7: 6 | G7: =(H7+I7+J7+K7)*(1+L7) -> 96.56 | H7: =VLOOKUP(B7,'[1]2.4消防工程 '!$B$3:$H$10,7,0) -> 0 | I7: =VLOOKUP(B7,'[1]2.4消防工程 '!$B$3:$I$10,8,0) -> 80 | J7: =VLOOKUP(B7,'[1]2.4消防工程 '!$B$3:$J$10,9,0) -> 0 | K7: =VLOOKUP(B7,'[1]2.4消防工程 '!$B$3:$K$10,10,0) -> 0 | L7: =$L$3 -> 0.207 | M7: =F7*G7 -> 579.36
A8: 6 | B8: 干粉灭火器 | C8: 1.干粉灭火器3kg（停车位） 2.不限放置形式（含同规格灭火弹） | E8: 个 | F8: 12 | G8: =(H8+I8+J8+K8)*(1+L8) -> 66.385 | H8: =VLOOKUP(B8,'[1]2.4消防工程 '!$B$3:$H$10,7,0) -> 0 | I8: 55 | J8: =VLOOKUP(B8,'[1]2.4消防工程 '!$B$3:$J$10,9,0) -> 0 | K8: =VLOOKUP(B8,'[1]2.4消防工程 '!$B$3:$K$10,10,0) -> 0 | L8: =$L$3 -> 0.207 | M8: =F8*G8 -> 796.62
A9: 7 | B9: 干粉灭火器 | C9: 1.干粉灭火器4kg（停车位） 2.不限放置形式（含同规格灭火弹） | E9: 个 | F9: 12 | G9: =(H9+I9+J9+K9)*(1+L9) -> 86.904 | H9: =VLOOKUP(B9,'[1]2.4消防工程 '!$B$3:$H$10,7,0) -> 0 | I9: 72 | J9: =VLOOKUP(B9,'[1]2.4消防工程 '!$B$3:$J$10,9,0) -> 0 | K9: =VLOOKUP(B9,'[1]2.4消防工程 '!$B$3:$K$10,10,0) -> 0 | L9: =$L$3 -> 0.207 | M9: =F9*G9 -> 1042.848
A10: 8 | B10: 干粉灭火器 | C10: 1.干粉灭火器5kg（停车位） 2.不限放置形式（含同规格灭火弹） | D10: 不限放置形式（含同规格灭火弹） | E10: 个 | F10: 12 | G10: =(H10+I10+J10+K10)*(1+L10) -> 102.595 | H10: =VLOOKUP(B10,'[1]2.4消防工程 '!$B$3:$H$10,7,0) -> 0 | I10: 85 | J10: =VLOOKUP(B10,'[1]2.4消防工程 '!$B$3:$J$10,9,0) -> 0 | K10: =VLOOKUP(B10,'[1]2.4消防工程 '!$B$3:$K$10,10,0) -> 0 | L10: =$L$3 -> 0.207 | M10: =F10*G10 -> 1231.14
A11: 9 | B11: 干粉灭火器 | C11: 1.干粉灭火器8kg（停车位） 2.不限放置形式（含同规格灭火弹） | D11: 不限放置形式（含同规格灭火弹） | F11: 12 | G11: =(H11+I11+J11+K11)*(1+L11) -> 175.015 | H11: =VLOOKUP(B11,'[1]2.4消防工程 '!$B$3:$H$10,7,0) -> 0 | I11: 145 | J11: =VLOOKUP(B11,'[1]2.4消防工程 '!$B$3:$J$10,9,0) -> 0 | K11: =VLOOKUP(B11,'[1]2.4消防工程 '!$B$3:$K$10,10,0) -> 0 | L11: =$L$3 -> 0.207 | M11: =F11*G11 -> 2100.18
A12: 10 | B12: 二氧化碳灭火器 | C12: 1.二氧化碳灭火器5kg（停车位） 2.放置式灭火器 | E12: 个 | F12: 5 | G12: =(H12+I12+J12+K12)*(1+L12) -> 193.12 | H12: =VLOOKUP(B12,'[1]2.4消防工程 '!$B$3:$H$10,7,0) -> 0 | I12: =VLOOKUP(B12,'[1]2.4消防工程 '!$B$3:$I$10,8,0) -> 160 | J12: =VLOOKUP(B12,'[1]2.4消防工程 '!$B$3:$J$10,9,0) -> 0 | K12: =VLOOKUP(B12,'[1]2.4消防工程 '!$B$3:$K$10,10,0) -> 0 | L12: =$L$3 -> 0.207 | M12: =F12*G12 -> 965.6
A13: 11 | B13: 水基灭火器 | C13: 1.水基灭火器6L（停车位） 2.放置式灭火器 | E13: 个 | F13: 5 | G13: =(H13+I13+J13+K13)*(1+L13) -> 126.735 | H13: =VLOOKUP(B13,'[1]2.4消防工程 '!$B$3:$H$10,7,0) -> 0 | I13: =VLOOKUP(B13,'[1]2.4消防工程 '!$B$3:$I$10,8,0) -> 105 | J13: =VLOOKUP(B13,'[1]2.4消防工程 '!$B$3:$J$10,9,0) -> 0 | K13: =VLOOKUP(B13,'[1]2.4消防工程 '!$B$3:$K$10,10,0) -> 0 | L13: =$L$3 -> 0.207 | M13: =F13*G13 -> 633.675
A14: 12 | B14: 水基灭火器 | C14: 1.水基灭火器3L（停车位） 2.放置式灭火器 | E14: 个 | F14: 5 | G14: =(H14+I14+J14+K14)*(1+L14) -> 78.455 | H14: =VLOOKUP(B14,'[1]2.4消防工程 '!$B$3:$H$10,7,0) -> 0 | I14: 65 | J14: =VLOOKUP(B14,'[1]2.4消防工程 '!$B$3:$J$10,9,0) -> 0 | K14: =VLOOKUP(B14,'[1]2.4消防工程 '!$B$3:$K$10,10,0) -> 0 | L14: =$L$3 -> 0.207 | M14: =F14*G14 -> 392.275
A15: 合计 | M15: =SUM(M3:M14) -> 399026.96

Sheet 2.5暖通工程
A1: 长城智选商超店装修项目装饰工程
A2: 序号 | B2: 分部分项名称 | C2: 项目特征 | D2: 计量规则 | E2: 单位 | F2: 工程量 | G2: 综合单价 | H2: 人工 | I2: 主材 | J2: 辅材 | K2: 机械 | L2: 其他综合费率 | M2: 合计 | N2: 备注
A3: 1 | B3: 多联式空调机组室外机5匹 | C3: 1.名称:多联式空调机组室外机 2.其他:根据现场情况按设计及规范要求 | D3: 按设计图示数量计算 | E3: 台 | G3: =(H3+I3+J3+K3)*(1+L3) -> 9482.0713 | H3: =VLOOKUP(B3,'[1]2.5暖通工程'!$B$3:$H$94,7,0) -> 841.3 | I3: =VLOOKUP(B3,'[1]2.5暖通工程'!$B$3:$I$94,8,0) -> 6976.11 | J3: =VLOOKUP(B3,'[1]2.5暖通工程'!$B$3:$J$94,9,0) -> 5.39 | K3: =VLOOKUP(B3,'[1]2.5暖通工程'!$B$3:$K$94,10,0) -> 33.1 | L3: ='2.1装饰工程'!$L$4 -> 0.207 | M3: =F3*G3 -> 0
A4: 2 | B4: 多联式空调机组室外机8匹 | C4: 1.名称:多联式空调机组室外机 2.其他:根据现场情况按设计及规范要求 | D4: 按设计图示数量计算，如5匹-8匹之间按5匹计费 | E4: 台 | G4: =(H4+I4+J4+K4)*(1+L4) -> 19176.526 | H4: =VLOOKUP(B4,'[1]2.5暖通工程'!$B$3:$H$94,7,0) -> 841.3 | I4: =VLOOKUP(B4,'[1]2.5暖通工程'!$B$3:$I$94,8,0) -> 15007.97 | J4: =VLOOKUP(B4,'[1]2.5暖通工程'!$B$3:$J$94,9,0) -> 5.39 | K4: =VLOOKUP(B4,'[1]2.5暖通工程'!$B$3:$K$94,10,0) -> 33.1 | L4: =$L$3 -> 0.207 | M4: =F4*G4 -> 0
A5: 3 | B5: 多联式空调机组室外机10匹 | C5: 1.名称:多联式空调机组室外机 2.其他:根据现场情况按设计及规范要求 | D5: 按设计图示数量计算，如8匹-10匹之间按8匹计费 | E5: 台 | G5: =(H5+I5+J5+K5)*(1+L5) -> 19777.89 | H5: =VLOOKUP(B5,'[1]2.5暖通工程'!$B$3:$H$94,7,0) -> 841.3 | I5: =VLOOKUP(B5,'[1]2.5暖通工程'!$B$3:$I$94,8,0) -> 15506.2 | J5: =VLOOKUP(B5,'[1]2.5暖通工程'!$B$3:$J$94,9,0) -> 5.39 | K5: =VLOOKUP(B5,'[1]2.5暖通工程'!$B$3:$K$94,10,0) -> 33.1 | L5: =$L$3 -> 0.207 | M5: =F5*G5 -> 0
A6: 4 | B6: 多联式空调机组室外机12匹 | C6: 1.名称:多联式空调机组室外机 2.其他:根据现场情况按设计及规范要求 | D6: 按设计图示数量计算，如10匹-12匹之间按10匹计费 | E6: 台 | G6: =(H6+I6+J6+K6)*(1+L6) -> 21938.734 | H6: =VLOOKUP(B6,'[1]2.5暖通工程'!$B$3:$H$94,7,0) -> 841.3 | I6: =VLOOKUP(B6,'[1]2.5暖通工程'!$B$3:$I$94,8,0) -> 17296.46 | J6: =VLOOKUP(B6,'[1]2.5暖通工程'!$B$3:$J$94,9,0) -> 5.39 | K6: =VLOOKUP(B6,'[1]2.5暖通工程'!$B$3:$K$94,10,0) -> 33.1 | L6: =$L$3 -> 0.207 | M6: =F6*G6 -> 0
A7: 5 | B7: 多联式空调机组室外机14匹 | C7: 1.名称:多联式空调机组室外机 2.其他:根据现场情况按设计及规范要求 | D7: 按设计图示数量计算，如14匹-16匹之间按14匹计费 | E7: 台 | G7: =(H7+I7+J7+K7)*(1+L7) -> 23382.354 | H7: =VLOOKUP(B7,'[1]2.5暖通工程'!$B$3:$H$94,7,0) -> 1260.35 | I7: =VLOOKUP(B7,'[1]2.5暖通工程'!$B$3:$I$94,8,0) -> 18073.45 | J7: =VLOOKUP(B7,'[1]2.5暖通工程'!$B$3:$J$94,9,0) -> 5.39 | K7: =VLOOKUP(B7,'[1]2.5暖通工程'!$B$3:$K$94,10,0) -> 33.1 | L7: =$L$3 -> 0.207 | M7: =F7*G7 -> 0
A8: 6 | B8: 多联式空调机组室外机16匹 | C8: 1.名称:多联式空调机组室外机 2.其他:根据现场情况按设计及规范要求 | D8: 按设计图示数量计算，如14匹-16匹之间按14匹计费 | E8: 台 | G8: =(H8+I8+J8+K8)*(1+L8) -> 26372.081 | H8: =VLOOKUP(B8,'[1]2.5暖通工程'!$B$3:$H$94,7,0) -> 1260.35 | I8: =VLOOKUP(B8,'[1]2.5暖通工程'!$B$3:$I$94,8,0) -> 20550.44 | J8: =VLOOKUP(B8,'[1]2.5暖通工程'!$B$3:$J$94,9,0) -> 5.39 | K8: =VLOOKUP(B8,'[1]2.5暖通工程'!$B$3:$K$94,10,0) -> 33.1 | L8: =$L$3 -> 0.207 | M8: =F8*G8 -> 0
A9: 7 | B9: 多联式空调机组室外机20匹 | C9: 1.名称:多联式空调机组室外机 2.其他:根据现场情况按设计及规范要求 | D9: 按设计图示数量计算，如16匹-20匹之间按16匹计费 | E9: 台 | G9: =(H9+I9+J9+K9)*(1+L9) -> 33364.135 | H9: =VLOOKUP(B9,'[1]2.5暖通工程'!$B$3:$H$94,7,0) -> 1260.35 | I9: =VLOOKUP(B9,'[1]2.5暖通工程'!$B$3:$I$94,8,0) -> 26343.36 | J9: =VLOOKUP(B9,'[1]2.5暖通工程'!$B$3:$J$94,9,0) -> 5.39 | K9: =VLOOKUP(B9,'[1]2.5暖通工程'!$B$3:$K$94,10,0) -> 33.1 | L9: =$L$3 -> 0.207 | M9: =F9*G9 -> 0
A10: 8 | B10: 多联式空调机组室外机22匹 | C10: 1.名称:多联式空调机组室外机 2.其他:根据现场情况按设计及规范要求 | D10: 按设计图示数量计算，如20匹-22匹之间按20匹计费 | E10: 台 | G10: =(H10+I10+J10+K10)*(1+L10) -> 34688.721 | H10: =VLOOKUP(B10,'[1]2.5暖通工程'!$B$3:$H$94,7,0) -> 1557.47 | I10: =VLOOKUP(B10,'[1]2.5暖通工程'!$B$3:$I$94,8,0) -> 27143.36 | J10: =VLOOKUP(B10,'[1]2.5暖通工程'!$B$3:$J$94,9,0) -> 5.69 | K10: =VLOOKUP(B10,'[1]2.5暖通工程'!$B$3:$K$94,10,0) -> 33.1 | L10: =$L$3 -> 0.207 | M10: =F10*G10 -> 0
A11: 9 | B11: 多联式空调机组室外机24匹 | C11: 1.名称:多联式空调机组室外机 2.其他:根据现场情况按设计及规范要求 | D11: 按设计图示数量计算，如22匹-24匹之间按22匹计费 | E11: 台 | G11: =(H11+I11+J11+K11)*(1+L11) -> 36951.05 | H11: =VLOOKUP(B11,'[1]2.5暖通工程'!$B$3:$H$94,7,0) -> 1557.47 | I11: =VLOOKUP(B11,'[1]2.5暖通工程'!$B$3:$I$94,8,0) -> 29017.7 | J11: =VLOOKUP(B11,'[1]2.5暖通工程'!$B$3:$J$94,9,0) -> 5.69 | K11: =VLOOKUP(B11,'[1]2.5暖通工程'!$B$3:$K$94,10,0) -> 33.1 | L11: =$L$3 -> 0.207 | M11: =F11*G11 -> 0
A12: 10 | B12: 多联式空调机组室外机26匹 | C12: 1.名称:多联式空调机组室外机 2.其他:根据现场情况按设计及规范要求 | D12: 按设计图示数量计算，如24匹-26匹之间按24匹计费 | E12: 台 | G12: =(H12+I12+J12+K12)*(1+L12) -> 39358.641 | H12: =VLOOKUP(B12,'[1]2.5暖通工程'!$B$3:$H$94,7,0) -> 1557.47 | I12: =VLOOKUP(B12,'[1]2.5暖通工程'!$B$3:$I$94,8,0) -> 31012.39 | J12: =VLOOKUP(B12,'[1]2.5暖通工程'!$B$3:$J$94,9,0) -> 5.69 | K12: =VLOOKUP(B12,'[1]2.5暖通工程'!$B$3:$K$94,10,0) -> 33.1 | L12: =$L$3 -> 0.207 | M12: =F12*G12 -> 0
A13: 11 | B13: 多联式空调机组室外机28匹 | C13: 1.名称:多联式空调机组室外机 2.其他:根据现场情况按设计及规范要求 | D13: 按设计图示数量计算，如26匹-28匹之间按28匹计费 | E13: 台 | G13: =(H13+I13+J13+K13)*(1+L13) -> 43275.512 | H13: =VLOOKUP(B13,'[1]2.5暖通工程'!$B$3:$H$94,7,0) -> 1557.47 | I13: =VLOOKUP(B13,'[1]2.5暖通工程'!$B$3:$I$94,8,0) -> 34257.52 | J13: =VLOOKUP(B13,'[1]2.5暖通工程'!$B$3:$J$94,9,0) -> 5.69 | K13: =VLOOKUP(B13,'[1]2.5暖通工程'!$B$3:$K$94,10,0) -> 33.1 | L13: =$L$3 -> 0.207 | M13: =F13*G13 -> 0
A14: 12 | B14: 四面出风多联式空调室内机制冷量2.8kw | C14: 1.名称:四面出风多联式空调室内机 2.安装形式:吊顶式 3.减振器、支架形式、材质:按设计及规范要求 4.附件：含紫铜管、分歧器、冷凝水管等至系统验收所需附件。 5.其他:按设计及规范要求 | D14: 按设计图示数量计算，如制冷量为2.8-3.6kw之间，按2.8kw计费 | E14: 台 | G14: =(H14+I14+J14+K14)*(1+L14) -> 3597.9342 | H14: =VLOOKUP(B14,'[1]2.5暖通工程'!$B$3:$H$94,7,0) -> 596.5 | I14: =VLOOKUP(B14,'[1]2.5暖通工程'!$B$3:$I$94,8,0) -> 2311.27 | J14: =VLOOKUP(B14,'[1]2.5暖通工程'!$B$3:$J$94,9,0) -> 40.39 | K14: =VLOOKUP(B14,'[1]2.5暖通工程'!$B$3:$K$94,10,0) -> 32.73 | L14: =$L$3 -> 0.207 | M14: =F14*G14 -> 0
A15: 13 | B15: 四面出风多联式空调室内机制冷量3.6kw | C15: 1.名称:四面出风多联式空调室内机 2.安装形式:吊顶式 3.减振器、支架形式、材质:按设计及规范要求 4.附件：含紫铜管、分歧器、冷凝水管等至系统验收所需附件。 5.其他:按设计及规范要求 | D15: 按设计图示数量计算，如制冷量为3.6-5.6kw之间，按3.6kw计费 | E15: 台 | G15: =(H15+I15+J15+K15)*(1+L15) -> 3650.2697 | H15: =VLOOKUP(B15,'[1]2.5暖通工程'!$B$3:$H$94,7,0) -> 596.5 | I15: =VLOOKUP(B15,'[1]2.5暖通工程'!$B$3:$I$94,8,0) -> 2354.63 | J15: =VLOOKUP(B15,'[1]2.5暖通工程'!$B$3:$J$94,9,0) -> 40.39 | K15: =VLOOKUP(B15,'[1]2.5暖通工程'!$B$3:$K$94,10,0) -> 32.73 | L15: =$L$3 -> 0.207 | M15: =F15*G15 -> 0
... A33: 31 | B33: 风机盘管制冷量14kw | C33: 1.名称:风机盘管 2.安装形式:吊顶式 3.减振器、支架形式、材质:按设计及规范要求 4.附件：含紫铜管、分歧器、冷凝水管等至系统验收所需附件。 5.其他:按设计及规范要求 | D33: 按设计图示数量计算，如制冷量≥14kw，按14kw计费 | E33: 台 | G33: =(H33+I33+J33+K33)*(1+L33) -> 5466.4789 | H33: =VLOOKUP(B33,'[1]2.5暖通工程'!$B$3:$H$94,7,0) -> 616.98 | I33: =VLOOKUP(B33,'[1]2.5暖通工程'!$B$3:$I$94,8,0) -> 3838 | J33: =VLOOKUP(B33,'[1]2.5暖通工程'!$B$3:$J$94,9,0) -> 41.27 | K33: =VLOOKUP(B33,'[1]2.5暖通工程'!$B$3:$K$94,10,0) -> 32.73 | L33: =$L$3 -> 0.207 | M33: =F33*G33 -> 0
A34: 32 | B34: 风机盘管制冷量2.8kw（水） | C34: 1.名称:风机盘管 2.安装形式:吊顶式 3.减振器、支架形式、材质:按设计及规范要求 4.附件：含供回水管、阀门、冷凝水管等至系统验收所需附件。 5.其他:按设计及规范要求 | D34: 按设计图示数量计算，如制冷量为2.8-3.6kw之间，按2.8kw计费 | E34: 台 | F34: 2 | G34: =(H34+I34+J34+K34)*(1+L34) -> 1720.8199 | H34: 680 | I34: 678.6 | J34: 33.95 | K34: 33.15 | L34: =$L$3 -> 0.207 | M34: =F34*G34 -> 3441.6398
